Workbook

Sheet December, 2021
B3: STAFF PAYROLL FOR THE MONTH OF DECEMBER, 2021
E4: ='[1]FEB 08'!E8/'[1]FEB 08'!M8 -> 0.22 | H4: ='[1]FEB 08'!F8/'[1]FEB 08'!Q8 -> 0.3
B5: STAFF NAME | T5: DEDUCTIONS | Z5: NET SALARY
C6: DESIGNATION | D6: SALARY | E6: BASIC | L6: MOTOR/ | M6: RESEARCH | N6: HARDSHIP | O6: LEAVE | P6: OUT FIT | Q6: LEGISLATIVE | R6: GROSS | Y6: NOVEMBER,2021 | Z6: DECEMBER,2021
D7: LEVEL | E7: SALARY | F7: SALARY/ALLOWCE AREARS | G7: RENT | H7: UTILITY | I7: DOMESTIC | J7: ENTERT. | K7: FURNIT. | L7: FUEL | M7: ALLOWANCE | N7: ALLOWANCE | O7: ALLCE | P7: ALLCE | Q7: DUTY ALLCE | R7: SALARY | S7: AUCTION | T7: COOP SOCIETY | U7: COOP. LOAN RECOVERY | V7: NHF DEDUCTION | W7: PAYE | X7: TOTAL
A8: S/N | B8: DG OFFICE | E8: N | H8: N | R8: N | W8: N
A9: 1 | B9: PROF. ABUBAKAR O. SULAIMAN | C9: DIRECTOR GENERAL | D9: CONSOL | E9: 160488.75 | G9: 320977.5 | H9: 48146.63 | I9: 120366.57 | J9: 72219.94 | K9: 0 | L9: 120366.57 | M9: =250000 -> 250000 | O9: 16048.88 | P9: 25000 | Q9: 25235 | R9: =Q9+P9+O9+N9+M9+L9+K9+J9+I9+H9+G9+F9+E9 -> 1158849.8 | W9: 113176.97 | X9: =W9+V9+U9+T9+S9 -> 113176.97 | Y9: 1045672.9 | Z9: =R9-X9 -> 1045672.9
A10: 2 | B10: DR ADEYEMI AKEEB FAJINGBESI | C10: DIR. SPECIAL DUTIES, DG OFFICE | D10: 17(9) | E10: 81740.02 | G10: =E10*300% -> 245220.06 | H10: =E10*7.5% -> 6130.5015 | I10: 80244.38 | J10: =E10*50% -> 40870.01 | K10: =E10*350% -> 286090.07 | L10: =E10*100% -> 81740.02 | M10: =200000 -> 200000 | O10: =E10*10% -> 8174.002 | P10: 20000 | Q10: 0 | R10: =Q10+P10+O10+N10+M10+L10+K10+J10+I10+H10+G10+F10+E10 -> 1050209.1 | T10: 200000 | U10: =59722.22 -> 59722.22 | V10: ='[2]Jan 2021'!$H$35 -> 2043.5005 | W10: 52776.63 | X10: =W10+V10+U10+T10+S10 -> 314542.35 | Y10: 735666.71 | Z10: =R10-X10 -> 735666.71
A11: 3 | B11: SARAFADEEN ALABELEWE | C11: SA- ADMIN | D11: 16(9) | E11: =42653.17 -> 42653.17 | G11: =E11*300% -> 127959.51 | H11: =E11*7.5% -> 3198.9877 | I11: 40122.19 | J11: =E11*50% -> 21326.585 | K11: =E11*350% -> 149286.1 | L11: =E11*100% -> 42653.17 | N11: =90000 -> 90000 | O11: =E11*10% -> 4265.317 | P11: 20000 | R11: =Q11+P11+O11+N11+M11+L11+K11+J11+I11+H11+G11+F11+E11 -> 541465.02 | T11: =100000 -> 100000 | U11: =201736.11 -> 201736.11 | W11: 21618.09 | X11: =W11+V11+U11+T11+S11 -> 323354.2 | Y11: 218110.82 | Z11: =R11-X11 -> 218110.82
A12: 4 | B12: DR JAKE DABANG DAN AZUMI | C12: DEPUTY DIRECTOR TRAINING | D12: 16(7) | E12: =39662.25 -> 39662.25 | G12: =E12*300% -> 118986.75 | H12: =E12*7.5% -> 2974.6687 | I12: 40122.19 | J12: =E12*50% -> 19831.125 | K12: =E12*350% -> 138817.88 | L12: =E12*100% -> 39662.25 | M12: =180000 -> 180000 | O12: =E12*10% -> 3966.225 | P12: 20000 | Q12: 150000 | R12: =Q12+P12+O12+N12+M12+L12+K12+J12+I12+H12+G12+F12+E12 -> 754023.33 | V12: ='[2]Jan 2021'!$H$27 -> 991.55625 | W12: =21618.09 -> 21618.09 | X12: =W12+V12+U12+T12+S12 -> 22609.646 | Y12: 731413.69 | Z12: =R12-X12 -> 731413.69
A13: 5 | B13: DR ABDULSALAM NASIRU NAEEM | C13: SA ACADEMICS | D13: 16(7) | E13: =39662.25 -> 39662.25 | G13: =E13*300% -> 118986.75 | H13: =E13*7.5% -> 2974.6687 | I13: 40122.19 | J13: =E13*50% -> 19831.125 | K13: =E13*350% -> 138817.88 | L13: =E13*100% -> 39662.25 | M13: =180000 -> 180000 | O13: =E13*10% -> 3966.225 | P13: 20000 | Q13: =100000 -> 100000 | R13: =Q13+P13+O13+N13+M13+L13+K13+J13+I13+H13+G13+F13+E13 -> 704023.33 | W13: =21618.09 -> 21618.09 | X13: =W13+V13+U13+T13+S13 -> 21618.09 | Y13: 682405.24 | Z13: =R13-X13 -> 682405.24
A14: 6 | B14: RAHEEM USMAN AYIGORO | C14: SA-INFRASTRUCTURE | D14: 16 (7) | E14: =39662.25 -> 39662.25 | G14: =E14*300% -> 118986.75 | H14: =E14*7.5% -> 2974.6687 | I14: 40122.19 | J14: =E14*50% -> 19831.125 | K14: =E14*350% -> 138817.88 | L14: =E14*100% -> 39662.25 | N14: =90000 -> 90000 | O14: =E14*10% -> 3966.225 | P14: 20000 | Q14: 0 | R14: =Q14+P14+O14+N14+M14+L14+K14+J14+I14+H14+G14+F14+E14 -> 514023.33 | W14: =21618.09 -> 21618.09 | X14: =W14+V14+U14+T14+S14 -> 21618.09 | Y14: 492405.24 | Z14: =R14-X14 -> 492405.24
A15: 7 | B15: AKINSANMI ADEJOKE OLUKEMI | C15: HEAD INFORMATION/PROTOCOL | D15: 15(9) | E15: 33507.5 | G15: =E15*300% -> 100522.5 | H15: =E15*7.5% -> 2513.0625 | I15: 40122.19 | J15: =E15*50% -> 16753.75 | K15: =E15*350% -> 117276.25 | L15: =E15*100% -> 33507.5 | N15: =80000 -> 80000 | O15: =E15*10% -> 3350.75 | P15: 20000 | Q15: =100000 -> 100000 | R15: =Q15+P15+O15+N15+M15+L15+K15+J15+I15+H15+G15+F15+E15 -> 547553.5 | T15: =0 -> 0 | U15: 0 | V15: =837.69 -> 837.69 | W15: 15548.33 | X15: =W15+V15+U15+T15+S15 -> 16386.02 | Y15: 531167.48 | Z15: =R15-X15 -> 531167.48
A16: 8 | B16: DR IKEME ARTHUR J.O | C16: SNR RESEARCH FELLOW | D16: 15(9) | E16: =33507.5 -> 33507.5 | G16: =E16*300% -> 100522.5 | H16: =E16*7.5% -> 2513.0625 | I16: 40122.19 | J16: =E16*50% -> 16753.75 | K16: =E16*350% -> 117276.25 | L16: =E16*100% -> 33507.5 | N16: =80000 -> 80000 | O16: =E16*10% -> 3350.75 | P16: 20000 | Q16: 0 | R16: =Q16+P16+O16+N16+M16+L16+K16+J16+I16+H16+G16+F16+E16 -> 447553.5 | T16: =50000 -> 50000 | U16: =160416.67 -> 160416.67 | V16: ='[3]DECEMBER 2019'!$H$38 -> 837.6875 | W16: 15548.33 | X16: =W16+V16+U16+T16+S16 -> 226802.69 | Y16: 220750.82 | Z16: =R16-X16 -> 220750.82
A17: 9 | B17: MOSHOOD M. OLALERE | C17: MANAGER ADMIN DG's OFFICE | D17: 15(9) | E17: =33507.5 -> 33507.5 | G17: =E17*300% -> 100522.5 | H17: =E17*7.5% -> 2513.0625 | I17: 40122.19 | J17: =E17*50% -> 16753.75 | K17: =E17*350% -> 117276.25 | L17: =E17*100% -> 33507.5 | N17: =80000 -> 80000 | O17: =E17*10% -> 3350.75 | P17: 20000 | Q17: 0 | R17: =Q17+P17+O17+N17+M17+L17+K17+J17+I17+H17+G17+F17+E17 -> 447553.5 | T17: =20000 -> 20000 | U17: =179017.51 -> 179017.51 | V17: ='[3]DECEMBER 2019'!$H$35 -> 837.6875 | W17: 15548.33 | X17: =W17+V17+U17+T17+S17 -> 215403.53 | Y17: 232149.97 | Z17: =R17-X17 -> 232149.97
A18: 10 | B18: ANDRAWUS MUSA | C18: ASST. DIRECTOR, STORE | D18: 15(8) | E18: =32263.2 -> 32263.2 | G18: =E18*300% -> 96789.6 | H18: =E18*7.5% -> 2419.74 | I18: =40122.19 -> 40122.19 | J18: =E18*50% -> 16131.6 | K18: =E18*350% -> 112921.2 | L18: =E18*100% -> 32263.2 | N18: =80000 -> 80000 | O18: =E18*10% -> 3226.32 | P18: 20000 | Q18: 0 | R18: =SUM(E18:Q18) -> 436137.05 | T18: =50000 -> 50000 | U18: =90000 -> 90000 | V18: ='[2]Jan 2021'!$H$29 -> 806.58 | W18: =15548.33 -> 15548.33 | X18: =W18+V18+U18+T18+S18 -> 156354.91 | Y18: 279782.14 | Z18: =R18-X18 -> 279782.14
A19: 11 | B19: AYOBOLU OLAJIDE OLUFUNSHO | C19: ASST.DIR., INFORMATION | D19: 15 (7) | E19: 31018.84 | G19: =E19*300% -> 93056.52 | H19: =E19*7.5% -> 2326.413 | I19: 40122.19 | J19: =E19*50% -> 15509.42 | K19: =E19*350% -> 108565.94 | L19: =E19*100% -> 31018.84 | N19: =80000 -> 80000 | O19: =E19*10% -> 3101.884 | P19: 20000 | Q19: 0 | R19: =Q19+P19+O19+N19+M19+L19+K19+J19+I19+H19+G19+F19+E19 -> 424720.05 | T19: =25000 -> 25000 | U19: =52500 -> 52500 | W19: 15548.33 | X19: =W19+V19+U19+T19+S19 -> 93048.33 | Y19: 331671.72 | Z19: =R19-X19 -> 331671.72
A20: 12 | B20: HUSSEIN EGYE MUSA | C20: CHIEF PROTOCOL OFFICER | D20: 14(8) | E20: =25854.1 -> 25854.1 | G20: =E20*300% -> 77562.3 | H20: =E20*7.5% -> 1939.0575 | J20: =E20*50% -> 12927.05 | K20: =E20*350% -> 90489.35 | L20: =E20*100% -> 25854.1 | N20: =70000 -> 70000 | O20: =E20*10% -> 2585.41 | P20: 20000 | Q20: 50000 | R20: =Q20+P20+O20+N20+M20+L20+K20+J20+I20+H20+G20+F20+E20 -> 377211.37 | T20: 50000 | U20: =150000 -> 150000 | V20: 0 | W20: 7709.76 | X20: =W20+V20+U20+T20+S20 -> 207709.76 | Y20: 169501.61 | Z20: =R20-X20 -> 169501.61
A21: 13 | B21: DONALD E. MKPANAM | C21: CHIEF ICT OFFICER | D21: 14(8) | E21: =25854.1 -> 25854.1 | G21: =E21*300% -> 77562.3 | H21: =E21*7.5% -> 1939.0575 | J21: =E21*50% -> 12927.05 | K21: =E21*350% -> 90489.35 | L21: =E21*100% -> 25854.1 | N21: =70000 -> 70000 | O21: =E21*10% -> 2585.41 | P21: 20000 | Q21: 0 | R21: =Q21+P21+O21+N21+M21+L21+K21+J21+I21+H21+G21+F21+E21 -> 327211.37 | V21: ='[2]Jan 2021'!$H$28 -> 658.4825 | W21: 7709.76 | X21: =W21+V21+U21+T21+S21 -> 8368.2425 | Y21: 318843.12 | Z21: =R21-X21 -> 318843.12
A22: 14 | B22: JOY HARUNA MAKERI | C22: RESEARCH FELLOW 1 TRAINING | D22: 14(8) | E22: =25854.1 -> 25854.1 | G22: =E22*300% -> 77562.3 | H22: =E22*7.5% -> 1939.0575 | J22: =E22*50% -> 12927.05 | K22: =E22*350% -> 90489.35 | L22: =E22*100% -> 25854.1 | M22: =140000 -> 140000 | O22: =E22*10% -> 2585.41 | P22: 20000 | Q22: =50000+100000 -> 150000 | R22: =Q22+P22+O22+N22+M22+L22+K22+J22+I22+H22+G22+F22+E22 -> 547211.37 | W22: =7709.76 -> 7709.76 | X22: =W22+V22+U22+T22+S22 -> 7709.76 | Y22: 539501.61 | Z22: =R22-X22 -> 539501.61
A23: 15 | B23: ALI ABDULLAHI | C23: ASST. CHIEF ICT OFFICER | D23: 13(11) | E23: =26339.3 -> 26339.3 | G23: =E23*300% -> 79017.9 | H23: =E23*7.5% -> 1975.4475 | I23: 0 | J23: =E23*50% -> 13169.65 | K23: =E23*350% -> 92187.55 | L23: =E23*100% -> 26339.3 | N23: =70000 -> 70000 | O23: =E23*10% -> 2633.93 | P23: 15000 | Q23: =0 -> 0 | R23: =Q23+P23+O23+N23+M23+L23+K23+J23+I23+H23+G23+F23+E23 -> 326663.08 | W23: =7709.76 -> 7709.76 | X23: =W23+V23+U23+T23+S23 -> 7709.76 | Y23: 318953.32 | Z23: =R23-X23 -> 318953.32
A24: 16 | B24: MARIAM MOHAMMED BELLO | C24: PA- SPECIAL DUTIES | D24: 13 (7) | E24: =23074.99 -> 23074.99 | G24: =E24*300% -> 69224.97 | H24: =E24*7.5% -> 1730.6243 | I24: 0 | J24: =E24*50% -> 11537.495 | K24: =E24*350% -> 80762.465 | L24: =E24*100% -> 23074.99 | N24: =70000 -> 70000 | O24: =E24*10% -> 2307.499 | P24: 15000 | Q24: =100000+100000 -> 200000 | R24: =Q24+P24+O24+N24+M24+L24+K24+J24+I24+H24+G24+F24+E24 -> 496713.03 | W24: =7709.76 -> 7709.76 | X24: =W24+V24+U24+T24+S24 -> 7709.76 | Y24: 489003.27 | Z24: =R24-X24 -> 489003.27
A25: 17 | B25: PERCY TERFA GBAHABO | C25: HEAD, NILDS LIAISON OFFICE | D25: 13(7) | E25: =23074.99 -> 23074.99 | G25: =E25*300% -> 69224.97 | H25: =E25*7.5% -> 1730.6243 | I25: 0 | J25: =E25*50% -> 11537.495 | K25: =E25*350% -> 80762.465 | L25: =E25*100% -> 23074.99 | M25: =120000 -> 120000 | O25: =E25*10% -> 2307.499 | P25: 15000 | Q25: 0 | R25: =Q25+P25+O25+N25+M25+L25+K25+J25+I25+H25+G25+F25+E25 -> 346713.03 | T25: =10000 -> 10000 | U25: =98464.26 -> 98464.26 | W25: =7709.76 -> 7709.76 | X25: =W25+V25+U25+T25+S25 -> 116174.02 | Y25: 230539.01 | Z25: =R25-X25 -> 230539.01
A26: 18 | B26: ADUGBA RICHARD TERSEER | C26: INFORMATION OFFICER | D26: 10(9) | E26: =18281.64 -> 18281.64 | G26: =E26*300% -> 54844.92 | H26: =E26*7.5% -> 1371.123 | J26: =E26*50% -> 9140.82 | K26: =E26*350% -> 63985.74 | L26: =E26*100% -> 18281.64 | N26: =60000 -> 60000 | O26: =E26*10% -> 1828.164 | P26: 10000 | R26: =Q26+P26+O26+N26+M26+L26+K26+J26+I26+H26+G26+F26+E26 -> 237734.05 | T26: =20000 -> 20000 | U26: =111833.33 -> 111833.33 | W26: 3369.51 | X26: =W26+V26+U26+T26+S26 -> 135202.84 | Y26: 102531.21 | Z26: =R26-X26 -> 102531.21
A27: 19 | B27: CHRISTIAN MADUABUCHI ODO | C27: PRINCIPAL ICT OFFICER | D27: 12(7) | E27: =20749 -> 20749 | G27: =E27*300% -> 62247 | H27: =E27*7.5% -> 1556.175 | J27: =E27*50% -> 10374.5 | K27: =E27*350% -> 72621.5 | L27: =E27*100% -> 20749 | N27: =60000 -> 60000 | O27: =E27*10% -> 2074.9 | P27: 15000 | R27: =Q27+P27+O27+N27+M27+L27+K27+J27+I27+H27+G27+F27+E27 -> 265372.07 | T27: =20000 -> 20000 | U27: =82500 -> 82500 | V27: ='[2]Jan 2021'!$H$47 -> 481.92375 | W27: 3369.51 | X27: =W27+V27+U27+T27+S27 -> 106351.43 | Y27: 159020.64 | Z27: =R27-X27 -> 159020.64
A28: 20 | B28: HASSANA AHMED IBRAHIM | C28: PA- TO DG | D28: 10(8) | E28: =17784 -> 17784 | G28: =E28*300% -> 53352 | H28: =E28*7.5% -> 1333.8 | J28: =E28*50% -> 8892 | K28: =E28*350% -> 62244 | L28: =E28*100% -> 17784 | M28: =100000 -> 100000 | O28: =E28*10% -> 1778.4 | P28: 10000 | Q28: =100000 -> 100000 | R28: =Q28+P28+O28+N28+M28+L28+K28+J28+I28+H28+G28+F28+E28 -> 373168.2 | T28: =30000 -> 30000 | V28: ='[2]Jan 2021'!$H$55 -> 444.6 | W28: 3369.51 | X28: =W28+V28+U28+T28+S28 -> 33814.11 | Y28: 339354.09 | Z28: =R28-X28 -> 339354.09
A29: 21 | B29: VICTOR ASUKWO | C29: ICT OFFICER | D29: 8 (9) | E29: =13112.16 -> 13112.16 | G29: =E29*300% -> 39336.48 | H29: =E29*7.5% -> 983.412 | J29: =E29*50% -> 6556.08 | K29: =E29*350% -> 45892.56 | L29: =E29*100% -> 13112.16 | N29: =50000 -> 50000 | O29: =E29*10% -> 1311.216 | P29: 10000 | R29: =Q29+P29+O29+N29+M29+L29+K29+J29+I29+H29+G29+F29+E29 -> 180304.07 | W29: 1484.37 | X29: =W29+V29+U29+T29+S29 -> 1484.37 | Y29: 178819.7 | Z29: =R29-X29 -> 178819.7
A30: 22 | B30: SULEIMAN ABUBAKAR SODEEQ | C30: ASST. ADMIN. OFFICER | D30: 8(7) | E30: =12351.94 -> 12351.94 | G30: =E30*300% -> 37055.82 | H30: =E30*7.5% -> 926.3955 | J30: =E30*50% -> 6175.97 | K30: =E30*350% -> 43231.79 | L30: =E30*100% -> 12351.94 | N30: =50000 -> 50000 | O30: =E30*10% -> 1235.194 | P30: 10000 | R30: =Q30+P30+O30+N30+M30+L30+K30+J30+I30+H30+G30+F30+E30 -> 173329.05 | W30: =1484.37 -> 1484.37 | X30: =W30+V30+U30+T30+S30 -> 1484.37 | Y30: 171844.68 | Z30: =R30-X30 -> 171844.68
A31: 23 | B31: YAKUB OLUWATOYIN USMAN | C31: ASST. ADMIN. OFFICER | D31: 10(7) | E31: =17286.33 -> 17286.33 | G31: =E31*300% -> 51858.99 | H31: =E31*7.5% -> 1296.4748 | J31: =E31*50% -> 8643.165 | K31: =E31*350% -> 60502.155 | L31: =E31*100% -> 17286.33 | N31: =60000 -> 60000 | O31: =E31*10% -> 1728.633 | P31: 10000 | R31: =Q31+P31+O31+N31+M31+L31+K31+J31+I31+H31+G31+F31+E31 -> 228602.08 | T31: =10000 -> 10000 | U31: =34333.33 -> 34333.33 | W31: =1484.37 -> 1484.37 | X31: =W31+V31+U31+T31+S31 -> 45817.7 | Y31: 182784.38 | Z31: =R31-X31 -> 182784.38
A32: 24 | B32: ANTHONY EDET | C32: ASST. MGR M&E | D32: 13(8) | E32: =23891.12 -> 23891.12 | G32: =E32*300% -> 71673.36 | H32: =E32*7.5% -> 1791.834 | I32: 0 | J32: =E32*50% -> 11945.56 | K32: =E32*350% -> 83618.92 | L32: =E32*100% -> 23891.12 | N32: =70000 -> 70000 | O32: =E32*10% -> 2389.112 | P32: 15000 | Q32: 0 | R32: =Q32+P32+O32+N32+M32+L32+K32+J32+I32+H32+G32+F32+E32 -> 304201.03 | T32: 20000 | U32: =68750 -> 68750 | V32: ='[2]Jan 2021'!$H$39 -> 597.278 | W32: =7709.76 -> 7709.76 | X32: =W32+V32+U32+T32+S32 -> 97057.038 | Y32: 207143.99 | Z32: =R32-X32 -> 207143.99
A33: 25 | B33: EGUATU U. ONYEJELEM | C33: OFFICER M&E | D33: 10(9) | E33: =18281.64 -> 18281.64 | G33: =E33*300% -> 54844.92 | H33: =E33*7.5% -> 1371.123 | J33: =E33*50% -> 9140.82 | K33: =E33*350% -> 63985.74 | L33: =E33*100% -> 18281.64 | N33: =60000 -> 60000 | O33: =E33*10% -> 1828.164 | P33: 10000 | R33: =Q33+P33+O33+N33+M33+L33+K33+J33+I33+H33+G33+F33+E33 -> 237734.05 | T33: =20000 -> 20000 | U33: =87500+43750 -> 131250 | W33: 3369.51 | X33: =W33+V33+U33+T33+S33 -> 154619.51 | Y33: 83114.537 | Z33: =R33-X33 -> 83114.537
A34: 26 | B34: ODEH SUZIE | C34: ADMIN. OFFICER, LIASION OFFICE | D34: 10(8) | E34: =17784 -> 17784 | G34: =E34*300% -> 53352 | H34: =E34*7.5% -> 1333.8 | J34: =E34*50% -> 8892 | K34: =E34*350% -> 62244 | L34: =E34*100% -> 17784 | N34: 60000 | O34: =E34*10% -> 1778.4 | P34: 10000 | R34: =Q34+P34+O34+N34+M34+L34+K34+J34+I34+H34+G34+F34+E34 -> 233168.2 | T34: =30000 -> 30000 | V34: =0 -> 0 | W34: 3369.51 | X34: =W34+V34+U34+T34+S34 -> 33369.51 | Y34: 199798.69 | Z34: =R34-X34 -> 199798.69
A35: 27 | B35: IJEOMA NKOLIKWA | C35: ASSISTANT STORES OFFICER | D35: 8(9) | E35: =13112.16 -> 13112.16 | G35: =E35*300% -> 39336.48 | H35: =E35*7.5% -> 983.412 | J35: =E35*50% -> 6556.08 | K35: =E35*350% -> 45892.56 | L35: =E35*100% -> 13112.16 | N35: =50000 -> 50000 | O35: =E35*10% -> 1311.216 | P35: 10000 | R35: =SUM(E35:Q35) -> 180304.07 | T35: =10000 -> 10000 | W35: 1484.37 | X35: =W35+V35+U35+T35+S35 -> 11484.37 | Y35: 168819.7 | Z35: =R35-X35 -> 168819.7
A36: 28 | B36: ABDULRAHMAN A SULAIMAN | C36: ASSISTANT STORES OFFICER | D36: 8 (8) | E36: =12732 -> 12732 | G36: =E36*300% -> 38196 | H36: =E36*7.5% -> 954.9 | J36: =E36*50% -> 6366 | K36: =E36*350% -> 44562 | L36: =E36*100% -> 12732 | N36: =50000 -> 50000 | O36: =E36*10% -> 1273.2 | P36: 10000 | R36: =SUM(E36:Q36) -> 176816.1 | T36: =20000 -> 20000 | U36: =10000 -> 10000 | W36: =(1484.37) -> 1484.37 | X36: =W36+V36+U36+T36+S36 -> 31484.37 | Y36: 145331.73 | Z36: =R36-X36 -> 145331.73
A37: 29 | B37: TASSNEEM IBRAHIM | C37: ASSIST. INFORMATION | D37: 8(8) | E37: =12732 -> 12732 | G37: =E37*300% -> 38196 | H37: =E37*7.5% -> 954.9 | J37: =E37*50% -> 6366 | K37: =E37*350% -> 44562 | L37: =E37*100% -> 12732 | N37: =50000 -> 50000 | O37: =E37*10% -> 1273.2 | P37: 10000 | R37: =Q37+P37+O37+N37+M37+L37+K37+J37+I37+H37+G37+F37+E37 -> 176816.1 | T37: =50000 -> 50000 | U37: =17166.67 -> 17166.67 | V37: =0 -> 0 | W37: =1484.37 -> 1484.37 | X37: =W37+V37+U37+T37+S37 -> 68651.04 | Y37: 108165.06 | Z37: =R37-X37 -> 108165.06
A38: 30 | B38: JIMOH ADEBAYO ZAKA | C38: ASST. OFFICER/COMM | D38: 8(7) | E38: =12351.94 -> 12351.94 | G38: =E38*300% -> 37055.82 | H38: =E38*7.5% -> 926.3955 | J38: =E38*50% -> 6175.97 | K38: =E38*350% -> 43231.79 | L38: =E38*100% -> 12351.94 | N38: =50000 -> 50000 | O38: =E38*10% -> 1235.194 | P38: 10000 | R38: =Q38+P38+O38+N38+M38+L38+K38+J38+I38+H38+G38+F38+E38 -> 173329.05 | T38: =50000 -> 50000 | V38: =0 -> 0 | W38: =1484.37 -> 1484.37 | X38: =W38+V38+U38+T38+S38 -> 51484.37 | Y38: 121844.68 | Z38: =R38-X38 -> 121844.68
B39: TOTAL | C39: 30 | E39: =SUM(E9:E38) -> 928174.74 | F39: =SUM(F9:F38) -> 0 | G39: =SUM(G9:G38) -> 2624035.5 | H39: =SUM(H9:H38) -> 105723.08 | I39: =SUM(I9:I38) -> 561710.66 | J39: =SUM(J9:J38) -> 456062.93 | K39: =SUM(K9:K38) -> 2686901 | L39: =SUM(L9:L38) -> 888052.56 | ... R39: =SUM(R9:R38) -> 12388713 | T39: =SUM(T9:T38) -> 785000 | U39: =SUM(U9:U38) -> 1447690.1 | V39: =SUM(V9:V38) -> 8536.986 | W39: =SUM(W9:W38) -> 411374.07 | X39: =SUM(X9:X38) -> 2652601.2 | Y39: 9736111.7 | Z39: =SUM(Z9:Z38) -> 9736111.7
B41: INTERNAL AUDIT
A42: 1 | B42: OSANAIYE DAVID AKINYEMI | C42: DIRECTOR INTERNAL AUDIT | D42: 17(7) | E42: =76339.3 -> 76339.3 | G42: =E42*300% -> 229017.9 | H42: =E42*7.5% -> 5725.4475 | I42: 80244.38 | J42: =E42*50% -> 38169.65 | K42: =E42*350% -> 267187.55 | L42: =E42*100% -> 76339.3 | N42: =100000 -> 100000 | O42: =E42*10% -> 7633.93 | P42: 20000 | R42: =SUM(E42:Q42) -> 900657.46 | W42: =(52776.63) -> 52776.63 | X42: =W42+V42+U42+T42+S42 -> 52776.63 | Y42: 847880.83 | Z42: =R42-X42 -> 847880.83
C43: 1 | E43: =SUM(E42:E42) -> 76339.3 | F43: =SUM(F42:F42) -> 0 | G43: =SUM(G42:G42) -> 229017.9 | H43: =SUM(H42:H42) -> 5725.4475 | I43: =SUM(I42:I42) -> 80244.38 | J43: =SUM(J42:J42) -> 38169.65 | K43: =SUM(K42:K42) -> 267187.55 | L43: =SUM(L42:L42) -> 76339.3 | N43: =SUM(N42:N42) -> 100000 | O43: =SUM(O42:O42) -> 7633.93 | P43: =SUM(P42:P42) -> 20000 | Q43: =SUM(Q42:Q42) -> 0 | R43: =SUM(R42:R42) -> 900657.46 | T43: =SUM(T42:T42) -> 0 | U43: =SUM(U42:U42) -> 0 | V43: =SUM(V42:V42) -> 0 | W43: =SUM(W42:W42) -> 52776.63 | X43: =SUM(X42:X42) -> 52776.63 | Y43: 847880.83 | Z43: =SUM(Z42:Z42) -> 847880.83
...

Sheet MEMO1
A2: NATIONAL INSTITUTE FOR LEGISLATIVE AND DEMOCRATIC STUDIES
B3: INTERNAL MEMO
A4: INTERNAL MEMO
A6: FROM : DEPUTY DIRECTOR, FINANCE AND ACCOUNTS
A7: THRU: DIRECTOR, FINANCE AND ACCOUNTS
A8: TO: DG
A9: 29TH JANUARY , 2021
A11: SUBJECT: PAYROLL FOR THE MONTH OF JANUARY, 2021
A12: Find below the details of NILDS Staff Payroll for the month of January, 2021
A14: TO: | C14: DIRECTOR, GENERAL
A15: THRU: | C15: DIRECTOR, FINANCE AND ACCOUNT
A16: FROM: | C16: DEPUTY DIRECTOR, FINANCE AND ACCOUNTS
A17: DATE: | C17: 13TH DECEMBER, 2021
A18: SUBJECT: PAYROLL FOR THE MONTH OF DECEMBER, 2021
A19: Find below the details of NILDS Staff Payroll for the month of December, 2021
A20: GROSS SALARY FOR DECEMBER, 2021 | H20: ='December, 2021'!R188 -> 51639317
A21: DEDUCTIONS
A22: COOP SOCIETY DEDUCTIONS | G22: ='December, 2021'!T188 -> 4849500
A23: COOP LOAN RECOVERY | G23: ='December, 2021'!U188 -> 6686064
A24: PAYE DEDUCTIONS | G24: ='December, 2021'!W188 -> 1514721.3
A25: NHF DEDUCTIONS | G25: ='December, 2021'!V188 -> 26068.025
A26: TOTAL DEDUCTIONS FOR DECEMBER, 2021 | H26: =G22+G23+G24+G25 -> 13076353
A27: NET PAY AS PER DECEMBER, 2021 PAYROLL | H27: =H20-H26 -> 38562964
A28: NET PAY AS PER NOVEMBER, 2021 PAYROLL | H28: ='December, 2021'!Y188 -> 39568935
A29: NET INCREASE/ (DECREASE) IN PAY FOR DECEMBER, 2021 | H29: =H27-H28-1.08 -> -1005971.7
A30: ANALYSED AS FOLLOWS:
A31: Effect of Cooperative adjustment for December 2021 | H31: =143971.73+22000 -> 165971.73
A32: Effect of removal of 1st 28 days to Sunday Adeyi and 2 other drivers (Tanimu & Abdullahi) in November, 2021 | H32: =280000*3 -> 840000
H33: =SUM(H31:H32) -> 1005971.7
E34: NOVEMBER, 2021 | G34: DECEMBER, 2021
E35: No. of Staff | F35: N | G35: No. of Staff | H35: N
A36: 1 | B36: Director General's Office | E36: 30 | F36: ='December, 2021'!Y39 -> 9736111.7 | G36: 30 | H36: ='December, 2021'!Z39 -> 9736111.7
A37: 2 | B37: Internal Audit | E37: 2 | F37: ='December, 2021'!Y43 -> 847880.83 | G37: 1 | H37: ='December, 2021'!Z43 -> 847880.83
A38: 3 | B38: Legis. Support Services | E38: 10 | F38: ='December, 2021'!Y56 -> 3633581.8 | G38: 10 | H38: ='December, 2021'!Z56 -> 3581081.8
A39: 4 | B39: Legal Services | E39: 2 | F39: ='December, 2021'!Y61 -> 1261604.2 | G39: 2 | H39: ='December, 2021'!Z61 -> 1261604.2
A40: 5 | B40: Democracy and Governance | E40: 12 | F40: ='December, 2021'!Y76 -> 3066776.8 | G40: 12 | H40: ='December, 2021'!Z76 -> 3098276.8
A41: 6 | B41: Studies | E41: =7 -> 7 | F41: ='December, 2021'!Y86 -> 2634412.2 | G41: =7 -> 7 | H41: ='December, 2021'!Z86 -> 2634412.2
A42: 7 | B42: Economic Dev. & Social Research | E42: 10 | F42: ='December, 2021'!Y99 -> 3316165.3 | G42: 10 | H42: ='December, 2021'!Z99 -> 3230332
A43: 8 | B43: Training & International | E43: 4 | F43: ='December, 2021'!Y106 -> 1264822 | G43: 4 | H43: ='December, 2021'!Z106 -> 1264822
A44: 9 | B44: Library & Documentation | E44: 8 | F44: ='December, 2021'!Y117 -> 2497780.6 | G44: 8 | H44: ='December, 2021'!Z117 -> 2497780.6
...

Sheet 13 month
B3: SCHEDULE OF 13TH MONTH SALARY FOR 3 STAFF FOR YEAR, 2021
F4: ='[1]FEB 08'!E8/'[1]FEB 08'!M8 -> 0.22 | I4: ='[1]FEB 08'!F8/'[1]FEB 08'!Q8 -> 0.3
B5: STAFF NAME | U5: DEDUCTIONS
D6: DESIGNATION | E6: SALARY | F6: BASIC | M6: MOTOR/ | N6: RESEARCH | O6: HARDSHIP | P6: LEAVE | Q6: OUT FIT | R6: LEGISLATIVE | S6: GROSS | Z6: NOVEMBER,2021 | AA6: N
E7: LEVEL | F7: SALARY | G7: SALARY/ALLOWCE AREARS | H7: RENT | I7: UTILITY | J7: DOMESTIC | K7: ENTERT. | L7: FURNIT. | M7: FUEL | N7: ALLOWANCE | O7: ALLOWANCE | P7: ALLCE | Q7: ALLCE | R7: DUTY ALLCE | S7: SALARY | T7: AUCTION | U7: COOP SOCIETY | V7: COOP. LOAN RECOVERY | W7: NHF DEDUCTION | X7: PAYE | Y7: TOTAL
A8: S/N | B8: DG OFFICE | F8: N | I8: N | S8: N | X8: N
B9: LEG. SUPPORT SEVICES
A10: 1 | B10: BETHEL UZOMA IHUGBA | D10: SNR RESEARCH FELLOW | E10: 15(9) | F10: =33507.5 -> 33507.5 | H10: =F10*300% -> 100522.5 | I10: =F10*7.5% -> 2513.0625 | J10: 40122.19 | K10: =F10*50% -> 16753.75 | L10: =F10*350% -> 117276.25 | M10: =F10*100% -> 33507.5 | N10: =160000 -> 160000 | P10: =F10*10% -> 3350.75 | Q10: 20000 | S10: =SUM(F10:R10) -> 527553.5 | Y10: =X10+W10+V10+U10+T10 -> 0 | Z10: 162099.21 | AA10: =S10-Y10 -> 527553.5
B11: TOTAL | D11: 1 | F11: =SUM(F10:F10) -> 33507.5 | G11: =SUM(G10:G10) -> 0 | H11: =SUM(H10:H10) -> 100522.5 | I11: =SUM(I10:I10) -> 2513.0625 | J11: =SUM(J10:J10) -> 40122.19 | K11: =SUM(K10:K10) -> 16753.75 | L11: =SUM(L10:L10) -> 117276.25 | M11: =SUM(M10:M10) -> 33507.5 | N11: =SUM(N10:N10) -> 160000 | P11: =SUM(P10:P10) -> 3350.75 | Q11: =SUM(Q10:Q10) -> 20000 | R11: =SUM(R10:R10) -> 0 | S11: =SUM(S10:S10) -> 527553.5 | W11: =SUM(W10:W10) -> 0 | Y11: =SUM(Y10:Y10) -> 0 | Z11: 3633581.8 | AA11: =SUM(AA10:AA10) -> 527553.5
B13: FINANCE & ACCOUNT
A14: 2 | B14: TONDO IORWUESE EDWARD | D14: ASST. DIRECTOR, ACCOUNTS | E14: 15(8) | F14: =32263.2 -> 32263.2 | H14: =F14*300% -> 96789.6 | I14: =F14*7.5% -> 2419.74 | J14: =40122.19 -> 40122.19 | K14: =F14*50% -> 16131.6 | L14: =F14*350% -> 112921.2 | M14: =F14*100% -> 32263.2 | O14: =80000 -> 80000 | P14: =F14*10% -> 3226.32 | Q14: 20000 | R14: =100000 -> 100000 | S14: =SUM(F14:R14) -> 536137.05 | Y14: =X14+W14+V14+U14+T14 -> 0 | Z14: 339782.14 | AA14: =S14-Y14 -> 536137.05
B15: TOTAL | D15: 1 | F15: =SUM(F14:F14) -> 32263.2 | H15: =SUM(H14:H14) -> 96789.6 | I15: =SUM(I14:I14) -> 2419.74 | J15: =SUM(J14:J14) -> 40122.19 | K15: =SUM(K14:K14) -> 16131.6 | L15: =SUM(L14:L14) -> 112921.2 | M15: =SUM(M14:M14) -> 32263.2 | O15: =SUM(O14:O14) -> 80000 | P15: =SUM(P14:P14) -> 3226.32 | Q15: =SUM(Q14:Q14) -> 20000 | R15: =SUM(R14:R14) -> 100000 | S15: =SUM(S14:S14) -> 536137.05 | Y15: =SUM(Y14:Y14) -> 0 | Z15: 2792106.4 | AA15: =SUM(AA14:AA14) -> 536137.05
B17: ADMINISTRATION & HUMAN RESOURCE
A18: 3 | B18: SALAMATU YAKUBU | D18: CHIEF ADMIN OFFICER | E18: 14(8) | F18: =25854.1 -> 25854.1 | H18: =F18*300% -> 77562.3 | I18: =F18*7.5% -> 1939.0575 | J18: 0 | K18: =F18*50% -> 12927.05 | L18: =F18*350% -> 90489.35 | M18: =F18*100% -> 25854.1 | O18: 70000 | P18: =F18*10% -> 2585.41 | Q18: 20000 | R18: 0 | S18: =SUM(F18:R18) -> 327211.37 | Y18: =X18+W18+V18+U18+T18 -> 0 | Z18: 185530.19 | AA18: =S18-Y18 -> 327211.37
B19: TOTAL | D19: 1 | F19: =SUM(F18:F18) -> 25854.1 | G19: =SUM(G18:G18) -> 0 | H19: =SUM(H18:H18) -> 77562.3 | I19: =SUM(I18:I18) -> 1939.0575 | J19: =SUM(J18:J18) -> 0 | K19: =SUM(K18:K18) -> 12927.05 | L19: =SUM(L18:L18) -> 90489.35 | M19: =SUM(M18:M18) -> 25854.1 | O19: =SUM(O18:O18) -> 70000 | P19: =SUM(P18:P18) -> 2585.41 | Q19: =SUM(Q18:Q18) -> 20000 | R19: =SUM(R18:R18) -> 0 | S19: =SUM(S18:S18) -> 327211.37 | U19: =SUM(U18:U18) -> 0 | V19: =SUM(V18:V18) -> 0 | Y19: =SUM(Y18:Y18) -> 0 | Z19: 8517692.7 | AA19: =SUM(AA18:AA18) -> 327211.37
B20: GRAND TOTAL | D20: 3 | F20: =SUM(F19,F15,F11) -> 91624.8 | G20: =SUM(G19,G11) -> 0 | H20: =SUM(H19,H15,H11) -> 274874.4 | I20: =SUM(I19,I15,I11) -> 6871.86 | J20: =SUM(J19,J15,J11) -> 80244.38 | K20: =SUM(K19,K15,K11) -> 45812.4 | L20: =SUM(L19,L15,L11) -> 320686.8 | M20: =SUM(M19,M15,M11) -> 91624.8 | N20: =SUM(N11) -> 160000 | O20: =SUM(O19,O15) -> 150000 | P20: =SUM(P19,P15,P11) -> 9162.48 | Q20: =SUM(Q19,Q15,Q11) -> 60000 | R20: =SUM(R19,R15,R11) -> 100000 | S20: =SUM(S19,S15,S11) -> 1390901.9 | U20: =SUM(U19,U15,U11) -> 0 | V20: =SUM(V19,V15,V11) -> 0 | W20: =SUM(W19,W15,W11) -> 0 | X20: =SUM(X19,X15,X11) -> 0 | Y20: =SUM(Y19,Y15,Y11) -> 0 | Z20: =SUM(Z10:Z19) -> 15630792 | AA20: =SUM(AA19,AA15,AA11) -> 1390901.9
K22: SIGNATURE | P22: DATE

Sheet Sheet3
A2: Research /Hardshi allowances
A4: 1 | B4: Fajingbesi | C4: =100000 -> 100000
A5: 2 | B5: Joy | C5: 50000
A6: 3 | B6: Maryam | C6: 100000
A7: 4 | B7: Terfa Gbahabo | C7: =50000 -> 50000
A8: 5 | B8: Hassana | C8: =140000 -> 140000
A9: 6 | B9: Yakub | C9: =10000 -> 10000
C10: =SUM(C4:C9) -> 450000
B11: Arears
A12: 1 | B12: Yakub | C12: =45283 -> 45283
A13: 2 | B13: Abdullahi | C13: =35436 -> 35436
C14: =SUM(C11:C13) -> 80719
B16: Late Staff
B17: Bashir Auwal | C17: =33074.51 -> 33074.51
B18: Chukwuka Edmond | C18: =148722.77 -> 148722.77
C19: =SUM(C17:C18) -> 181797.28
B21: Dr. Eze
B22: Director Salary | C22: =925433.08 -> 925433.08
B23: DD | C23: =451465+90000 -> 541465
B24: DIFF. | C24: =C22-C23 -> 383968.08
B25: Portion for 12 days | C25: =C24*12/31 -> 148632.81

Sheet Promotion
B3: STAFF PAYROLL FOR THE MONTH OF SEPTEMBER, 2021
F4: ='[1]FEB 08'!E8/'[1]FEB 08'!M8 -> 0.22 | I4: ='[1]FEB 08'!F8/'[1]FEB 08'!Q8 -> 0.3
B5: EFFECT OF PROMOTION | U5: DEDUCTIONS | AA5: NET SALARY
D6: DESIGNATION | E6: OLD SALARY | F6: BASIC | M6: MOTOR/ | N6: RESEARCH | O6: HARDSHIP | P6: LEAVE | Q6: OUT FIT | R6: LEGISLATIVE | S6: OLD GROSS | Z6: AUGUST,2021 | AA6: SEPTEMBER,2021 | AB6: NEW SALARY | AC6: NEWGROSS
E7: LEVEL | F7: SALARY | G7: SALARY/ALLOWCE AREARS | H7: RENT | I7: UTILITY | J7: DOMESTIC | K7: ENTERT. | L7: FURNIT. | M7: FUEL | N7: ALLOWANCE | O7: ALLOWANCE | P7: ALLCE | Q7: ALLCE | R7: DUTY ALLCE | S7: SALARY | T7: AUCTION | U7: COOP SOCIETY | V7: COOP. LOAN RECOVERY | W7: NHF DEDUCTION | X7: PAYE | Y7: TOTAL | AB7: GRADE LEVEL | AC7: SALARY | AD7: DIFFERENCE | AE7: AREARS FOR AUGUST | AF7: TOTAL DIFFERENCE | AG7: OLD PAYE | AH7: NEW PAYE | AI7: DIFF
A8: S/N | B8: DG OFFICE | F8: N | I8: N | S8: N | X8: N
A9: 1 | B9: HUSSEIN EGYE MUSA | D9: AM PROTOCOL | E9: 13(10) | F9: =25523.45 -> 25523.45 | H9: =F9*300% -> 76570.35 | I9: =F9*7.5% -> 1914.2587 | K9: =F9*50% -> 12761.725 | L9: =F9*350% -> 89332.075 | M9: =F9*100% -> 25523.45 | O9: =70000 -> 70000 | P9: =F9*10% -> 2552.345 | Q9: 15000 | R9: 50000 | S9: =R9+Q9+P9+O9+N9+M9+L9+K9+J9+I9+H9+G9+F9 -> 369177.65 | U9: 50000 | V9: =150000 -> 150000 | W9: 0 | X9: 7709.76 | Y9: =X9+W9+V9+U9+T9 -> 207709.76 | Z9: 160467.89 | AA9: =S9-Y9 -> 161467.89 | AB9: 14 (8) | AC9: =257211+70000+50000 -> 377211 | AD9: =AC9-S9 -> 8033.3463 | AE9: =23/31*AD9 -> 5960.2246 | AF9: =AD9+AE9 -> 13993.571 | AG9: 7709.76 | AH9: 7709.76 | AI9: =AH9-AG9 -> 0 | AK9: =AC9+AE9 -> 383171.22
A10: 2 | B10: DONALD E. MKPANAM | D10: AM ICT | E10: 13(11) | F10: 26339.3 | H10: =F10*300% -> 79017.9 | I10: =F10*7.5% -> 1975.4475 | K10: =F10*50% -> 13169.65 | L10: =F10*350% -> 92187.55 | M10: =F10*100% -> 26339.3 | O10: =70000 -> 70000 | P10: =F10*10% -> 2633.93 | Q10: 15000 | R10: 0 | S10: =R10+Q10+P10+O10+N10+M10+L10+K10+J10+I10+H10+G10+F10 -> 326663.08 | W10: ='[2]Jan 2021'!$H$28 -> 658.4825 | X10: 7709.76 | Y10: =X10+W10+V10+U10+T10 -> 8368.2425 | Z10: 318294.83 | AA10: =S10-Y10 -> 318294.83 | AB10: 14 (8) | AC10: =257211+70000 -> 327211 | AD10: =AC10-S10 -> 547.9225 | AE10: =23/31*AD10 -> 406.52315 | AF10: =AD10+AE10 -> 954.44565 | AG10: 7709.76 | AH10: 7709.76 | AI10: =AH10-AG10 -> 0 | AK10: =AC10+AE10 -> 327617.52
A11: 3 | B11: JOY HARUNA MAKERI | D11: AM TRAINING | E11: 13(10) | F11: =25523.45 -> 25523.45 | H11: =F11*300% -> 76570.35 | I11: =F11*7.5% -> 1914.2587 | K11: =F11*50% -> 12761.725 | L11: =F11*350% -> 89332.075 | M11: =F11*100% -> 25523.45 | N11: =120000 -> 120000 | P11: =F11*10% -> 2552.345 | Q11: 15000 | R11: =50000+100000 -> 150000 | S11: =R11+Q11+P11+O11+N11+M11+L11+K11+J11+I11+H11+G11+F11 -> 519177.65 | X11: =7709.76 -> 7709.76 | Y11: =X11+W11+V11+U11+T11 -> 7709.76 | Z11: 546467.89 | AA11: =S11-Y11 -> 511467.89 | AB11: 14 (8) | AC11: =257211+140000+150000 -> 547211 | AD11: =AC11-S11 -> 28033.346 | AE11: =23/31*AD11 -> 20798.934 | AF11: =AD11+AE11 -> 48832.281 | AG11: 7709.76 | AH11: 7709.76 | AI11: =AH11-AG11 -> 0
A12: 4 | B12: CHRISTIAN MADUABUCHI ODO | D12: ICT OFFICER | E12: 10(11) | S12: 246866.02 | AB12: 12(7) | AC12: =205372+60000 -> 265372 | AD12: =AC12-S12 -> 18505.984 | AE12: =23/31*AD12 -> 13730.246 | AF12: =AD12+AE12 -> 32236.23 | AG12: =3369.51 -> 3369.51 | AH12: =3369.51 -> 3369.51 | AI12: =AH12-AG12 -> 0
B13: TOTAL | D13: 4 | F13: =SUM(F9:F11) -> 77386.2 | G13: =SUM(G9:G11) -> 0 | H13: =SUM(H9:H11) -> 232158.6 | I13: =SUM(I9:I11) -> 5803.965 | J13: =SUM(J9:J11) -> 0 | K13: =SUM(K9:K11) -> 38693.1 | L13: =SUM(L9:L11) -> 270851.7 | M13: =SUM(M9:M11) -> 77386.2 | ... S13: =SUM(S9:S11) -> 1215018.4 | U13: =SUM(U9:U11) -> 50000 | V13: =SUM(V9:V11) -> 150000 | W13: =SUM(W9:W11) -> 658.4825 | X13: =SUM(X9:X11) -> 23129.28 | Y13: =SUM(Y9:Y11) -> 223787.76 | Z13: 9309597.9 | AA13: =SUM(AA9:AA11) -> 991230.62 | AC13: =SUM(AC9:AC12) -> 1517005 | AD13: =SUM(AD9:AD12) -> 55120.599 | AE13: =SUM(AE9:AE12) -> 40895.928 | AF13: =SUM(AF9:AF12) -> 96016.527 | AG13: =SUM(AG9:AG12) -> 26498.79 | AH13: =SUM(AH9:AH12) -> 26498.79 | AI13: =SUM(AI9:AI12) -> 0
B15: INTERNAL AUDIT
C16: TOTAL | F16: =SUM(#REF!) -> #REF! | H16: =SUM(#REF!) -> #REF! | I16: =SUM(#REF!) -> #REF! | J16: =SUM(#REF!) -> #REF! | K16: =SUM(#REF!) -> #REF! | L16: =SUM(#REF!) -> #REF! | M16: =SUM(#REF!) -> #REF! | N16: =SUM(#REF!) -> #REF! | O16: =SUM(#REF!) -> #REF! | P16: =SUM(#REF!) -> #REF! | U16: =SUM(#REF!) -> #REF! | V16: =SUM(#REF!) -> #REF! | W16: =SUM(#REF!) -> #REF! | X16: =SUM(#REF!) -> #REF! | Y16: =SUM(#REF!) -> #REF! | Z16: 478180.46 | AA16: =SUM(#REF!) -> #REF!
B17: LEG. SUPPORT SEVICES
A18: 1 | B18: OGUCHE SAMUEL | D18: RESEARCH FELLOW I | E18: 14(11) | F18: 28489.81 | H18: =F18*300% -> 85469.43 | I18: =F18*7.5% -> 2136.7357 | K18: =F18*50% -> 14244.905 | L18: =F18*350% -> 99714.335 | M18: =F18*100% -> 28489.81 | N18: =140000 -> 140000 | P18: =F18*10% -> 2848.981 | Q18: 20000 | S18: =SUM(F18:R18) -> 421394.01 | U18: =30000 -> 30000 | V18: =0 -> 0 | X18: 7709.76 | Y18: =X18+W18+V18+U18+T18 -> 37709.76 | Z18: 383684.25 | AA18: =S18-Y18 -> 383684.25 | AB18: 15(7) | AC18: =344720+160000 -> 504720 | AD18: =AC18-S18 -> 83325.993 | AE18: =23/31*AD18 -> 61822.511 | AF18: =AE18+AD18 -> 145148.5 | AG18: 7709.76 | AH18: 15548.33 | AI18: =AH18-AG18 -> 7838.57
A19: 2 | B19: YAHAYA SHAMSU | D19: RESEARCH FELLOW 11 | E19: 13(11) | F19: =26339.3 -> 26339.3 | H19: =F19*300% -> 79017.9 | I19: =F19*7.5% -> 1975.4475 | K19: =F19*50% -> 13169.65 | L19: =F19*350% -> 92187.55 | M19: =F19*100% -> 26339.3 | N19: =120000 -> 120000 | P19: =F19*10% -> 2633.93 | Q19: 15000 | S19: =SUM(F19:R19) -> 376663.08 | W19: 0 | X19: 7709.76 | Y19: =X19+W19+V19+U19+T19 -> 7709.76 | Z19: 368953.32 | AA19: =S19-Y19 -> 368953.32 | AB19: 14(8) | AC19: =257211+140000 -> 397211 | AD19: =AC19-S19 -> 20547.923 | AE19: =23/31*AD19 -> 15245.233 | AF19: =AE19+AD19 -> 35793.155 | AG19: 7709.76 | AH19: 7709.76 | AI19: =AH19-AG19 -> 0
B20: TOTAL | D20: 2 | F20: =SUM(F18:F19) -> 54829.11 | H20: =SUM(H18:H19) -> 164487.33 | I20: =SUM(I18:I19) -> 4112.1833 | J20: =SUM(J18:J19) -> 0 | K20: =SUM(K18:K19) -> 27414.555 | L20: =SUM(L18:L19) -> 191901.89 | M20: =SUM(M18:M19) -> 54829.11 | N20: =SUM(N18:N19) -> 260000 | P20: =SUM(P18:P19) -> 5482.911 | Q20: =SUM(Q18:Q19) -> 35000 | R20: =SUM(R18:R19) -> 0 | S20: =SUM(S18:S19) -> 798057.08 | U20: =SUM(U18:U19) -> 30000 | V20: =SUM(V18:V19) -> 0 | W20: =SUM(W18:W19) -> 0 | X20: =SUM(X18:X19) -> 15419.52 | Y20: =SUM(Y18:Y19) -> 45419.52 | Z20: 3862557.6 | AA20: =SUM(AA18:AA19) -> 752637.56 | AC20: =SUM(AC18:AC19) -> 901931 | AD20: =SUM(AD18:AD19) -> 103873.92 | AE20: =SUM(AE18:AE19) -> 77067.744 | AF20: =SUM(AF18:AF19) -> 180941.66 | AG20: =SUM(AG18:AG19) -> 15419.52 | AH20: =SUM(AH18:AH19) -> 23258.09 | AI20: =SUM(AI18:AI19) -> 7838.57
B22: LEGAL SERVICES
B23: TOTAL | F23: =SUM(#REF!) -> #REF! | H23: =SUM(#REF!) -> #REF! | I23: =SUM(#REF!) -> #REF! | J23: =SUM(#REF!) -> #REF! | K23: =SUM(#REF!) -> #REF! | L23: =SUM(#REF!) -> #REF! | M23: =SUM(#REF!) -> #REF! | N23: =SUM(#REF!) -> #REF! | O23: =SUM(#REF!) -> #REF! | ... R23: =SUM(#REF!) -> #REF! | S23: =0 -> 0 | U23: =SUM(#REF!) -> #REF! | W23: =SUM(#REF!) -> #REF! | X23: =SUM(#REF!) -> #REF! | Y23: =SUM(#REF!) -> #REF! | Z23: 931604.15 | AA23: =SUM(#REF!) -> #REF!
B25: DEMOCRACY AND GOVERNANCE
A26: 1 | B26: YUNUSA ABDULLAHI | D26: RESEARCH FELLOW 11 | E26: 13(11) | F26: =26339.3 -> 26339.3 | H26: =F26*300% -> 79017.9 | I26: =F26*7.5% -> 1975.4475 | K26: =F26*50% -> 13169.65 | L26: =F26*350% -> 92187.55 | M26: =F26*100% -> 26339.3 | N26: =120000 -> 120000 | P26: =F26*10% -> 2633.93 | Q26: 15000 | S26: =SUM(F26:R26) -> 376663.08 | U26: =10000 -> 10000 | V26: =54585.66 -> 54585.66 | X26: =7709.76 -> 7709.76 | Y26: =X26+W26+V26+U26+T26 -> 72295.42 | Z26: 303367.66 | AA26: =S26-Y26 -> 304367.66 | AB26: 14(8) | AC26: =257211+140000 -> 397211 | AD26: =AC26-S26 -> 20547.923 | AE26: =23/31*AD26 -> 15245.233 | AF26: =AE26+AD26 -> 35793.155 | AG26: 7709.76 | AH26: 7709.76 | AI26: =AH26-AG26 -> 0
A27: 2 | B27: OSOLAFIA MUHAMMAD EGYE | D27: RESEARCH OFFICER | E27: 10(11) | F27: =19276.95 -> 19276.95 | H27: =F27*300% -> 57830.85 | I27: =F27*7.5% -> 1445.7713 | J27: 0 | K27: =F27*50% -> 9638.475 | L27: =F27*350% -> 67469.325 | M27: =F27*100% -> 19276.95 | N27: =100000 -> 100000 | P27: =F27*10% -> 1927.695 | Q27: 10000 | R27: 0 | S27: =SUM(F27:R27) -> 286866.02 | U27: =20000 -> 20000 | V27: =100000 -> 100000 | W27: ='[2]Jan 2021'!$H$43 -> 481.92375 | X27: =3369.51 -> 3369.51 | Y27: =X27+W27+V27+U27+T27 -> 123851.43 | Z27: 163014.58 | AA27: =S27-Y27 -> 163014.58 | AB27: 12(7) | AC27: =205372+110000 -> 315372 | AD27: =AC27-S27 -> 28505.984 | AE27: =23/31*AD27 -> 21149.601 | AF27: =AE27+AD27 -> 49655.585 | AG27: =3369.51 -> 3369.51 | AH27: =3369.51 -> 3369.51 | AI27: =AH27-AG27 -> 0 | AK27: =AC27+AE27 -> 336521.6
B28: TOTAL | D28: 2 | F28: =SUM(F26:F27) -> 45616.25 | H28: =SUM(H26:H27) -> 136848.75 | I28: =SUM(I26:I27) -> 3421.2188 | J28: =SUM(J26:J27) -> 0 | K28: =SUM(K26:K27) -> 22808.125 | L28: =SUM(L26:L27) -> 159656.88 | M28: =SUM(M26:M27) -> 45616.25 | N28: =SUM(N26:N27) -> 220000 | P28: =SUM(P26:P27) -> 4561.625 | Q28: =SUM(Q26:Q27) -> 25000 | R28: =SUM(R26:R27) -> 0 | S28: =SUM(S26:S27) -> 663529.09 | U28: =SUM(U26:U27) -> 30000 | V28: =SUM(V26:V27) -> 154585.66 | W28: =SUM(W26:W27) -> 481.92375 | X28: =SUM(X26:X27) -> 11079.27 | Y28: =SUM(Y26:Y27) -> 196146.85 | Z28: 3477220.9 | AA28: =SUM(AA26:AA27) -> 467382.24 | AC28: =SUM(AC26:AC27) -> 712583 | AD28: =SUM(AD26:AD27) -> 49053.906 | AE28: =SUM(AE26:AE27) -> 36394.834 | AF28: =SUM(AF26:AF27) -> 85448.74 | AG28: =SUM(AG26:AG27) -> 11079.27 | AH28: =SUM(AH26:AH27) -> 11079.27 | AI28: =SUM(AI26:AI27) -> 0
B30: STUDIES
B31: TOTAL | F31: =SUM(#REF!) -> #REF! | H31: =SUM(#REF!) -> #REF! | I31: =SUM(#REF!) -> #REF! | J31: =SUM(#REF!) -> #REF! | K31: =SUM(#REF!) -> #REF! | L31: =SUM(#REF!) -> #REF! | M31: =SUM(#REF!) -> #REF! | N31: =SUM(#REF!) -> #REF! | P31: =SUM(#REF!) -> #REF! | Q31: =SUM(#REF!) -> #REF! | R31: =SUM(#REF!) -> #REF! | S31: =0 -> 0 | U31: =SUM(#REF!) -> #REF! | V31: =SUM(#REF!) -> #REF! | W31: =SUM(#REF!) -> #REF! | X31: =SUM(#REF!) -> #REF! | Y31: =SUM(#REF!) -> #REF! | Z31: 3200748.9 | AA31: =SUM(#REF!) -> #REF!
B33: ECONOMIC DEV. AND SOCIAL RESEARCH
B34: TOTAL | F34: =SUM(#REF!) -> #REF! | G34: =SUM(#REF!) -> #REF! | H34: =SUM(#REF!) -> #REF! | I34: =SUM(#REF!) -> #REF! | J34: =SUM(#REF!) -> #REF! | K34: =SUM(#REF!) -> #REF! | L34: =SUM(#REF!) -> #REF! | M34: =SUM(#REF!) -> #REF! | N34: =SUM(#REF!) -> #REF! | P34: =SUM(#REF!) -> #REF! | Q34: =SUM(#REF!) -> #REF! | R34: =SUM(#REF!) -> #REF! | S34: =0 -> 0 | U34: =SUM(#REF!) -> #REF! | V34: =SUM(#REF!) -> #REF! | W34: =SUM(#REF!) -> #REF! | X34: =SUM(#REF!) -> #REF! | Y34: =SUM(#REF!) -> #REF! | Z34: 3494235.1 | AA34: =SUM(#REF!) -> #REF!
B36: TRAINING AND INTERNATIONAL COOP
B37: TOTAL | F37: =SUM(#REF!) -> #REF! | H37: =SUM(#REF!) -> #REF! | I37: =SUM(#REF!) -> #REF! | J37: =SUM(#REF!) -> #REF! | K37: =SUM(#REF!) -> #REF! | L37: =SUM(#REF!) -> #REF! | M37: =SUM(#REF!) -> #REF! | N37: =SUM(#REF!) -> #REF! | O37: =SUM(#REF!) -> #REF! | ... R37: =SUM(#REF!) -> #REF! | S37: =0 -> 0 | U37: =SUM(#REF!) -> #REF! | V37: =SUM(#REF!) -> #REF! | W37: =SUM(#REF!) -> #REF! | X37: =SUM(#REF!) -> #REF! | Y37: =SUM(#REF!) -> #REF! | Z37: 547219.79 | AA37: =SUM(#REF!) -> #REF!
B39: LIBRARY AND DOCUMENTATION
B40: TOTAL | F40: =SUM(#REF!) -> #REF! | H40: =SUM(#REF!) -> #REF! | I40: =SUM(#REF!) -> #REF! | J40: =SUM(#REF!) -> #REF! | K40: =SUM(#REF!) -> #REF! | L40: =SUM(#REF!) -> #REF! | M40: =SUM(#REF!) -> #REF! | N40: =SUM(#REF!) -> #REF! | P40: =SUM(#REF!) -> #REF! | Q40: =SUM(#REF!) -> #REF! | R40: =SUM(#REF!) -> #REF! | S40: =0 -> 0 | U40: =SUM(#REF!) -> #REF! | V40: =SUM(#REF!) -> #REF! | W40: =SUM(#REF!) -> #REF! | X40: =SUM(#REF!) -> #REF! | Y40: =SUM(#REF!) -> #REF! | Z40: 2082060.7 | AA40: =SUM(#REF!) -> #REF!
B42: FINANCE & ACCOUNT
B43: TOTAL | F43: =SUM(#REF!) -> #REF! | H43: =SUM(#REF!) -> #REF! | I43: =SUM(#REF!) -> #REF! | J43: =SUM(#REF!) -> #REF! | K43: =SUM(#REF!) -> #REF! | L43: =SUM(#REF!) -> #REF! | M43: =SUM(#REF!) -> #REF! | O43: =SUM(#REF!) -> #REF! | P43: =SUM(#REF!) -> #REF! | Q43: =SUM(#REF!) -> #REF! | R43: =SUM(#REF!) -> #REF! | S43: =0 -> 0 | U43: =SUM(#REF!) -> #REF! | V43: =SUM(#REF!) -> #REF! | W43: =SUM(#REF!) -> #REF! | X43: =SUM(#REF!) -> #REF! | Y43: =SUM(#REF!) -> #REF! | Z43: 2761365 | AA43: =SUM(#REF!) -> #REF!
B45: ADMINISTRATION & HUMAN RESOURCE
A46: 1 | B46: SIMON YAKUBU WAKAWA | D46: ASST. MANAGER , ASSETS & MAINT. | E46: 13(10) | F46: =25523.45 -> 25523.45 | H46: =F46*300% -> 76570.35 | I46: =F46*7.5% -> 1914.2587 | J46: 0 | K46: =F46*50% -> 12761.725 | L46: =F46*350% -> 89332.075 | M46: =F46*100% -> 25523.45 | O46: 70000 | P46: =F46*10% -> 2552.345 | Q46: 15000 | S46: =SUM(F46:R46) -> 319177.65 | U46: 30000 | V46: =52500 -> 52500 | W46: ='[2]Jan 2021'!$H$49 -> 638.08625 | X46: 7709.76 | Y46: =X46+W46+V46+U46+T46 -> 90847.846 | Z46: 223329.81 | AA46: =S46-Y46 -> 228329.81 | AB46: 14 (8) | AC46: =257211+70000 -> 327211 | AD46: =AC46-S46 -> 8033.3463 | AE46: =23/31*AD46 -> 5960.2246 | AF46: =AE46+AD46 -> 13993.571 | AG46: 7709.76 | AH46: 7709.76 | AI46: =AH46-AG46 -> 0
A47: 2 | B47: SALAMATU YAKUBU | D47: PRINCIPAL CONF. SECRETARY | E47: 13(10) | F47: =25523.45 -> 25523.45 | H47: =F47*300% -> 76570.35 | I47: =F47*7.5% -> 1914.2587 | J47: 0 | K47: =F47*50% -> 12761.725 | L47: =F47*350% -> 89332.075 | M47: =F47*100% -> 25523.45 | O47: 70000 | P47: =F47*10% -> 2552.345 | Q47: 15000 | R47: 0 | S47: =SUM(F47:R47) -> 319177.65 | U47: =0 -> 0 | V47: =0 -> 0 | W47: ='[2]Jan 2021'!$H$53 -> 638.08625 | X47: 7709.76 | Y47: =X47+W47+V47+U47+T47 -> 8347.8463 | Z47: 308829.81 | AA47: =S47-Y47 -> 310829.81 | AB47: 14 (8) | AC47: =257211+70000 -> 327211 | AD47: =AC47-S47 -> 8033.3463 | AE47: =23/31*AD47 -> 5960.2246 | AF47: =AE47+AD47 -> 13993.571 | AG47: 7709.76 | AH47: 7709.76 | AI47: =AH47-AG47 -> 0
A48: 3 | B48: USMAN WAZIRI | D48: PRINCIPAL CONF. SECRETARY | E48: 13(10) | F48: =25523.45 -> 25523.45 | H48: =F48*300% -> 76570.35 | I48: =F48*7.5% -> 1914.2587 | J48: 0 | K48: =F48*50% -> 12761.725 | L48: =F48*350% -> 89332.075 | M48: =F48*100% -> 25523.45 | O48: 70000 | P48: =F48*10% -> 2552.345 | Q48: 15000 | R48: 0 | S48: =SUM(F48:R48) -> 319177.65 | U48: =3000 -> 3000 | V48: =50000 -> 50000 | X48: 7709.76 | Y48: =X48+W48+V48+U48+T48 -> 60709.76 | Z48: 258467.89 | AA48: =S48-Y48 -> 258467.89 | AB48: 14 (8) | AC48: =257211+70000 -> 327211 | AD48: =AC48-S48 -> 8033.3463 | AE48: =23/31*AD48 -> 5960.2246 | AF48: =AE48+AD48 -> 13993.571 | AG48: 7709.76 | AH48: 7709.76 | AI48: =AH48-AG48 -> 0
A49: 4 | B49: EROMOSELE OMONIGBO | D49: PERSONNEL OFFICER | E49: 10(11) | F49: =19276.95 -> 19276.95 | H49: =F49*300% -> 57830.85 | I49: =F49*7.5% -> 1445.7713 | J49: 0 | K49: =F49*50% -> 9638.475 | L49: =F49*350% -> 67469.325 | M49: =F49*100% -> 19276.95 | O49: =60000 -> 60000 | P49: =F49*10% -> 1927.695 | Q49: 10000 | R49: 0 | S49: =SUM(F49:R49) -> 246866.02 | U49: 10000 | V49: =0 -> 0 | W49: ='[2]Jan 2021'!$H$41 -> 481.92375 | X49: =3369.51 -> 3369.51 | Y49: =X49+W49+V49+U49+T49 -> 13851.434 | Z49: 233014.58 | AA49: =S49-Y49 -> 233014.58 | AB49: 12(7) | AC49: =205372+60000 -> 265372 | AD49: =AC49-S49 -> 18505.984 | AE49: =23/31*AD49 -> 13730.246 | AF49: =AE49+AD49 -> 32236.23 | AG49: =3369.51 -> 3369.51 | AH49: =3369.51 -> 3369.51 | AI49: =AH49-AG49 -> 0
A50: 5 | B50: OGUNYOMI ROTIMI | D50: PERSONNEL OFFICER | E50: 10(10) | F50: =18779.3 -> 18779.3 | H50: =F50*300% -> 56337.9 | I50: =F50*7.5% -> 1408.4475 | J50: 0 | K50: =F50*50% -> 9389.65 | L50: =F50*350% -> 65727.55 | M50: =F50*100% -> 18779.3 | O50: =60000 -> 60000 | P50: =F50*10% -> 1877.93 | Q50: 10000 | R50: 0 | S50: =SUM(F50:R50) -> 242300.08 | V50: =50000 -> 50000 | X50: 3369.51 | Y50: =X50+W50+V50+U50+T50 -> 53369.51 | Z50: 188930.57 | AA50: =S50-Y50 -> 188930.57 | AB50: 12(7) | AC50: =205372+60000 -> 265372 | AD50: =AC50-S50 -> 23071.923 | AE50: =23/31*AD50 -> 17117.878 | AF50: =AE50+AD50 -> 40189.8 | AG50: =3369.51 -> 3369.51 | AH50: =3369.51 -> 3369.51 | AI50: =AH50-AG50 -> 0
A51: 6 | B51: OMOUDU QUEEN PRISCILLA | D51: SECRETARY | E51: 10(11) | F51: =19276.95 -> 19276.95 | H51: =F51*300% -> 57830.85 | I51: =F51*7.5% -> 1445.7713 | K51: =F51*50% -> 9638.475 | L51: =F51*350% -> 67469.325 | M51: =F51*100% -> 19276.95 | O51: =60000 -> 60000 | P51: =F51*10% -> 1927.695 | Q51: 10000 | S51: =SUM(F51:R51) -> 246866.02 | U51: =20000+10000 -> 30000 | X51: 3369.51 | Y51: =X51+W51+V51+U51+T51 -> 33369.51 | Z51: 213496.51 | AA51: =S51-Y51 -> 213496.51 | AB51: 12(7) | AC51: =205372+60000 -> 265372 | AD51: =AC51-S51 -> 18505.984 | AE51: =23/31*AD51 -> 13730.246 | AF51: =AE51+AD51 -> 32236.23 | AG51: =3369.51 -> 3369.51 | AH51: =3369.51 -> 3369.51 | AI51: =AH51-AG51 -> 0
...

Sheet Library
D2: DESIGNATION | E2: GRADE LEVEL | F2: SALARY | G2: SALARY/ALLOWCE AREARS | H2: RENT | I2: UTILITY | J2: DOMESTIC | K2: ENTERT. | L2: FURNIT. | M2: FUEL | N2: ALLOWANCE | O2: ALLOWANCE | P2: ALLCE | Q2: ALLCE | R2: DUTY ALLCE | S2: GROSS SALARY | T2: AUCTION | U2: COOP SOCIETY | V2: COOP. LOAN RECOVERY | W2: NHF DEDUCTION | X2: PAYE | Y2: TOTAL | AB2: SHIFT DUTY ALLOWANCES (11% of GROSS)
B3: LIBRARY AND DOCUMENTATION
A4: 1 | B4: ALIYU SANNI ABUBAKAR | D4: RESEARCH FELLOW 11 DATA & DOCU | E4: 13(11) | F4: =26339.3 -> 26339.3 | H4: =F4*300% -> 79017.9 | I4: =F4*7.5% -> 1975.4475 | J4: 0 | K4: =F4*50% -> 13169.65 | L4: =F4*350% -> 92187.55 | M4: =F4*100% -> 26339.3 | N4: =120000 -> 120000 | P4: =F4*10% -> 2633.93 | Q4: 15000 | R4: 0 | S4: =SUM(F4:R4) -> 376663.08 | U4: 30000 | V4: =43750 -> 43750 | W4: ='[2]Jan 2021'!$H$36 -> 658.4825 | X4: =7709.76 -> 7709.76 | Y4: =X4+W4+V4+U4+T4 -> 82118.242 | Z4: 294544.83 | AA4: =S4-Y4 -> 294544.83 | AB4: =S4*0.11 -> 41432.939
A5: 2 | B5: CHINAKO N. ASOGWA | D5: RESEARCH FELLOW 11 DATA & DOCU | E5: 13(9) | F5: =24741.26 -> 24741.26 | H5: =F5*300% -> 74223.78 | I5: =F5*7.5% -> 1855.5945 | J5: 0 | K5: =F5*50% -> 12370.63 | L5: =F5*350% -> 86594.41 | M5: =F5*100% -> 24741.26 | N5: =120000 -> 120000 | P5: =F5*10% -> 2474.126 | Q5: 15000 | S5: =SUM(F5:R5) -> 362001.06 | U5: =50000 -> 50000 | V5: =68750+45833.33 -> 114583.33 | X5: =7709.76 -> 7709.76 | Y5: =X5+W5+V5+U5+T5 -> 172293.09 | Z5: 235541.3 | AA5: =S5-Y5 -> 189707.97 | AB5: =S5*0.11 -> 39820.117
A6: 3 | B6: AMOS ABA | D6: LIBRARY ASSISTANT | E6: 8(9) | F6: =13112.16 -> 13112.16 | H6: =F6*300% -> 39336.48 | I6: =F6*7.5% -> 983.412 | K6: =F6*50% -> 6556.08 | L6: =F6*350% -> 45892.56 | M6: =F6*100% -> 13112.16 | N6: =100000 -> 100000 | P6: =F6*10% -> 1311.216 | Q6: 10000 | S6: =SUM(F6:R6) -> 230304.07 | U6: 20000 | V6: =50000 -> 50000 | X6: 1484.37 | Y6: =X6+W6+V6+U6+T6 -> 71484.37 | Z6: 158819.7 | AA6: =S6-Y6 -> 158819.7 | AB6: =S6*0.11 -> 25333.447
A7: 4 | B7: TITILAYO DANIEL MARVELLOUS | D7: LIBRARY ASSISTANT | E7: 8(8) | F7: =12732 -> 12732 | H7: =F7*300% -> 38196 | I7: =F7*7.5% -> 954.9 | K7: =F7*50% -> 6366 | L7: =F7*350% -> 44562 | M7: =F7*100% -> 12732 | N7: =100000 -> 100000 | P7: =F7*10% -> 1273.2 | Q7: 10000 | S7: =SUM(F7:R7) -> 226816.1 | U7: =25000 -> 25000 | V7: 0 | X7: 1484.37 | Y7: =X7+W7+V7+U7+T7 -> 26484.37 | Z7: 200580.91 | AA7: =S7-Y7 -> 200331.73 | AB7: =S7*0.11 -> 24949.771
A8: 5 | B8: ENENCHE JEREMIAH AGADA | D8: LIBRARY ASSISTANT | E8: 8(7) | F8: =12351.94 -> 12351.94 | H8: =F8*300% -> 37055.82 | I8: =F8*7.5% -> 926.3955 | K8: =F8*50% -> 6175.97 | L8: =F8*350% -> 43231.79 | M8: =F8*100% -> 12351.94 | N8: =100000 -> 100000 | P8: =F8*10% -> 1235.194 | Q8: 10000 | S8: =SUM(F8:R8) -> 223329.05 | X8: 1484.37 | Y8: =X8+W8+V8+U8+T8 -> 1484.37 | AA8: =S8-Y8 -> 221844.68 | AB8: =S8*0.11 -> 24566.195
A9: 6 | B9: ABBAS ZAINAB | D9: LIBRARY ASSISTANT | E9: 8(7) | F9: =12351.94 -> 12351.94 | H9: =F9*300% -> 37055.82 | I9: =F9*7.5% -> 926.3955 | K9: =F9*50% -> 6175.97 | L9: =F9*350% -> 43231.79 | M9: =F9*100% -> 12351.94 | N9: =100000 -> 100000 | P9: =F9*10% -> 1235.194 | Q9: 10000 | S9: =SUM(F9:R9) -> 223329.05 | X9: 1484.37 | Y9: =X9+W9+V9+U9+T9 -> 1484.37 | AA9: =S9-Y9 -> 221844.68 | AB9: =S9*0.11 -> 24566.195
B10: TOTAL | D10: 6 | F10: =SUM(F4:F9) -> 101628.6 | H10: =SUM(H4:H9) -> 304885.8 | I10: =SUM(I4:I9) -> 7622.145 | J10: =SUM(J4:J9) -> 0 | K10: =SUM(K4:K9) -> 50814.3 | L10: =SUM(L4:L9) -> 355700.1 | M10: =SUM(M4:M9) -> 101628.6 | N10: =SUM(N4:N9) -> 640000 | P10: =SUM(P4:P9) -> 10162.86 | Q10: =SUM(Q4:Q9) -> 70000 | R10: =SUM(R4:R9) -> 0 | S10: =SUM(S4:S9) -> 1642442.4 | U10: =SUM(U4:U9) -> 125000 | V10: =SUM(V4:V9) -> 208333.33 | W10: =SUM(W4:W9) -> 658.4825 | X10: =SUM(X4:X9) -> 21357 | Y10: =SUM(Y4:Y9) -> 355348.81 | Z10: =SUM(Z4:Z9) -> 889486.74 | AA10: =SUM(AA4:AA9) -> 1287093.6 | AB10: =SUM(AB4:AB9) -> 180668.66

Sheet New staff
B3: STAFF PAYROLL FOR THE MONTH OF SEPTEMBER, 2021
F4: ='[1]FEB 08'!E8/'[1]FEB 08'!M8 -> 0.22 | I4: ='[1]FEB 08'!F8/'[1]FEB 08'!Q8 -> 0.3
B5: EFFECT OF ADDITION OF NEW STAFF | S5: DEDUCTIONS | Y5: NET SALARY
D6: DESIGNATION | E6: SALARY | F6: BASIC | M6: MOTOR/ | N6: OLD | O6: LEAVE | P6: OUT FIT | Q6: LEGISLATIVE | R6: GROSS | X6: JUNE,2021 | Y6: JULY,2021 | Z6: NEW
E7: LEVEL | F7: SALARY | G7: SALARY/ALLOWCE AREARS | H7: RENT | I7: UTILITY | J7: DOMESTIC | K7: ENTERT. | L7: FURNIT. | M7: FUEL | N7: SALARY | O7: ALLCE | P7: ALLCE | Q7: DUTY ALLCE | R7: SALARY | S7: COOP SOCIETY | T7: COOP. LOAN RECOVERY | U7: NHF DEDUCTION | V7: PAYE | W7: TOTAL | Z7: SALARY | AA7: DIFFERENCE | AB7: OLD TAX | AC7: NEW TAX | AD7: DIFFERENCE
A8: S/N | B8: DG OFFICE | F8: N | I8: N | R8: N | V8: N
A9: 1 | B9: JIMOH ADEBAYO ZAKA | D9: ASST. OFFICER INF/COMM | E9: 8(7) | Z9: =123329+50000 -> 173329 | AA9: =Z9-N9 -> 173329 | AC9: =1484.37 -> 1484.37 | AD9: =AC9-AB9 -> 1484.37
B10: TOTAL | D10: 1 | F10: =SUM(F9:F9) -> 0 | H10: =SUM(H9:H9) -> 0 | I10: =SUM(I9:I9) -> 0 | J10: =SUM(J9:J9) -> 0 | K10: =SUM(K9:K9) -> 0 | L10: =SUM(L9:L9) -> 0 | M10: =SUM(M9:M9) -> 0 | N10: =SUM(N9:N9) -> 0 | O10: =SUM(O9:O9) -> 0 | ... W10: =SUM(W9:W9) -> 0 | X10: 7468053.9 | Y10: =SUM(Y9:Y9) -> 0 | Z10: =SUM(Z9) -> 173329 | AA10: =SUM(AA9) -> 173329 | AC10: =SUM(AC9) -> 1484.37 | AD10: =SUM(AD9) -> 1484.37
B12: INTERNAL AUDIT
A13: 1 | B13: OSANAIYE DAVID AKINYEMI | D13: DIRECTOR INTERNAL AUDIT | E13: 17 (7) | Z13: =(800657+100000)*18/30 -> 540394.2 | AA13: =Z13-N13 -> 540394.2 | AC13: =('December, 2021'!W46)*18/30 -> 31665.978 | AD13: =AC13-AB13 -> 31665.978
B14: NWOSU EZE MATTHEW | D14: DEPUTY DIRECTOR IA | E14: 16 (9) | AB14: 52776.63 | AC14: 21618.09 | AD14: =AC14-AB14 -> -31158.54
C15: TOTAL | D15: 1 | F15: =SUM(F13:F13) -> 0 | H15: =SUM(H13:H13) -> 0 | I15: =SUM(I13:I13) -> 0 | J15: =SUM(J13:J13) -> 0 | K15: =SUM(K13:K13) -> 0 | L15: =SUM(L13:L13) -> 0 | M15: =SUM(M13:M13) -> 0 | N15: =SUM(N13:N13) -> 0 | O15: =SUM(O13:O13) -> 0 | ... W15: =SUM(W13:W13) -> 0 | X15: 383180.46 | Y15: =SUM(Y13:Y13) -> 0 | Z15: =SUM(Z13:Z14) -> 540394.2 | AA15: =SUM(AA13:AA14) -> 540394.2 | AB15: =SUM(AB13:AB14) -> 52776.63 | AC15: =SUM(AC13:AC14) -> 53284.068 | AD15: =SUM(AD13:AD14) -> 507.438
B17: LEG. SUPPORT SEVICES
B18: TOTAL | D18: 0 | F18: =SUM(#REF!) -> #REF! | H18: =SUM(#REF!) -> #REF! | I18: =SUM(#REF!) -> #REF! | J18: =SUM(#REF!) -> #REF! | K18: =SUM(#REF!) -> #REF! | L18: =SUM(#REF!) -> #REF! | M18: =SUM(#REF!) -> #REF!
B20: LEGAL SERVICES
A21: 1 | B21: ENECHE JERIMIAH AGADA | D21: LIBRARY ASSISTANT | E21: 8 (7) | N21: =0 -> 0 | Z21: =123329+100000 -> 223329 | AA21: =Z21-N21 -> 223329 | AC21: =1484.37 -> 1484.37 | AD21: =AC21-AB21 -> 1484.37
A22: 2 | B22: ABBAS ZAINAB | D22: LIBRARY ASSISTANT | E22: 8 (7) | N22: =0 -> 0 | Z22: =123329+100000 -> 223329 | AA22: =Z22-N22 -> 223329 | AC22: =1484.37 -> 1484.37 | AD22: =AC22-AB22 -> 1484.37
B23: TOTAL | D23: 2 | F23: =SUM(F21:F22) -> 0 | H23: =SUM(H21:H22) -> 0 | I23: =SUM(I21:I22) -> 0 | J23: =SUM(J21:J22) -> 0 | K23: =SUM(K21:K22) -> 0 | L23: =SUM(L21:L22) -> 0 | M23: =SUM(M21:M22) -> 0 | N23: =SUM(N21:N22) -> 0 | O23: =SUM(O21:O22) -> 0 | ... S23: =SUM(S21:S22) -> 0 | U23: =SUM(U21:U22) -> 0 | V23: =SUM(V21:V22) -> 0 | W23: =SUM(W21:W22) -> 0 | X23: 1126604.2 | Y23: =SUM(Y21:Y22) -> 0 | Z23: =SUM(Z21:Z22) -> 446658 | AA23: =SUM(AA21:AA22) -> 446658 | AC23: =SUM(AC21:AC22) -> 2968.74 | AD23: =SUM(AD21:AD22) -> 2968.74
B25: DEMOCRATIC STUDIES
B26: TOTAL | F26: =SUM(#REF!) -> #REF! | H26: =SUM(#REF!) -> #REF! | I26: =SUM(#REF!) -> #REF! | J26: =SUM(#REF!) -> #REF! | K26: =SUM(#REF!) -> #REF! | L26: =SUM(#REF!) -> #REF! | M26: =SUM(#REF!) -> #REF!
B28: STUDIES
B29: TOTAL | F29: =SUM(#REF!) -> #REF! | H29: =SUM(#REF!) -> #REF! | I29: =SUM(#REF!) -> #REF! | J29: =SUM(#REF!) -> #REF! | K29: =SUM(#REF!) -> #REF! | L29: =SUM(#REF!) -> #REF! | M29: =SUM(#REF!) -> #REF!
B31: ECONOMIC AND SOCIAL DEV.
B32: TOTAL | D32: 0 | F32: =SUM(#REF!) -> #REF! | H32: =SUM(#REF!) -> #REF! | I32: =SUM(#REF!) -> #REF! | J32: =SUM(#REF!) -> #REF! | K32: =SUM(#REF!) -> #REF! | L32: =SUM(#REF!) -> #REF! | M32: =SUM(#REF!) -> #REF!
B34: TRAINING AND INTERNATIONAL COOP
A35: 1 | B35: REKIYA IBRAHIM ATTAH | D35: DEPUTY DIRECTOR TRAINING | E35: 16 (7) | N35: =0 -> 0 | Z35: =(424023+90000)*21/30 -> 359816.1 | AA35: =Z35-N35 -> 359816.1 | AC35: =21618.09 -> 21618.09 | AD35: =AC35-AB35 -> 21618.09
A36: 2 | B36: ABUBAKAR MOHAMMED BASHIR | D36: ASST. CHIEF TRAINING OFFICER | E36: 13 (7) | Z36: =226713+70000 -> 296713 | AA36: =Z36-N36 -> 296713 | AC36: ='December, 2021'!W92 -> 7709.76 | AD36: =AC36-AB36 -> 7709.76
B37: TOTAL | D37: 2 | F37: =SUM(F35:F36) -> 0 | H37: =SUM(H35:H36) -> 0 | I37: =SUM(I35:I36) -> 0 | J37: =SUM(J35:J36) -> 0 | K37: =SUM(K35:K36) -> 0 | L37: =SUM(L35:L36) -> 0 | M37: =SUM(M35:M36) -> 0 | N37: =SUM(N35:N36) -> 0 | O37: =SUM(O35:O36) -> 0 | ... W37: =SUM(W35:W36) -> 0 | X37: 1259979.1 | Y37: =SUM(Y35:Y36) -> 0 | Z37: =SUM(Z35:Z36) -> 656529.1 | AA37: =SUM(AA35:AA36) -> 656529.1 | AC37: =SUM(AC35:AC36) -> 29327.85 | AD37: =SUM(AD35:AD36) -> 29327.85
B39: LIBRARY AND DOCUMENTATION
B40: TOTAL | F40: =SUM(#REF!) -> #REF! | H40: =SUM(#REF!) -> #REF! | I40: =SUM(#REF!) -> #REF! | J40: =SUM(#REF!) -> #REF! | K40: =SUM(#REF!) -> #REF! | L40: =SUM(#REF!) -> #REF! | M40: =SUM(#REF!) -> #REF!
B42: FINANCE & ACCOUNT
A43: 1 | B43: ARAOYE GANIYAT TITILOLA | D43: ASST. DIRECTOR Accounts | E43: 15 (7) | N43: =0 -> 0 | Z43: =(344720+80000)*18/30 -> 254832 | AA43: =Z43-N43 -> 254832 | AC43: =('December, 2021'!W90)*18/30 -> 9328.998 | AD43: =AC43-AB43 -> 9328.998
A44: 2 | B44: SALMAN RABBIAT BOLATITO | D44: ASST. CHIEF | E44: 13 (7) | Z44: =226713+70000 -> 296713 | AA44: =Z44-N44 -> 296713 | AC44: =AC36 -> 7709.76 | AD44: =AC44-AB44 -> 7709.76
B45: TOTAL | D45: 2 | F45: =SUM(F43:F44) -> 0 | H45: =SUM(H43:H44) -> 0 | I45: =SUM(I43:I44) -> 0 | J45: =SUM(J43:J44) -> 0 | K45: =SUM(K43:K44) -> 0 | L45: =SUM(L43:L44) -> 0 | M45: =SUM(M43:M44) -> 0 | N45: =SUM(N43:N44) -> 0 | O45: =SUM(O43:O44) -> 0 | ... W45: =SUM(W43:W44) -> 0 | X45: 2217865 | Y45: =SUM(Y43:Y44) -> 0 | Z45: =SUM(Z43:Z44) -> 551545 | AA45: =SUM(AA43:AA44) -> 551545 | AC45: =SUM(AC43:AC44) -> 17038.758 | AD45: =SUM(AD43:AD44) -> 17038.758
B47: ADMINISTRATION & HUMAN RESOURCE
A48: 1 | B48: PRISCILLA NKECHI CHUKWU | D48: ASST. DIRECTOR HR | E48: 15 (9) | N48: =0 -> 0 | Z48: =367553+80000 -> 447553 | AA48: =Z48-N48 -> 447553 | AC48: ='December, 2021'!W135 -> 15548.33 | AD48: =AC48-AB48 -> 15548.33
A49: 2 | B49: OLOLADE ABRU IDOWU | D49: CONFIDENTIAL SECRETARY | E49: 8(7) | Z49: =123329+50000 -> 173329 | AA49: =Z49-N49 -> 173329 | AC49: =1484.37 -> 1484.37 | AD49: =AC49-AB49 -> 1484.37
B50: TOTAL | D50: 2 | F50: =SUM(#REF!) -> #REF! | H50: =SUM(#REF!) -> #REF! | I50: =SUM(#REF!) -> #REF! | J50: =SUM(#REF!) -> #REF! | K50: =SUM(#REF!) -> #REF! | L50: =SUM(#REF!) -> #REF! | M50: =SUM(#REF!) -> #REF! | Z50: =SUM(Z48:Z49) -> 620882 | AA50: =SUM(AA48:AA49) -> 620882 | AC50: =SUM(AC48:AC49) -> 17032.7 | AD50: =SUM(AD48:AD49) -> 17032.7
B51: GRAND TOTAL | D51: =D10+D15+D18+D23+D26+D29+D32+D37+D40+D45+D50 -> 10 | F51: =F10+F15+F18+F23+F26+F29+F32+F37+F40+F45+F50 -> #REF! | G51: =G10+G15+G18+G23+G26+G29+G32+G37+G40+G45+G50 -> 0 | H51: =H10+H15+H18+H23+H26+H29+H32+H37+H40+H45+H50 -> #REF! | I51: =I10+I15+I18+I23+I26+I29+I32+I37+I40+I45+I50 -> #REF! | J51: =J10+J15+J18+J23+J26+J29+J32+J37+J40+J45+J50 -> #REF! | K51: =K10+K15+K18+K23+K26+K29+K32+K37+K40+K45+K50 -> #REF! | L51: =L10+L15+L18+L23+L26+L29+L32+L37+L40+L45+L50 -> #REF! | M51: =M10+M15+M18+M23+M26+M29+M32+M37+M40+M45+M50 -> #REF! | ... AA51: =AA10+AA15+AA18+AA23+AA26+AA29+AA32+AA37+AA40+AA45+AA50 -> 2989337.3 | AC51: =AC50+AC45+AC37+AC23+AC15+AC10 -> 121136.49 | AD51: =AD50+AD45+AD37+AD23+AD15+AD10 -> 68359.856
C53: SULEIMAN ABUBAKAR SODEEQ | AB53: =1235.19 -> 1235.19 | AC53: =1484.37 -> 1484.37 | AD53: =AC53-AB53 -> 249.18
...

Sheet New staff (2)
B3: STAFF PAYROLL FOR THE MONTH OF SEPTEMBER, 2021
F4: ='[1]FEB 08'!E8/'[1]FEB 08'!M8 -> 0.22 | I4: ='[1]FEB 08'!F8/'[1]FEB 08'!Q8 -> 0.3
B5: EFFECT OF ADDITION OF NEW STAFF | S5: DEDUCTIONS | Y5: NET SALARY
D6: DESIGNATION | E6: SALARY | F6: BASIC | M6: MOTOR/ | N6: OLD | O6: LEAVE | P6: OUT FIT | Q6: LEGISLATIVE | R6: GROSS | X6: JUNE,2021 | Y6: JULY,2021 | Z6: NEW
E7: LEVEL | F7: SALARY | G7: SALARY/ALLOWCE AREARS | H7: RENT | I7: UTILITY | J7: DOMESTIC | K7: ENTERT. | L7: FURNIT. | M7: FUEL | N7: SALARY | O7: ALLCE | P7: ALLCE | Q7: DUTY ALLCE | R7: SALARY | S7: COOP SOCIETY | T7: COOP. LOAN RECOVERY | U7: NHF DEDUCTION | V7: PAYE | W7: TOTAL | Z7: SALARY | AA7: DIFFERENCE | AB7: OLD TAX | AC7: NEW TAX | AD7: DIFFERENCE
B8: INTERNAL AUDIT
A9: 1 | B9: OSANAIYE DAVID AKINYEMI | D9: DIRECTOR INTERNAL AUDIT | E9: 17 (7) | N9: 540394.2 | Z9: =(800657+100000) -> 900657 | AA9: =Z9-N9 -> 360262.8 | AB9: 31665.978 | AC9: =('December, 2021'!W46) -> 52776.63 | AD9: =AC9-AB9 -> 21110.652
C10: TOTAL | D10: 1 | F10: =SUM(F9:F9) -> 0 | H10: =SUM(H9:H9) -> 0 | I10: =SUM(I9:I9) -> 0 | J10: =SUM(J9:J9) -> 0 | K10: =SUM(K9:K9) -> 0 | L10: =SUM(L9:L9) -> 0 | M10: =SUM(M9:M9) -> 0 | N10: 540394.2 | O10: =SUM(O9:O9) -> 0 | P10: =SUM(P9:P9) -> 0 | Q10: =SUM(Q9:Q9) -> 0 | R10: =SUM(R9:R9) -> 0 | S10: =SUM(S9:S9) -> 0 | T10: =SUM(T9:T9) -> 0 | U10: =SUM(U9:U9) -> 0 | V10: =SUM(V9:V9) -> 0 | W10: =SUM(W9:W9) -> 0 | X10: 383180.46 | Y10: =SUM(Y9:Y9) -> 0 | Z10: =SUM(Z9:Z9) -> 900657 | AA10: =SUM(AA9:AA9) -> 360262.8 | AB10: 53284.068 | AC10: =SUM(AC9:AC9) -> 52776.63 | AD10: =SUM(AD9:AD9) -> 21110.652
B12: TRAINING AND INTERNATIONAL COOP
A13: 1 | B13: REKIYA IBRAHIM ATTAH | D13: DEPUTY DIRECTOR TRAINING | E13: 16 (7) | N13: 359816.1 | Z13: =(424023+90000) -> 514023 | AA13: =Z13-N13 -> 154206.9 | AB13: 21618.09 | AC13: =21618.09 -> 21618.09 | AD13: =AC13-AB13 -> 0
B14: TOTAL | D14: 2 | F14: =SUM(F13:F13) -> 0 | H14: =SUM(H13:H13) -> 0 | I14: =SUM(I13:I13) -> 0 | J14: =SUM(J13:J13) -> 0 | K14: =SUM(K13:K13) -> 0 | L14: =SUM(L13:L13) -> 0 | M14: =SUM(M13:M13) -> 0 | N14: 359816.1 | O14: =SUM(O13:O13) -> 0 | P14: =SUM(P13:P13) -> 0 | Q14: =SUM(Q13:Q13) -> 0 | R14: =SUM(R13:R13) -> 0 | S14: =SUM(S13:S13) -> 0 | T14: =SUM(T13:T13) -> 0 | U14: =SUM(U13:U13) -> 0 | V14: =SUM(V13:V13) -> 0 | W14: =SUM(W13:W13) -> 0 | X14: 1259979.1 | Y14: =SUM(Y13:Y13) -> 0 | Z14: =SUM(Z13:Z13) -> 514023 | AA14: =SUM(AA13:AA13) -> 154206.9 | AB14: 21618.09 | AC14: =SUM(AC13:AC13) -> 21618.09 | AD14: =SUM(AD13:AD13) -> 0
B15: FINANCE & ACCOUNT
A16: 1 | B16: ARAOYE GANIYAT TITILOLA | D16: ASST. DIRECTOR Accounts | E16: 15 (7) | N16: 254832 | Z16: =(344720+80000) -> 424720 | AA16: =Z16-N16 -> 169888 | AB16: 9328.998 | AC16: =('December, 2021'!W90) -> 15548.33 | AD16: =AC16-AB16 -> 6219.332
B17: TOTAL | D17: 2 | F17: =SUM(F16:F16) -> 0 | H17: =SUM(H16:H16) -> 0 | I17: =SUM(I16:I16) -> 0 | J17: =SUM(J16:J16) -> 0 | K17: =SUM(K16:K16) -> 0 | L17: =SUM(L16:L16) -> 0 | M17: =SUM(M16:M16) -> 0 | N17: 254832 | O17: =SUM(O16:O16) -> 0 | P17: =SUM(P16:P16) -> 0 | Q17: =SUM(Q16:Q16) -> 0 | R17: =SUM(R16:R16) -> 0 | S17: =SUM(S16:S16) -> 0 | T17: =SUM(T16:T16) -> 0 | U17: =SUM(U16:U16) -> 0 | V17: =SUM(V16:V16) -> 0 | W17: =SUM(W16:W16) -> 0 | X17: 2217865 | Y17: =SUM(Y16:Y16) -> 0 | Z17: =SUM(Z16:Z16) -> 424720 | AA17: =SUM(AA16:AA16) -> 169888 | AB17: 9328.998 | AC17: =SUM(AC16:AC16) -> 15548.33 | AD17: =SUM(AD16:AD16) -> 6219.332
B18: GRAND TOTAL | N18: =N10+N14+N17 -> 1155042.3 | O18: =O10+O14+O17 -> 0 | P18: =P10+P14+P17 -> 0 | Q18: =Q10+Q14+Q17 -> 0 | R18: =R10+R14+R17 -> 0 | S18: =S10+S14+S17 -> 0 | T18: =T10+T14+T17 -> 0 | U18: =U10+U14+U17 -> 0 | ... AD18: =AD10+AD14+AD17 -> 27329.984
B19: NET DIFFERENCE | AD19: =-AA18+AD18 -> -657027.72

Sheet Adj Hardship
B3: STAFF PAYROLL FOR THE MONTH OF JULY, 2021
F4: ='[1]FEB 08'!E8/'[1]FEB 08'!M8 -> 0.22 | I4: ='[1]FEB 08'!F8/'[1]FEB 08'!Q8 -> 0.3
B5: STAFF NAME | S5: DEDUCTIONS | Y5: NET SALARY
D6: DESIGNATION | E6: SALARY | F6: BASIC | M6: MOTOR/ | N6: RESEARCH | O6: LEAVE | P6: OUT FIT | Q6: LEGISLATIVE | R6: GROSS | X6: JUNE,2021 | Y6: JULY,2021 | Z6: NEW RESEARCH/
