Workbook

Sheet April 2012
W1: Page 1 of 2
A3: STAFF PAYROLL FOR THE MONTH OF april 2012.
F4: ='[1]FEB 08'!E8/'[1]FEB 08'!M8 -> 0.22 | J4: ='[1]FEB 08'!F8/'[1]FEB 08'!Q8 -> 0.3
A5: STAFF NAME | V5: NET SALARY | W5: NET SALARY
D6: DESIGNATION | E6: SALARY | F6: BASIC | G6: 28 DAYS ALCE | H6: 40969 | N6: PERSONAL | O6: MOTOR/ | P6: RESEARCH | Q6: LEAVE | R6: OUT FIT | S6: LEGISLATIVE | T6: GROSS | W6: April
E7: LEVEL | F7: SALARY | G7: IN LIEU | H7: AREARS | I7: RENT | J7: UTILITY | K7: DOMESTIC | L7: ENTERT. | M7: FURNIT. | N7: ASSISTANT | O7: FUEL | P7: ALLOWANCE | Q7: ALLCE | R7: ALLCE | S7: DUTY ALLCE | T7: SALARY | U7: PAYE
A8: DG OFFICE | F8: N | J8: N | T8: N | U8: N | W8: N
A9: DR LADI HAMALAI | D9: DG | E9: CONSOL | F9: 160488.75 | G9: 0 | I9: 320977.5 | J9: 48146.63 | K9: 120366.57 | L9: 72219.94 | M9: 481466.25 | N9: 40122.19 | O9: 120366.57 | P9: 150000 | Q9: 16048.88 | R9: 25000 | S9: 25235 | T9: =SUM(F9:S9) -> 1580438.3 | U9: 0 | V9: =T9-U9 -> 1580438.3 | W9: 1880438.3
A10: PROF. OFFORNZE AMUCHEAZI | D10: LEGAL ADVISER | E10: 16(7) | F10: =F21 -> 39662.25 | G10: 0 | I10: =I21 -> 118986.75 | J10: =J21 -> 2974.6687 | K10: =K21 -> 40122.19 | L10: =F10*50% -> 19831.125 | M10: =F10*350% -> 138817.88 | N10: 0 | O10: =F10*100% -> 39662.25 | P10: 0 | Q10: =F10*10% -> 3966.225 | R10: 20000 | S10: 0 | T10: =SUM(F10:S10) -> 424023.33 | U10: 0 | V10: =T10-U10 -> 424023.33 | W10: =T10-U10 -> 424023.33
A11: MOHAMMED ISIAKA YAKUBU | D11: SPECIAL ASSISTANT | E11: 16(7) | F11: =F10 -> 39662.25 | G11: 0 | I11: =I10 -> 118986.75 | J11: =J10 -> 2974.6687 | K11: 40122.19 | L11: 19831.13 | M11: 138817.88 | N11: 0 | O11: 39662.25 | P11: 0 | Q11: 3966.23 | R11: =R10 -> 20000 | S11: 0 | T11: 424023.33 | U11: 0 | V11: =T11-U11 -> 424023.33 | W11: 424023.33
A12: RICHARD KWALMI | D12: MICT | E12: 15(7) | F12: 31018.9 | G12: 0 | I12: =F12*300% -> 93056.7 | J12: =F12*7.5% -> 2326.4175 | K12: =K9/3 -> 40122.19 | L12: =F12*50% -> 15509.45 | M12: =F12*350% -> 108566.15 | N12: 0 | O12: =F12*100% -> 31018.9 | P12: 0 | Q12: =F12*10% -> 3101.89 | R12: 20000 | S12: 0 | T12: =SUM(F12:S12) -> 344720.6 | U12: 0 | V12: =T12-U12 -> 344720.6 | W12: =T12-U12 -> 344720.6
A13: KENNETH OKEREAFOR | D13: AM MICT | E13: 13(7) | F13: 23891.12 | G13: 252000 | I13: =F13*300% -> 71673.36 | J13: =F13*7.5% -> 1791.834 | K13: 0 | L13: =F13*50% -> 11945.56 | M13: =F13*350% -> 83618.92 | N13: 0 | O13: =F13*100% -> 23891.12 | P13: 0 | Q13: =F13*10% -> 2389.112 | R13: 15000 | S13: 0 | T13: =SUM(F13:S13) -> 486201.03 | U13: 0 | V13: =T13-U13 -> 486201.03 | W13: 0
A14: ABDULSALAM MUSTAFA | D14: ICT OFFICER | E14: 10(10) | F14: 18234.42 | G14: 0 | I14: =F14*300% -> 54703.26 | J14: =F14*7.5% -> 1367.5815 | K14: 0 | L14: =F14*50% -> 9117.21 | M14: =F14*350% -> 63820.47 | N14: 0 | O14: =F14*100% -> 18234.42 | P14: 0 | Q14: =F14*10% -> 1823.442 | R14: 15000 | S14: 0 | T14: =SUM(F14:S14) -> 182300.8 | U14: 0 | V14: =T14-U14 -> 182300.8 | W14: =T14-U14 -> 182300.8
A15: ALI ABDULLAHI | D15: 1CT ASSISTANT | E15: 8(7) | F15: 12351.94 | G15: 0 | I15: =F15*300% -> 37055.82 | J15: =F15*7.5% -> 926.3955 | K15: 0 | L15: =F15*50% -> 6175.97 | M15: =F15*350% -> 43231.79 | N15: 0 | O15: =F15*100% -> 12351.94 | P15: 0 | Q15: =F15*10% -> 1235.194 | R15: 10000 | S15: 0 | T15: =SUM(F15:S15) -> 123329.05 | V15: =T15-U16 -> 123329.05 | W15: 105890.22
A16: MKPANAM DONALD EFFIONG | D16: ICT ASSISTANT | E16: 8(7) | F16: 12351.94 | G16: 252000 | I16: =F16*300% -> 37055.82 | J16: =F16*7.5% -> 926.3955 | L16: =F16*50% -> 6175.97 | M16: =F16*350% -> 43231.79 | O16: =F16*100% -> 12351.94 | P16: 0 | Q16: =F16*10% -> 1235.194 | R16: 10000 | S16: 0 | T16: =SUM(F16:S16) -> 375329.05 | U16: 0 | V16: =T16-U17 -> 375329.05 | W16: 0
A17: TOTAL | D17: 8 | F17: =SUM(F9:F16) -> 337661.57 | G17: =SUM(G9:G16) -> 504000 | H17: =SUM(H9:H16) -> 0 | I17: =SUM(I9:I16) -> 852495.96 | J17: =SUM(J9:J16) -> 61434.591 | K17: =SUM(K9:K16) -> 240733.14 | L17: =SUM(L9:L16) -> 160806.36 | M17: =SUM(M9:M16) -> 1101571.1 | ... W17: =SUM(W9:W16) -> 3361396.6
G18: 0
A20: LEG. SUPPORT SEVICES
A21: DR SHUIBU DANWANKA | D21: DD | E21: 16(7) | F21: 39662.25 | G21: 0 | I21: =F21*300% -> 118986.75 | J21: =F21*7.5% -> 2974.6687 | K21: =K12 -> 40122.19 | L21: =F21*50% -> 19831.125 | M21: =F21*350% -> 138817.88 | N21: 0 | O21: =F21*100% -> 39662.25 | P21: 100000 | Q21: =F21*10% -> 3966.225 | R21: 20000 | S21: 0 | T21: =SUM(F21:S21) -> 524023.33 | U21: 0 | V21: =T21-U21 -> 524023.33 | W21: 724023.33
A22: TOTAL | D22: 1 | F22: =SUM(F21) -> 39662.25 | G22: 0 | H22: 0 | I22: =SUM(I21) -> 118986.75 | J22: =SUM(J21) -> 2974.6687 | K22: =SUM(K21) -> 40122.19 | L22: =SUM(L21) -> 19831.125 | M22: =SUM(M21) -> 138817.88 | N22: =SUM(N21) -> 0 | O22: =SUM(O21) -> 39662.25 | P22: =SUM(P21) -> 100000 | ... W22: =SUM(W21) -> 724023.33
A24: RESEARCH & TRAINING
A25: DR ASIMIYU G. ABIOLA | D25: DD RESEARCH | E25: 16(7) | F25: =F21 -> 39662.25 | G25: 0 | I25: =I21 -> 118986.75 | J25: =J21 -> 2974.6687 | K25: =K21 -> 40122.19 | L25: =L21 -> 19831.125 | M25: =F25*350% -> 138817.88 | N25: 0 | O25: =F25*100% -> 39662.25 | P25: =P21 -> 100000 | Q25: =F25*10% -> 3966.225 | R25: 20000 | S25: 0 | T25: =SUM(F25:S25) -> 524023.33 | U25: 0 | V25: =T25-U25 -> 524023.33 | W25: 724023.33
A26: SOLOMON A. BENJAMIN | D26: DD TRAINING | E26: 16(7) | F26: =F22 -> 39662.25 | G26: 0 | I26: =I22 -> 118986.75 | J26: =J22 -> 2974.6687 | K26: =K22 -> 40122.19 | L26: =L22 -> 19831.125 | M26: =F26*350% -> 138817.88 | N26: 0 | O26: =F26*100% -> 39662.25 | P26: =P22 -> 100000 | Q26: =F26*10% -> 3966.225 | R26: 20000 | S26: 0 | T26: =SUM(F26:S26) -> 524023.33 | U26: =U22 -> 0 | V26: =T26-U26 -> 524023.33 | W26: 724023.33
A27: DR PATTERSON EKEOCHA | D27: SRF | E27: 15(9) | F27: 33507.5 | G27: 0 | I27: =F27*300% -> 100522.5 | J27: =F27*7.5% -> 2513.0625 | K27: =K12 -> 40122.19 | L27: =F27*50% -> 16753.75 | M27: =F27*350% -> 117276.25 | N27: 0 | O27: =F27*100% -> 33507.5 | P27: 100000 | Q27: =F27*10% -> 3350.75 | R27: 20000 | S27: 0 | T27: =SUM(F27:S27) -> 467553.5 | U27: 0 | V27: =T27-U27 -> 467553.5 | W27: 667553.5
A28: CATHERINE E. IKOKOH | D28: RESEARCH FELLOW 1 | E28: 13(7) | F28: 23891.12 | G28: 252000 | H28: 131762 | I28: =F28*300% -> 71673.36 | J28: =F28*7.5% -> 1791.834 | K28: =K13 -> 0 | L28: =F28*50% -> 11945.56 | M28: =F28*350% -> 83618.92 | N28: 0 | O28: =F28*100% -> 23891.12 | P28: 80000 | Q28: =F28*10% -> 2389.112 | R28: 15000 | S28: 0 | T28: =SUM(F28:S28) -> 697963.03 | U28: 0 | V28: =T28-U28 -> 697963.03 | W28: 0
A29: ALIYU SANNI ABUBAKAR | D29: DATA & DOCU. OFFICER | E29: 10(7) | F29: 17286.33 | G29: 252000 | I29: =F29*300% -> 51858.99 | J29: =F29*7.5% -> 1296.4748 | K29: =K13 -> 0 | L29: =F29*50% -> 8643.165 | M29: =F29*350% -> 60502.155 | N29: 0 | O29: =F29*100% -> 17286.33 | P29: 40000 | Q29: =F29*10% -> 1728.633 | R29: 10000 | S29: 0 | T29: =SUM(F29:S29) -> 460602.08 | V29: 0 | W29: 0
A30: TOTAL | D30: 5 | F30: =SUM(F25:F29) -> 154009.45 | G30: =SUM(G25:G29) -> 504000 | H30: =SUM(H25:H29) -> 131762 | I30: =SUM(I25:I29) -> 462028.35 | J30: =SUM(J25:J29) -> 11550.709 | K30: =SUM(K25:K29) -> 120366.57 | L30: =SUM(L25:L29) -> 77004.725 | M30: =SUM(M25:M29) -> 539033.07 | ... W30: =SUM(W25:W29) -> 2115600.2
A32: FINANCE & ADMIN.
A33: DR KABIR AHMED | D33: DFA | E33: 17(7) | F33: ='17.7'!E4 -> 76339.3 | G33: 0 | I33: =F33*300% -> 229017.9 | J33: =F33*7.5% -> 5725.4475 | K33: ='17.7'!E7 -> 80244.38 | L33: =F33*50% -> 38169.65 | M33: =F33*350% -> 267187.55 | N33: 0 | O33: =F33*100% -> 76339.3 | P33: 0 | Q33: =F33*10% -> 7633.93 | R33: 20000 | S33: 0 | T33: =SUM(F33:S33) -> 800657.46 | U33: 0 | V33: =T33-U33 -> 800657.46 | W33: 712778.05
A34: IBRAHIM M. MSHELIA | D34: DD F&A | E34: 16(7) | F34: 39662.25 | G34: 0 | I34: =F34*300% -> 118986.75 | J34: =F34*7.5% -> 2974.6687 | K34: =K26 -> 40122.19 | L34: =F34*50% -> 19831.125 | M34: =F34*350% -> 138817.88 | N34: 0 | O34: =F34*100% -> 39662.25 | P34: 0 | Q34: =F34*10% -> 3966.225 | R34: 20000 | S34: 0 | T34: =SUM(F34:S34) -> 424023.33 | U34: 0 | V34: =T34-U34 -> 424023.33 | W34: =T34-U34 -> 424023.33
A35: AMINU BELLO DUKKU | D35: DD ADMIN/HR | E35: 16(7) | F35: 39662.25 | G35: 0 | I35: =F35*300% -> 118986.75 | J35: =F35*7.5% -> 2974.6687 | K35: =K27 -> 40122.19 | L35: =F35*50% -> 19831.125 | M35: =F35*350% -> 138817.88 | N35: 0 | O35: =F35*100% -> 39662.25 | P35: 0 | Q35: =F35*10% -> 3966.225 | R35: 20000 | S35: 0 | T35: =SUM(F35:S35) -> 424023.33 | U35: 0 | V35: =T35-U35 -> 424023.33 | W35: =T35-U35 -> 424023.33
A36: KABIR MUHAMMAD SULAIMAN | D36: MANAGER ADMIN&HR | E36: 15(7) | F36: 31018.9 | G36: 364000 | I36: =F36*300% -> 93056.7 | J36: =F36*7.5% -> 2326.4175 | K36: =K35 -> 40122.19 | L36: =F36*50% -> 15509.45 | M36: =F36*350% -> 108566.15 | N36: 0 | O36: =F36*100% -> 31018.9 | P36: 0 | Q36: =F36*10% -> 3101.89 | R36: 20000 | S36: 0 | T36: =SUM(F36:S36) -> 708720.6 | U36: 0 | V36: =T36-U36 -> 708720.6 | W36: 0
A37: PRISCILLA AGWU | D37: MANAGER PROCUREMENT | E37: 15(7) | F37: 31018.9 | G37: 364000 | I37: =F37*300% -> 93056.7 | J37: =F37*7.5% -> 2326.4175 | K37: =K36 -> 40122.19 | L37: =F37*50% -> 15509.45 | M37: =F37*350% -> 108566.15 | N37: 0 | O37: =F37*100% -> 31018.9 | P37: 0 | Q37: =F37*10% -> 3101.89 | R37: 20000 | S37: 0 | T37: =SUM(F37:S37) -> 708720.6 | U37: 0 | V37: =T37-U37 -> 708720.6 | W37: 0
A38: NWOSU MATHEW EZE | D38: MANAGER INT. AUDIT | E38: 15(7) | F38: 31018.9 | G38: 364000 | I38: =F38*300% -> 93056.7 | J38: =F38*7.5% -> 2326.4175 | K38: =K37 -> 40122.19 | L38: =F38*50% -> 15509.45 | M38: =F38*350% -> 108566.15 | N38: 0 | O38: =F38*100% -> 31018.9 | P38: 0 | Q38: =F38*10% -> 3101.89 | R38: 20000 | S38: 0 | T38: =SUM(F38:S38) -> 708720.6 | U38: 0 | V38: =T38-U38 -> 708720.6 | W38: 0
A39: MAGAJI BALA | D39: MANGER ACCOUNTS | E39: 15(7) | F39: 31018.9 | G39: 364000 | I39: =F39*300% -> 93056.7 | J39: =F39*7.5% -> 2326.4175 | K39: =K38 -> 40122.19 | L39: =F39*50% -> 15509.45 | M39: =F39*350% -> 108566.15 | N39: 0 | O39: =F39*100% -> 31018.9 | P39: 0 | Q39: =F39*10% -> 3101.89 | R39: 20000 | S39: 0 | T39: =SUM(F39:S39) -> 708720.6 | U39: 0 | V39: =T39-U39 -> 708720.6 | W39: 0
A40: RAHILA AMOS | D40: OFFICER ACCTS | E40: 10(11) | F40: 18732 | G40: 0 | I40: =F40*300% -> 56196 | J40: =F40*7.5% -> 1404.9 | K40: 0 | L40: =F40*50% -> 9366 | M40: =F40*350% -> 65562 | N40: 0 | O40: =F40*100% -> 18732 | P40: 0 | Q40: =F40*10% -> 1873.2 | R40: 15000 | S40: 0 | T40: =SUM(F40:S40) -> 186866.1 | U40: 0 | V40: =T40-U40 -> 186866.1 | W40: =T40-U40 -> 186866.1
A41: HUSSEIN MUSA AGYE | D41: PROTOCOL OFFICER | E41: 10(7) | F41: 17286.33 | G41: 0 | I41: =F41*300% -> 51858.99 | J41: =F41*7.5% -> 1296.4748 | K41: 0 | L41: =F41*50% -> 8643.165 | M41: =F41*350% -> 60502.155 | N41: 0 | O41: =F41*100% -> 17286.33 | P41: 0 | Q41: =F41*10% -> 1728.633 | R41: 10000 | S41: 0 | T41: =SUM(F41:S41) -> 168602.08 | U41: 0 | V41: =T41-U41 -> 168602.08 | W41: 420602.08
A42: ABDULLAHI YUNUSA | D42: PERSONNEL OFFICER | E42: 10(7) | F42: 17286.33 | G42: 252000 | I42: =F42*300% -> 51858.99 | J42: =F42*7.5% -> 1296.4748 | K42: 0 | L42: =F42*50% -> 8643.165 | M42: =F42*350% -> 60502.155 | N42: 0 | O42: =F42*100% -> 17286.33 | P42: 0 | Q42: =F42*10% -> 1728.633 | R42: 10000 | S42: 0 | T42: =SUM(F42:S42) -> 420602.08 | U42: 0 | V42: =T42-U42 -> 420602.08 | W42: 0
A43: PATIENCE AMUDA BOSAH | D43: PERSONNEL OFFICER | E43: 10(7) | F43: 17286.33 | G43: 252000 | I43: =F43*300% -> 51858.99 | J43: =F43*7.5% -> 1296.4748 | K43: 0 | L43: =F43*50% -> 8643.165 | M43: =F43*350% -> 60502.155 | N43: 0 | O43: =F43*100% -> 17286.33 | P43: 0 | Q43: =F43*10% -> 1728.633 | R43: 10000 | S43: 0 | T43: =SUM(F43:S43) -> 420602.08 | U43: 0 | V43: =T43-U43 -> 420602.08 | W43: 0
A44: MARUF ABDULSALAM | D44: ASSET& MAINT. OFFICER | E44: 10(7) | F44: 17286.33 | G44: 252000 | I44: =F44*300% -> 51858.99 | J44: =F44*7.5% -> 1296.4748 | K44: 0 | L44: =F44*50% -> 8643.165 | M44: =F44*350% -> 60502.155 | N44: 0 | O44: =F44*100% -> 17286.33 | P44: 0 | Q44: =F44*10% -> 1728.633 | R44: 10000 | S44: 0 | T44: =SUM(F44:S44) -> 420602.08 | U44: 0 | V44: =T44-U44 -> 420602.08 | W44: 0
...

Sheet MEMO
A1: NATIONAL INSTITUTE FOR LEGISLATIVE STUDIES
A4: INTERNAL MEMO
A7: FROM : DEPUTY DIRCTOR FINANCE & ACCOUNTS
A8: THROUGH: DIRECTOR, FINANCE & ADMIN.
A9: TO: DIRECTOR GENERAL
A10: DATE: 20TH APRIL, 2012
A12: Subject: Payroll for the Month of April, 2012.
A14: Find below the details of NILS Staff Payroll for the month of April, 2012:
E16: APRIL, 2012 | G16: MARCH, 2012
E17: No of | F17: Amount | G17: No of | H17: Amount
E18: Staff | F18: N | G18: Staff | H18: N
A19: 1 | B19: Director General's Office | E19: ='April 2012'!D17 -> 8 | F19: ='April 2012'!V17 -> 3940365.5 | G19: 1 | H19: ='April 2012'!W17 -> 3361396.6
A20: 2 | B20: Leg. Support Services | E20: ='April 2012'!D22 -> 1 | F20: ='April 2012'!V22 -> 524023.33 | G20: 1 | H20: ='April 2012'!W22 -> 724023.33
A21: 3 | B21: Research & Training | E21: ='April 2012'!D30 -> 5 | F21: ='April 2012'!V30 -> 2213563.2 | G21: 3 | H21: ='April 2012'!W30 -> 2115600.2
A22: 4 | B22: Finance/ Admin & HR | E22: ='April 2012'!D81 -> 48 | F22: ='April 2012'!V81 -> 12124738 | G22: 28 | H22: ='April 2012'!W81 -> 3625456.9
E23: 62 | F23: =SUM(F19:F22) -> 18802690 | G23: =SUM(G19:G22) -> 33 | H23: =SUM(H19:H22) -> 9826477
A25: VARIATION IN APRIL, 2012 OVER MARCH,2012 PAYROLL
A27: NET PAY AS PER APRIL, 2012 PAYROLL | H27: =F23 -> 18802690
A28: NET PAY AS PER MARCH, 2012 PAYROLL | H28: =H23 -> 9826477
A29: NET INCREASE IN PAY FOR MARCH, 2012. | H29: =H27-H28 -> 8976212.8
A32: The net Salary Increase is reconciled as follows:
A33: Net Salary for the month of MARCH, 2012 | H33: =H23 -> 9826477
A34: Appendix A: Payment of Salary to Newly Recruited Staff | G34: =4422057.81-208602.08 -> 4213455.7
A35: Appendix B: 28 Days allowance in Lieu of Accomdation to New Staff | G35: =6244000-252000 -> 5992000
A36: Salary Adjustment for 2 Office Assistants | G36: 34877.66
A37: Effect of Payment of Full Salary to DFA in April | G37: 451879.41
A38: Reducing effect of 28 days allowance in Lieu for March | G38: -616000
A39: Reducing Effect of Research allowance arears in March | G39: -1100000 | H39: =SUM(G34:G39) -> 8976212.8
H40: =H33+H39 -> 18802690
A42: Net Salary for the month of APRIL, 2012 | H42: ='April 2012'!V82 -> 18802690
A44: The Director General is requested to consider and approve payment of N18,802,689.78
A45: being April, 2012 Net Salary Payable to NILS Staff.
A48: Mshelia Madu Ibrahim
A49: Deputy Director, Finance & Accounts

Sheet 17.7
A1: SALARY DETAILS OF NILS DIRECTORS
A2: GRADE LEVEL 17 STEP 7
D3: ANNUALLY | E3: MONTHLY
A4: Basic Salary | D4: =E4*12 -> 916071.6 | E4: =sUMMARY!F3 -> 76339.3
A5: Rent Subsidy | D5: =E5*12 -> 2748214.8 | E5: =sUMMARY!H3 -> 229017.9
A6: Utility | D6: =E6*12 -> 68705.37 | E6: =sUMMARY!I3 -> 5725.4475
A7: Domestic Staff Allowance | D7: =E7*12 -> 962932.56 | E7: =sUMMARY!J3 -> 80244.38
A8: Entertainment Allowance | D8: =E8*12 -> 458035.8 | E8: =sUMMARY!K3 -> 38169.65
A9: Furniture Allowance | D9: =E9*12 -> 3206250.6 | E9: =sUMMARY!L3 -> 267187.55
A10: Motor Fuel Allowance | D10: =E10*12 -> 916071.6 | E10: =sUMMARY!N3 -> 76339.3
A11: Leave Allowance | D11: =E11*12 -> 91607.16 | E11: =sUMMARY!O3 -> 7633.93
A12: Outfit Allowance | D12: =E12*12 -> 240000 | E12: =sUMMARY!P3 -> 20000
A13: GROSS SALARY | D13: =E13*12 -> 9607889.5 | E13: =SUM(E4:E12) -> 800657.46

Sheet 16.7
A1: SALARY DETAILS OF NILS DEPUTY DIRECTORS
A2: GRADE LEVEL 16 STEP 7
D3: ANNUALLY | E3: MONTHLY
A4: Basic Salary | D4: =E4*12 -> 475947 | E4: ='April 2012'!F10 -> 39662.25
A5: Rent Subsidy | D5: =E5*12 -> 1427841 | E5: ='April 2012'!I10 -> 118986.75
A6: Utility | D6: =E6*12 -> 35696.025 | E6: ='April 2012'!J10 -> 2974.6687
A7: Domestic Staff Allowance | D7: =E7*12 -> 481466.28 | E7: ='April 2012'!K10 -> 40122.19
A8: Entertainment Allowance | D8: =E8*12 -> 237973.5 | E8: ='April 2012'!L10 -> 19831.125
A9: Furniture Allowance | D9: =E9*12 -> 1665814.5 | E9: ='April 2012'!M10 -> 138817.88
A10: Motor Fuel Allowance | D10: =E10*12 -> 475947 | E10: ='April 2012'!O10 -> 39662.25
A11: Leave Allowance | D11: =E11*12 -> 47594.7 | E11: ='April 2012'!Q10 -> 3966.225
A12: Outfit Allowance | D12: =E12*12 -> 240000 | E12: =sUMMARY!P3 -> 20000
A13: GROSS SALARY | D13: =E13*12 -> 5088280 | E13: =SUM(E4:E12) -> 424023.33

Sheet 15.9
A1: SALARY DETAILS OF NILS SENIOR RESEARCH FELLOWS
A2: GRADE LEVEL 15 STEP 9
D3: ANNUALLY | E3: MONTHLY
A4: Basic Salary | D4: =E4*12 -> 402090 | E4: ='April 2012'!F27 -> 33507.5
A5: Rent Subsidy | D5: =E5*12 -> 1206270 | E5: ='April 2012'!I27 -> 100522.5
A6: Utility | D6: =E6*12 -> 30156.75 | E6: ='April 2012'!J27 -> 2513.0625
A7: Domestic Staff Allowance | D7: =E7*12 -> 481466.28 | E7: ='April 2012'!K27 -> 40122.19
A8: Entertainment Allowance | D8: =E8*12 -> 201045 | E8: ='April 2012'!L27 -> 16753.75
A9: Furniture Allowance | D9: =E9*12 -> 1407315 | E9: ='April 2012'!M27 -> 117276.25
A10: Motor Fuel Allowance | D10: =E10*12 -> 402090 | E10: ='April 2012'!O27 -> 33507.5
A11: Research Allowance | D11: =E11*12 -> 1200000 | E11: 100000
A12: Leave Allowance | D12: =E12*12 -> 40209 | E12: ='April 2012'!Q27 -> 3350.75
A13: Outfit Allowance | D13: =E13*12 -> 240000 | E13: ='April 2012'!R27 -> 20000
A14: GROSS SALARY | D14: =E14*12 -> 5610642 | E14: =SUM(E4:E13) -> 467553.5

Sheet 13.7
A1: SALARY DETAILS OF NILS ASSISTANT MANAGER
A2: GRADE LEVEL 13 STEP 7
D3: ANNUALLY | E3: MONTHLY
A4: Basic Salary | D4: =E4*12 -> 286693.44 | E4: =sUMMARY!F5 -> 23891.12
A5: Rent Subsidy | D5: =E5*12 -> 860080.32 | E5: =sUMMARY!H5 -> 71673.36
A6: Utility | D6: =E6*12 -> 21502.008 | E6: =sUMMARY!I5 -> 1791.834
A7: Domestic Staff Allowance | D7: =E7*12 -> 0 | E7: =sUMMARY!J5 -> 0
A8: Entertainment Allowance | D8: =E8*12 -> 143346.72 | E8: =sUMMARY!K5 -> 11945.56
A9: Furniture Allowance | D9: =E9*12 -> 1003427 | E9: =sUMMARY!L5 -> 83618.92
A10: Motor Fuel Allowance | D10: =E10*12 -> 286693.44 | E10: =sUMMARY!N5 -> 23891.12
A11: Research Allowance | D11: =E11*12 -> 0 | E11: 0
A12: Leave Allowance | D12: =E12*12 -> 28669.344 | E12: =sUMMARY!O5 -> 2389.112
A13: Outfit Allowance | D13: =E13*12 -> 180000 | E13: =sUMMARY!P5 -> 15000
A14: GROSS SALARY | D14: =E14*12 -> 2810412.3 | E14: =SUM(E4:E13) -> 234201.03

Sheet 12.7
D3: ANNUALLY | E3: MONTHLY
A4: Basic Salary | D4: =E4*12 -> 255527.52 | E4: =sUMMARY!F6 -> 21293.96
A5: Rent Subsidy | D5: =E5*12 -> 766582.56 | E5: =sUMMARY!H6 -> 63881.88
A6: Utility | D6: =E6*12 -> 19164.564 | E6: =sUMMARY!I6 -> 1597.047
A7: Domestic Staff Allowance | D7: =E7*12 -> 0 | E7: =sUMMARY!J5 -> 0
A8: Entertainment Allowance | D8: =E8*12 -> 127763.76 | E8: =sUMMARY!K6 -> 10646.98
A9: Furniture Allowance | D9: =E9*12 -> 894346.32 | E9: =sUMMARY!L6 -> 74528.86
A10: Motor Fuel Allowance | D10: =E10*12 -> 255527.52 | E10: =sUMMARY!N6 -> 21293.96
A11: Leave Allowance | D11: =E11*12 -> 25552.752 | E11: =sUMMARY!O6 -> 2129.396
A12: Outfit Allowance | D12: =E12*12 -> 120000 | E12: =sUMMARY!P6 -> 10000
A13: GROSS SALARY | D13: =E13*12 -> 2464465 | E13: =SUM(E4:E12) -> 205372.08

Sheet 10.7
A1: SALARY DETAILS OF NILS RESEARCH OFFICERS
A2: GRADE LEVEL 10 STEP 7
D3: ANNUALLY | E3: MONTHLY
A4: Basic Salary | D4: =E4*12 -> 207435.96 | E4: =sUMMARY!F7 -> 17286.33
A5: Rent Subsidy | D5: =E5*12 -> 622307.88 | E5: =sUMMARY!H7 -> 51858.99
A6: Utility | D6: =E6*12 -> 15557.697 | E6: =sUMMARY!I7 -> 1296.4748
A7: Domestic Staff Allowance | D7: =E7*12 -> 0 | E7: =sUMMARY!J5 -> 0
A8: Entertainment Allowance | D8: =E8*12 -> 103717.98 | E8: =sUMMARY!K7 -> 8643.165
A9: Furniture Allowance | D9: =E9*12 -> 726025.86 | E9: =sUMMARY!L7 -> 60502.155
A10: Motor Fuel Allowance | D10: =E10*12 -> 207435.96 | E10: =sUMMARY!N7 -> 17286.33
A11: Research Allowance | D11: =E11*12 -> 480000 | E11: 40000
A12: Leave Allowance | D12: =E12*12 -> 20743.596 | E12: =sUMMARY!O7 -> 1728.633
A13: Outfit Allowance | D13: =E13*12 -> 120000 | E13: =sUMMARY!P6 -> 10000
A14: GROSS SALARY | D14: =E14*12 -> 2503224.9 | E14: =SUM(E4:E13) -> 208602.08

Sheet 9.7
A1: SALARY DETAILS OF NILS RESEARCH ASSISTANTS
A2: GRADE LEVEL 9 STEP 7
D3: ANNUALLY | E3: MONTHLY
A4: Basic Salary | D4: =E4*12 -> 176833.68 | E4: =sUMMARY!F8 -> 14736.14
A5: Rent Subsidy | D5: =E5*12 -> 530501.04 | E5: =sUMMARY!H8 -> 44208.42
A6: Utility | D6: =E6*12 -> 13262.526 | E6: =sUMMARY!I8 -> 1105.2105
A7: Domestic Staff Allowance | D7: =E7*12 -> 0 | E7: =sUMMARY!J5 -> 0
A8: Entertainment Allowance | D8: =E8*12 -> 88416.84 | E8: =sUMMARY!K8 -> 7368.07
A9: Furniture Allowance | D9: =E9*12 -> 618917.88 | E9: =sUMMARY!L8 -> 51576.49
A10: Motor Fuel Allowance | D10: =E10*12 -> 176833.68 | E10: =sUMMARY!N8 -> 14736.14
A11: Research Assistants | D11: =E11*12 -> 480000 | E11: 40000
A12: Leave Allowance | D12: =E12*12 -> 17683.368 | E12: =sUMMARY!O8 -> 1473.614
A13: Outfit Allowance | D13: =E13*12 -> 120000 | E13: =sUMMARY!P6 -> 10000
A14: GROSS SALARY | D14: =E14*12 -> 2222449 | E14: =SUM(E4:E13) -> 185204.08

Sheet 8.7
D3: ANNUALLY | E3: MONTHLY
A4: Basic Salary | D4: =E4*12 -> 148223.28 | E4: =sUMMARY!F9 -> 12351.94
A5: Rent Subsidy | D5: =E5*12 -> 444669.84 | E5: =sUMMARY!H9 -> 37055.82
A6: Utility | D6: =E6*12 -> 11116.746 | E6: =sUMMARY!I9 -> 926.3955
A7: Domestic Staff Allowance | D7: =E7*12 -> 0 | E7: =sUMMARY!J5 -> 0
A8: Entertainment Allowance | D8: =E8*12 -> 74111.64 | E8: =sUMMARY!K9 -> 6175.97
A9: Furniture Allowance | D9: =E9*12 -> 518781.48 | E9: =sUMMARY!L9 -> 43231.79
A10: Motor Fuel Allowance | D10: =E10*12 -> 148223.28 | E10: =sUMMARY!N9 -> 12351.94
A11: Leave Allowance | D11: =E11*12 -> 14822.328 | E11: =sUMMARY!O9 -> 1235.194
A12: Outfit Allowance | D12: =E12*12 -> 120000 | E12: =sUMMARY!P6 -> 10000
A13: GROSS SALARY | D13: =E13*12 -> 1479948.6 | E13: =SUM(E4:E12) -> 123329.05

Sheet sUMMARY
F1: BASIC | G1: 28 DAYS ALCE | M1: PERSONAL | N1: MOTOR/ | O1: RESEARCH | P1: LEAVE | Q1: OUT FIT | R1: LEGISLATIVE | S1: GROSS | U1: MAR.2012 | V1: FEB. 2012
F2: SALARY | G2: IN LIEU | H2: RENT | I2: UTILITY | J2: DOMESTIC | K2: ENTERT. | L2: FURNIT. | M2: ASSISTANT | N2: FUEL | O2: ALLOWANCE | P2: ALLCE | Q2: ALLCE | R2: DUTY ALLCE | S2: SALARY | T2: PAYE
A3: DIRECTOR | E3: 17/7 | F3: 76339.3 | H3: =F3*300% -> 229017.9 | I3: =F3*7.5% -> 5725.4475 | J3: 80244.38 | K3: =F3*50% -> 38169.65 | L3: =F3*350% -> 267187.55 | M3: 0 | N3: =F3*100% -> 76339.3 | O3: =F3*10% -> 7633.93 | P3: 20000 | Q3: 0 | R3: =SUM(F3:Q3) -> 800657.46
A4: RESEARCH FELLOW I | E4: 14(7) | F4: 24975.81 | G4: 0 | H4: =F4*300% -> 74927.43 | I4: =F4*7.5% -> 1873.1858 | J4: 0 | K4: =F4*50% -> 12487.905 | L4: =F4*350% -> 87415.335 | M4: 0 | N4: =F4*100% -> 24975.81 | O4: 100000 | P4: =F4*10% -> 2497.581 | Q4: 20000 | R4: 0 | S4: =SUM(F4:R4) -> 349153.06 | T4: 0 | U4: =S4-T4 -> 349153.06 | V4: 344720.6
A5: RESEARCH FELLOW II | E5: 13/7 | F5: 23891.12 | H5: =F5*300% -> 71673.36 | I5: =F5*7.5% -> 1791.834 | J5: 0 | K5: =F5*50% -> 11945.56 | L5: =F5*350% -> 83618.92 | M5: 0 | N5: =F5*100% -> 23891.12 | O5: =F5*10% -> 2389.112 | P5: 15000 | Q5: 0 | R5: =SUM(F5:Q5) -> 234201.03
A6: RESEARCH FELLOW | E6: 12/7 | F6: 21293.96 | H6: =F6*300% -> 63881.88 | I6: =F6*7.5% -> 1597.047 | J6: 0 | K6: =F6*50% -> 10646.98 | L6: =F6*350% -> 74528.86 | M6: 0 | N6: =F6*100% -> 21293.96 | O6: =F6*10% -> 2129.396 | P6: 10000 | Q6: 0 | R6: =SUM(F6:Q6) -> 205372.08
A7: RESEARCH OFFICER | E7: 10/7 | F7: 17286.33 | H7: =F7*300% -> 51858.99 | I7: =F7*7.5% -> 1296.4748 | J7: 0 | K7: =F7*50% -> 8643.165 | L7: =F7*350% -> 60502.155 | M7: 0 | N7: =F7*100% -> 17286.33 | O7: =F7*10% -> 1728.633 | P7: 10000 | Q7: 0 | R7: =SUM(F7:Q7) -> 168602.08
A8: RESEARCH ASSISTANTS | E8: 9/7 | F8: 14736.14 | H8: =F8*300% -> 44208.42 | I8: =F8*7.5% -> 1105.2105 | J8: 0 | K8: =F8*50% -> 7368.07 | L8: =F8*350% -> 51576.49 | M8: 0 | N8: =F8*100% -> 14736.14 | O8: =F8*10% -> 1473.614 | P8: 10000 | Q8: 0 | R8: =SUM(F8:Q8) -> 145204.08
E9: 8/7 | F9: 12351.94 | H9: =F9*300% -> 37055.82 | I9: =F9*7.5% -> 926.3955 | J9: 0 | K9: =F9*50% -> 6175.97 | L9: =F9*350% -> 43231.79 | M9: 0 | N9: =F9*100% -> 12351.94 | O9: =F9*10% -> 1235.194 | P9: 10000 | Q9: 0 | R9: =SUM(F9:Q9) -> 123329.05

Sheet 14.7
A1: SALARY DETAILS OF NILS RESEARCH FELLOW I
A2: GRADE LEVEL 14 STEP 7
D3: ANNUALLY | E3: MONTHLY
A4: Basic Salary | D4: =E4*12 -> 299709.72 | E4: =sUMMARY!F4 -> 24975.81
A5: Rent Subsidy | D5: =E5*12 -> 899129.16 | E5: =sUMMARY!H4 -> 74927.43
A6: Utility | D6: =E6*12 -> 22478.229 | E6: =sUMMARY!I4 -> 1873.1858
A7: Domestic Staff Allowance | D7: =E7*12 -> 0 | E7: =sUMMARY!J5 -> 0
A8: Entertainment Allowance | D8: =E8*12 -> 149854.86 | E8: =sUMMARY!K4 -> 12487.905
A9: Furniture Allowance | D9: =E9*12 -> 1048984 | E9: =sUMMARY!L4 -> 87415.335
A10: Motor Fuel Allowance | D10: =E10*12 -> 299709.72 | E10: =sUMMARY!N4 -> 24975.81
A11: Research Allowance | D11: =E11*12 -> 1200000 | E11: =sUMMARY!O4 -> 100000
A12: Leave Allowance | D12: =E12*12 -> 29970.972 | E12: =sUMMARY!P4 -> 2497.581
A13: Outfit Allowance | D13: =E13*12 -> 240000 | E13: =sUMMARY!Q4 -> 20000
A14: GROSS SALARY | D14: =E14*12 -> 4189836.7 | E14: =SUM(E4:E13) -> 349153.06

Sheet Sheet2
A1: LIST OF STAFF THAT HAVE ASSUMED DUTY
A2: STAFF NAME
D3: DESIGNATION | E3: SALARY
E4: LEVEL
A5: DG OFFICE
A6: DR LADI HAMALAI | D6: DG | E6: CONSOL
A7: PROF. OFFORNZE AMUCHEAZI | D7: LEGAL ADVISER | E7: 16(7)
A8: MOHAMMED ISIAKA YAKUBU | D8: SPECIAL ASSISTANT | E8: 16(7)
A9: RICHARD KWALMI | D9: DSM | E9: 15(7)
A10: ABDULSALAM MUSTAFA | D10: ICT OFFICER | E10: 10(10)
A11: ALI ABDULLAHI | D11: 1CT ASSISTANT | E11: 8(2)
A13: LEG. SUPPORT SEVICES
A14: DR SHUIBU DANWANKA | D14: DD | E14: 16(7)
A16: RESEARCH & TRAINING
A17: DR ASIMIYU G. ABIOLA | D17: DD RESEARCH | E17: 16(7)
A18: SOLOMON A. BENJAMIN | D18: DD TRAINING | E18: 16(7)
A19: DR PATTERSON EKEOCHA | D19: SRF | E19: 15(9)
A21: FINANCE & ADMIN.
A22: DR KABIR AHMED | D22: DFA | E22: 17(7)
A23: IBRAHIM M. MSHELIA | D23: DD F&A | E23: 16(7)
A24: AMINU BELLO DUKKU | D24: DD ADMIN/HR | E24: 16(7)
A25: RAHILA AMOS | D25: OFFICER ACCTS | E25: 10(11)
A26: HUSSEIN MUSA AGYE | D26: PROTOCOL OFFICER | E26: 10(&)
A27: USMAN WAZIRI | D27: SEC. FINANCE | E27: 8(9)
A28: SALAMATU YAKUBU | D28: SECRETARY | E28: 8(9)
A29: IDAHOSA JANE CECILIA | D29: SECRETARY | E29: 8/(9)
A30: ESTHER WAMINAJE | D30: SECRETARY | E30: 8(9)
A31: ANTHONY EDET | D31: RECEPTIONIST | E31: 8(2)
A32: OLATUNJI OYEDELE YUSUF | D32: DRIVER | E32: 4(10)
A33: TASIU MOHAMMED | D33: DRIVER | E33: 4(10)
... A41: ABDULLAHI HARUNA | D41: DRIVER | E41: 3(8)
A42: ABDULWAHAB DAHIRU | D42: DISPATCH CLERK
A43: GIDEON B. LAMIDO | D43: DISPATCH CLERK
A44: JOHN JAMBU ASIGAN | D44: STEWARD
A45: AYUBA SULE | D45: STEWARD
A46: EWELIKWA IJEOMA NKOLIKWA | D46: STEWARD

Sheet 5.7
A1: SALARY DETAILS OF NILS SENIOR MOTOR DRIVER-MECHANIC
A2: GRADE LEVEL 5 STEP 7
D3: ANNUALLY | E3: MONTHLY
A4: Basic Salary | D4: =E4*12 -> #REF! | E4: ='April 2012'!#REF! -> #REF!
A5: Rent Subsidy | D5: =E5*12 -> #REF! | E5: ='April 2012'!#REF! -> #REF!
A6: Utility | D6: =E6*12 -> #REF! | E6: ='April 2012'!#REF! -> #REF!
A7: Domestic Staff Allowance | D7: =E7*12 -> 0 | E7: =sUMMARY!J5 -> 0
A8: Entertainment Allowance | D8: =E8*12 -> #REF! | E8: ='April 2012'!#REF! -> #REF!
A9: Furniture Allowance | D9: =E9*12 -> #REF! | E9: ='April 2012'!#REF! -> #REF!
A10: Motor Fuel Allowance | D10: =E10*12 -> #REF! | E10: ='April 2012'!#REF! -> #REF!
A11: Research Allowance | D11: =E11*12 -> 0 | E11: 0
A12: Leave Allowance | D12: =E12*12 -> #REF! | E12: ='April 2012'!#REF! -> #REF!
A13: Outfit Allowance | D13: =E13*12 -> #REF! | E13: ='April 2012'!#REF! -> #REF!
A14: GROSS SALARY | D14: =E14*12 -> #REF! | E14: =SUM(E4:E13) -> #REF!
