Workbook

Sheet Apr, 14
A3: STAFF PAYROLL FOR THE MONTH OF APRIL, 2014
F4: ='[1]FEB 08'!E8/'[1]FEB 08'!M8 -> 0.22 | I4: ='[1]FEB 08'!F8/'[1]FEB 08'!Q8 -> 0.3
A5: STAFF NAME | T5: DEDUCTIONS | X5: NET SALARY
D6: DESIGNATION | E6: SALARY | F6: BASIC | G6: SALARY | M6: PERSONAL | N6: MOTOR/ | O6: RESEARCH | P6: LEAVE | Q6: OUT FIT | R6: LEGISLATIVE | S6: GROSS | W6: MAR,14 | X6: APR,14
E7: LEVEL | F7: SALARY | G7: AREARS | H7: RENT | I7: UTILITY | J7: DOMESTIC | K7: ENTERT. | L7: FURNIT. | M7: ASSISTANT | N7: FUEL | O7: ALLOWANCE | P7: ALLCE | Q7: ALLCE | R7: DUTY ALLCE | S7: SALARY | T7: SALARY ADV. | U7: PAYE | V7: TOTAL
A8: DG OFFICE | F8: N | I8: N | S8: N | U8: N
A9: DR LADI HAMALAI | D9: DIRECTOR GENERAL | E9: CONSOL | F9: 160488.75 | H9: 320977.5 | I9: 48146.63 | J9: 120366.57 | K9: 72219.94 | L9: 481466.25 | M9: 40122.19 | N9: 120366.57 | O9: 150000 | P9: 16048.88 | Q9: 25000 | R9: 25235 | S9: =SUM(F9:R9) -> 1580438.3 | U9: 113176.97 | V9: =T9+U9 -> 113176.97 | W9: 1467261.3 | X9: =S9-V9 -> 1467261.3
A10: PROF. OFFORNZE AMUCHEAZI | D10: LEGAL ADVISER | E10: 16(8) | F10: =F37 -> 41157.69 | G10: 0 | H10: =H37 -> 123473.07 | I10: =I37 -> 3086.8268 | J10: =J37 -> 40122.19 | K10: =F10*50% -> 20578.845 | L10: =F10*350% -> 144051.92 | M10: 0 | N10: =F10*100% -> 41157.69 | O10: 0 | P10: =F10*10% -> 4115.769 | Q10: 20000 | R10: 100000 | S10: =SUM(F10:R10) -> 537744 | U10: 21618.09 | V10: =T10+U10 -> 21618.09 | W10: 516125.91 | X10: =S10-V10 -> 516125.91
A11: MOHAMMED ISIAKA YAKUBU | D11: HEAD PUBLICATION | E11: 16(8) | F11: =F10 -> 41157.69 | H11: =H10 -> 123473.07 | I11: =I10 -> 3086.8268 | J11: 40122.19 | K11: =F11*50% -> 20578.845 | L11: =F11*350% -> 144051.92 | M11: 0 | N11: =F11*100% -> 41157.69 | O11: 0 | P11: =F11*10% -> 4115.769 | Q11: =Q10 -> 20000 | R11: 0 | S11: =SUM(F11:R11) -> 437744 | T11: 0 | U11: 21618.09 | V11: =T11+U11 -> 21618.09 | W11: 416125.91 | X11: =S11-V11 -> 416125.91
A12: DR MOBOLAJI HAKEEM | D12: SPECIAL ASSISTANT | E12: 16(7) | F12: 39662.25 | G12: 0 | H12: =F12*300% -> 118986.75 | I12: =F12*7.5% -> 2974.6687 | J12: 40122.19 | K12: =F12*50% -> 19831.125 | L12: =F12*350% -> 138817.88 | N12: =F12*100% -> 39662.25 | O12: 100000 | P12: =F12*10% -> 3966.225 | Q12: =Q11 -> 20000 | S12: =SUM(F12:R12) -> 524023.33 | U12: 21618.09 | V12: =T12+U12 -> 21618.09 | W12: 502405.24 | X12: =S12-V12 -> 502405.24
A13: RICHARD KWALMI | D13: MICT | E13: 15(8) | F13: 32263.2 | H13: =F13*300% -> 96789.6 | I13: =F13*7.5% -> 2419.74 | J13: =J9/3 -> 40122.19 | K13: =F13*50% -> 16131.6 | L13: =F13*350% -> 112921.2 | M13: 0 | N13: =F13*100% -> 32263.2 | O13: 0 | P13: =F13*10% -> 3226.32 | Q13: 20000 | R13: 0 | S13: =SUM(F13:R13) -> 356137.05 | T13: 0 | U13: 15548.33 | V13: =T13+U13 -> 15548.33 | W13: 340588.72 | X13: =S13-V13 -> 340588.72
A14: ADAMU ISA ABBA | D14: INFO. MANAGER | E14: 15(8) | F14: 32263.2 | H14: =F14*300% -> 96789.6 | I14: =F14*7.5% -> 2419.74 | J14: 40122.19 | K14: =F14*50% -> 16131.6 | L14: =F14*350% -> 112921.2 | M14: 0 | N14: =F14*100% -> 32263.2 | O14: 0 | P14: =F14*10% -> 3226.32 | Q14: 20000 | R14: 0 | S14: =SUM(F14:R14) -> 356137.05 | U14: 15548.33 | V14: =T14+U14 -> 15548.33 | W14: 340588.72 | X14: =S14-V14 -> 340588.72
A15: NWOSU MATHEW EZE | D15: MANAGER INT. AUDIT | E15: 15(8) | F15: 32263.2 | H15: =F15*300% -> 96789.6 | I15: =F15*7.5% -> 2419.74 | J15: =J16 -> 40122.19 | K15: =F15*50% -> 16131.6 | L15: =F15*350% -> 112921.2 | M15: 0 | N15: =F15*100% -> 32263.2 | O15: 0 | P15: =F15*10% -> 3226.32 | Q15: 20000 | R15: 0 | S15: =SUM(F15:R15) -> 356137.05 | U15: 15548.33 | V15: =T15+U15 -> 15548.33 | W15: 340588.72 | X15: =S15-V15 -> 340588.72
A16: PRISCILLA CHUKWU | D16: MANAGER PROCUREMENT | E16: 15(8) | F16: 32263.2 | H16: =F16*300% -> 96789.6 | I16: =F16*7.5% -> 2419.74 | J16: =J72 -> 40122.19 | K16: =F16*50% -> 16131.6 | L16: =F16*350% -> 112921.2 | M16: 0 | N16: =F16*100% -> 32263.2 | O16: 0 | P16: =F16*10% -> 3226.32 | Q16: 20000 | R16: 0 | S16: =SUM(F16:R16) -> 356137.05 | U16: 15548.33 | V16: =T16+U16 -> 15548.33 | W16: 340588.72 | X16: =S16-V16 -> 340588.72
A17: DR ANAH O. PAMELA | D17: SRF | E17: 15(8) | F17: 32263.2 | H17: =F17*300% -> 96789.6 | I17: =F17*7.5% -> 2419.74 | J17: =J14 -> 40122.19 | K17: =F17*50% -> 16131.6 | L17: =F17*350% -> 112921.2 | M17: 0 | N17: =F17*100% -> 32263.2 | P17: =F17*10% -> 3226.32 | Q17: 20000 | R17: 0 | S17: =SUM(F17:R17) -> 356137.05 | U17: 15548.33 | V17: =U17+T17 -> 15548.33 | W17: 340588.72 | X17: =S17-V17 -> 340588.72
A18: AKINSANMI ADEJOKE OLUKEMI | D18: AM INFORMATION | E18: 13(8) | F18: 23891.12 | H18: =F18*300% -> 71673.36 | I18: =F18*7.5% -> 1791.834 | J18: 0 | K18: =F18*50% -> 11945.56 | L18: =F18*350% -> 83618.92 | M18: 0 | N18: =F18*100% -> 23891.12 | O18: 0 | P18: =F18*10% -> 2389.112 | Q18: 15000 | R18: 0 | S18: =SUM(F18:R18) -> 234201.03 | U18: 7709 | V18: =T18+U18 -> 7709 | W18: 226492.03 | X18: =S18-V18 -> 226492.03
A19: FAROUK U. M ILLO | D19: PA DG | E19: 13(8) | F19: 23891.12 | H19: =F19*300% -> 71673.36 | I19: =F19*7.5% -> 1791.834 | J19: 0 | K19: =F19*50% -> 11945.56 | L19: =F19*350% -> 83618.92 | M19: 0 | N19: =F19*100% -> 23891.12 | O19: 80000 | P19: =F19*10% -> 2389.112 | Q19: 15000 | R19: 0 | S19: =SUM(F19:R19) -> 314201.03 | U19: 7709 | V19: =T19+U19 -> 7709 | W19: 306492.03 | X19: =S19-V19 -> 306492.03
A20: UMOLU ADAEZE OBIAMAKA | D20: INFO OFFICER | E20: 10(8) | F20: 17784 | H20: =F20*300% -> 53352 | I20: =F20*7.5% -> 1333.8 | J20: 0 | K20: =F20*50% -> 8892 | L20: =F20*350% -> 62244 | M20: 0 | N20: =F20*100% -> 17784 | O20: 0 | P20: =F20*10% -> 1778.4 | Q20: 10000 | R20: 0 | S20: =SUM(F20:R20) -> 173168.2 | U20: 3369.51 | V20: =T20+U20 -> 3369.51 | W20: 0 | X20: 0
A21: TONDO IORWUESEEDWARD | D21: OFFICER INT AUDIT | E21: 10(8) | F21: 17784 | H21: =F21*300% -> 53352 | I21: =F21*7.5% -> 1333.8 | J21: 0 | K21: =F21*50% -> 8892 | L21: =F21*350% -> 62244 | M21: 0 | N21: =F21*100% -> 17784 | O21: 0 | P21: =F21*10% -> 1778.4 | Q21: 10000 | R21: 0 | S21: =SUM(F21:R21) -> 173168.2 | U21: 3369.51 | V21: =T21+U21 -> 3369.51 | W21: 169798.69 | X21: =S21-V21 -> 169798.69
A22: BEDARI HARI | D22: LEGAL OFFICER | E22: 10(8) | F22: 17784 | H22: =F22*300% -> 53352 | I22: =F22*7.5% -> 1333.8 | J22: 0 | K22: =F22*50% -> 8892 | L22: =F22*350% -> 62244 | M22: 0 | N22: =F22*100% -> 17784 | O22: 0 | P22: =F22*10% -> 1778.4 | Q22: 10000 | R22: 0 | S22: =SUM(F22:R22) -> 173168.2 | U22: 3369.51 | V22: =T22+U22 -> 3369.51 | W22: 169798.69 | X22: =S22-V22 -> 169798.69
A23: NGARA CHRISTOPHER OCHANJA | B23: NGARA CHRISTOPHER OCHANJA | D23: OFFICER, SPECIAL DUTIES | E23: 10(8) | F23: 17784 | H23: =F23*300% -> 53352 | I23: =F23*7.5% -> 1333.8 | K23: =F23*50% -> 8892 | L23: =F23*350% -> 62244 | N23: =F23*100% -> 17784 | O23: 0 | P23: =F23*10% -> 1778.4 | Q23: 10000 | S23: =SUM(F23:R23) -> 173168.2 | T23: =169798.69/3 -> 56599.563 | U23: 3369.51 | V23: =T23+U23 -> 59969.073 | W23: 113199.13 | X23: =S23-V23 -> 113199.13
A24: JOY HARUNA MAKERI | B24: JOY HARUNA MAKERI | D24: PA DG | E24: 10(8) | F24: 17784 | H24: =F24*300% -> 53352 | I24: =F24*7.5% -> 1333.8 | K24: =F24*50% -> 8892 | L24: =F24*350% -> 62244 | N24: =F24*100% -> 17784 | P24: =F24*10% -> 1778.4 | Q24: 10000 | S24: =SUM(F24:R24) -> 173168.2 | U24: 3369.51 | V24: =T24+U24 -> 3369.51 | W24: 169798.69 | X24: =S24-V24 -> 169798.69
B25: DONALD E. MKPANAM | D25: IT OFFICER | E25: 10(8) | F25: 17784 | H25: =F25*300% -> 53352 | I25: =F25*7.5% -> 1333.8 | K25: =F25*50% -> 8892 | L25: =F25*350% -> 62244 | N25: =F25*100% -> 17784 | P25: =F25*10% -> 1778.4 | Q25: 10000 | S25: =SUM(F25:R25) -> 173168.2 | U25: 3369.51 | V25: =T25+U25 -> 3369.51 | W25: 169798.69 | X25: =S25-V25 -> 169798.69
A26: BASHIRU ABBA WALI | D26: ASSIT. INT. AUDIT | E26: 8(8) | F26: 12732 | H26: =F26*300% -> 38196 | I26: =F26*7.5% -> 954.9 | J26: 0 | K26: =F26*50% -> 6366 | L26: =F26*350% -> 44562 | M26: 0 | N26: =F26*100% -> 12732 | O26: 0 | P26: =F26*10% -> 1273.2 | Q26: 10000 | R26: 0 | S26: =SUM(F26:R26) -> 126816.1 | T26: 0 | U26: 1484.37 | V26: =T26+U26 -> 1484.37 | W26: 125331.73 | X26: =S26-V26 -> 125331.73
A27: ALI ABDULLAHI | D27: 1CT ASSISTANT | E27: 8(8) | F27: 12732 | H27: =F27*300% -> 38196 | I27: =F27*7.5% -> 954.9 | J27: 0 | K27: =F27*50% -> 6366 | L27: =F27*350% -> 44562 | M27: 0 | N27: =F27*100% -> 12732 | O27: 0 | P27: =F27*10% -> 1273.2 | Q27: 10000 | R27: 0 | S27: =SUM(F27:R27) -> 126816.1 | U27: 1484.37 | V27: =T27+U27 -> 1484.37 | W27: 125331.73 | X27: =S27-V27 -> 125331.73
A28: UZODINMA EMMANUEL EZENWA | D28: INFORMATION ASST | E28: 8(8) | F28: 12732 | H28: =F28*300% -> 38196 | I28: =F28*7.5% -> 954.9 | J28: 0 | K28: =F28*50% -> 6366 | L28: =F28*350% -> 44562 | M28: 0 | N28: =F28*100% -> 12732 | O28: 0 | P28: =F28*10% -> 1273.2 | Q28: 10000 | R28: 0 | S28: =SUM(F28:R28) -> 126816.1 | U28: 1484.37 | V28: =T28+U28 -> 1484.37 | W28: 125331.73 | X28: =S28-V28 -> 125331.73
A29: IBRAHIM TASSNEEM | D29: INFORMATION ASST | E29: 8(8) | F29: 12732 | H29: =F29*300% -> 38196 | I29: =F29*7.5% -> 954.9 | J29: 0 | K29: =F29*50% -> 6366 | L29: =F29*350% -> 44562 | M29: 0 | N29: =F29*100% -> 12732 | O29: 0 | P29: =F29*10% -> 1273.2 | Q29: 10000 | R29: 0 | S29: =SUM(F29:R29) -> 126816.1 | U29: 1484.37 | V29: =T29+U29 -> 1484.37 | W29: 125331.73 | X29: =S29-V29 -> 125331.73
A30: GLORIA NDIDI HELG | D30: CONFIDENTIAL SECRETARY | E30: 8(8) | F30: 12732 | G30: 0 | H30: =F30*300% -> 38196 | I30: =F30*7.5% -> 954.9 | J30: 0 | K30: =F30*50% -> 6366 | L30: =F30*350% -> 44562 | M30: 0 | N30: =F30*100% -> 12732 | O30: 0 | P30: =F30*10% -> 1273.2 | Q30: 10000 | R30: 0 | S30: =SUM(F30:R30) -> 126816.1 | T30: =125331.73/3 -> 41777.243 | U30: 1484.37 | V30: =T30+U30 -> 43261.613 | W30: 250663.46 | X30: =S30-V30 -> 83554.487
A31: CHRISTIAN MADUABUCHI ODO | D31: ICT ASSISTANT | E31: 8(8) | F31: 12732 | H31: =F31*300% -> 38196 | I31: =F31*7.5% -> 954.9 | K31: =F31*50% -> 6366 | L31: =F31*350% -> 44562 | N31: =F31*100% -> 12732 | P31: =F31*10% -> 1273.2 | Q31: 10000 | S31: =SUM(F31:R31) -> 126816.1 | U31: 1484.37 | V31: =T31+U31 -> 1484.37 | W31: 125331.73 | X31: =S31-V31 -> 125331.73
A32: TOTAL | D32: 22 | F32: =SUM(F9:F31) -> 674660.62 | G32: =SUM(G9:G31) -> 0 | H32: =SUM(H9:H31) -> 1863493.1 | I32: =SUM(I9:I31) -> 86709.52 | J32: =SUM(J9:J31) -> 441344.09 | K32: =SUM(K9:K31) -> 329305.88 | L32: =SUM(L9:L31) -> 2281067.8 | M32: =SUM(M9:M31) -> 40122.19 | ... X32: =SUM(X9:X31) -> 6640453
V33: =SUM(T33:U33)*0.075 -> 0
V34: =SUM(T34:U34)*0.075 -> 0
A35: LEG. SUPPORT SEVICES | V35: =SUM(T35:U35)*0.075 -> 0
A36: PROF OKECHUKWU OKO | D36: DIR. LEG. SP SERVICES | E36: 17(8) | F36: =F45 -> 79039.64 | H36: =F36*300% -> 237118.92 | I36: =F36*7.5% -> 5927.973 | J36: 80244.38 | K36: =F36*50% -> 39519.82 | L36: =F36*350% -> 276638.74 | M36: 0 | N36: =F36*100% -> 79039.64 | O36: 150000 | P36: =F36*10% -> 7903.964 | Q36: 20000 | R36: 0 | S36: =SUM(F36:R36) -> 975433.08 | U36: 52776.63 | V36: =U36+T36 -> 52776.63 | W36: 922656.45 | X36: =S36-V36 -> 922656.45
A37: DR SHUIBU DANWANKA | D37: DD LEG. SP SERVICES | E37: 16(8) | F37: =F46 -> 41157.69 | H37: =F37*300% -> 123473.07 | I37: =F37*7.5% -> 3086.8268 | J37: =J13 -> 40122.19 | K37: =F37*50% -> 20578.845 | L37: =F37*350% -> 144051.92 | M37: 0 | N37: =F37*100% -> 41157.69 | O37: 100000 | P37: =F37*10% -> 4115.769 | Q37: 20000 | R37: 0 | S37: =SUM(F37:R37) -> 537744 | U37: 21618.09 | V37: =U37+T37 -> 21618.09 | W37: 516125.91 | X37: =S37-V37 -> 516125.91
A38: IBRAHIM USMAN | D38: RESEARCH FELLOW II | E38: 13(8) | F38: 23891.12 | H38: =F38*300% -> 71673.36 | I38: =F38*7.5% -> 1791.834 | J38: =J54 -> 0 | K38: =F38*50% -> 11945.56 | L38: =F38*350% -> 83618.92 | M38: 0 | N38: =F38*100% -> 23891.12 | O38: 80000 | P38: =F38*10% -> 2389.112 | Q38: 15000 | R38: 0 | S38: =SUM(F38:R38) -> 314201.03 | U38: 7709.76 | V38: =U38+T38 -> 7709.76 | W38: 306491.27 | X38: =S38-V38 -> 306491.27
A39: OFORDEME ADAOBI JULIA | D39: RESEARCH OFFICER | E39: 10(8) | F39: 17784 | H39: =F39*300% -> 53352 | I39: =F39*7.5% -> 1333.8 | J39: 0 | K39: =F39*50% -> 8892 | L39: =F39*350% -> 62244 | M39: 0 | N39: =F39*100% -> 17784 | O39: 40000 | P39: =F39*10% -> 1778.4 | Q39: 10000 | R39: 0 | S39: =SUM(F39:R39) -> 213168.2 | U39: 3369.51 | V39: =U39+T39 -> 3369.51 | W39: 209798.69 | X39: =S39-V39 -> 209798.69
A40: IKPEAZU CHINEDU ANITA | B40: IKPEAZU CHINEDU ANITA | D40: RESEARCH OFFICER | E40: 10(8) | F40: 17784 | H40: =F40*300% -> 53352 | I40: =F40*7.5% -> 1333.8 | J40: 0 | K40: =F40*50% -> 8892 | L40: =F40*350% -> 62244 | M40: 0 | N40: =F40*100% -> 17784 | O40: 40000 | P40: =F40*10% -> 1778.4 | Q40: 10000 | R40: 0 | S40: =SUM(F40:R40) -> 213168.2 | U40: 3369.51 | V40: =U40+T40 -> 3369.51 | W40: 209798.69 | X40: =S40-V40 -> 209798.69
A41: ONYEAKU CHUKWUKA EDMOND | D41: RESEARCH ASSISTANT | E41: 9(8) | F41: 15188.67 | H41: =F41*300% -> 45566.01 | I41: =F41*7.5% -> 1139.1502 | J41: =J27 -> 0 | K41: =F41*50% -> 7594.335 | L41: =F41*350% -> 53160.345 | M41: 0 | N41: =F41*100% -> 15188.67 | O41: 40000 | P41: =F41*10% -> 1518.867 | Q41: 10000 | R41: 0 | S41: =SUM(F41:R41) -> 189356.05 | T41: 0 | U41: 2443.88 | V41: =U41+T41 -> 2443.88 | W41: 186912.17 | X41: =S41-V41 -> 186912.17
A42: TOTAL | D42: 6 | F42: =SUM(F36:F41) -> 194845.12 | G42: =SUM(G36:G41) -> 0 | H42: =SUM(H36:H41) -> 584535.36 | I42: =SUM(I36:I41) -> 14613.384 | J42: =SUM(J36:J41) -> 120366.57 | K42: =SUM(K36:K41) -> 97422.56 | L42: =SUM(L36:L41) -> 681957.92 | M42: =SUM(M36:M41) -> 0 | ... X42: =SUM(X36:X41) -> 2351783.2
...

Sheet Sheet4
A1: S/N | B1: NAMES | E1: AMOUNT
A2: 1 | B2: PROF OKECHUKWU OKO | E2: 120000
A3: 2 | B3: DR KABIR AHMED | E3: 120000
A4: 3 | B4: DR BADAYI M. SANI | E4: 120000
A5: 4 | B5: PROF. OFFORNZE AMUCHEAZI | E5: 60000
A6: 5 | B6: DR ASIMIYU G. ABIOLA | E6: 60000
A7: 6 | B7: DR SHUIBU DANWANKA | E7: 60000
A8: 7 | B8: IBRAHIM M. MSHELIA | E8: 60000
A9: 8 | B9: AMINU BELLO DUKKU | E9: 60000
A10: 9 | B10: DR ANAH O. PAMELA | E10: 30000
A11: 10 | B11: MAGAJI BALA | E11: 30000
A12: 11 | B12: RAHILA AMOS | E12: 30000
A13: 12 | B13: DR KANAYO OGUJIUBA | E13: 30000
... A23: 22 | B23: BASHIR A. WALI | E23: 20000
E24: =SUM(E2:E23) -> 1000000

Sheet MEMO
A1: NATIONAL INSTITUTE FOR LEGISLATIVE STUDIES
A4: INTERNAL MEMO
A6: FROM : DDF
A7: THROUGH: DFA
A8: TO: DG
A9: DATE: 21ST MARCH, 2014
A11: Subject: Payroll for the Month of March, 2014
A13: Find below the details of NILS Staff Payroll for the month of March, 2014:
E15: FEBRUARY, 2014 | G15: MARCH, 2014
E16: NO OF | F16: AMOUNT | G16: NO OF | H16: AMOUNT
E17: STAFF | F17: N | G17: STAFF | H17: N
A18: 1 | B18: Director General's Office | E18: 22 | F18: ='Apr, 14'!W32 -> 6807562 | G18: 22 | H18: ='Apr, 14'!X32 -> 6640453
A19: 2 | B19: Leg. Support Services | E19: 6 | F19: ='Apr, 14'!W42 -> 2351783.2 | G19: 6 | H19: ='Apr, 14'!X42 -> 2351783.2
A20: 3 | B20: Research & Training | E20: 20 | F20: ='Apr, 14'!W66 -> 6143265.7 | G20: 20 | H20: ='Apr, 14'!X66 -> 5772198.5
A21: 4 | B21: Finance/ Admin & HR | E21: 41 | F21: ='Apr, 14'!W110 -> 8532323.5 | G21: 41 | H21: ='Apr, 14'!X110 -> 5813967.4
A22: 5 | B22: Casual Staff/NYSC | E22: 12 | F22: ='Apr, 14'!W125 -> 720000 | G22: 12 | H22: ='Apr, 14'!X125 -> 720000
A23: 6 | B23: NASS/ Deployed Staff | E23: 11 | F23: ='Apr, 14'!W140 -> 1965634.3 | G23: 11 | H23: ='Apr, 14'!X140 -> 1965634.2
E24: =SUM(E18:E23) -> 112 | F24: =SUM(F18:F23) -> 26520569 | G24: =SUM(G18:G23) -> 112 | H24: =SUM(H18:H23) -> 23264036
A26: VARIATION INMARCH, 2014 OVER FEBRUARY, 2014 SALARIES
A28: NET PAY AS PER MARCH, 2014 PAYROLL | H28: =H24 -> 23264036
A29: NET PAY AS PER FEBRUARY, 2014 PAYROLL | H29: =F24 -> 26520569
A30: NET INCREASE/ (DECREASE) IN PAY FOR MARCH, 2014 | H30: =H28-H29 -> -3256532.3
A32: The net Salary Increase is reconciled as follows:
A33: Removal Efect of Jan 23rd to 31st prorated allowance added to Feb 2014 Salary to re deployed staff to Research Division | G33: 0
A35: Removal Effect of Payment of 13th Month Salary to Training and Finance Divisions | G35: =-2803643.08+219.78 -> -2803423.3
A36: Removal Effect of Prof Edet Akpakpan on completion of Sabatical | G36: -630962.12
A37: Effect of Payment of New Sabatical Staff Prof, Rotimi Suberu | G37: 630962.12
A38: Net Effect of Conversion of Driver from Casual to Permanent Staff | G38: 0
A39: Removal Effect of 28 Days Allow in Lieu of Accomodation to LA Secretary | G39: -252000
A40: Removal Effect of 28 Days allow in lieu of Accomodation to Driver on Conversion | G40: -84000
A41: Effect of Stoppage of Salary Advance to Yunusa Abdullahi | G41: 0
A42: Effect of Salary Advance Recovery to Dr Charles Anumudu | G42: 0
A43: Effect of Salary Recovery to Driver as Deterent | G43: 0
A44: Removal Effect of Payment of Salary Advance to Gloria Helg | G44: -125331.73
A45: Effect of Payment of Legislative Duty allowance to Jake Danazumi | G45: 50000
A46: Effect of Salary Advance Recovery from Gloria | G46: -41777.24
H47: =SUM(G33:G46) -> -3256532.3 | I47: =H30-H47 -> -0.0036666682
A49: The Director General is requested to consider and approve payment of N23,264,036.36 to FIRST BANK being March, 2014 Salary and N763,137.21 being March, 2014 PAYE TAX Deductions from Staff Salary.
A52: Mshelia Madu Ibrahim
A53: Deputy Director, Finance & Accounts

Sheet 17.9
A1: SALARY DETAILS OF NILS DIRECTOR RESEARCH AND TRAINING
A2: GRADE LEVEL 17 STEP 7
D3: ANNUALLY | E3: MONTHLY
A4: Basic Salary | D4: =E4*12 -> 948475.68 | E4: =sUMMARY!F3 -> 79039.64
A5: Rent Subsidy | D5: =E5*12 -> 2845427 | E5: =sUMMARY!H3 -> 237118.92
A6: Utility | D6: =E6*12 -> 71135.676 | E6: =sUMMARY!I3 -> 5927.973
A7: Domestic Staff Allowance | D7: =E7*12 -> 962932.56 | E7: =sUMMARY!J3 -> 80244.38
A8: Entertainment Allowance | D8: =E8*12 -> 474237.84 | E8: =sUMMARY!K3 -> 39519.82
A9: Furniture Allowance | D9: =E9*12 -> 3319664.9 | E9: =sUMMARY!L3 -> 276638.74
A10: Research Allowance | D10: =E10*12 -> 0
A11: Motor Fuel Allowance | D11: =E11*12 -> 948475.68 | E11: =sUMMARY!N3 -> 79039.64
A12: Leave Allowance | D12: =E12*12 -> 94847.568 | E12: =sUMMARY!O3 -> 7903.964
A13: Outfit Allowance | D13: =E13*12 -> 240000 | E13: =sUMMARY!P3 -> 20000
A14: GROSS SALARY | D14: =E14*12 -> 9905196.9 | E14: =SUM(E4:E13) -> 825433.08

Sheet 16.9
A1: SALARY DETAILS OF NILS DEPUTY DIRECTORS
A2: GRADE LEVEL 16 STEP 7
D3: ANNUALLY | E3: MONTHLY
A4: Basic Salary | D4: =E4*12 -> 493892.28 | E4: ='Apr, 14'!F10 -> 41157.69
A5: Rent Subsidy | D5: =E5*12 -> 1481676.8 | E5: ='Apr, 14'!H10 -> 123473.07
A6: Utility | D6: =E6*12 -> 37041.921 | E6: ='Apr, 14'!I10 -> 3086.8268
A7: Domestic Staff Allowance | D7: =E7*12 -> 481466.28 | E7: ='Apr, 14'!J10 -> 40122.19
A8: Entertainment Allowance | D8: =E8*12 -> 246946.14 | E8: ='Apr, 14'!K10 -> 20578.845
A9: Furniture Allowance | D9: =E9*12 -> 1728623 | E9: ='Apr, 14'!L10 -> 144051.92
A10: Motor Fuel Allowance | D10: =E10*12 -> 493892.28 | E10: ='Apr, 14'!N10 -> 41157.69
A11: Leave Allowance | D11: =E11*12 -> 49389.228 | E11: ='Apr, 14'!P10 -> 4115.769
A12: Outfit Allowance | D12: =E12*12 -> 240000 | E12: =sUMMARY!P3 -> 20000
A13: GROSS SALARY | D13: =E13*12 -> 5252927.9 | E13: =SUM(E4:E12) -> 437744

Sheet 15.9
A1: SALARY DETAILS OF NILS SENIOR RESEARCH FELLOWS
A2: GRADE LEVEL 15 STEP 9
D3: ANNUALLY | E3: MONTHLY
A4: Basic Salary | D4: =E4*12 -> #REF! | E4: ='Apr, 14'!#REF! -> #REF!
A5: Rent Subsidy | D5: =E5*12 -> #REF! | E5: ='Apr, 14'!#REF! -> #REF!
A6: Utility | D6: =E6*12 -> #REF! | E6: ='Apr, 14'!#REF! -> #REF!
A7: Domestic Staff Allowance | D7: =E7*12 -> #REF! | E7: ='Apr, 14'!#REF! -> #REF!
A8: Entertainment Allowance | D8: =E8*12 -> #REF! | E8: ='Apr, 14'!#REF! -> #REF!
A9: Furniture Allowance | D9: =E9*12 -> #REF! | E9: ='Apr, 14'!#REF! -> #REF!
A10: Motor Fuel Allowance | D10: =E10*12 -> #REF! | E10: ='Apr, 14'!#REF! -> #REF!
A11: Research Allowance | D11: =E11*12 -> 1200000 | E11: 100000
A12: Leave Allowance | D12: =E12*12 -> #REF! | E12: ='Apr, 14'!#REF! -> #REF!
A13: Outfit Allowance | D13: =E13*12 -> #REF! | E13: ='Apr, 14'!#REF! -> #REF!
A14: GROSS SALARY | D14: =E14*12 -> #REF! | E14: =SUM(E4:E13) -> #REF!

Sheet 13.7
A1: SALARY DETAILS OF NILS ASSISTANT MANAGER
A2: GRADE LEVEL 13 STEP 7
D3: ANNUALLY | E3: MONTHLY
A4: Basic Salary | D4: =E4*12 -> 286693.44 | E4: =sUMMARY!F6 -> 23891.12
A5: Rent Subsidy | D5: =E5*12 -> 860080.32 | E5: =sUMMARY!H6 -> 71673.36
A6: Utility | D6: =E6*12 -> 21502.008 | E6: =sUMMARY!I6 -> 1791.834
A7: Domestic Staff Allowance | D7: =E7*12 -> 0 | E7: =sUMMARY!J6 -> 0
A8: Entertainment Allowance | D8: =E8*12 -> 143346.72 | E8: =sUMMARY!K6 -> 11945.56
A9: Furniture Allowance | D9: =E9*12 -> 1003427 | E9: =sUMMARY!L6 -> 83618.92
A10: Motor Fuel Allowance | D10: =E10*12 -> 286693.44 | E10: =sUMMARY!N6 -> 23891.12
A11: Research Allowance | D11: =E11*12 -> 0 | E11: 0
A12: Leave Allowance | D12: =E12*12 -> 28669.344 | E12: =sUMMARY!O6 -> 2389.112
A13: Outfit Allowance | D13: =E13*12 -> 180000 | E13: =sUMMARY!P6 -> 15000
A14: GROSS SALARY | D14: =E14*12 -> 2810412.3 | E14: =SUM(E4:E13) -> 234201.03

Sheet 12.7
D3: ANNUALLY | E3: MONTHLY
A4: Basic Salary | D4: =E4*12 -> 255527.52 | E4: =sUMMARY!F7 -> 21293.96
A5: Rent Subsidy | D5: =E5*12 -> 766582.56 | E5: =sUMMARY!H7 -> 63881.88
A6: Utility | D6: =E6*12 -> 19164.564 | E6: =sUMMARY!I7 -> 1597.047
A7: Domestic Staff Allowance | D7: =E7*12 -> 0 | E7: =sUMMARY!J6 -> 0
A8: Entertainment Allowance | D8: =E8*12 -> 127763.76 | E8: =sUMMARY!K7 -> 10646.98
A9: Furniture Allowance | D9: =E9*12 -> 894346.32 | E9: =sUMMARY!L7 -> 74528.86
A10: Motor Fuel Allowance | D10: =E10*12 -> 255527.52 | E10: =sUMMARY!N7 -> 21293.96
A11: Leave Allowance | D11: =E11*12 -> 25552.752 | E11: =sUMMARY!O7 -> 2129.396
A12: Outfit Allowance | D12: =E12*12 -> 120000 | E12: =sUMMARY!P7 -> 10000
A13: GROSS SALARY | D13: =E13*12 -> 2464465 | E13: =SUM(E4:E12) -> 205372.08

Sheet 10.7
A1: SALARY DETAILS OF NILS OFFICERS
A2: GRADE LEVEL 10 STEP 7
D3: ANNUALLY | E3: MONTHLY
A4: Basic Salary | D4: =E4*12 -> 207435.96 | E4: =sUMMARY!F8 -> 17286.33
A5: Rent Subsidy | D5: =E5*12 -> 622307.88 | E5: =sUMMARY!H8 -> 51858.99
A6: Utility | D6: =E6*12 -> 15557.697 | E6: =sUMMARY!I8 -> 1296.4748
A7: Domestic Staff Allowance | D7: =E7*12 -> 0 | E7: =sUMMARY!J6 -> 0
A8: Entertainment Allowance | D8: =E8*12 -> 103717.98 | E8: =sUMMARY!K8 -> 8643.165
A9: Furniture Allowance | D9: =E9*12 -> 726025.86 | E9: =sUMMARY!L8 -> 60502.155
A10: Motor Fuel Allowance | D10: =E10*12 -> 207435.96 | E10: =sUMMARY!N8 -> 17286.33
A11: Research Allowance | D11: =E11*12 -> 0 | E11: 0
A12: Leave Allowance | D12: =E12*12 -> 20743.596 | E12: =sUMMARY!O8 -> 1728.633
A13: Outfit Allowance | D13: =E13*12 -> 120000 | E13: =sUMMARY!P7 -> 10000
A14: GROSS SALARY | D14: =E14*12 -> 2023224.9 | E14: =SUM(E4:E13) -> 168602.08

Sheet 9.7
A1: SALARY DETAILS OF NILS RESEARCH ASSISTANTS
A2: GRADE LEVEL 9 STEP 7
D3: ANNUALLY | E3: MONTHLY
A4: Basic Salary | D4: =E4*12 -> 176833.68 | E4: =sUMMARY!F9 -> 14736.14
A5: Rent Subsidy | D5: =E5*12 -> 530501.04 | E5: =sUMMARY!H9 -> 44208.42
A6: Utility | D6: =E6*12 -> 13262.526 | E6: =sUMMARY!I9 -> 1105.2105
A7: Domestic Staff Allowance | D7: =E7*12 -> 0 | E7: =sUMMARY!J6 -> 0
A8: Entertainment Allowance | D8: =E8*12 -> 88416.84 | E8: =sUMMARY!K9 -> 7368.07
A9: Furniture Allowance | D9: =E9*12 -> 618917.88 | E9: =sUMMARY!L9 -> 51576.49
A10: Motor Fuel Allowance | D10: =E10*12 -> 176833.68 | E10: =sUMMARY!N9 -> 14736.14
A11: Research Assistants | D11: =E11*12 -> 480000 | E11: 40000
A12: Leave Allowance | D12: =E12*12 -> 17683.368 | E12: =sUMMARY!O9 -> 1473.614
A13: Outfit Allowance | D13: =E13*12 -> 120000 | E13: =sUMMARY!P7 -> 10000
A14: GROSS SALARY | D14: =E14*12 -> 2222449 | E14: =SUM(E4:E13) -> 185204.08

Sheet 8.7
A1: SALARY OF SECRTARY ON SCALE 8 STEP 7
D3: ANNUALLY | E3: MONTHLY
A4: Basic Salary | D4: =E4*12 -> 176833.68 | E4: ='Apr, 14'!F64 -> 14736.14
A5: Rent Subsidy | D5: =E5*12 -> 458352 | E5: ='Apr, 14'!H82 -> 38196
A6: Utility | D6: =E6*12 -> 11458.8 | E6: ='Apr, 14'!I87 -> 954.9
A7: Entertainment Allowance | D7: =E7*12 -> 76392 | E7: ='Apr, 14'!K83 -> 6366
A8: Furniture Allowance | D8: =E8*12 -> 534744 | E8: ='Apr, 14'!L82 -> 44562
A9: Motor Fuel Allowance | D9: =E9*12 -> 152784 | E9: ='Apr, 14'!N83 -> 12732
A10: Leave Allowance | D10: =E10*12 -> 17683.368 | E10: ='Apr, 14'!P65 -> 1473.614
A11: Outfit Allowance | D11: =E11*12 -> 120000 | E11: ='Apr, 14'!Q83 -> 10000
A12: GROSS SALARY | D12: =E12*12 -> 1548247.8 | E12: =SUM(E4:E11) -> 129020.65

Sheet sUMMARY
F1: BASIC | G1: 28 DAYS ALCE | M1: PERSONAL | N1: MOTOR/ | O1: RESEARCH | P1: LEAVE | Q1: OUT FIT | R1: LEGISLATIVE | S1: GROSS | U1: MAR.2012 | V1: FEB. 2012
F2: SALARY | G2: IN LIEU | H2: RENT | I2: UTILITY | J2: DOMESTIC | K2: ENTERT. | L2: FURNIT. | M2: ASSISTANT | N2: FUEL | O2: ALLOWANCE | P2: ALLCE | Q2: ALLCE | R2: DUTY ALLCE | S2: SALARY | T2: PAYE
A3: DIRECTOR | E3: 17/8 | F3: 79039.64 | H3: =F3*300% -> 237118.92 | I3: =F3*7.5% -> 5927.973 | J3: 80244.38 | K3: =F3*50% -> 39519.82 | L3: =F3*350% -> 276638.74 | M3: 0 | N3: =F3*100% -> 79039.64 | O3: =F3*10% -> 7903.964 | P3: 20000 | Q3: 0 | R3: =SUM(F3:Q3) -> 825433.08
A4: DEPUTY DIRECTOR | E4: 16/8 | F4: 36784.71 | H4: =F4*300% -> 110354.13 | I4: =F4*7.5% -> 2758.8532 | J4: 80244.38 | K4: =F4*50% -> 18392.355 | L4: =F4*350% -> 128746.49 | N4: =F4*100% -> 36784.71 | O4: =F4*10% -> 3678.471 | P4: 20000 | Q4: 0 | R4: =SUM(F4:Q4) -> 437744.09
A5: RESEARCH FELLOW I | E5: 14(7) | F5: 24975.81 | G5: 0 | H5: =F5*300% -> 74927.43 | I5: =F5*7.5% -> 1873.1858 | J5: 0 | K5: =F5*50% -> 12487.905 | L5: =F5*350% -> 87415.335 | M5: 0 | N5: =F5*100% -> 24975.81 | O5: 100000 | P5: =F5*10% -> 2497.581 | Q5: 20000 | R5: 0 | S5: =SUM(F5:R5) -> 349153.06 | T5: 0 | U5: =S5-T5 -> 349153.06 | V5: 344720.6
A6: RESEARCH FELLOW II | E6: 13/7 | F6: 23891.12 | H6: =F6*300% -> 71673.36 | I6: =F6*7.5% -> 1791.834 | J6: 0 | K6: =F6*50% -> 11945.56 | L6: =F6*350% -> 83618.92 | M6: 0 | N6: =F6*100% -> 23891.12 | O6: =F6*10% -> 2389.112 | P6: 15000 | Q6: 0 | R6: =SUM(F6:Q6) -> 234201.03
A7: RESEARCH FELLOW | E7: 12/7 | F7: 21293.96 | H7: =F7*300% -> 63881.88 | I7: =F7*7.5% -> 1597.047 | J7: 0 | K7: =F7*50% -> 10646.98 | L7: =F7*350% -> 74528.86 | M7: 0 | N7: =F7*100% -> 21293.96 | O7: =F7*10% -> 2129.396 | P7: 10000 | Q7: 0 | R7: =SUM(F7:Q7) -> 205372.08
A8: RESEARCH OFFICER | E8: 10/7 | F8: 17286.33 | H8: =F8*300% -> 51858.99 | I8: =F8*7.5% -> 1296.4748 | J8: 0 | K8: =F8*50% -> 8643.165 | L8: =F8*350% -> 60502.155 | M8: 0 | N8: =F8*100% -> 17286.33 | O8: =F8*10% -> 1728.633 | P8: 10000 | Q8: 0 | R8: =SUM(F8:Q8) -> 168602.08
A9: RESEARCH ASSISTANTS | E9: 9/7 | F9: 14736.14 | H9: =F9*300% -> 44208.42 | I9: =F9*7.5% -> 1105.2105 | J9: 0 | K9: =F9*50% -> 7368.07 | L9: =F9*350% -> 51576.49 | M9: 0 | N9: =F9*100% -> 14736.14 | O9: =F9*10% -> 1473.614 | P9: 10000 | Q9: 0 | R9: =SUM(F9:Q9) -> 145204.08
E10: 8/7 | F10: 12351.94 | H10: =F10*300% -> 37055.82 | I10: =F10*7.5% -> 926.3955 | J10: 0 | K10: =F10*50% -> 6175.97 | L10: =F10*350% -> 43231.79 | M10: 0 | N10: =F10*100% -> 12351.94 | O10: =F10*10% -> 1235.194 | P10: 10000 | Q10: 0 | R10: =SUM(F10:Q10) -> 123329.05

Sheet 14.7
A1: SALARY DETAILS OF NILS RESEARCH FELLOW I
A2: GRADE LEVEL 14 STEP 7
D3: ANNUALLY | E3: MONTHLY
A4: Basic Salary | D4: =E4*12 -> 299709.72 | E4: =sUMMARY!F5 -> 24975.81
A5: Rent Subsidy | D5: =E5*12 -> 899129.16 | E5: =sUMMARY!H5 -> 74927.43
A6: Utility | D6: =E6*12 -> 22478.229 | E6: =sUMMARY!I5 -> 1873.1858
A7: Domestic Staff Allowance | D7: =E7*12 -> 0 | E7: =sUMMARY!J6 -> 0
A8: Entertainment Allowance | D8: =E8*12 -> 149854.86 | E8: =sUMMARY!K5 -> 12487.905
A9: Furniture Allowance | D9: =E9*12 -> 1048984 | E9: =sUMMARY!L5 -> 87415.335
A10: Motor Fuel Allowance | D10: =E10*12 -> 299709.72 | E10: =sUMMARY!N5 -> 24975.81
A11: Research Allowance | D11: =E11*12 -> 1200000 | E11: =sUMMARY!O5 -> 100000
A12: Leave Allowance | D12: =E12*12 -> 29970.972 | E12: =sUMMARY!P5 -> 2497.581
A13: Outfit Allowance | D13: =E13*12 -> 240000 | E13: =sUMMARY!Q5 -> 20000
A14: GROSS SALARY | D14: =E14*12 -> 4189836.7 | E14: =SUM(E4:E13) -> 349153.06

Sheet Sheet2
A1: LIST OF STAFF THAT HAVE ASSUMED DUTY
A2: STAFF NAME
D3: DESIGNATION | E3: SALARY
E4: LEVEL
A5: DG OFFICE
A6: DR LADI HAMALAI | D6: DG | E6: CONSOL
A7: PROF. OFFORNZE AMUCHEAZI | D7: LEGAL ADVISER | E7: 16(7)
A8: MOHAMMED ISIAKA YAKUBU | D8: SPECIAL ASSISTANT | E8: 16(7)
A9: RICHARD KWALMI | D9: DSM | E9: 15(7)
A10: ABDULSALAM MUSTAFA | D10: ICT OFFICER | E10: 10(10)
A11: ALI ABDULLAHI | D11: 1CT ASSISTANT | E11: 8(2)
A13: LEG. SUPPORT SEVICES
A14: DR SHUIBU DANWANKA | D14: DD | E14: 16(7)
A16: RESEARCH & TRAINING
A17: DR ASIMIYU G. ABIOLA | D17: DD RESEARCH | E17: 16(7)
A18: SOLOMON A. BENJAMIN | D18: DD TRAINING | E18: 16(7)
A19: DR PATTERSON EKEOCHA | D19: SRF | E19: 15(9)
A21: FINANCE & ADMIN.
A22: DR KABIR AHMED | D22: DFA | E22: 17(7)
A23: IBRAHIM M. MSHELIA | D23: DD F&A | E23: 16(7)
A24: AMINU BELLO DUKKU | D24: DD ADMIN/HR | E24: 16(7)
A25: RAHILA AMOS | D25: OFFICER ACCTS | E25: 10(11)
A26: HUSSEIN MUSA AGYE | D26: PROTOCOL OFFICER | E26: 10(&)
A27: USMAN WAZIRI | D27: SEC. FINANCE | E27: 8(9)
A28: SALAMATU YAKUBU | D28: SECRETARY | E28: 8(9)
A29: IDAHOSA JANE CECILIA | D29: SECRETARY | E29: 8/(9)
A30: ESTHER WAMINAJE | D30: SECRETARY | E30: 8(9)
A31: ANTHONY EDET | D31: RECEPTIONIST | E31: 8(2)
A32: OLATUNJI OYEDELE YUSUF | D32: DRIVER | E32: 4(10)
A33: TASIU MOHAMMED | D33: DRIVER | E33: 4(10)
... A41: ABDULLAHI HARUNA | D41: DRIVER | E41: 3(8)
A42: ABDULWAHAB DAHIRU | D42: DISPATCH CLERK
A43: GIDEON B. LAMIDO | D43: DISPATCH CLERK
A44: JOHN JAMBU ASIGAN | D44: STEWARD
A45: AYUBA SULE | D45: STEWARD
A46: EWELIKWA IJEOMA NKOLIKWA | D46: STEWARD

Sheet 5.7
A1: SALARY DETAILS OF NILS SENIOR MOTOR DRIVER-MECHANIC
A2: GRADE LEVEL 5 STEP 7
D3: ANNUALLY | E3: MONTHLY
A4: Basic Salary | D4: =E4*12 -> #REF! | E4: ='Apr, 14'!#REF! -> #REF!
A5: Rent Subsidy | D5: =E5*12 -> #REF! | E5: ='Apr, 14'!#REF! -> #REF!
A6: Utility | D6: =E6*12 -> #REF! | E6: ='Apr, 14'!#REF! -> #REF!
A7: Domestic Staff Allowance | D7: =E7*12 -> 0 | E7: =sUMMARY!J6 -> 0
A8: Entertainment Allowance | D8: =E8*12 -> #REF! | E8: ='Apr, 14'!#REF! -> #REF!
A9: Furniture Allowance | D9: =E9*12 -> #REF! | E9: ='Apr, 14'!#REF! -> #REF!
A10: Motor Fuel Allowance | D10: =E10*12 -> #REF! | E10: ='Apr, 14'!#REF! -> #REF!
A11: Research Allowance | D11: =E11*12 -> 0 | E11: 0
A12: Leave Allowance | D12: =E12*12 -> #REF! | E12: ='Apr, 14'!#REF! -> #REF!
A13: Outfit Allowance | D13: =E13*12 -> #REF! | E13: ='Apr, 14'!#REF! -> #REF!
A14: GROSS SALARY | D14: =E14*12 -> #REF! | E14: =SUM(E4:E13) -> #REF!

Sheet Noninal roll
A2: NOMINAL ROLL AND 2012 PERSONEL COST ESTIMATION
A3: S/NO | B3: DESIGNATION | C3: SALARY LEVEL | D3: NUMBER | E3: ANNUAL SALARY | F3: TOTAL
A5: 1 | B5: DIRECTOR GENERAL | C5: CONS. | D5: 1 | E5: =1580439.5*12 -> 18965274 | F5: =E5*D5 -> 18965274
A6: 2 | B6: DIRECTORS | C6: 17(7) | D6: 4 | E6: 9607889.5 | F6: =E6*D6 -> 38431558
A7: 3 | B7: LEGAL ADVISER | C7: 16(7) | D7: 1 | E7: =424023.33*12 -> 5088280 | F7: =E7*D7 -> 5088280
A8: 4 | B8: SPECIAL ASSISTANT | C8: 16(7) | D8: 2 | E8: =424023.33*12 -> 5088280 | F8: =E8*D8 -> 10176560
A9: 5 | B9: DEUTY DIRECTORS | C9: 16(7) | D9: 10 | E9: 5088280 | F9: =E9*D9 -> 50882800
A10: 6 | B10: SENIOR RESEARCH FELLOWS | C10: 16(7) | D10: 10 | E10: 4136647.2 | F10: =E10*D10 -> 41366472
A11: 7 | B11: MANAGERS | C11: 15(7) | D11: 12 | E11: =344720.6*12 -> 4136647.2 | F11: =E11*D11 -> 49639766
A12: 8 | B12: RESEARCH FELLOW I | C12: 14(7) | D12: 10 | E12: =249153.06*12 -> 2989836.7 | F12: =E12*D12 -> 29898367
A13: 9 | B13: ASSISTANT MANAGERS | C13: 13(7) | D13: 8 | E13: 2810412.4 | F13: =E13*D13 -> 22483299
A14: 10 | B14: OFFICERS | C14: 10(7) | D14: 15 | E14: =168602.08*12 -> 2023225 | F14: =E14*D14 -> 30348374
A15: 11 | B15: OFFICE ASSISTANTS | C15: 8(7) | D15: 20 | E15: =123329.05*12 -> 1479948.6 | F15: =E15*D15 -> 29598972
A16: 12 | B16: SECRETARIES | C16: 8(9) | D16: 15 | E16: =130304.44*12 -> 1563653.3 | F16: =E16*D16 -> 23454799
A17: 13 | B17: DRIVERS | C17: 4(10) | D17: 20 | E17: =46676.06*12 -> 560112.72 | F17: =E17*D17 -> 11202254
D18: =SUM(D9:D17) -> 100 | F18: =SUM(F5:F17) -> 3.6153678e+08

Sheet Welfare List Mgt Staff
A2: STAFF NAME | D2: DESIGNATION | E2: GRADE | F2: AMOUNT | G2: SIGNATURE
F3: 300000
A4: PROF OKECHUKWU OKO | D4: DIR. LEG. SP SERVICES | E4: 17(7) | F4: 150000
A5: DR BADAYI M. SANI | D5: DIR. RES. & TRAINING | E5: 17(7) | F5: 150000
A6: DR KABIR AHMED | D6: DIR. FINANCE & ADMIN | E6: 17(7) | F6: 150000
A7: PROF. OFFORNZE AMUCHEAZI | D7: LEGAL ADVISER | E7: 16(7) | F7: 100000
A8: MOHAMMED ISIAKA YAKUBU | D8: HEAD PUBLICATION | E8: 16(7) | F8: 100000
A9: DR MOBOLAJI HAKEEM | D9: SPECIAL ASSISTANT | E9: 16(7) | F9: 100000
A10: DR SHUIBU DANWANKA | D10: DD LEG. SP SERVICES | E10: 16(7) | F10: 100000
A11: DR ASIMIYU G. ABIOLA | D11: DD RESEARCH | E11: 16(7) | F11: 100000
A12: IBRAHIM M. MSHELIA | D12: DD F&A | E12: 16(7) | F12: 100000
A13: AMINU BELLO DUKKU | D13: DD ADMIN/HR | E13: 16(7) | F13: 100000
A14: RICHARD KWALMI | D14: MICT | E14: 15(7) | F14: 80000
A15: ADAMU ISA ABBA | D15: INFO. MANAGER | E15: 15(7) | F15: 80000
... A22: EDET B. AKPAKPAN | D22: SABATICAL | E22: Sab. | F22: 80000
A23: TOTAL | F23: =SUM(F3:F22) -> 2170000

Sheet Welfare Support Staff
A1: S/N | B1: NAMES | E1: DESIGNATION | F1: GRADE | G1: AMOUNT | H1: SIGNATURE
A2: 1 | B2: AKINSANMI ADEJOKE OLUKEMI | E2: AM INFORMATION | F2: 13(7) | G2: 20000
A3: 2 | B3: FAROUK U. M ILLO | E3: PA DG | F3: 13(7) | G3: 20000
A4: 3 | B4: UMOLU ADAEZE OBIAMAKA | E4: INFO OFFICER | F4: 10(7) | G4: 20000
A5: 4 | B5: TONDO IORWUESE EDWARD | E5: OFFICER INT AUDIT | F5: 10(7) | G5: 20000
A6: 5 | B6: BEDARI HARI | E6: LEGAL OFFICER | F6: 10(7) | G6: 20000
A7: 6 | B7: NGARA CHRISTOPHER OCHANJA | C7: NGARA CHRISTOPHER OCHANJA | E7: OFFICER, SPECIAL DUTIES | F7: 10(7) | G7: 20000
A8: 7 | B8: JOY HARUNA MAKERI | E8: PA DG | F8: 10(7) | G8: 20000
A9: 8 | B9: BASHIRU ABBA WALI | E9: ASSIT. INT. AUDIT | F9: 8(7) | G9: 20000
A10: 9 | B10: ALI ABDULLAHI | E10: 1CT ASSISTANT | F10: 8(7) | G10: 20000
A11: 10 | B11: UZODINMA EMMANUEL EZENWA | E11: INFORMATION ASST | F11: 8(7) | G11: 20000
A12: 11 | B12: IBRAHIM TASSNEEM | E12: INFORMATION ASST | F12: 8(7) | G12: 20000
A13: 12 | B13: GLORIA NDIDI HELG | E13: CONFIDENTIAL SECRETARY | F13: 8(7) | G13: 20000
A14: 13 | B14: CHRISTIAN MADUABUCHI ODO | E14: ICT ASSISTANT | F14: 8(7) | G14: 20000
A15: 14 | B15: IBRAHIM USMAN | E15: RESEARCH FELLOW II | F15: 13(7) | G15: 20000
A16: 15 | B16: OFORDEME ADAOBI JULIA | E16: RESEARCH OFFICER | F16: 10(7) | G16: 20000
A17: 16 | B17: IKPEAZU CHINEDU ANITA | E17: RESEARCH OFFICER | F17: 10(7) | G17: 20000
A18: 17 | B18: ONYEAKU CHUKWUKA EDMOND | E18: RESEARCH ASSISTANT | F18: 9(7) | G18: 20000
A19: 18 | B19: DR ANUMUDU CHARLES NNAMDI | E19: SRF I SOCIAL SECTOR | F19: 14(7) | G19: 20000
... A77: 76 | B77: AYUBA SULE | E77: STEWARD | F77: - | G77: 10000
A78: 77 | B78: EWELIKWA IJEOMA NKOLIKWA | E78: DISPATCH CLERK | F78: 0 | G78: 10000
A79: 78 | B79: JUMMAI AJIYA | E79: STEWARD | F79: 0 | G79: 10000
A80: 79 | B80: HUSSAIN HAZEEM MOHAMMED | E80: DISPATCH CLERK | F80: - | G80: 10000
A81: 80 | B81: ABOMAN INNOCENT | E81: CLEANER | G81: 10000
A82: 81 | B82: AKEUSOLA SEGUN | E82: CLEANER | G82: 10000
A83: 82 | B83: EDACHE OGA | E83: DRIVER | G83: 10000
A84: 83 | B84: ONCHE ENOKELA ONCHE | E84: STEWARD | G84: 10000
G85: =SUM(G2:G84) -> 1390000

Sheet Welfare Deployed Staff
A1: EID EL KABIR TRANSPORT ALLOWANCE TO NILS DEPLOYED STAFF
A2: S/N | C2: DESIGNATION | D2: GRADE | E2: AMOUNT | F2: SIGNATURE
A3: 1 | B3: ARC OJO M.O | C3: DD & HEAD OF BUILDING | D3: 16(7) | E3: 100000
A4: 2 | B4: AMINCI THOMAS | C4: MANAGER LIB. & DOCUM. | D4: 15(7) | E4: 80000
A5: 3 | B5: AMINU F. HAMAJODA | C5: MANAGER INFORMATION | D5: 15(7) | E5: 80000
A6: 4 | B6: DAHIRU M. ABDULLAHI | C6: PROTOCOL OFFICER | D6: 10(7) | E6: 20000
A7: 5 | B7: MOSHOOD M. OLARELE | C7: ADMIN OFFICER | D7: 10(7) | E7: 20000
A8: 6 | B8: IBRAHIM A. BABANGISHIRI | C8: OFFICER INFORMATION | D8: 10(7) | E8: 20000
A9: 7 | B9: JIBRIN USHAMA AHMED | C9: OFFICER LEGAL | D9: 10(7) | E9: 20000
A10: 8 | B10: ENGR. EBI THOMPSON | C10: ASSISTANT CHIEF ENGINEER | D10: 13(7) | E10: 20000
A11: 9 | B11: ADEOGUN MORUF | C11: PRINCIPAL Q.S | D11: 10(7) | E11: 20000
B12: TOTAL | E12: =SUM(E3:E11) -> 380000

Sheet Sheet1
B1: 2013 END OF YEAR STAFF WELFARE TO ASSIST WITH TRANSPORTATION AND LOGISTICS.
E3: DESIGNATION | F3: SALARY | G3: BASIC
F4: LEVEL | G4: SALARY
B5: DG OFFICE | G5: N
A6: 1 | B6: DR LADI HAMALAI | E6: DIRECTOR GENERAL | F6: CONSOL | G6: 400000
A7: 2 | B7: PROF. OFFORNZE AMUCHEAZI | E7: LEGAL ADVISER | F7: 16(7) | G7: 200000
A8: 3 | B8: MOHAMMED ISIAKA YAKUBU | E8: HEAD PUBLICATION | F8: 16(7) | G8: 200000
A9: 4 | B9: DR MOBOLAJI HAKEEM | E9: SPECIAL ASSISTANT | F9: 16(70 | G9: 200000
A10: 5 | B10: RICHARD KWALMI | E10: MICT | F10: 15(7) | G10: 100000
A11: 6 | B11: ADAMU ISA ABBA | E11: INFO. MANAGER | F11: 15(7) | G11: 100000
A12: 7 | B12: NWOSU MATHEW EZE | E12: MANAGER INT. AUDIT | F12: 15(7) | G12: 100000
A13: 8 | B13: PRISCILLA CHUKWU | E13: MANAGER PROCUREMENT | F13: 15(7) | G13: 100000
A14: 9 | B14: DR ANAH O. PAMELA | E14: SRF | F14: 15((7) | G14: 100000
A15: 10 | B15: AKINSANMI ADEJOKE OLUKEMI | E15: AM INFORMATION | F15: 13(7) | G15: 80000
A16: 11 | B16: FAROUK U. M ILLO | E16: PA DG | F16: 13(7) | G16: 80000
A17: 12 | B17: UMOLU ADAEZE OBIAMAKA | E17: INFO OFFICER | F17: 10(7) | G17: 50000
... A19: 14 | B19: BEDARI HARI | E19: LEGAL OFFICER | F19: 10(7) | G19: 50000
A20: 15 | B20: NGARA CHRISTOPHER OCHANJA | C20: NGARA CHRISTOPHER OCHANJA | E20: OFFICER, SPECIAL DUTIES | F20: 10(7) | G20: 50000
A21: 16 | B21: JOY HARUNA MAKERI | C21: JOY HARUNA MAKERI | E21: PA DG | F21: 10(7) | G21: 50000
A22: 17 | B22: DONALD E. MKPANAM | E22: IT OFFICER | F22: 10(7) | G22: 50000
A23: 18 | B23: BASHIRU ABBA WALI | E23: ASSIT. INT. AUDIT | F23: 8(7) | G23: 50000
A24: 19 | B24: ALI ABDULLAHI | E24: 1CT ASSISTANT | F24: 8(7) | G24: 50000
A25: 20 | B25: UZODINMA EMMANUEL EZENWA | E25: INFORMATION ASST | F25: 8(7) | G25: 50000
A26: 21 | B26: IBRAHIM TASSNEEM | E26: INFORMATION ASST | F26: 8(7) | G26: 50000
A27: 22 | B27: GLORIA NDIDI HELG | E27: CONFIDENTIAL SECRETARY | F27: 8(7) | G27: 50000
A28: 23 | B28: CHRISTIAN MADUABUCHI ODO | E28: ICT ASSISTANT | F28: 8(7) | G28: 50000
B29: TOTAL | E29: 23 | G29: =SUM(G6:G28) -> 2260000
B30: LEG. SUPPORT SEVICES
A31: 1 | B31: PROF OKECHUKWU OKO | E31: DIR. LEG. SP SERVICES | F31: 17(7) | G31: 300000
A32: 2 | B32: DR SHUIBU DANWANKA | E32: DD LEG. SP SERVICES | F32: 16(7) | G32: 200000
A33: 3 | B33: IBRAHIM USMAN | E33: RESEARCH FELLOW II | F33: 13(7) | G33: 80000
A34: 4 | B34: OFORDEME ADAOBI JULIA | E34: RESEARCH OFFICER | F34: 10(7) | G34: 50000
A35: 5 | B35: IKPEAZU CHINEDU ANITA | C35: IKPEAZU CHINEDU ANITA | E35: RESEARCH OFFICER | F35: 10(7) | G35: 50000
A36: 6 | B36: ONYEAKU CHUKWUKA EDMOND | E36: RESEARCH ASSISTANT | F36: 9(7) | G36: 50000
B37: TOTAL | E37: 6 | G37: =SUM(G31:G36) -> 730000
A39: 1 | B39: DR BADAYI M. SANI | E39: DIR. RES. & TRAINING | F39: 17(7) | G39: 300000
A40: 2 | B40: DR ASIMIYU G. ABIOLA | E40: DD RESEARCH | F40: 16(7) | G40: 200000
A41: 3 | B41: DR KANAYO OGUJIUBA | E41: SRF SOCIAL SECTOR | F41: 15(9) | G41: 100000
A42: 4 | B42: DR ANUMUDU CHARLES NNAMDI | E42: SRF I SOCIAL SECTOR | F42: 14(7) | G42: 80000
A43: 5 | B43: CATHERINE E. IKOKOH | E43: RESEARCH FELLOW1 DOCU | F43: 14(7) | G43: 80000
...

Sheet Sheet3
