Workbook

Sheet JANUARY 2024
A1: CONTRACT/SABBATICAL AND NYSC SALARY FOR THE MONTH OF JANUARY
A3: S/N | B3: STAFF NAME | C3: DESIGNATION | D3: BASIC ALLOWANCE | E3: LEGISLATIVE ALLOWCE | F3: GROSS | G3: DEDUCTIONS | K3: JANUARY 2024 NET SALARY
G4: COOP CONTR | H4: COOP LOAN RECOVERY | I4: PAYE TAX | J4: TOTAL DEDUCTION | K4: N
A5: 1 | B5: Takwasa A. Galadima | C5: Nass Deployed | D5: =136027.8 -> 136027.8 | E5: =60000 -> 60000 | F5: =D5+E5 -> 196027.8 | G5: =30000 -> 30000 | I5: ='[1]August 2022 '!$AD$6 -> 20099.337 | J5: =G5+H5+I5 -> 50099.337 | K5: =F5-J5 -> 145928.46
A6: 2 | B6: Saratu Adamu Attajiri | C6: Office Assistant | D6: 90000 | E6: 30000 | F6: =D6+E6 -> 120000 | G6: 10000 | H6: 40000 | I6: 8900 | J6: =G6+H6+I6 -> 58900 | K6: =F6-J6 -> 61100
A7: 3 | B7: Aboaman Innocent | C7: Casual | D7: 45000 | E7: 15000 | F7: =D7+E7 -> 60000 | G7: =10000 -> 10000 | H7: =10000+10000 -> 20000 | I7: 2446.6667 | J7: =G7+H7+I7 -> 32446.667 | K7: =F7-J7 -> 27553.333
A8: 4 | B8: Kusai E. Richard | C8: Plumber | D8: 45000 | E8: 15000 | F8: =D8+E8 -> 60000 | G8: =10000 -> 10000 | H8: =20000 -> 20000 | I8: 2446.6667 | J8: =G8+H8+I8 -> 32446.667 | K8: =F8-J8 -> 27553.333
A9: 5 | B9: Bulus Ishaya | C9: Gardener | D9: 45000 | E9: 15000 | F9: =D9+E9 -> 60000 | G9: 0 | H9: 0 | I9: 2446.6667 | J9: =G9+H9+I9 -> 2446.6667 | K9: =F9-J9 -> 57553.333
A10: 6 | B10: Alhamdu Iliya | C10: Casual-Gardner | D10: =50000 -> 50000 | E10: 15000 | F10: =D10+E10 -> 65000 | G10: =5000+5000+5000 -> 15000 | H10: =14350 -> 14350 | I10: 2886.6667 | J10: =G10+H10+I10 -> 32236.667 | K10: =F10-J10 -> 32763.333
A11: 7 | B11: Salihu Hassan | C11: Casual-Gardner | D11: =50000 -> 50000 | E11: 15000 | F11: =D11+E11 -> 65000 | G11: =5000 -> 5000 | H11: 0 | I11: 2886.6667 | J11: =G11+H11+I11 -> 7886.6667 | K11: =F11-J11 -> 57113.333
A12: 8 | B12: Ishaya Moro James | C12: Gardener | D12: =60000 -> 60000 | E12: 20000 | F12: =D12+E12 -> 80000 | G12: =10000 -> 10000 | H12: =17500 -> 17500 | I12: 4206.6667 | J12: =G12+H12+I12 -> 31706.667 | K12: =F12-J12 -> 48293.333
A13: 9 | B13: Enobong Sambo | C13: Retainership | D13: =70000 -> 70000 | E13: 20000 | F13: =D13+E13 -> 90000 | G13: =0 -> 0 | H13: 0 | I13: 5300 | J13: =G13+H13+I13 -> 5300 | K13: =F13-J13 -> 84700
A14: 10 | B14: Masarr Sarr | C14: Casual | D14: =90000 -> 90000 | E14: 30000 | F14: =D14+E14 -> 120000 | G14: =0 -> 0 | H14: 0 | I14: 8900 | J14: =G14+H14+I14 -> 8900 | K14: =F14-J14 -> 111100
A15: 11 | B15: Said Idris Abduljalil | C15: Secondment | D15: =105352.17 -> 105352.17 | E15: =(60000+50000) -> 110000 | F15: =D15+E15 -> 215352.17 | G15: =0 -> 0 | H15: 0 | I15: 23345.831 | J15: =G15+H15+I15 -> 23345.831 | K15: =F15-J15 -> 192006.34
A16: 12 | B16: Prof. Peter Siyan | C16: Sabbatical | D16: =502746.92 -> 502746.92 | E16: 180000 | F16: =D16+E16 -> 682746.92 | G16: =0 -> 0 | H16: 0 | I16: 109754.08 | J16: =G16+H16+I16 -> 109754.08 | K16: =F16-J16 -> 572992.84
A17: 13 | B17: Pro. Francis Onyekwere Ozoh | C17: Sabbatical | D17: =555351.17 -> 555351.17 | E17: 180000 | F17: =D17+E17 -> 735351.17 | G17: =0 -> 0 | H17: 0 | I17: =(119693.26) -> 119693.26 | J17: =G17+H17+I17 -> 119693.26 | K17: =F17-J17 -> 615657.91
A18: 14 | B18: Prof. Zubairu Kwambo Dagona | C18: Contract Staff | D18: =800656.58 -> 800656.58 | E18: 200000 | F18: =D18+E18 -> 1000656.6 | G18: =0 -> 0 | H18: 0 | I18: =(170631.89) -> 170631.89 | J18: =G18+H18+I18 -> 170631.89 | K18: =F18-J18 -> 830024.69
A19: 15 | B19: Abdulkareem Toyeeb | C19: NYSC | D19: 25000 | E19: 0 | F19: =D19+E19 -> 25000 | G19: =0 -> 0 | H19: 0 | J19: =G19+H19+I19 -> 0 | K19: =F19-J19 -> 25000
A20: 16 | B20: Akeh Blessing | C20: NYSC | D20: 25000 | E20: 0 | F20: =D20+E20 -> 25000 | G20: =0 -> 0 | H20: 0 | J20: =G20+H20+I20 -> 0 | K20: =F20-J20 -> 25000
A21: 17 | B21: Fasasi Ahmed Olalekan | C21: NYSC | D21: 25000 | E21: 0 | F21: =D21+E21 -> 25000 | G21: =0 -> 0 | H21: 0 | J21: =G21+H21+I21 -> 0 | K21: =F21-J21 -> 25000
A22: 18 | B22: Nwabueze Joy Oluchi | C22: NYSC | D22: 25000 | E22: 0 | F22: =D22+E22 -> 25000 | G22: =0 -> 0 | H22: 0 | J22: =G22+H22+I22 -> 0 | K22: =F22-J22 -> 25000
A23: 19 | B23: Muhammad Kudu Abubakar | C23: Ag. Gen Manager | D23: =424023.33 -> 424023.33 | E23: 90000 | F23: =D23+E23 -> 514023.33 | G23: =0 -> 0 | H23: 0 | I23: =77198.31 -> 77198.31 | J23: =G23+H23+I23 -> 77198.31 | K23: =F23-J23 -> 436825.02
A24: 20 | B24: Prof. Mohammed Mustapha Namadi | C24: Sabbatical | D24: =496425.42 -> 496425.42 | E24: 180000 | F24: =D24+E24 -> 676425.42 | G24: =0 -> 0 | H24: 0 | I24: =108540.35 -> 108540.35 | J24: =G24+H24+I24 -> 108540.35 | K24: =F24-J24 -> 567885.07
A25: 21 | B25: Ibrahim Kaltume Onawo | C25: NYSC (Arrears) | D25: =25000+7500 -> 32500 | E25: 0 | F25: =D25+E25 -> 32500 | G25: =0 -> 0 | H25: 0 | J25: =G25+H25+I25 -> 0 | K25: =F25-J25 -> 32500
A26: 22 | B26: Hassan Mahmud Adewole | C26: NYSC | D26: 25000 | E26: 0 | F26: =D26+E26 -> 25000 | G26: =0 -> 0 | H26: 0 | J26: =G26+H26+I26 -> 0 | K26: =F26-J26 -> 25000
A27: 23 | B27: Nwanganga Chidozie | C27: House Keeper | D27: 60000 | E27: 20000 | F27: =D27+E27 -> 80000 | G27: =0 -> 0 | H27: 0 | I27: =4206.67 -> 4206.67 | J27: =G27+H27+I27 -> 4206.67 | K27: =F27-J27 -> 75793.33
A28: 24 | B28: Mary Shadrach | C28: Cleaner | D28: 55000 | E28: 15000 | F28: =D28+E28 -> 70000 | G28: =0 -> 0 | H28: 0 | I28: =3326.67 -> 3326.67 | J28: =G28+H28+I28 -> 3326.67 | K28: =F28-J28 -> 66673.33
A29: 25 | B29: Akinboboye Oluwatosin Ifedayo | C29: NYSC | D29: 25000 | E29: 0 | F29: =D29+E29 -> 25000 | G29: =0 -> 0 | H29: 0 | J29: =G29+H29+I29 -> 0 | K29: =F29-J29 -> 25000
A30: 26 | B30: Abdulrahim Abdullahi | C30: NYSC | D30: 25000 | F30: =D30+E30 -> 25000 | G30: =0 -> 0 | H30: 0 | J30: =G30+H30+I30 -> 0 | K30: =F30-J30 -> 25000
A31: 27 | B31: Julie G. Sanda | C31: Sabbatical | D31: 410900.75 | E31: 160000 | F31: =D31+E31 -> 570900.75 | G31: =0 -> 0 | H31: 0 | I31: =88279.61 -> 88279.61 | J31: =G31+H31+I31 -> 88279.61 | K31: =F31-J31 -> 482621.14
A32: 28 | B32: Rahimat Suberu Onize | C32: Contract Staff | D32: =123329.05 -> 123329.05 | E32: 50000 | F32: =D32+E32 -> 173329.05 | G32: 20000 | H32: 0 | I32: 16512.68 | J32: =G32+H32+I32 -> 36512.68 | K32: =F32-J32 -> 136816.37
A33: 29 | B33: Ikip Lebo | C33: Contract Staff | D33: =226713 -> 226713 | E33: =70000 -> 70000 | F33: =D33+E33 -> 296713 | G33: =20000 -> 20000 | H33: 0 | I33: =37014.45 -> 37014.45 | J33: =G33+H33+I33 -> 57014.45 | K33: =F33-J33 -> 239698.55
A34: 30 | B34: Yusuf Yusuf Dayyabu | C34: Contract Staff | D34: =145204 -> 145204 | E34: =60000 -> 60000 | F34: =D34+E34 -> 205204 | G34: =0 -> 0 | H34: 0 | I34: 21640.953 | J34: =G34+H34+I34 -> 21640.953 | K34: =F34-J34 -> 183563.05
A35: 31 | B35: Musa Mustapha Adekola | C35: Casual Staff | D35: =90000 -> 90000 | E35: =30000 -> 30000 | F35: =D35+E35 -> 120000 | G35: =0 -> 0 | H35: 0 | I35: =8600 -> 8600 | J35: =G35+H35+I35 -> 8600 | K35: =F35-J35 -> 111400
A36: 32 | B36: Ramatu Ibrahim Abdulrahim | C36: Contract Staff | D36: =123329.05 -> 123329.05 | E36: =50000 -> 50000 | F36: =D36+E36 -> 173329.05 | G36: =50000 -> 50000 | H36: 0 | I36: 16512.68 | J36: =G36+H36+I36 -> 66512.68 | K36: =F36-J36 -> 106816.37
A37: 33 | B37: Rasheedat Daibu | C37: Contract Staff | D37: =168602 -> 168602 | E37: =60000 -> 60000 | F37: =D37+E37 -> 228602 | G37: =0 -> 0 | H37: 0 | I37: =25571.8 -> 25571.8 | J37: =G37+H37+I37 -> 25571.8 | K37: =F37-J37 -> 203030.2
A38: 34 | B38: Ladan Abdulmushin Tawfiq | C38: Contract Staff | D38: 145204 | E38: 60000 | F38: =D38+E38 -> 205204 | G38: =0 -> 0 | H38: 0 | I38: =21640.95 -> 21640.95 | J38: =G38+H38+I38 -> 21640.95 | K38: =F38-J38 -> 183563.05
A39: 35 | B39: Dr. Alabi Adesina Muhydeen | C39: Contract Staff | D39: =226713 -> 226713 | E39: =120000 -> 120000 | F39: =D39+E39 -> 346713 | G39: =0 -> 0 | H39: 0 | I39: =45414.45 -> 45414.45 | J39: =G39+H39+I39 -> 45414.45 | K39: =F39-J39 -> 301298.55
A40: 36 | B40: Lukman Abdullahi Opobiyi | C40: NYSC | D40: 25000 | F40: =D40+E40 -> 25000 | G40: =0 -> 0 | H40: 0 | J40: =G40+H40+I40 -> 0 | K40: =F40-J40 -> 25000
A41: 37 | B41: Zainab Bakare | C41: Contract Staff | D41: =123329.05 -> 123329.05 | E41: =50000 -> 50000 | F41: =D41+E41 -> 173329.05 | G41: =0 -> 0 | H41: 0 | I41: 16512.68 | J41: =G41+H41+I41 -> 16512.68 | K41: =F41-J41 -> 156816.37
...

Sheet JANUARY 2024 2
A1: CONSULTANCY FEES FOR THE MONTH OF JANUARY 2024
A3: S/N | B3: STAFF NAME | C3: DESIGNATION | D3: TOTAL/GROSS FEES | E3: DEDUCTIONS | I3: NET PAYMENT JANUARY 2024
E4: COOP CONTR | F4: COOP LOAN RECOVERY | G4: WITHOLDING TAX | H4: TOTAL DEDUCTION | I4: N
A5: 1 | B5: Dr. Mohammed Etudaiye | C5: Consultant | D5: =300000 -> 300000 | G5: =D5*0.05 -> 15000 | H5: =E5+F5+G5 -> 15000 | I5: =D5-H5 -> 285000
A6: 2 | B6: Barr. James G Bathna | C6: Consultancy | D6: =300000 -> 300000 | G6: =D6*0.05 -> 15000 | H6: =E6+F6+G6 -> 15000 | I6: =D6-H6 -> 285000
A7: 3 | B7: Dr. John Niyi Olanrewaju | C7: Consultancy | D7: =500000 -> 500000 | E7: =25000 -> 25000 | F7: 60640 | G7: =D7*0.05 -> 25000 | H7: =E7+F7+G7 -> 110640 | I7: =D7-H7 -> 389360
A8: 4 | B8: Dr. Shehu Wahab L | C8: Consultant | D8: 300000 | G8: =D8*0.05 -> 15000 | H8: =E8+F8+G8 -> 15000 | I8: =D8-H8 -> 285000
A9: 5 | B9: Moshood Tsoho Amuda | C9: Consultancy | D9: =500000 -> 500000 | G9: =D9*0.05 -> 25000 | H9: =E9+F9+G9 -> 25000 | I9: =D9-H9 -> 475000
A10: 6 | B10: Inya Joephine Ode | C10: Consultant | D10: =300000 -> 300000 | G10: =D10*0.05 -> 15000 | H10: =E10+F10+G10 -> 15000 | I10: =D10-H10 -> 285000
A11: 7 | B11: Prof Charles U. Ilebune | C11: Consultant | D11: =300000 -> 300000 | G11: =D11*0.05 -> 15000 | H11: =E11+F11+G11 -> 15000 | I11: =D11-H11 -> 285000
A12: 8 | B12: Prof. Maryam Adepeju Abdulraheem-Mustapha | C12: Consultant | D12: =300000*0.77 -> 231000 | G12: =D12*0.05 -> 11550 | H12: =E12+F12+G12 -> 11550 | I12: =D12-H12 -> 219450
A13: 9 | B13: Victoria Stephanie David | C13: Consultancy | D13: =150000 -> 150000 | G13: =D13*0.05 -> 7500 | H13: =E13+F13+G13 -> 7500 | I13: =D13-H13 -> 142500
A14: 10 | B14: Kindness Oluwakemi M | C14: Consultancy | D14: =200000 -> 200000 | G14: =D14*0.05 -> 10000 | H14: =E14+F14+G14 -> 10000 | I14: =D14-H14 -> 190000
A15: 11 | B15: Danladi Idris Daniel | C15: Consultancy | D15: =200000 -> 200000 | G15: =D15*0.05 -> 10000 | H15: =E15+F15+G15 -> 10000 | I15: =D15-H15 -> 190000
A16: 12 | B16: Ufomba Patricia Osinachi | C16: Consultancy | D16: =150000 -> 150000 | G16: =D16*0.05 -> 7500 | H16: =E16+F16+G16 -> 7500 | I16: =D16-H16 -> 142500
A17: 13 | B17: Anayo Akwitti | C17: Consultancy | D17: =200000 -> 200000 | G17: =D17*0.05 -> 10000 | H17: =E17+F17+G17 -> 10000 | I17: =D17-H17 -> 190000
A18: 14 | B18: Otene Oche Jonah | C18: Consultancy (Arrears) | D18: =200000+20000 -> 220000 | G18: =D18*0.05 -> 11000 | H18: =E18+F18+G18 -> 11000 | I18: =D18-H18 -> 209000
A19: 15 | B19: Julian Chinyere Osamoto | C19: Consultancy | D19: =150000 -> 150000 | G19: =D19*0.05 -> 7500 | H19: =E19+F19+G19 -> 7500 | I19: =D19-H19 -> 142500
A20: 16 | B20: Faith Onyebujoh | C20: Consultancy | D20: =200000 -> 200000 | G20: =D20*0.05 -> 10000 | H20: =E20+F20+G20 -> 10000 | I20: =D20-H20 -> 190000
A21: 17 | B21: Dr. Dare Fatai | C21: Consultancy | D21: 300000 | G21: =D21*0.05 -> 15000 | H21: =E21+F21+G21 -> 15000 | I21: =D21-H21 -> 285000
A22: 18 | B22: Alkadriyar Abdullahi Abdullahi | C22: Consultancy | D22: =150000 -> 150000 | G22: =D22*0.05 -> 7500 | H22: =E22+F22+G22 -> 7500 | I22: =D22-H22 -> 142500
A23: 19 | B23: Benjamin Ubiri | C23: Consultancy | D23: 200000 | G23: =D23*0.05 -> 10000 | H23: =E23+F23+G23 -> 10000 | I23: =D23-H23 -> 190000
A24: 20 | B24: Mugisat Abdulganiyyu | C24: Consultancy | D24: 150000 | G24: =D24*0.05 -> 7500 | H24: =E24+F24+G24 -> 7500 | I24: =D24-H24 -> 142500
A25: 21 | B25: Sofiat Adepeju Adenekan | C25: Consultancy | D25: 150000 | G25: =D25*0.05 -> 7500 | H25: =E25+F25+G25 -> 7500 | I25: =D25-H25 -> 142500
A26: 22 | B26: Echianu Chinedu Chikadibia | C26: Consultancy | D26: 150000 | G26: =D26*0.05 -> 7500 | H26: =E26+F26+G26 -> 7500 | I26: =D26-H26 -> 142500
B27: TOTAL | D27: =SUM(D5:D26) -> 5301000 | E27: =SUM(E5:E26) -> 25000 | F27: =SUM(F5:F26) -> 60640 | G27: =SUM(G5:G26) -> 265050 | H27: =SUM(H5:H26) -> 350690 | I27: =SUM(I5:I26) -> 4950310
K109: =60000 -> 60000

Sheet ENHANCED WELFARE 2024
A1: NATIONAL INSTITUTE FOR LEGISLATIVE AND DEMOCRATIC STUDIES
A2: STAFF ENHANCED WELFARE SCHEDULE 2024
A3: STAFF ENHANCED WELFARE SCHEDULE 2024
A4: S/N | B4: STAFF NAME | C4: DESIGNATION | D4: AMOUNT
D5: N
A6: 1 | B6: Takwasa A. Galadima | C6: NASS Deployed | D6: 500000
A7: 2 | B7: Saratu Adamu Attajiri | C7: Office Assistant | D7: 300000
A8: 3 | B8: Aboaman Innocent | C8: Casual | D8: 100000
A9: 4 | B9: Kusai E. Richard | C9: Plumber | D9: 100000
A10: 5 | B10: Bulus Ishaya | C10: Gardener | D10: 100000
A11: 6 | B11: Alhamdu Iliya | C11: Casual-Gardner | D11: 100000
A12: 7 | B12: Salihu Hassan | C12: Casual-Gardner | D12: 100000
A13: 8 | B13: Ishaya Moro James | C13: Gardener | D13: 100000
A14: 9 | B14: Dr. John Niyi Olanrewaju | C14: Contract | D14: 500000
A15: 10 | B15: Enobong Sambo | C15: Retainership | D15: 100000
A16: 11 | B16: Masarr Sarr | C16: Casual | D16: 300000
A17: 12 | B17: Said Idris Abduljalil | C17: Secondment | D17: 300000
... A39: 35 | B39: Godwin Etim | C39: Sergent at Arms | D39: 100000
B40: TOTAL | D40: =SUM(D6:D39) -> 9750000
F122: =60000 -> 60000

Sheet ENHANCED WELFARE 2024 2
A1: NATIONAL INSTITUTE FOR LEGISLATIVE AND DEMOCRATIC STUDIES
A2: STAFF ENHANCED WELFARE SCHEDULE 2024
A3: STAFF ENHANCED WELFARE SCHEDULE 2024
A4: S/N | B4: STAFF NAME | C4: DESIGNATION | D4: AMOUNT
D5: N
A6: 1 | B6: Victoria Stephanie David | C6: Consultancy | D6: 100000
A7: 2 | B7: Kindness Oluwakemi M | C7: Consultancy | D7: 100000
A8: 3 | B8: Danladi Idris Daniel | C8: Consultancy | D8: 100000
A9: 4 | B9: Ufomba Patricia Osinachi | C9: Consultancy | D9: 100000
A10: 5 | B10: Anayo Akwitti | C10: Consultancy | D10: 100000
A11: 6 | B11: Otene Oche Jonah | C11: Consultancy | D11: 100000
A12: 7 | B12: Julian Chinyere Osamoto | C12: Consultancy | D12: 100000
A13: 8 | B13: Faith Onyebujoh | C13: Consultancy | D13: 100000
A14: 9 | B14: Dr. Dare Fatai | C14: Consultancy | D14: 100000
A15: 10 | B15: Alkadriyar Abdullahi Abdullahi | C15: Consultancy | D15: 100000
A16: 11 | B16: Benjamin Ubiri | C16: Consultancy | D16: 100000
A17: 12 | B17: Mugisat Abdulganiyyu | C17: Consultancy | D17: 100000
... A23: 18 | B23: Moshood Tsoho Amuda | C23: Consultancy | D23: 100000
B24: TOTAL | D24: =SUM(D6:D23) -> 1800000
F106: =60000 -> 60000

Sheet JANUARY 2024 (2)
A1: CONTRACT/SABBATICAL AND NYSC SALARY FOR THE MONTH OF JANUARY
A3: S/N | B3: STAFF NAME | C3: DESIGNATION | D3: BASIC ALLOWANCE | E3: LEGISLATIVE ALLOWCE | F3: GROSS | G3: DEDUCTIONS | K3: JANUARY 2024 NET SALARY
G4: COOP CONTR | H4: COOP LOAN RECOVERY | I4: PAYE TAX | J4: TOTAL DEDUCTION | K4: N
A5: 1 | B5: Takwasa A. Galadima | C5: Nass Deployed | D5: =136027.8 -> 136027.8 | E5: =60000 -> 60000 | F5: =D5+E5 -> 196027.8 | G5: =30000 -> 30000 | I5: ='[1]August 2022 '!$AD$6 -> 20099.337 | J5: =G5+H5+I5 -> 50099.337 | K5: =F5-J5 -> 145928.46
A6: 2 | B6: Saratu Adamu Attajiri | C6: Office Assistant | D6: 90000 | E6: 30000 | F6: =D6+E6 -> 120000 | G6: 10000 | H6: 40000 | I6: 8900 | J6: =G6+H6+I6 -> 58900 | K6: =F6-J6 -> 61100
A7: 3 | B7: Aboaman Innocent | C7: Casual | D7: 45000 | E7: 15000 | F7: =D7+E7 -> 60000 | G7: =10000 -> 10000 | H7: =10000+10000 -> 20000 | I7: 2446.6667 | J7: =G7+H7+I7 -> 32446.667 | K7: =F7-J7 -> 27553.333
A8: 4 | B8: Kusai E. Richard | C8: Plumber | D8: 45000 | E8: 15000 | F8: =D8+E8 -> 60000 | G8: =10000 -> 10000 | H8: =20000 -> 20000 | I8: 2446.6667 | J8: =G8+H8+I8 -> 32446.667 | K8: =F8-J8 -> 27553.333
A9: 5 | B9: Bulus Ishaya | C9: Gardener | D9: 45000 | E9: 15000 | F9: =D9+E9 -> 60000 | G9: 0 | H9: 0 | I9: 2446.6667 | J9: =G9+H9+I9 -> 2446.6667 | K9: =F9-J9 -> 57553.333
A10: 6 | B10: Alhamdu Iliya | C10: Casual-Gardner | D10: =50000 -> 50000 | E10: 15000 | F10: =D10+E10 -> 65000 | G10: =5000+5000+5000 -> 15000 | H10: =14350 -> 14350 | I10: 2886.6667 | J10: =G10+H10+I10 -> 32236.667 | K10: =F10-J10 -> 32763.333
A11: 7 | B11: Salihu Hassan | C11: Casual-Gardner | D11: =50000 -> 50000 | E11: 15000 | F11: =D11+E11 -> 65000 | G11: =5000 -> 5000 | H11: 0 | I11: 2886.6667 | J11: =G11+H11+I11 -> 7886.6667 | K11: =F11-J11 -> 57113.333
A12: 8 | B12: Ishaya Moro James | C12: Gardener | D12: =60000 -> 60000 | E12: 20000 | F12: =D12+E12 -> 80000 | G12: =10000 -> 10000 | H12: =17500 -> 17500 | I12: 4206.6667 | J12: =G12+H12+I12 -> 31706.667 | K12: =F12-J12 -> 48293.333
A13: 9 | B13: Enobong Sambo | C13: Retainership | D13: =70000 -> 70000 | E13: 20000 | F13: =D13+E13 -> 90000 | G13: =0 -> 0 | H13: 0 | I13: 5300 | J13: =G13+H13+I13 -> 5300 | K13: =F13-J13 -> 84700
A14: 10 | B14: Masarr Sarr | C14: Casual | D14: =90000 -> 90000 | E14: 30000 | F14: =D14+E14 -> 120000 | G14: =0 -> 0 | H14: 0 | I14: 8900 | J14: =G14+H14+I14 -> 8900 | K14: =F14-J14 -> 111100
A15: 11 | B15: Said Idris Abduljalil | C15: Secondment | D15: =105352.17 -> 105352.17 | E15: =(60000+50000) -> 110000 | F15: =D15+E15 -> 215352.17 | G15: =0 -> 0 | H15: 0 | I15: 23345.831 | J15: =G15+H15+I15 -> 23345.831 | K15: =F15-J15 -> 192006.34
A16: 12 | B16: Prof. Peter Siyan | C16: Sabbatical | D16: =502746.92 -> 502746.92 | E16: 180000 | F16: =D16+E16 -> 682746.92 | G16: =0 -> 0 | H16: 0 | I16: 109754.08 | J16: =G16+H16+I16 -> 109754.08 | K16: =F16-J16 -> 572992.84
A17: 13 | B17: Pro. Francis Onyekwere Ozoh | C17: Sabbatical | D17: =555351.17 -> 555351.17 | E17: 180000 | F17: =D17+E17 -> 735351.17 | G17: =0 -> 0 | H17: 0 | I17: =(119693.26) -> 119693.26 | J17: =G17+H17+I17 -> 119693.26 | K17: =F17-J17 -> 615657.91
A18: 14 | B18: Prof. Zubairu Kwambo Dagona | C18: Contract Staff | D18: =800656.58 -> 800656.58 | E18: 200000 | F18: =D18+E18 -> 1000656.6 | G18: =0 -> 0 | H18: 0 | I18: =(170631.89) -> 170631.89 | J18: =G18+H18+I18 -> 170631.89 | K18: =F18-J18 -> 830024.69
A19: 15 | B19: Abdulkareem Toyeeb | C19: NYSC | D19: 25000 | E19: 0 | F19: =D19+E19 -> 25000 | G19: =0 -> 0 | H19: 0 | J19: =G19+H19+I19 -> 0 | K19: =F19-J19 -> 25000
A20: 16 | B20: Akeh Blessing | C20: NYSC | D20: 25000 | E20: 0 | F20: =D20+E20 -> 25000 | G20: =0 -> 0 | H20: 0 | J20: =G20+H20+I20 -> 0 | K20: =F20-J20 -> 25000
A21: 17 | B21: Fasasi Ahmed Olalekan | C21: NYSC | D21: 25000 | E21: 0 | F21: =D21+E21 -> 25000 | G21: =0 -> 0 | H21: 0 | J21: =G21+H21+I21 -> 0 | K21: =F21-J21 -> 25000
A22: 18 | B22: Nwabueze Joy Oluchi | C22: NYSC | D22: 25000 | E22: 0 | F22: =D22+E22 -> 25000 | G22: =0 -> 0 | H22: 0 | J22: =G22+H22+I22 -> 0 | K22: =F22-J22 -> 25000
A23: 19 | B23: Muhammad Kudu Abubakar | C23: Ag. Gen Manager | D23: =424023.33 -> 424023.33 | E23: 90000 | F23: =D23+E23 -> 514023.33 | G23: =0 -> 0 | H23: 0 | I23: =77198.31 -> 77198.31 | J23: =G23+H23+I23 -> 77198.31 | K23: =F23-J23 -> 436825.02
A24: 20 | B24: Prof. Mohammed Mustapha Namadi | C24: Sabbatical | D24: =496425.42 -> 496425.42 | E24: 180000 | F24: =D24+E24 -> 676425.42 | G24: =0 -> 0 | H24: 0 | I24: =108540.35 -> 108540.35 | J24: =G24+H24+I24 -> 108540.35 | K24: =F24-J24 -> 567885.07
A25: 21 | B25: Ibrahim Kaltume Onawo | C25: NYSC (Arrears) | D25: =25000+7500 -> 32500 | E25: 0 | F25: =D25+E25 -> 32500 | G25: =0 -> 0 | H25: 0 | J25: =G25+H25+I25 -> 0 | K25: =F25-J25 -> 32500
A26: 22 | B26: Hassan Mahmud Adewole | C26: NYSC | D26: 25000 | E26: 0 | F26: =D26+E26 -> 25000 | G26: =0 -> 0 | H26: 0 | J26: =G26+H26+I26 -> 0 | K26: =F26-J26 -> 25000
A27: 23 | B27: Nwanganga Chidozie | C27: House Keeper | D27: 60000 | E27: 20000 | F27: =D27+E27 -> 80000 | G27: =0 -> 0 | H27: 0 | I27: =4206.67 -> 4206.67 | J27: =G27+H27+I27 -> 4206.67 | K27: =F27-J27 -> 75793.33
A28: 24 | B28: Mary Shadrach | C28: Cleaner | D28: 55000 | E28: 15000 | F28: =D28+E28 -> 70000 | G28: =0 -> 0 | H28: 0 | I28: =3326.67 -> 3326.67 | J28: =G28+H28+I28 -> 3326.67 | K28: =F28-J28 -> 66673.33
A29: 25 | B29: Akinboboye Oluwatosin Ifedayo | C29: NYSC | D29: 25000 | E29: 0 | F29: =D29+E29 -> 25000 | G29: =0 -> 0 | H29: 0 | J29: =G29+H29+I29 -> 0 | K29: =F29-J29 -> 25000
A30: 26 | B30: Abdulrahim Abdullahi | C30: NYSC | D30: 25000 | F30: =D30+E30 -> 25000 | G30: =0 -> 0 | H30: 0 | J30: =G30+H30+I30 -> 0 | K30: =F30-J30 -> 25000
A31: 27 | B31: Julie G. Sanda | C31: Sabbatical | D31: 410900.75 | E31: 160000 | F31: =D31+E31 -> 570900.75 | G31: =0 -> 0 | H31: 0 | I31: =88279.61 -> 88279.61 | J31: =G31+H31+I31 -> 88279.61 | K31: =F31-J31 -> 482621.14
A32: 28 | B32: Rahimat Suberu Onize | C32: Contract Staff | D32: =123329.05 -> 123329.05 | E32: 50000 | F32: =D32+E32 -> 173329.05 | G32: 20000 | H32: 0 | I32: 16512.68 | J32: =G32+H32+I32 -> 36512.68 | K32: =F32-J32 -> 136816.37
A33: 29 | B33: Ikip Lebo | C33: Contract Staff | D33: =226713 -> 226713 | E33: =70000 -> 70000 | F33: =D33+E33 -> 296713 | G33: =20000 -> 20000 | H33: 0 | I33: =37014.45 -> 37014.45 | J33: =G33+H33+I33 -> 57014.45 | K33: =F33-J33 -> 239698.55
A34: 30 | B34: Yusuf Yusuf Dayyabu | C34: Contract Staff | D34: =145204 -> 145204 | E34: =60000 -> 60000 | F34: =D34+E34 -> 205204 | G34: =0 -> 0 | H34: 0 | I34: 21640.953 | J34: =G34+H34+I34 -> 21640.953 | K34: =F34-J34 -> 183563.05
A35: 31 | B35: Musa Mustapha Adekola | C35: Casual Staff | D35: =90000 -> 90000 | E35: =30000 -> 30000 | F35: =D35+E35 -> 120000 | G35: =0 -> 0 | H35: 0 | I35: =8600 -> 8600 | J35: =G35+H35+I35 -> 8600 | K35: =F35-J35 -> 111400
A36: 32 | B36: Ramatu Ibrahim Abdulrahim | C36: Contract Staff | D36: =123329.05 -> 123329.05 | E36: =50000 -> 50000 | F36: =D36+E36 -> 173329.05 | G36: =50000 -> 50000 | H36: 0 | I36: 16512.68 | J36: =G36+H36+I36 -> 66512.68 | K36: =F36-J36 -> 106816.37
A37: 33 | B37: Rasheedat Daibu | C37: Contract Staff | D37: =168602 -> 168602 | E37: =60000 -> 60000 | F37: =D37+E37 -> 228602 | G37: =0 -> 0 | H37: 0 | I37: =25571.8 -> 25571.8 | J37: =G37+H37+I37 -> 25571.8 | K37: =F37-J37 -> 203030.2
A38: 34 | B38: Ladan Abdulmushin Tawfiq | C38: Contract Staff | D38: 145204 | E38: 60000 | F38: =D38+E38 -> 205204 | G38: =0 -> 0 | H38: 0 | I38: =21640.95 -> 21640.95 | J38: =G38+H38+I38 -> 21640.95 | K38: =F38-J38 -> 183563.05
A39: 35 | B39: Dr. Alabi Adesina Muhydeen | C39: Contract Staff | D39: =226713 -> 226713 | E39: =120000 -> 120000 | F39: =D39+E39 -> 346713 | G39: =0 -> 0 | H39: 0 | I39: =45414.45 -> 45414.45 | J39: =G39+H39+I39 -> 45414.45 | K39: =F39-J39 -> 301298.55
A40: 36 | B40: Lukman Abdullahi Opobiyi | C40: NYSC | D40: 25000 | F40: =D40+E40 -> 25000 | G40: =0 -> 0 | H40: 0 | J40: =G40+H40+I40 -> 0 | K40: =F40-J40 -> 25000
A41: 37 | B41: Zainab Bakare | C41: Contract Staff | D41: =123329.05 -> 123329.05 | E41: =50000 -> 50000 | F41: =D41+E41 -> 173329.05 | G41: =0 -> 0 | H41: 0 | I41: 16512.68 | J41: =G41+H41+I41 -> 16512.68 | K41: =F41-J41 -> 156816.37
...

Sheet Sheet32

Sheet CHRISTMAS WELFARE 1
A1: CONTRACT/SABBATICAL AND CONSULTANT CHRISTMAS WELFARE DECEMBER 2023
A3: S/N | B3: STAFF NAME | C3: DESIGNATION | D3: AMOUNT (N)
A4: 1 | B4: Dr. Mohammed Etudaiye | C4: Consultant | D4: 90000
A5: 2 | B5: Takwasa A. Galadima | C5: Nass Deployed | D5: 90000
A6: 3 | B6: Saratu Adamu Attajiri | C6: Office Assistant | D6: 54000
A7: 4 | B7: Aboaman Innocent | C7: Casual | D7: 36000
A8: 5 | B8: Kusai E. Richard | C8: Plumber | D8: 36000
A9: 6 | B9: Bulus Ishaya | C9: Gardener | D9: 36000
A10: 7 | B10: Alhamdu Iliya | C10: Casual-Gardner | D10: 36000
A11: 8 | B11: Salihu Hassan | C11: Casual-Gardner | D11: 36000
A12: 9 | B12: Ishaya Moro James | C12: Gardener | D12: 36000
A13: 10 | B13: Barr. James G Bathna | C13: Consultancy | D13: 90000
A14: 11 | B14: Dr. John Niyi Olanrewaju | C14: Consultancy | D14: 90000
A15: 12 | B15: Dr. Shehu Wahab L | C15: Consultant | D15: 90000
... A71: 68 | B71: Shittu Deborah Damilola | C71: NYSC | D71: 18000
B72: TOTAL | D72: =SUM(D4:D71) -> 3861000
F154: =60000 -> 60000

Sheet CHRISTMAS WELFARE 2
A1: CONSULTANCY WELFARE SCHEDULE DECEMBER 2023
A3: S/N | B3: STAFF NAME | C3: DESIGNATION | D3: AMOUNT (N)
A4: 1 | B4: Victoria Stephanie David | C4: Consultancy | D4: 54000
A5: 2 | B5: Kindness Oluwakemi M | C5: Consultancy | D5: 54000
A6: 3 | B6: Danladi Idris Daniel | C6: Consultancy | D6: 54000
A7: 4 | B7: Ufomba Patricia Osinachi | C7: Consultancy | D7: 54000
A8: 5 | B8: Anayo Akwitti | C8: Consultancy | D8: 54000
A9: 6 | B9: Otene Oche Jonah | C9: Consultancy | D9: 54000
A10: 7 | B10: Julian Chinyere Osamoto | C10: Consultancy | D10: 54000
A11: 8 | B11: Faith Onyebujoh | C11: Consultancy | D11: 54000
A12: 9 | B12: Dr. Dare Fatai | C12: Consultancy | D12: 90000
A13: 10 | B13: Alkadriyar Abdullahi Abdullahi | C13: Consultancy | D13: 54000
A14: 11 | B14: Benjamin Ubiri | C14: Consultancy | D14: 54000
A15: 12 | B15: Mugisat Abdulganiyyu | C15: Consultancy | D15: 54000
... A18: 15 | B18: Godwin Etim | C18: Sergearnt at Arms | D18: 54000
B19: TOTAL | D19: =SUM(D4:D18) -> 846000
E101: =60000 -> 60000

Sheet HALF SALARY
A1: CONTRACT/SABBATICAL AND CONSULTANT HALF SALARY FOR THE MONTH OF DECEMBER 2023
A3: S/N | B3: STAFF NAME | C3: DESIGNATION | D3: TOTAL SALARY | E3: HALF SALARY DECEMBER 2023
E4: N
A5: 1 | B5: Dr. Mohammed Etudaiye | C5: Consultant | D5: 300000 | E5: =D5/2 -> 150000
A6: 2 | B6: Takwasa A. Galadima | C6: Nass Deployed | D6: 196027.8 | E6: =D6/2 -> 98013.9
A7: 3 | B7: Saratu Adamu Attajiri | C7: Office Assistant | D7: 120000 | E7: =D7/2 -> 60000
A8: 4 | B8: Aboaman Innocent | C8: Casual | D8: 60000 | E8: =D8/2 -> 30000
A9: 5 | B9: Kusai E. Richard | C9: Plumber | D9: 60000 | E9: =D9/2 -> 30000
A10: 6 | B10: Bulus Ishaya | C10: Gardener | D10: 60000 | E10: =D10/2 -> 30000
A11: 7 | B11: Alhamdu Iliya | C11: Casual-Gardner | D11: 65000 | E11: =D11/2 -> 32500
A12: 8 | B12: Salihu Hassan | C12: Casual-Gardner | D12: 65000 | E12: =D12/2 -> 32500
A13: 9 | B13: Ishaya Moro James | C13: Gardener | D13: 80000 | E13: =D13/2 -> 40000
A14: 10 | B14: Barr. James G Bathna | C14: Consultancy | D14: 300000 | E14: =D14/2 -> 150000
A15: 11 | B15: Dr. John Niyi Olanrewaju | C15: Consultancy | D15: 500000 | E15: =D15/2 -> 250000
A16: 12 | B16: Dr. Shehu Wahab L | C16: Consultant | D16: 300000 | E16: =D16/2 -> 150000
... A60: 68 | B60: Shittu Deborah Damilola | C60: NYSC | D60: 15000 | E60: =D60/2 -> 7500
B61: TOTAL | D61: 13498810 | E61: =SUM(E5:E60) -> 6659405.1
G143: =60000 -> 60000

Sheet HALF PAYMT (3)
A1: CONSULTANCY FEES FOR THE MONTH OF DECEMBER 2023
A3: S/N | B3: STAFF NAME | C3: DESIGNATION | D3: TOTAL/GROSS FEES | E3: HALF PAYMENT DECEMBER 2023
E4: N
A5: 1 | B5: Victoria Stephanie David | C5: Consultancy | D5: =150000 -> 150000 | E5: =D5/2 -> 75000
A6: 2 | B6: Kindness Oluwakemi M | C6: Consultancy | D6: =200000 -> 200000 | E6: =D6/2 -> 100000
A7: 3 | B7: Danladi Idris Daniel | C7: Consultancy | D7: =200000 -> 200000 | E7: =D7/2 -> 100000
A8: 4 | B8: Ufomba Patricia Osinachi | C8: Consultancy | D8: =150000 -> 150000 | E8: =D8/2 -> 75000
A9: 5 | B9: Anayo Akwitti | C9: Consultancy | D9: =200000 -> 200000 | E9: =D9/2 -> 100000
A10: 6 | B10: Otene Oche Jonah | C10: Consultancy | D10: =200000 -> 200000 | E10: =D10/2 -> 100000
A11: 7 | B11: Julian Chinyere Osamoto | C11: Consultancy | D11: =150000 -> 150000 | E11: =D11/2 -> 75000
A12: 8 | B12: Faith Onyebujoh | C12: Consultancy | D12: =200000 -> 200000 | E12: =D12/2 -> 100000
A13: 9 | B13: Dr. Dare Fatai | C13: Consultancy | D13: 300000 | E13: =D13/2 -> 150000
A14: 10 | B14: Alkadriyar Abdullahi Abdullahi | C14: Consultancy | D14: =150000 -> 150000 | E14: =D14/2 -> 75000
A15: 11 | B15: Benjamin Ubiri | C15: Consultancy | D15: 200000 | E15: =D15/2 -> 100000
A16: 12 | B16: Mugisat Abdulganiyyu | C16: Consultancy | D16: 150000 | E16: =D16/2 -> 75000
A17: 13 | B17: Echianu Chinedu Chikadibia | C17: Consultancy | D17: 150000 | E17: =D17/2 -> 75000
B18: TOTAL | D18: =SUM(D5:D17) -> 2400000 | E18: =SUM(E5:E17) -> 1200000
G100: =60000 -> 60000

Sheet Sheet28

Sheet Tenure 
B1: TENURE OF CONTRACT , SABBATICAL AND NYSC STAFF
B2: TENURE OF CONTRACT AND SABBATICAL STAFF
B4: STAFF NAME | C4: DESIGNATION | D4: START DATE | E4: EXPIRY DATE | F4: FIRST RENEWAL | G4: EXPIRY DATE
A5: 1 | B5: Prof. Edoba B. Omoregie | C5: Sabbatical | D5: 18th December, 2020 | E5: 18th December, 2021 | F5: 44478 | G5: 44842
A6: 2 | B6: Dr. Shehu Yahaya | C6: Consultant | D6: 25th February 2021 | E6: 25th February 2022
A7: 3 | B7: Prof. Attahiru Muhammadu Jega | C7: Consultant | D7: 7th September, 2020 | E7: 6th September, 2021
A8: 4 | B8: Prof. Alabi O Mojeed | C8: Sabbatical | D8: 11th August, 2020 | E8: 10th August, 2021
A9: 7 | B9: Abayomi Kolapo Quadri | D9: 1st June, 2021 | E9: 1st June, 2022 | F9: 44706 | G9: 45070
A10: 8 | B10: Takwasa A. Galadima | C10: Nass Deployed
A11: 12 | B11: Saratu Adamu Attajiri | C11: Office Assistant
A12: 13 | B12: Moshood Tosho Amuda | C12: Manager, Exams & Records | D12: 1st July, 2020 | E12: 30th June 2021
A13: 14 | B13: Maryam Muhammed Bello | C13: PA Special Duties | D13: 2nd August, 2019 | E13: 31st July, 2020
A14: 18 | B14: Aboaman Innocent | C14: Steward
A15: 19 | B15: Adanhou V. Alfred | C15: Steward
A16: 20 | B16: Kusai E. Richard | C16: Plumber
A17: 21 | B17: Enenche Jeremiah Agada | C17: Casual | D17: 4th September, 2020
A18: 22 | B18: Yahaya Adamu Abdulhamid | C18: Casual | D18: 30th November, 2020
A19: 23 | B19: Bulus Ishaya | C19: Gardener
A20: 24 | B20: Mohammed Etudaiye | C20: Consultant | D20: 1st February, 2021 | E20: 31st January, 2022 | F20: 44593 | G20: 44957
A21: 25 | B21: Prof. Jide Oladipo | C21: Sabbatical | D21: 26th August 2020 | E21: 25th August, 2021
A22: 26 | B22: Prof. Yusuf I. Arowosaiye | C22: Sabbatical | D22: 1st September, 2020 | E22: 31st August, 2021
A23: 27 | B23: Ndanusa Mohammed Manzuma -Ndaaba | C23: Mgr. Admin-Contract | D23: 2nd September, 2020 | E23: 1st September, 2021 | F23: 44835 | G23: 45170
A24: 28 | B24: Zainab Abbas | C24: Casual | D24: 4th September, 2020
A25: 29 | B25: Dr. Usman Wali | C25: SNR- Ast. PG Cood-Contract | D25: 17th August, 2020 | E25: 16th August 2021 | F25: 44845 | G25: 45209
A26: 30 | B26: Ayobolu Olajide Olufunsho | C26: Internal Editor- Contract | D26: 14th October, 2020 | E26: 13th October, 2021 | F26: 44835 | G26: 45170
A27: 31 | B27: Jimoh Munirat Olaide | C27: Casual | D27: 16th October, 2020 | E27: Contract Service
A28: 32 | B28: Dr. Olanrewaju John | C28: Contract | D28: 22nd May, 2020 | E28: 21st May 2021 | F28: 44739 | G28: 45103
A29: 33 | B29: Massarr Sarr | C29: Casual | D29: 24th November, 2020
A30: 34 | B30: Tessneem Ibrahim | C30: Permanent Staff | D30: 18th November, 2020
A31: 35 | B31: Dr. Olajide O Akanji | C31: Sabbatical | D31: 16th November, 2020
A32: 36 | B32: Prof. Shola Jeremiah Omotola | C32: Consultant | D32: 8th August 2020 | E32: 7th August 2021
A33: 37 | B33: Enobong Peter Sambo | C33: Retainership | D33: 9th October, 2020
A34: 38 | B34: Mr. Shehu Wahab | C34: Consultant | D34: 7th September, 2020 | E34: 6th September 2021 | F34: 1st November 2021 | G34: 31st October 2022
A35: 39 | B35: Abru Ololade Idowu | C35: Contract | D35: 5th October, 2020 | E35: 4th October, 2021
A36: 40 | B36: Adeojo Bolaji Joy | C36: NYSC | D36: 21st September, 2020
A37: 41 | B37: Jimoh Adebayo Zaka | C37: Casual | D37: 4th September, 2020
A38: 42 | B38: Abu Joan | C38: NYSC | D38: 1st September, 2020
A39: 43 | B39: Abdulsalam Iyabo Jariatu | C39: NYSC | D39: 1st September, 2020
A40: 44 | B40: Michael Daksiri Yahra | C40: NYSC | D40: 27th July, 2020
A41: 45 | B41: Dr Chris Itsede | C41: Consultant | D41: 1st July, 2020 | E41: 30th June 2021
...

Sheet Half Salary Allowance
A1: CONTRACT/SABBATICAL AND CONSULTANT HALF SALARY ALLOWANCE FOR THE MONTH OF DECEMBER 2022
A3: S/N | B3: STAFF NAME | C3: DESIGNATION | D3: BASIC ALLOWANCE | E3: LEGISLATIVE ALLOWCE | F3: GROSS | G3: NET SALARY DECEMBER 22
G4: N
A5: 1 | B5: Dr. Mohammed Etudaiye | C5: Consultant | D5: =300000 -> 300000 | E5: =0 -> 0 | F5: =D5+E5 -> 300000 | G5: =F5/2 -> 150000
A6: 2 | B6: Takwasa A. Galadima | C6: Nass Deployed | D6: =136027.8 -> 136027.8 | E6: =60000 -> 60000 | F6: =D6+E6 -> 196027.8 | G6: =F6/2 -> 98013.9
A7: 3 | B7: Saratu Adamu Attajiri | C7: Office Assistant | D7: 90000 | E7: 30000 | F7: =D7+E7 -> 120000 | G7: =F7/2 -> 60000
A8: 4 | B8: Aboaman Innocent | C8: Casual | D8: 45000 | E8: 15000 | F8: =D8+E8 -> 60000 | G8: =F8/2 -> 30000
A9: 5 | B9: Kusai E. Richard | C9: Plumber | D9: 45000 | E9: 15000 | F9: =D9+E9 -> 60000 | G9: =F9/2 -> 30000
A10: 6 | B10: Bulus Ishaya | C10: Gardener | D10: 45000 | E10: 15000 | F10: =D10+E10 -> 60000 | G10: =F10/2 -> 30000
A11: 7 | B11: Sholagberu T Sofiat | C11: Casual | D11: =90000 -> 90000 | E11: 30000 | F11: =D11+E11 -> 120000 | G11: =F11/2 -> 60000
A12: 8 | B12: Alhamdu Iliya | C12: Casual-Gardner | D12: =50000 -> 50000 | E12: 15000 | F12: =D12+E12 -> 65000 | G12: =F12/2 -> 32500
A13: 9 | B13: Salihu Hassan | C13: Casual-Gardner | D13: =50000 -> 50000 | E13: 15000 | F13: =D13+E13 -> 65000 | G13: =F13/2 -> 32500
A14: 10 | B14: Ishaya Moro James | C14: Gardener | D14: =60000 -> 60000 | E14: 20000 | F14: =D14+E14 -> 80000 | G14: =F14/2 -> 40000
A15: 11 | B15: James G Bathna | C15: Sabbatical | D15: =300000 -> 300000 | F15: =D15+E15 -> 300000 | G15: =F15/2 -> 150000
A16: 12 | B16: Dr. John Niyi Olanrewaju | C16: Consultancy | D16: =500000 -> 500000 | E16: =0 -> 0 | F16: =D16+E16 -> 500000 | G16: =F16/2 -> 250000
A17: 13 | B17: Mr. Shehu Wahab L | C17: Consultant | D17: 300000 | E17: 0 | F17: =D17+E17 -> 300000 | G17: =F17/2 -> 150000
A18: 14 | B18: Enobong Sambo | C18: Retainership | D18: =70000 -> 70000 | E18: 20000 | F18: =D18+E18 -> 90000 | G18: =F18/2 -> 45000
A19: 15 | B19: Masarr Sarr | C19: Casual | D19: =90000 -> 90000 | E19: 30000 | F19: =D19+E19 -> 120000 | G19: =F19/2 -> 60000
A20: 16 | B20: Aleke Friday Onyantu | C20: Casual | D20: =90000 -> 90000 | E20: =30000 -> 30000 | F20: =D20+E20 -> 120000 | G20: =F20/2 -> 60000
A21: 17 | B21: Ode Ijoko Michael | C21: Casual | D21: =90000 -> 90000 | E21: =30000 -> 30000 | F21: =D21+E21 -> 120000 | G21: =F21/2 -> 60000
A22: 18 | B22: Said Idris Abduljalil | C22: Secondment | D22: =105352.17 -> 105352.17 | E22: =(60000+50000) -> 110000 | F22: =D22+E22 -> 215352.17 | G22: =F22/2 -> 107676.08
A23: 19 | B23: Giwa Sidika Ajoke | C23: Casual(DGs GH) | D23: =90000 -> 90000 | E23: =30000 -> 30000 | F23: =D23+E23 -> 120000 | G23: =F23/2 -> 60000
A24: 20 | B24: Muhammed Khadijah Grema | C24: NYSC | D24: 15000 | E24: 0 | F24: =D24+E24 -> 15000 | G24: =F24/2 -> 7500
A25: 21 | B25: Rasheed Mariam Folashade | C25: Casual | D25: 90000 | E25: =30000 -> 30000 | F25: =D25+E25 -> 120000 | G25: =F25/2 -> 60000
A26: 22 | B26: Hadiza Saidu | C26: Sabbatical | D26: =399385.82 -> 399385.82 | E26: =160000 -> 160000 | F26: =D26+E26 -> 559385.82 | G26: =F26/2 -> 279692.91
A27: 23 | B27: Adebayo Warith Bolaji | C27: NYSC | D27: =15000 -> 15000 | E27: 0 | F27: =D27+E27 -> 15000 | G27: =F27/2 -> 7500
A28: 24 | B28: Moyaki Michael Olumide | C28: NYSC | D28: 15000 | F28: =D28+E28 -> 15000 | G28: =F28/2 -> 7500
A29: 25 | B29: Jibrin Blessing Ojone | C29: NYSC | D29: 15000 | F29: =D29+E29 -> 15000 | G29: =F29/2 -> 7500
A30: 26 | B30: Ajibade Saheed Olabanji | C30: NYSC | D30: 15000 | F30: =D30+E30 -> 15000 | G30: =F30/2 -> 7500
A31: 27 | B31: Suleiman Oluwatosin Mutiat | C31: NYSC | D31: 15000 | F31: =D31+E31 -> 15000 | G31: =F31/2 -> 7500
A32: 28 | B32: Omirinde Mariam | C32: NYSC | D32: 15000 | F32: =D32+E32 -> 15000 | G32: =F32/2 -> 7500
A33: 29 | B33: Mustapha Raheemat Adebola | C33: NYSC | D33: 15000 | F33: =D33+E33 -> 15000 | G33: =F33/2 -> 7500
A34: 30 | B34: Rosemighty Papki Ishaku | C34: NYSC | D34: 15000 | F34: =D34+E34 -> 15000 | G34: =F34/2 -> 7500
A35: 31 | B35: Etti Hawanat Oyenike | C35: Contract Staff | D35: =123329.05 -> 123329.05 | E35: 50000 | F35: =D35+E35 -> 173329.05 | G35: =F35/2 -> 86664.525
A36: 32 | B36: Lawal-Gambari Bilkis Sitou | C36: Contract Staff | D36: ='[3]Nils Salary Structure'!$H$36 -> 168601.58 | E36: 100000 | F36: =D36+E36 -> 268601.58 | G36: =F36/2 -> 134300.79
A37: 33 | B37: Olaniyan Taiwo Abimbola | C37: Contract Staff | D37: ='[3]Nils Salary Structure'!$H$35 -> 145203.67 | E37: 100000 | F37: =D37+E37 -> 245203.67 | G37: =F37/2 -> 122601.83
A38: 34 | B38: Sulaimon Aminat Jumoke | C38: Contract Staff | D38: =123329.05 -> 123329.05 | E38: 50000 | F38: =D38+E38 -> 173329.05 | G38: =F38/2 -> 86664.525
A39: 35 | B39: Mustapha Rafiu Ayobanji | C39: Contract Staff | D39: ='[4]October 2022'!$R$108-60000 -> 244895.91 | E39: 60000 | F39: =D39+E39 -> 304895.91 | G39: =F39/2 -> 152447.96
A40: 36 | B40: Idris Ibrahim | C40: Contract Staff | D40: =205372.08 -> 205372.08 | E40: 110000 | F40: =D40+E40 -> 315372.08 | G40: =F40/2 -> 157686.04
A41: 37 | B41: Aishatu O. Usman | C41: Sabbatical | D41: 328759.88 | E41: 160000 | F41: =D41+E41 -> 488759.88 | G41: =F41/2 -> 244379.94
...

Sheet Chrismas  Welfare (3)
A1: CONTRACT/SABBATICAL AND CONSULTANT STAFF WELFARE DECEMBER 2022
A3: S/N | B3: STAFF NAME | C3: DESIGNATION | D3: AMOUNT
A5: 1 | B5: Takwasa A. Galadima | C5: Nass Deployed | D5: 75000 | E5: =SUM(D5:D5) -> 75000
A6: 2 | B6: Saratu Adamu Attajiri | C6: Office Assistant | D6: 45000 | E6: =SUM(D6:D6) -> 45000
A7: 3 | B7: Aboaman Innocent | C7: Casual | D7: 30000 | E7: =SUM(D7:D7) -> 30000
A8: 4 | B8: Kusai E. Richard | C8: Plumber | D8: 30000 | E8: =SUM(D8:D8) -> 30000
A9: 5 | B9: Bulus Ishaya | C9: Gardener | D9: 30000 | E9: =SUM(D9:D9) -> 30000
A10: 6 | B10: Sholagberu T Sofiat | C10: Casual | D10: 45000 | E10: =SUM(D10:D10) -> 45000
A11: 7 | B11: Alhamdu Iliya | C11: Casual-Gardner | D11: 30000 | E11: =SUM(D11:D11) -> 30000
A12: 8 | B12: Salihu Hassan | C12: Casual-Gardner | D12: 30000 | E12: =SUM(D12:D12) -> 30000
A13: 9 | B13: Ishaya Moro James | C13: Gardener | D13: 30000 | E13: =SUM(D13:D13) -> 30000
A14: 10 | B14: James G Bathna | C14: Sabbatical | D14: 75000 | E14: =SUM(D14:D14) -> 75000
A15: 11 | B15: John Niyi Olanrewaju | C15: Consultant | D15: =105000 -> 105000
A16: 12 | B16: Enobong Sambo | C16: Retainership | D16: =25000*1.5 -> 37500 | E16: =SUM(D16:D16) -> 37500
A17: 13 | B17: Masarr Sarr | C17: Casual | D17: 45000 | E17: =SUM(D17:D17) -> 45000
A18: 14 | B18: Aleke Friday Onyantu | C18: Casual | D18: 45000 | E18: =SUM(D18:D18) -> 45000
A19: 15 | B19: Ode Ijoko Michael | C19: Casual | D19: 45000 | E19: =SUM(D19:D19) -> 45000
A20: 16 | B20: Said Idris Abduljalil | C20: Secondment | D20: 45000 | E20: =SUM(D20:D20) -> 45000
A21: 17 | B21: Giwa Sidika Ajoke | C21: Casual(DGs GH) | D21: 45000 | E21: =SUM(D21:D21) -> 45000
A22: 18 | B22: Abdullahi Ali Arazeem | C22: Sabbatical
A23: 19 | B23: Muhammed Khadijat | C23: NYSC | D23: 15000 | E23: =SUM(D23:D23) -> 15000
A24: 20 | B24: Rasheed Mariam Folashade | C24: Casual | D24: 45000 | E24: =SUM(D24:D24) -> 45000
A25: 21 | B25: Hadiza Saidu | C25: Sabbatical | D25: 105000 | E25: =SUM(D25:D25) -> 105000
A26: 22 | B26: Adebayo Warith Bolaji | C26: NYSC | D26: 15000 | E26: =SUM(D26:D26) -> 15000
A27: 23 | B27: Moyaki Michael Olumide | C27: NYSC | D27: 15000 | E27: =SUM(D27:D27) -> 15000
A28: 24 | B28: Jibrin Blessing Ojone | C28: NYSC | D28: 15000 | E28: =SUM(D28:D28) -> 15000
A29: 25 | B29: Ajibade Saheed Olabanji | C29: NYSC | D29: 15000 | E29: =SUM(D29:D29) -> 15000
A30: 26 | B30: Suleiman Oluwatosin Mutiat | C30: NYSC | D30: 15000
A31: 27 | B31: Omirinde Mariam | C31: NYSC | D31: 15000
A32: 28 | B32: Mustapha Raheemat Adebola | C32: NYSC | D32: 15000
A33: 29 | B33: Rosemighty Papki Ishaku | C33: NYSC | D33: 15000
A34: 30 | B34: Etti Hawanat Oyenike | C34: Contract Staff | D34: 45000
A35: 31 | B35: Lawal-Gambari Bilkis Sitou | C35: Contract Staff | D35: 45000
A36: 32 | B36: Olaniyan Taiwo Abimbola | C36: Contract Staff | D36: 45000
A37: 33 | B37: Sulaimon Aminat Jumoke | C37: Contract Staff | D37: 45000 | E37: =#REF!-#REF! -> #REF!
A38: 34 | B38: Mustapha Rafiu Ayobanji | C38: Contract Staff | D38: 45000
A39: 35 | B39: Idris Ibrahim | C39: Contract Staff | D39: 45000
A40: 36 | B40: Aishatu O. Usman | C40: Sabbatical | D40: 75000
A41: 37 | B41: Gunat Nansat Mark | C41: Contract Staff | D41: 45000
A42: 38 | B42: Suleima Abubakar Sodeeq | C42: Contract Staff | D42: 45000
...

Sheet Chrismas  Welfare (4)
A1: CONTRACT/SABBATICAL AND CONSULTANT STAFF WELFARE DECEMBER 2022
A3: S/N | B3: STAFF NAME | C3: DESIGNATION | D3: AMOUNT
A5: 1 | B5: Takwasa A. Galadima | C5: Nass Deployed | D5: =50000 -> 50000 | E5: =SUM(D5:D5) -> 50000
A6: 2 | B6: Saratu Adamu Attajiri | C6: Office Assistant | D6: 30000 | E6: =SUM(D6:D6) -> 30000
A7: 3 | B7: Aboaman Innocent | C7: Casual | D7: 20000 | E7: =SUM(D7:D7) -> 20000
A8: 4 | B8: Kusai E. Richard | C8: Plumber | D8: 20000 | E8: =SUM(D8:D8) -> 20000
A9: 5 | B9: Bulus Ishaya | C9: Gardener | D9: 20000 | E9: =SUM(D9:D9) -> 20000
A10: 6 | B10: Sholagberu T Sofiat | C10: Casual | D10: 30000 | E10: =SUM(D10:D10) -> 30000
A11: 7 | B11: Alhamdu Iliya | C11: Casual-Gardner | D11: 20000 | E11: =SUM(D11:D11) -> 20000
A12: 8 | B12: Salihu Hassan | C12: Casual-Gardner | D12: 20000 | E12: =SUM(D12:D12) -> 20000
A13: 9 | B13: Ishaya Moro James | C13: Gardener | D13: 20000 | E13: =SUM(D13:D13) -> 20000
A14: 10 | B14: James G Bathna | C14: Sabbatical | D14: 50000 | E14: =SUM(D14:D14) -> 50000
A15: 11 | B15: John Niyi Olanrewaju | C15: Consultant | D15: =70000 -> 70000
A16: 12 | B16: Enobong Sambo | C16: Retainership | D16: 25000 | E16: =SUM(D16:D16) -> 25000
A17: 13 | B17: Masarr Sarr | C17: Casual | D17: 30000 | E17: =SUM(D17:D17) -> 30000
A18: 14 | B18: Aleke Friday Onyantu | C18: Casual | D18: 30000 | E18: =SUM(D18:D18) -> 30000
A19: 15 | B19: Ode Ijoko Michael | C19: Casual | D19: 30000 | E19: =SUM(D19:D19) -> 30000
A20: 16 | B20: Said Idris Abduljalil | C20: Secondment | D20: 30000 | E20: =SUM(D20:D20) -> 30000
A21: 17 | B21: Giwa Sidika Ajoke | C21: Casual(DGs GH) | D21: 30000 | E21: =SUM(D21:D21) -> 30000
A22: 18 | B22: Abdullahi Ali Arazeem | C22: Sabbatical | D22: 70000
A23: 19 | B23: Muhammed Khadijat | C23: NYSC | D23: 10000 | E23: =SUM(D23:D23) -> 10000
A24: 20 | B24: Rasheed Mariam Folashade | C24: Casual | D24: 30000 | E24: =SUM(D24:D24) -> 30000
A25: 21 | B25: Hadiza Saidu | C25: Sabbatical | D25: 70000 | E25: =SUM(D25:D25) -> 70000
A26: 22 | B26: Adebayo Warith Bolaji | C26: NYSC | D26: =10000 -> 10000 | E26: =SUM(D26:D26) -> 10000
A27: 23 | B27: Moyaki Michael Olumide | C27: NYSC | D27: =10000 -> 10000 | E27: =SUM(D27:D27) -> 10000
A28: 24 | B28: Jibrin Blessing Ojone | C28: NYSC | D28: =10000 -> 10000 | E28: =SUM(D28:D28) -> 10000
A29: 25 | B29: Ajibade Saheed Olabanji | C29: NYSC | D29: =10000 -> 10000 | E29: =SUM(D29:D29) -> 10000
A30: 26 | B30: Suleiman Oluwatosin Mutiat | C30: NYSC | D30: =10000 -> 10000
A31: 27 | B31: Omirinde Mariam | C31: NYSC | D31: =10000 -> 10000
A32: 28 | B32: Mustapha Raheemat Adebola | C32: NYSC | D32: =10000 -> 10000
A33: 29 | B33: Rosemighty Papki Ishaku | C33: NYSC | D33: =10000 -> 10000
A34: 30 | B34: Etti Hawanat Oyenike | C34: Contract Staff | D34: 30000
A35: 31 | B35: Lawal-Gambari Bilkis Sitou | C35: Contract Staff | D35: 30000
A36: 32 | B36: Olaniyan Taiwo Abimbola | C36: Contract Staff | D36: 30000
A37: 33 | B37: Sulaimon Aminat Jumoke | C37: Contract Staff | D37: 30000 | E37: =#REF!-#REF! -> #REF!
A38: 34 | B38: Mustapha Rafiu Ayobanji | C38: Contract Staff | D38: 30000
A39: 35 | B39: Idris Ibrahim | C39: Contract Staff | D39: 30000
A40: 36 | B40: Aishatu O. Usman | C40: Sabbatical | D40: 50000
A41: 37 | B41: Gunat Nansat Mark | C41: Contract Staff | D41: 30000
A42: 38 | B42: Suleima Abubakar Sodeeq | C42: Contract Staff | D42: 30000
...

Sheet Sallah Welfare June 2023 
A1: CONTRACT/SABBATICAL AND CONSULTANT WELFARE JUNE 2023
A2: S/N | B2: STAFF NAME | C2: DESIGNATION | D2: WELFARE AMOUNT
D3: N
A4: 1 | B4: Dr. Mohammed Etudaiye | C4: Consultant | D4: 75000
A5: 2 | B5: Takwasa A. Galadima | C5: Nass Deployed | D5: 75000
A6: 3 | B6: Saratu Adamu Attajiri | C6: Office Assistant | D6: 45000
A7: 4 | B7: Aboaman Innocent | C7: Casual | D7: 30000
A8: 5 | B8: Kusai E. Richard | C8: Plumber | D8: 30000
A9: 6 | B9: Bulus Ishaya | C9: Gardener | D9: 30000
A10: 7 | B10: Alhamdu Iliya | C10: Casual-Gardner | D10: 30000
A11: 8 | B11: Salihu Hassan | C11: Casual-Gardner | D11: 30000
A12: 9 | B12: Ishaya Moro James | C12: Gardener | D12: 30000
A13: 10 | B13: James G Bathna | C13: Sabbatical | D13: 75000
A14: 11 | B14: Dr. John Niyi Olanrewaju | C14: Consultancy | D14: 75000
A15: 12 | B15: Mr. Shehu Wahab L | C15: Consultant | D15: 75000
... A59: 56 | B59: Francis Onyekwere Ozoh | C59: Sabbatical | D59: 75000
A60: 57 | B60: Prof. Zubairu Kwambo Dagona | C60: Contract Staff | D60: =225000 -> 225000
A61: 58 | B61: Atofarati Umar Faruq | C61: NYSC | D61: 15000
A62: 59 | B62: Ogbormeh Micheal Ikenchukwu | C62: NYSC | D62: 15000
A63: 60 | B63: Abdullahi Sekinat Ayomide | C63: NYSC | D63: 15000
A64: 61 | B64: Mustapha Ola Sulyman | C64: NYSC | D64: 15000
A65: 62 | B65: Muhammad Kudu Abubakar | C65: Ag. Gen Manager | D65: 150000
A66: 63 | B66: Prof. Mohammed Mustapha Namadi | C66: Sabbatical | D66: 75000
A67: 64 | B67: Ibrahim Kaltume Onawo | C67: NYSC | D67: 15000
A68: 65 | B68: Hassan Mahmud Adewole | C68: NYSC | D68: 15000
A69: 66 | B69: Nwanganga Chidozie | C69: House Keeper | D69: 45000
A70: 67 | B70: Mary Shadrach | C70: Cleaner | D70: 45000
A71: 68 | B71: Suberu Rahimat Onize | C71: Intern | D71: 45000
A72: 69 | B72: Akinboboye Oluwatosin Ifedayo | C72: NYSC | D72: 15000
B73: TOTAL | D73: =SUM(D4:D72) -> 2842500
F158: =60000 -> 60000

Sheet Sallah Welfare June 2023 Latest
A1: CONTRACT/SABBATICAL AND CONSULTANT WELFARE JUNE 2023
A2: S/N | B2: STAFF NAME | C2: DESIGNATION | D2: WELFARE AMOUNT
D3: N
A4: 1 | B4: Dr. Mohammed Etudaiye | C4: Consultant | D4: 90000
A5: 2 | B5: Takwasa A. Galadima | C5: Nass Deployed | D5: 90000
A6: 3 | B6: Saratu Adamu Attajiri | C6: Office Assistant | D6: 54000
A7: 4 | B7: Aboaman Innocent | C7: Casual | D7: 36000
A8: 5 | B8: Kusai E. Richard | C8: Plumber | D8: 36000
A9: 6 | B9: Bulus Ishaya | C9: Gardener | D9: 36000
A10: 7 | B10: Alhamdu Iliya | C10: Casual-Gardner | D10: 36000
A11: 8 | B11: Salihu Hassan | C11: Casual-Gardner | D11: 36000
A12: 9 | B12: Ishaya Moro James | C12: Gardener | D12: 36000
A13: 10 | B13: James G Bathna | C13: Sabbatical | D13: 90000
A14: 11 | B14: Dr. John Niyi Olanrewaju | C14: Consultancy | D14: 90000
A15: 12 | B15: Mr. Shehu Wahab L | C15: Consultant | D15: 90000
... A66: 63 | B66: Akinboboye Oluwatosin Ifedayo | C66: NYSC | D66: 18000
B67: TOTAL | D67: =SUM(D4:D66) -> 3159000
F152: =60000 -> 60000

Sheet Sheet27

Sheet Sallah Welfare April 2023
A1: CONTRACT/SABBATICAL AND CONSULTANT WELFARE APRIL 2023
A3: S/N | B3: STAFF NAME | C3: DESIGNATION | D3: WELFARE AMOUNT
D4: N
A5: 1 | B5: Dr. Mohammed Etudaiye | C5: Consultant | D5: 75000
A6: 2 | B6: Takwasa A. Galadima | C6: Nass Deployed | D6: 75000
A7: 3 | B7: Saratu Adamu Attajiri | C7: Office Assistant | D7: 45000
A8: 4 | B8: Aboaman Innocent | C8: Casual | D8: 30000
A9: 5 | B9: Kusai E. Richard | C9: Plumber | D9: 30000
A10: 6 | B10: Bulus Ishaya | C10: Gardener | D10: 30000
A11: 8 | B11: Alhamdu Iliya | C11: Casual-Gardner | D11: 30000
A12: 9 | B12: Salihu Hassan | C12: Casual-Gardner | D12: 30000
A13: 10 | B13: Ishaya Moro James | C13: Gardener | D13: 30000
A14: 11 | B14: James G Bathna | C14: Sabbatical | D14: 75000
A15: 12 | B15: Dr. John Niyi Olanrewaju | C15: Consultancy | D15: 75000
A16: 13 | B16: Mr. Shehu Wahab L | C16: Consultant | D16: 75000
... A61: 62 | B61: Francis Onyekwere Ozoh | C61: Sabbatical | D61: 75000
B62: TOTAL | D62: =SUM(D5:D61) -> 2197500
A67: PREPARED BY: RAHILA N. HABU
F149: =60000 -> 60000

Sheet March (2)
A1: CONTRACT/SABBATICAL AND CONSULTANT SALARY FOR THE MONTH OF MARCH 2023
A3: S/N | B3: STAFF NAME | C3: DESIGNATION | D3: BASIC ALLOWANCE | E3: LEGISLATIVE ALLOWCE | F3: GROSS | G3: DEDUCTIONS | K3: NET SALARY MARCH 2023
G4: COOP CONTR | H4: COOP LOAN RECOVERY | I4: PAYE TAX | J4: TOTAL DEDUCTION | K4: N
A5: 1 | B5: Dr. Mohammed Etudaiye | C5: Consultant | D5: =300000 -> 300000 | E5: =0 -> 0 | F5: =D5+E5 -> 300000 | I5: 37566.667 | J5: =G5+H5+I5 -> 37566.667 | K5: =F5-J5 -> 262433.33
A6: 2 | B6: Takwasa A. Galadima | C6: Nass Deployed | D6: =136027.8 -> 136027.8 | E6: =60000 -> 60000 | F6: =D6+E6 -> 196027.8 | G6: =30000 -> 30000 | I6: ='[1]August 2022 '!$AD$6 -> 20099.337 | J6: =G6+H6+I6 -> 50099.337 | K6: =F6-J6 -> 145928.46
A7: 3 | B7: Saratu Adamu Attajiri | C7: Office Assistant | D7: 90000 | E7: 30000 | F7: =D7+E7 -> 120000 | G7: 10000 | H7: =20000 -> 20000 | I7: 8900 | J7: =G7+H7+I7 -> 38900 | K7: =F7-J7 -> 81100
A8: 4 | B8: Aboaman Innocent | C8: Casual | D8: 45000 | E8: 15000 | F8: =D8+E8 -> 60000 | G8: =10000 -> 10000 | H8: =10000+10000 -> 20000 | I8: 2446.6667 | J8: =G8+H8+I8 -> 32446.667 | K8: =F8-J8 -> 27553.333
A9: 5 | B9: Kusai E. Richard | C9: Plumber | D9: 45000 | E9: 15000 | F9: =D9+E9 -> 60000 | G9: =10000 -> 10000 | H9: =20000 -> 20000 | I9: 2446.6667 | J9: =G9+H9+I9 -> 32446.667 | K9: =F9-J9 -> 27553.333
A10: 6 | B10: Bulus Ishaya | C10: Gardener | D10: 45000 | E10: 15000 | F10: =D10+E10 -> 60000 | I10: 2446.6667 | J10: =G10+H10+I10 -> 2446.6667 | K10: =F10-J10 -> 57553.333
A11: 8 | B11: Alhamdu Iliya | C11: Casual-Gardner | D11: =50000 -> 50000 | E11: 15000 | F11: =D11+E11 -> 65000 | G11: =5000+5000+5000 -> 15000 | H11: =14350 -> 14350 | I11: 2886.6667 | J11: =G11+H11+I11 -> 32236.667 | K11: =F11-J11 -> 32763.333
A12: 9 | B12: Salihu Hassan | C12: Casual-Gardner | D12: =50000 -> 50000 | E12: 15000 | F12: =D12+E12 -> 65000 | G12: =5000 -> 5000 | H12: 10500 | I12: 2886.6667 | J12: =G12+H12+I12 -> 18386.667 | K12: =F12-J12 -> 46613.333
A13: 10 | B13: Ishaya Moro James | C13: Gardener | D13: =60000 -> 60000 | E13: 20000 | F13: =D13+E13 -> 80000 | G13: =10000 -> 10000 | H13: =17500 -> 17500 | I13: 4206.6667 | J13: =G13+H13+I13 -> 31706.667 | K13: =F13-J13 -> 48293.333
A14: 11 | B14: James G Bathna | C14: Sabbatical | D14: =300000 -> 300000 | F14: =D14+E14 -> 300000 | I14: 37566.667 | J14: =G14+H14+I14 -> 37566.667 | K14: =F14-J14 -> 262433.33
A15: 12 | B15: Dr. John Niyi Olanrewaju | C15: Consultancy | D15: =500000 -> 500000 | E15: =0 -> 0 | F15: =D15+E15 -> 500000 | G15: 25000 | H15: 60640 | I15: 74666.667 | J15: =G15+H15+I15 -> 160306.67 | K15: =F15-J15 -> 339693.33
A16: 13 | B16: Mr. Shehu Wahab L | C16: Consultant | D16: 300000 | E16: 0 | F16: =D16+E16 -> 300000 | I16: 37566.667 | J16: =G16+H16+I16 -> 37566.667 | K16: =F16-J16 -> 262433.33
A17: 14 | B17: Enobong Sambo | C17: Retainership | D17: =70000 -> 70000 | E17: 20000 | F17: =D17+E17 -> 90000 | G17: =0 -> 0 | I17: 5300 | J17: =G17+H17+I17 -> 5300 | K17: =F17-J17 -> 84700
A18: 15 | B18: Masarr Sarr | C18: Casual | D18: =90000 -> 90000 | E18: 30000 | F18: =D18+E18 -> 120000 | I18: 8900 | J18: =G18+H18+I18 -> 8900 | K18: =F18-J18 -> 111100
A19: 16 | B19: Aleke Friday Onyantu | C19: Casual | D19: =90000 -> 90000 | E19: =30000 -> 30000 | F19: =D19+E19 -> 120000 | I19: 8900 | J19: =G19+H19+I19 -> 8900 | K19: =F19-J19 -> 111100
A20: 17 | B20: Ode Ijoko Michael | C20: Casual | D20: =90000 -> 90000 | E20: =30000 -> 30000 | F20: =D20+E20 -> 120000 | I20: 8900 | J20: =G20+H20+I20 -> 8900 | K20: =F20-J20 -> 111100
A21: 18 | B21: Said Idris Abduljalil | C21: Secondment | D21: =105352.17 -> 105352.17 | E21: =(60000+50000) -> 110000 | F21: =D21+E21 -> 215352.17 | I21: 23345.831 | J21: =G21+H21+I21 -> 23345.831 | K21: =F21-J21 -> 192006.34
A22: 19 | B22: Giwa Sidika Ajoke | C22: Casual (DGs GH) | D22: =90000 -> 90000 | E22: =30000 -> 30000 | F22: =D22+E22 -> 120000 | I22: 8900 | J22: =G22+H22+I22 -> 8900 | K22: =F22-J22 -> 111100
A23: 21 | B23: Rasheed Mariam Folashade | C23: Casual | D23: 90000 | E23: =30000 -> 30000 | F23: =D23+E23 -> 120000 | I23: 8900 | J23: =G23+H23+I23 -> 8900 | K23: =F23-J23 -> 111100
A24: 22 | B24: Hadiza Saidu | C24: Sabbatical | D24: =399385.82 -> 399385.82 | E24: =160000 -> 160000 | F24: =D24+E24 -> 559385.82 | I24: 86068.744 | J24: =G24+H24+I24 -> 86068.744 | K24: =F24-J24 -> 473317.08
A25: 24 | B25: Moyaki Michael Olumide | C25: NYSC | D25: 15000 | F25: =D25+E25 -> 15000 | I25: 0 | J25: =G25+H25+I25 -> 0 | K25: =F25-J25 -> 15000
A26: 25 | B26: Jibrin Blessing Ojone | C26: NYSC | D26: 15000 | F26: =D26+E26 -> 15000 | I26: 0 | J26: =G26+H26+I26 -> 0 | K26: =F26-J26 -> 15000
A27: 27 | B27: Suleiman Oluwatosin Mutiat | C27: NYSC | D27: 15000 | F27: =D27+E27 -> 15000 | I27: 0 | J27: =G27+H27+I27 -> 0 | K27: =F27-J27 -> 15000
A28: 29 | B28: Mustapha Raheemat Adebola | C28: NYSC | D28: 15000 | F28: =D28+E28 -> 15000 | I28: 0 | J28: =G28+H28+I28 -> 0 | K28: =F28-J28 -> 15000
A29: 30 | B29: Rosemighty Papki Ishaku | C29: NYSC | D29: 15000 | F29: =D29+E29 -> 15000 | I29: 0 | J29: =G29+H29+I29 -> 0 | K29: =F29-J29 -> 15000
A30: 31 | B30: Etti Hawanat Oyenike | C30: Contract Staff | D30: =123329.05 -> 123329.05 | E30: 50000 | F30: =D30+E30 -> 173329.05 | I30: =16512.68 -> 16512.68 | J30: =G30+H30+I30 -> 16512.68 | K30: =F30-J30 -> 156816.37
A31: 32 | B31: Lawal-Gambari Bilkis Sitou | C31: Contract Staff | D31: ='[3]Nils Salary Structure'!$H$36 -> 168601.58 | E31: 100000 | F31: =D31+E31 -> 268601.58 | I31: =32291.82 -> 32291.82 | J31: =G31+H31+I31 -> 32291.82 | K31: =F31-J31 -> 236309.76
A32: 33 | B32: Olaniyan Taiwo Abimbola | C32: Contract Staff | D32: ='[3]Nils Salary Structure'!$H$35 -> 145203.67 | E32: 100000 | F32: =D32+E32 -> 245203.67 | I32: =21640.95 -> 21640.95 | J32: =G32+H32+I32 -> 21640.95 | K32: =F32-J32 -> 223562.72
A33: 34 | B33: Sulaimon Aminat Jumoke | C33: Contract Staff | D33: =123329.05 -> 123329.05 | E33: 50000 | F33: =D33+E33 -> 173329.05 | G33: 20000 | I33: =I30 -> 16512.68 | J33: =G33+H33+I33 -> 36512.68 | K33: =F33-J33 -> 136816.37
A34: 35 | B34: Mustapha Rafiu Ayobanji | C34: Contract Staff | D34: ='[4]October 2022'!$R$108-60000 -> 244895.91 | E34: 60000 | F34: =D34+E34 -> 304895.91 | I34: =31749.1368366667 -> 31749.137 | J34: =G34+H34+I34 -> 31749.137 | K34: =F34-J34 -> 273146.78
A35: 36 | B35: Idris Ibrahim | C35: Contract Staff | D35: =205372.08 -> 205372.08 | E35: 110000 | F35: =D35+E35 -> 315372.08 | I35: ='Arrears in Nov'!B4 -> 40149.18 | J35: =G35+H35+I35 -> 40149.18 | K35: =F35-J35 -> 275222.9
A36: 37 | B36: Aishatu O. Usman | C36: Sabbatical | D36: 328759.88 | E36: 160000 | F36: =D36+E36 -> 488759.88 | I36: =72508.5636266667 -> 72508.564 | J36: =G36+H36+I36 -> 72508.564 | K36: =F36-J36 -> 416251.32
A37: 38 | B37: Maryam Musa Sada | C37: Contract Staff | D37: =268602.07775-100000 -> 168602.08 | E37: 100000 | F37: =D37+E37 -> 268602.08 | I37: 32291.82 | J37: =G37+H37+I37 -> 32291.82 | K37: =F37-J37 -> 236310.26
A38: 39 | B38: Garba Rofiat Kehinde | C38: NYSC | D38: 15000 | F38: =D38+E38 -> 15000 | I38: 0 | J38: =G38+H38+I38 -> 0 | K38: =F38-J38 -> 15000
A39: 40 | B39: Ogah Friday David | C39: NYSC | D39: 15000 | F39: =D39+E39 -> 15000 | I39: 0 | J39: =G39+H39+I39 -> 0 | K39: =F39-J39 -> 15000
A40: 41 | B40: Ismail Fauzyat | C40: NYSC | D40: 15000 | F40: =D40+E40 -> 15000 | I40: 0 | J40: =G40+H40+I40 -> 0 | K40: =F40-J40 -> 15000
A41: 42 | B41: Owolabi Olawale Adebayo | C41: NYSC | D41: 15000 | F41: =D41+E41 -> 15000 | I41: 0 | J41: =G41+H41+I41 -> 0 | K41: =F41-J41 -> 15000
...

Sheet Sheet26

Sheet Arrears in Nov
A2: Idris Ibrahim | B2: New Placement | C2: 40 days old grade | D2: 40 days New placement | E2: diffrence | F2: Total Salary in November
B3: 315372.08 | C3: 346583.33 | D3: 406931.72 | E3: =D3-C3 -> 60348.39 | F3: =B3+E3 -> 375720.47
B4: 40149.18 | C4: 41666.865 | D4: 51805.394 | E4: =D4-C4 -> 10138.529 | F4: =B4+E4 -> 50287.709
B5: 275222.9 | C5: 304916.46 | D5: 355126.32 | E5: =D5-C5 -> 50209.861 | F5: =B5+E5 -> 325432.76
A7: Emily | B7: Diff for 1 month | C7: No of Month | D7: Total
B8: ='[5]Promotion Arrear'!$H$17 -> 8607 | C8: =7.73 -> 7.73 | D8: =B8*C8 -> 66532.11
A9: Research Allowance | B9: 20000 | C9: =7.73 -> 7.73 | D9: =B9*C9 -> 154600
B10: Total Arrears | D10: =SUM(D8:D9) -> 221132.11

Sheet Salah Welfare
G5: DEDUCTIONS | K5: WELFARE
A6: S/N | B6: STAFF NAME | C6: DESIGNATION | D6: GROSS | E6: LEGISLATIVE | F6: GROSS | K6: 44743
G7: COOP CONTR | H7: COOP LOAN | I7: TAX | J7: TOTAL DEDUCTION | K7: N
A8: 1 | B8: Takwasa A. Galadima | C8: Nass Deployed | D8: 114649.42 | E8: =60000 -> 60000 | F8: =D8+E8 -> 174649.42 | G8: =30000 -> 30000 | I8: 0 | J8: =G8+H8+I8 -> 30000 | K8: 30000
A9: 2 | B9: Saratu Adamu Attajiri | C9: Office Assistant | D9: 90000 | E9: 30000 | F9: =D9+E9 -> 120000 | G9: 50000 | H9: =20000 -> 20000 | I9: 0 | J9: =G9+H9+I9 -> 70000 | K9: 30000
A10: 3 | B10: Aboaman Innocent | C10: Casual | D10: 45000 | E10: 15000 | F10: =D10+E10 -> 60000 | G10: =10000 -> 10000 | H10: =10000+10000 -> 20000 | I10: 0 | J10: =G10+H10+I10 -> 30000 | K10: 20000
A11: 4 | B11: Kusai E. Richard | C11: Plumber | D11: 45000 | E11: 15000 | F11: =D11+E11 -> 60000 | G11: =10000 -> 10000 | H11: =20000 -> 20000 | I11: 0 | J11: =G11+H11+I11 -> 30000 | K11: 20000
A12: 5 | B12: Ayuba Sule | C12: Contract | D12: =96825 -> 96825 | E12: 30000 | F12: =D12+E12 -> 126825 | G12: =10000+5000 -> 15000 | H12: =32000 -> 32000 | I12: 0 | J12: =G12+H12+I12 -> 47000 | K12: 30000
A13: 6 | B13: Bulus Ishaya | C13: Gardener | D13: 45000 | E13: 15000 | F13: =D13+E13 -> 60000 | J13: =G13+H13+I13 -> 0 | K13: 20000
A14: 7 | B14: Sholagberu T Sofiat | C14: Casual | D14: =90000 -> 90000 | E14: 30000 | F14: =D14+E14 -> 120000 | G14: =30000 -> 30000 | H14: =0 -> 0 | J14: =G14+H14+I14 -> 30000 | K14: 30000
A15: 8 | B15: Jimoh Munirat Olaide | C15: Casual | D15: =90000 -> 90000 | E15: 30000 | F15: =D15+E15 -> 120000 | G15: =50000 -> 50000 | H15: =10000 -> 10000 | J15: =G15+H15+I15 -> 60000 | K15: 30000
A16: 9 | B16: Alhamdu Iliya | C16: Casual-Gardner | D16: =50000 -> 50000 | E16: 15000 | F16: =D16+E16 -> 65000 | G16: =5000+5000 -> 10000 | H16: =14350 -> 14350 | J16: =G16+H16+I16 -> 24350 | K16: 20000
A17: 10 | B17: Salihu Hassan | C17: Casual-Gardner | D17: =50000 -> 50000 | E17: 15000 | F17: =D17+E17 -> 65000 | G17: =5000 -> 5000 | J17: =G17+H17+I17 -> 5000 | K17: 20000
A18: 11 | B18: Ishaya Moro James | C18: Gardener | D18: =60000 -> 60000 | E18: 20000 | F18: =D18+E18 -> 80000 | G18: =10000 -> 10000 | J18: =G18+H18+I18 -> 10000 | K18: 20000
A19: 12 | B19: John Niyi Olanrewaju | C19: Consultant | K19: =70000 -> 70000
A20: 13 | B20: Enobong Sambo | C20: Retainership | D20: =70000 -> 70000 | E20: 20000 | F20: =D20+E20 -> 90000 | G20: =0 -> 0 | J20: =G20+H20+I20 -> 0 | K20: 20000
A21: 14 | B21: Masarr Sarr | C21: Casual | D21: =90000 -> 90000 | E21: 30000 | F21: =(D21+E21) -> 120000 | J21: =G21+H21+I21 -> 0 | K21: 30000
A22: 15 | B22: Yahaya Adamu Abdulhamid | C22: Casual | D22: =90000 -> 90000 | E22: 30000 | F22: =D22+E22 -> 120000 | J22: =G22+H22+I22 -> 0 | K22: 30000
A23: 16 | B23: Frances Edna Hananiya | C23: Casual | D23: =90000 -> 90000 | E23: 30000 | F23: =D23+E23 -> 120000 | J23: =G23+H23+I23 -> 0 | K23: 30000
A24: 17 | B24: Hazeem Hussain | C24: Casual | D24: =90000 -> 90000 | E24: =30000 -> 30000 | F24: =(D24+E24) -> 120000 | G24: =3000 -> 3000 | H24: =25000 -> 25000 | J24: =G24+H24 -> 28000 | K24: 30000
A25: 18 | B25: Aleke Friday Onyantu | C25: Casual | D25: =90000 -> 90000 | E25: =30000 -> 30000 | F25: =(D25+E25) -> 120000 | J25: =G25+H25+I25 -> 0 | K25: 30000
A26: 19 | B26: Ode Ijoko Michael | C26: Casual | D26: =90000 -> 90000 | E26: =30000 -> 30000 | F26: =(D26+E26) -> 120000 | J26: =G26+H26+I26 -> 0 | K26: 30000
A27: 20 | B27: Haruna Jibril Ameh | C27: Casual | D27: =90000 -> 90000 | E27: =30000 -> 30000 | F27: =D27+E27 -> 120000 | J27: =G27+H27+I27 -> 0 | K27: 30000
A28: 21 | B28: Akwawo Michele Kennedy | C28: NYSC | D28: =15000 -> 15000 | F28: =D28+E28 -> 15000 | J28: =G28+H28+I28 -> 0 | K28: 10000
A29: 22 | B29: Schicha Ebweyi Joshua | C29: NYSC | D29: =15000 -> 15000 | F29: 15000 | J29: =G29+H29+I29 -> 0 | K29: 10000
A30: 23 | B30: Abdullahi Ali Arazeem | C30: Sabbatical | D30: =373287.83 -> 373287.83 | E30: =160000 -> 160000 | F30: =D30+E30 -> 533287.83 | I30: =15548.33 -> 15548.33 | J30: =G30+H30+I30 -> 15548.33 | K30: =70000 -> 70000
