Workbook

Sheet DECEMBER 2024
A1: NATIONAL INSTITUTE FOR LEGISLATIVE AND DEMOCRATIC STUDIES
A2: STAFF PAYROLL FOR THE MONTH OF DECEMBER, 2024
E3: ='[1]FEB 08'!E11/'[1]FEB 08'!M11 -> #REF!
B4: STAFF NAME | C4: DESIGNATION | D4: GRADE LEVEL | E4: BASIC SALARY | F4: ALLCE/ AREARS | G4: ALLOWANCE | H4: ALLOWANCE | I4: DUTY ALLCE | J4: GROSS SALARY | K4: AUCTION | L4: COOP CONTR/SPEC SAVINGS | M4: COOP. LOAN RECOVERY | N4: NHF DED. | O4: PAYE | P4: EMPLOYEE PENSIONS | Q4: TOTAL DEDUCTION | R4: NOVEMBER, 2024 | S4: DECEMBER, 2024
E5: N | F5: N | G5: N | H5: N | I5: N | J5: N | K5: N | L5: N | M5: N | N5: N | O5: N | P5: N | Q5: N | R5: N | S5: N
A6: S/N | B6: DG'S OFFICE
A7: 1 | B7: PROF. ABUBAKAR O. SULAIMAN | C7: DIRECTOR GENERAL | D7: CONSOL | E7: 1659751.2 | G7: =250000 -> 250000 | I7: 25235 | J7: =E7+F7+G7+H7+I7 -> 1934986.2 | O7: 350184.01 | Q7: =O7+N7+M7+L7+K7+P7 -> 350184.01 | R7: 1584802.2 | S7: =J7-Q7 -> 1584802.2
A8: 2 | B8: RAHEEM USMAN AYIGORO | C8: SA-INFRASTRUCTURE | D8: 16 (9) | E8: 762373.17 | H8: =90000 -> 90000 | I8: =100000 -> 100000 | J8: =E8+F8+G8+H8+I8 -> 952373.17 | L8: =250000 -> 250000 | O8: ='Additional Leg Duty Allowance'!P7 -> 149812.26 | P8: 60989.853 | Q8: =O8+N8+M8+L8+K8+P8 -> 460802.12 | R8: 491571.05 | S8: =J8-Q8 -> 491571.05
A9: 3 | B9: MARIAM MOHAMMED BELLO | C9: SA- SPECIAL DUTIES | D9: 16 (9) | E9: 762373.17 | H9: =90000 -> 90000 | I9: =200000+100000 -> 300000 | J9: =E9+F9+G9+H9+I9 -> 1152373.2 | O9: ='Additional Leg Duty Allowance'!P8 -> 199922.31 | Q9: =O9+N9+M9+L9+K9+P9 -> 199922.31 | R9: 952450.85 | S9: =J9-Q9 -> 952450.85
A10: 4 | B10: DR IKEME ARTHUR J.O | C10: DEPUTY DIRECTOR, M&E | D10: 16 (9) | E10: 762373.17 | G10: 180000 | I10: 0 | J10: =E10+F10+G10+H10+I10 -> 942373.17 | L10: =50000 -> 50000 | M10: 0 | N10: 10293.398 | O10: 147687.53 | P10: 60989.853 | Q10: =O10+N10+M10+L10+K10+P10 -> 268970.78 | R10: 673402.39 | S10: =J10-Q10 -> 673402.39
A11: 5 | B11: MOSHOOD M. OLALERE | C11: DEPUTY DIR. GENERAL SERVICE | D11: 16 (9) | E11: 762373.17 | H11: =80000+10000 -> 90000 | I11: =150000+100000 -> 250000 | J11: =E11+F11+G11+H11+I11 -> 1102373.2 | L11: =20000+60000 -> 80000 | M11: ='[2]OCTOBER 2023 '!$D$193 -> 230499.8 | N11: 10293.398 | O11: ='Additional Leg Duty Allowance'!P9 -> 178407.53 | P11: 60989.853 | Q11: =O11+N11+M11+L11+K11+P11 -> 560190.58 | R11: 542182.59 | S11: =J11-Q11 -> 542182.59
A12: 6 | B12: ANDRAWUS MUSA | C12: ASST. DIRECTOR, STORES | D12: 15(9) | E12: 620675.58 | H12: =80000 -> 80000 | I12: 50000 | J12: =E12+F12+G12+H12+I12 -> 750675.58 | L12: =50000-40000 -> 10000 | M12: =90000+110000 -> 200000 | N12: 8380.2271 | O12: 113101.97 | P12: 49654.047 | Q12: =O12+N12+M12+L12+K12+P12 -> 381136.24 | R12: 369539.34 | S12: =J12-Q12 -> 369539.34
A13: 7 | B13: DR FRANCIS NDUM OJIE | C13: AD, TRAINING & IC./SA TO DG | D13: 15(7) | E13: 582118.08 | G13: 160000 | I13: =100000+100000 -> 200000 | J13: =E13+F13+G13+H13+I13 -> 942118.08 | N13: 7859.6313 | O13: ='Additional Leg Duty Allowance'!P12 -> 150463.11 | P13: 46569.447 | Q13: =O13+N13+M13+L13+K13+P13 -> 204892.19 | R13: 737225.9 | S13: =J13-Q13 -> 737225.9
A14: 8 | B14: ALI ABDULLAHI | C14: CHIEF ICT OFFICER | D14: 14(11) | E14: 484373.75 | H14: =70000 -> 70000 | I14: =0 -> 0 | J14: =E14+F14+G14+H14+I14 -> 554373.75 | O14: 77666.446 | P14: 38749.9 | Q14: =O14+N14+M14+L14+K14+P14 -> 116416.35 | R14: 437957.4 | S14: =J14-Q14 -> 437957.4
A15: 9 | B15: EMILY EKHIDE | C15: SENIOR RESEARCH FELLOW | D15: 15(7) | E15: 582118.08 | G15: 160000 | I15: =50000+100000 -> 150000 | J15: =E15+F15+G15+H15+I15 -> 892118.08 | L15: =50000 -> 50000 | O15: 141011.99 | P15: =46569.45 -> 46569.45 | Q15: =O15+N15+M15+L15+K15+P15 -> 237581.44 | R15: 1110207.2 | S15: =J15-Q15 -> 654536.64
A16: 10 | B16: DORIS DAKDA AARON | C16: RESEARCH FELLOW I | D16: 14(8) | E16: 442746.5 | G16: =140000 -> 140000 | I16: =150000+100000 -> 250000 | J16: =E16+F16+G16+H16+I16 -> 832746.5 | L16: 70000 | M16: 175000 | O16: ='Additional Leg Duty Allowance'!P13 -> 131753.41 | P16: 35419.72 | Q16: =O16+N16+M16+L16+K16+P16 -> 412173.13 | R16: 420573.37 | S16: =J16-Q16 -> 420573.37
A17: 11 | B17: ABDULSALAM S. MUSTAPHA | C17: ASST. DIRECTOR ICT | D17: 15(7) | E17: 582118.08 | H17: 80000 | I17: 50000 | J17: =E17+F17+G17+H17+I17 -> 712118.08 | O17: 106452 | P17: =46569.45 -> 46569.45 | Q17: =O17+N17+M17+L17+K17+P17 -> 153021.45 | R17: 662060.49 | S17: =J17-Q17 -> 559096.63
A18: 12 | B18: PERCY TERFA GBAHABO | C18: HEAD, NILDS LIAISON OFFICE | D18: 13(10) | E18: 428915.92 | G18: =120000 -> 120000 | I18: 0 | J18: =E18+F18+G18+H18+I18 -> 548915.92 | L18: =50000 -> 50000 | M18: 105000 | O18: 77470.374 | P18: 34313.273 | Q18: =O18+N18+M18+L18+K18+P18 -> 266783.65 | R18: 282132.27 | S18: =J18-Q18 -> 282132.27
A19: 13 | B19: HASSANA AHMED IBRAHIM | C19: PA- TO DG | D19: 13 (9) | E19: 416026.92 | G19: =120000 -> 120000 | I19: =100000+100000 -> 200000 | J19: =E19+F19+G19+H19+I19 -> 736026.92 | L19: =30000-20000 -> 10000 | M19: =95833.33 -> 95833.33 | N19: 5607.1771 | O19: ='Additional Leg Duty Allowance'!P14 -> 113474.9 | P19: 33282.153 | Q19: =O19+N19+M19+L19+K19+P19 -> 258197.56 | R19: 477829.35 | S19: =J19-Q19 -> 477829.35
A20: 14 | B20: IKIP LEBO | C20: ASST CHIEF PROC. OFFICER | D20: 13 (7) | E20: ='[3]Annual & Monthly'!$H$40 -> 390248.92 | H20: 70000 | J20: =E20+F20+G20+H20+I20 -> 460248.92 | L20: 50000 | O20: =61040.2353066666 -> 61040.235 | P20: =390248.916666667*0.08 -> 31219.913 | Q20: =O20+N20+M20+L20+K20+P20 -> 142260.15 | R20: 317988.77 | S20: =J20-Q20 -> 317988.77
A21: 15 | B21: ALABI ADESINA MUHYDEEN | C21: HEAD, NILDS LIAISON OFFICE | D21: 13 (7) | E21: 390248.92 | G21: 120000 | J21: =E21+F21+G21+H21+I21 -> 510248.92 | O21: =70640.2353066667 -> 70640.235 | P21: 31219.913 | Q21: =O21+N21+M21+L21+K21+P21 -> 101860.15 | R21: 408388.77 | S21: =J21-Q21 -> 408388.77
A22: 16 | B22: ADUGBA RICHARD TERSEER | C22: PRINCIPAL INFO. OFFICER | D22: 12(9) | E22: 377895.17 | H22: =60000 -> 60000 | I22: =100000+50000 -> 150000 | J22: =E22+F22+G22+H22+I22 -> 587895.17 | L22: =20000+30000 -> 50000 | M22: =111833.33 -> 111833.33 | O22: 82601.205 | P22: 30231.613 | Q22: =O22+N22+M22+L22+K22+P22 -> 274666.15 | R22: 313229.02 | S22: =J22-Q22 -> 313229.02
A23: 17 | B23: LUCKY AGWOM | C23: RESEARCH ASSISTANT | D23: 12(7) | E23: 353512.5 | G23: =100000 -> 100000 | I23: =100000+100000 -> 200000 | J23: =E23+F23+G23+H23+I23 -> 653512.5 | L23: =50000+100000 -> 150000 | O23: ='Additional Leg Duty Allowance'!P15 -> 98711.115 | P23: 28281 | Q23: =O23+N23+M23+L23+K23+P23 -> 276992.11 | R23: 376520.39 | S23: =J23-Q23 -> 376520.39
A24: 18 | B24: IDRIS IBRAHIM | C24: PRINCIPAL RESEARCH OFFICER | D24: 12(7) | E24: 353512.5 | G24: 110000 | I24: 0 | J24: =E24+F24+G24+H24+I24 -> 463512.5 | L24: 0 | O24: 62231.115 | P24: 28281 | Q24: =O24+N24+M24+L24+K24+P24 -> 90512.115 | R24: 373000.39 | S24: =J24-Q24 -> 373000.39
A25: 19 | B25: FARUQ ATOFARATI | C25: PA (SPECIAL DUTIES) TO DG | D25: 10(7) | E25: 293029.67 | H25: =50000+10000 -> 60000 | I25: =100000+100000 -> 200000 | J25: =E25+F25+G25+H25+I25 -> 553029.67 | L25: 130000 | O25: ='Additional Leg Duty Allowance'!P16 -> 80347.427 | P25: 23442.373 | Q25: =O25+N25+M25+L25+K25+P25 -> 233789.8 | R25: 319239.87 | S25: =J25-Q25 -> 319239.87
A26: 20 | B26: RASHEEDAT DAIBU | C26: SENIOR INFO. OFFICER | D26: 10(7) | E26: 293029.67 | H26: 60000 | J26: =E26+F26+G26+H26+I26 -> 353029.67 | L26: 40000 | O26: =42537.3319466667 -> 42537.332 | P26: 23442.373 | Q26: =O26+N26+M26+L26+K26+P26 -> 105979.71 | R26: 247049.96 | S26: =J26-Q26 -> 247049.96
A27: 21 | B27: ELIZABETH OGECHUKWU ONYEAKU | C27: ICT OFFICER | D27: 9(9) | E27: 270481.67 | H27: =50000+10000 -> 60000 | J27: =E27+F27+G27+H27+I27 -> 330481.67 | L27: 10000 | O27: 39052.313 | P27: 21638.533 | Q27: =O27+N27+M27+L27+K27+P27 -> 70690.846 | R27: 259790.82 | S27: =J27-Q27 -> 259790.82
A28: 22 | B28: VICTOR ASUKWO | C28: ICT OFFICER | D28: 9(9) | E28: 270481.67 | H28: =50000+10000 -> 60000 | J28: =E28+F28+G28+H28+I28 -> 330481.67 | O28: 39052.313 | P28: 21638.533 | Q28: =O28+N28+M28+L28+K28+P28 -> 60690.846 | R28: 269790.82 | S28: =J28-Q28 -> 269790.82
A29: 23 | B29: NNANDI LIVINUS ATURE | C29: RESEARCH ASSISTANT | D29: 9(9) | E29: 270481.67 | G29: =100000 -> 100000 | J29: =E29+F29+G29+H29+I29 -> 370481.67 | L29: =10000 -> 10000 | M29: =95833.33 -> 95833.33 | O29: 45772.313 | P29: 21638.533 | Q29: =O29+N29+M29+L29+K29+P29 -> 173244.18 | R29: 197237.49 | S29: =J29-Q29 -> 197237.49
A30: 24 | B30: ABDULRAHMAN A SULAIMAN | C30: STORE OFFICER | D30: 9(8) | E30: 263165.33 | H30: =60000 -> 60000 | J30: =E30+F30+G30+H30+I30 -> 323165.33 | L30: =20000 -> 20000 | M30: =17500 -> 17500 | O30: 37921.501 | P30: 21053.227 | Q30: =O30+N30+M30+L30+K30+P30 -> 96474.727 | R30: 226690.61 | S30: =J30-Q30 -> 226690.61
A31: 25 | B31: DARE SHEU MAGBON | C31: ADMINISTRATION OFFICER | D31: 9(7) | E31: 255849 | H31: =60000 -> 60000 | J31: =E31+F31+G31+H31+I31 -> 315849 | L31: =30000+20000 -> 50000 | M31: 0 | O31: 36790.688 | P31: 20467.92 | Q31: =O31+N31+M31+L31+K31+P31 -> 107258.61 | R31: 208590.39 | S31: =J31-Q31 -> 208590.39
A32: 26 | B32: ABUBAKAR SULAIMAN SODEEQ | C32: ADMINISTRATION OFFICER | D32: 9(7) | E32: 255849 | H32: =60000 -> 60000 | J32: =E32+F32+G32+H32+I32 -> 315849 | M32: 0 | O32: 36790.688 | P32: 20467.92 | Q32: =O32+N32+M32+L32+K32+P32 -> 57258.608 | R32: 258590.39 | S32: =J32-Q32 -> 258590.39
A33: 27 | B33: JIMOH ADEBAYO ZAKA | C33: ASST. OFFICER/COMM | D33: 9(9) | E33: 270481.67 | H33: =60000 -> 60000 | J33: =E33+F33+G33+H33+I33 -> 330481.67 | L33: =10000 -> 10000 | M33: 161429.76 | N33: =3653.5 -> 3653.5 | O33: 39052.313 | P33: 21638.533 | Q33: =O33+N33+M33+L33+K33+P33 -> 235774.11 | R33: 94707.56 | S33: =J33-Q33 -> 94707.56
A34: 28 | B34: ABDULMUSHIN TAWFIQ LADAN | C34: ICT OFFICER | D34: 9(7) | E34: 255849 | H34: =60000 -> 60000 | J34: =E34+F34+G34+H34+I34 -> 315849 | M34: 0 | O34: =36790.6881066667 -> 36790.688 | P34: 20467.92 | Q34: =O34+N34+M34+L34+K34+P34 -> 57258.608 | R34: 258590.39 | S34: =J34-Q34 -> 258590.39
A35: 29 | B35: MOHAMMED BELLO | C35: PROTOCOL ASSISTANT | D35: 9(7) | E35: 255849 | H35: =60000 -> 60000 | J35: =E35+F35+G35+H35+I35 -> 315849 | L35: =0 -> 0 | O35: 36790.688 | P35: 20467.92 | Q35: =O35+N35+M35+L35+K35+P35 -> 57258.608 | R35: 258590.39 | S35: =J35-Q35 -> 258590.39
A36: 30 | B36: HARUNA JIBRIL AMEH | C36: ASST. ADMIN. OFFICER | D36: 8(8) | E36: 224459.75 | H36: 50000 | J36: =E36+F36+G36+H36+I36 -> 274459.75 | L36: 20000 | M36: 0 | O36: 30259.166 | P36: 17956.78 | Q36: =O36+N36+M36+L36+K36+P36 -> 68215.946 | R36: 206243.8 | S36: =J36-Q36 -> 206243.8
A37: 31 | B37: RAMATU IBRAHIM ABDULRAHEEM | C37: INFORMATION OFFICER | D37: 8(7) | E37: 218287.58 | H37: 50000 | J37: =E37+F37+G37+H37+I37 -> 268287.58 | L37: 50000 | M37: 45833.33 | O37: =29305.1955466667 -> 29305.196 | P37: =218287.583333333*0.08 -> 17463.007 | Q37: =O37+N37+M37+L37+K37+P37 -> 142601.53 | R37: 125686.05 | S37: =J37-Q37 -> 125686.05
B38: TOTAL | C38: 31 | E38: =SUM(E7:E37) -> 14111049 | F38: =SUM(F7:F37) -> 0 | G38: =SUM(G7:G37) -> 1560000 | H38: =SUM(H7:H37) -> 1330000 | I38: =SUM(I7:I37) -> 2125235 | J38: =SUM(J7:J37) -> 19126284 | K38: =SUM(K7:K37) -> 0 | L38: =SUM(L7:L37) -> 1160000 | ... Q38: =SUM(Q7:Q37) -> 6223058.6 | R38: 13461860 | S38: =SUM(S7:S37) -> 12903226
B40: INTERNAL AUDIT
A41: 1 | B41: OSANAIYE DAVID AKINYEMI | C41: DIRECTOR INTERNAL AUDIT | D41: 17(9) | E41: 1435720 | H41: =100000 -> 100000 | J41: =SUM(E41:I41) -> 1535720 | K41: ='DECEMBER 2024'!F205 -> 0 | L41: =200000+200000 -> 400000 | M41: 0 | O41: 251472.25 | P41: 114857.6 | Q41: =O41+N41+M41+L41+K41+P41 -> 766329.85 | R41: 769390.15 | S41: =J41-Q41 -> 769390.15
...

Sheet MEMO
A2: NATIONAL INSTITUTE FOR LEGISLATIVE AND DEMOCRATIC STUDIES
A3: INTERNAL MEMO
A4: FROM : DEPUTY DIRECTOR, FINANCE AND ACCOUNTS
A5: THRU: DIRECTOR, FINANCE AND ACCOUNTS
A6: TO: DG
A7: 29TH JANUARY , 2021
A9: SUBJECT: PAYROLL FOR THE MONTH OF JANUARY, 2021
A10: Find below the details of NILDS Staff Payroll for the month of January, 2021
A13: TO: | C13: DIRECTOR, GENERAL
A14: THRU: | C14: DIRECTOR, FINANCE AND ACCOUNT
A15: FROM: | C15: DEPUTY DIRECTOR, FINANCE AND ACCOUNTS
A16: DATE: | C16: 26TH DECEMBER 2024
A18: SUBJECT: PAYROLL FOR THE MONTH OF DECEMBER 2024
A19: Find below the details of NILDS Staff Payroll for the Month of December, 2024: | G19: NGN | H19: NGN
A20: GROSS SALARY FOR DECEMBER, 2024 | H20: ='DECEMBER 2024'!J203 -> 81547106
A22: DEDUCTIONS
A23: COOP SOCIETY DEDUCTIONS ( CONTR.& SPEC. SAVINGS) | G23: ='DECEMBER 2024'!L203 -> 6703500
A24: COOP LOAN RECOVERY | G24: ='DECEMBER 2024'!M203 -> 7797849.2
A25: NHF DEDUCTIONS | G25: ='DECEMBER 2024'!N203 -> 237989.65
A26: PAYE DEDUCTIONS | G26: ='DECEMBER 2024'!O203 -> 11583471
A27: PENSION DEDUCTIONS | G27: ='DECEMBER 2024'!P203 -> 4865149.9
A28: TOTAL DEDUCTIONS FOR DECEMBER 2024 | H28: =G23+G24+G26+G25+G27 -> 31187960
A29: NET PAY AS PER DECEMBER 2024 PAYROLL | H29: =H20-H28 -> 50359146
A30: NET PAY AS PER NOVEMBER, 2024 PAYROLL | H30: ='DECEMBER 2024'!R203 -> 55578848
A31: NET INCREASE/ (DECREASE) IN PAY FOR DECEMBER, 2024 | H31: =H29-H30 -> -5219701.7
A32: ANALYSED AS FOLLOWS:
A33: Effect of Cooperative Adjustment for December, 2024 | H33: 282500
A34: Effect of Removal of Promotion Arrears for Abdulsalam Mustapha & 17 Others | H34: =6231679.78 -> 6231679.8
A35: Effect of reduction in PAYE due to removal of Arrears for Abdulsalam Mustapha & 17 Others | H35: -752754.99
A36: Effect of Head of Unit Allowance ifo Abdulsalam Mustapha | H36: -40399.99
A37: Effect of regularization of promotion of Taiwo Ismaeel Iyinlola & 1 other | H37: -501323.1
H38: =SUM(H33:H37) -> 5219701.7
E41: NOVEMBER, 2024 | G41: DECEMBER, 2024
E42: No. of Staff | F42: N | G42: No. of Staff | H42: N
A43: 1 | B43: Director General's Office | E43: 32 | F43: ='DECEMBER 2024'!R38 -> 13461860 | G43: ='DECEMBER 2024'!C38 -> 31 | H43: ='DECEMBER 2024'!S38 -> 12903226
A44: 2 | B44: Internal Audit | E44: 3 | F44: ='DECEMBER 2024'!R45 -> 1512321.6 | G44: ='DECEMBER 2024'!C45 -> 4 | H44: ='DECEMBER 2024'!S45 -> 1482321.6
A45: 3 | B45: Legis. Support Services | E45: 11 | F45: ='DECEMBER 2024'!R57 -> 4501924.2 | G45: ='DECEMBER 2024'!C57 -> 9 | H45: ='DECEMBER 2024'!S57 -> 4152743.7
A46: 4 | B46: Legal Services | E46: 2 | F46: ='DECEMBER 2024'!R62 -> 1482548.9 | G46: ='DECEMBER 2024'!C62 -> 2 | H46: ='DECEMBER 2024'!S62 -> 1482548.9
A47: 5 | B47: Democracy and Governance | E47: 12 | F47: ='DECEMBER 2024'!R73 -> 2448685.1 | G47: ='DECEMBER 2024'!C73 -> 8 | H47: ='DECEMBER 2024'!S73 -> 2448685.1
A48: 6 | B48: Studies | E48: 6 | F48: ='DECEMBER 2024'!R82 -> 2738248.1 | G48: ='DECEMBER 2024'!C82 -> 6 | H48: ='DECEMBER 2024'!S82 -> 3095189.7
...

Sheet 2024 Promotion Arrears
A1: NATIONAL INSTITUTE FOR LEGISLATIVE & DEMOCRATIC STUDIES
A2: 2024 ANALYSIS OF STAFF PROMOTION ARREARS
A4: SN | B4: Name of Employee | C4: Department | D4: Present Grade Level | E4: New Grade Level | F4: Consolidated Salary of Present Position | G4: Consolidated Salary of New Position | H4: Diference/Arrears | I4: No of Months | J4: Total Amount of Arrears (Gross)
F5: N | G5: N | H5: N | J5: N
A6: 1 | B6: ABDULSALAM MUSTAPHA | C6: DG's Office | D6: 13/11 | E6: 15/7 | F6: =511804.92 -> 511804.92 | G6: =582118+80000 -> 662118 | H6: =G6-F6 -> 150313.08 | I6: 1 | J6: =H6*I6 -> 150313.08
A7: 2 | B7: EMILY EDIOSA IKHIDE | C7: DG's Office | D7: 014/10 | E7: 015/7 | F7: 610498 | G7: =582118+160000 -> 742118 | H7: =G7-F7 -> 131620 | I7: 4 | J7: =H7*I7 -> 526480
A8: 3 | B8: SIMON WAKAWA | C8: DG's Office | D8: 014/11 | E8: 015/7 | F8: 554373.75 | G8: =582118+80000 -> 662118 | H8: =G8-F8 -> 107744.25 | I8: =2.71 -> 2.71 | J8: =H8*I8 -> 291986.92
A9: 4 | B9: WAZIRI USMAN | C9: Admin. & HR | D9: 014/11 | E9: 015/7 | F9: 554374.75 | G9: =582118+80000 -> 662118 | H9: =G9-F9 -> 107743.25 | I9: =2.71 -> 2.71 | J9: =H9*I9 -> 291984.21
A10: 5 | B10: TAIWO I. OYINLOLA | C10: Admin. & HR | D10: 05/9 | E10: 07/3 | F10: 121145.75 | G10: 189814.17 | H10: =G10-F10 -> 68668.417 | I10: 0 | J10: =H10*I10 -> 0 | K10: Effective in Dec
A11: 6 | B11: SARATU ATAJIRI | C11: Admin. & HR | D11: N/A | E11: 09/7 | F11: 120000 | G11: =255849+60000 -> 315849 | H11: =G11-F11 -> 195849 | I11: 8 | J11: =H11*I11 -> 1566792
A12: 7 | B12: YUSIF SANI SADIQ | C12: Admin. & HR | D12: 10/9 | E12: 12/7 | F12: 368901.5 | G12: 413512.5 | H12: =G12-F12 -> 44611 | I12: 2.71 | J12: =H12*I12 -> 120895.81
A13: 8 | B13: STELLA NGOZI PAUL | C13: Admin. & HR | D13: 10/10 | E13: 12/7 | F13: 376837.42 | G13: 413512.5 | H13: =G13-F13 -> 36675.083 | I13: 2.71 | J13: =H13*I13 -> 99389.476
A14: 9 | B14: OMONIGHO EROMOSELE-WESEY | C14: Admin. & HR | D14: 12/10 | E14: 13/7 | F14: 450086.5 | G14: 510248.92 | H14: =G14-F14 -> 60162.417 | I14: 8 | J14: =H14*I14 -> 481299.33
A15: 10 | B15: QUEEN ONYEKESON | C15: Admin. & HR | D15: 12/10 | E15: 13/7 | F15: 450086.5 | G15: 510248.92 | H15: =G15-F15 -> 60162.417 | I15: 2.71 | J15: =H15*I15 -> 163040.15
A16: 11 | B16: SHAMSUDEEN YAHAYA | C16: LSS | D16: 014/10 | E16: 015/7 | F16: 610498 | G16: 742118 | H16: =G16-F16 -> 131620 | I16: 3 | J16: =H16*I16 -> 394860
A17: 12 | B17: SALAMATU YAKUBU | C17: LSS | D17: 014/11 | E17: 015/7 | F17: 554373.75 | G17: 662118 | H17: =G17-F17 -> 107744.25 | I17: 3 | J17: =H17*I17 -> 323232.75
A18: 13 | B18: ROTIMI OGUNYOMI | C18: LSS | D18: 12/10 | E18: 13/7 | F18: 450086.5 | G18: 510248.92 | H18: =G18-F18 -> 60162.417 | I18: 3 | J18: =H18*I18 -> 180487.25
A19: 14 | B19: LEO IGBANOI | C19: Dem. & Gov. | D19: 13/10 | E19: 14/8 | F19: 548915.92 | G19: 582746.5 | H19: =G19-F19 -> 33830.583 | I19: 20 | J19: =H19*I19 -> 676611.67
A20: 15 | B20: TOSIN OWOEYE | C20: Dem. & Gov. | D20: 10/9 | E20: 12/7 | F20: 368901.5 | G20: 413512.5 | H20: =G20-F20 -> 44611 | I20: 9 | J20: =H20*I20 -> 401499
A21: 16 | B21: STACY CHINYERE IGWE | C21: DOS | D21: 10/9 | E21: 12/7 | F21: 408901.5 | G21: =353512.5+110000 -> 463512.5 | H21: =G21-F21 -> 54611 | I21: 12 | J21: =H21*I21 -> 655332
A22: 17 | B22: TANIMU M. LAWAL | C22: Econ/ & Social Res. | D22: 04/10 | E22: 07/3 | F22: 102926.92 | G22: 189814.17 | H22: =G22-F22 -> 86887.25 | I22: 1 | J22: =H22*I22 -> 86887.25
A23: 18 | B23: CHRISTIAN MADUABUCHI ODO | C23: Finance & Accts | D23: 12/10 | E23: 13/7 | F23: 450086.5 | G23: 510248.92 | H23: =G23-F23 -> 60162.417 | I23: 3 | J23: =H23*I23 -> 180487.25
B24: TOTAL | J24: =SUM(J6:J23) -> 6591578.1

Sheet Promotion in Sept
A1: NATIONAL INSTITUTE FOR LEGISLATIVE AND DEMOCRATIC STUDIES | G1: ='[1]FEB 08'!F8/'[1]FEB 08'!Q8 -> 0.3
A2: STAFF PAYROLL FOR THE MONTH OF NOVEMBER 2024
E3: ='[1]FEB 08'!E11/'[1]FEB 08'!M11 -> #REF! | G3: ='[1]FEB 08'!F11/'[1]FEB 08'!Q11 -> #REF!
B4: STAFF NAME | C4: DESIGNATION | D4: GRADE LEVEL | E4: BASIC SALARY | F4: ALLCE/ AREARS | G4: ALLOWANCE | H4: ALLOWANCE | I4: DUTY ALLCE | J4: CURRENT GROSS SALARY | K4: NEW GRADE LEVEL | L4: NEW GROSS SALARY | M4: INCREMENT IN GROSS SALARY | N4: CURRENT NHF | O4: NEW NHF | P4: CURRENT PAYE | Q4: NEW PAYE | S4: INCREMENT IN PAYE | T4: NET SALARY INCREMENT | U4: NO OF MONTHS | V4: ARREARS
E5: N | F5: N | G5: N | H5: N | I5: N | J5: N | L5: N | N5: N | P5: N
A7: 1 | B7: IBE EZECHI CYRIACUS | C7: RESEARCH FELLOW II | D7: 13(11) | E7: 441804.92 | G7: =120000 -> 120000 | I7: 0 | J7: =SUM(E7:I7) -> 561804.92 | K7: 14(7) | L7: =442746.5+140000 -> 582746.5 | M7: =L7-J7 -> 20941.583 | P7: 79747.087 | Q7: =83767.87 -> 83767.87 | S7: =Q7-P7 -> 4020.7829 | T7: =M7-S7 -> 16920.8 | U7: 4.55 | V7: =T7*U7 -> 76989.642
B8: TOTAL | E8: =SUM(E7:E7) -> 441804.92 | F8: =SUM(F7:F7) -> 0 | G8: =SUM(G7:G7) -> 120000 | H8: =SUM(H7:H7) -> 0 | I8: =SUM(I7:I7) -> 0 | J8: =SUM(J7:J7) -> 561804.92 | L8: =SUM(L7:L7) -> 582746.5 | M8: =SUM(M7:M7) -> 20941.583 | N8: =SUM(N7:N7) -> 0 | O8: =SUM(O7:O7) -> 0 | P8: =SUM(P7:P7) -> 79747.087 | Q8: =SUM(Q7:Q7) -> 83767.87 | S8: =SUM(S7:S7) -> 4020.7829 | T8: =SUM(T7:T7) -> 16920.8 | V8: =SUM(V7:V7) -> 76989.642

Sheet  New Grade PAYE 
A1: NATIONAL INSTITUTE FOR LEGISLATIVE AND DEMOCRATIC STUDIES
A2: NATIONAL ASSEMBLY ABUJA
A3: TAX COMPUTATION FOR 2022
A4: S/NO | B4: NAME | C4: MONTHLY TOTAL SALARY | D4: NO OF MONTHS | E4: ANNUAL SALARY GROSSED UP | F4: NATIONAL HOUSING SCHEME = 2.5% OF BASIC SALARY | G4: PENSION CONTRIBUTION = 8% OF CONSOLIDATED | H4: NHIS | I4: NET SALARY (EXC OF CRA) | M4: CRA=#200,000+(20% 0F NET SALARY (EXC OF CRA) | N4: TOTAL RELIEF | O4: CHARGEABLE INCOME | P4: FIRST N300,000 @ 7% | Q4: NEXT N300,000 @ 11% | R4: NEXT N500,000 @ 15% | S4: NEXT N500,000@ 19% | T4: NEXT N1,600,000 @ 21% | U4: ABOVE N3,200,000 @ 24% | V4: ANNUAL TAX PAYABLE | X4: MONTHLY TAX PAYABLE | Y4: MINIMUM TAX PAYABLE | Z4: NEW ACTUAL TAX PAYABLE | AA4: TAX PAYABLE ON ARREARS | AB4: TOTAL TAX PAYABLE IN NOVEMBER
A5: 1 | B5: ABDULSALAM MUSTAPHA | C5: 712118.08 | D5: 12 | E5: =C5*D5 -> 8545417 | G5: 558833.36 | I5: =E5-F5-G5-H5 -> 7986583.6 | J5: 200000 | K5: 0.2 | L5: =I5*K5 -> 1597316.7 | M5: =J5+L5 -> 1797316.7 | N5: =F5+G5+H5+M5 -> 2356150.1 | O5: =E5-N5 -> 6189266.9 | P5: =IF(O5<300000,0.07*O5,21000) -> 21000 | Q5: =IF((O5-300000)<0,0,IF((O5-300000)<300000,0.11*(O5-300000),33000)) -> 33000 | R5: =IF((O5-600000)<0,0,IF((O5-600000)<500000,0.15*(O5-600000),75000)) -> 75000 | S5: =IF((O5-1100000)<0,0,IF((O5-1100000)<500000,0.19*(O5-1100000),95000)) -> 95000 | T5: =IF((O5-1600000)<0,0,IF((O5-1600000)<1600000,0.21*(O5-1600000),336000)) -> 336000 | U5: =24%*(O5-3200000) -> 717424.06 | V5: =P5+Q5+R5+S5+T5+U5 -> 1277424.1 | W5: 12 | X5: =V5/W5 -> 106452 | Z5: =X5 -> 106452 | AA5: 6949.236 | AB5: =Z5+AA5 -> 113401.24 | AC5: ABDULSALAM MUSTAPHA
A6: 2 | B6: EMILY EDIOSA IKHIDE | C6: =582118+160000+150000 -> 892118 | D6: 12 | E6: =C6*D6 -> 10705416 | G6: 558833.36 | I6: =E6-F6-G6-H6 -> 10146583 | J6: 200000 | K6: 0.2 | L6: =I6*K6 -> 2029316.5 | M6: =J6+L6 -> 2229316.5 | N6: =F6+G6+H6+M6 -> 2788149.9 | O6: =E6-N6 -> 7917266.1 | P6: =IF(O6<300000,0.07*O6,21000) -> 21000 | Q6: =IF((O6-300000)<0,0,IF((O6-300000)<300000,0.11*(O6-300000),33000)) -> 33000 | R6: =IF((O6-600000)<0,0,IF((O6-600000)<500000,0.15*(O6-600000),75000)) -> 75000 | S6: =IF((O6-1100000)<0,0,IF((O6-1100000)<500000,0.19*(O6-1100000),95000)) -> 95000 | T6: =IF((O6-1600000)<0,0,IF((O6-1600000)<1600000,0.21*(O6-1600000),336000)) -> 336000 | U6: =24%*(O6-3200000) -> 1132143.9 | V6: =P6+Q6+R6+S6+T6+U6 -> 1692143.9 | W6: 12 | X6: =V6/W6 -> 141011.99 | Z6: =X6 -> 141011.99 | AA6: 70809.493 | AB6: =Z6+AA6 -> 211821.48 | AC6: EMILY EDIOSA IKHIDE
A7: 3 | B7: SIMON WAKAWA | C7: =582118+80000 -> 662118 | D7: 12 | E7: =C7*D7 -> 7945416 | F7: =8019.8*12 -> 96237.6 | G7: 558833.36 | I7: =E7-F7-G7-H7 -> 7290345 | J7: 200000 | K7: 0.2 | L7: =I7*K7 -> 1458069 | M7: =J7+L7 -> 1658069 | N7: =F7+G7+H7+M7 -> 2313140 | O7: =E7-N7 -> 5632276 | P7: =IF(O7<300000,0.07*O7,21000) -> 21000 | Q7: =IF((O7-300000)<0,0,IF((O7-300000)<300000,0.11*(O7-300000),33000)) -> 33000 | R7: =IF((O7-600000)<0,0,IF((O7-600000)<500000,0.15*(O7-600000),75000)) -> 75000 | S7: =IF((O7-1100000)<0,0,IF((O7-1100000)<500000,0.19*(O7-1100000),95000)) -> 95000 | T7: =IF((O7-1600000)<0,0,IF((O7-1600000)<1600000,0.21*(O7-1600000),336000)) -> 336000 | U7: =24%*(O7-3200000) -> 583746.25 | V7: =P7+Q7+R7+S7+T7+U7 -> 1143746.2 | W7: 12 | X7: =V7/W7 -> 95312.187 | Z7: =X7 -> 95312.187 | AA7: 27049.475 | AB7: =Z7+AA7 -> 122361.66 | AC7: SIMON WAKAWA
A8: 4 | B8: WAZIRI USMAN | C8: =582118+80000 -> 662118 | D8: 12 | E8: =C8*D8 -> 7945416 | F8: =8019.8*12 -> 96237.6 | G8: 558833.36 | I8: =E8-F8-G8-H8 -> 7290345 | J8: 200000 | K8: 0.2 | L8: =I8*K8 -> 1458069 | M8: =J8+L8 -> 1658069 | N8: =F8+G8+H8+M8 -> 2313140 | O8: =E8-N8 -> 5632276 | P8: =IF(O8<300000,0.07*O8,21000) -> 21000 | Q8: =IF((O8-300000)<0,0,IF((O8-300000)<300000,0.11*(O8-300000),33000)) -> 33000 | R8: =IF((O8-600000)<0,0,IF((O8-600000)<500000,0.15*(O8-600000),75000)) -> 75000 | S8: =IF((O8-1100000)<0,0,IF((O8-1100000)<500000,0.19*(O8-1100000),95000)) -> 95000 | T8: =IF((O8-1600000)<0,0,IF((O8-1600000)<1600000,0.21*(O8-1600000),336000)) -> 336000 | U8: =24%*(O8-3200000) -> 583746.25 | V8: =P8+Q8+R8+S8+T8+U8 -> 1143746.2 | W8: 12 | X8: =V8/W8 -> 95312.187 | Z8: =X8 -> 95312.187 | AA8: 27049.02 | AB8: =Z8+AA8 -> 122361.21 | AC8: WAZIRI USMAN
A9: 5 | B9: TAIWO I. OYINLOLA | C9: 189814.17 | D9: 12 | E9: =C9*D9 -> 2277770 | G9: 146701.6 | I9: =E9-F9-G9-H9 -> 2131068.4 | J9: 200000 | K9: 0.2 | L9: =I9*K9 -> 426213.68 | M9: =J9+L9 -> 626213.68 | N9: =F9+G9+H9+M9 -> 772915.28 | O9: =E9-N9 -> 1504854.7 | P9: =IF(O9<300000,0.07*O9,21000) -> 21000 | Q9: =IF((O9-300000)<0,0,IF((O9-300000)<300000,0.11*(O9-300000),33000)) -> 33000 | R9: =IF((O9-600000)<0,0,IF((O9-600000)<500000,0.15*(O9-600000),75000)) -> 75000 | S9: =IF((O9-1100000)<0,0,IF((O9-1100000)<500000,0.19*(O9-1100000),95000)) -> 76922.396 | T9: =IF((O9-1600000)<0,0,IF((O9-1600000)<1600000,0.21*(O9-1600000),336000)) -> 0 | V9: =P9+Q9+R9+S9+T9+U9 -> 205922.4 | W9: 12 | X9: =V9/W9 -> 17160.2 | Z9: =X9 -> 17160.2 | AA9: 0 | AB9: =Z9+AA9 -> 17160.2 | AC9: TAIWO I. OYINLOLA
A10: 6 | B10: SARATU ATAJIRI | C10: =255849+50000 -> 305849 | D10: 12 | E10: =C10*D10 -> 3670188 | G10: 245615.04 | I10: =E10-F10-G10-H10 -> 3424573 | J10: 200000 | K10: 0.2 | L10: =I10*K10 -> 684914.59 | M10: =J10+L10 -> 884914.59 | N10: =F10+G10+H10+M10 -> 1130529.6 | O10: =E10-N10 -> 2539658.4 | P10: =IF(O10<300000,0.07*O10,21000) -> 21000 | Q10: =IF((O10-300000)<0,0,IF((O10-300000)<300000,0.11*(O10-300000),33000)) -> 33000 | R10: =IF((O10-600000)<0,0,IF((O10-600000)<500000,0.15*(O10-600000),75000)) -> 75000 | S10: =IF((O10-1100000)<0,0,IF((O10-1100000)<500000,0.19*(O10-1100000),95000)) -> 95000 | T10: =IF((O10-1600000)<0,0,IF((O10-1600000)<1600000,0.21*(O10-1600000),336000)) -> 197328.26 | V10: =P10+Q10+R10+S10+T10+U10 -> 421328.26 | W10: 12 | X10: =V10/W10 -> 35110.688 | Z10: =X10 -> 35110.688 | AA10: 260200.89 | AB10: =Z10+AA10 -> 295311.58 | AC10: SARATU ATAJIRI
A11: 7 | B11: YUSIF SANI SADIQ | C11: 413512.5 | D11: 12 | E11: =C11*D11 -> 4962150 | G11: 339372 | I11: =E11-F11-G11-H11 -> 4622778 | J11: 200000 | K11: 0.2 | L11: =I11*K11 -> 924555.6 | M11: =J11+L11 -> 1124555.6 | N11: =F11+G11+H11+M11 -> 1463927.6 | O11: =E11-N11 -> 3498222.4 | P11: =IF(O11<300000,0.07*O11,21000) -> 21000 | Q11: =IF((O11-300000)<0,0,IF((O11-300000)<300000,0.11*(O11-300000),33000)) -> 33000 | R11: =IF((O11-600000)<0,0,IF((O11-600000)<500000,0.15*(O11-600000),75000)) -> 75000 | S11: =IF((O11-1100000)<0,0,IF((O11-1100000)<500000,0.19*(O11-1100000),95000)) -> 95000 | T11: =IF((O11-1600000)<0,0,IF((O11-1600000)<1600000,0.21*(O11-1600000),336000)) -> 336000 | U11: =24%*(O11-3200000) -> 71573.376 | V11: =P11+Q11+R11+S11+T11+U11 -> 631573.38 | W11: 12 | X11: =V11/W11 -> 52631.115 | Z11: =X11 -> 52631.115 | AA11: 5613.7772 | AB11: =Z11+AA11 -> 58244.892 | AC11: YUSIF SANI SADIQ
A12: 8 | B12: STELLA NGOZI PAUL | C12: 413512.5 | D12: 12 | E12: =C12*D12 -> 4962150 | G12: 339372 | I12: =E12-F12-G12-H12 -> 4622778 | J12: 200000 | K12: 0.2 | L12: =I12*K12 -> 924555.6 | M12: =J12+L12 -> 1124555.6 | N12: =F12+G12+H12+M12 -> 1463927.6 | O12: =E12-N12 -> 3498222.4 | P12: =IF(O12<300000,0.07*O12,21000) -> 21000 | Q12: =IF((O12-300000)<0,0,IF((O12-300000)<300000,0.11*(O12-300000),33000)) -> 33000 | R12: =IF((O12-600000)<0,0,IF((O12-600000)<500000,0.15*(O12-600000),75000)) -> 75000 | S12: =IF((O12-1100000)<0,0,IF((O12-1100000)<500000,0.19*(O12-1100000),95000)) -> 95000 | T12: =IF((O12-1600000)<0,0,IF((O12-1600000)<1600000,0.21*(O12-1600000),336000)) -> 336000 | U12: =24%*(O12-3200000) -> 71573.376 | V12: =P12+Q12+R12+S12+T12+U12 -> 631573.38 | W12: 12 | X12: =V12/W12 -> 52631.115 | Z12: =X12 -> 52631.115 | AA12: 3424.2125 | AB12: =Z12+AA12 -> 56055.327 | AC12: STELLA NGOZI PAUL
A13: 9 | B13: OMONIGHO EROMOSELE-WESEY | C13: 510248.92 | D13: 12 | E13: =C13*D13 -> 6122987 | F13: =6922.5*12 -> 83070 | G13: 374638.96 | I13: =E13-F13-G13-H13 -> 5665278 | J13: 200000 | K13: 0.2 | L13: =I13*K13 -> 1133055.6 | M13: =J13+L13 -> 1333055.6 | N13: =F13+G13+H13+M13 -> 1790764.6 | O13: =E13-N13 -> 4332222.4 | P13: =IF(O13<300000,0.07*O13,21000) -> 21000 | Q13: =IF((O13-300000)<0,0,IF((O13-300000)<300000,0.11*(O13-300000),33000)) -> 33000 | R13: =IF((O13-600000)<0,0,IF((O13-600000)<500000,0.15*(O13-600000),75000)) -> 75000 | S13: =IF((O13-1100000)<0,0,IF((O13-1100000)<500000,0.19*(O13-1100000),95000)) -> 95000 | T13: =IF((O13-1600000)<0,0,IF((O13-1600000)<1600000,0.21*(O13-1600000),336000)) -> 336000 | U13: =24%*(O13-3200000) -> 271733.38 | V13: =P13+Q13+R13+S13+T13+U13 -> 831733.38 | W13: 12 | X13: =V13/W13 -> 69311.115 | Z13: =X13 -> 69311.115 | AA13: 63752.795 | AB13: =Z13+AA13 -> 133063.91 | AC13: OMONIGHO EROMOSELE-WESEY
A14: 10 | B14: QUEEN ONYEKESON | C14: 510248.92 | D14: 12 | E14: =C14*D14 -> 6122987 | G14: 374638.96 | I14: =E14-F14-G14-H14 -> 5748348 | J14: 200000 | K14: 0.2 | L14: =I14*K14 -> 1149669.6 | M14: =J14+L14 -> 1349669.6 | N14: =F14+G14+H14+M14 -> 1724308.6 | O14: =E14-N14 -> 4398678.4 | P14: =IF(O14<300000,0.07*O14,21000) -> 21000 | Q14: =IF((O14-300000)<0,0,IF((O14-300000)<300000,0.11*(O14-300000),33000)) -> 33000 | R14: =IF((O14-600000)<0,0,IF((O14-600000)<500000,0.15*(O14-600000),75000)) -> 75000 | S14: =IF((O14-1100000)<0,0,IF((O14-1100000)<500000,0.19*(O14-1100000),95000)) -> 95000 | T14: =IF((O14-1600000)<0,0,IF((O14-1600000)<1600000,0.21*(O14-1600000),336000)) -> 336000 | U14: =24%*(O14-3200000) -> 287682.82 | V14: =P14+Q14+R14+S14+T14+U14 -> 847682.82 | W14: 12 | X14: =V14/W14 -> 70640.235 | Z14: =X14 -> 70640.235 | AA14: 10318.428 | AB14: =Z14+AA14 -> 80958.664 | AC14: QUEEN ONYEKESON
A15: 11 | B15: SHAMSUDEEN YAHAYA | C15: 742118 | D15: 12 | E15: =C15*D15 -> 8905416 | G15: 558833.36 | I15: =E15-F15-G15-H15 -> 8346582.6 | J15: 200000 | K15: 0.2 | L15: =I15*K15 -> 1669316.5 | M15: =J15+L15 -> 1869316.5 | N15: =F15+G15+H15+M15 -> 2428149.9 | O15: =E15-N15 -> 6477266.1 | P15: =IF(O15<300000,0.07*O15,21000) -> 21000 | Q15: =IF((O15-300000)<0,0,IF((O15-300000)<300000,0.11*(O15-300000),33000)) -> 33000 | R15: =IF((O15-600000)<0,0,IF((O15-600000)<500000,0.15*(O15-600000),75000)) -> 75000 | S15: =IF((O15-1100000)<0,0,IF((O15-1100000)<500000,0.19*(O15-1100000),95000)) -> 95000 | T15: =IF((O15-1600000)<0,0,IF((O15-1600000)<1600000,0.21*(O15-1600000),336000)) -> 336000 | U15: =24%*(O15-3200000) -> 786543.87 | V15: =P15+Q15+R15+S15+T15+U15 -> 1346543.9 | W15: 12 | X15: =V15/W15 -> 112211.99 | Z15: =X15 -> 112211.99 | AA15: 45679.48 | AB15: =Z15+AA15 -> 157891.47 | AC15: SHAMSUDEEN YAHAYA
A16: 12 | B16: SALAMATU YAKUBU | C16: 662118 | D16: 12 | E16: =C16*D16 -> 7945416 | F16: =8019.8*12 -> 96237.6 | G16: 558833.36 | I16: =E16-F16-G16-H16 -> 7290345 | J16: 200000 | K16: 0.2 | L16: =I16*K16 -> 1458069 | M16: =J16+L16 -> 1658069 | N16: =F16+G16+H16+M16 -> 2313140 | O16: =E16-N16 -> 5632276 | P16: =IF(O16<300000,0.07*O16,21000) -> 21000 | Q16: =IF((O16-300000)<0,0,IF((O16-300000)<300000,0.11*(O16-300000),33000)) -> 33000 | R16: =IF((O16-600000)<0,0,IF((O16-600000)<500000,0.15*(O16-600000),75000)) -> 75000 | S16: =IF((O16-1100000)<0,0,IF((O16-1100000)<500000,0.19*(O16-1100000),95000)) -> 95000 | T16: =IF((O16-1600000)<0,0,IF((O16-1600000)<1600000,0.21*(O16-1600000),336000)) -> 336000 | U16: =24%*(O16-3200000) -> 583746.25 | V16: =P16+Q16+R16+S16+T16+U16 -> 1143746.2 | W16: 12 | X16: =V16/W16 -> 95312.187 | Z16: =X16 -> 95312.187 | AA16: 32298.775 | AB16: =Z16+AA16 -> 127610.96 | AC16: SALAMATU YAKUBU
A17: 13 | B17: ROTIMI OGUNYOMI | C17: 510248.92 | D17: 12 | E17: =C17*D17 -> 6122987 | G17: 374638.96 | I17: =E17-F17-G17-H17 -> 5748348 | J17: 200000 | K17: 0.2 | L17: =I17*K17 -> 1149669.6 | M17: =J17+L17 -> 1349669.6 | N17: =F17+G17+H17+M17 -> 1724308.6 | O17: =E17-N17 -> 4398678.4 | P17: =IF(O17<300000,0.07*O17,21000) -> 21000 | Q17: =IF((O17-300000)<0,0,IF((O17-300000)<300000,0.11*(O17-300000),33000)) -> 33000 | R17: =IF((O17-600000)<0,0,IF((O17-600000)<500000,0.15*(O17-600000),75000)) -> 75000 | S17: =IF((O17-1100000)<0,0,IF((O17-1100000)<500000,0.19*(O17-1100000),95000)) -> 95000 | T17: =IF((O17-1600000)<0,0,IF((O17-1600000)<1600000,0.21*(O17-1600000),336000)) -> 336000 | U17: =24%*(O17-3200000) -> 287682.82 | V17: =P17+Q17+R17+S17+T17+U17 -> 847682.82 | W17: 12 | X17: =V17/W17 -> 70640.235 | Z17: =X17 -> 70640.235 | AA17: 12855.302 | AB17: =Z17+AA17 -> 83495.537 | AC17: ROTIMI OGUNYOMI
A18: 14 | B18: LEO IGBANOI | C18: 582746.5 | D18: 12 | E18: =C18*D18 -> 6992958 | G18: 425036.64 | I18: =E18-F18-G18-H18 -> 6567921.4 | J18: 200000 | K18: 0.2 | L18: =I18*K18 -> 1313584.3 | M18: =J18+L18 -> 1513584.3 | N18: =F18+G18+H18+M18 -> 1938620.9 | O18: =E18-N18 -> 5054337.1 | P18: =IF(O18<300000,0.07*O18,21000) -> 21000 | Q18: =IF((O18-300000)<0,0,IF((O18-300000)<300000,0.11*(O18-300000),33000)) -> 33000 | R18: =IF((O18-600000)<0,0,IF((O18-600000)<500000,0.15*(O18-600000),75000)) -> 75000 | S18: =IF((O18-1100000)<0,0,IF((O18-1100000)<500000,0.19*(O18-1100000),95000)) -> 95000 | T18: =IF((O18-1600000)<0,0,IF((O18-1600000)<1600000,0.21*(O18-1600000),336000)) -> 336000 | U18: =24%*(O18-3200000) -> 445040.9 | V18: =P18+Q18+R18+S18+T18+U18 -> 1005040.9 | W18: 12 | X18: =V18/W18 -> 83753.408 | Z18: =X18 -> 83753.408 | AA18: 101775.52 | AB18: =Z18+AA18 -> 185528.93 | AC18: LEO IGBANOI
A19: 15 | B19: TOSIN OWOEYE | C19: 413512.5 | D19: 12 | E19: =C19*D19 -> 4962150 | G19: 339372 | I19: =E19-F19-G19-H19 -> 4622778 | J19: 200000 | K19: 0.2 | L19: =I19*K19 -> 924555.6 | M19: =J19+L19 -> 1124555.6 | N19: =F19+G19+H19+M19 -> 1463927.6 | O19: =E19-N19 -> 3498222.4 | P19: =IF(O19<300000,0.07*O19,21000) -> 21000 | Q19: =IF((O19-300000)<0,0,IF((O19-300000)<300000,0.11*(O19-300000),33000)) -> 33000 | R19: =IF((O19-600000)<0,0,IF((O19-600000)<500000,0.15*(O19-600000),75000)) -> 75000 | S19: =IF((O19-1100000)<0,0,IF((O19-1100000)<500000,0.19*(O19-1100000),95000)) -> 95000 | T19: =IF((O19-1600000)<0,0,IF((O19-1600000)<1600000,0.21*(O19-1600000),336000)) -> 336000 | U19: =24%*(O19-3200000) -> 71573.376 | V19: =P19+Q19+R19+S19+T19+U19 -> 631573.38 | W19: 12 | X19: =V19/W19 -> 52631.115 | Z19: =X19 -> 52631.115 | AA19: 50324.523 | AB19: =Z19+AA19 -> 102955.64 | AC19: TOSIN OWOEYE
A20: 16 | B20: STACY CHINYERE IGWE | C20: =353512.5+110000 -> 463512.5 | D20: 12 | E20: =C20*D20 -> 5562150 | G20: 339372 | I20: =E20-F20-G20-H20 -> 5222778 | J20: 200000 | K20: 0.2 | L20: =I20*K20 -> 1044555.6 | M20: =J20+L20 -> 1244555.6 | N20: =F20+G20+H20+M20 -> 1583927.6 | O20: =E20-N20 -> 3978222.4 | P20: =IF(O20<300000,0.07*O20,21000) -> 21000 | Q20: =IF((O20-300000)<0,0,IF((O20-300000)<300000,0.11*(O20-300000),33000)) -> 33000 | R20: =IF((O20-600000)<0,0,IF((O20-600000)<500000,0.15*(O20-600000),75000)) -> 75000 | S20: =IF((O20-1100000)<0,0,IF((O20-1100000)<500000,0.19*(O20-1100000),95000)) -> 95000 | T20: =IF((O20-1600000)<0,0,IF((O20-1600000)<1600000,0.21*(O20-1600000),336000)) -> 336000 | U20: =24%*(O20-3200000) -> 186773.38 | V20: =P20+Q20+R20+S20+T20+U20 -> 746773.38 | W20: 12 | X20: =V20/W20 -> 62231.115 | Z20: =X20 -> 62231.115 | AA20: 19114.051 | AB20: =Z20+AA20 -> 81345.165 | AC20: STACY CHINYERE IGWE
A21: 17 | B21: TANIMU M. LAWAL | C21: 189814.17 | D21: 12 | E21: =C21*D21 -> 2277770 | G21: 146701.6 | I21: =E21-F21-G21-H21 -> 2131068.4 | J21: 200000 | K21: 0.2 | L21: =I21*K21 -> 426213.68 | M21: =J21+L21 -> 626213.68 | N21: =F21+G21+H21+M21 -> 772915.28 | O21: =E21-N21 -> 1504854.7 | P21: =IF(O21<300000,0.07*O21,21000) -> 21000 | Q21: =IF((O21-300000)<0,0,IF((O21-300000)<300000,0.11*(O21-300000),33000)) -> 33000 | R21: =IF((O21-600000)<0,0,IF((O21-600000)<500000,0.15*(O21-600000),75000)) -> 75000 | S21: =IF((O21-1100000)<0,0,IF((O21-1100000)<500000,0.19*(O21-1100000),95000)) -> 76922.396 | T21: =IF((O21-1600000)<0,0,IF((O21-1600000)<1600000,0.21*(O21-1600000),336000)) -> 0 | V21: =P21+Q21+R21+S21+T21+U21 -> 205922.4 | W21: 12 | X21: =V21/W21 -> 17160.2 | Z21: =X21 -> 17160.2 | AA21: 3736.9329 | AB21: =Z21+AA21 -> 20897.133 | AC21: TANIMU M. LAWAL
A22: 18 | B22: CHRISTIAN MADUABUCHI ODO | C22: 510248.92 | D22: 12 | E22: =C22*D22 -> 6122987 | F22: =6922.5*12 -> 83070 | G22: 374638.96 | I22: =E22-F22-G22-H22 -> 5665278 | J22: 200000 | K22: 0.2 | L22: =I22*K22 -> 1133055.6 | M22: =J22+L22 -> 1333055.6 | N22: =F22+G22+H22+M22 -> 1790764.6 | O22: =E22-N22 -> 4332222.4 | P22: =IF(O22<300000,0.07*O22,21000) -> 21000 | Q22: =IF((O22-300000)<0,0,IF((O22-300000)<300000,0.11*(O22-300000),33000)) -> 33000 | R22: =IF((O22-600000)<0,0,IF((O22-600000)<500000,0.15*(O22-600000),75000)) -> 75000 | S22: =IF((O22-1100000)<0,0,IF((O22-1100000)<500000,0.19*(O22-1100000),95000)) -> 95000 | T22: =IF((O22-1600000)<0,0,IF((O22-1600000)<1600000,0.21*(O22-1600000),336000)) -> 336000 | U22: =24%*(O22-3200000) -> 271733.38 | V22: =P22+Q22+R22+S22+T22+U22 -> 831733.38 | W22: 12 | X22: =V22/W22 -> 69311.115 | Z22: =X22 -> 69311.115 | AA22: 11803.082 | AB22: =Z22+AA22 -> 81114.197 | AC22: CHRISTIAN MADUABUCHI ODO
B23: TOTAL - ANNUAL | C23: =SUM(C5:C22) -> 9345977.6 | F23: =SUM(F5:F22) -> 454852.8 | G23: =SUM(G5:G22) -> 7173098.9 | V23: =SUM(V5:V22) -> 15585890 | X23: =SUM(X5:X22) -> 1298824.2 | Z23: =SUM(Z5:Z22) -> 1298824.2
B24: TOTAL - MONTHLY | F24: =F23/12 -> 37904.4 | G24: =G23/12 -> 597758.24 | V24: =V23/12 -> 1298824.2
Z26: 11287301

Sheet Tax on Arrears
A1: NATIONAL INSTITUTE FOR LEGISLATIVE AND DEMOCRATIC STUDIES
A2: NATIONAL ASSEMBLY ABUJA
A3: TAX COMPUTATION FOR 2022
A4: S/NO | B4: NAME | C4: ARREARS OF PROMOTION | D4: NO OF MONTHS | E4: ANNUAL SALARY GROSSED UP | F4: NATIONAL HOUSING SCHEME = 2.5% OF BASIC SALARY | G4: PENSION CONTRIBUTION = 8% OF CONSOLIDATED | H4: NHIS | I4: NET SALARY (EXC OF CRA) | M4: CRA=#200,000+(20% 0F NET SALARY (EXC OF CRA) | N4: TOTAL RELIEF | O4: CHARGEABLE INCOME | P4: FIRST N300,000 @ 7% | Q4: NEXT N300,000 @ 11% | R4: NEXT N500,000 @ 15% | S4: NEXT N500,000@ 19% | T4: NEXT N1,600,000 @ 21% | U4: ABOVE N3,200,000 @ 24% | V4: ANNUAL TAX PAYABLE | X4: MONTHLY TAX PAYABLE | Y4: MINIMUM TAX PAYABLE | Z4: TAX PAYABLE ON ARREARS
A5: 1 | B5: ABDULSALAM MUSTAPHA | C5: 150313.08 | D5: 12 | E5: =C5*D5 -> 1803757 | G5: 558833.36 | I5: =E5-F5-G5-H5 -> 1244923.6 | J5: 200000 | K5: 0.2 | L5: =I5*K5 -> 248984.72 | M5: =J5+L5 -> 448984.72 | N5: =F5+G5+H5+M5 -> 1007818.1 | O5: =E5-N5 -> 795938.88 | P5: =IF(O5<300000,0.07*O5,21000) -> 21000 | Q5: =IF((O5-300000)<0,0,IF((O5-300000)<300000,0.11*(O5-300000),33000)) -> 33000 | R5: =IF((O5-600000)<0,0,IF((O5-600000)<500000,0.15*(O5-600000),75000)) -> 29390.832 | S5: =IF((O5-1100000)<0,0,IF((O5-1100000)<500000,0.19*(O5-1100000),95000)) -> 0 | T5: =IF((O5-1600000)<0,0,IF((O5-1600000)<1600000,0.21*(O5-1600000),336000)) -> 0 | U5: 0 | V5: =P5+Q5+R5+S5+T5+U5 -> 83390.832 | W5: 12 | X5: =V5/W5 -> 6949.236 | Z5: =X5 -> 6949.236
A6: 2 | B6: EMILY EDIOSA IKHIDE | C6: 526480 | D6: 12 | E6: =C6*D6 -> 6317760 | G6: 558833.36 | I6: =E6-F6-G6-H6 -> 5758926.6 | J6: 200000 | K6: 0.2 | L6: =I6*K6 -> 1151785.3 | M6: =J6+L6 -> 1351785.3 | N6: =F6+G6+H6+M6 -> 1910618.7 | O6: =E6-N6 -> 4407141.3 | P6: =IF(O6<300000,0.07*O6,21000) -> 21000 | Q6: =IF((O6-300000)<0,0,IF((O6-300000)<300000,0.11*(O6-300000),33000)) -> 33000 | R6: =IF((O6-600000)<0,0,IF((O6-600000)<500000,0.15*(O6-600000),75000)) -> 75000 | S6: =IF((O6-1100000)<0,0,IF((O6-1100000)<500000,0.19*(O6-1100000),95000)) -> 95000 | T6: =IF((O6-1600000)<0,0,IF((O6-1600000)<1600000,0.21*(O6-1600000),336000)) -> 336000 | U6: =24%*(O6-3200000) -> 289713.92 | V6: =P6+Q6+R6+S6+T6+U6 -> 849713.92 | W6: 12 | X6: =V6/W6 -> 70809.493 | Z6: =X6 -> 70809.493
A7: 3 | B7: SIMON WAKAWA | C7: 291986.92 | D7: 12 | E7: =C7*D7 -> 3503843 | F7: =8019.8*12 -> 96237.6 | G7: 558833.36 | I7: =E7-F7-G7-H7 -> 2848772.1 | J7: 200000 | K7: 0.2 | L7: =I7*K7 -> 569754.41 | M7: =J7+L7 -> 769754.41 | N7: =F7+G7+H7+M7 -> 1424825.4 | O7: =E7-N7 -> 2079017.6 | P7: =IF(O7<300000,0.07*O7,21000) -> 21000 | Q7: =IF((O7-300000)<0,0,IF((O7-300000)<300000,0.11*(O7-300000),33000)) -> 33000 | R7: =IF((O7-600000)<0,0,IF((O7-600000)<500000,0.15*(O7-600000),75000)) -> 75000 | S7: =IF((O7-1100000)<0,0,IF((O7-1100000)<500000,0.19*(O7-1100000),95000)) -> 95000 | T7: =IF((O7-1600000)<0,0,IF((O7-1600000)<1600000,0.21*(O7-1600000),336000)) -> 100593.7 | V7: =P7+Q7+R7+S7+T7+U7 -> 324593.7 | W7: 12 | X7: =V7/W7 -> 27049.475 | Z7: =X7 -> 27049.475
A8: 4 | B8: WAZIRI USMAN | C8: 291984.21 | D8: 12 | E8: =C8*D8 -> 3503810.5 | F8: =8019.8*12 -> 96237.6 | G8: 558833.36 | I8: =E8-F8-G8-H8 -> 2848739.5 | J8: 200000 | K8: 0.2 | L8: =I8*K8 -> 569747.91 | M8: =J8+L8 -> 769747.91 | N8: =F8+G8+H8+M8 -> 1424818.9 | O8: =E8-N8 -> 2078991.6 | P8: =IF(O8<300000,0.07*O8,21000) -> 21000 | Q8: =IF((O8-300000)<0,0,IF((O8-300000)<300000,0.11*(O8-300000),33000)) -> 33000 | R8: =IF((O8-600000)<0,0,IF((O8-600000)<500000,0.15*(O8-600000),75000)) -> 75000 | S8: =IF((O8-1100000)<0,0,IF((O8-1100000)<500000,0.19*(O8-1100000),95000)) -> 95000 | T8: =IF((O8-1600000)<0,0,IF((O8-1600000)<1600000,0.21*(O8-1600000),336000)) -> 100588.24 | V8: =P8+Q8+R8+S8+T8+U8 -> 324588.24 | W8: 12 | X8: =V8/W8 -> 27049.02 | Z8: =X8 -> 27049.02
A9: 5 | B9: TAIWO I. OYINLOLA | C9: 0 | D9: 0 | E9: =C9*D9 -> 0 | G9: 0 | I9: =E9-F9-G9-H9 -> 0 | J9: 0 | K9: 0.2 | L9: =I9*K9 -> 0 | M9: =J9+L9 -> 0 | N9: =F9+G9+H9+M9 -> 0 | O9: =E9-N9 -> 0 | P9: =IF(O9<300000,0.07*O9,21000) -> 0 | Q9: =IF((O9-300000)<0,0,IF((O9-300000)<300000,0.11*(O9-300000),33000)) -> 0 | R9: =IF((O9-600000)<0,0,IF((O9-600000)<500000,0.15*(O9-600000),75000)) -> 0 | S9: =IF((O9-1100000)<0,0,IF((O9-1100000)<500000,0.19*(O9-1100000),95000)) -> 0 | T9: =IF((O9-1600000)<0,0,IF((O9-1600000)<1600000,0.21*(O9-1600000),336000)) -> 0 | V9: =P9+Q9+R9+S9+T9+U9 -> 0 | W9: 12 | X9: =V9/W9 -> 0 | Z9: =X9 -> 0
A10: 6 | B10: SARATU ATAJIRI | C10: 1486792 | D10: 12 | E10: =C10*D10 -> 17841504 | G10: 245615.04 | I10: =E10-F10-G10-H10 -> 17595889 | J10: 200000 | K10: 0.2 | L10: =I10*K10 -> 3519177.8 | M10: =J10+L10 -> 3719177.8 | N10: =F10+G10+H10+M10 -> 3964792.8 | O10: =E10-N10 -> 13876711 | P10: =IF(O10<300000,0.07*O10,21000) -> 21000 | Q10: =IF((O10-300000)<0,0,IF((O10-300000)<300000,0.11*(O10-300000),33000)) -> 33000 | R10: =IF((O10-600000)<0,0,IF((O10-600000)<500000,0.15*(O10-600000),75000)) -> 75000 | S10: =IF((O10-1100000)<0,0,IF((O10-1100000)<500000,0.19*(O10-1100000),95000)) -> 95000 | T10: =IF((O10-1600000)<0,0,IF((O10-1600000)<1600000,0.21*(O10-1600000),336000)) -> 336000 | U10: =24%*(O10-3200000) -> 2562410.7 | V10: =P10+Q10+R10+S10+T10+U10 -> 3122410.7 | W10: 12 | X10: =V10/W10 -> 260200.89 | Z10: =X10 -> 260200.89
A11: 7 | B11: YUSIF SANI SADIQ | C11: 120895.81 | D11: 12 | E11: =C11*D11 -> 1450749.7 | G11: 339372 | I11: =E11-F11-G11-H11 -> 1111377.7 | J11: 200000 | K11: 0.2 | L11: =I11*K11 -> 222275.54 | M11: =J11+L11 -> 422275.54 | N11: =F11+G11+H11+M11 -> 761647.54 | O11: =E11-N11 -> 689102.18 | P11: =IF(O11<300000,0.07*O11,21000) -> 21000 | Q11: =IF((O11-300000)<0,0,IF((O11-300000)<300000,0.11*(O11-300000),33000)) -> 33000 | R11: =IF((O11-600000)<0,0,IF((O11-600000)<500000,0.15*(O11-600000),75000)) -> 13365.326 | S11: =IF((O11-1100000)<0,0,IF((O11-1100000)<500000,0.19*(O11-1100000),95000)) -> 0 | T11: =IF((O11-1600000)<0,0,IF((O11-1600000)<1600000,0.21*(O11-1600000),336000)) -> 0 | V11: =P11+Q11+R11+S11+T11+U11 -> 67365.326 | W11: 12 | X11: =V11/W11 -> 5613.7772 | Z11: =X11 -> 5613.7772
A12: 8 | B12: STELLA NGOZI PAUL | C12: 99389.476 | D12: 12 | E12: =C12*D12 -> 1192673.7 | G12: 339372 | I12: =E12-F12-G12-H12 -> 853301.71 | J12: 200000 | K12: 0.2 | L12: =I12*K12 -> 170660.34 | M12: =J12+L12 -> 370660.34 | N12: =F12+G12+H12+M12 -> 710032.34 | O12: =E12-N12 -> 482641.37 | P12: =IF(O12<300000,0.07*O12,21000) -> 21000 | Q12: =IF((O12-300000)<0,0,IF((O12-300000)<300000,0.11*(O12-300000),33000)) -> 20090.55 | R12: =IF((O12-600000)<0,0,IF((O12-600000)<500000,0.15*(O12-600000),75000)) -> 0 | S12: =IF((O12-1100000)<0,0,IF((O12-1100000)<500000,0.19*(O12-1100000),95000)) -> 0 | T12: =IF((O12-1600000)<0,0,IF((O12-1600000)<1600000,0.21*(O12-1600000),336000)) -> 0 | V12: =P12+Q12+R12+S12+T12+U12 -> 41090.55 | W12: 12 | X12: =V12/W12 -> 3424.2125 | Z12: =X12 -> 3424.2125
A13: 9 | B13: OMONIGHO EROMOSELE-WESEY | C13: 481299.33 | D13: 12 | E13: =C13*D13 -> 5775592 | F13: =6922.5*12 -> 83070 | G13: 374638.96 | I13: =E13-F13-G13-H13 -> 5317883 | J13: 200000 | K13: 0.2 | L13: =I13*K13 -> 1063576.6 | M13: =J13+L13 -> 1263576.6 | N13: =F13+G13+H13+M13 -> 1721285.6 | O13: =E13-N13 -> 4054306.4 | P13: =IF(O13<300000,0.07*O13,21000) -> 21000 | Q13: =IF((O13-300000)<0,0,IF((O13-300000)<300000,0.11*(O13-300000),33000)) -> 33000 | R13: =IF((O13-600000)<0,0,IF((O13-600000)<500000,0.15*(O13-600000),75000)) -> 75000 | S13: =IF((O13-1100000)<0,0,IF((O13-1100000)<500000,0.19*(O13-1100000),95000)) -> 95000 | T13: =IF((O13-1600000)<0,0,IF((O13-1600000)<1600000,0.21*(O13-1600000),336000)) -> 336000 | U13: =24%*(O13-3200000) -> 205033.54 | V13: =P13+Q13+R13+S13+T13+U13 -> 765033.54 | W13: 12 | X13: =V13/W13 -> 63752.795 | Z13: =X13 -> 63752.795
A14: 10 | B14: QUEEN ONYEKESON | C14: 163040.15 | D14: 12 | E14: =C14*D14 -> 1956481.8 | G14: 374638.96 | I14: =E14-F14-G14-H14 -> 1581842.8 | J14: 200000 | K14: 0.2 | L14: =I14*K14 -> 316368.57 | M14: =J14+L14 -> 516368.57 | N14: =F14+G14+H14+M14 -> 891007.53 | O14: =E14-N14 -> 1065474.3 | P14: =IF(O14<300000,0.07*O14,21000) -> 21000 | Q14: =IF((O14-300000)<0,0,IF((O14-300000)<300000,0.11*(O14-300000),33000)) -> 33000 | R14: =IF((O14-600000)<0,0,IF((O14-600000)<500000,0.15*(O14-600000),75000)) -> 69821.139 | S14: =IF((O14-1100000)<0,0,IF((O14-1100000)<500000,0.19*(O14-1100000),95000)) -> 0 | T14: =IF((O14-1600000)<0,0,IF((O14-1600000)<1600000,0.21*(O14-1600000),336000)) -> 0 | V14: =P14+Q14+R14+S14+T14+U14 -> 123821.14 | W14: 12 | X14: =V14/W14 -> 10318.428 | Z14: =X14 -> 10318.428
A15: 11 | B15: SHAMSUDEEN YAHAYA | C15: 394860 | D15: 12 | E15: =C15*D15 -> 4738320 | G15: 558833.36 | I15: =E15-F15-G15-H15 -> 4179486.6 | J15: 200000 | K15: 0.2 | L15: =I15*K15 -> 835897.33 | M15: =J15+L15 -> 1035897.3 | N15: =F15+G15+H15+M15 -> 1594730.7 | O15: =E15-N15 -> 3143589.3 | P15: =IF(O15<300000,0.07*O15,21000) -> 21000 | Q15: =IF((O15-300000)<0,0,IF((O15-300000)<300000,0.11*(O15-300000),33000)) -> 33000 | R15: =IF((O15-600000)<0,0,IF((O15-600000)<500000,0.15*(O15-600000),75000)) -> 75000 | S15: =IF((O15-1100000)<0,0,IF((O15-1100000)<500000,0.19*(O15-1100000),95000)) -> 95000 | T15: =IF((O15-1600000)<0,0,IF((O15-1600000)<1600000,0.21*(O15-1600000),336000)) -> 324153.76 | V15: =P15+Q15+R15+S15+T15+U15 -> 548153.76 | W15: 12 | X15: =V15/W15 -> 45679.48 | Z15: =X15 -> 45679.48
A16: 12 | B16: SALAMATU YAKUBU | C16: 323232.75 | D16: 12 | E16: =C16*D16 -> 3878793 | F16: =8019.8*12 -> 96237.6 | G16: 558833.36 | I16: =E16-F16-G16-H16 -> 3223722 | J16: 200000 | K16: 0.2 | L16: =I16*K16 -> 644744.41 | M16: =J16+L16 -> 844744.41 | N16: =F16+G16+H16+M16 -> 1499815.4 | O16: =E16-N16 -> 2378977.6 | P16: =IF(O16<300000,0.07*O16,21000) -> 21000 | Q16: =IF((O16-300000)<0,0,IF((O16-300000)<300000,0.11*(O16-300000),33000)) -> 33000 | R16: =IF((O16-600000)<0,0,IF((O16-600000)<500000,0.15*(O16-600000),75000)) -> 75000 | S16: =IF((O16-1100000)<0,0,IF((O16-1100000)<500000,0.19*(O16-1100000),95000)) -> 95000 | T16: =IF((O16-1600000)<0,0,IF((O16-1600000)<1600000,0.21*(O16-1600000),336000)) -> 163585.3 | V16: =P16+Q16+R16+S16+T16+U16 -> 387585.3 | W16: 12 | X16: =V16/W16 -> 32298.775 | Z16: =X16 -> 32298.775
A17: 13 | B17: ROTIMI OGUNYOMI | C17: 180487.25 | D17: 12 | E17: =C17*D17 -> 2165847 | G17: 374638.96 | I17: =E17-F17-G17-H17 -> 1791208 | J17: 200000 | K17: 0.2 | L17: =I17*K17 -> 358241.61 | M17: =J17+L17 -> 558241.61 | N17: =F17+G17+H17+M17 -> 932880.57 | O17: =E17-N17 -> 1232966.4 | P17: =IF(O17<300000,0.07*O17,21000) -> 21000 | Q17: =IF((O17-300000)<0,0,IF((O17-300000)<300000,0.11*(O17-300000),33000)) -> 33000 | R17: =IF((O17-600000)<0,0,IF((O17-600000)<500000,0.15*(O17-600000),75000)) -> 75000 | S17: =IF((O17-1100000)<0,0,IF((O17-1100000)<500000,0.19*(O17-1100000),95000)) -> 25263.622 | T17: =IF((O17-1600000)<0,0,IF((O17-1600000)<1600000,0.21*(O17-1600000),336000)) -> 0 | V17: =P17+Q17+R17+S17+T17+U17 -> 154263.62 | W17: 12 | X17: =V17/W17 -> 12855.302 | Z17: =X17 -> 12855.302
A18: 14 | B18: LEO IGBANOI | C18: 676611.67 | D18: 12 | E18: =C18*D18 -> 8119340 | G18: 425036.64 | I18: =E18-F18-G18-H18 -> 7694303.4 | J18: 200000 | K18: 0.2 | L18: =I18*K18 -> 1538860.7 | M18: =J18+L18 -> 1738860.7 | N18: =F18+G18+H18+M18 -> 2163897.3 | O18: =E18-N18 -> 5955442.7 | P18: =IF(O18<300000,0.07*O18,21000) -> 21000 | Q18: =IF((O18-300000)<0,0,IF((O18-300000)<300000,0.11*(O18-300000),33000)) -> 33000 | R18: =IF((O18-600000)<0,0,IF((O18-600000)<500000,0.15*(O18-600000),75000)) -> 75000 | S18: =IF((O18-1100000)<0,0,IF((O18-1100000)<500000,0.19*(O18-1100000),95000)) -> 95000 | T18: =IF((O18-1600000)<0,0,IF((O18-1600000)<1600000,0.21*(O18-1600000),336000)) -> 336000 | U18: =24%*(O18-3200000) -> 661306.25 | V18: =P18+Q18+R18+S18+T18+U18 -> 1221306.2 | W18: 12 | X18: =V18/W18 -> 101775.52 | Z18: =X18 -> 101775.52
A19: 15 | B19: LOHNA BONKAT JONATHAN | C19: 575119.92 | D19: 12 | E19: =C19*D19 -> 6901439 | G19: 425036.64 | I19: =E19-F19-G19-H19 -> 6476402.4 | J19: 200000 | K19: 0.2 | L19: =I19*K19 -> 1295280.5 | M19: =J19+L19 -> 1495280.5 | N19: =F19+G19+H19+M19 -> 1920317.1 | O19: =E19-N19 -> 4981121.9 | P19: =IF(O19<300000,0.07*O19,21000) -> 21000 | Q19: =IF((O19-300000)<0,0,IF((O19-300000)<300000,0.11*(O19-300000),33000)) -> 33000 | R19: =IF((O19-600000)<0,0,IF((O19-600000)<500000,0.15*(O19-600000),75000)) -> 75000 | S19: =IF((O19-1100000)<0,0,IF((O19-1100000)<500000,0.19*(O19-1100000),95000)) -> 95000 | T19: =IF((O19-1600000)<0,0,IF((O19-1600000)<1600000,0.21*(O19-1600000),336000)) -> 336000 | U19: =24%*(O19-3200000) -> 427469.25 | V19: =P19+Q19+R19+S19+T19+U19 -> 987469.25 | W19: 12 | X19: =V19/W19 -> 82289.104 | Z19: =X19 -> 82289.104
A20: 16 | B20: TOSIN OWOEYE | C20: 401499 | D20: 12 | E20: =C20*D20 -> 4817988 | G20: 339372 | I20: =E20-F20-G20-H20 -> 4478616 | J20: 200000 | K20: 0.2 | L20: =I20*K20 -> 895723.2 | M20: =J20+L20 -> 1095723.2 | N20: =F20+G20+H20+M20 -> 1435095.2 | O20: =E20-N20 -> 3382892.8 | P20: =IF(O20<300000,0.07*O20,21000) -> 21000 | Q20: =IF((O20-300000)<0,0,IF((O20-300000)<300000,0.11*(O20-300000),33000)) -> 33000 | R20: =IF((O20-600000)<0,0,IF((O20-600000)<500000,0.15*(O20-600000),75000)) -> 75000 | S20: =IF((O20-1100000)<0,0,IF((O20-1100000)<500000,0.19*(O20-1100000),95000)) -> 95000 | T20: =IF((O20-1600000)<0,0,IF((O20-1600000)<1600000,0.21*(O20-1600000),336000)) -> 336000 | U20: =24%*(O20-3200000) -> 43894.272 | V20: =P20+Q20+R20+S20+T20+U20 -> 603894.27 | W20: 12 | X20: =V20/W20 -> 50324.523 | Z20: =X20 -> 50324.523
A21: 17 | B21: STACY CHINYERE IGWE | C21: 655332 | D21: 12 | E21: =C21*D21 -> 7863984 | G21: 339372 | I21: =E21-F21-G21-H21 -> 7524612 | J21: 200000 | K21: 0.2 | L21: =I21*K21 -> 1504922.4 | M21: =J21+L21 -> 1704922.4 | N21: =F21+G21+H21+M21 -> 2044294.4 | O21: =E21-N21 -> 5819689.6 | P21: =IF(O21<300000,0.07*O21,21000) -> 21000 | Q21: =IF((O21-300000)<0,0,IF((O21-300000)<300000,0.11*(O21-300000),33000)) -> 33000 | R21: =IF((O21-600000)<0,0,IF((O21-600000)<500000,0.15*(O21-600000),75000)) -> 75000 | S21: =IF((O21-1100000)<0,0,IF((O21-1100000)<500000,0.19*(O21-1100000),95000)) -> 95000 | T21: =IF((O21-1600000)<0,0,IF((O21-1600000)<1600000,0.21*(O21-1600000),336000)) -> 336000 | U21: =24%*(O21-3200000) -> 628725.5 | V21: =P21+Q21+R21+S21+T21+U21 -> 1188725.5 | W21: 12 | X21: =V21/W21 -> 99060.459 | Z21: =X21 -> 99060.459
A22: 18 | B22: TITILAYO MARVELOUS DANIEL | C22: 176519 | D22: 12 | E22: =C22*D22 -> 2118228 | G22: 245615.04 | I22: =E22-F22-G22-H22 -> 1872613 | J22: 200000 | K22: 0.2 | L22: =I22*K22 -> 374522.59 | M22: =J22+L22 -> 574522.59 | N22: =F22+G22+H22+M22 -> 820137.63 | O22: =E22-N22 -> 1298090.4 | P22: =IF(O22<300000,0.07*O22,21000) -> 21000 | Q22: =IF((O22-300000)<0,0,IF((O22-300000)<300000,0.11*(O22-300000),33000)) -> 33000 | R22: =IF((O22-600000)<0,0,IF((O22-600000)<500000,0.15*(O22-600000),75000)) -> 75000 | S22: =IF((O22-1100000)<0,0,IF((O22-1100000)<500000,0.19*(O22-1100000),95000)) -> 37637.17 | T22: =IF((O22-1600000)<0,0,IF((O22-1600000)<1600000,0.21*(O22-1600000),336000)) -> 0 | V22: =P22+Q22+R22+S22+T22+U22 -> 166637.17 | W22: 12 | X22: =V22/W22 -> 13886.431 | Z22: =X22 -> 13886.431
A23: 19 | B23: TANIMU M. LAWAL | C23: 86887.25 | D23: 12 | E23: =C23*D23 -> 1042647 | G23: 146701.6 | I23: =E23-F23-G23-H23 -> 895945.4 | J23: 200000 | K23: 0.2 | L23: =I23*K23 -> 179189.08 | M23: =J23+L23 -> 379189.08 | N23: =F23+G23+H23+M23 -> 525890.68 | O23: =E23-N23 -> 516756.32 | P23: =IF(O23<300000,0.07*O23,21000) -> 21000 | Q23: =IF((O23-300000)<0,0,IF((O23-300000)<300000,0.11*(O23-300000),33000)) -> 23843.195 | R23: =IF((O23-600000)<0,0,IF((O23-600000)<500000,0.15*(O23-600000),75000)) -> 0 | S23: =IF((O23-1100000)<0,0,IF((O23-1100000)<500000,0.19*(O23-1100000),95000)) -> 0 | T23: =IF((O23-1600000)<0,0,IF((O23-1600000)<1600000,0.21*(O23-1600000),336000)) -> 0 | V23: =P23+Q23+R23+S23+T23+U23 -> 44843.195 | W23: 12 | X23: =V23/W23 -> 3736.9329 | Z23: =X23 -> 3736.9329
A24: 20 | B24: CHRISTIAN MADUABUCHI ODO | C24: 180487.25 | D24: 12 | E24: =C24*D24 -> 2165847 | F24: =6922.5*12 -> 83070 | G24: 374638.96 | I24: =E24-F24-G24-H24 -> 1708138 | J24: 200000 | K24: 0.2 | L24: =I24*K24 -> 341627.61 | M24: =J24+L24 -> 541627.61 | N24: =F24+G24+H24+M24 -> 999336.57 | O24: =E24-N24 -> 1166510.4 | P24: =IF(O24<300000,0.07*O24,21000) -> 21000 | Q24: =IF((O24-300000)<0,0,IF((O24-300000)<300000,0.11*(O24-300000),33000)) -> 33000 | R24: =IF((O24-600000)<0,0,IF((O24-600000)<500000,0.15*(O24-600000),75000)) -> 75000 | S24: =IF((O24-1100000)<0,0,IF((O24-1100000)<500000,0.19*(O24-1100000),95000)) -> 12636.982 | T24: =IF((O24-1600000)<0,0,IF((O24-1600000)<1600000,0.21*(O24-1600000),336000)) -> 0 | V24: =P24+Q24+R24+S24+T24+U24 -> 141636.98 | W24: 12 | X24: =V24/W24 -> 11803.082 | Z24: =X24 -> 11803.082
Z25: 11287301

Sheet Stoppage of Salary
A1: NATIONAL INSTITUTE FOR LEGISLATIVE AND DEMOCRATIC STUDIES
A2: STAFF PAYROLL FOR THE MONTH OF NOVEMBER, 2024
E3: ='[1]FEB 08'!E11/'[1]FEB 08'!M11 -> #REF!
B4: STAFF NAME | C4: DESIGNATION | D4: GRADE LEVEL | E4: BASIC SALARY | F4: ALLCE/ AREARS | G4: ALLOWANCE | H4: ALLOWANCE | I4: DUTY ALLCE | J4: GROSS SALARY | K4: AUCTION | L4: COOP CONTR/SPEC SAVINGS | M4: COOP. LOAN RECOVERY | N4: NHF DED. | O4: PAYE | P4: EMPLOYEE PENSIONS | Q4: TOTAL DEDUCTION | R4: OCTOBER, 2024 | S4: NOVEMBER, 2024
E5: N | F5: N | G5: N | H5: N | I5: N | J5: N | K5: N | L5: N | M5: N | N5: N | O5: N | P5: N | Q5: N | R5: N | S5: N
A6: S/N | B6: DG'S OFFICE
A7: 2 | B7: DR CLINTON JAJA | C7: SENIOR RESEARCH FELLOW | D7: 15(9) | E7: 620675.58 | G7: =160000 -> 160000 | I7: 0 | J7: =SUM(E7:I7) -> 780675.58 | L7: =50000 -> 50000 | M7: =385000 -> 385000 | O7: 119022.8 | P7: 49654.047 | Q7: =O7+N7+M7+L7+K7+P7 -> 603676.85 | R7: 176998.73 | S7: =J7-Q7 -> 176998.73
A8: 3 | B8: LOHNA BONKAT JONATHAN | C8: RESEARCH FELLOW 11 | D8: 13(10) | E8: 428915.92 | F8: 0 | G8: =120000 -> 120000 | I8: 0 | J8: =SUM(E8:I8) -> 548915.92 | L8: =20000+65000+65000 -> 150000 | M8: 0 | N8: 0 | O8: 77470.374 | P8: 34313.273 | Q8: =O8+N8+M8+L8+K8+P8 -> 261783.65 | R8: 287132.27 | S8: =J8-Q8 -> 287132.27
B9: TOTAL | C9: 31 | E9: =SUM(E7:E8) -> 1049591.5 | F9: =SUM(F7:F8) -> 0 | G9: =SUM(G7:G8) -> 280000 | H9: =SUM(H7:H8) -> 0 | I9: =SUM(I7:I8) -> 0 | J9: =SUM(J7:J8) -> 1329591.5 | K9: =SUM(K7:K8) -> 0 | L9: =SUM(L7:L8) -> 200000 | ... Q9: =SUM(Q7:Q8) -> 865460.5 | R9: 13026183 | S9: =SUM(S7:S8) -> 464131

Sheet New PAYE

Sheet New Pensions Promotion
A1: NATIONAL INSTITUTE FOR LEGISLATIVE & DEMOCRATIC STUDIES
A2: 2024 ANALYSIS OF STAFF PROMOTION ARREARS
A4: SN | B4: Name of Employee | C4: Department | D4: New Grade Level | E4: Annual Consolidated Salary of New Position(Less Res/Harsh Allow | F4: Monthly Consolidated Salary of New Position(Less Res/Harsh Allow | G4: 8% Employee Contr | H4: Annual 8% Employee Contr
F5: N | G5: N | H5: N
A6: 1 | B6: ABDULSALAM MUSTAPHA | C6: DG's Office | D6: 15/7 | E6: =F6*12 -> 6985417 | F6: =582118.08 -> 582118.08 | G6: =F6*0.08 -> 46569.446 | H6: =G6*12 -> 558833.36
A7: 2 | B7: EMILY EDIOSA IKHIDE | C7: DG's Office | D7: 015/7 | E7: =F7*12 -> 6985417 | F7: =582118.08 -> 582118.08 | G7: =F7*0.08 -> 46569.446 | H7: =G7*12 -> 558833.36
A8: 3 | B8: SIMON WAKAWA | C8: DG's Office | D8: 015/7 | E8: =F8*12 -> 6985417 | F8: =582118.08 -> 582118.08 | G8: =F8*0.08 -> 46569.446 | H8: =G8*12 -> 558833.36
A9: 4 | B9: WAZIRI USMAN | C9: DG's Office | D9: 015/7 | E9: =F9*12 -> 6985417 | F9: =582118.08 -> 582118.08 | G9: =F9*0.08 -> 46569.446 | H9: =G9*12 -> 558833.36
A10: 5 | B10: TAIWO I. OYINLOLA | C10: Admin. & HR | D10: 07/3 | E10: =F10*12 -> 1833770 | F10: =152814.17 -> 152814.17 | G10: =F10*0.08 -> 12225.134 | H10: =G10*12 -> 146701.6
A11: 6 | B11: SARATU ATAJIRI | C11: Admin. & HR | D11: 09/7 | E11: =F11*12 -> 3070188 | F11: =255849 -> 255849 | G11: =F11*0.08 -> 20467.92 | H11: =G11*12 -> 245615.04
A12: 7 | B12: YUSIF SANI SADIQ | C12: Admin. & HR | D12: 12/7 | E12: =F12*12 -> 4242150 | F12: =353512.5 -> 353512.5 | G12: =F12*0.08 -> 28281 | H12: =G12*12 -> 339372
A13: 8 | B13: STELLA NGOZI PAUL | C13: Admin. & HR | D13: 12/7 | E13: =F13*12 -> 4242150 | F13: =353512.5 -> 353512.5 | G13: =F13*0.08 -> 28281 | H13: =G13*12 -> 339372
A14: 9 | B14: OMONIGHO EROMOSELE-WESEY | C14: Admin. & HR | D14: 13/7 | E14: =F14*12 -> 4682987 | F14: =390248.92 -> 390248.92 | G14: =F14*0.08 -> 31219.914 | H14: =G14*12 -> 374638.96
A15: 10 | B15: QUEEN ONYEKESON | C15: Admin. & HR | D15: 13/7 | E15: =F15*12 -> 4682987 | F15: =390248.92 -> 390248.92 | G15: =F15*0.08 -> 31219.914 | H15: =G15*12 -> 374638.96
A16: 11 | B16: SHAMSUDEEN YAHAYA | C16: LSS | D16: 015/7 | E16: =F16*12 -> 6985417 | F16: 582118.08 | G16: =F16*0.08 -> 46569.446 | H16: =G16*12 -> 558833.36
A17: 12 | B17: SALAMATU YAKUBU | C17: LSS | D17: 015/7 | E17: =F17*12 -> 6985417 | F17: 582118.08 | G17: =F17*0.08 -> 46569.446 | H17: =G17*12 -> 558833.36
A18: 13 | B18: ROTIMI OGUNYOMI | C18: LSS | D18: 13/7 | E18: =F18*12 -> 4682987 | F18: 390248.92 | G18: =F18*0.08 -> 31219.914 | H18: =G18*12 -> 374638.96
A19: 14 | B19: LEO IGBANOI | C19: Dem. & Gov. | D19: 14/8 | E19: =F19*12 -> 5312958 | F19: =442746.5 -> 442746.5 | G19: =F19*0.08 -> 35419.72 | H19: =G19*12 -> 425036.64
A20: 15 | B20: LOHNA BONKAT JONATHAN | C20: Dem. & Gov. | D20: 14/8 | E20: =F20*12 -> 5312958 | F20: =442746.5 -> 442746.5 | G20: =F20*0.08 -> 35419.72 | H20: =G20*12 -> 425036.64
A21: 16 | B21: TOSIN OWOEYE | C21: Dem. & Gov. | D21: 12/7 | E21: =F21*12 -> 4242150 | F21: 353512.5 | G21: =F21*0.08 -> 28281 | H21: =G21*12 -> 339372
A22: 17 | B22: STACY CHINYERE IGWE | C22: DOS | D22: 12/7 | E22: =F22*12 -> 4242150 | F22: 353512.5 | G22: =F22*0.08 -> 28281 | H22: =G22*12 -> 339372
A23: 18 | B23: TITILAYO MARVELOUS DANIEL | C23: Library | D23: 09/7 | E23: =F23*12 -> 3070188 | F23: 255849 | G23: =F23*0.08 -> 20467.92 | H23: =G23*12 -> 245615.04
A24: 19 | B24: TANIMU M. LAWAL | C24: Econ/ & Social Res. | D24: 07/3 | E24: =F24*12 -> 1833770 | F24: 152814.17 | G24: =F24*0.08 -> 12225.134 | H24: =G24*12 -> 146701.6
A25: 20 | B25: CHRISTIAN MADUABUCHI ODO | C25: Finance & Accts | D25: 13/7 | E25: =F25*12 -> 4682987 | F25: 390248.92 | G25: =F25*0.08 -> 31219.914 | H25: =G25*12 -> 374638.96
B26: TOTAL

Sheet Conversion in Nov
A1: NATIONAL INSTITUTE FOR LEGISLATIVE AND DEMOCRATIC STUDIES
A2: STAFF PAYROLL FOR THE MONTH OF NOVEMBER, 2024
E3: ='[1]FEB 08'!E11/'[1]FEB 08'!M11 -> #REF!
B4: STAFF NAME | C4: DESIGNATION | D4: GRADE LEVEL | E4: BASIC SALARY | F4: ALLCE/ AREARS | G4: ALLOWANCE | H4: ALLOWANCE | I4: DUTY ALLCE | J4: GROSS SALARY | K4: AUCTION | L4: COOP CONTR/SPEC SAVINGS | M4: COOP. LOAN RECOVERY | N4: NHF DED. | O4: PAYE | P4: EMPLOYEE PENSIONS | Q4: TOTAL DEDUCTION | R4: OCTOBER, 2024 | S4: NOVEMBER, 2024
E5: N | F5: N | G5: N | H5: N | I5: N | J5: N | K5: N | L5: N | M5: N | N5: N | O5: N | P5: N | Q5: N | R5: N | S5: N
A6: S/N | B6: DG'S OFFICE
A7: 25 | B7: SARATU ATAJIRI | C7: ADMINI OFFICER | D7: 9(7) | E7: 255849 | H7: =60000 -> 60000 | J7: =E7+F7+G7+H7+I7 -> 315849 | O7: 36790.688 | P7: 20467.92 | Q7: =O7+N7+M7+L7+K7+P7 -> 57258.608 | S7: =J7-Q7 -> 258590.39

