Workbook

Sheet Feb. 15
A3: STAFF PAYROLL FOR THE MONTH OF OCTOBER, 2014
E4: 0.22 | H4: 0.3
A5: STAFF NAME | S5: DEDUCTIONS | W5: NET SALARY
C6: DESIGNATION | D6: SALARY | E6: BASIC | F6: SALARY AREARS | L6: PERSONAL | M6: MOTOR/ | N6: RESEARCH | O6: LEAVE | P6: OUT FIT | Q6: LEGISLATIVE | R6: GROSS | V6: JANUARY, 15 | W6: FEBRUARY,15
D7: LEVEL | E7: SALARY | F7: ADVANCE | G7: RENT | H7: UTILITY | I7: DOMESTIC | J7: ENTERT. | K7: FURNIT. | L7: ASSISTANT | M7: FUEL | N7: ALLOWANCE | O7: ALLCE | P7: ALLCE | Q7: DUTY ALLCE | R7: SALARY | S7: SALARY ADV. | T7: PAYE | U7: TOTAL
A8: DG OFFICE | E8: N | H8: N | R8: N | T8: N
A9: DR LADI HAMALAI | C9: DIRECTOR GENERAL | D9: CONSOL | E9: 160488.75 | G9: 320977.5 | H9: 48146.63 | I9: 120366.57 | J9: 72219.94 | K9: 481466.25 | L9: 40122.19 | M9: 120366.57 | N9: 150000 | O9: 16048.88 | P9: 25000 | Q9: 25235 | R9: =SUM(E9:Q9) -> 1580438.3 | T9: 113176.97 | U9: =S9+T9 -> 113176.97 | V9: 1467261.3 | W9: =R9-U9 -> 1467261.3
A10: PROF. OFFORNZE AMUCHEAZI | C10: LEGAL ADVISER | D10: 16(9) | E10: =E34 -> 42653.17 | G10: =G34 -> 127959.51 | H10: =H34 -> 3198.9877 | I10: =I34 -> 40122.19 | J10: =E10*50% -> 21326.585 | K10: =E10*350% -> 149286.1 | L10: 0 | M10: =E10*100% -> 42653.17 | N10: 0 | O10: =E10*10% -> 4265.317 | P10: 20000 | Q10: 100000 | R10: =SUM(E10:Q10) -> 551465.02 | T10: 21618.09 | U10: =S10+T10 -> 21618.09 | V10: 529846.93 | W10: =R10-U10 -> 529846.93
A11: DR MOBOLAJI HAKEEM | C11: SPECIAL ASSISTANT | D11: 16(8) | E11: 41157.69 | G11: =E11*300% -> 123473.07 | H11: =E11*7.5% -> 3086.8268 | I11: 40122.19 | J11: =E11*50% -> 20578.845 | K11: =E11*350% -> 144051.92 | M11: =E11*100% -> 41157.69 | N11: 100000 | O11: =E11*10% -> 4115.769 | P11: 20000 | R11: =SUM(E11:Q11) -> 537744 | T11: 21618.09 | U11: =S11+T11 -> 21618.09 | V11: 516125.91 | W11: =R11-U11 -> 516125.91
A12: RICHARD KWALMI | C12: MICT | D12: 15(9) | E12: =E76 -> 33507.5 | F12: 113529.57 | G12: =E12*300% -> 100522.5 | H12: =E12*7.5% -> 2513.0625 | I12: =I9/3 -> 40122.19 | J12: =E12*50% -> 16753.75 | K12: =E12*350% -> 117276.25 | L12: 0 | M12: =E12*100% -> 33507.5 | N12: 0 | O12: =E12*10% -> 3350.75 | P12: 20000 | Q12: 0 | R12: =SUM(E12:Q12) -> 481083.07 | T12: 15548.33 | U12: =S12+T12 -> 15548.33 | V12: 238475.6 | W12: =R12-U12 -> 465534.74
A13: ADAMU ISA ABBA | C13: INFO. MANAGER | D13: 15(9) | E13: =E76 -> 33507.5 | G13: =E13*300% -> 100522.5 | H13: =E13*7.5% -> 2513.0625 | I13: 40122.19 | J13: =E13*50% -> 16753.75 | K13: =E13*350% -> 117276.25 | L13: 0 | M13: =E13*100% -> 33507.5 | N13: 0 | O13: =E13*10% -> 3350.75 | P13: 20000 | Q13: 0 | R13: =SUM(E13:Q13) -> 367553.5 | T13: 15548.33 | U13: =S13+T13 -> 15548.33 | V13: 352005.17 | W13: =R13-U13 -> 352005.17
A14: NWOSU MATHEW EZE | C14: MANAGER INT. AUDIT | D14: 15(9) | E14: =E76 -> 33507.5 | G14: =E14*300% -> 100522.5 | H14: =E14*7.5% -> 2513.0625 | I14: =I75 -> 40122.19 | J14: =E14*50% -> 16753.75 | K14: =E14*350% -> 117276.25 | L14: 0 | M14: =E14*100% -> 33507.5 | N14: 0 | O14: =E14*10% -> 3350.75 | P14: 20000 | Q14: 0 | R14: =SUM(E14:Q14) -> 367553.5 | T14: 15548.33 | U14: =S14+T14 -> 15548.33 | V14: 352005.17 | W14: =R14-U14 -> 352005.17
A15: CHIEDO AKALEU | C15: RESEARCH FELLOW II | D15: 15(8) | E15: 32263.2 | G15: =E15*300% -> 96789.6 | H15: =E15*7.5% -> 2419.74 | I15: 40122.19 | J15: =E15*50% -> 16131.6 | K15: =E15*350% -> 112921.2 | L15: 0 | M15: =E15*100% -> 32263.2 | N15: 0 | O15: =E15*10% -> 3226.32 | P15: 15000 | Q15: 0 | R15: =SUM(E15:Q15) -> 351137.05 | T15: 15548.33 | U15: =T15+S15 -> 15548.33 | V15: 335588.72 | W15: =R15-U15 -> 335588.72
A16: AKINSANMI ADEJOKE OLUKEMI | C16: AM INFORMATION | D16: 13(9) | E16: =E17 -> 24741.26 | G16: =E16*300% -> 74223.78 | H16: =E16*7.5% -> 1855.5945 | I16: 0 | J16: =E16*50% -> 12370.63 | K16: =E16*350% -> 86594.41 | L16: 0 | M16: =E16*100% -> 24741.26 | N16: 100000 | O16: =E16*10% -> 2474.126 | P16: 15000 | Q16: 0 | R16: =SUM(E16:Q16) -> 342001.06 | T16: 7709 | U16: =S16+T16 -> 7709 | V16: 334292.06 | W16: =R16-U16 -> 334292.06
A17: FAROUK U. M ILLO | C17: PA DG | D17: 13(9) | E17: =E77 -> 24741.26 | G17: =E17*300% -> 74223.78 | H17: =E17*7.5% -> 1855.5945 | I17: 0 | J17: =E17*50% -> 12370.63 | K17: =E17*350% -> 86594.41 | L17: 0 | M17: =E17*100% -> 24741.26 | N17: 0 | O17: =E17*10% -> 2474.126 | P17: 15000 | Q17: 0 | R17: =SUM(E17:Q17) -> 242001.06 | T17: 7709 | U17: =S17+T17 -> 7709 | V17: 234292.06 | W17: =R17-U17 -> 234292.06
A18: BEDARI HARI | C18: LEGAL OFFICER | D18: 10(9) | E18: =E82 -> 18281.64 | G18: =E18*300% -> 54844.92 | H18: =E18*7.5% -> 1371.123 | I18: 0 | J18: =E18*50% -> 9140.82 | K18: =E18*350% -> 63985.74 | L18: 0 | M18: =E18*100% -> 18281.64 | N18: 0 | O18: =E18*10% -> 1828.164 | P18: 10000 | Q18: 0 | R18: =SUM(E18:Q18) -> 177734.05 | T18: 3369.51 | U18: =S18+T18 -> 3369.51 | V18: 174364.54 | W18: =R18-U18 -> 174364.54
A19: NGARA CHRISTOPHER OCHANJA | B19: NGARA CHRISTOPHER OCHANJA | C19: OFFICER, SPECIAL DUTIES | D19: 10(9) | E19: =E82 -> 18281.64 | G19: =E19*300% -> 54844.92 | H19: =E19*7.5% -> 1371.123 | J19: =E19*50% -> 9140.82 | K19: =E19*350% -> 63985.74 | M19: =E19*100% -> 18281.64 | N19: 0 | O19: =E19*10% -> 1828.164 | P19: 10000 | Q19: 40000 | R19: =SUM(E19:Q19) -> 217734.05 | S19: 0 | T19: 3369.51 | U19: =S19+T19 -> 3369.51 | V19: 214364.54 | W19: =R19-U19 -> 214364.54
A20: JOY HARUNA MAKERI | B20: JOY HARUNA MAKERI | C20: PA DG | D20: 10(9) | E20: =E82 -> 18281.64 | G20: =E20*300% -> 54844.92 | H20: =E20*7.5% -> 1371.123 | J20: =E20*50% -> 9140.82 | K20: =E20*350% -> 63985.74 | M20: =E20*100% -> 18281.64 | O20: =E20*10% -> 1828.164 | P20: 10000 | R20: =SUM(E20:Q20) -> 177734.05 | T20: 3369.51 | U20: =S20+T20 -> 3369.51 | V20: 174364.54 | W20: =R20-U20 -> 174364.54
B21: DONALD E. MKPANAM | C21: IT OFFICER | D21: 10(9) | E21: =E82 -> 18281.64 | G21: =E21*300% -> 54844.92 | H21: =E21*7.5% -> 1371.123 | J21: =E21*50% -> 9140.82 | K21: =E21*350% -> 63985.74 | M21: =E21*100% -> 18281.64 | O21: =E21*10% -> 1828.164 | P21: 10000 | R21: =SUM(E21:Q21) -> 177734.05 | T21: 3369.51 | U21: =S21+T21 -> 3369.51 | V21: 174364.54 | W21: =R21-U21 -> 174364.54
A22: HUSSEIN MUSA AGYE | C22: PROTOCOL OFFICER | D22: 10(9) | E22: =E58 -> 18281.64 | G22: =E22*300% -> 54844.92 | H22: =E22*7.5% -> 1371.123 | I22: 0 | J22: =E22*50% -> 9140.82 | K22: =E22*350% -> 63985.74 | L22: 0 | M22: =E22*100% -> 18281.64 | N22: 0 | O22: =E22*10% -> 1828.164 | P22: 10000 | Q22: 0 | R22: =SUM(E22:Q22) -> 177734.05 | T22: 3369.51 | U22: =T22+S22 -> 3369.51 | V22: 174364.54 | W22: =R22-U22 -> 174364.54
A23: BASHIRU ABBA WALI | C23: ASSIT. INT. AUDIT | D23: 8(9) | E23: 13112.16 | G23: =E23*300% -> 39336.48 | H23: =E23*7.5% -> 983.412 | I23: 0 | J23: =E23*50% -> 6556.08 | K23: =E23*350% -> 45892.56 | L23: 0 | M23: =E23*100% -> 13112.16 | N23: 0 | O23: =E23*10% -> 1311.216 | P23: 10000 | Q23: 0 | R23: =SUM(E23:Q23) -> 130304.07 | S23: 0 | T23: 1484.37 | U23: =S23+T23 -> 1484.37 | V23: 128819.7 | W23: =R23-U23 -> 128819.7
A24: ALI ABDULLAHI | C24: 1CT ASSISTANT | D24: 8(9) | E24: 13112.16 | G24: =E24*300% -> 39336.48 | H24: =E24*7.5% -> 983.412 | I24: 0 | J24: =E24*50% -> 6556.08 | K24: =E24*350% -> 45892.56 | L24: 0 | M24: =E24*100% -> 13112.16 | N24: 0 | O24: =E24*10% -> 1311.216 | P24: 10000 | Q24: 0 | R24: =SUM(E24:Q24) -> 130304.07 | T24: 1484.37 | U24: =S24+T24 -> 1484.37 | V24: 128819.7 | W24: =R24-U24 -> 128819.7
A25: UZODINMA EMMANUEL EZENWA | C25: INFORMATION ASST | D25: 8(9) | E25: 13112.16 | G25: =E25*300% -> 39336.48 | H25: =E25*7.5% -> 983.412 | I25: 0 | J25: =E25*50% -> 6556.08 | K25: =E25*350% -> 45892.56 | L25: 0 | M25: =E25*100% -> 13112.16 | N25: 0 | O25: =E25*10% -> 1311.216 | P25: 10000 | Q25: 0 | R25: =SUM(E25:Q25) -> 130304.07 | T25: 1484.37 | U25: =S25+T25 -> 1484.37 | V25: 128819.7 | W25: =R25-U25 -> 128819.7
A26: IBRAHIM TASSNEEM | C26: INFORMATION ASST | D26: 8(9) | E26: 13112.16 | G26: =E26*300% -> 39336.48 | H26: =E26*7.5% -> 983.412 | I26: 0 | J26: =E26*50% -> 6556.08 | K26: =E26*350% -> 45892.56 | L26: 0 | M26: =E26*100% -> 13112.16 | N26: 0 | O26: =E26*10% -> 1311.216 | P26: 10000 | Q26: 0 | R26: =SUM(E26:Q26) -> 130304.07 | T26: 1484.37 | U26: =S26+T26 -> 1484.37 | V26: 128819.7 | W26: =R26-U26 -> 128819.7
A27: GLORIA NDIDI HELG | C27: CONFIDENTIAL SECRETARY | D27: 8(9) | E27: 13112.16 | G27: =E27*300% -> 39336.48 | H27: =E27*7.5% -> 983.412 | I27: 0 | J27: =E27*50% -> 6556.08 | K27: =E27*350% -> 45892.56 | L27: 0 | M27: =E27*100% -> 13112.16 | N27: 0 | O27: =E27*10% -> 1311.216 | P27: 10000 | Q27: 0 | R27: =SUM(E27:Q27) -> 130304.07 | S27: 0 | T27: 1484.37 | U27: =S27+T27 -> 1484.37 | V27: 128819.7 | W27: =R27-U27 -> 128819.7
A28: CHRISTIAN MADUABUCHI ODO | C28: ICT ASSISTANT | D28: 8(9) | E28: 13112.16 | G28: =E28*300% -> 39336.48 | H28: =E28*7.5% -> 983.412 | J28: =E28*50% -> 6556.08 | K28: =E28*350% -> 45892.56 | M28: =E28*100% -> 13112.16 | O28: =E28*10% -> 1311.216 | P28: 10000 | R28: =SUM(E28:Q28) -> 130304.07 | T28: 1484.37 | U28: =S28+T28 -> 1484.37 | V28: 128819.7 | W28: =R28-U28 -> 128819.7
A29: TOTAL | C29: 20 | E29: =SUM(E9:E28) -> 596648.99 | F29: =SUM(F9:F28) -> 113529.57 | G29: =SUM(G9:G28) -> 1629458.2 | H29: =SUM(H9:H28) -> 80858.648 | I29: =SUM(I9:I28) -> 361099.71 | J29: =SUM(J9:J28) -> 290300.06 | K29: =SUM(K9:K28) -> 2008027.1 | L29: =SUM(L9:L28) -> 40122.19 | ... W29: =SUM(W9:W28) -> 6271693
U30: =SUM(S30:T30)*0.075 -> 0
U31: =SUM(S31:T31)*0.075 -> 0
A32: LEG. SUPPORT SEVICES | U32: =SUM(S32:T32)*0.075 -> 0
A33: PROF OKECHUKWU OKO | C33: DIR. LEG. SP SERVICES | D33: 17(9) | E33: =E71 -> 81740.02 | G33: =E33*300% -> 245220.06 | H33: =E33*7.5% -> 6130.5015 | I33: 80244.38 | J33: =E33*50% -> 40870.01 | K33: =E33*350% -> 286090.07 | L33: 0 | M33: =E33*100% -> 81740.02 | N33: 150000 | O33: =E33*10% -> 8174.002 | P33: 20000 | Q33: 0 | R33: =SUM(E33:Q33) -> 1000209.1 | T33: 52776.63 | U33: =T33+S33 -> 52776.63 | V33: 947432.43 | W33: =R33-U33 -> 947432.43
A34: DR SHUIBU DANWANKA | C34: DD LEG. SP SERVICES | D34: 16(9) | E34: =E43 -> 42653.17 | G34: =E34*300% -> 127959.51 | H34: =E34*7.5% -> 3198.9877 | I34: =I12 -> 40122.19 | J34: =E34*50% -> 21326.585 | K34: =E34*350% -> 149286.1 | L34: 0 | M34: =E34*100% -> 42653.17 | N34: 100000 | O34: =E34*10% -> 4265.317 | P34: 20000 | Q34: 0 | R34: =SUM(E34:Q34) -> 551465.02 | T34: 21618.09 | U34: =T34+S34 -> 21618.09 | V34: 529846.93 | W34: =R34-U34 -> 529846.93
A35: IBRAHIM USMAN | C35: RESEARCH FELLOW II | D35: 13(9) | E35: =E51 -> 24741.26 | G35: =E35*300% -> 74223.78 | H35: =E35*7.5% -> 1855.5945 | I35: =I57 -> 0 | J35: =E35*50% -> 12370.63 | K35: =E35*350% -> 86594.41 | L35: 0 | M35: =E35*100% -> 24741.26 | N35: 80000 | O35: =E35*10% -> 2474.126 | P35: 15000 | Q35: 0 | R35: =SUM(E35:Q35) -> 322001.06 | T35: 7709.76 | U35: =T35+S35 -> 7709.76 | V35: 314291.3 | W35: =R35-U35 -> 314291.3
A36: OFORDEME ADAOBI JULIA | C36: RESEARCH OFFICER | D36: 10(9) | E36: =E82 -> 18281.64 | G36: =E36*300% -> 54844.92 | H36: =E36*7.5% -> 1371.123 | I36: 0 | J36: =E36*50% -> 9140.82 | K36: =E36*350% -> 63985.74 | L36: 0 | M36: =E36*100% -> 18281.64 | N36: 40000 | O36: =E36*10% -> 1828.164 | P36: 10000 | Q36: 0 | R36: =SUM(E36:Q36) -> 217734.05 | T36: 3369.51 | U36: =T36+S36 -> 3369.51 | V36: 214364.54 | W36: =R36-U36 -> 214364.54
A37: IKPEAZU CHINEDU ANITA | B37: IKPEAZU CHINEDU ANITA | C37: RESEARCH OFFICER | D37: 10(9) | E37: =E82 -> 18281.64 | G37: =E37*300% -> 54844.92 | H37: =E37*7.5% -> 1371.123 | I37: 0 | J37: =E37*50% -> 9140.82 | K37: =E37*350% -> 63985.74 | L37: 0 | M37: =E37*100% -> 18281.64 | N37: 40000 | O37: =E37*10% -> 1828.164 | P37: 10000 | Q37: 0 | R37: =SUM(E37:Q37) -> 217734.05 | T37: 3369.51 | U37: =T37+S37 -> 3369.51 | V37: 214364.54 | W37: =R37-U37 -> 214364.54
A38: ONYEAKU CHUKWUKA EDMOND | C38: RESEARCH ASSISTANT | D38: 9(9) | E38: 15641.2 | G38: =E38*300% -> 46923.6 | H38: =E38*7.5% -> 1173.09 | I38: =I24 -> 0 | J38: =E38*50% -> 7820.6 | K38: =E38*350% -> 54744.2 | L38: 0 | M38: =E38*100% -> 15641.2 | N38: 40000 | O38: =E38*10% -> 1564.12 | P38: 10000 | Q38: 0 | R38: =SUM(E38:Q38) -> 193508.01 | S38: 0 | T38: 2443.88 | U38: =T38+S38 -> 2443.88 | V38: 191064.13 | W38: =R38-U38 -> 191064.13
A39: TOTAL | C39: 6 | E39: =SUM(E33:E38) -> 201338.93 | F39: =SUM(F33:F38) -> 0 | G39: =SUM(G33:G38) -> 604016.79 | H39: =SUM(H33:H38) -> 15100.42 | I39: =SUM(I33:I38) -> 120366.57 | J39: =SUM(J33:J38) -> 100669.47 | K39: =SUM(K33:K38) -> 704686.26 | L39: =SUM(L33:L38) -> 0 | ... W39: =SUM(W33:W38) -> 2411363.9
U40: =SUM(S40:T40)*0.075 -> 0
A41: RESEARCH & TRAINING | B41: RESEARCH AND TRAINING | U41: =SUM(S41:T41)*0.075 -> 0
A42: DR ADEYEMI AKEEB FAJINGBESI | C42: DIR. RES. & TRAINING | D42: 17(7) | E42: 76339.3 | G42: =E42*300% -> 229017.9 | H42: =E42*7.5% -> 5725.4475 | I42: 80244.38 | J42: =E42*50% -> 38169.65 | K42: =E42*350% -> 267187.55 | L42: 0 | M42: =E42*100% -> 76339.3 | N42: 150000 | O42: =E42*10% -> 7633.93 | P42: 20000 | Q42: 0 | R42: =SUM(E42:Q42) -> 950657.46 | T42: 52776.63 | U42: =T42+S42 -> 52776.63 | V42: 897880.83 | W42: =R42-U42 -> 897880.83
...

Sheet Enhanced welfare
A1: NATIONAL INSTITUTE FOR LEGISLATIVE STUDIES
A2: ENHANCED WELFARE INCENTIVE TO STAFF TO ALLEVIATE COST OF LIVING IN ABUJA
A4: STAFF NAME | D4: DESIGNATION | E4: SALARY | F4: AMOUNT
E5: LEVEL | F5: N
A6: DG OFFICE
A7: DR LADI HAMALAI | D7: DIRECTOR GENERAL | E7: CONSOL | F7: 2000000
A8: TOTAL | D8: 1 | F8: =SUM(F7:F7) -> 2000000
A11: LEG. SUPPORT SERVICES
A12: PROF OKECHUKWU OKO | D12: DIR. LEG. SP SERVICES | E12: 17(9) | F12: 500000
A13: TOTAL | D13: 1 | F13: =SUM(F12:F12) -> 500000
A15: RESEARCH & TRAINING
A16: DR ADEYEMI AKEEB FAJINGBESI | D16: DIR. RES. & TRAINING | E16: 17(7) | F16: 500000
A17: DR ASEMOTA O. JOSEPH | D17: RESEARCH OFFICER | E17: 14(7) | F17: 300000
A18: EHIGIAMUSOE UYI KIZITO | D18: RESEARCH ASSISTANT | E18: 9(9) | F18: 150000
A19: OGBONNAYA UFIEM MAURICE | D19: RESEARCH ASSISTANT | E19: 9(9) | F19: 150000
A20: TOTAL | D20: 4 | F20: =SUM(F16:F19) -> 1100000
A22: FINANCE & ADMIN.
A23: ABUBAKAR MUSA DANLAMI | D23: DRIVER | E23: 4(8) | F23: 80000
D24: 1 | F24: =SUM(F23:F23) -> 80000
A26: GRAND TOTAL | D26: 7 | F26: =F8+F13+F20+F24 -> 3680000

Sheet  Welfare 2
A1: ABDULLAHI HARUNA | B1: DRIVER | C1: 4(9) | D1: 80000
A2: EJEME PATRICK | B2: DRIVER | C2: 4(9) | D2: 80000
A3: OGABO OGAH USMAN | B3: DRIVER | C3: 4(9) | D3: 80000
A4: ETSU UMARU | B4: DRIVER | C4: 4(9) | D4: 80000
A5: MURTALA LAWAL | B5: DRIVER | C5: 4(9) | D5: 80000
A6: EDACHE OGA | B6: DRIVER | C6: 4(9) | D6: 80000
A7: YUGUDA S. IDRIS | B7: DRIVER | C7: 4(9) | D7: 80000
A8: GARBA ADAMU | B8: DRIVER | C8: 4(8) | D8: 80000
A9: ABDULWAHAB DAHIRU | B9: DISPATCH CLERK | C9: - | D9: 150000
A10: GIDEON B. LAMIDO | B10: DISPATCH CLERK | C10: - | D10: 150000
A11: AYUBA SULE | B11: STEWARD | C11: - | D11: 80000
A12: EWELIKWA IJEOMA NKOLIKWA | B12: DISPATCH CLERK | C12: 0 | D12: 150000
A13: HUSSAIN HAZEEM MOHAMMED | B13: DISPATCH CLERK | C13: - | D13: 150000
A14: BAKARI HUSSEINI | B14: DRIVER | C14: 0 | D14: 80000
A15: DAHIRU M. ABDULLAHI | B15: PROTOCOL OFFICER | C15: 10(7) | D15: 200000
A16: MOSHOOD M. OLARELE | B16: ADMIN OFFICER | C16: 10(7) | D16: 200000
A17: IBRAHIM A. BABANGISHIRI | B17: OFFICER INFORMATION | C17: 10(7) | D17: 200000
A18: JIBRIN USHAMA AHMED | B18: OFFICER LEGAL | C18: 10(7) | D18: 200000
A19: ABDULMALIK DAHIRU | B19: INFORMATION OFFICER | C19: 10(7) | D19: 200000
A20: GRAND TOTAL | D20: 9890000

Sheet MEMO
A1: NATIONAL INSTITUTE FOR LEGISLATIVE STUDIES
A4: INTERNAL MEMO
A6: FROM : DDF
A7: THROUGH: DFA
A8: TO: DG
A9: 23RD FEBRUARY, 2015
A11: Subject: Payroll for the month of February , 2015
A13: Find below the details of NILS Staff Payroll for the month of February, 2015:
E15: JANUARY, 2015 | G15: FEBRUARY, 2015
E16: NO OF | F16: AMOUNT | G16: NO OF | H16: AMOUNT
E17: STAFF | F17: N | G17: STAFF | H17: N
A18: 1 | B18: Director General's Office | E18: 21 | F18: ='Feb. 15'!V29 -> 6044633.8 | G18: 20 | H18: ='Feb. 15'!W29 -> 6271693
A19: 2 | B19: Leg. Support Services | E19: 6 | F19: ='Feb. 15'!V39 -> 2411363.9 | G19: 6 | H19: ='Feb. 15'!W39 -> 2411363.9
A20: 3 | B20: Research & Training | E20: 22 | F20: ='Feb. 15'!V68 -> 7553095.8 | G20: 25 | H20: ='Feb. 15'!W68 -> 8645871.8
A21: 4 | B21: Finance/ Admin & HR | E21: 38 | F21: ='Feb. 15'!V112 -> 6058176.4 | G21: 39 | H21: ='Feb. 15'!W112 -> 6161025
A22: 5 | B22: Casual Staff/NYSC | E22: 13 | F22: ='Feb. 15'!V131 -> 735000 | G22: 13 | H22: ='Feb. 15'!W131 -> 765000
A23: 6 | B23: Deployed Staff/Sabatical | E23: 11 | F23: ='Feb. 15'!V145 -> 1654277.6 | G23: 11 | H23: ='Feb. 15'!W145 -> 1823997.3
E24: =SUM(E18:E23) -> 111 | F24: =SUM(F18:F23) -> 24456547 | G24: =SUM(G18:G23) -> 114 | H24: =SUM(H18:H23) -> 26078951
A26: VARIATION IN FEBRUARY, 2015 OVER JANUARY, 2015 SALARIES
A28: NET PAY AS PER FEBRUARY, 2015 PAYROLL | H28: =H24 -> 26078951
A29: NET PAY AS PER JANUARY, 2015 PAYROLL | H29: =F24 -> 24456547
A30: NET INCREASE/ (DECREASE) IN PAY FOR FEBRUARY, 2015 | H30: =H28-H29 -> 1622403.5
A32: The net Salary Decrease is reconciled as follows:
A33: Effect of Payment of Full Salary to Dr Aderemi Adekunle Taiwo in February | G33: 113916.45
A34: Effect of payment of full Salary to Dr Ihugba Uzoma Bethel in February | G34: 134187.48
A35: Effect of payment of Full Allowance to Dr Aremu F. Ayinde as a Sabatical Staff | G35: 130360.45
A36: Effect of Completion of Salary Advance by Richard Kwalmi | G36: 113529.57
A37: Refund of Salary Advance Over-Deduction to Richard Kwalmi in Jan, 2015 | G37: 113529.57
A38: Effet of Adjustment of Moshood Olalere Salary on Promotion to AM | G38: 39359.37
A39: Effect of Allowance to Coordinate NJLA and NPSS to Dr Kanayo | G39: 50000
A40: Enrolment of Research Fellow I Dr Asemota | G40: 340154.73
A41: Payment of 28 days allowance in lieu of Hotel Accomodation to Dr Asemota | G41: 252000
A42: Effect of status upgrade of Mustapha S. atanda to Research Fellow II | G42: 101258.7
A43: Arears of Status upgrade of Mustapha S. Atanda | G43: 101258.7
A44: Payment of Pro rated Salary to Nils-Cap Driver Abubakar M. Danlami | G44: 18848.57
... A46: Enrolment of two new nysc | G46: 30000
H47: =SUM(G33:G46) -> 1622403.6
A49: The Director General is requested to consider and approve payment of N26,078,950.95 to FIRST BANK being February, 2015 Salary and N787,566.36 being February, 2015 PAYE TAX Deductions from Staff Salary.
A52: Mshelia Madu Ibrahim
A53: Deputy Director, Finance & Accounts

Sheet 17.9
A1: SALARY DETAILS OF NILS DIRECTOR RESEARCH AND TRAINING
A2: GRADE LEVEL 17 STEP 7
D3: ANNUALLY | E3: MONTHLY
A4: Basic Salary | D4: =E4*12 -> 948475.68 | E4: =sUMMARY!F3 -> 79039.64
A5: Rent Subsidy | D5: =E5*12 -> 2845427 | E5: =sUMMARY!H3 -> 237118.92
A6: Utility | D6: =E6*12 -> 71135.676 | E6: =sUMMARY!I3 -> 5927.973
A7: Domestic Staff Allowance | D7: =E7*12 -> 962932.56 | E7: =sUMMARY!J3 -> 80244.38
A8: Entertainment Allowance | D8: =E8*12 -> 474237.84 | E8: =sUMMARY!K3 -> 39519.82
A9: Furniture Allowance | D9: =E9*12 -> 3319664.9 | E9: =sUMMARY!L3 -> 276638.74
A10: Research Allowance | D10: =E10*12 -> 0
A11: Motor Fuel Allowance | D11: =E11*12 -> 948475.68 | E11: =sUMMARY!N3 -> 79039.64
A12: Leave Allowance | D12: =E12*12 -> 94847.568 | E12: =sUMMARY!O3 -> 7903.964
A13: Outfit Allowance | D13: =E13*12 -> 240000 | E13: =sUMMARY!P3 -> 20000
A14: GROSS SALARY | D14: =E14*12 -> 9905196.9 | E14: =SUM(E4:E13) -> 825433.08

Sheet 16.9
A1: SALARY DETAILS OF NILS DEPUTY DIRECTORS
A2: GRADE LEVEL 16 STEP 7
D3: ANNUALLY | E3: MONTHLY
A4: Basic Salary | D4: =E4*12 -> 511838.04 | E4: ='Feb. 15'!E10 -> 42653.17
A5: Rent Subsidy | D5: =E5*12 -> 1535514.1 | E5: ='Feb. 15'!G10 -> 127959.51
A6: Utility | D6: =E6*12 -> 38387.853 | E6: ='Feb. 15'!H10 -> 3198.9877
A7: Domestic Staff Allowance | D7: =E7*12 -> 481466.28 | E7: ='Feb. 15'!I10 -> 40122.19
A8: Entertainment Allowance | D8: =E8*12 -> 255919.02 | E8: ='Feb. 15'!J10 -> 21326.585
A9: Furniture Allowance | D9: =E9*12 -> 1791433.1 | E9: ='Feb. 15'!K10 -> 149286.1
A10: Motor Fuel Allowance | D10: =E10*12 -> 511838.04 | E10: ='Feb. 15'!M10 -> 42653.17
A11: Leave Allowance | D11: =E11*12 -> 51183.804 | E11: ='Feb. 15'!O10 -> 4265.317
A12: Outfit Allowance | D12: =E12*12 -> 240000 | E12: =sUMMARY!P3 -> 20000
A13: GROSS SALARY | D13: =E13*12 -> 5417580.3 | E13: =SUM(E4:E12) -> 451465.02

Sheet 15.9
A1: SALARY DETAILS OF NILS SENIOR RESEARCH FELLOWS
A2: GRADE LEVEL 15 STEP 9
D3: ANNUALLY | E3: MONTHLY
A4: Basic Salary | D4: =E4*12 -> 402090 | E4: ='Feb. 15'!E44 -> 33507.5
A5: Rent Subsidy | D5: =E5*12 -> 1206270 | E5: ='Feb. 15'!G44 -> 100522.5
A6: Utility | D6: =E6*12 -> 30156.72 | E6: 2513.06
A7: Domestic Staff Allowance | D7: =E7*12 -> 481466.28 | E7: 40122.19
A8: Entertainment Allowance | D8: =E8*12 -> 201045 | E8: 16753.75
A9: Furniture Allowance | D9: =E9*12 -> 1407315 | E9: 117276.25
A10: Motor Fuel Allowance | D10: =E10*12 -> 402090 | E10: 33507.5
A11: Research Allowance | D11: =E11*12 -> 1200000 | E11: 100000
A12: Leave Allowance | D12: =E12*12 -> 40209 | E12: 3350.75
A13: Outfit Allowance | D13: =E13*12 -> 240000 | E13: 20000
A14: GROSS SALARY | D14: =E14*12 -> 5610642 | E14: =SUM(E4:E13) -> 467553.5

Sheet 13.7
A1: SALARY DETAILS OF NILS RESEARCH FELLOW II
A2: GRADE LEVEL 13 STEP 8
D3: ANNUALLY | E3: MONTHLY
A4: Basic Salary | D4: =E4*12 -> 286693.44 | E4: =sUMMARY!F6 -> 23891.12
A5: Rent Subsidy | D5: =E5*12 -> 860080.32 | E5: =sUMMARY!H6 -> 71673.36
A6: Utility | D6: =E6*12 -> 21502.008 | E6: =sUMMARY!I6 -> 1791.834
A7: Domestic Staff Allowance | D7: =E7*12 -> 0 | E7: =sUMMARY!J6 -> 0
A8: Entertainment Allowance | D8: =E8*12 -> 143346.72 | E8: =sUMMARY!K6 -> 11945.56
A9: Furniture Allowance | D9: =E9*12 -> 1003427 | E9: =sUMMARY!L6 -> 83618.92
A10: Motor Fuel Allowance | D10: =E10*12 -> 286693.44 | E10: =sUMMARY!N6 -> 23891.12
A11: Research Allowance | D11: =E11*12 -> 0 | E11: 0
A12: Leave Allowance | D12: =E12*12 -> 28669.344 | E12: =sUMMARY!O6 -> 2389.112
A13: Outfit Allowance | D13: =E13*12 -> 180000 | E13: =sUMMARY!P6 -> 15000
A14: GROSS SALARY | D14: =E14*12 -> 2810412.3 | E14: =SUM(E4:E13) -> 234201.03

Sheet 12.7
D3: ANNUALLY | E3: MONTHLY
A4: Basic Salary | D4: =E4*12 -> 255527.52 | E4: =sUMMARY!F7 -> 21293.96
A5: Rent Subsidy | D5: =E5*12 -> 766582.56 | E5: =sUMMARY!H7 -> 63881.88
A6: Utility | D6: =E6*12 -> 19164.564 | E6: =sUMMARY!I7 -> 1597.047
A7: Domestic Staff Allowance | D7: =E7*12 -> 0 | E7: =sUMMARY!J6 -> 0
A8: Entertainment Allowance | D8: =E8*12 -> 127763.76 | E8: =sUMMARY!K7 -> 10646.98
A9: Furniture Allowance | D9: =E9*12 -> 894346.32 | E9: =sUMMARY!L7 -> 74528.86
A10: Motor Fuel Allowance | D10: =E10*12 -> 255527.52 | E10: =sUMMARY!N7 -> 21293.96
A11: Leave Allowance | D11: =E11*12 -> 25552.752 | E11: =sUMMARY!O7 -> 2129.396
A12: Outfit Allowance | D12: =E12*12 -> 120000 | E12: =sUMMARY!P7 -> 10000
A13: GROSS SALARY | D13: =E13*12 -> 2464465 | E13: =SUM(E4:E12) -> 205372.08

Sheet 10.7
A1: SALARY DETAILS OF NILS RESEARCH OFFICERS
A2: GRADE LEVEL 10 STEP 7
D3: ANNUALLY | E3: MONTHLY
A4: Basic Salary | D4: =E4*12 -> 207435.96 | E4: =sUMMARY!F8 -> 17286.33
A5: Rent Subsidy | D5: =E5*12 -> 622307.88 | E5: =sUMMARY!H8 -> 51858.99
A6: Utility | D6: =E6*12 -> 15557.697 | E6: =sUMMARY!I8 -> 1296.4748
A7: Domestic Staff Allowance | D7: =E7*12 -> 0 | E7: =sUMMARY!J6 -> 0
A8: Entertainment Allowance | D8: =E8*12 -> 103717.98 | E8: =sUMMARY!K8 -> 8643.165
A9: Furniture Allowance | D9: =E9*12 -> 726025.86 | E9: =sUMMARY!L8 -> 60502.155
A10: Motor Fuel Allowance | D10: =E10*12 -> 207435.96 | E10: =sUMMARY!N8 -> 17286.33
A11: Research Allowance | D11: =E11*12 -> 480000 | E11: 40000
A12: Leave Allowance | D12: =E12*12 -> 20743.596 | E12: =sUMMARY!O8 -> 1728.633
A13: Outfit Allowance | D13: =E13*12 -> 120000 | E13: =sUMMARY!P7 -> 10000
A14: GROSS SALARY | D14: =E14*12 -> 2503224.9 | E14: =SUM(E4:E13) -> 208602.08

Sheet 9.7
A1: SALARY DETAILS OF NILS RESEARCH ASSISTANTS
A2: GRADE LEVEL 9 STEP 7
D3: ANNUALLY | E3: MONTHLY
A4: Basic Salary | D4: =E4*12 -> 176833.68 | E4: =sUMMARY!F9 -> 14736.14
A5: Rent Subsidy | D5: =E5*12 -> 530501.04 | E5: =sUMMARY!H9 -> 44208.42
A6: Utility | D6: =E6*12 -> 13262.526 | E6: =sUMMARY!I9 -> 1105.2105
A7: Domestic Staff Allowance | D7: =E7*12 -> 0 | E7: =sUMMARY!J6 -> 0
A8: Entertainment Allowance | D8: =E8*12 -> 88416.84 | E8: =sUMMARY!K9 -> 7368.07
A9: Furniture Allowance | D9: =E9*12 -> 618917.88 | E9: =sUMMARY!L9 -> 51576.49
A10: Motor Fuel Allowance | D10: =E10*12 -> 176833.68 | E10: =sUMMARY!N9 -> 14736.14
A11: Research Assistants | D11: =E11*12 -> 480000 | E11: 40000
A12: Leave Allowance | D12: =E12*12 -> 17683.368 | E12: =sUMMARY!O9 -> 1473.614
A13: Outfit Allowance | D13: =E13*12 -> 120000 | E13: =sUMMARY!P7 -> 10000
A14: GROSS SALARY | D14: =E14*12 -> 2222449 | E14: =SUM(E4:E13) -> 185204.08

Sheet 8.7
A1: SALARY OF SECRTARY ON SCALE 8 STEP 7
D3: ANNUALLY | E3: MONTHLY
A4: Basic Salary | D4: =E4*12 -> 182264.04 | E4: ='Feb. 15'!E67 -> 15188.67
A5: Rent Subsidy | D5: =E5*12 -> #REF! | E5: ='Feb. 15'!#REF! -> #REF!
A6: Utility | D6: =E6*12 -> #REF! | E6: ='Feb. 15'!#REF! -> #REF!
A7: Entertainment Allowance | D7: =E7*12 -> 78672.96 | E7: ='Feb. 15'!J85 -> 6556.08
A8: Furniture Allowance | D8: =E8*12 -> #REF! | E8: ='Feb. 15'!#REF! -> #REF!
A9: Motor Fuel Allowance | D9: =E9*12 -> 157345.92 | E9: ='Feb. 15'!M85 -> 13112.16
A10: Leave Allowance | D10: =E10*12 -> #REF! | E10: ='Feb. 15'!#REF! -> #REF!
A11: Outfit Allowance | D11: =E11*12 -> 120000 | E11: ='Feb. 15'!P85 -> 10000
A12: GROSS SALARY | D12: =E12*12 -> #REF! | E12: =SUM(E4:E11) -> #REF!

Sheet sUMMARY
F1: BASIC | G1: 28 DAYS ALCE | M1: PERSONAL | N1: MOTOR/ | O1: RESEARCH | P1: LEAVE | Q1: OUT FIT | R1: LEGISLATIVE | S1: GROSS | U1: MAR.2012 | V1: FEB. 2012
F2: SALARY | G2: IN LIEU | H2: RENT | I2: UTILITY | J2: DOMESTIC | K2: ENTERT. | L2: FURNIT. | M2: ASSISTANT | N2: FUEL | O2: ALLOWANCE | P2: ALLCE | Q2: ALLCE | R2: DUTY ALLCE | S2: SALARY | T2: PAYE
A3: DIRECTOR | E3: 17/8 | F3: 79039.64 | H3: =F3*300% -> 237118.92 | I3: =F3*7.5% -> 5927.973 | J3: 80244.38 | K3: =F3*50% -> 39519.82 | L3: =F3*350% -> 276638.74 | M3: 0 | N3: =F3*100% -> 79039.64 | O3: =F3*10% -> 7903.964 | P3: 20000 | Q3: 0 | R3: =SUM(F3:Q3) -> 825433.08
A4: DEPUTY DIRECTOR | E4: 16/8 | F4: 36784.71 | H4: =F4*300% -> 110354.13 | I4: =F4*7.5% -> 2758.8532 | J4: 80244.38 | K4: =F4*50% -> 18392.355 | L4: =F4*350% -> 128746.49 | N4: =F4*100% -> 36784.71 | O4: =F4*10% -> 3678.471 | P4: 20000 | Q4: 0 | R4: =SUM(F4:Q4) -> 437744.09
A5: RESEARCH FELLOW I | E5: 14(7) | F5: 24975.81 | G5: 0 | H5: =F5*300% -> 74927.43 | I5: =F5*7.5% -> 1873.1858 | J5: 0 | K5: =F5*50% -> 12487.905 | L5: =F5*350% -> 87415.335 | M5: 0 | N5: =F5*100% -> 24975.81 | O5: 100000 | P5: =F5*10% -> 2497.581 | Q5: 20000 | R5: 0 | S5: =SUM(F5:R5) -> 349153.06 | T5: 0 | U5: =S5-T5 -> 349153.06 | V5: 344720.6
A6: RESEARCH FELLOW II | E6: 13/7 | F6: 23891.12 | H6: =F6*300% -> 71673.36 | I6: =F6*7.5% -> 1791.834 | J6: 0 | K6: =F6*50% -> 11945.56 | L6: =F6*350% -> 83618.92 | M6: 0 | N6: =F6*100% -> 23891.12 | O6: =F6*10% -> 2389.112 | P6: 15000 | Q6: 0 | R6: =SUM(F6:Q6) -> 234201.03
A7: RESEARCH FELLOW | E7: 12/7 | F7: 21293.96 | H7: =F7*300% -> 63881.88 | I7: =F7*7.5% -> 1597.047 | J7: 0 | K7: =F7*50% -> 10646.98 | L7: =F7*350% -> 74528.86 | M7: 0 | N7: =F7*100% -> 21293.96 | O7: =F7*10% -> 2129.396 | P7: 10000 | Q7: 0 | R7: =SUM(F7:Q7) -> 205372.08
A8: RESEARCH OFFICER | E8: 10/7 | F8: 17286.33 | H8: =F8*300% -> 51858.99 | I8: =F8*7.5% -> 1296.4748 | J8: 0 | K8: =F8*50% -> 8643.165 | L8: =F8*350% -> 60502.155 | M8: 0 | N8: =F8*100% -> 17286.33 | O8: =F8*10% -> 1728.633 | P8: 10000 | Q8: 0 | R8: =SUM(F8:Q8) -> 168602.08
A9: RESEARCH ASSISTANTS | E9: 9/7 | F9: 14736.14 | H9: =F9*300% -> 44208.42 | I9: =F9*7.5% -> 1105.2105 | J9: 0 | K9: =F9*50% -> 7368.07 | L9: =F9*350% -> 51576.49 | M9: 0 | N9: =F9*100% -> 14736.14 | O9: =F9*10% -> 1473.614 | P9: 10000 | Q9: 0 | R9: =SUM(F9:Q9) -> 145204.08
E10: 8/7 | F10: 12351.94 | H10: =F10*300% -> 37055.82 | I10: =F10*7.5% -> 926.3955 | J10: 0 | K10: =F10*50% -> 6175.97 | L10: =F10*350% -> 43231.79 | M10: 0 | N10: =F10*100% -> 12351.94 | O10: =F10*10% -> 1235.194 | P10: 10000 | Q10: 0 | R10: =SUM(F10:Q10) -> 123329.05

Sheet 14.7
A1: SALARY DETAILS OF NILS CHIEF LIBRARIAN
A2: GRADE LEVEL 14 STEP 7
D3: ANNUALLY | E3: MONTHLY
A4: Basic Salary | D4: =E4*12 -> 299709.72 | E4: =sUMMARY!F5 -> 24975.81
A5: Rent Subsidy | D5: =E5*12 -> 899129.16 | E5: =sUMMARY!H5 -> 74927.43
A6: Utility | D6: =E6*12 -> 22478.229 | E6: =sUMMARY!I5 -> 1873.1858
A7: Domestic Staff Allowance | D7: =E7*12 -> 0 | E7: =sUMMARY!J6 -> 0
A8: Entertainment Allowance | D8: =E8*12 -> 149854.86 | E8: =sUMMARY!K5 -> 12487.905
A9: Furniture Allowance | D9: =E9*12 -> 1048984 | E9: =sUMMARY!L5 -> 87415.335
A10: Motor Fuel Allowance | D10: =E10*12 -> 299709.72 | E10: =sUMMARY!N5 -> 24975.81
A11: Research Allowance | D11: =E11*12 -> 0 | E11: 0
A12: Leave Allowance | D12: =E12*12 -> 29970.972 | E12: =sUMMARY!P5 -> 2497.581
A13: Outfit Allowance | D13: =E13*12 -> 240000 | E13: =sUMMARY!Q5 -> 20000
A14: GROSS SALARY | D14: =E14*12 -> 2989836.7 | E14: =SUM(E4:E13) -> 249153.06

Sheet Sheet2
A1: LIST OF STAFF THAT HAVE ASSUMED DUTY
A2: STAFF NAME
D3: DESIGNATION | E3: SALARY
E4: LEVEL
A5: DG OFFICE
A6: DR LADI HAMALAI | D6: DG | E6: CONSOL
A7: PROF. OFFORNZE AMUCHEAZI | D7: LEGAL ADVISER | E7: 16(7)
A8: MOHAMMED ISIAKA YAKUBU | D8: SPECIAL ASSISTANT | E8: 16(7)
A9: RICHARD KWALMI | D9: DSM | E9: 15(7)
A10: ABDULSALAM MUSTAFA | D10: ICT OFFICER | E10: 10(10)
A11: ALI ABDULLAHI | D11: 1CT ASSISTANT | E11: 8(2)
A13: LEG. SUPPORT SEVICES
A14: DR SHUIBU DANWANKA | D14: DD | E14: 16(7)
A16: RESEARCH & TRAINING
A17: DR ASIMIYU G. ABIOLA | D17: DD RESEARCH | E17: 16(7)
A18: SOLOMON A. BENJAMIN | D18: DD TRAINING | E18: 16(7)
A19: DR PATTERSON EKEOCHA | D19: SRF | E19: 15(9)
A21: FINANCE & ADMIN.
A22: DR KABIR AHMED | D22: DFA | E22: 17(7)
A23: IBRAHIM M. MSHELIA | D23: DD F&A | E23: 16(7)
A24: AMINU BELLO DUKKU | D24: DD ADMIN/HR | E24: 16(7)
A25: RAHILA AMOS | D25: OFFICER ACCTS | E25: 10(11)
A26: HUSSEIN MUSA AGYE | D26: PROTOCOL OFFICER | E26: 10(&)
A27: USMAN WAZIRI | D27: SEC. FINANCE | E27: 8(9)
A28: SALAMATU YAKUBU | D28: SECRETARY | E28: 8(9)
A29: IDAHOSA JANE CECILIA | D29: SECRETARY | E29: 8/(9)
A30: ESTHER WAMINAJE | D30: SECRETARY | E30: 8(9)
A31: ANTHONY EDET | D31: RECEPTIONIST | E31: 8(2)
A32: OLATUNJI OYEDELE YUSUF | D32: DRIVER | E32: 4(10)
A33: TASIU MOHAMMED | D33: DRIVER | E33: 4(10)
... A41: ABDULLAHI HARUNA | D41: DRIVER | E41: 3(8)
A42: ABDULWAHAB DAHIRU | D42: DISPATCH CLERK
A43: GIDEON B. LAMIDO | D43: DISPATCH CLERK
A44: JOHN JAMBU ASIGAN | D44: STEWARD
A45: AYUBA SULE | D45: STEWARD
A46: EWELIKWA IJEOMA NKOLIKWA | D46: STEWARD

Sheet 15.7
A1: SALARY DETAILS OF NILS LIBRARIAN
A2: GRADE LEVEL 15 STEP 7
B3: ANNUALLY | C3: MONTHLY
A4: Basic Salary | B4: =C4*12 -> 475947 | C4: 39662.25
A5: Rent Subsidy | B5: =C5*12 -> 1427841 | C5: 118986.75
A6: Utility | B6: =C6*12 -> 35696.04 | C6: 2974.67
A7: Domestic Staff Allowance | B7: =C7*12 -> 481466.28 | C7: ='Feb. 15'!I10 -> 40122.19
A8: Entertainment Allowance | B8: =C8*12 -> 237973.56 | C8: 19831.13
A9: Furniture Allowance | B9: =C9*12 -> 1665814.6 | C9: 138817.88
A10: Motor Fuel Allowance | B10: =C10*12 -> 475947 | C10: 39662.25
A11: Research Allowance | B11: =C11*12 -> 0 | C11: 0
A12: Leave Allowance | B12: =C12*12 -> 47594.76 | C12: 3966.23
A13: Outfit Allowance | B13: =C13*12 -> 240000 | C13: ='Feb. 15'!P10 -> 20000
A14: GROSS SALARY | B14: =SUM(B4:B13) -> 5088280.2 | C14: =SUM(C4:C13) -> 424023.35

Sheet 5.7
A1: SALARY DETAILS OF NILS SENIOR MOTOR DRIVER-MECHANIC
A2: GRADE LEVEL 5 STEP 7
D3: ANNUALLY | E3: MONTHLY
A4: Basic Salary | D4: =E4*12 -> #REF! | E4: ='Feb. 15'!#REF! -> #REF!
A5: Rent Subsidy | D5: =E5*12 -> #REF! | E5: ='Feb. 15'!#REF! -> #REF!
A6: Utility | D6: =E6*12 -> #REF! | E6: ='Feb. 15'!#REF! -> #REF!
A7: Domestic Staff Allowance | D7: =E7*12 -> 0 | E7: =sUMMARY!J6 -> 0
A8: Entertainment Allowance | D8: =E8*12 -> #REF! | E8: ='Feb. 15'!#REF! -> #REF!
A9: Furniture Allowance | D9: =E9*12 -> #REF! | E9: ='Feb. 15'!#REF! -> #REF!
A10: Motor Fuel Allowance | D10: =E10*12 -> #REF! | E10: ='Feb. 15'!#REF! -> #REF!
A11: Research Allowance | D11: =E11*12 -> 0 | E11: 0
A12: Leave Allowance | D12: =E12*12 -> #REF! | E12: ='Feb. 15'!#REF! -> #REF!
A13: Outfit Allowance | D13: =E13*12 -> #REF! | E13: ='Feb. 15'!#REF! -> #REF!
A14: GROSS SALARY | D14: =E14*12 -> #REF! | E14: =SUM(E4:E13) -> #REF!

Sheet Noninal roll
A2: NOMINAL ROLL AND 2012 PERSONEL COST ESTIMATION
A3: S/NO | B3: DESIGNATION | C3: SALARY LEVEL | D3: NUMBER | E3: ANNUAL SALARY | F3: TOTAL
A5: 1 | B5: DIRECTOR GENERAL | C5: CONS. | D5: 1 | E5: =1580439.5*12 -> 18965274 | F5: =E5*D5 -> 18965274
A6: 2 | B6: DIRECTORS | C6: 17(7) | D6: 4 | E6: 9607889.5 | F6: =E6*D6 -> 38431558
A7: 3 | B7: LEGAL ADVISER | C7: 16(7) | D7: 1 | E7: =424023.33*12 -> 5088280 | F7: =E7*D7 -> 5088280
A8: 4 | B8: SPECIAL ASSISTANT | C8: 16(7) | D8: 2 | E8: =424023.33*12 -> 5088280 | F8: =E8*D8 -> 10176560
A9: 5 | B9: DEUTY DIRECTORS | C9: 16(7) | D9: 10 | E9: 5088280 | F9: =E9*D9 -> 50882800
A10: 6 | B10: SENIOR RESEARCH FELLOWS | C10: 16(7) | D10: 10 | E10: 4136647.2 | F10: =E10*D10 -> 41366472
A11: 7 | B11: MANAGERS | C11: 15(7) | D11: 12 | E11: =344720.6*12 -> 4136647.2 | F11: =E11*D11 -> 49639766
A12: 8 | B12: RESEARCH FELLOW I | C12: 14(7) | D12: 10 | E12: =249153.06*12 -> 2989836.7 | F12: =E12*D12 -> 29898367
A13: 9 | B13: ASSISTANT MANAGERS | C13: 13(7) | D13: 8 | E13: 2810412.4 | F13: =E13*D13 -> 22483299
A14: 10 | B14: OFFICERS | C14: 10(7) | D14: 15 | E14: =168602.08*12 -> 2023225 | F14: =E14*D14 -> 30348374
A15: 11 | B15: OFFICE ASSISTANTS | C15: 8(7) | D15: 20 | E15: =123329.05*12 -> 1479948.6 | F15: =E15*D15 -> 29598972
A16: 12 | B16: SECRETARIES | C16: 8(9) | D16: 15 | E16: =130304.44*12 -> 1563653.3 | F16: =E16*D16 -> 23454799
A17: 13 | B17: DRIVERS | C17: 4(10) | D17: 20 | E17: =46676.06*12 -> 560112.72 | F17: =E17*D17 -> 11202254
D18: =SUM(D9:D17) -> 100 | F18: =SUM(F5:F17) -> 3.6153678e+08

Sheet Welfare List Mgt Staff
A2: STAFF NAME | D2: DESIGNATION | E2: GRADE | F2: AMOUNT | G2: SIGNATURE
F3: 300000
A4: PROF OKECHUKWU OKO | D4: DIR. LEG. SP SERVICES | E4: 17(7) | F4: 150000
A5: DR BADAYI M. SANI | D5: DIR. RES. & TRAINING | E5: 17(7) | F5: 150000
A6: DR KABIR AHMED | D6: DIR. FINANCE & ADMIN | E6: 17(7) | F6: 150000
A7: PROF. OFFORNZE AMUCHEAZI | D7: LEGAL ADVISER | E7: 16(7) | F7: 100000
A8: MOHAMMED ISIAKA YAKUBU | D8: HEAD PUBLICATION | E8: 16(7) | F8: 100000
A9: DR MOBOLAJI HAKEEM | D9: SPECIAL ASSISTANT | E9: 16(7) | F9: 100000
A10: DR SHUIBU DANWANKA | D10: DD LEG. SP SERVICES | E10: 16(7) | F10: 100000
A11: DR ASIMIYU G. ABIOLA | D11: DD RESEARCH | E11: 16(7) | F11: 100000
A12: IBRAHIM M. MSHELIA | D12: DD F&A | E12: 16(7) | F12: 100000
A13: AMINU BELLO DUKKU | D13: DD ADMIN/HR | E13: 16(7) | F13: 100000
A14: RICHARD KWALMI | D14: MICT | E14: 15(7) | F14: 80000
A15: ADAMU ISA ABBA | D15: INFO. MANAGER | E15: 15(7) | F15: 80000
... A22: EDET B. AKPAKPAN | D22: SABATICAL | E22: Sab. | F22: 80000
A23: TOTAL | F23: =SUM(F3:F22) -> 2170000

Sheet Welfare Support Staff
A1: S/N | B1: NAMES | E1: DESIGNATION | F1: GRADE | G1: AMOUNT | H1: SIGNATURE
A2: 1 | B2: AKINSANMI ADEJOKE OLUKEMI | E2: AM INFORMATION | F2: 13(7) | G2: 20000
A3: 2 | B3: FAROUK U. M ILLO | E3: PA DG | F3: 13(7) | G3: 20000
A4: 3 | B4: UMOLU ADAEZE OBIAMAKA | E4: INFO OFFICER | F4: 10(7) | G4: 20000
A5: 4 | B5: TONDO IORWUESE EDWARD | E5: OFFICER INT AUDIT | F5: 10(7) | G5: 20000
A6: 5 | B6: BEDARI HARI | E6: LEGAL OFFICER | F6: 10(7) | G6: 20000
A7: 6 | B7: NGARA CHRISTOPHER OCHANJA | C7: NGARA CHRISTOPHER OCHANJA | E7: OFFICER, SPECIAL DUTIES | F7: 10(7) | G7: 20000
A8: 7 | B8: JOY HARUNA MAKERI | E8: PA DG | F8: 10(7) | G8: 20000
A9: 8 | B9: BASHIRU ABBA WALI | E9: ASSIT. INT. AUDIT | F9: 8(7) | G9: 20000
A10: 9 | B10: ALI ABDULLAHI | E10: 1CT ASSISTANT | F10: 8(7) | G10: 20000
A11: 10 | B11: UZODINMA EMMANUEL EZENWA | E11: INFORMATION ASST | F11: 8(7) | G11: 20000
A12: 11 | B12: IBRAHIM TASSNEEM | E12: INFORMATION ASST | F12: 8(7) | G12: 20000
A13: 12 | B13: GLORIA NDIDI HELG | E13: CONFIDENTIAL SECRETARY | F13: 8(7) | G13: 20000
A14: 13 | B14: CHRISTIAN MADUABUCHI ODO | E14: ICT ASSISTANT | F14: 8(7) | G14: 20000
A15: 14 | B15: IBRAHIM USMAN | E15: RESEARCH FELLOW II | F15: 13(7) | G15: 20000
A16: 15 | B16: OFORDEME ADAOBI JULIA | E16: RESEARCH OFFICER | F16: 10(7) | G16: 20000
A17: 16 | B17: IKPEAZU CHINEDU ANITA | E17: RESEARCH OFFICER | F17: 10(7) | G17: 20000
A18: 17 | B18: ONYEAKU CHUKWUKA EDMOND | E18: RESEARCH ASSISTANT | F18: 9(7) | G18: 20000
A19: 18 | B19: DR ANUMUDU CHARLES NNAMDI | E19: SRF I SOCIAL SECTOR | F19: 14(7) | G19: 20000
... A77: 76 | B77: AYUBA SULE | E77: STEWARD | F77: - | G77: 10000
A78: 77 | B78: EWELIKWA IJEOMA NKOLIKWA | E78: DISPATCH CLERK | F78: 0 | G78: 10000
A79: 78 | B79: JUMMAI AJIYA | E79: STEWARD | F79: 0 | G79: 10000
A80: 79 | B80: HUSSAIN HAZEEM MOHAMMED | E80: DISPATCH CLERK | F80: - | G80: 10000
A81: 80 | B81: ABOMAN INNOCENT | E81: CLEANER | G81: 10000
A82: 81 | B82: AKEUSOLA SEGUN | E82: CLEANER | G82: 10000
A83: 82 | B83: EDACHE OGA | E83: DRIVER | G83: 10000
A84: 83 | B84: ONCHE ENOKELA ONCHE | E84: STEWARD | G84: 10000
G85: =SUM(G2:G84) -> 1390000

Sheet Welfare Deployed Staff
A1: EID EL KABIR TRANSPORT ALLOWANCE TO NILS DEPLOYED STAFF
A2: S/N | C2: DESIGNATION | D2: GRADE | E2: AMOUNT | F2: SIGNATURE
A3: 1 | B3: ARC OJO M.O | C3: DD & HEAD OF BUILDING | D3: 16(7) | E3: 100000
A4: 2 | B4: AMINCI THOMAS | C4: MANAGER LIB. & DOCUM. | D4: 15(7) | E4: 80000
A5: 3 | B5: AMINU F. HAMAJODA | C5: MANAGER INFORMATION | D5: 15(7) | E5: 80000
A6: 4 | B6: DAHIRU M. ABDULLAHI | C6: PROTOCOL OFFICER | D6: 10(7) | E6: 20000
A7: 5 | B7: MOSHOOD M. OLARELE | C7: ADMIN OFFICER | D7: 10(7) | E7: 20000
A8: 6 | B8: IBRAHIM A. BABANGISHIRI | C8: OFFICER INFORMATION | D8: 10(7) | E8: 20000
A9: 7 | B9: JIBRIN USHAMA AHMED | C9: OFFICER LEGAL | D9: 10(7) | E9: 20000
A10: 8 | B10: ENGR. EBI THOMPSON | C10: ASSISTANT CHIEF ENGINEER | D10: 13(7) | E10: 20000
A11: 9 | B11: ADEOGUN MORUF | C11: PRINCIPAL Q.S | D11: 10(7) | E11: 20000
B12: TOTAL | E12: =SUM(E3:E11) -> 380000

Sheet Sheet1
B1: 2013 END OF YEAR STAFF WELFARE TO ASSIST WITH TRANSPORTATION AND LOGISTICS.
E3: DESIGNATION | F3: SALARY | G3: BASIC
F4: LEVEL | G4: SALARY
B5: DG OFFICE | G5: N
A6: 1 | B6: DR LADI HAMALAI | E6: DIRECTOR GENERAL | F6: CONSOL | G6: 400000
A7: 2 | B7: PROF. OFFORNZE AMUCHEAZI | E7: LEGAL ADVISER | F7: 16(7) | G7: 200000
A8: 3 | B8: MOHAMMED ISIAKA YAKUBU | E8: HEAD PUBLICATION | F8: 16(7) | G8: 200000
A9: 4 | B9: DR MOBOLAJI HAKEEM | E9: SPECIAL ASSISTANT | F9: 16(70 | G9: 200000
A10: 5 | B10: RICHARD KWALMI | E10: MICT | F10: 15(7) | G10: 100000
A11: 6 | B11: ADAMU ISA ABBA | E11: INFO. MANAGER | F11: 15(7) | G11: 100000
A12: 7 | B12: NWOSU MATHEW EZE | E12: MANAGER INT. AUDIT | F12: 15(7) | G12: 100000
A13: 8 | B13: PRISCILLA CHUKWU | E13: MANAGER PROCUREMENT | F13: 15(7) | G13: 100000
A14: 9 | B14: DR ANAH O. PAMELA | E14: SRF | F14: 15((7) | G14: 100000
A15: 10 | B15: AKINSANMI ADEJOKE OLUKEMI | E15: AM INFORMATION | F15: 13(7) | G15: 80000
A16: 11 | B16: FAROUK U. M ILLO | E16: PA DG | F16: 13(7) | G16: 80000
A17: 12 | B17: UMOLU ADAEZE OBIAMAKA | E17: INFO OFFICER | F17: 10(7) | G17: 50000
... A19: 14 | B19: BEDARI HARI | E19: LEGAL OFFICER | F19: 10(7) | G19: 50000
A20: 15 | B20: NGARA CHRISTOPHER OCHANJA | C20: NGARA CHRISTOPHER OCHANJA | E20: OFFICER, SPECIAL DUTIES | F20: 10(7) | G20: 50000
A21: 16 | B21: JOY HARUNA MAKERI | C21: JOY HARUNA MAKERI | E21: PA DG | F21: 10(7) | G21: 50000
A22: 17 | B22: DONALD E. MKPANAM | E22: IT OFFICER | F22: 10(7) | G22: 50000
A23: 18 | B23: BASHIRU ABBA WALI | E23: ASSIT. INT. AUDIT | F23: 8(7) | G23: 50000
A24: 19 | B24: ALI ABDULLAHI | E24: 1CT ASSISTANT | F24: 8(7) | G24: 50000
A25: 20 | B25: UZODINMA EMMANUEL EZENWA | E25: INFORMATION ASST | F25: 8(7) | G25: 50000
A26: 21 | B26: IBRAHIM TASSNEEM | E26: INFORMATION ASST | F26: 8(7) | G26: 50000
A27: 22 | B27: GLORIA NDIDI HELG | E27: CONFIDENTIAL SECRETARY | F27: 8(7) | G27: 50000
A28: 23 | B28: CHRISTIAN MADUABUCHI ODO | E28: ICT ASSISTANT | F28: 8(7) | G28: 50000
B29: TOTAL | E29: 23 | G29: =SUM(G6:G28) -> 2260000
B30: LEG. SUPPORT SEVICES
A31: 1 | B31: PROF OKECHUKWU OKO | E31: DIR. LEG. SP SERVICES | F31: 17(7) | G31: 300000
A32: 2 | B32: DR SHUIBU DANWANKA | E32: DD LEG. SP SERVICES | F32: 16(7) | G32: 200000
A33: 3 | B33: IBRAHIM USMAN | E33: RESEARCH FELLOW II | F33: 13(7) | G33: 80000
A34: 4 | B34: OFORDEME ADAOBI JULIA | E34: RESEARCH OFFICER | F34: 10(7) | G34: 50000
A35: 5 | B35: IKPEAZU CHINEDU ANITA | C35: IKPEAZU CHINEDU ANITA | E35: RESEARCH OFFICER | F35: 10(7) | G35: 50000
A36: 6 | B36: ONYEAKU CHUKWUKA EDMOND | E36: RESEARCH ASSISTANT | F36: 9(7) | G36: 50000
B37: TOTAL | E37: 6 | G37: =SUM(G31:G36) -> 730000
A39: 1 | B39: DR BADAYI M. SANI | E39: DIR. RES. & TRAINING | F39: 17(7) | G39: 300000
A40: 2 | B40: DR ASIMIYU G. ABIOLA | E40: DD RESEARCH | F40: 16(7) | G40: 200000
A41: 3 | B41: DR KANAYO OGUJIUBA | E41: SRF SOCIAL SECTOR | F41: 15(9) | G41: 100000
A42: 4 | B42: DR ANUMUDU CHARLES NNAMDI | E42: SRF I SOCIAL SECTOR | F42: 14(7) | G42: 80000
A43: 5 | B43: CATHERINE E. IKOKOH | E43: RESEARCH FELLOW1 DOCU | F43: 14(7) | G43: 80000
...

Sheet Sheet3
