Workbook

Sheet FEB NEW PERM
A1: NATIONAL INSTITUTE FOR LEGISLATIVE AND DEMOCRATIC STUDIES
A2: STAFF PAYROLL FOR THE MONTH OF FEBRUARY, 2026 (NEW PERM STAFF)
E3: ='[1]FEB 08'!E11/'[1]FEB 08'!M11 -> #REF!
B4: STAFF NAME | C4: DESIGNATION | D4: GRADE LEVEL | E4: BASIC SALARY | F4: ALLCE/ AREARS | G4: ALLOWANCE | H4: ALLOWANCE | I4: DUTY ALLCE | J4: GROSS SALARY | K4: AUCTION | L4: COOP 1 CONTR/SPEC SAVINGS | M4: COOP.1 LOAN RECOVERY | N4: COOP 2 CONTR/SPEC SAVINGS | O4: NHF DED. | P4: PAYE | Q4: EMPLOYEE PENSIONS | R4: TOTAL DEDUCTION | S4: JANUARY, 2026 | T4: FEBRUARY, 2026
E5: N | F5: N | G5: N | H5: N | I5: N | J5: N | K5: N | L5: N | M5: N | N5: N | O5: N | P5: N | Q5: N | R5: N | S5: N | T5: N
A6: S/N | B6: DG'S OFFICE
A7: 1 | B7: ATAKPO EMMANUEL OKON | C7: ASSISTANT DIRECTOR | D7: 15(7) | E7: 700713.92 | H7: =80000 -> 80000 | J7: =E7+F7+G7+H7+I7 -> 780713.92 | L7: 152000 | P7: 112938.22 | Q7: =0.08*E7 -> 56057.113 | R7: =Q7+P7+O7+M7+N7+L7+K7 -> 320995.34 | S7: 1279494.3 | T7: =J7-R7 -> 459718.58
A8: 2 | B8: BAFFA ALASAN | C8: CHIEF LEGAL OFFICCER | D8: 14(7) | E8: ='[2] FGN 2024 MGT Monthly'!$H$42+'[2]Peculiar Allowance'!$H$42 -> 526673.58 | H8: 70000 | J8: =E8+F8+G8+H8+I8 -> 596673.58 | P8: 82317.145 | Q8: =0.08*E8 -> 42133.887 | R8: =Q8+P8+O8+M8+N8+L8+K8 -> 124451.03 | S8: 986578.99 | T8: =J8-R8 -> 472222.55
A9: 3 | B9: OCHUNU LYNDA IHEKANMANANDU | C9: PRINCIPAL LEGAL OFFICER | D9: 12(7) | E9: ='[2]Peculiar Allowance'!$H$40+'[2] FGN 2024 MGT Monthly'!$H$40 -> 441159 | H9: 60000 | J9: =E9+F9+G9+H9+I9 -> 501159 | P9: 66355.93 | Q9: =0.08*E9 -> 35292.72 | R9: =Q9+P9+O9+M9+N9+L9+K9 -> 101648.65 | S9: 834313.42 | T9: =J9-R9 -> 399510.35
A10: 4 | B10: DORCAS MARK ESSET | C10: PRINCIPAL RESEARCH OFFICER | D10: 12(7) | E10: ='[2]Peculiar Allowance'!$H$40+'[2] FGN 2024 MGT Monthly'!$H$40 -> 441159 | G10: 110000 | J10: =E10+F10+G10+H10+I10 -> 551159 | P10: 73555.93 | Q10: =0.08*E10 -> 35292.72 | R10: =Q10+P10+O10+M10+N10+L10+K10 -> 108848.65 | S10: 909913.42 | T10: =J10-R10 -> 442310.35
A11: 5 | B11: AYOPEMI AYOBAMI ANUOLUWAPO | C11: SENIOR LEGAL OFFICER | D11: 10(7) | E11: 372145.33 | H11: =60000 -> 60000 | J11: =E11+F11+G11+H11+I11 -> 432145.33 | P11: 54927.267 | Q11: =0.08*E11 -> 29771.627 | R11: =Q11+P11+O11+M11+N11+L11+K11 -> 84698.894 | S11: 724664.51 | T11: =J11-R11 -> 347446.44
A12: 6 | B12: PRINCESS BARBARA AGOYE | C12: SENIORGI OFFICER | D12: 10(7) | E12: 372145.33 | H12: =60000 -> 60000 | J12: =E12+F12+G12+H12+I12 -> 432145.33 | P12: 54927.267 | Q12: =0.08*E12 -> 29771.627 | R12: =Q12+P12+O12+M12+N12+L12+K12 -> 84698.894 | S12: 724664.51 | T12: =J12-R12 -> 347446.44
A13: 7 | B13: SANUSI MOHAMMED MATO | C13: SENIOR INF &COMM OFFICER | D13: 10(7) | E13: 372145.33 | H13: =60000 -> 60000 | J13: =E13+F13+G13+H13+I13 -> 432145.33 | P13: 54927.267 | Q13: =0.08*E13 -> 29771.627 | R13: =Q13+P13+O13+M13+N13+L13+K13 -> 84698.894 | S13: 724664.51 | T13: =J13-R13 -> 347446.44
B14: TOTAL | C14: 7 | E14: =SUM(E7:E13) -> 3226141.5 | F14: =SUM(F7:F13) -> 0 | G14: =SUM(G7:G13) -> 110000 | H14: =SUM(H7:H13) -> 390000 | I14: =SUM(I7:I13) -> 0 | J14: =SUM(J7:J13) -> 3726141.5 | K14: =SUM(K7:K13) -> 0 | L14: =SUM(L7:L13) -> 152000 | ... R14: =SUM(R7:R13) -> 910040.35 | S14: 6184293.6 | T14: =SUM(T7:T13) -> 2816101.1
B16: LEG. SUPPORT SEVICES
A17: 1 | B17: IBRAHIM BELLO IBRAHIM | C17: PRINC. RESEARCH OFFICER | D17: 12(7) | E17: ='[2]Peculiar Allowance'!$H$40+'[2] FGN 2024 MGT Monthly'!$H$40 -> 441159 | G17: =110000 -> 110000 | J17: =E17+F17+G17+H17+I17 -> 551159 | P17: 75355.93 | Q17: =0.08*E17 -> 35292.72 | R17: =Q17+P17+O17+M17+N17+L17+K17 -> 110648.65 | S17: 916313.42 | T17: =J17-R17 -> 440510.35
A18: 2 | B18: ENI GEMOGONO-EVAL DAVID | C18: PRINC. RESEARCH OFFICER | D18: 12(7) | E18: ='[2]Peculiar Allowance'!$H$40+'[2] FGN 2024 MGT Monthly'!$H$40 -> 441159 | G18: =110000 -> 110000 | J18: =E18+F18+G18+H18+I18 -> 551159 | L18: 32000 | P18: 75355.93 | Q18: =0.08*E18 -> 35292.72 | R18: =Q18+P18+O18+M18+N18+L18+K18 -> 142648.65 | S18: 916313.42 | T18: =J18-R18 -> 408510.35
A19: 3 | B19: AKEBONG SAMUEL ESSIEN | C19: PRINC. RESEARCH OFFICER | D19: 12(7) | E19: ='[2]Peculiar Allowance'!$H$40+'[2] FGN 2024 MGT Monthly'!$H$40 -> 441159 | G19: =110000 -> 110000 | J19: =E19+F19+G19+H19+I19 -> 551159 | L19: 52000 | P19: 75355.93 | Q19: =0.08*E19 -> 35292.72 | R19: =Q19+P19+O19+M19+N19+L19+K19 -> 162648.65 | S19: 916313.42 | T19: =J19-R19 -> 388510.35
A20: 4 | B20: UDUAKOBONG JOHN OBOT | C20: SENIOR RESEARCH OFFICER | D20: 10(7) | E20: 372145.33 | F20: 1650 | G20: =100000 -> 100000 | J20: =E20+F20+G20+H20+I20 -> 473795.33 | P20: 60477.267 | Q20: =0.08*E20 -> 29771.627 | R20: =Q20+P20+O20+M20+N20+L20+K20 -> 90248.894 | S20: 790264.51 | T20: =J20-R20 -> 383546.44
A21: 5 | B21: MATHIAS OMANULU AGBONI | C21: SENIOR RESEARCH OFFICER | D21: 10(7) | E21: 372145.33 | G21: =100000 -> 100000 | J21: =E21+F21+G21+H21+I21 -> 472145.33 | P21: 62127.267 | Q21: =0.08*E21 -> 29771.627 | R21: =Q21+P21+O21+M21+N21+L21+K21 -> 91898.894 | S21: 790264.51 | T21: =J21-R21 -> 380246.44
A22: 6 | B22: OLUFADI MARIAM MOJISOLA | C22: SENIOR. RESEARCH OFFICER | D22: 10(7) | E22: 372145.33 | G22: =100000 -> 100000 | J22: =E22+F22+G22+H22+I22 -> 472145.33 | P22: 62127.267 | Q22: =0.08*E22 -> 29771.627 | R22: =Q22+P22+O22+M22+N22+L22+K22 -> 91898.894 | S22: 790264.51 | T22: =J22-R22 -> 380246.44
A23: 7 | B23: EBUNILO ELVIS EBUKA | C23: RESEARCH OFFICER | D23: 9(7) | E23: 330408.08 | F23: 3000 | G23: =100000 -> 100000 | J23: =E23+F23+G23+H23+I23 -> 433408.08 | P23: 52215.579 | Q23: =0.08*E23 -> 26432.647 | R23: =Q23+P23+O23+M23+N23+L23+K23 -> 78648.225 | S23: 723952.36 | T23: =J23-R23 -> 354759.86
A24: 8 | B24: MUHAMMED BASHIR ABDULLAHI | C24: RESEARCH OFFICER | D24: 9(7) | E24: 330408.08 | G24: =100000 -> 100000 | J24: =E24+F24+G24+H24+I24 -> 430408.08 | P24: 55215.579 | Q24: =0.08*E24 -> 26432.647 | R24: =Q24+P24+O24+M24+N24+L24+K24 -> 81648.225 | S24: 723952.36 | T24: =J24-R24 -> 348759.86
A25: 9 | B25: BENEDICTA OGHECHI BNNAMANI | C25: RESEARCH OFFICER | D25: 9(7) | E25: 330408.08 | G25: =100000 -> 100000 | J25: =E25+F25+G25+H25+I25 -> 430408.08 | P25: 55215.579 | Q25: =0.08*E25 -> 26432.647 | R25: =Q25+P25+O25+M25+N25+L25+K25 -> 81648.225 | S25: 644257.45 | T25: =J25-R25 -> 348759.86
A26: 10 | B26: GARBA EPHRAIM | C26: RESEARCH OFFICER | D26: 9(7) | E26: =330408.083333333 -> 330408.08 | G26: =100000 -> 100000 | J26: =E26+F26+G26+H26+I26 -> 430408.08 | P26: 55215.579 | Q26: =0.08*E26 -> 26432.647 | R26: =Q26+P26+O26+M26+N26+L26+K26 -> 81648.225 | S26: 156299.89 | T26: =J26-R26 -> 348759.86
A27: 11 | B27: ABDURRAHMANZUWAIRA IBRAHIM | C27: RESEARCH OFFICER | D27: 9(7) | E27: 330408.08 | G27: =100000 -> 100000 | J27: =E27+F27+G27+H27+I27 -> 430408.08 | P27: 55215.579 | Q27: =0.08*E27 -> 26432.647 | R27: =Q27+P27+O27+M27+N27+L27+K27 -> 81648.225 | S27: 723952.36 | T27: =J27-R27 -> 348759.86
B28: TOTAL | C28: 11 | E28: =SUM(E17:E27) -> 4091953.4 | F28: =SUM(F17:F27) -> 4650 | G28: =SUM(G17:G27) -> 1130000 | H28: =SUM(H17:H27) -> 0 | I28: =SUM(I17:I27) -> 0 | J28: =SUM(J17:J27) -> 5226603.4 | K28: =SUM(K17:K27) -> 0 | L28: =SUM(L17:L27) -> 84000 | ... R28: =SUM(R17:R27) -> 1095233.8 | S28: 8092148.2 | T28: =SUM(T17:T27) -> 4131369.7
B30: DEMOCRACY & GOVERNANCE
A31: 1 | B31: NAPHTALI AMANA | C31: SENIOR RESEARCH OFFICER | D31: 10(7) | E31: 372145.33 | F31: 1950 | G31: 100000 | I31: 0 | J31: =E31+F31+G31+H31+I31 -> 474095.33 | L31: 0 | N31: 0 | P31: 63777.267 | Q31: 29771.627 | R31: =Q31+P31+O31+M31+N31+L31+K31 -> 93548.894 | S31: 790264.51 | T31: =J31-R31 -> 380546.44
A32: 2 | B32: UDOFA SAMUEL IME | C32: RESEARCH OFFICER | D32: 9(7) | E32: 330408.08 | G32: 100000 | I32: 0 | J32: =E32+F32+G32+H32+I32 -> 430408.08 | L32: 0 | N32: 0 | P32: 51151.062 | Q32: =0.08*E32 -> 26432.647 | R32: =Q32+P32+O32+M32+N32+L32+K32 -> 77583.709 | S32: 732081.4 | T32: =J32-R32 -> 352824.37
B33: TOTAL | C33: 2 | E33: =SUM(E31:E32) -> 702553.42 | F33: =SUM(F31:F32) -> 1950 | G33: =SUM(G31:G32) -> 200000 | H33: =SUM(H31:H32) -> 0 | I33: =SUM(I31:I32) -> 0 | J33: =SUM(J31:J32) -> 904503.42 | K33: =SUM(K31:K32) -> 0 | L33: =SUM(L31:L32) -> 0 | ... R33: =SUM(R31:R32) -> 171132.6 | S33: 1522345.9 | T33: =SUM(T31:T32) -> 733370.81
B35: DEPARTMENT OF STUDIES
A36: 1 | B36: AHMAD IBRAHIM | C36: PROGRM OFFICER | D36: 14(7) | E36: =526673.583333333 -> 526673.58 | G36: 140000 | I36: 0 | J36: =E36+F36+G36+H36+I36 -> 666673.58 | L36: 0 | N36: 0 | P36: 96881.661 | Q36: =0.08*E36 -> 42133.887 | R36: =Q36+P36+O36+M36+N36+L36+K36 -> 139015.55 | S36: 1097450 | T36: =J36-R36 -> 527658.04
A37: 2 | B37: INUWA ABDULLAHI GAMAU | C37: CHIEF PROGRM OFFICER | D37: 9(7) | E37: 330408.08 | G37: =100000 -> 100000 | J37: =E37+F37+G37+H37+I37 -> 430408.08 | P37: 55215.579 | Q37: 26432.647 | R37: =Q37+P37+O37+M37+N37+L37+K37 -> 81648.225 | S37: 732081.4 | T37: =J37-R37 -> 348759.86
A38: 3 | B38: ABDULKAREEM SOFIAT DAMOLA | C38: ASSISTANT PROGRM OFFICER | D38: 8(7) | E38: 287890.92 | G38: =100000 -> 100000 | J38: =E38+F38+G38+H38+I38 -> 387890.92 | P38: 48174.736 | Q38: =0.08*E38 -> 23031.273 | R38: =Q38+P38+O38+M38+N38+L38+K38 -> 71206.009 | S38: 564058.03 | T38: =J38-R38 -> 316684.91
A39: 4 | B39: UBOSI CHIZOBA AUGUSTINE | C39: ASSISTANT PROGRM OFFICER | D39: 8(7) | E39: 287890.92 | G39: =100000 -> 100000 | J39: =E39+F39+G39+H39+I39 -> 387890.92 | P39: 48174.736 | Q39: =0.08*E39 -> 23031.273 | R39: =Q39+P39+O39+M39+N39+L39+K39 -> 71206.009 | S39: 656401.09 | T39: =J39-R39 -> 316684.91
B40: TOTAL | C40: 4 | E40: =SUM(E36:E39) -> 1432863.5 | F40: =SUM(F36:F39) -> 0 | G40: =SUM(G36:G39) -> 440000 | H40: =SUM(H36:H39) -> 0 | I40: =SUM(I36:I39) -> 0 | J40: =SUM(J36:J39) -> 1872863.5 | K40: =SUM(K36:K39) -> 0 | L40: =SUM(L36:L39) -> 0 | ... R40: =SUM(R36:R39) -> 363075.79 | S40: 3049990.5 | T40: =SUM(T36:T39) -> 1509787.7
B42: ECON. DEV. & SOC. RESEARCH
A43: 1 | B43: HABIBA AWWALU BABANGIDA | C43: SENIOR RESEARCH FELLOW | D43: 15(7) | E43: 700713.92 | G43: 160000 | J43: =E43+F43+G43+H43+I43 -> 860713.92 | P43: 129844.41 | Q43: 56057.113 | R43: =Q43+P43+O43+M43+N43+L43+K43 -> 185901.52 | T43: =J43-R43 -> 674812.4
A44: 2 | B44: FADILA JUMARE | C44: REASEARCH FELLOW 1 | D44: 14(7) | E44: =526673.583333333 -> 526673.58 | G44: =140000 -> 140000 | J44: =E44+F44+G44+H44+I44 -> 666673.58 | N44: 22000 | P44: 96881.661 | Q44: 42133.887 | R44: =Q44+P44+O44+M44+N44+L44+K44 -> 161015.55 | S44: 265103.68 | T44: =J44-R44 -> 505658.04
...

Sheet MEMO
A2: NATIONAL INSTITUTE FOR LEGISLATIVE AND DEMOCRATIC STUDIES
A3: INTERNAL MEMO
A4: FROM : DEPUTY DIRECTOR, FINANCE AND ACCOUNTS
A5: THRU: DIRECTOR, FINANCE AND ACCOUNTS
A6: TO: DG
A7: 29TH JANUARY , 2021
A9: SUBJECT: PAYROLL FOR THE MONTH OF JANUARY, 2021
A10: Find below the details of NILDS Staff Payroll for the month of January, 2021
A13: TO: | B13: DIRECTOR, GENERAL
A14: THRU: | B14: DIRECTOR, FINANCE AND ACCOUNT
A15: FROM: | B15: DEPUTY DIRECTOR, FINANCE AND ACCOUNTS
A16: DATE: | B16: 25TH FEBRUARY, 2026
A18: SUBJECT: PAYROLL OF NEW PERMANENT STAFF FOR THE MONTH OF FEBRUARY 2026
A19: Find below the details of NILDS Staff Payroll for the Month of February 2026: | E19: NGN | F19: NGN
A20: GROSS SALARY FOR FEBRUARY, 2026 | F20: ='FEB NEW PERM'!J77 -> 22256923
A22: DEDUCTIONS
A23: COOP SOCIETY 1 DEDUCTIONS | E23: ='FEB NEW PERM'!L77+'FEB NEW PERM'!M77 -> 384000
A24: COOP SOCIETY 2 DEDUCTIONS | E24: ='FEB NEW PERM'!N77 -> 115332.5
A25: NHF DEDUCTIONS | E25: ='FEB NEW PERM'!O77 -> 0
A26: PAYE DEDUCTIONS | E26: ='FEB NEW PERM'!P77 -> 2935966.4
A27: PENSION DEDUCTIONS | E27: ='FEB NEW PERM'!Q77 -> 1472619.7
A28: TOTAL DEDUCTIONS FOR FEBRUARY 2026 | F28: =E23+E24+E25+E26+E27 -> 4907918.6
A29: NET PAY AS PER FEBRUARY 2026 PAYROLL | F29: =F20-F28 -> 17349004
A30: NET PAY AS PER JANUARY 2026 PAYROLL | F30: ='FEB NEW PERM'!S77 -> 27779512
A31: NET INCREASE/ (DECREASE) IN PAY FOR FEBRUARY 2026 | F31: =F29-F30 -> -10430508
A33: ANALYSED AS FOLLOWS:
A34: Effect of Cooperative 1 Adjustments for February 2026 | F34: =384000 -> 384000
A35: Effect of Cooperative 2 Adjustments for February 2026 | F35: 115332.5
A36: Effect of annual rent relief on PAYE ifo Ibrahim Abubakar Waziri & 4 others | F36: -27000
A37: Effect of enrolment of Habiba Awwalu Babangida on resumption | F37: -674812.4
A38: Effect of removal of December 2025 salary arrears paid in January | F38: 13600244
A39: Effect of prorated salary of Garba Ephraim & 3 others now grossed up | F39: -894610.74
A40: Effect of enrolment of Al-kadriyar Abdullahi & 3 others due to conversion | F40: -1183289.5
A41: Effect of regularization of assumption date ifo Ibrahim Abubakar Waziri | F41: =-845825.94-43530.03 -> -889355.97
F42: =SUM(F33:F41) -> 10430508
C45: JANUARY, 2025 | E45: FEBRUARY, 2025
C46: No. of Staff | D46: N | E46: No. of Staff | F46: N
A47: 1 | B47: Director General's Office | C47: 7 | D47: 6184293.6 | E47: ='FEB NEW PERM'!C14 -> 7 | F47: ='FEB NEW PERM'!T14 -> 2816101.1
A48: 2 | B48: Legis. Support Services | C48: 11 | D48: 8092148.2 | E48: ='FEB NEW PERM'!C28 -> 11 | F48: ='FEB NEW PERM'!T28 -> 4131369.7
A49: 3 | B49: Democracy and Governance | C49: 2 | D49: 1522345.9 | E49: ='FEB NEW PERM'!C33 -> 2 | F49: ='FEB NEW PERM'!T33 -> 733370.81
...

Sheet PAYE
A1: S/NO | B1: NAME | C1: N | D1: NO OF MONTHS | E1: ANNUAL SALARY GROSSED UP | F1: ANNUAL RENT RELIEF (20% MAX OF N500,000) | G1: NATIONAL HOUSING SCHEME = 2.5% OF BASIC SALARY | H1: PENSION CONTRIBUTION = 8% OF CONSOLIDATED | I1: NHIS | J1: TOTAL RELIEF | K1: CHARGEABLE INCOME | L1: ANNUAL TAX PAYABLE | N1: MONTHLY TAX PAYABLE JANUARY
A2: S/N | B2: DG'S OFFICE
A3: 1 | B3: ATAKPO EMMANUEL OKON | C3: 780713.92 | D3: 12 | E3: =C3*D3 -> 9368567 | H3: 672685.36 | J3: =F3+G3+H3 -> 672685.36 | K3: =E3-J3 -> 8695881.6 | L3: =IF(K3<=800000,0,IF(K3<=3000000,(K3-800000)*15%,IF(K3<=12000000,330000+(K3-3000000)*18%,IF(K3<=25000000,1950000+(K3-12000000)*21%,IF(K3<=50000000,4680000+(K3-25000000)*23%,10430000+(K3-50000000)*25%))))) -> 1355258.7 | M3: 12 | N3: =L3/M3 -> 112938.22
A4: 2 | B4: BAFFA ALASAN | C4: 596673.58 | D4: 12 | E4: =C4*D4 -> 7160083 | H4: 505606.64 | J4: =F4+G4+H4 -> 505606.64 | K4: =E4-J4 -> 6654476.4 | L4: =IF(K4<=800000,0,IF(K4<=3000000,(K4-800000)*15%,IF(K4<=12000000,330000+(K4-3000000)*18%,IF(K4<=25000000,1950000+(K4-12000000)*21%,IF(K4<=50000000,4680000+(K4-25000000)*23%,10430000+(K4-50000000)*25%))))) -> 987805.74 | M4: 12 | N4: =L4/M4 -> 82317.145
A5: 3 | B5: OCHUNU LYNDA IHEKANMANANDU | C5: 501159 | D5: 12 | E5: =C5*D5 -> 6013908 | H5: 423512.64 | J5: =F5+G5+H5 -> 423512.64 | K5: =E5-J5 -> 5590395.4 | L5: =IF(K5<=800000,0,IF(K5<=3000000,(K5-800000)*15%,IF(K5<=12000000,330000+(K5-3000000)*18%,IF(K5<=25000000,1950000+(K5-12000000)*21%,IF(K5<=50000000,4680000+(K5-25000000)*23%,10430000+(K5-50000000)*25%))))) -> 796271.16 | M5: 12 | N5: =L5/M5 -> 66355.93
A6: 4 | B6: DORCAS MARK ESSET | C6: 541159 | D6: 12 | E6: =C6*D6 -> 6493908 | H6: 423512.64 | J6: =F6+G6+H6 -> 423512.64 | K6: =E6-J6 -> 6070395.4 | L6: =IF(K6<=800000,0,IF(K6<=3000000,(K6-800000)*15%,IF(K6<=12000000,330000+(K6-3000000)*18%,IF(K6<=25000000,1950000+(K6-12000000)*21%,IF(K6<=50000000,4680000+(K6-25000000)*23%,10430000+(K6-50000000)*25%))))) -> 882671.16 | M6: 12 | N6: =L6/M6 -> 73555.93
A7: 5 | B7: AYOPEMI AYOBAMI ANUOLUWAPO | C7: 432145.33 | D7: 12 | E7: =C7*D7 -> 5185744 | H7: 357259.52 | J7: =F7+G7+H7 -> 357259.52 | K7: =E7-J7 -> 4828484.5 | L7: =IF(K7<=800000,0,IF(K7<=3000000,(K7-800000)*15%,IF(K7<=12000000,330000+(K7-3000000)*18%,IF(K7<=25000000,1950000+(K7-12000000)*21%,IF(K7<=50000000,4680000+(K7-25000000)*23%,10430000+(K7-50000000)*25%))))) -> 659127.21 | M7: 12 | N7: =L7/M7 -> 54927.267
A8: 6 | B8: PRINCESS BARBARA AGOYE | C8: 432145.33 | D8: 12 | E8: =C8*D8 -> 5185744 | H8: 357259.52 | J8: =F8+G8+H8 -> 357259.52 | K8: =E8-J8 -> 4828484.5 | L8: =IF(K8<=800000,0,IF(K8<=3000000,(K8-800000)*15%,IF(K8<=12000000,330000+(K8-3000000)*18%,IF(K8<=25000000,1950000+(K8-12000000)*21%,IF(K8<=50000000,4680000+(K8-25000000)*23%,10430000+(K8-50000000)*25%))))) -> 659127.21 | M8: 12 | N8: =L8/M8 -> 54927.267
A9: 7 | B9: SANUSI MOHAMMED MATO | C9: 432145.33 | D9: 12 | E9: =C9*D9 -> 5185744 | H9: 357259.52 | J9: =F9+G9+H9 -> 357259.52 | K9: =E9-J9 -> 4828484.5 | L9: =IF(K9<=800000,0,IF(K9<=3000000,(K9-800000)*15%,IF(K9<=12000000,330000+(K9-3000000)*18%,IF(K9<=25000000,1950000+(K9-12000000)*21%,IF(K9<=50000000,4680000+(K9-25000000)*23%,10430000+(K9-50000000)*25%))))) -> 659127.21 | M9: 12 | N9: =L9/M9 -> 54927.267
A10: 8 | B10: TOTAL | N10: =SUM(N3:N9) -> 499949.03
A11: 9
A12: 10 | B12: LEG. SUPPORT SEVICES
A13: 11 | B13: IBRAHIM BELLO IBRAHIM | C13: 551159 | D13: 12 | E13: =C13*D13 -> 6613908 | H13: 423512.64 | J13: =F13+G13+H13 -> 423512.64 | K13: =E13-J13 -> 6190395.4 | L13: =IF(K13<=800000,0,IF(K13<=3000000,(K13-800000)*15%,IF(K13<=12000000,330000+(K13-3000000)*18%,IF(K13<=25000000,1950000+(K13-12000000)*21%,IF(K13<=50000000,4680000+(K13-25000000)*23%,10430000+(K13-50000000)*25%))))) -> 904271.16 | M13: 12 | N13: =L13/M13 -> 75355.93
A14: 12 | B14: ENI GEMOGONO-EVAL DAVID | C14: 551159 | D14: 12 | E14: =C14*D14 -> 6613908 | H14: 423512.64 | J14: =F14+G14+H14 -> 423512.64 | K14: =E14-J14 -> 6190395.4 | L14: =IF(K14<=800000,0,IF(K14<=3000000,(K14-800000)*15%,IF(K14<=12000000,330000+(K14-3000000)*18%,IF(K14<=25000000,1950000+(K14-12000000)*21%,IF(K14<=50000000,4680000+(K14-25000000)*23%,10430000+(K14-50000000)*25%))))) -> 904271.16 | M14: 12 | N14: =L14/M14 -> 75355.93
A15: 13 | B15: AKEBONG SAMUEL ESSIEN | C15: 551159 | D15: 12 | E15: =C15*D15 -> 6613908 | H15: 423512.64 | J15: =F15+G15+H15 -> 423512.64 | K15: =E15-J15 -> 6190395.4 | L15: =IF(K15<=800000,0,IF(K15<=3000000,(K15-800000)*15%,IF(K15<=12000000,330000+(K15-3000000)*18%,IF(K15<=25000000,1950000+(K15-12000000)*21%,IF(K15<=50000000,4680000+(K15-25000000)*23%,10430000+(K15-50000000)*25%))))) -> 904271.16 | M15: 12 | N15: =L15/M15 -> 75355.93
A16: 14 | B16: UDUAKOBONG JOHN OBOT | C16: 472145.33 | D16: 12 | E16: =C16*D16 -> 5665744 | F16: 110000 | H16: 357259.52 | J16: =F16+G16+H16 -> 467259.52 | K16: =E16-J16 -> 5198484.5 | L16: =IF(K16<=800000,0,IF(K16<=3000000,(K16-800000)*15%,IF(K16<=12000000,330000+(K16-3000000)*18%,IF(K16<=25000000,1950000+(K16-12000000)*21%,IF(K16<=50000000,4680000+(K16-25000000)*23%,10430000+(K16-50000000)*25%))))) -> 725727.21 | M16: 12 | N16: =L16/M16 -> 60477.267 | O16: 62127.267 | P16: =O16-N16 -> 1650
A17: 15 | B17: MATHIAS OMANULU AGBONI | C17: 472145.33 | D17: 12 | E17: =C17*D17 -> 5665744 | H17: 357259.52 | J17: =F17+G17+H17 -> 357259.52 | K17: =E17-J17 -> 5308484.5 | L17: =IF(K17<=800000,0,IF(K17<=3000000,(K17-800000)*15%,IF(K17<=12000000,330000+(K17-3000000)*18%,IF(K17<=25000000,1950000+(K17-12000000)*21%,IF(K17<=50000000,4680000+(K17-25000000)*23%,10430000+(K17-50000000)*25%))))) -> 745527.21 | M17: 12 | N17: =L17/M17 -> 62127.267
A18: 16 | B18: OLUFADI MARIAM MOJISOLA | C18: 472145.33 | D18: 12 | E18: =C18*D18 -> 5665744 | H18: 357259.52 | J18: =F18+G18+H18 -> 357259.52 | K18: =E18-J18 -> 5308484.5 | L18: =IF(K18<=800000,0,IF(K18<=3000000,(K18-800000)*15%,IF(K18<=12000000,330000+(K18-3000000)*18%,IF(K18<=25000000,1950000+(K18-12000000)*21%,IF(K18<=50000000,4680000+(K18-25000000)*23%,10430000+(K18-50000000)*25%))))) -> 745527.21 | M18: 12 | N18: =L18/M18 -> 62127.267
A19: 17 | B19: EBUNILO ELVIS EBUKA | C19: 430408.08 | D19: 12 | E19: =C19*D19 -> 5164897 | F19: 200000 | H19: 317191.76 | J19: =F19+G19+H19 -> 517191.76 | K19: =E19-J19 -> 4647705.2 | L19: =IF(K19<=800000,0,IF(K19<=3000000,(K19-800000)*15%,IF(K19<=12000000,330000+(K19-3000000)*18%,IF(K19<=25000000,1950000+(K19-12000000)*21%,IF(K19<=50000000,4680000+(K19-25000000)*23%,10430000+(K19-50000000)*25%))))) -> 626586.94 | M19: 12 | N19: =L19/M19 -> 52215.579 | O19: 55215.579 | P19: =O19-N19 -> 3000
A20: 18 | B20: MUHAMMED BASHIR ABDULLAHI | C20: 430408.08 | D20: 12 | E20: =C20*D20 -> 5164897 | H20: 317191.76 | J20: =F20+G20+H20 -> 317191.76 | K20: =E20-J20 -> 4847705.2 | L20: =IF(K20<=800000,0,IF(K20<=3000000,(K20-800000)*15%,IF(K20<=12000000,330000+(K20-3000000)*18%,IF(K20<=25000000,1950000+(K20-12000000)*21%,IF(K20<=50000000,4680000+(K20-25000000)*23%,10430000+(K20-50000000)*25%))))) -> 662586.94 | M20: 12 | N20: =L20/M20 -> 55215.579
A21: 19 | B21: BENEDICTA OGHECHI BNNAMANI | C21: 430408.08 | D21: 12 | E21: =C21*D21 -> 5164897 | H21: 317191.76 | J21: =F21+G21+H21 -> 317191.76 | K21: =E21-J21 -> 4847705.2 | L21: =IF(K21<=800000,0,IF(K21<=3000000,(K21-800000)*15%,IF(K21<=12000000,330000+(K21-3000000)*18%,IF(K21<=25000000,1950000+(K21-12000000)*21%,IF(K21<=50000000,4680000+(K21-25000000)*23%,10430000+(K21-50000000)*25%))))) -> 662586.94 | M21: 12 | N21: =L21/M21 -> 55215.579
A22: 20 | B22: GARBA EPHRAIM | C22: 180493.71 | D22: 12 | E22: =C22*D22 -> 2165924.5 | H22: 317191.76 | J22: =F22+G22+H22 -> 317191.76 | K22: =E22-J22 -> 1848732.8 | L22: =IF(K22<=800000,0,IF(K22<=3000000,(K22-800000)*15%,IF(K22<=12000000,330000+(K22-3000000)*18%,IF(K22<=25000000,1950000+(K22-12000000)*21%,IF(K22<=50000000,4680000+(K22-25000000)*23%,10430000+(K22-50000000)*25%))))) -> 157309.92 | M22: 12 | N22: =L22/M22 -> 13109.16
A23: 21 | B23: ABDURRAHMANZUWAIRA IBRAHIM | C23: 430408.08 | D23: 12 | E23: =C23*D23 -> 5164897 | H23: 317191.76 | J23: =F23+G23+H23 -> 317191.76 | K23: =E23-J23 -> 4847705.2 | L23: =IF(K23<=800000,0,IF(K23<=3000000,(K23-800000)*15%,IF(K23<=12000000,330000+(K23-3000000)*18%,IF(K23<=25000000,1950000+(K23-12000000)*21%,IF(K23<=50000000,4680000+(K23-25000000)*23%,10430000+(K23-50000000)*25%))))) -> 662586.94 | M23: 12 | N23: =L23/M23 -> 55215.579
A24: 22 | B24: TOTAL | N24: =SUM(N13:N23) -> 641771.07
A25: 23
A26: 24 | B26: DEMOCRACY & GOVERNANCE
A27: 25 | B27: NAPHTALI AMANA | C27: 492145.33 | D27: 12 | E27: =C27*D27 -> 5905744 | F27: 130000 | H27: 357259.52 | J27: =F27+G27+H27 -> 487259.52 | K27: =E27-J27 -> 5418484.5 | L27: =IF(K27<=800000,0,IF(K27<=3000000,(K27-800000)*15%,IF(K27<=12000000,330000+(K27-3000000)*18%,IF(K27<=25000000,1950000+(K27-12000000)*21%,IF(K27<=50000000,4680000+(K27-25000000)*23%,10430000+(K27-50000000)*25%))))) -> 765327.21 | M27: 12 | N27: =L27/M27 -> 63777.267 | O27: 65727.267 | P27: =O27-N27 -> 1950
A28: 26 | B28: UDOFA SAMUEL IME | C28: 407827.44 | D28: 12 | E28: =C28*D28 -> 4893929.3 | H28: 317191.76 | J28: =F28+G28+H28 -> 317191.76 | K28: =E28-J28 -> 4576737.5 | L28: =IF(K28<=800000,0,IF(K28<=3000000,(K28-800000)*15%,IF(K28<=12000000,330000+(K28-3000000)*18%,IF(K28<=25000000,1950000+(K28-12000000)*21%,IF(K28<=50000000,4680000+(K28-25000000)*23%,10430000+(K28-50000000)*25%))))) -> 613812.75 | M28: 12 | N28: =L28/M28 -> 51151.062
A29: 27 | B29: TOTAL | N29: =SUM(N27:N28) -> 114928.33
A30: 28
A31: 29 | B31: DEPARTMENT OF STUDIES
A32: 30 | B32: AHMAD IBRAHIM | C32: 666673.58 | D32: 12 | E32: =C32*D32 -> 8000083 | H32: 374638.96 | J32: =F32+G32+H32 -> 374638.96 | K32: =E32-J32 -> 7625444 | L32: =IF(K32<=800000,0,IF(K32<=3000000,(K32-800000)*15%,IF(K32<=12000000,330000+(K32-3000000)*18%,IF(K32<=25000000,1950000+(K32-12000000)*21%,IF(K32<=50000000,4680000+(K32-25000000)*23%,10430000+(K32-50000000)*25%))))) -> 1162579.9 | M32: 12 | N32: =L32/M32 -> 96881.661
A33: 31 | B33: INUWA ABDULLAHI GAMAU | C33: 430408.08 | D33: 12 | E33: =C33*D33 -> 5164897 | H33: 317191.76 | J33: =F33+G33+H33 -> 317191.76 | K33: =E33-J33 -> 4847705.2 | L33: =IF(K33<=800000,0,IF(K33<=3000000,(K33-800000)*15%,IF(K33<=12000000,330000+(K33-3000000)*18%,IF(K33<=25000000,1950000+(K33-12000000)*21%,IF(K33<=50000000,4680000+(K33-25000000)*23%,10430000+(K33-50000000)*25%))))) -> 662586.94 | M33: 12 | N33: =L33/M33 -> 55215.579
A34: 32 | B34: ABDULKAREEM SOFIAT DAMOLA | C34: 387890.92 | D34: 12 | E34: =C34*D34 -> 4654691 | H34: 276375.28 | J34: =F34+G34+H34 -> 276375.28 | K34: =E34-J34 -> 4378315.7 | L34: =IF(K34<=800000,0,IF(K34<=3000000,(K34-800000)*15%,IF(K34<=12000000,330000+(K34-3000000)*18%,IF(K34<=25000000,1950000+(K34-12000000)*21%,IF(K34<=50000000,4680000+(K34-25000000)*23%,10430000+(K34-50000000)*25%))))) -> 578096.83 | M34: 12 | N34: =L34/M34 -> 48174.736
A35: 33 | B35: UBOSI CHIZOBA AUGUSTINE | C35: 387890.92 | D35: 12 | E35: =C35*D35 -> 4654691 | H35: 276375.28 | J35: =F35+G35+H35 -> 276375.28 | K35: =E35-J35 -> 4378315.7 | L35: =IF(K35<=800000,0,IF(K35<=3000000,(K35-800000)*15%,IF(K35<=12000000,330000+(K35-3000000)*18%,IF(K35<=25000000,1950000+(K35-12000000)*21%,IF(K35<=50000000,4680000+(K35-25000000)*23%,10430000+(K35-50000000)*25%))))) -> 578096.83 | M35: 12 | N35: =L35/M35 -> 48174.736
A36: 34 | B36: TOTAL | N36: =SUM(N32:N35) -> 248446.71
A37: 35
A38: 36 | B38: ECON. DEV. & SOC. RESEARCH
A39: 37 | B39: FADILA JUMARE | C39: 860713.92 | D39: 12 | E39: =C39*D39 -> 10328567 | H39: 505606.64 | J39: =F39+G39+H39 -> 505606.64 | K39: =E39-J39 -> 9822960.4 | L39: =IF(K39<=800000,0,IF(K39<=3000000,(K39-800000)*15%,IF(K39<=12000000,330000+(K39-3000000)*18%,IF(K39<=25000000,1950000+(K39-12000000)*21%,IF(K39<=50000000,4680000+(K39-25000000)*23%,10430000+(K39-50000000)*25%))))) -> 1558132.9 | M39: 12 | N39: =L39/M39 -> 129844.41
A40: 38 | B40: JAMILU SANI | C40: 252806.63 | D40: 12 | E40: =C40*D40 -> 3033679.6 | H40: 463532.72 | J40: =F40+G40+H40 -> 463532.72 | K40: =E40-J40 -> 2570146.9 | L40: =IF(K40<=800000,0,IF(K40<=3000000,(K40-800000)*15%,IF(K40<=12000000,330000+(K40-3000000)*18%,IF(K40<=25000000,1950000+(K40-12000000)*21%,IF(K40<=50000000,4680000+(K40-25000000)*23%,10430000+(K40-50000000)*25%))))) -> 265522.03 | M40: 12 | N40: =L40/M40 -> 22126.836
...

Sheet DEC NEW PERM
A1: NATIONAL INSTITUTE FOR LEGISLATIVE AND DEMOCRATIC STUDIES
A2: STAFF PAYROLL FOR THE MONTH OF DECEMBER, 2025 (NEW PERM STAFF)
E3: ='[1]FEB 08'!E11/'[1]FEB 08'!M11 -> #REF!
B4: STAFF NAME | C4: DESIGNATION | D4: GRADE LEVEL | E4: BASIC SALARY | F4: ARREARS | G4: ALLOWANCE | H4: ALLOWANCE | I4: DUTY ALLCE | J4: GROSS SALARY | K4: AUCTION | L4: COOP CONTR/SPEC SAVINGS | M4: COOP. LOAN RECOVERY | N4: NHF DED. | O4: PAYE | P4: EMPLOYEE PENSIONS | Q4: TOTAL DEDUCTION | R4: DECEMBER, 2025
E5: N | F5: N | G5: N | H5: N | I5: N | J5: N | K5: N | L5: N | M5: N | N5: N | O5: N | P5: N | Q5: N | R5: N
A6: S/N | B6: DG'S OFFICE
A7: 1 | B7: ATAKPO EMMANUEL OKON | C7: ASSISTANT DIRECTOR | D7: 15(7) | E7: 700713.92 | H7: =80000 -> 80000 | J7: =E7+F7+G7+H7+I7 -> 780713.92 | O7: 112938.22 | P7: =0.08*E7 -> 56057.113 | Q7: =P7+O7+N7+M7+L7+K7 -> 168995.34 | R7: =J7-Q7 -> 611718.58
A8: 2 | B8: BAFFA ALASAN | C8: CHIEF LEGAL OFFICCER | D8: 14(7) | E8: ='[2] FGN 2024 MGT Monthly'!$H$42+'[2]Peculiar Allowance'!$H$42 -> 526673.58 | H8: 70000 | J8: =E8+F8+G8+H8+I8 -> 596673.58 | O8: 82317.145 | P8: =0.08*E8 -> 42133.887 | Q8: =P8+O8+N8+M8+L8+K8 -> 124451.03 | R8: =J8-Q8 -> 472222.55
A9: 3 | B9: OCHUNU LYNDA IHEKANMANANDU | C9: PRINCIPAL LEGAL OFFICER | D9: 12(7) | E9: ='[2]Peculiar Allowance'!$H$40+'[2] FGN 2024 MGT Monthly'!$H$40 -> 441159 | H9: 60000 | J9: =E9+F9+G9+H9+I9 -> 501159 | O9: 66355.93 | P9: =0.08*E9 -> 35292.72 | Q9: =P9+O9+N9+M9+L9+K9 -> 101648.65 | R9: =J9-Q9 -> 399510.35
A10: 4 | B10: DORCAS MARK ESSET | C10: PRINCIPAL RESEARCH OFFICER | D10: 12(7) | E10: ='[2]Peculiar Allowance'!$H$40+'[2] FGN 2024 MGT Monthly'!$H$40 -> 441159 | G10: 110000 | J10: =E10+F10+G10+H10+I10 -> 551159 | O10: 75355.93 | P10: 35292.72 | Q10: =P10+O10+N10+M10+L10+K10 -> 110648.65 | R10: =J10-Q10 -> 440510.35
A11: 5 | B11: AYOPEMI AYOBAMI ANUOLUWAPO | C11: SENIOR LEGAL OFFICER | D11: 10(7) | E11: 372145.33 | H11: =60000 -> 60000 | J11: =E11+F11+G11+H11+I11 -> 432145.33 | O11: 54927.267 | P11: =0.08*E11 -> 29771.627 | Q11: =P11+O11+N11+M11+L11+K11 -> 84698.894 | R11: =J11-Q11 -> 347446.44
A12: 6 | B12: PRINCESS BARBARA AGOYE | C12: SENIORGI OFFICER | D12: 10(7) | E12: 372145.33 | H12: =60000 -> 60000 | J12: =E12+F12+G12+H12+I12 -> 432145.33 | O12: 54927.267 | P12: =0.08*E12 -> 29771.627 | Q12: =P12+O12+N12+M12+L12+K12 -> 84698.894 | R12: =J12-Q12 -> 347446.44
A13: 7 | B13: SANUSI MOHAMMED MATO | C13: SENIOR INF &COMM OFFICER | D13: 10(7) | E13: 372145.33 | H13: =60000 -> 60000 | J13: =E13+F13+G13+H13+I13 -> 432145.33 | O13: 54927.267 | P13: =0.08*E13 -> 29771.627 | Q13: =P13+O13+N13+M13+L13+K13 -> 84698.894 | R13: =J13-Q13 -> 347446.44
B14: TOTAL | C14: 7 | E14: =SUM(E7:E13) -> 3226141.5 | F14: =SUM(F7:F13) -> 0 | G14: =SUM(G7:G13) -> 110000 | H14: =SUM(H7:H13) -> 390000 | I14: =SUM(I7:I13) -> 0 | J14: =SUM(J7:J13) -> 3726141.5 | K14: =SUM(K7:K13) -> 0 | L14: =SUM(L7:L13) -> 0 | ... R14: =SUM(R7:R13) -> 2966301.1
B16: LEG. SUPPORT SEVICES
A17: 1 | B17: IBRAHIM BELLO IBRAHIM | C17: PRINC. RESEARCH OFFICER | D17: 12(7) | E17: ='[2]Peculiar Allowance'!$H$40+'[2] FGN 2024 MGT Monthly'!$H$40 -> 441159 | G17: =110000 -> 110000 | J17: =E17+F17+G17+H17+I17 -> 551159 | O17: 75355.93 | P17: =0.08*E17 -> 35292.72 | Q17: =P17+O17+N17+M17+L17+K17 -> 110648.65 | R17: =J17-Q17 -> 440510.35
A18: 2 | B18: ENI GEMOGONO-EVAL DAVID | C18: PRINC. RESEARCH OFFICER | D18: 12(7) | E18: ='[2]Peculiar Allowance'!$H$40+'[2] FGN 2024 MGT Monthly'!$H$40 -> 441159 | G18: =110000 -> 110000 | J18: =E18+F18+G18+H18+I18 -> 551159 | O18: 75355.93 | P18: =0.08*E18 -> 35292.72 | Q18: =P18+O18+N18+M18+L18+K18 -> 110648.65 | R18: =J18-Q18 -> 440510.35
A19: 3 | B19: AKEBONG SAMUEL ESSIEN | C19: PRINC. RESEARCH OFFICER | D19: 12(7) | E19: ='[2]Peculiar Allowance'!$H$40+'[2] FGN 2024 MGT Monthly'!$H$40 -> 441159 | G19: =110000 -> 110000 | J19: =E19+F19+G19+H19+I19 -> 551159 | O19: 75355.93 | P19: =0.08*E19 -> 35292.72 | Q19: =P19+O19+N19+M19+L19+K19 -> 110648.65 | R19: =J19-Q19 -> 440510.35
A20: 4 | B20: UDUAKOBONG JOHN OBOT | C20: SENIOR RESEARCH OFFICER | D20: 10(7) | E20: 372145.33 | G20: =100000 -> 100000 | J20: =E20+F20+G20+H20+I20 -> 472145.33 | O20: 62127.267 | P20: =0.08*E20 -> 29771.627 | Q20: =P20+O20+N20+M20+L20+K20 -> 91898.894 | R20: =J20-Q20 -> 380246.44
A21: 5 | B21: MATHIAS OMANULU AGBONI | C21: SENIOR RESEARCH OFFICER | D21: 10(7) | E21: 372145.33 | G21: =100000 -> 100000 | J21: =E21+F21+G21+H21+I21 -> 472145.33 | O21: 62127.267 | P21: =0.08*E21 -> 29771.627 | Q21: =P21+O21+N21+M21+L21+K21 -> 91898.894 | R21: =J21-Q21 -> 380246.44
A22: 6 | B22: OLUFADI MARIAM MOJISOLA | C22: SENIOR. RESEARCH OFFICER | D22: 10(7) | E22: 372145.33 | G22: =100000 -> 100000 | J22: =E22+F22+G22+H22+I22 -> 472145.33 | O22: 62127.267 | P22: =0.08*E22 -> 29771.627 | Q22: =P22+O22+N22+M22+L22+K22 -> 91898.894 | R22: =J22-Q22 -> 380246.44
A23: 7 | B23: EBUNILO ELVIS EBUKA | C23: RESEARCH OFFICER | D23: 9(7) | E23: 330408.08 | G23: =100000 -> 100000 | J23: =E23+F23+G23+H23+I23 -> 430408.08 | O23: 55215.579 | P23: =0.08*E23 -> 26432.647 | Q23: =P23+O23+N23+M23+L23+K23 -> 81648.225 | R23: =J23-Q23 -> 348759.86
A24: 8 | B24: MUHAMMED BASHIR ABDULLAHI | C24: RESEARCH OFFICER | D24: 9(7) | E24: 330408.08 | G24: =100000 -> 100000 | J24: =E24+F24+G24+H24+I24 -> 430408.08 | O24: 55215.579 | P24: =0.08*E24 -> 26432.647 | Q24: =P24+O24+N24+M24+L24+K24 -> 81648.225 | R24: =J24-Q24 -> 348759.86
A25: 9 | B25: BENEDICTA OGHECHI BNNAMANI | C25: RESEARCH OFFICER | D25: 9(7) | E25: =330408.083333333*24/31 -> 255799.81 | G25: =100000*24/31 -> 77419.355 | J25: =E25+F25+G25+H25+I25 -> 333219.16 | O25: 37721.573 | P25: =0.08*E25 -> 20463.985 | Q25: =P25+O25+N25+M25+L25+K25 -> 58185.557 | R25: =J25-Q25 -> 275033.6
A26: 10 | B26: ABDURRAHMANZUWAIRA IBRAHIM | C26: RESEARCH OFFICER | D26: 9(7) | E26: 330408.08 | G26: =100000 -> 100000 | J26: =E26+F26+G26+H26+I26 -> 430408.08 | O26: 55215.579 | P26: =0.08*E26 -> 26432.647 | Q26: =P26+O26+N26+M26+L26+K26 -> 81648.225 | R26: =J26-Q26 -> 348759.86
B27: TOTAL | C27: 10 | E27: =SUM(E17:E26) -> 3686937.1 | F27: =SUM(F17:F26) -> 0 | G27: =SUM(G17:G26) -> 1007419.4 | H27: =SUM(H17:H26) -> 0 | I27: =SUM(I17:I26) -> 0 | J27: =SUM(J17:J26) -> 4694356.4 | K27: =SUM(K17:K26) -> 0 | L27: =SUM(L17:L26) -> 0 | ... R27: =SUM(R17:R26) -> 3783583.5
B29: DEMOCRACY & GOVERNANCE
A30: 1 | B30: NAPHTALI AMANA | C30: SENIOR RESEARCH OFFICER | D30: 10(7) | E30: 372145.33 | G30: 100000 | I30: 0 | J30: =E30+F30+G30+H30+I30 -> 472145.33 | L30: 0 | O30: 65727.267 | P30: =0.08*E30 -> 29771.627 | Q30: =P30+O30+N30+M30+L30+K30 -> 95498.894 | R30: =J30-Q30 -> 376646.44
A31: 2 | B31: UDOFA SAMUEL IME | C31: RESEARCH OFFICER | D31: 9(7) | E31: 330408.08 | G31: 100000 | I31: 0 | J31: =E31+F31+G31+H31+I31 -> 430408.08 | L31: 0 | O31: 55215.579 | P31: 26432.647 | Q31: =P31+O31+N31+M31+L31+K31 -> 81648.225 | R31: =J31-Q31 -> 348759.86
B32: TOTAL | C32: 2 | E32: =SUM(E30:E31) -> 702553.42 | F32: =SUM(F30:F31) -> 0 | G32: =SUM(G30:G31) -> 200000 | H32: =SUM(H30:H31) -> 0 | I32: =SUM(I30:I31) -> 0 | J32: =SUM(J30:J31) -> 902553.42 | K32: =SUM(K30:K31) -> 0 | L32: =SUM(L30:L31) -> 0 | ... R32: =SUM(R30:R31) -> 725406.3
B34: DEPARTMENT OF STUDIES
A35: 1 | B35: AHMAD IBRAHIM | C35: PROGRM OFFICER | D35: 14(7) | E35: 526673.58 | G35: =140000 -> 140000 | I35: 0 | J35: =E35+F35+G35+H35+I35 -> 666673.58 | L35: 0 | O35: 96881.661 | P35: =0.08*E35 -> 42133.887 | Q35: =P35+O35+N35+M35+L35+K35 -> 139015.55 | R35: =J35-Q35 -> 527658.04
A36: 2 | B36: INUWA ABDULLAHI GAMAU | C36: CHIEF PROGRM OFFICER | D36: 9(7) | E36: 330408.08 | G36: =100000 -> 100000 | J36: =E36+F36+G36+H36+I36 -> 430408.08 | O36: 55215.579 | P36: =0.08*E36 -> 26432.647 | Q36: =P36+O36+N36+M36+L36+K36 -> 81648.225 | R36: =J36-Q36 -> 348759.86
A37: 3 | B37: ABDULKAREEM SOFIAT DAMOLA | C37: ASSISTANT PROGRM OFFICER | D37: 8(7) | E37: =287890.916666667*22/31 -> 204309.68 | G37: =100000*22/31 -> 70967.742 | J37: =E37+F37+G37+H37+I37 -> 275277.42 | O37: 27904.307 | P37: =0.08*E37 -> 16344.775 | Q37: =P37+O37+N37+M37+L37+K37 -> 44249.082 | R37: =J37-Q37 -> 231028.34
A38: 4 | B38: UBOSI CHIZOBA AUGUSTINE | C38: ASSISTANT PROGRM OFFICER | D38: 8(7) | E38: 287890.92 | G38: =100000 -> 100000 | J38: =E38+F38+G38+H38+I38 -> 387890.92 | O38: 48174.736 | P38: =0.08*E38 -> 23031.273 | Q38: =P38+O38+N38+M38+L38+K38 -> 71206.009 | R38: =J38-Q38 -> 316684.91
B39: TOTAL | C39: 4 | D39: =SUM(D35:D38) -> 0 | E39: =SUM(E35:E38) -> 1349282.3 | F39: =SUM(F35:F38) -> 0 | G39: =SUM(G35:G38) -> 410967.74 | H39: =SUM(H35:H38) -> 0 | I39: =SUM(I35:I38) -> 0 | J39: =SUM(J35:J38) -> 1760250 | K39: =SUM(K35:K38) -> 0 | ... R39: =SUM(R35:R38) -> 1424131.1
B41: ECON. DEV. & SOC. RESEARCH
A42: 1 | B42: YUSUF ADENIYI JAMIU | C42: PRINC. RESEARCH OFFICER | D42: 12(7) | E42: ='[2]Peculiar Allowance'!$H$40+'[2] FGN 2024 MGT Monthly'!$H$40 -> 441159 | G42: 110000 | J42: =E42+F42+G42+H42+I42 -> 551159 | O42: 75355.93 | P42: =0.08*E42 -> 35292.72 | Q42: =P42+O42+N42+M42+L42+K42 -> 110648.65 | R42: =J42-Q42 -> 440510.35
A43: 2 | B43: UDUIJE PAUL IFEANYICHUKWU | C43: RESEARCH OFFICER | D43: 10(7) | E43: =372145.333333333*22/33 -> 248096.89 | G43: =100000*22/31 -> 70967.742 | J43: =E43+F43+G43+H43+I43 -> 319064.63 | O43: 62127.267 | P43: =0.08*E43 -> 19847.751 | Q43: =P43+O43+N43+M43+L43+K43 -> 81975.018 | R43: =J43-Q43 -> 237089.61
B44: TOTAL | C44: 2 | E44: =SUM(E42:E43) -> 689255.89 | F44: =SUM(F42:F43) -> 0 | G44: =SUM(G42:G43) -> 180967.74 | H44: =SUM(H42:H43) -> 0 | I44: =SUM(I42:I43) -> 0 | J44: =SUM(J42:J43) -> 870223.63 | K44: =SUM(K42:K43) -> 0 | L44: =SUM(L42:L43) -> 0 | ... R44: =SUM(R42:R43) -> 677599.96
...

Sheet 2026 ENHANCED WELFARE
A1: NATIONAL INSTITUTE FOR LEGISLATIVE AND DEMOCRATIC STUDIES
A2: NEW PERMANENT STAFF ENHANCED WELFARE SCHEDULE 2026
B4: STAFF NAME | C4: DESIGNATION | D4: GRADE LEVEL | E4: AMOUNT | F4: Grade Level 01 - 13 | G4: Grade Level 14 - 17
E5: N | F5: N | G5: N
A6: S/N | B6: DG'S OFFICE
A7: 1 | B7: ATAKPO EMMANUEL OKON | C7: ASSISTANT DIRECTOR | D7: 15(7) | E7: 700000 | G7: =E7 -> 700000
A8: 2 | B8: BAFFA ALASAN | C8: CHIEF LEGAL OFFICCER | D8: 14(7) | E8: 500000 | G8: =E8 -> 500000
A9: 3 | B9: OCHUNU LYNDA IHEKANMANANDU | C9: PRINCIPAL LEGAL OFFICER | D9: 12(7) | E9: 400000 | F9: =E9 -> 400000
A10: 4 | B10: DORCAS MARK ESSET | C10: PRINCIPAL RESEARCH OFFICER | D10: 12(7) | E10: 400000 | F10: =E10 -> 400000
A11: 5 | B11: AYOPEMI AYOBAMI ANUOLUWAPO | C11: SENIOR LEGAL OFFICER | D11: 10(7) | E11: 300000 | F11: =E11 -> 300000
A12: 6 | B12: PRINCESS BARBARA AGOYE | C12: SENIORGI OFFICER | D12: 10(7) | E12: 300000 | F12: =E12 -> 300000
A13: 7 | B13: SANUSI MOHAMMED MATO | C13: SENIOR INF &COMM OFFICER | D13: 10(7) | E13: 300000 | F13: =E13 -> 300000
B14: TOTAL | C14: 7 | E14: =SUM(E7:E13) -> 2900000 | F14: =SUM(F7:F13) -> 1700000 | G14: =SUM(G7:G13) -> 1200000
B16: LEG. SUPPORT SEVICES
A17: 1 | B17: IBRAHIM BELLO IBRAHIM | C17: PRINC. RESEARCH OFFICER | D17: 12(7) | E17: 400000 | F17: =E17 -> 400000
A18: 2 | B18: ENI GEMOGONO-EVAL DAVID | C18: PRINC. RESEARCH OFFICER | D18: 12(7) | E18: 400000 | F18: =E18 -> 400000
A19: 3 | B19: AKEBONG SAMUEL ESSIEN | C19: PRINC. RESEARCH OFFICER | D19: 12(7) | E19: 400000 | F19: =E19 -> 400000
A20: 4 | B20: UDUAKOBONG JOHN OBOT | C20: SENIOR RESEARCH OFFICER | D20: 10(7) | E20: 300000 | F20: =E20 -> 300000
A21: 5 | B21: MATHIAS OMANULU AGBONI | C21: SENIOR RESEARCH OFFICER | D21: 10(7) | E21: 300000 | F21: =E21 -> 300000
A22: 6 | B22: OLUFADI MARIAM MOJISOLA | C22: SENIOR. RESEARCH OFFICER | D22: 10(7) | E22: 300000 | F22: =E22 -> 300000
A23: 7 | B23: EBUNILO ELVIS EBUKA | C23: RESEARCH OFFICER | D23: 9(7) | E23: 300000 | F23: =E23 -> 300000
A24: 8 | B24: MUHAMMED BASHIR ABDULLAHI | C24: RESEARCH OFFICER | D24: 9(7) | E24: 300000 | F24: =E24 -> 300000
A25: 9 | B25: BENEDICTA OGHECHI BNNAMANI | C25: RESEARCH OFFICER | D25: 9(7) | E25: 300000 | F25: =E25 -> 300000
A26: 10 | B26: GARBA EPHRAIM | C26: RESEARCH OFFICER | D26: 9(7) | E26: 300000 | F26: =E26 -> 300000
A27: 11 | B27: ABDURRAHMANZUWAIRA IBRAHIM | C27: RESEARCH OFFICER | D27: 9(7) | E27: 300000 | F27: =E27 -> 300000
B28: TOTAL | C28: 11 | E28: =SUM(E17:E27) -> 3600000 | F28: =SUM(F17:F27) -> 3600000 | G28: =SUM(G17:G27) -> 0
B30: DEMOCRACY & GOVERNANCE
A31: 1 | B31: NAPHTALI AMANA | C31: SENIOR RESEARCH OFFICER | D31: 10(7) | E31: 300000 | F31: =E31 -> 300000
A32: 2 | B32: UDOFA SAMUEL IME | C32: RESEARCH OFFICER | D32: 9(7) | E32: 300000 | F32: =E32 -> 300000
B33: TOTAL | C33: 2 | E33: =SUM(E31:E32) -> 600000 | F33: =SUM(F31:F32) -> 600000 | G33: =SUM(G31:G32) -> 0
B35: DEPARTMENT OF STUDIES
A36: 1 | B36: AHMAD IBRAHIM | C36: PROGRM OFFICER | D36: 14(7) | E36: 500000 | G36: =E36 -> 500000
A37: 2 | B37: INUWA ABDULLAHI GAMAU | C37: CHIEF PROGRM OFFICER | D37: 9(7) | E37: 300000 | F37: =E37 -> 300000
A38: 3 | B38: ABDULKAREEM SOFIAT DAMOLA | C38: ASSISTANT PROGRM OFFICER | D38: 8(7) | E38: 300000 | F38: =E38 -> 300000
A39: 4 | B39: UBOSI CHIZOBA AUGUSTINE | C39: ASSISTANT PROGRM OFFICER | D39: 8(7) | E39: 300000 | F39: =E39 -> 300000
B40: TOTAL | C40: 4 | E40: =SUM(E36:E39) -> 1400000 | F40: =SUM(F36:F39) -> 900000 | G40: =SUM(G36:G39) -> 500000
B42: ECON. DEV. & SOC. RESEARCH
A43: 1 | B43: FADILA JUMARE | C43: REASEARCH FELLOW 1 | D43: 14(7) | E43: 500000 | G43: =E43 -> 500000
A44: 2 | B44: JAMILU SANI | C44: REASEARCH FELLOW 2 | D44: 13(7) | E44: 500000 | F44: =E44 -> 500000
A45: 3 | B45: YUSUF ADENIYI JAMIU | C45: PRINC. RESEARCH OFFICER | D45: 12(7) | E45: 400000 | F45: =E45 -> 400000
...

Sheet Sheet7

Sheet Sheet6
A1: SUMMARY OF FUNDING
B2: PARTICULARS | C2: AMOUNT(N)
A3: 1 | B3: Permanent Staff | C3: ='[3]JANUARY 2026'!$J$249-'[3]JANUARY 2026'!$Q$249 -> 154016.01
B4: Total on Personnel Account | C4: =SUM(C3:C3) -> 154016.01
A6: 2 | B6: Contract Staff | C6: ='[4]Jan Contract'!$H$32 -> 11633711
A7: 3 | B7: Casual, Sabbatical & NYSC | C7: =18271171.91 -> 18271172
A8: 4 | B8: Consultancy Staff | C8: ='[4]Jan CONSULTANTS '!$D$21 -> 4600000
A9: 5 | B9: New Perm Staff | C9: ='FEB NEW PERM'!J77 -> 22256923
A10: 6 | B10: New Contract Staff | C10: ='[4]Jan New Contract '!$H$23 -> 9924247
B11: Total on Overhead Account | C11: =SUM(C6:C10) -> 66686053

Sheet Christmas 2024
A1: NATIONAL INSTITUTE FOR LEGISLATIVE AND DEMOCRATIC STUDIES
A2: NEW STAFF CHRISTMAS WELFARE DECEMBER, 2024
B4: STAFF NAME | C4: DESIGNATION | D4: GRADE LEVEL | E4: AMOUNT
E5: N
A6: S/N | B6: DG'S OFFICE
A7: 1 | B7: HOLINESS PAUL UDO | C7: ADMINISTRATION OFFICER, M&E | D7: 9(7) | E7: 54000
A8: 2 | B8: CHARITY UDO AKAN | C8: ADMINISTRATION OFFICER, M&E | D8: 9(7) | E8: 54000
A9: 3 | B9: SANI UMAR IBRAHIM | C9: STORE OFFICER | D9: 9(7) | E9: 54000
A10: 4 | B10: EDIDIONG EZEKIEL ATAT | C10: ASSIST PROCUREMENT OFFICER | D10: 8(7) | E10: 54000
A11: 5 | B11: ALIYU GARBA LERE | C11: ASSIST INFORMATION OFFICER | D11: 8(7) | E11: 54000
B12: TOTAL | C12: 5 | E12: =SUM(E7:E11) -> 270000
B14: INTERNAL AUDIT
A15: 1 | B15: HASSAN ABDULHADI | C15: AUDITOR 11 | D15: 10(7) | E15: 68000
C16: 1 | E16: =SUM(E15:E15) -> 68000
B18: LEG. SUPPORT SEVICES
A19: 1 | B19: UMAR MUSA PADAH | C19: PRINC. RESEARCH OFFICER | D19: 12(7) | E19: 68000
A20: 2 | B20: UMOH USENOBONG EMMANUEL | C20: SENIOR RESEARCH OFFICER | D20: 10(7) | E20: 68000
B21: TOTAL | C21: 2 | E21: =SUM(E19:E20) -> 136000
B23: DEMOCRACY & GOVERNANCE
A24: 1 | B24: MARTINS SOLOMON UDOM | C24: RESEARCH FELLOW 11 | D24: 13(7) | E24: 90000
A25: 2 | B25: OBOT ETIMBUK EMMANUEL | C25: PRINCIPAL INFO. OFFICER | D25: 12(7) | E25: 68000
A26: 3 | B26: ISHAKA DELE | C26: RESEARCH FELLOW 11 | D26: 13(7) | E26: 90000
B27: TOTAL | C27: 2 | E27: =SUM(E24:E26) -> 248000
B29: DEPARTMENT OF STUDIES
A30: 1 | B30: DR. IBANGA ISSAC JONAH | C30: ASSIST. CHIEF PROGRM OFFICER | D30: 13(7) | E30: 90000
A31: 2 | B31: UDONSI QUEENETH CHIWENDU | C31: ASSIST PROGRAMME OFFICER | D31: 8(7) | E31: 54000
B32: TOTAL | C32: 2 | E32: =SUM(E30:E31) -> 144000
B34: ECON. DEV. & SOC. RESEARCH
A35: 1 | B35: UDOKANG NSISONG BONIFACE | C35: PRINC. RESEARCH OFFICER | D35: 12(7) | E35: 68000
B36: TOTAL | C36: 1 | E36: =SUM(E35) -> 68000
B38: TRAINING & INT''L COOP
A39: 1 | B39: DR. SAMUEL AKPAN MBADAH | C39: ASSIST. CHIEF TRAINING OFFICER | D39: 13(7) | E39: 90000
B40: TOTAL | C40: 1 | E40: =SUM(E39:E39) -> 90000
B42: LEG, CTRE FOR SEC. ANALYSIS
A43: 1 | B43: UDOH ANIETIE JONAH | C43: RESEARCH OFFICER | D43: 9(7) | E43: 54000
A44: 2 | B44: ENYONGAMA SUNDAY THOMAS | C44: RESEARCH OFFICER | D44: 9(7) | E44: 54000
A45: 3 | B45: UDUAK MONDAY ETIAN | C45: ASSIST RESEARCH OFFICER | D45: 8(7) | E45: 54000
B46: TOTAL | C46: 3 | E46: =SUM(E43:E45) -> 162000
B48: FINANCE & ACCOUNTS
A49: 1 | B49: DAUDA HAMZA ILIYASU | C49: ASST. ACCOUNT. OFFICER | D49: 10(7) | E49: 68000
...

Sheet NEW STAFF BONUS
A1: NATIONAL INSTITUTE FOR LEGISLATIVE AND DEMOCRATIC STUDIES
A2: NEW STAFF END OF YEAR BONUS DECEMBER 2024
B4: STAFF NAME | C4: DESIGNATION | D4: GRADE LEVEL | E4: GROSS SALARY | F4: HALF SALARY
E5: N | F5: N
A6: S/N | B6: DG'S OFFICE
A7: 1 | B7: HOLINESS PAUL UDO | C7: ADMINISTRATION OFFICER, M&E | D7: 9(7) | E7: 315849 | F7: =E7/2 -> 157924.5
A8: 2 | B8: CHARITY UDO AKAN | C8: ADMINISTRATION OFFICER, M&E | D8: 9(7) | E8: 315849 | F8: =E8/2 -> 157924.5
A9: 3 | B9: SANI UMAR IBRAHIM | C9: STORE OFFICER | D9: 9(7) | E9: 315849 | F9: =E9/2 -> 157924.5
A10: 4 | B10: EDIDIONG EZEKIEL ATAT | C10: ASSIST PROCUREMENT OFFICER | D10: 8(7) | E10: 268287.58 | F10: =E10/2 -> 134143.79
A11: 5 | B11: ALIYU GARBA LERE | C11: ASSIST INFORMATION OFFICER | D11: 8(7) | E11: 268287.58 | F11: =E11/2 -> 134143.79
B12: TOTAL | C12: 5 | E12: 1484122.2 | F12: =SUM(F7:F11) -> 742061.08
B14: INTERNAL AUDIT
A15: 1 | B15: HASSAN ABDULHADI | C15: AUDITOR 11 | D15: 10(7) | E15: 353029.67 | F15: =E15/2 -> 176514.83
C16: 1 | E16: 353029.67 | F16: =SUM(F15:F15) -> 176514.83
B18: LEG. SUPPORT SEVICES
A19: 1 | B19: UMAR MUSA PADAH | C19: PRINC. RESEARCH OFFICER | D19: 12(7) | E19: 463512.5 | F19: =E19/2 -> 231756.25
A20: 2 | B20: UMOH USENOBONG EMMANUEL | C20: SENIOR RESEARCH OFFICER | D20: 10(7) | E20: 393029.67 | F20: =E20/2 -> 196514.83
B21: TOTAL | C21: 2 | E21: 856542.17 | F21: =SUM(F19:F20) -> 428271.08
B23: DEMOCRACY & GOVERNANCE
A24: 1 | B24: MARTINS SOLOMON UDOM | C24: RESEARCH FELLOW 11 | D24: 13(7) | E24: 510248.92 | F24: =E24/2 -> 255124.46
A25: 2 | B25: OBOT ETIMBUK EMMANUEL | C25: PRINCIPAL INFO. OFFICER | D25: 12(7) | E25: 463512.5 | F25: =E25/2 -> 231756.25
B26: TOTAL | C26: 2 | E26: 973761.42 | F26: =SUM(F24:F25) -> 486880.71
B28: DEPARTMENT OF STUDIES
A29: 1 | B29: DR. IBANGA ISSAC JONAH | C29: ASSIST. CHIEF PROGRM OFFICER | D29: 13(7) | E29: 510248.92 | F29: =E29/2 -> 255124.46
A30: 2 | B30: UDONSI QUEENETH CHIWENDU | C30: ASSIST PROGRAMME OFFICER | D30: 8(7) | E30: 318287.58 | F30: =E30/2 -> 159143.79
B31: TOTAL | C31: 2 | E31: 828536.5 | F31: =SUM(F29:F30) -> 414268.25
B33: ECON. DEV. & SOC. RESEARCH
A34: 1 | B34: UDOKANG NSISONG BONIFACE | C34: PRINC. RESEARCH OFFICER | D34: 12(7) | E34: 463512.5 | F34: =E34/2 -> 231756.25
B35: TOTAL | C35: 1 | E35: 463512.5 | F35: =SUM(F34) -> 231756.25
B37: TRAINING & INT''L COOP
A38: 1 | B38: DR. SAMUEL AKPAN MBADAH | C38: ASSIST. CHIEF TRAINING OFFICER | D38: 13(7) | E38: 460248.92 | F38: =E38/2 -> 230124.46
B39: TOTAL | C39: 1 | E39: 460248.92 | F39: =SUM(F38:F38) -> 230124.46
B41: LEG, CTRE FOR SEC. ANALYSIS
A42: 1 | B42: UDOH ANIETIE JONAH | C42: RESEARCH OFFICER | D42: 9(7) | E42: 355849 | F42: =E42/2 -> 177924.5
A43: 2 | B43: ENYONGAMA SUNDAY THOMAS | C43: RESEARCH OFFICER | D43: 9(7) | E43: 358160.16 | F43: =E43/2 -> 179080.08
A44: 3 | B44: UDUAK MONDAY ETIAN | C44: ASSIST RESEARCH OFFICER | D44: 8(7) | E44: 318287.58 | F44: =E44/2 -> 159143.79
B45: TOTAL | C45: 3 | E45: 1032296.7 | F45: =SUM(F42:F44) -> 516148.37
B47: FINANCE & ACCOUNTS
A48: 1 | B48: DAUDA HAMZA ILIYASU | C48: ASST. ACCOUNT. OFFICER | D48: 10(7) | E48: 353029.67 | F48: =E48/2 -> 176514.83
B49: TOTAL | C49: 1 | E49: 353029.67 | F49: =SUM(F48:F48) -> 176514.83
...

Sheet Sheet5

Sheet Placement
A1: NATIONAL INSTITUTE FOR LEGISLATIVE AND DEMOCRATIC STUDIES | G1: ='[1]FEB 08'!F8/'[1]FEB 08'!Q8 -> 0.3
A2: STAFF PAYROLL FOR THE MONTH OF SEPTEMBER 2024
E3: ='[1]FEB 08'!E11/'[1]FEB 08'!M11 -> #REF! | G3: ='[1]FEB 08'!F11/'[1]FEB 08'!Q11 -> #REF!
B4: STAFF NAME | C4: DESIGNATION | D4: GRADE LEVEL | E4: PRORATED BASIC SALARY | F4: ALLCE/ AREARS | G4: ALLOWANCE | H4: PRORATED ALLOWANCE | I4: DUTY ALLCE | J4: CURRENT GROSS SALARY | K4: PAYE | L4: PENSION | M4: NET SALARY
E5: N | F5: N | G5: N | H5: N | I5: N | J5: N
B7: HASSAN ABDULHADI | C7: AUDITOR 11 | D7: 8(7) | E7: =218287.583333333*(13/31) -> 91539.954 | H7: =50000*(13/31) -> 20967.742 | J7: =E7+H7 -> 112507.7
B8: HASSAN ABDULHADI | C8: AUDITOR 11 | D8: 10(7) | E8: =293029.666666667*(18/31) -> 170146.26 | H8: =60000*(18/31) -> 34838.71 | J8: =E8+H8 -> 204984.97
B9: TOTAL | E9: =SUM(E7:E8) -> 261686.21 | F9: =SUM(F7:F8) -> 0 | G9: =SUM(G7:G8) -> 0 | H9: =SUM(H7:H8) -> 55806.452 | I9: =SUM(I7:I8) -> 0 | J9: =SUM(J7:J8) -> 317492.66 | K9: =37571.65 -> 37571.65 | L9: 17463.007 | M9: =J9-K9-L9 -> 262458.01

Sheet New Staff PAYE
A1: NATIONAL INSTITUTE FOR LEGISLATIVE AND DEMOCRATIC STUDIES
A2: NATIONAL ASSEMBLY ABUJA
A3: TAX COMPUTATION FOR 2022
A4: S/NO | B4: NAME | C4: MONTHLY TOTAL SALARY | D4: NO OF MONTHS | E4: ANNUAL SALARY GROSSED UP | F4: NATIONAL HOUSING SCHEME = 2.5% OF BASIC SALARY | G4: PENSION CONTRIBUTION = 8% OF CONSOLIDATED | H4: NHIS | I4: NET SALARY (EXC OF CRA) | M4: CRA=#200,000+(20% 0F NET SALARY (EXC OF CRA) | N4: TOTAL RELIEF | O4: CHARGEABLE INCOME | P4: FIRST N300,000 @ 7% | Q4: NEXT N300,000 @ 11% | R4: NEXT N500,000 @ 15% | S4: NEXT N500,000@ 19% | T4: NEXT N1,600,000 @ 21% | U4: ABOVE N3,200,000 @ 24% | V4: ANNUAL TAX PAYABLE | X4: MONTHLY TAX PAYABLE | Y4: MINIMUM TAX PAYABLE | Z4: NEW ACTUAL TAX PAYABLE
A5: 1
A6: 3 | B6: OBOT ETIMBUK EMMANUEL | C6: 261891.25 | D6: 12 | E6: =C6*D6 -> 3142695 | G6: 209556.08 | I6: =E6-F6-G6-H6 -> 2933138.9 | J6: 200000 | K6: 0.2 | L6: =I6*K6 -> 586627.78 | M6: =J6+L6 -> 786627.78 | N6: =F6+G6+H6+M6 -> 996183.86 | O6: =E6-N6 -> 2146511.1 | P6: =IF(O6<300000,0.07*O6,21000) -> 21000 | Q6: =IF((O6-300000)<0,0,IF((O6-300000)<300000,0.11*(O6-300000),33000)) -> 33000 | R6: =IF((O6-600000)<0,0,IF((O6-600000)<500000,0.15*(O6-600000),75000)) -> 75000 | S6: =IF((O6-1100000)<0,0,IF((O6-1100000)<500000,0.19*(O6-1100000),95000)) -> 95000 | T6: =IF((O6-1600000)<0,0,IF((O6-1600000)<1600000,0.21*(O6-1600000),336000)) -> 114767.34 | V6: =P6+Q6+R6+S6+T6+U6 -> 338767.34 | W6: 12 | X6: =V6/W6 -> 28230.612 | Z6: =X6 -> 28230.612
A7: 4 | B7: HOLINESS PAUL UDO | C7: 231622.6 | D7: 12 | E7: =C7*D7 -> 2779471.2 | G7: 374638.96 | I7: =E7-F7-G7-H7 -> 2404832.2 | J7: 200000 | K7: 0.2 | L7: =I7*K7 -> 480966.45 | M7: =J7+L7 -> 680966.45 | N7: =F7+G7+H7+M7 -> 1055605.4 | O7: =E7-N7 -> 1723865.8 | P7: =IF(O7<300000,0.07*O7,21000) -> 21000 | Q7: =IF((O7-300000)<0,0,IF((O7-300000)<300000,0.11*(O7-300000),33000)) -> 33000 | R7: =IF((O7-600000)<0,0,IF((O7-600000)<500000,0.15*(O7-600000),75000)) -> 75000 | S7: =IF((O7-1100000)<0,0,IF((O7-1100000)<500000,0.19*(O7-1100000),95000)) -> 95000 | T7: =IF((O7-1600000)<0,0,IF((O7-1600000)<1600000,0.21*(O7-1600000),336000)) -> 26011.816 | V7: =P7+Q7+R7+S7+T7+U7 -> 250011.82 | W7: 12 | X7: =V7/W7 -> 20834.318 | Z7: =X7 -> 20834.318
A8: 5 | B8: CHARITY UDO AKAN | C8: 231622.6 | D8: 12 | E8: =C8*D8 -> 2779471.2 | G8: 245615.04 | I8: =E8-F8-G8-H8 -> 2533856.2 | J8: 200000 | K8: 0.2 | L8: =I8*K8 -> 506771.23 | M8: =J8+L8 -> 706771.23 | N8: =F8+G8+H8+M8 -> 952386.27 | O8: =E8-N8 -> 1827084.9 | P8: =IF(O8<300000,0.07*O8,21000) -> 21000 | Q8: =IF((O8-300000)<0,0,IF((O8-300000)<300000,0.11*(O8-300000),33000)) -> 33000 | R8: =IF((O8-600000)<0,0,IF((O8-600000)<500000,0.15*(O8-600000),75000)) -> 75000 | S8: =IF((O8-1100000)<0,0,IF((O8-1100000)<500000,0.19*(O8-1100000),95000)) -> 95000 | T8: =IF((O8-1600000)<0,0,IF((O8-1600000)<1600000,0.21*(O8-1600000),336000)) -> 47687.835 | V8: =P8+Q8+R8+S8+T8+U8 -> 271687.83 | W8: 12 | X8: =V8/W8 -> 22640.653 | Z8: =X8 -> 22640.653
A9: 6 | B9: SANI UMAR IBRAHIM | C9: 315849 | D9: 12 | E9: =C9*D9 -> 3790188 | G9: 209556.08 | I9: =E9-F9-G9-H9 -> 3580631.9 | J9: 200000 | K9: 0.2 | L9: =I9*K9 -> 716126.38 | M9: =J9+L9 -> 916126.38 | N9: =F9+G9+H9+M9 -> 1125682.5 | O9: =E9-N9 -> 2664505.5 | P9: =IF(O9<300000,0.07*O9,21000) -> 21000 | Q9: =IF((O9-300000)<0,0,IF((O9-300000)<300000,0.11*(O9-300000),33000)) -> 33000 | R9: =IF((O9-600000)<0,0,IF((O9-600000)<500000,0.15*(O9-600000),75000)) -> 75000 | S9: =IF((O9-1100000)<0,0,IF((O9-1100000)<500000,0.19*(O9-1100000),95000)) -> 95000 | T9: =IF((O9-1600000)<0,0,IF((O9-1600000)<1600000,0.21*(O9-1600000),336000)) -> 223546.16 | V9: =P9+Q9+R9+S9+T9+U9 -> 447546.16 | W9: 12 | X9: =V9/W9 -> 37295.514 | Z9: =X9 -> 37295.514
A10: 7 | B10: EDIDIONG EZEKIEL ATAT | C10: 169915.47 | D10: 12 | E10: =C10*D10 -> 2038985.6 | G10: 281308.48 | I10: =E10-F10-G10-H10 -> 1757677.2 | J10: 200000 | K10: 0.2 | L10: =I10*K10 -> 351535.43 | M10: =J10+L10 -> 551535.43 | N10: =F10+G10+H10+M10 -> 832843.91 | O10: =E10-N10 -> 1206141.7 | P10: =IF(O10<300000,0.07*O10,21000) -> 21000 | Q10: =IF((O10-300000)<0,0,IF((O10-300000)<300000,0.11*(O10-300000),33000)) -> 33000 | R10: =IF((O10-600000)<0,0,IF((O10-600000)<500000,0.15*(O10-600000),75000)) -> 75000 | S10: =IF((O10-1100000)<0,0,IF((O10-1100000)<500000,0.19*(O10-1100000),95000)) -> 20166.927 | T10: =IF((O10-1600000)<0,0,IF((O10-1600000)<1600000,0.21*(O10-1600000),336000)) -> 0 | V10: =P10+Q10+R10+S10+T10+U10 -> 149166.93 | W10: 12 | X10: =V10/W10 -> 12430.577 | Z10: =X10 -> 12430.577
A11: 8 | B11: ALIYU GARBA LERE | C11: 196744.23 | D11: 12 | E11: =C11*D11 -> 2360930.7 | G11: 374638.96 | I11: =E11-F11-G11-H11 -> 1986291.8 | J11: 200000 | K11: 0.2 | L11: =I11*K11 -> 397258.35 | M11: =J11+L11 -> 597258.35 | N11: =F11+G11+H11+M11 -> 971897.31 | O11: =E11-N11 -> 1389033.4 | P11: =IF(O11<300000,0.07*O11,21000) -> 21000 | Q11: =IF((O11-300000)<0,0,IF((O11-300000)<300000,0.11*(O11-300000),33000)) -> 33000 | R11: =IF((O11-600000)<0,0,IF((O11-600000)<500000,0.15*(O11-600000),75000)) -> 75000 | S11: =IF((O11-1100000)<0,0,IF((O11-1100000)<500000,0.19*(O11-1100000),95000)) -> 54916.35 | T11: =IF((O11-1600000)<0,0,IF((O11-1600000)<1600000,0.21*(O11-1600000),336000)) -> 0 | V11: =P11+Q11+R11+S11+T11+U11 -> 183916.35 | W11: 12 | X11: =V11/W11 -> 15326.362 | Z11: =X11 -> 15326.362
A13: 10 | B13: HASSAN ABDULHADI | C13: 268287.58 | D13: 12 | E13: =C13*D13 -> 3219451 | G13: 209556.08 | I13: =E13-F13-G13-H13 -> 3009894.9 | J13: 200000 | K13: 0.2 | L13: =I13*K13 -> 601978.98 | M13: =J13+L13 -> 801978.98 | N13: =F13+G13+H13+M13 -> 1011535.1 | O13: =E13-N13 -> 2207915.9 | P13: =IF(O13<300000,0.07*O13,21000) -> 21000 | Q13: =IF((O13-300000)<0,0,IF((O13-300000)<300000,0.11*(O13-300000),33000)) -> 33000 | R13: =IF((O13-600000)<0,0,IF((O13-600000)<500000,0.15*(O13-600000),75000)) -> 75000 | S13: =IF((O13-1100000)<0,0,IF((O13-1100000)<500000,0.19*(O13-1100000),95000)) -> 95000 | T13: =IF((O13-1600000)<0,0,IF((O13-1600000)<1600000,0.21*(O13-1600000),336000)) -> 127662.35 | V13: =P13+Q13+R13+S13+T13+U13 -> 351662.35 | W13: 12 | X13: =V13/W13 -> 29305.196 | Z13: =X13 -> 29305.196
A15: 4 | B15: UMAR MUSA PADAH | C15: 293557.92 | D15: 12 | E15: =C15*D15 -> 3522695 | G15: 374638.96 | I15: =E15-F15-G15-H15 -> 3148056 | J15: 200000 | K15: 0.2 | L15: =I15*K15 -> 629611.21 | M15: =J15+L15 -> 829611.21 | N15: =F15+G15+H15+M15 -> 1204250.2 | O15: =E15-N15 -> 2318444.8 | P15: =IF(O15<300000,0.07*O15,21000) -> 21000 | Q15: =IF((O15-300000)<0,0,IF((O15-300000)<300000,0.11*(O15-300000),33000)) -> 33000 | R15: =IF((O15-600000)<0,0,IF((O15-600000)<500000,0.15*(O15-600000),75000)) -> 75000 | S15: =IF((O15-1100000)<0,0,IF((O15-1100000)<500000,0.19*(O15-1100000),95000)) -> 95000 | T15: =IF((O15-1600000)<0,0,IF((O15-1600000)<1600000,0.21*(O15-1600000),336000)) -> 150873.41 | V15: =P15+Q15+R15+S15+T15+U15 -> 374873.41 | W15: 12 | X15: =V15/W15 -> 31239.451 | Z15: =X15 -> 31239.451
A16: 5 | B16: UMOH USENOBONG EMMANUEL | C16: 248918.79 | D16: 12 | E16: =C16*D16 -> 2987025.5 | G16: 245615.04 | I16: =E16-F16-G16-H16 -> 2741410.4 | J16: 200000 | K16: 0.2 | L16: =I16*K16 -> 548282.09 | M16: =J16+L16 -> 748282.09 | N16: =F16+G16+H16+M16 -> 993897.13 | O16: =E16-N16 -> 1993128.3 | P16: =IF(O16<300000,0.07*O16,21000) -> 21000 | Q16: =IF((O16-300000)<0,0,IF((O16-300000)<300000,0.11*(O16-300000),33000)) -> 33000 | R16: =IF((O16-600000)<0,0,IF((O16-600000)<500000,0.15*(O16-600000),75000)) -> 75000 | S16: =IF((O16-1100000)<0,0,IF((O16-1100000)<500000,0.19*(O16-1100000),95000)) -> 95000 | T16: =IF((O16-1600000)<0,0,IF((O16-1600000)<1600000,0.21*(O16-1600000),336000)) -> 82556.952 | V16: =P16+Q16+R16+S16+T16+U16 -> 306556.95 | W16: 12 | X16: =V16/W16 -> 25546.413 | Z16: =X16 -> 25546.413
A18: 7 | B18: MARTINS SOLOMON UDOM | C18: 374182.54 | D18: 12 | E18: =C18*D18 -> 4490190.5 | G18: 281308.48 | I18: =E18-F18-G18-H18 -> 4208882 | J18: 200000 | K18: 0.2 | L18: =I18*K18 -> 841776.4 | M18: =J18+L18 -> 1041776.4 | N18: =F18+G18+H18+M18 -> 1323084.9 | O18: =E18-N18 -> 3167105.6 | P18: =IF(O18<300000,0.07*O18,21000) -> 21000 | Q18: =IF((O18-300000)<0,0,IF((O18-300000)<300000,0.11*(O18-300000),33000)) -> 33000 | R18: =IF((O18-600000)<0,0,IF((O18-600000)<500000,0.15*(O18-600000),75000)) -> 75000 | S18: =IF((O18-1100000)<0,0,IF((O18-1100000)<500000,0.19*(O18-1100000),95000)) -> 95000 | T18: =IF((O18-1600000)<0,0,IF((O18-1600000)<1600000,0.21*(O18-1600000),336000)) -> 329092.17 | V18: =P18+Q18+R18+S18+T18+U18 -> 553092.17 | W18: 12 | X18: =V18/W18 -> 46091.014 | Z18: =X18 -> 46091.014
A20: 9 | B20: DR. IBANGA ISSAC JONAH | C20: 374182.54 | D20: 12 | E20: =C20*D20 -> 4490190.5 | G20: 209556.08 | I20: =E20-F20-G20-H20 -> 4280634.4 | J20: 200000 | K20: 0.2 | L20: =I20*K20 -> 856126.88 | M20: =J20+L20 -> 1056126.9 | N20: =F20+G20+H20+M20 -> 1265683 | O20: =E20-N20 -> 3224507.5 | P20: =IF(O20<300000,0.07*O20,21000) -> 21000 | Q20: =IF((O20-300000)<0,0,IF((O20-300000)<300000,0.11*(O20-300000),33000)) -> 33000 | R20: =IF((O20-600000)<0,0,IF((O20-600000)<500000,0.15*(O20-600000),75000)) -> 75000 | S20: =IF((O20-1100000)<0,0,IF((O20-1100000)<500000,0.19*(O20-1100000),95000)) -> 95000 | T20: =IF((O20-1600000)<0,0,IF((O20-1600000)<1600000,0.21*(O20-1600000),336000)) -> 336000 | U20: =24%*(O20-3200000) -> 5881.8022 | V20: =P20+Q20+R20+S20+T20+U20 -> 565881.8 | W20: 12 | X20: =V20/W20 -> 47156.817 | Z20: =X20 -> 47156.817
A21: 10 | B21: UDONSI QUEENETH CHIWENDU | C21: 233410.89 | D21: 12 | E21: =C21*D21 -> 2800930.7 | G21: 209556.08 | I21: =E21-F21-G21-H21 -> 2591374.7 | J21: 200000 | K21: 0.2 | L21: =I21*K21 -> 518274.93 | M21: =J21+L21 -> 718274.93 | N21: =F21+G21+H21+M21 -> 927831.01 | O21: =E21-N21 -> 1873099.7 | P21: =IF(O21<300000,0.07*O21,21000) -> 21000 | Q21: =IF((O21-300000)<0,0,IF((O21-300000)<300000,0.11*(O21-300000),33000)) -> 33000 | R21: =IF((O21-600000)<0,0,IF((O21-600000)<500000,0.15*(O21-600000),75000)) -> 75000 | S21: =IF((O21-1100000)<0,0,IF((O21-1100000)<500000,0.19*(O21-1100000),95000)) -> 95000 | T21: =IF((O21-1600000)<0,0,IF((O21-1600000)<1600000,0.21*(O21-1600000),336000)) -> 57350.942 | V21: =P21+Q21+R21+S21+T21+U21 -> 281350.94 | W21: 12 | X21: =V21/W21 -> 23445.912 | Z21: =X21 -> 23445.912
A23: 4 | B23: UDOKANG NSISONG BONIFACE | C23: 216305.83 | D23: 12 | E23: =C23*D23 -> 2595670 | G23: 374638.96 | I23: =E23-F23-G23-H23 -> 2221031 | J23: 200000 | K23: 0.2 | L23: =I23*K23 -> 444206.21 | M23: =J23+L23 -> 644206.21 | N23: =F23+G23+H23+M23 -> 1018845.2 | O23: =E23-N23 -> 1576824.8 | P23: =IF(O23<300000,0.07*O23,21000) -> 21000 | Q23: =IF((O23-300000)<0,0,IF((O23-300000)<300000,0.11*(O23-300000),33000)) -> 33000 | R23: =IF((O23-600000)<0,0,IF((O23-600000)<500000,0.15*(O23-600000),75000)) -> 75000 | S23: =IF((O23-1100000)<0,0,IF((O23-1100000)<500000,0.19*(O23-1100000),95000)) -> 90596.718 | T23: =IF((O23-1600000)<0,0,IF((O23-1600000)<1600000,0.21*(O23-1600000),336000)) -> 0 | V23: =P23+Q23+R23+S23+T23+U23 -> 219596.72 | W23: 12 | X23: =V23/W23 -> 18299.727 | Z23: =X23 -> 18299.727
A25: 6 | B25: DR. SAMUEL AKPAN MBADAH | C25: 337515.87 | D25: 12 | E25: =C25*D25 -> 4050190.5 | G25: 209556.08 | I25: =E25-F25-G25-H25 -> 3840634.4 | J25: 200000 | K25: 0.2 | L25: =I25*K25 -> 768126.88 | M25: =J25+L25 -> 968126.88 | N25: =F25+G25+H25+M25 -> 1177683 | O25: =E25-N25 -> 2872507.5 | P25: =IF(O25<300000,0.07*O25,21000) -> 21000 | Q25: =IF((O25-300000)<0,0,IF((O25-300000)<300000,0.11*(O25-300000),33000)) -> 33000 | R25: =IF((O25-600000)<0,0,IF((O25-600000)<500000,0.15*(O25-600000),75000)) -> 75000 | S25: =IF((O25-1100000)<0,0,IF((O25-1100000)<500000,0.19*(O25-1100000),95000)) -> 95000 | T25: =IF((O25-1600000)<0,0,IF((O25-1600000)<1600000,0.21*(O25-1600000),336000)) -> 267226.58 | V25: =P25+Q25+R25+S25+T25+U25 -> 491226.58 | W25: 12 | X25: =V25/W25 -> 40935.548 | Z25: =X25 -> 40935.548
A27: 8 | B27: UDOH ANIETIE JONAH | C27: 260955.93 | D27: 12 | E27: =C27*D27 -> 3131471.2 | G27: 374638.96 | I27: =E27-F27-G27-H27 -> 2756832.2 | J27: 200000 | K27: 0.2 | L27: =I27*K27 -> 551366.45 | M27: =J27+L27 -> 751366.45 | N27: =F27+G27+H27+M27 -> 1126005.4 | O27: =E27-N27 -> 2005465.8 | P27: =IF(O27<300000,0.07*O27,21000) -> 21000 | Q27: =IF((O27-300000)<0,0,IF((O27-300000)<300000,0.11*(O27-300000),33000)) -> 33000 | R27: =IF((O27-600000)<0,0,IF((O27-600000)<500000,0.15*(O27-600000),75000)) -> 75000 | S27: =IF((O27-1100000)<0,0,IF((O27-1100000)<500000,0.19*(O27-1100000),95000)) -> 95000 | T27: =IF((O27-1600000)<0,0,IF((O27-1600000)<1600000,0.21*(O27-1600000),336000)) -> 85147.816 | V27: =P27+Q27+R27+S27+T27+U27 -> 309147.82 | W27: 12 | X27: =V27/W27 -> 25762.318 | Z27: =X27 -> 25762.318
A28: 9 | B28: ENYONGAMA SUNDAY THOMAS | C28: 260955.93 | D28: 12 | E28: =C28*D28 -> 3131471.2 | G28: 209556.08 | I28: =E28-F28-G28-H28 -> 2921915.1 | J28: 200000 | K28: 0.2 | L28: =I28*K28 -> 584383.02 | M28: =J28+L28 -> 784383.02 | N28: =F28+G28+H28+M28 -> 993939.1 | O28: =E28-N28 -> 2137532.1 | P28: =IF(O28<300000,0.07*O28,21000) -> 21000 | Q28: =IF((O28-300000)<0,0,IF((O28-300000)<300000,0.11*(O28-300000),33000)) -> 33000 | R28: =IF((O28-600000)<0,0,IF((O28-600000)<500000,0.15*(O28-600000),75000)) -> 75000 | S28: =IF((O28-1100000)<0,0,IF((O28-1100000)<500000,0.19*(O28-1100000),95000)) -> 95000 | T28: =IF((O28-1600000)<0,0,IF((O28-1600000)<1600000,0.21*(O28-1600000),336000)) -> 112881.74 | V28: =P28+Q28+R28+S28+T28+U28 -> 336881.74 | W28: 12 | X28: =V28/W28 -> 28073.478 | Z28: =X28 -> 28073.478
