Workbook

Sheet FEBRUARY 2024
A1: NATIONAL INSTITUTE FOR LEGISLATIVE AND DEMOCRATIC STUDIES
A2: STAFF PAYROLL FOR THE MONTH OF FEBRUARY, 2024
E3: ='[1]FEB 08'!E11/'[1]FEB 08'!M11 -> #REF!
B4: STAFF NAME | C4: DESIGNATION | D4: GRADE LEVEL | E4: BASIC SALARY | F4: ALLCE/ AREARS | G4: ALLOWANCE | H4: ALLOWANCE | I4: DUTY ALLCE | J4: GROSS SALARY | K4: AUCTION | L4: COOP CONTR/SPEC SAVINGS | M4: COOP. LOAN RECOVERY | N4: NHF DED. | O4: PAYE | P4: EMPLOYEE PENSIONS | Q4: TOTAL DEDUCTION | R4: JANUARY, 2023 | S4: FEBRUARY, 2024
E5: N | G5: N | H5: N | I5: N | J5: N | K5: N | L5: N | M5: N | N5: N | O5: N | P5: N | Q5: N | R5: N | S5: N
A6: S/N | B6: DG'S OFFICE
A7: 1 | B7: PROF. ABUBAKAR O. SULAIMAN | C7: DIRECTOR GENERAL | D7: CONSOL | E7: 1659751.2 | F7: 627118.15 | G7: =250000 -> 250000 | I7: 25235 | J7: =E7+F7+G7+H7+I7 -> 2562104.3 | O7: 350184.01 | Q7: =O7+N7+M7+L7+K7+P7 -> 350184.01 | R7: 957684 | S7: =J7-Q7 -> 2211920.3
A8: 2 | B8: RAHEEM USMAN AYIGORO | C8: SA-INFRASTRUCTURE | D8: 16 (9) | E8: 762373.17 | F8: 262923.83 | H8: =90000 -> 90000 | I8: 0 | J8: =E8+F8+G8+H8+I8 -> 1115297 | L8: =100000 -> 100000 | O8: 130612.26 | P8: 60989.853 | Q8: =O8+N8+M8+L8+K8+P8 -> 291602.12 | R8: 358837.07 | S8: =J8-Q8 -> 823694.88
A9: 3 | B9: MARIAM MOHAMMED BELLO | C9: SA- SPECIAL DUTIES | D9: 16 (9) | E9: 762373.17 | F9: 251213.78 | H9: =90000 -> 90000 | I9: =100000+100000 -> 200000 | J9: =E9+F9+G9+H9+I9 -> 1303586.9 | O9: 180722.31 | Q9: =O9+N9+M9+L9+K9+P9 -> 180722.31 | R9: 620437.07 | S9: =J9-Q9 -> 1122864.6
A10: 4 | B10: DR IKEME ARTHUR J.O | C10: DEPUTY DIRECTOR, M&E | D10: 16 (9) | E10: 762373.17 | F10: 262923.83 | G10: 180000 | I10: 0 | J10: =E10+F10+G10+H10+I10 -> 1205297 | L10: =50000 -> 50000 | M10: 103000 | N10: 1066.3293 | O10: 147687.53 | P10: 60989.853 | Q10: =O10+N10+M10+L10+K10+P10 -> 362743.71 | R10: 377695.48 | S10: =J10-Q10 -> 842553.29
A11: 5 | B11: MOSHOOD M. OLALERE | C11: DEPUTY DIR. GENERAL SERVICE | D11: 16 (9) | E11: 762373.17 | F11: 262923.83 | H11: =80000+10000 -> 90000 | I11: 150000 | J11: =E11+F11+G11+H11+I11 -> 1265297 | L11: =20000+60000 -> 80000 | M11: ='[2]OCTOBER 2023 '!$D$193 -> 230499.8 | N11: 1066.3293 | O11: 159207.53 | P11: 60989.853 | Q11: =O11+N11+M11+L11+K11+P11 -> 531763.51 | R11: 268675.68 | S11: =J11-Q11 -> 733533.49
A12: 6 | B12: REKIYA IBRAHIM ATTAH | C12: DEPUTY DIRECTOR TRAINING | D12: 16 (9) | E12: 762373.17 | F12: 251213.78 | H12: =90000 -> 90000 | I12: 100000 | J12: =E12+F12+G12+H12+I12 -> 1203586.9 | L12: =50000 -> 50000 | M12: =91666.67 -> 91666.67 | O12: 161522.31 | Q12: =O12+N12+M12+L12+K12+P12 -> 303188.98 | R12: 397970.4 | S12: =J12-Q12 -> 900397.96
A13: 7 | B13: ANDRAWUS MUSA | C13: ASST. DIRECTOR, STORES | D13: 15(9) | E13: 620675.58 | F13: 214056.22 | H13: =80000 -> 80000 | I13: 50000 | J13: =E13+F13+G13+H13+I13 -> 964731.8 | L13: =50000-40000 -> 10000 | M13: =90000+110000 -> 200000 | N13: 837.6875 | O13: 113101.97 | P13: 49654.047 | Q13: =O13+N13+M13+L13+K13+P13 -> 373593.7 | R13: 212679.71 | S13: =J13-Q13 -> 591138.1
A14: 8 | B14: DR FRANCIS NDUM OJIE | C14: AD, TRAINING & IC./SA TO DG | D14: 15(7) | E14: 582118.08 | F14: 200751.53 | G14: 160000 | I14: =100000 -> 100000 | J14: =E14+F14+G14+H14+I14 -> 1042869.6 | N14: 775.496 | O14: 131263.11 | P14: 46569.447 | Q14: =O14+N14+M14+L14+K14+P14 -> 178608.05 | R14: 509327.94 | S14: =J14-Q14 -> 864261.56
A15: 9 | B15: ALI ABDULLAHI | C15: CHIEF ICT OFFICER | D15: 14(11) | E15: 484373.75 | F15: 178220.89 | H15: =70000 -> 70000 | I15: =0 -> 0 | J15: =E15+F15+G15+H15+I15 -> 732594.64 | O15: 77666.446 | P15: 38749.9 | Q15: =O15+N15+M15+L15+K15+P15 -> 116416.35 | R15: 298486.42 | S15: =J15-Q15 -> 616178.29
A16: 10 | B16: EMILY EKHIDE | C16: RESEARCH FELLOW 1 | D16: 14(10) | E16: 470498 | F16: 166536.14 | G16: 140000 | I16: 50000 | J16: =E16+F16+G16+H16+I16 -> 827034.14 | L16: =50000 -> 50000 | O16: 98255.433 | P16: 37639.84 | Q16: =O16+N16+M16+L16+K16+P16 -> 185895.27 | R16: 366666.37 | S16: =J16-Q16 -> 641138.87
A17: 11 | B17: DORIS DAKDA AARON | C17: RESEARCH FELLOW I | D17: 14(8) | E17: 442746.5 | F17: 156712.97 | G17: =140000 -> 140000 | I17: 150000 | J17: =E17+F17+G17+H17+I17 -> 889459.47 | L17: 70000 | O17: 112553.41 | P17: 35419.72 | Q17: =O17+N17+M17+L17+K17+P17 -> 217973.13 | R17: 430544.7 | S17: =J17-Q17 -> 671486.34
A18: 12 | B18: ABDULSALAM S. MUSTAPHA | C18: ASST. MANAGER ICT | D18: 13(11) | E18: 441804.92 | F18: 157040.82 | H18: 70000 | J18: =E18+F18+G18+H18+I18 -> 668845.73 | O18: 70147.087 | P18: 35344.393 | Q18: =O18+N18+M18+L18+K18+P18 -> 105491.48 | R18: 284617.02 | S18: =J18-Q18 -> 563354.25
A19: 13 | B19: PERCY TERFA GBAHABO | C19: HEAD, NILDS LIAISON OFFICE | D19: 13(10) | E19: 428915.92 | F19: 151816.66 | G19: =120000 -> 120000 | I19: 0 | J19: =E19+F19+G19+H19+I19 -> 700732.58 | L19: =50000 -> 50000 | M19: 0 | O19: 77470.374 | P19: 34313.273 | Q19: =O19+N19+M19+L19+K19+P19 -> 161783.65 | R19: 272510.99 | S19: =J19-Q19 -> 538948.93
A20: 14 | B20: HASSANA AHMED IBRAHIM | C20: PA- TO DG | D20: 13 (9) | E20: 416026.92 | F20: 147121.82 | G20: =120000 -> 120000 | I20: =100000 -> 100000 | J20: =E20+F20+G20+H20+I20 -> 783148.74 | L20: =30000-20000 -> 10000 | M20: =95833.33 -> 95833.33 | N20: 618.5315 | O20: 94274.903 | P20: 33282.153 | Q20: =O20+N20+M20+L20+K20+P20 -> 234008.92 | R20: 308882.53 | S20: =J20-Q20 -> 549139.82
A21: 15 | B21: ADUGBA RICHARD TERSEER | C21: PRINCIPAL INFO. OFFICER | D21: 12(9) | E21: 377895.17 | F21: 129717.87 | H21: =60000 -> 60000 | I21: 100000 | J21: =E21+F21+G21+H21+I21 -> 667613.04 | L21: =20000 -> 20000 | M21: =111833.33 -> 111833.33 | O21: 76138.069 | P21: 30231.613 | Q21: =O21+N21+M21+L21+K21+P21 -> 238203.01 | R21: 200205.9 | S21: =J21-Q21 -> 429410.02
A22: 16 | B22: LUCKY AGWOM | C22: RESEARCH ASSISTANT | D22: 12(7) | E22: 353512.5 | F22: 129167.42 | G22: =100000 -> 100000 | I22: 100000 | J22: =E22+F22+G22+H22+I22 -> 682679.92 | L22: 50000 | O22: 79511.115 | P22: 28281 | Q22: =O22+N22+M22+L22+K22+P22 -> 157792.11 | R22: 301705.41 | S22: =J22-Q22 -> 524887.8
A23: 17 | B23: IDRIS IBRAHIM | C23: PRINCIPAL RESEARCH OFFICER | D23: 12(7) | E23: 353512.5 | F23: ='January Arrears'!Q23 -> 126058.49 | G23: 110000 | I23: 0 | J23: =E23+F23+G23+H23+I23 -> 589570.99 | L23: 0 | O23: 62231.115 | P23: 28281 | Q23: =O23+N23+M23+L23+K23+P23 -> 90512.115 | R23: 968705.41 | S23: =J23-Q23 -> 499058.87
A24: 18 | B24: FARUQ ATOFARATI | C24: PA (SPECIAL DUTIES) TO DG | D24: 10(7) | E24: 293029.67 | F24: 105651.98 | H24: =50000+10000 -> 60000 | I24: 100000 | J24: =E24+F24+G24+H24+I24 -> 558681.64 | O24: 61147.427 | P24: 23442.373 | Q24: =O24+N24+M24+L24+K24+P24 -> 84589.8 | R24: 286230.26 | S24: =J24-Q24 -> 474091.84
A25: 19 | B25: ELIZABETH OGECHUKWU ONYEAKU | C25: ICT OFFICER | D25: 9(9) | E25: 270481.67 | F25: 100957.36 | H25: =50000+10000 -> 60000 | J25: =E25+F25+G25+H25+I25 -> 431439.02 | L25: 10000 | M25: =20000 -> 20000 | O25: 39052.313 | P25: 21638.533 | Q25: =O25+N25+M25+L25+K25+P25 -> 90690.846 | R25: 160472 | S25: =J25-Q25 -> 340748.18
A26: 20 | B26: VICTOR ASUKWO | C26: ICT OFFICER | D26: 9(9) | E26: 270481.67 | F26: 100957.36 | H26: =50000+10000 -> 60000 | J26: =E26+F26+G26+H26+I26 -> 431439.02 | O26: 39052.313 | P26: 21638.533 | Q26: =O26+N26+M26+L26+K26+P26 -> 60690.846 | R26: 190472 | S26: =J26-Q26 -> 370748.18
A27: 21 | B27: NNANDI LIVINUS ATURE | C27: RESEARCH ASSISTANT | D27: 9(9) | E27: 270481.67 | F27: 100957.36 | G27: =100000 -> 100000 | J27: =E27+F27+G27+H27+I27 -> 471439.02 | L27: =10000 -> 10000 | M27: =95833.33 -> 95833.33 | O27: 45772.313 | P27: 21638.533 | Q27: =O27+N27+M27+L27+K27+P27 -> 173244.18 | R27: 117918.67 | S27: =J27-Q27 -> 298194.85
A28: 22 | B28: ABDULRAHMAN A SULAIMAN | C28: STORE OFFICER | D28: 9(8) | E28: 263165.33 | F28: 98226.268 | H28: =60000 -> 60000 | J28: =E28+F28+G28+H28+I28 -> 421391.6 | L28: =20000 -> 20000 | M28: =17500 -> 17500 | O28: 37921.501 | P28: 21053.227 | Q28: =O28+N28+M28+L28+K28+P28 -> 96474.727 | R28: 149517.56 | S28: =J28-Q28 -> 324916.87
A29: 23 | B29: DARE SHEU MAGBON | C29: ADMINISTRATION OFFICER | D29: 9(7) | E29: 255849 | F29: 95495.18 | H29: =60000 -> 60000 | J29: =E29+F29+G29+H29+I29 -> 411344.18 | L29: =30000+20000 -> 50000 | M29: 0 | O29: 36790.688 | P29: 20467.92 | Q29: =O29+N29+M29+L29+K29+P29 -> 107258.61 | R29: 133563.13 | S29: =J29-Q29 -> 304085.57
A30: 24 | B30: ABUBAKAR SULAIMAN SODEEQ | C30: ADMINISTRATION OFFICER | D30: 9(7) | E30: 255849 | F30: 95495.18 | H30: =60000 -> 60000 | J30: =E30+F30+G30+H30+I30 -> 411344.18 | M30: 0 | O30: 36790.688 | P30: 20467.92 | Q30: =O30+N30+M30+L30+K30+P30 -> 57258.608 | R30: 183563.13 | S30: =J30-Q30 -> 354085.57
A31: 25 | B31: JIMOH ADEBAYO ZAKA | C31: ASST. OFFICER/COMM | D31: 9(9) | E31: 270481.67 | F31: 104411.79 | H31: =60000 -> 60000 | J31: =E31+F31+G31+H31+I31 -> 434893.46 | L31: =50000 -> 50000 | M31: 50000 | O31: 39052.313 | P31: 21638.533 | Q31: =O31+N31+M31+L31+K31+P31 -> 160690.85 | R31: 87017.565 | S31: =J31-Q31 -> 274202.61
A32: 26 | B32: MOHAMMED BELLO | C32: PROTOCOL ASSISTANT | D32: 8(9) | E32: 230631.92 | F32: 86687.598 | H32: =50000 -> 50000 | J32: =E32+F32+G32+H32+I32 -> 367319.51 | L32: =0 -> 0 | M32: =26666.67 -> 26666.67 | O32: 31213.136 | P32: 18450.553 | Q32: =O32+N32+M32+L32+K32+P32 -> 76330.359 | R32: 136064.51 | S32: =J32-Q32 -> 290989.16
A33: 27 | B33: HARUNA JIBRIL AMEH | C33: ASST. ADMIN. OFFICER | D33: 8(8) | E33: 224459.75 | F33: 87384.217 | H33: 50000 | J33: =E33+F33+G33+H33+I33 -> 361843.97 | L33: 20000 | M33: 0 | O33: 30259.166 | P33: 17956.78 | Q33: =O33+N33+M33+L33+K33+P33 -> 68215.946 | R33: 136816.37 | S33: =J33-Q33 -> 293628.02
B34: TOTAL | C34: 27 | E34: 13048608 | F34: =SUM(F7:F33) -> 4651742.3 | G34: =SUM(G7:G33) -> 1420000 | H34: =SUM(H7:H33) -> 1160000 | I34: =SUM(I7:I33) -> 1225235 | J34: =SUM(J7:J33) -> 21505585 | K34: =SUM(K7:K33) -> 0 | L34: =SUM(L7:L33) -> 700000 | M34: =SUM(M7:M33) -> 1042833.1 | ... Q34: =SUM(Q7:Q33) -> 5055927.2 | R34: 8717267.3 | S34: =SUM(S7:S33) -> 16449658
B36: INTERNAL AUDIT
A37: 1 | B37: OSANAIYE DAVID AKINYEMI | C37: DIRECTOR INTERNAL AUDIT | D37: 17(9) | E37: 1435720 | F37: 495145.5 | H37: =100000 -> 100000 | J37: =SUM(E37:I37) -> 2030865.5 | K37: ='FEBRUARY 2024'!F196 -> 0 | L37: 200000 | M37: 0 | O37: 251472.25 | P37: 114857.6 | Q37: =O37+N37+M37+L37+K37+P37 -> 566329.85 | R37: 589102.26 | S37: =J37-Q37 -> 1464535.6
A38: 2 | B38: JAMILA ABDUL | C38: AUDITOR II | D38: 10(7) | E38: 293029.67 | F38: =150718.948586667+37675.34 -> 188394.29 | H38: =60000 -> 60000 | J38: =SUM(E38:I38) -> 541423.96 | L38: =20000 -> 20000 | N38: 0 | O38: 42537.332 | P38: 23442.373 | Q38: =O38+N38+M38+L38+K38+P38 -> 85979.705 | R38: 139773.39 | S38: =J38-Q38 -> 455444.25
A39: 3 | B39: IJEOMA EWELUKWA | C39: AUDIT OFFICER | D39: 10(8) | E39: 300965.58 | F39: 110371.64 | H39: =50000+10000 -> 60000 | J39: =SUM(E39:I39) -> 471337.22 | L39: =10000 -> 10000 | O39: 43763.907 | P39: 24077.247 | Q39: =O39+N39+M39+L39+K39+P39 -> 77841.154 | R39: 196830.04 | S39: =J39-Q39 -> 393496.07
C40: 3 | E40: 2029715.2 | F40: =SUM(F37:F39) -> 793911.42 | G40: =SUM(G37:G39) -> 0 | H40: =SUM(H37:H39) -> 220000 | I40: =SUM(I37:I39) -> 0 | J40: =SUM(J37:J39) -> 3043626.7 | K40: =SUM(K37:K39) -> 0 | L40: =SUM(L37:L39) -> 230000 | M40: =SUM(M37:M39) -> 0 | N40: 0 | O40: 337773.49 | P40: =SUM(P37:P39) -> 162377.22 | Q40: =SUM(Q37:Q39) -> 730150.71 | R40: 925705.68 | S40: =SUM(S37:S39) -> 2313476
B42: LEG. SUPPORT SEVICES
...

Sheet MEMO
A2: NATIONAL INSTITUTE FOR LEGISLATIVE AND DEMOCRATIC STUDIES
A3: INTERNAL MEMO
A4: FROM : DEPUTY DIRECTOR, FINANCE AND ACCOUNTS
A5: THRU: DIRECTOR, FINANCE AND ACCOUNTS
A6: TO: DG
A7: 29TH JANUARY , 2021
A9: SUBJECT: PAYROLL FOR THE MONTH OF JANUARY, 2021
A10: Find below the details of NILDS Staff Payroll for the month of January, 2021
A13: TO: | C13: DIRECTOR, GENERAL
A14: THRU: | C14: DIRECTOR, FINANCE AND ACCOUNT
A15: FROM: | C15: DEPUTY DIRECTOR, FINANCE AND ACCOUNTS
A16: DATE: | C16: 29TH FEBRUARY 2024
A18: SUBJECT: PAYROLL FOR THE MONTH OF FEBRUARY 2024
A19: Find below the details of NILDS Staff Payroll for the Month of February 2024: | G19: NGN | H19: NGN
A20: GROSS SALARY FOR FEBRUARY, 2024 | H20: ='FEBRUARY 2024'!J194 -> 1.0195062e+08
A22: DEDUCTIONS
A23: COOP SOCIETY DEDUCTIONS ( CONTR.& SPEC. SAVINGS) | G23: ='FEBRUARY 2024'!L194 -> 5123500
A24: COOP LOAN RECOVERY | G24: ='FEBRUARY 2024'!M194 -> 7075945.7
A25: NHF DEDUCTIONS | G25: ='FEBRUARY 2024'!N194 -> 23031.314
A26: PAYE DEDUCTIONS | G26: ='FEBRUARY 2024'!O194 -> 11302661
A27: PENSION DEDUCTIONS | G27: ='Employee Pensions'!F195 -> 4564480.7
A28: TOTAL DEDUCTIONS FOR FEBRUARY 2024 | H28: =G23+G24+G26+G25+G27 -> 28089619
A29: NET PAY AS PER FEBRUARY, 2024 PAYROLL | H29: =H20-H28 -> 73861003
A30: NET PAY AS PER JANUARY, 2024 PAYROLL | H30: ='FEBRUARY 2024'!R194 -> 33238252
A31: NET INCREASE/ (DECREASE) IN PAY FOR FEBRUARY, 2024 | H31: =H29-H30 -> 40622751
A32: ANALYSED AS FOLLOWS:
A33: Effect of Cooperative Adjustment for February, 2024 | H33: -152000
A34: Effect of Increase in Gross Salary due to change in Salary Scale | H34: -26073904
A35: Effect of Increase in PAYE Tax due to change in Salary Scale | H35: =4073085.37 -> 4073085.4
A36: Effect of 8% Employee Pension deductions in February change in Salary Scale | H36: =4564480.74 -> 4564480.7
A37: Salary Arrears for the Month of January 2024 to all Staff | H37: =-22700818.57 -> -22700819
A38: Effect Regularisation of Taxes of Dr. Augustine Osigwe & 17 others | H38: =-224761.32 -> -224761.32
A39: Effect of Arrears due to over deduction of Tax of Dr. Idris Ibrahim | H39: =-6517.49 -> -6517.49
A40: Net Effect of Arrears ifo Jamila Abdul due to Upgrade in Grade Level | H40: -37675.34
A41: Net Effect of Research Allowance to Ayobolu Olufunso | H41: -64640
H42: =SUM(H33:H41) -> -40622751
E44: JANUARY, 2023 | G44: FEBRUARY, 2024
E45: No. of Staff | F45: N | G45: No. of Staff | H45: N
A46: 1 | B46: Director General's Office | E46: 33 | F46: ='FEBRUARY 2024'!R34 -> 8717267.3 | G46: ='FEBRUARY 2024'!C34 -> 27 | H46: ='FEBRUARY 2024'!S34 -> 16449658
A47: 2 | B47: Internal Audit | E47: 2 | F47: ='FEBRUARY 2024'!R40 -> 925705.68 | G47: ='FEBRUARY 2024'!C40 -> 3 | H47: ='FEBRUARY 2024'!S40 -> 2313476
...

Sheet January Arrears
A1: NATIONAL INSTITUTE FOR LEGISLATIVE AND DEMOCRATIC STUDIES
A2: COMPUTATION OF JANUARY 2024 ARREARS
E3: ='[1]FEB 08'!E11/'[1]FEB 08'!M11 -> #REF!
B4: STAFF NAME | C4: DESIGNATION | D4: GRADE LEVEL | E4: SALARY | F4: AREARS | G4: RESEARCH ALLOW. | H4: HARDSHIP ALLOW. | I4: DUTY ALLCE | J4: NEW GROSS SALARY | K4: OLD GROSS SALARY | L4: VARIATION IN GROSS SALARY | M4: NEW PAYE TAX | N4: OLD PAYE TAX | O4: VARIATION IN PAYE TAX | Q4: JANUARY 2024 ARREARS
L5: A | O5: B | Q5: (A-B)
A6: S/N | B6: DG'S OFFICE | E6: N | F6: N | G6: N | H6: N | I6: N | J6: N | K6: N | L6: N | M6: N | N6: N | O6: N | Q6: N
A7: 1 | B7: PROF. ABUBAKAR O. SULAIMAN | C7: DIRECTOR GENERAL | D7: CONSOL | E7: 1659751.2 | G7: =250000 -> 250000 | I7: 25235 | J7: =E7+F7+G7+H7+I7 -> 1934986.2 | K7: 1158849.8 | L7: =J7-K7 -> 776136.33 | M7: 350184.01 | N7: 201165.84 | O7: =M7-N7 -> 149018.17 | Q7: =L7-O7 -> 627118.15
A8: 2 | B8: RAHEEM USMAN AYIGORO | C8: SA-INFRASTRUCTURE | D8: 16 (9) | E8: 762373.17 | H8: =90000 -> 90000 | I8: 0 | J8: =E8+F8+G8+H8+I8 -> 852373.17 | K8: 541465.02 | L8: =J8-K8 -> 310908.14 | M8: 130612.26 | N8: 82627.951 | O8: =M8-N8 -> 47984.311 | Q8: =L8-O8 -> 262923.83
A9: 3 | B9: MARIAM MOHAMMED BELLO | C9: SA- SPECIAL DUTIES | D9: 16 (9) | E9: 762373.17 | H9: =90000 -> 90000 | I9: =100000+100000 -> 200000 | J9: =E9+F9+G9+H9+I9 -> 1052373.2 | K9: 741465.02 | L9: =J9-K9 -> 310908.14 | M9: 180722.31 | N9: 121027.95 | O9: =M9-N9 -> 59694.363 | Q9: =L9-O9 -> 251213.78
A10: 4 | B10: DR IKEME ARTHUR J.O | C10: DEPUTY DIRECTOR, M&E | D10: 16 (9) | E10: 762373.17 | G10: 180000 | I10: 0 | J10: =E10+F10+G10+H10+I10 -> 942373.17 | K10: 631465.02 | L10: =J10-K10 -> 310908.14 | M10: 147687.53 | N10: 99703.216 | O10: =M10-N10 -> 47984.311 | Q10: =L10-O10 -> 262923.83
A11: 5 | B11: MOSHOOD M. OLALERE | C11: PPS TO DG | D11: 16 (9) | E11: 762373.17 | H11: =80000+10000 -> 90000 | I11: 150000 | J11: =E11+F11+G11+H11+I11 -> 1002373.2 | K11: 691465.02 | L11: =J11-K11 -> 310908.14 | M11: 159207.53 | N11: 111223.22 | O11: =M11-N11 -> 47984.311 | Q11: =L11-O11 -> 262923.83
A12: 6 | B12: REKIYA IBRAHIM ATTAH | C12: DEPUTY DIRECTOR TRAINING | D12: 16 (9) | E12: 762373.17 | H12: =90000 -> 90000 | I12: 100000 | J12: =E12+F12+G12+H12+I12 -> 952373.17 | K12: 641465.02 | L12: =J12-K12 -> 310908.14 | M12: 161522.31 | N12: 101827.95 | O12: =M12-N12 -> 59694.363 | Q12: =L12-O12 -> 251213.78
A13: 7 | B13: ANDRAWUS MUSA | C13: ASST. DIRECTOR, STORES | D13: 15(9) | E13: 620675.58 | H13: =80000 -> 80000 | I13: 50000 | J13: =E13+F13+G13+H13+I13 -> 750675.58 | K13: 497553.5 | L13: =J13-K13 -> 253122.08 | M13: 113101.97 | N13: 74036.103 | O13: =M13-N13 -> 39065.863 | Q13: =L13-O13 -> 214056.22
A14: 8 | B14: DR FRANCIS NDUM OJIE | C14: AD, TRAINING & IC./SA TO DG | D14: 15(7) | E14: 582118.08 | G14: 160000 | I14: =100000 -> 100000 | J14: =E14+F14+G14+H14+I14 -> 842118.08 | K14: 604729.22 | L14: =J14-K14 -> 237388.86 | M14: 131263.11 | N14: 94625.782 | O14: =M14-N14 -> 36637.328 | Q14: =L14-O14 -> 200751.53
A15: 9 | B15: ALI ABDULLAHI | C15: CHIEF ICT OFFICER | D15: 14(11) | E15: 484373.75 | H15: =70000 -> 70000 | I15: =0 -> 0 | J15: =E15+F15+G15+H15+I15 -> 554373.75 | K15: 343333.04 | L15: =J15-K15 -> 211040.71 | M15: 77666.446 | N15: 44846.617 | O15: =M15-N15 -> 32819.829 | Q15: =L15-O15 -> 178220.89
A16: 10 | B16: EMILY EKHIDE | C16: RESEARCH FELLOW 1 | D16: 14(10) | E16: 470498 | G16: 140000 | I16: 50000 | J16: =E16+F16+G16+H16+I16 -> 660498 | K16: 463333.04 | L16: =J16-K16 -> 197164.96 | M16: 98255.433 | N16: 67626.609 | O16: =M16-N16 -> 30628.824 | Q16: =L16-O16 -> 166536.14
A17: 11 | B17: DORIS DAKDA AARON | C17: RESEARCH FELLOW I | D17: 14(8) | E17: 442746.5 | G17: =140000 -> 140000 | I17: 150000 | J17: =E17+F17+G17+H17+I17 -> 732746.5 | K17: 547211.37 | L17: =J17-K17 -> 185535.13 | M17: 112553.41 | N17: 83731.249 | O17: =M17-N17 -> 28822.159 | Q17: =L17-O17 -> 156712.97
A18: 12 | B18: ABDULSALAM S. MUSTAPHA | C18: ASST. MANAGER ICT | D18: 13(11) | E18: 441804.92 | H18: 70000 | J18: =E18+F18+G18+H18+I18 -> 511804.92 | K18: 326663.08 | L18: =J18-K18 -> 185141.84 | M18: 70147.087 | N18: 42046.064 | O18: =M18-N18 -> 28101.023 | Q18: =L18-O18 -> 157040.82
A19: 13 | B19: PERCY TERFA GBAHABO | C19: HEAD, NILDS LIAISON OFFICE | D19: 13(10) | E19: 428915.92 | G19: =120000 -> 120000 | I19: 0 | J19: =E19+F19+G19+H19+I19 -> 548915.92 | K19: 369177.65 | L19: =J19-K19 -> 179738.26 | M19: 77470.374 | N19: 49548.776 | O19: =M19-N19 -> 27921.598 | Q19: =L19-O19 -> 151816.66
A20: 14 | B20: HASSANA AHMED IBRAHIM | C20: PA- TRAINING | D20: 13 (9) | E20: 416026.92 | G20: =120000 -> 120000 | I20: =100000 -> 100000 | J20: =E20+F20+G20+H20+I20 -> 636026.92 | K20: 462001.06 | L20: =J20-K20 -> 174025.86 | M20: 94274.903 | N20: 67370.87 | O20: =M20-N20 -> 26904.033 | Q20: =L20-O20 -> 147121.82
A21: 15 | B21: ADUGBA RICHARD TERSEER | C21: PRINCIPAL INFO. OFFICER | D21: 12(9) | E21: 377895.17 | H21: =60000 -> 60000 | I21: 100000 | J21: =E21+F21+G21+H21+I21 -> 537895.17 | K21: 384537 | L21: =J21-K21 -> 153358.17 | M21: 76138.069 | N21: 52497.77 | O21: =M21-N21 -> 23640.299 | Q21: =L21-O21 -> 129717.87
A22: 16 | B22: LUCKY AGWOM | C22: PA-TECHNICAL | D22: 12(7) | E22: 353512.5 | G22: =100000 -> 100000 | I22: 100000 | J22: =E22+F22+G22+H22+I22 -> 553512.5 | K22: 400372.08 | L22: =J22-K22 -> 153140.42 | M22: 79511.115 | N22: 55538.105 | O22: =M22-N22 -> 23973.01 | Q22: =L22-O22 -> 129167.42
A23: 17 | B23: IDRIS IBRAHIM | C23: PRINCIPAL RESEARCH OFFICER | D23: 12(7) | E23: 353512.5 | G23: 110000 | I23: 0 | J23: =E23+F23+G23+H23+I23 -> 463512.5 | K23: =1015372.075-700000 -> 315372.07 | L23: =J23-K23 -> 148140.43 | M23: 62231.115 | N23: 40149.175 | O23: =M23-N23 -> 22081.939 | Q23: =L23-O23 -> 126058.49
A24: 18 | B24: FARUQ ATOFARATI | C24: PA (SPECIAL DUTIES) TO DG | D24: 10(7) | E24: 293029.67 | H24: =50000+10000 -> 60000 | I24: 100000 | J24: =E24+F24+G24+H24+I24 -> 453029.67 | K24: 328602.08 | L24: =J24-K24 -> 124427.59 | M24: 61147.427 | N24: 42371.816 | O24: =M24-N24 -> 18775.611 | Q24: =L24-O24 -> 105651.98
A25: 19 | B25: ELIZABETH OGECHUKWU ONYEAKU | C25: ICT OFFICER | D25: 9(9) | E25: 270481.67 | H25: =50000+10000 -> 60000 | J25: =E25+F25+G25+H25+I25 -> 330481.67 | K25: 213508.01 | L25: =J25-K25 -> 116973.66 | M25: 39052.313 | N25: 23036.012 | O25: =M25-N25 -> 16016.301 | Q25: =L25-O25 -> 100957.36
A26: 20 | B26: VICTOR ASUKWO | C26: ICT OFFICER | D26: 9(9) | E26: 270481.67 | H26: =50000+10000 -> 60000 | J26: =E26+F26+G26+H26+I26 -> 330481.67 | K26: 213508.01 | L26: =J26-K26 -> 116973.66 | M26: 39052.313 | N26: 23036.012 | O26: =M26-N26 -> 16016.301 | Q26: =L26-O26 -> 100957.36
A27: 21 | B27: NNANDI LIVINUS ATURE | C27: RESEARCH ASSISTANT | D27: 9(9) | E27: 270481.67 | G27: =100000 -> 100000 | J27: =E27+F27+G27+H27+I27 -> 370481.67 | K27: 253508.01 | L27: =J27-K27 -> 116973.66 | M27: 45772.313 | N27: 29756.012 | O27: =M27-N27 -> 16016.301 | Q27: =L27-O27 -> 100957.36
A28: 22 | B28: ABDULRAHMAN A SULAIMAN | C28: STORE OFFICER | D28: 9(8) | E28: 263165.33 | H28: =60000 -> 60000 | J28: =E28+F28+G28+H28+I28 -> 323165.33 | K28: 209356.05 | L28: =J28-K28 -> 113809.29 | M28: 37921.501 | N28: 22338.483 | O28: =M28-N28 -> 15583.018 | Q28: =L28-O28 -> 98226.268
A29: 23 | B29: DARE SHEU MAGBON | C29: ADMINISTRATION OFFICER | D29: 9(7) | E29: 255849 | H29: =60000 -> 60000 | J29: =E29+F29+G29+H29+I29 -> 315849 | K29: 205204.08 | L29: =J29-K29 -> 110644.92 | M29: 36790.688 | N29: 21640.953 | O29: =M29-N29 -> 15149.735 | Q29: =L29-O29 -> 95495.18
A30: 24 | B30: ABUBAKAR SULAIMAN SODEEQ | C30: ADMINISTRATION OFFICER | D30: 9(7) | E30: 255849 | H30: =60000 -> 60000 | J30: =E30+F30+G30+H30+I30 -> 315849 | K30: 205204.08 | L30: =J30-K30 -> 110644.92 | M30: 36790.688 | N30: 21640.953 | O30: =M30-N30 -> 15149.735 | Q30: =L30-O30 -> 95495.18
A31: 25 | B31: JIMOH ADEBAYO ZAKA | C31: ASST. OFFICER/COMM | D31: 9(9) | E31: 270481.67 | H31: =60000 -> 60000 | J31: =E31+F31+G31+H31+I31 -> 330481.67 | K31: 209356.05 | L31: =J31-K31 -> 121125.62 | M31: 39052.313 | N31: 22338.483 | O31: =M31-N31 -> 16713.83 | Q31: =L31-O31 -> 104411.79
A32: 26 | B32: MOHAMMED BELLO | C32: PROTOCOL ASSISTANT | D32: 8(9) | E32: 230631.92 | H32: =50000 -> 50000 | J32: =E32+F32+G32+H32+I32 -> 280631.92 | K32: 180304.07 | L32: =J32-K32 -> 100327.85 | M32: 31213.136 | N32: 17572.885 | O32: =M32-N32 -> 13640.251 | Q32: =L32-O32 -> 86687.598
A33: 27 | B33: HARUNA JIBRIL AMEH | C33: ASST. ADMIN. OFFICER | D33: 8(8) | E33: 224459.75 | H33: 50000 | J33: =E33+F33+G33+H33+I33 -> 274459.75 | K33: 173329.05 | L33: =J33-K33 -> 101130.7 | M33: 30259.166 | N33: 16512.682 | O33: =M33-N33 -> 13746.483 | Q33: =L33-O33 -> 87384.217
B34: TOTAL | C34: 27 | E34: =SUM(E7:E33) -> 13048608 | F34: =SUM(F7:F33) -> 0 | G34: =SUM(G7:G33) -> 1420000 | H34: =SUM(H7:H33) -> 1160000 | I34: =SUM(I7:I33) -> 1225235 | J34: =SUM(J7:J33) -> 16853843 | K34: =SUM(K7:K33) -> 11312338 | L34: =SUM(L7:L33) -> 5541505.6 | ... O34: =SUM(O7:O33) -> 889763.31 | Q34: =SUM(Q7:Q33) -> 4651742.3
B36: INTERNAL AUDIT
A37: 1 | B37: OSANAIYE DAVID AKINYEMI | C37: DIRECTOR INTERNAL AUDIT | D37: 17(9) | E37: 1435720 | H37: =100000 -> 100000 | J37: =E37+F37+G37+H37+I37 -> 1535720 | K37: 950209.06 | L37: =J37-K37 -> 585510.94 | M37: 251472.25 | N37: 161106.81 | O37: =M37-N37 -> 90365.441 | Q37: =L37-O37 -> 495145.5
A38: 2 | B38: JAMILA ABDUL | C38: SENIOR INTERNAL AUDITOR | D38: 10(7) | E38: 293029.67 | H38: =60000 -> 60000 | J38: =E38+F38+G38+H38+I38 -> 353029.67 | K38: 176816.1 | L38: =J38-K38 -> 176213.57 | M38: 42537.332 | N38: 17042.714 | O38: =M38-N38 -> 25494.618 | Q38: =L38-O38 -> 150718.95
A39: 3 | B39: IJEOMA EWELUKWA | C39: AUDIT OFFICER | D39: 10(8) | E39: 300965.58 | H39: =50000+10000 -> 60000 | J39: =E39+F39+G39+H39+I39 -> 360965.58 | K39: 233169.12 | L39: =J39-K39 -> 127796.47 | M39: 43763.907 | N39: 26339.078 | O39: =M39-N39 -> 17424.829 | Q39: =L39-O39 -> 110371.64
C40: 3 | E40: =SUM(E37:E39) -> 2029715.2 | F40: =SUM(F37:F39) -> 0 | G40: =SUM(G37:G39) -> 0 | H40: =SUM(H37:H39) -> 220000 | I40: =SUM(I37:I39) -> 0 | J40: =SUM(J37:J39) -> 2249715.2 | K40: 1360194.3 | L40: =SUM(L37:L39) -> 889520.97 | M40: =SUM(M37:M39) -> 337773.49 | N40: 204488.6 | O40: =SUM(O37:O39) -> 133284.89 | Q40: =SUM(Q37:Q39) -> 756236.08
B42: LEG. SUPPORT SEVICES
...

Sheet Tax Reg Sch. 
A1: NATIONAL INSTITUTE FOR LEGISLATIVE AND DEMOCRATIC STUDIES
A2: NATIONAL ASSEMBLY ABUJA
A3: TAX COMPUTATION FOR 2022
A4: S/NO | B4: NAME | C4: MONTHLY TOTAL SALARY | D4: NO OF MONTHS | E4: ANNUAL SALARY GROSSED UP | F4: NATIONAL HOUSING SCHEME = 2.5% OF BASIC SALARY | G4: PENSION CONTRIBUTION = 8% OF CONSOLIDATED | H4: NHIS | I4: NET SALARY (EXC OF CRA) | M4: CRA=#200,000+(20% 0F NET SALARY (EXC OF CRA) | N4: TOTAL RELIEF | O4: CHARGEABLE INCOME | P4: FIRST N300,000 @ 7% | Q4: NEXT N300,000 @ 11% | R4: NEXT N500,000 @ 15% | S4: NEXT N500,000@ 19% | T4: NEXT N1,600,000 @ 21% | U4: ABOVE N3,200,000 @ 24% | V4: ANNUAL TAX PAYABLE | X4: MONTHLY TAX PAYABLE | Y4: MINIMUM TAX PAYABLE | Z4: NEW ACTUAL TAX PAYABLE | AB4: Difference
A5: 1 | B5: DG'S OFFICE
A6: 3 | B6: PROF. ABUBAKAR O. SULAIMAN | C6: 1158849.8 | D6: 12 | E6: =C6*D6 -> 13906198 | I6: =E6-F6-G6-H6 -> 13906198 | J6: 200000 | K6: 0.2 | L6: =I6*K6 -> 2781239.6 | M6: =J6+L6 -> 2981239.6 | N6: =F6+G6+H6+M6 -> 2981239.6 | O6: =E6-N6 -> 10924958 | P6: =IF(O6<300000,0.07*O6,21000) -> 21000 | Q6: =IF((O6-300000)<0,0,IF((O6-300000)<300000,0.11*(O6-300000),33000)) -> 33000 | R6: =IF((O6-600000)<0,0,IF((O6-600000)<500000,0.15*(O6-600000),75000)) -> 75000 | S6: =IF((O6-1100000)<0,0,IF((O6-1100000)<500000,0.19*(O6-1100000),95000)) -> 95000 | T6: =IF((O6-1600000)<0,0,IF((O6-1600000)<1600000,0.21*(O6-1600000),336000)) -> 336000 | U6: =24%*(O6-3200000) -> 1853990 | V6: =P6+Q6+R6+S6+T6+U6 -> 2413990 | W6: 12 | X6: =V6/W6 -> 201165.84 | Z6: =X6 -> 201165.84 | AA6: 201165.84 | AB6: =Z6-AA6 -> 0
A7: 4 | B7: RAHEEM USMAN AYIGORO | C7: 541465.02 | D7: 12 | E7: =C7*D7 -> 6497580.3 | I7: =E7-F7-G7-H7 -> 6497580.3 | J7: 200000 | K7: 0.2 | L7: =I7*K7 -> 1299516.1 | M7: =J7+L7 -> 1499516.1 | N7: =F7+G7+H7+M7 -> 1499516.1 | O7: =E7-N7 -> 4998064.2 | P7: =IF(O7<300000,0.07*O7,21000) -> 21000 | Q7: =IF((O7-300000)<0,0,IF((O7-300000)<300000,0.11*(O7-300000),33000)) -> 33000 | R7: =IF((O7-600000)<0,0,IF((O7-600000)<500000,0.15*(O7-600000),75000)) -> 75000 | S7: =IF((O7-1100000)<0,0,IF((O7-1100000)<500000,0.19*(O7-1100000),95000)) -> 95000 | T7: =IF((O7-1600000)<0,0,IF((O7-1600000)<1600000,0.21*(O7-1600000),336000)) -> 336000 | U7: =24%*(O7-3200000) -> 431535.42 | V7: =P7+Q7+R7+S7+T7+U7 -> 991535.42 | W7: 12 | X7: =V7/W7 -> 82627.951 | Z7: =X7 -> 82627.951 | AA7: 82627.951 | AB7: =Z7-AA7 -> 0
A8: 5 | B8: MARIAM MOHAMMED BELLO | C8: 741465.02 | D8: 12 | E8: =C8*D8 -> 8897580.3 | I8: =E8-F8-G8-H8 -> 8897580.3 | J8: 200000 | K8: 0.2 | L8: =I8*K8 -> 1779516.1 | M8: =J8+L8 -> 1979516.1 | N8: =F8+G8+H8+M8 -> 1979516.1 | O8: =E8-N8 -> 6918064.2 | P8: =IF(O8<300000,0.07*O8,21000) -> 21000 | Q8: =IF((O8-300000)<0,0,IF((O8-300000)<300000,0.11*(O8-300000),33000)) -> 33000 | R8: =IF((O8-600000)<0,0,IF((O8-600000)<500000,0.15*(O8-600000),75000)) -> 75000 | S8: =IF((O8-1100000)<0,0,IF((O8-1100000)<500000,0.19*(O8-1100000),95000)) -> 95000 | T8: =IF((O8-1600000)<0,0,IF((O8-1600000)<1600000,0.21*(O8-1600000),336000)) -> 336000 | U8: =24%*(O8-3200000) -> 892335.42 | V8: =P8+Q8+R8+S8+T8+U8 -> 1452335.4 | W8: 12 | X8: =V8/W8 -> 121027.95 | Z8: =X8 -> 121027.95 | AA8: 121027.95 | AB8: =Z8-AA8 -> 0
A9: 6 | B9: DR IKEME ARTHUR J.O | C9: 631465.02 | D9: 12 | E9: =C9*D9 -> 7577580.3 | F9: ='[4]JANUARY 2024'!$V$10*12 -> 12795.951 | I9: =E9-F9-G9-H9 -> 7564784.3 | J9: 200000 | K9: 0.2 | L9: =I9*K9 -> 1512956.9 | M9: =J9+L9 -> 1712956.9 | N9: =F9+G9+H9+M9 -> 1725752.8 | O9: =E9-N9 -> 5851827.5 | P9: =IF(O9<300000,0.07*O9,21000) -> 21000 | Q9: =IF((O9-300000)<0,0,IF((O9-300000)<300000,0.11*(O9-300000),33000)) -> 33000 | R9: =IF((O9-600000)<0,0,IF((O9-600000)<500000,0.15*(O9-600000),75000)) -> 75000 | S9: =IF((O9-1100000)<0,0,IF((O9-1100000)<500000,0.19*(O9-1100000),95000)) -> 95000 | T9: =IF((O9-1600000)<0,0,IF((O9-1600000)<1600000,0.21*(O9-1600000),336000)) -> 336000 | U9: =24%*(O9-3200000) -> 636438.59 | V9: =P9+Q9+R9+S9+T9+U9 -> 1196438.6 | W9: 12 | X9: =V9/W9 -> 99703.216 | Z9: =X9 -> 99703.216 | AA9: 99703.216 | AB9: =Z9-AA9 -> 0
A10: 7 | B10: MOSHOOD M. OLALERE | C10: 691465.02 | D10: 12 | E10: =C10*D10 -> 8297580.3 | F10: ='[4]JANUARY 2024'!$V$10*12 -> 12795.951 | I10: =E10-F10-G10-H10 -> 8284784.3 | J10: 200000 | K10: 0.2 | L10: =I10*K10 -> 1656956.9 | M10: =J10+L10 -> 1856956.9 | N10: =F10+G10+H10+M10 -> 1869752.8 | O10: =E10-N10 -> 6427827.5 | P10: =IF(O10<300000,0.07*O10,21000) -> 21000 | Q10: =IF((O10-300000)<0,0,IF((O10-300000)<300000,0.11*(O10-300000),33000)) -> 33000 | R10: =IF((O10-600000)<0,0,IF((O10-600000)<500000,0.15*(O10-600000),75000)) -> 75000 | S10: =IF((O10-1100000)<0,0,IF((O10-1100000)<500000,0.19*(O10-1100000),95000)) -> 95000 | T10: =IF((O10-1600000)<0,0,IF((O10-1600000)<1600000,0.21*(O10-1600000),336000)) -> 336000 | U10: =24%*(O10-3200000) -> 774678.59 | V10: =P10+Q10+R10+S10+T10+U10 -> 1334678.6 | W10: 12 | X10: =V10/W10 -> 111223.22 | Z10: =X10 -> 111223.22 | AA10: 111223.22 | AB10: =Z10-AA10 -> 0
A11: 8 | B11: REKIYA IBRAHIM ATTAH | C11: 641465.02 | D11: 12 | E11: =C11*D11 -> 7697580.3 | I11: =E11-F11-G11-H11 -> 7697580.3 | J11: 200000 | K11: 0.2 | L11: =I11*K11 -> 1539516.1 | M11: =J11+L11 -> 1739516.1 | N11: =F11+G11+H11+M11 -> 1739516.1 | O11: =E11-N11 -> 5958064.2 | P11: =IF(O11<300000,0.07*O11,21000) -> 21000 | Q11: =IF((O11-300000)<0,0,IF((O11-300000)<300000,0.11*(O11-300000),33000)) -> 33000 | R11: =IF((O11-600000)<0,0,IF((O11-600000)<500000,0.15*(O11-600000),75000)) -> 75000 | S11: =IF((O11-1100000)<0,0,IF((O11-1100000)<500000,0.19*(O11-1100000),95000)) -> 95000 | T11: =IF((O11-1600000)<0,0,IF((O11-1600000)<1600000,0.21*(O11-1600000),336000)) -> 336000 | U11: =24%*(O11-3200000) -> 661935.42 | V11: =P11+Q11+R11+S11+T11+U11 -> 1221935.4 | W11: 12 | X11: =V11/W11 -> 101827.95 | Z11: =X11 -> 101827.95 | AA11: 101827.95 | AB11: =Z11-AA11 -> 0
A12: 9 | B12: ANDRAWUS MUSA | C12: 497553.5 | D12: 12 | E12: =C12*D12 -> 5970642 | F12: ='[4]JANUARY 2024'!$V$13*12 -> 10052.25 | I12: =E12-F12-G12-H12 -> 5960589.8 | J12: 200000 | K12: 0.2 | L12: =I12*K12 -> 1192118 | M12: =J12+L12 -> 1392118 | N12: =F12+G12+H12+M12 -> 1402170.2 | O12: =E12-N12 -> 4568471.8 | P12: =IF(O12<300000,0.07*O12,21000) -> 21000 | Q12: =IF((O12-300000)<0,0,IF((O12-300000)<300000,0.11*(O12-300000),33000)) -> 33000 | R12: =IF((O12-600000)<0,0,IF((O12-600000)<500000,0.15*(O12-600000),75000)) -> 75000 | S12: =IF((O12-1100000)<0,0,IF((O12-1100000)<500000,0.19*(O12-1100000),95000)) -> 95000 | T12: =IF((O12-1600000)<0,0,IF((O12-1600000)<1600000,0.21*(O12-1600000),336000)) -> 336000 | U12: =24%*(O12-3200000) -> 328433.24 | V12: =P12+Q12+R12+S12+T12+U12 -> 888433.24 | W12: 12 | X12: =V12/W12 -> 74036.103 | Z12: =X12 -> 74036.103 | AA12: 74036.103 | AB12: =Z12-AA12 -> 0
A13: 10 | B13: DR FRANCIS NDUM OJIE | C13: 604729.22 | D13: 12 | E13: =C13*D13 -> 7256750.7 | F13: ='[4]JANUARY 2024'!$V$14*12 -> 9305.952 | I13: =E13-F13-G13-H13 -> 7247444.7 | J13: 200000 | K13: 0.2 | L13: =I13*K13 -> 1449488.9 | M13: =J13+L13 -> 1649488.9 | N13: =F13+G13+H13+M13 -> 1658794.9 | O13: =E13-N13 -> 5597955.8 | P13: =IF(O13<300000,0.07*O13,21000) -> 21000 | Q13: =IF((O13-300000)<0,0,IF((O13-300000)<300000,0.11*(O13-300000),33000)) -> 33000 | R13: =IF((O13-600000)<0,0,IF((O13-600000)<500000,0.15*(O13-600000),75000)) -> 75000 | S13: =IF((O13-1100000)<0,0,IF((O13-1100000)<500000,0.19*(O13-1100000),95000)) -> 95000 | T13: =IF((O13-1600000)<0,0,IF((O13-1600000)<1600000,0.21*(O13-1600000),336000)) -> 336000 | U13: =24%*(O13-3200000) -> 575509.38 | V13: =P13+Q13+R13+S13+T13+U13 -> 1135509.4 | W13: 12 | X13: =V13/W13 -> 94625.782 | Z13: =X13 -> 94625.782 | AA13: 94625.782 | AB13: =Z13-AA13 -> 0
A14: 11 | B14: ALI ABDULLAHI | C14: 343333.04 | D14: 12 | E14: =C14*D14 -> 4119996.4 | I14: =E14-F14-G14-H14 -> 4119996.4 | J14: 200000 | K14: 0.2 | L14: =I14*K14 -> 823999.28 | M14: =J14+L14 -> 1023999.3 | N14: =F14+G14+H14+M14 -> 1023999.3 | O14: =E14-N14 -> 3095997.1 | P14: =IF(O14<300000,0.07*O14,21000) -> 21000 | Q14: =IF((O14-300000)<0,0,IF((O14-300000)<300000,0.11*(O14-300000),33000)) -> 33000 | R14: =IF((O14-600000)<0,0,IF((O14-600000)<500000,0.15*(O14-600000),75000)) -> 75000 | S14: =IF((O14-1100000)<0,0,IF((O14-1100000)<500000,0.19*(O14-1100000),95000)) -> 95000 | T14: =IF((O14-1600000)<0,0,IF((O14-1600000)<1600000,0.21*(O14-1600000),336000)) -> 314159.4 | V14: =P14+Q14+R14+S14+T14+U14 -> 538159.4 | W14: 12 | X14: =V14/W14 -> 44846.617 | Z14: =X14 -> 44846.617 | AA14: 44846.617 | AB14: =Z14-AA14 -> 0
A15: 12 | B15: EMILY EKHIDE | C15: 463333.04 | D15: 12 | E15: =C15*D15 -> 5559996.4 | I15: =E15-F15-G15-H15 -> 5559996.4 | J15: 200000 | K15: 0.2 | L15: =I15*K15 -> 1111999.3 | M15: =J15+L15 -> 1311999.3 | N15: =F15+G15+H15+M15 -> 1311999.3 | O15: =E15-N15 -> 4247997.1 | P15: =IF(O15<300000,0.07*O15,21000) -> 21000 | Q15: =IF((O15-300000)<0,0,IF((O15-300000)<300000,0.11*(O15-300000),33000)) -> 33000 | R15: =IF((O15-600000)<0,0,IF((O15-600000)<500000,0.15*(O15-600000),75000)) -> 75000 | S15: =IF((O15-1100000)<0,0,IF((O15-1100000)<500000,0.19*(O15-1100000),95000)) -> 95000 | T15: =IF((O15-1600000)<0,0,IF((O15-1600000)<1600000,0.21*(O15-1600000),336000)) -> 336000 | U15: =24%*(O15-3200000) -> 251519.31 | V15: =P15+Q15+R15+S15+T15+U15 -> 811519.31 | W15: 12 | X15: =V15/W15 -> 67626.609 | Z15: =X15 -> 67626.609 | AA15: 46666.667 | AB15: =Z15-AA15 -> 20959.943
A16: 13 | B16: DORIS DAKDA AARON | C16: 547211.37 | D16: 12 | E16: =C16*D16 -> 6566536.4 | I16: =E16-F16-G16-H16 -> 6566536.4 | J16: 200000 | K16: 0.2 | L16: =I16*K16 -> 1313307.3 | M16: =J16+L16 -> 1513307.3 | N16: =F16+G16+H16+M16 -> 1513307.3 | O16: =E16-N16 -> 5053229.1 | P16: =IF(O16<300000,0.07*O16,21000) -> 21000 | Q16: =IF((O16-300000)<0,0,IF((O16-300000)<300000,0.11*(O16-300000),33000)) -> 33000 | R16: =IF((O16-600000)<0,0,IF((O16-600000)<500000,0.15*(O16-600000),75000)) -> 75000 | S16: =IF((O16-1100000)<0,0,IF((O16-1100000)<500000,0.19*(O16-1100000),95000)) -> 95000 | T16: =IF((O16-1600000)<0,0,IF((O16-1600000)<1600000,0.21*(O16-1600000),336000)) -> 336000 | U16: =24%*(O16-3200000) -> 444774.99 | V16: =P16+Q16+R16+S16+T16+U16 -> 1004775 | W16: 12 | X16: =V16/W16 -> 83731.249 | Z16: =X16 -> 83731.249 | AA16: 46666.667 | AB16: =Z16-AA16 -> 37064.583
A17: 14 | B17: ABDULSALAM S. MUSTAPHA | C17: 326663.08 | D17: 12 | E17: =C17*D17 -> 3919956.9 | I17: =E17-F17-G17-H17 -> 3919956.9 | J17: 200000 | K17: 0.2 | L17: =I17*K17 -> 783991.39 | M17: =J17+L17 -> 983991.39 | N17: =F17+G17+H17+M17 -> 983991.39 | O17: =E17-N17 -> 2935965.5 | P17: =IF(O17<300000,0.07*O17,21000) -> 21000 | Q17: =IF((O17-300000)<0,0,IF((O17-300000)<300000,0.11*(O17-300000),33000)) -> 33000 | R17: =IF((O17-600000)<0,0,IF((O17-600000)<500000,0.15*(O17-600000),75000)) -> 75000 | S17: =IF((O17-1100000)<0,0,IF((O17-1100000)<500000,0.19*(O17-1100000),95000)) -> 95000 | T17: =IF((O17-1600000)<0,0,IF((O17-1600000)<1600000,0.21*(O17-1600000),336000)) -> 280552.76 | V17: =P17+Q17+R17+S17+T17+U17 -> 504552.76 | W17: 12 | X17: =V17/W17 -> 42046.064 | Z17: =X17 -> 42046.064 | AA17: 42046.064 | AB17: =Z17-AA17 -> 0
A18: 15 | B18: PERCY TERFA GBAHABO | C18: 369177.65 | D18: 12 | E18: =C18*D18 -> 4430131.8 | I18: =E18-F18-G18-H18 -> 4430131.8 | J18: 200000 | K18: 0.2 | L18: =I18*K18 -> 886026.37 | M18: =J18+L18 -> 1086026.4 | N18: =F18+G18+H18+M18 -> 1086026.4 | O18: =E18-N18 -> 3344105.5 | P18: =IF(O18<300000,0.07*O18,21000) -> 21000 | Q18: =IF((O18-300000)<0,0,IF((O18-300000)<300000,0.11*(O18-300000),33000)) -> 33000 | R18: =IF((O18-600000)<0,0,IF((O18-600000)<500000,0.15*(O18-600000),75000)) -> 75000 | S18: =IF((O18-1100000)<0,0,IF((O18-1100000)<500000,0.19*(O18-1100000),95000)) -> 95000 | T18: =IF((O18-1600000)<0,0,IF((O18-1600000)<1600000,0.21*(O18-1600000),336000)) -> 336000 | U18: =24%*(O18-3200000) -> 34585.314 | V18: =P18+Q18+R18+S18+T18+U18 -> 594585.31 | W18: 12 | X18: =V18/W18 -> 49548.776 | Z18: =X18 -> 49548.776 | AA18: 46666.667 | AB18: =Z18-AA18 -> 2882.1095
A19: 16 | B19: HASSANA AHMED IBRAHIM | C19: 462001.06 | D19: 12 | E19: =C19*D19 -> 5544012.7 | I19: =E19-F19-G19-H19 -> 5544012.7 | J19: 200000 | K19: 0.2 | L19: =I19*K19 -> 1108802.5 | M19: =J19+L19 -> 1308802.5 | N19: =F19+G19+H19+M19 -> 1308802.5 | O19: =E19-N19 -> 4235210.2 | P19: =IF(O19<300000,0.07*O19,21000) -> 21000 | Q19: =IF((O19-300000)<0,0,IF((O19-300000)<300000,0.11*(O19-300000),33000)) -> 33000 | R19: =IF((O19-600000)<0,0,IF((O19-600000)<500000,0.15*(O19-600000),75000)) -> 75000 | S19: =IF((O19-1100000)<0,0,IF((O19-1100000)<500000,0.19*(O19-1100000),95000)) -> 95000 | T19: =IF((O19-1600000)<0,0,IF((O19-1600000)<1600000,0.21*(O19-1600000),336000)) -> 336000 | U19: =24%*(O19-3200000) -> 248450.44 | V19: =P19+Q19+R19+S19+T19+U19 -> 808450.44 | W19: 12 | X19: =V19/W19 -> 67370.87 | Z19: =X19 -> 67370.87 | AA19: 46666.667 | AB19: =Z19-AA19 -> 20704.204
A20: 17 | B20: ADUGBA RICHARD TERSEER | C20: 384537 | D20: 12 | E20: =C20*D20 -> 4614444 | I20: =E20-F20-G20-H20 -> 4614444 | J20: 200000 | K20: 0.2 | L20: =I20*K20 -> 922888.8 | M20: =J20+L20 -> 1122888.8 | N20: =F20+G20+H20+M20 -> 1122888.8 | O20: =E20-N20 -> 3491555.2 | P20: =IF(O20<300000,0.07*O20,21000) -> 21000 | Q20: =IF((O20-300000)<0,0,IF((O20-300000)<300000,0.11*(O20-300000),33000)) -> 33000 | R20: =IF((O20-600000)<0,0,IF((O20-600000)<500000,0.15*(O20-600000),75000)) -> 75000 | S20: =IF((O20-1100000)<0,0,IF((O20-1100000)<500000,0.19*(O20-1100000),95000)) -> 95000 | T20: =IF((O20-1600000)<0,0,IF((O20-1600000)<1600000,0.21*(O20-1600000),336000)) -> 336000 | U20: =24%*(O20-3200000) -> 69973.245 | V20: =P20+Q20+R20+S20+T20+U20 -> 629973.24 | W20: 12 | X20: =V20/W20 -> 52497.77 | Z20: =X20 -> 52497.77 | AA20: 52497.77 | AB20: =Z20-AA20 -> 0
A21: 18 | B21: LUCKY AGWOM | C21: 400372.08 | D21: 12 | E21: =C21*D21 -> 4804464.9 | I21: =E21-F21-G21-H21 -> 4804464.9 | J21: 200000 | K21: 0.2 | L21: =I21*K21 -> 960892.98 | M21: =J21+L21 -> 1160893 | N21: =F21+G21+H21+M21 -> 1160893 | O21: =E21-N21 -> 3643571.9 | P21: =IF(O21<300000,0.07*O21,21000) -> 21000 | Q21: =IF((O21-300000)<0,0,IF((O21-300000)<300000,0.11*(O21-300000),33000)) -> 33000 | R21: =IF((O21-600000)<0,0,IF((O21-600000)<500000,0.15*(O21-600000),75000)) -> 75000 | S21: =IF((O21-1100000)<0,0,IF((O21-1100000)<500000,0.19*(O21-1100000),95000)) -> 95000 | T21: =IF((O21-1600000)<0,0,IF((O21-1600000)<1600000,0.21*(O21-1600000),336000)) -> 336000 | U21: =24%*(O21-3200000) -> 106457.26 | V21: =P21+Q21+R21+S21+T21+U21 -> 666457.26 | W21: 12 | X21: =V21/W21 -> 55538.105 | Z21: =X21 -> 55538.105 | AA21: 46666.667 | AB21: =Z21-AA21 -> 8871.4384
A22: 19 | B22: IDRIS IBRAHIM | C22: =1015372.075-700000 -> 315372.07 | D22: 12 | E22: =C22*D22 -> 3784464.9 | I22: =E22-F22-G22-H22 -> 3784464.9 | J22: 200000 | K22: 0.2 | L22: =I22*K22 -> 756892.98 | M22: =J22+L22 -> 956892.98 | N22: =F22+G22+H22+M22 -> 956892.98 | O22: =E22-N22 -> 2827571.9 | P22: =IF(O22<300000,0.07*O22,21000) -> 21000 | Q22: =IF((O22-300000)<0,0,IF((O22-300000)<300000,0.11*(O22-300000),33000)) -> 33000 | R22: =IF((O22-600000)<0,0,IF((O22-600000)<500000,0.15*(O22-600000),75000)) -> 75000 | S22: =IF((O22-1100000)<0,0,IF((O22-1100000)<500000,0.19*(O22-1100000),95000)) -> 95000 | T22: =IF((O22-1600000)<0,0,IF((O22-1600000)<1600000,0.21*(O22-1600000),336000)) -> 257790.1 | V22: =P22+Q22+R22+S22+T22+U22 -> 481790.1 | W22: 12 | X22: =V22/W22 -> 40149.175 | Z22: =X22 -> 40149.175 | AA22: 46666.667 | AB22: =Z22-AA22 -> -6517.4914 | AC22: to be paid in February
A23: 20 | B23: FARUQ ATOFARATI | C23: 328602.08 | D23: 12 | E23: =C23*D23 -> 3943224.9 | I23: =E23-F23-G23-H23 -> 3943224.9 | J23: 200000 | K23: 0.2 | L23: =I23*K23 -> 788644.99 | M23: =J23+L23 -> 988644.99 | N23: =F23+G23+H23+M23 -> 988644.99 | O23: =E23-N23 -> 2954579.9 | P23: =IF(O23<300000,0.07*O23,21000) -> 21000 | Q23: =IF((O23-300000)<0,0,IF((O23-300000)<300000,0.11*(O23-300000),33000)) -> 33000 | R23: =IF((O23-600000)<0,0,IF((O23-600000)<500000,0.15*(O23-600000),75000)) -> 75000 | S23: =IF((O23-1100000)<0,0,IF((O23-1100000)<500000,0.19*(O23-1100000),95000)) -> 95000 | T23: =IF((O23-1600000)<0,0,IF((O23-1600000)<1600000,0.21*(O23-1600000),336000)) -> 284461.79 | V23: =P23+Q23+R23+S23+T23+U23 -> 508461.79 | W23: 12 | X23: =V23/W23 -> 42371.816 | Z23: =X23 -> 42371.816 | AA23: 42371.816 | AB23: =Z23-AA23 -> 0
A24: 21 | B24: ELIZABETH OGECHUKWU ONYEAKU | C24: 213508.01 | D24: 12 | E24: =C24*D24 -> 2562096.1 | I24: =E24-F24-G24-H24 -> 2562096.1 | J24: 200000 | K24: 0.2 | L24: =I24*K24 -> 512419.22 | M24: =J24+L24 -> 712419.22 | N24: =F24+G24+H24+M24 -> 712419.22 | O24: =E24-N24 -> 1849676.9 | P24: =IF(O24<300000,0.07*O24,21000) -> 21000 | Q24: =IF((O24-300000)<0,0,IF((O24-300000)<300000,0.11*(O24-300000),33000)) -> 33000 | R24: =IF((O24-600000)<0,0,IF((O24-600000)<500000,0.15*(O24-600000),75000)) -> 75000 | S24: =IF((O24-1100000)<0,0,IF((O24-1100000)<500000,0.19*(O24-1100000),95000)) -> 95000 | T24: =IF((O24-1600000)<0,0,IF((O24-1600000)<1600000,0.21*(O24-1600000),336000)) -> 52432.148 | V24: =P24+Q24+R24+S24+T24+U24 -> 276432.15 | W24: 12 | X24: =V24/W24 -> 23036.012 | Z24: =X24 -> 23036.012 | AA24: 23036.012 | AB24: =Z24-AA24 -> 0
A25: 22 | B25: VICTOR ASUKWO | C25: 213508.01 | D25: 12 | E25: =C25*D25 -> 2562096.1 | I25: =E25-F25-G25-H25 -> 2562096.1 | J25: 200000 | K25: 0.2 | L25: =I25*K25 -> 512419.22 | M25: =J25+L25 -> 712419.22 | N25: =F25+G25+H25+M25 -> 712419.22 | O25: =E25-N25 -> 1849676.9 | P25: =IF(O25<300000,0.07*O25,21000) -> 21000 | Q25: =IF((O25-300000)<0,0,IF((O25-300000)<300000,0.11*(O25-300000),33000)) -> 33000 | R25: =IF((O25-600000)<0,0,IF((O25-600000)<500000,0.15*(O25-600000),75000)) -> 75000 | S25: =IF((O25-1100000)<0,0,IF((O25-1100000)<500000,0.19*(O25-1100000),95000)) -> 95000 | T25: =IF((O25-1600000)<0,0,IF((O25-1600000)<1600000,0.21*(O25-1600000),336000)) -> 52432.148 | V25: =P25+Q25+R25+S25+T25+U25 -> 276432.15 | W25: 12 | X25: =V25/W25 -> 23036.012 | Z25: =X25 -> 23036.012 | AA25: 23036.012 | AB25: =Z25-AA25 -> 0
A26: 23 | B26: NNANDI LIVINUS ATURE | C26: 253508.01 | D26: 12 | E26: =C26*D26 -> 3042096.1 | I26: =E26-F26-G26-H26 -> 3042096.1 | J26: 200000 | K26: 0.2 | L26: =I26*K26 -> 608419.22 | M26: =J26+L26 -> 808419.22 | N26: =F26+G26+H26+M26 -> 808419.22 | O26: =E26-N26 -> 2233676.9 | P26: =IF(O26<300000,0.07*O26,21000) -> 21000 | Q26: =IF((O26-300000)<0,0,IF((O26-300000)<300000,0.11*(O26-300000),33000)) -> 33000 | R26: =IF((O26-600000)<0,0,IF((O26-600000)<500000,0.15*(O26-600000),75000)) -> 75000 | S26: =IF((O26-1100000)<0,0,IF((O26-1100000)<500000,0.19*(O26-1100000),95000)) -> 95000 | T26: =IF((O26-1600000)<0,0,IF((O26-1600000)<1600000,0.21*(O26-1600000),336000)) -> 133072.15 | V26: =P26+Q26+R26+S26+T26+U26 -> 357072.15 | W26: 12 | X26: =V26/W26 -> 29756.012 | Z26: =X26 -> 29756.012 | AA26: 29756.012 | AB26: =Z26-AA26 -> 0
A27: 24 | B27: ABDULRAHMAN A SULAIMAN | C27: 209356.05 | D27: 12 | E27: =C27*D27 -> 2512272.6 | I27: =E27-F27-G27-H27 -> 2512272.6 | J27: 200000 | K27: 0.2 | L27: =I27*K27 -> 502454.51 | M27: =J27+L27 -> 702454.51 | N27: =F27+G27+H27+M27 -> 702454.51 | O27: =E27-N27 -> 1809818.1 | P27: =IF(O27<300000,0.07*O27,21000) -> 21000 | Q27: =IF((O27-300000)<0,0,IF((O27-300000)<300000,0.11*(O27-300000),33000)) -> 33000 | R27: =IF((O27-600000)<0,0,IF((O27-600000)<500000,0.15*(O27-600000),75000)) -> 75000 | S27: =IF((O27-1100000)<0,0,IF((O27-1100000)<500000,0.19*(O27-1100000),95000)) -> 95000 | T27: =IF((O27-1600000)<0,0,IF((O27-1600000)<1600000,0.21*(O27-1600000),336000)) -> 44061.791 | V27: =P27+Q27+R27+S27+T27+U27 -> 268061.79 | W27: 12 | X27: =V27/W27 -> 22338.483 | Z27: =X27 -> 22338.483 | AA27: 22338.483 | AB27: =Z27-AA27 -> 0
A28: 25 | B28: DARE SHEU MAGBON | C28: 205204.08 | D28: 12 | E28: =C28*D28 -> 2462449 | I28: =E28-F28-G28-H28 -> 2462449 | J28: 200000 | K28: 0.2 | L28: =I28*K28 -> 492489.8 | M28: =J28+L28 -> 692489.8 | N28: =F28+G28+H28+M28 -> 692489.8 | O28: =E28-N28 -> 1769959.2 | P28: =IF(O28<300000,0.07*O28,21000) -> 21000 | Q28: =IF((O28-300000)<0,0,IF((O28-300000)<300000,0.11*(O28-300000),33000)) -> 33000 | R28: =IF((O28-600000)<0,0,IF((O28-600000)<500000,0.15*(O28-600000),75000)) -> 75000 | S28: =IF((O28-1100000)<0,0,IF((O28-1100000)<500000,0.19*(O28-1100000),95000)) -> 95000 | T28: =IF((O28-1600000)<0,0,IF((O28-1600000)<1600000,0.21*(O28-1600000),336000)) -> 35691.434 | V28: =P28+Q28+R28+S28+T28+U28 -> 259691.43 | W28: 12 | X28: =V28/W28 -> 21640.953 | Z28: =X28 -> 21640.953 | AA28: 21640.953 | AB28: =Z28-AA28 -> 0
A29: 26 | B29: ABUBAKAR SULAIMAN SODEEQ | C29: 205204.08 | D29: 12 | E29: =C29*D29 -> 2462449 | I29: =E29-F29-G29-H29 -> 2462449 | J29: 200000 | K29: 0.2 | L29: =I29*K29 -> 492489.8 | M29: =J29+L29 -> 692489.8 | N29: =F29+G29+H29+M29 -> 692489.8 | O29: =E29-N29 -> 1769959.2 | P29: =IF(O29<300000,0.07*O29,21000) -> 21000 | Q29: =IF((O29-300000)<0,0,IF((O29-300000)<300000,0.11*(O29-300000),33000)) -> 33000 | R29: =IF((O29-600000)<0,0,IF((O29-600000)<500000,0.15*(O29-600000),75000)) -> 75000 | S29: =IF((O29-1100000)<0,0,IF((O29-1100000)<500000,0.19*(O29-1100000),95000)) -> 95000 | T29: =IF((O29-1600000)<0,0,IF((O29-1600000)<1600000,0.21*(O29-1600000),336000)) -> 35691.434 | V29: =P29+Q29+R29+S29+T29+U29 -> 259691.43 | W29: 12 | X29: =V29/W29 -> 21640.953 | Z29: =X29 -> 21640.953 | AA29: 21640.953 | AB29: =Z29-AA29 -> 0
A30: 27 | B30: JIMOH ADEBAYO ZAKA | C30: 209356.05 | D30: 12 | E30: =C30*D30 -> 2512272.6 | I30: =E30-F30-G30-H30 -> 2512272.6 | J30: 200000 | K30: 0.2 | L30: =I30*K30 -> 502454.51 | M30: =J30+L30 -> 702454.51 | N30: =F30+G30+H30+M30 -> 702454.51 | O30: =E30-N30 -> 1809818.1 | P30: =IF(O30<300000,0.07*O30,21000) -> 21000 | Q30: =IF((O30-300000)<0,0,IF((O30-300000)<300000,0.11*(O30-300000),33000)) -> 33000 | R30: =IF((O30-600000)<0,0,IF((O30-600000)<500000,0.15*(O30-600000),75000)) -> 75000 | S30: =IF((O30-1100000)<0,0,IF((O30-1100000)<500000,0.19*(O30-1100000),95000)) -> 95000 | T30: =IF((O30-1600000)<0,0,IF((O30-1600000)<1600000,0.21*(O30-1600000),336000)) -> 44061.791 | V30: =P30+Q30+R30+S30+T30+U30 -> 268061.79 | W30: 12 | X30: =V30/W30 -> 22338.483 | Z30: =X30 -> 22338.483 | AA30: 22338.483 | AB30: =Z30-AA30 -> 0
A31: 28 | B31: MOHAMMED BELLO | C31: 180304.07 | D31: 12 | E31: =C31*D31 -> 2163648.8 | I31: =E31-F31-G31-H31 -> 2163648.8 | J31: 200000 | K31: 0.2 | L31: =I31*K31 -> 432729.76 | M31: =J31+L31 -> 632729.76 | N31: =F31+G31+H31+M31 -> 632729.76 | O31: =E31-N31 -> 1530919.1 | P31: =IF(O31<300000,0.07*O31,21000) -> 21000 | Q31: =IF((O31-300000)<0,0,IF((O31-300000)<300000,0.11*(O31-300000),33000)) -> 33000 | R31: =IF((O31-600000)<0,0,IF((O31-600000)<500000,0.15*(O31-600000),75000)) -> 75000 | S31: =IF((O31-1100000)<0,0,IF((O31-1100000)<500000,0.19*(O31-1100000),95000)) -> 81874.62 | T31: =IF((O31-1600000)<0,0,IF((O31-1600000)<1600000,0.21*(O31-1600000),336000)) -> 0 | V31: =P31+Q31+R31+S31+T31+U31 -> 210874.62 | W31: 12 | X31: =V31/W31 -> 17572.885 | Z31: =X31 -> 17572.885 | AA31: 17572.885 | AB31: =Z31-AA31 -> 0
A32: 29 | B32: HARUNA JIBRIL AMEH | C32: 173329.05 | D32: 12 | E32: =C32*D32 -> 2079948.6 | I32: =E32-F32-G32-H32 -> 2079948.6 | J32: 200000 | K32: 0.2 | L32: =I32*K32 -> 415989.72 | M32: =J32+L32 -> 615989.72 | N32: =F32+G32+H32+M32 -> 615989.72 | O32: =E32-N32 -> 1463958.9 | P32: =IF(O32<300000,0.07*O32,21000) -> 21000 | Q32: =IF((O32-300000)<0,0,IF((O32-300000)<300000,0.11*(O32-300000),33000)) -> 33000 | R32: =IF((O32-600000)<0,0,IF((O32-600000)<500000,0.15*(O32-600000),75000)) -> 75000 | S32: =IF((O32-1100000)<0,0,IF((O32-1100000)<500000,0.19*(O32-1100000),95000)) -> 69152.186 | T32: =IF((O32-1600000)<0,0,IF((O32-1600000)<1600000,0.21*(O32-1600000),336000)) -> 0 | V32: =P32+Q32+R32+S32+T32+U32 -> 198152.19 | W32: 12 | X32: =V32/W32 -> 16512.682 | Z32: =X32 -> 16512.682 | AA32: 16512.682 | AB32: =Z32-AA32 -> 0
A33: 31 | AB33: =SUM(AB6:AB32) -> 83964.785
A34: 32 | B34: INTERNAL AUDIT
B35: OSANAIYE DAVID AKINYEMI | C35: 950209.06 | D35: 12 | E35: =C35*D35 -> 11402509 | G35: =SUM(G5:G34) -> 0 | I35: =E35-F35-G35-H35 -> 11402509 | J35: 200000 | K35: 0.2 | L35: =I35*K35 -> 2280501.8 | M35: =J35+L35 -> 2480501.8 | N35: =F35+G35+H35+M35 -> 2480501.8 | O35: =E35-N35 -> 8922007 | P35: =IF(O35<300000,0.07*O35,21000) -> 21000 | Q35: =IF((O35-300000)<0,0,IF((O35-300000)<300000,0.11*(O35-300000),33000)) -> 33000 | R35: =IF((O35-600000)<0,0,IF((O35-600000)<500000,0.15*(O35-600000),75000)) -> 75000 | S35: =IF((O35-1100000)<0,0,IF((O35-1100000)<500000,0.19*(O35-1100000),95000)) -> 95000 | T35: =IF((O35-1600000)<0,0,IF((O35-1600000)<1600000,0.21*(O35-1600000),336000)) -> 336000 | U35: =24%*(O35-3200000) -> 1373281.7 | V35: =P35+Q35+R35+S35+T35+U35 -> 1933281.7 | W35: 12 | X35: =V35/W35 -> 161106.81 | Z35: =X35 -> 161106.81 | AA35: 161106.81 | AB35: =Z35-AA35 -> 0
B36: JAMILA ABDUL | C36: 176816.1 | D36: 12 | E36: =C36*D36 -> 2121793.2 | G36: =SUM(G6:G35) -> 0 | I36: =E36-F36-G36-H36 -> 2121793.2 | J36: 200000 | K36: 0.2 | L36: =I36*K36 -> 424358.64 | M36: =J36+L36 -> 624358.64 | N36: =F36+G36+H36+M36 -> 624358.64 | O36: =E36-N36 -> 1497434.6 | P36: =IF(O36<300000,0.07*O36,21000) -> 21000 | Q36: =IF((O36-300000)<0,0,IF((O36-300000)<300000,0.11*(O36-300000),33000)) -> 33000 | R36: =IF((O36-600000)<0,0,IF((O36-600000)<500000,0.15*(O36-600000),75000)) -> 75000 | S36: =IF((O36-1100000)<0,0,IF((O36-1100000)<500000,0.19*(O36-1100000),95000)) -> 75512.566 | T36: =IF((O36-1600000)<0,0,IF((O36-1600000)<1600000,0.21*(O36-1600000),336000)) -> 0 | V36: =P36+Q36+R36+S36+T36+U36 -> 204512.57 | W36: 12 | X36: =V36/W36 -> 17042.714 | Z36: =X36 -> 17042.714 | AA36: 17042.714 | AB36: =Z36-AA36 -> 0
A37: 33 | B37: IJEOMA EWELUKWA | C37: 233169.12 | D37: 12 | E37: =C37*D37 -> 2798029.4 | G37: =SUM(G7:G36) -> 0 | I37: =E37-F37-G37-H37 -> 2798029.4 | J37: 200000 | K37: 0.2 | L37: =I37*K37 -> 559605.88 | M37: =J37+L37 -> 759605.88 | N37: =F37+G37+H37+M37 -> 759605.88 | O37: =E37-N37 -> 2038423.5 | P37: =IF(O37<300000,0.07*O37,21000) -> 21000 | Q37: =IF((O37-300000)<0,0,IF((O37-300000)<300000,0.11*(O37-300000),33000)) -> 33000 | R37: =IF((O37-600000)<0,0,IF((O37-600000)<500000,0.15*(O37-600000),75000)) -> 75000 | S37: =IF((O37-1100000)<0,0,IF((O37-1100000)<500000,0.19*(O37-1100000),95000)) -> 95000 | T37: =IF((O37-1600000)<0,0,IF((O37-1600000)<1600000,0.21*(O37-1600000),336000)) -> 92068.941 | V37: =P37+Q37+R37+S37+T37+U37 -> 316068.94 | W37: 12 | X37: =V37/W37 -> 26339.078 | Z37: =X37 -> 26339.078 | AA37: 26339.078 | AB37: =Z37-AA37 -> 0
B39: LEG. SUPPORT SEVICES
A40: 35 | B40: PROF. EDOBA BRIGHT OMOREGBE | C40: 1050209.1 | D40: 12 | E40: =C40*D40 -> 12602509 | I40: =E40-F40-G40-H40 -> 12602509 | J40: 200000 | K40: 0.2 | L40: =I40*K40 -> 2520501.8 | M40: =J40+L40 -> 2720501.8 | N40: =F40+G40+H40+M40 -> 2720501.8 | O40: =E40-N40 -> 9882007 | P40: =IF(O40<300000,0.07*O40,21000) -> 21000 | Q40: =IF((O40-300000)<0,0,IF((O40-300000)<300000,0.11*(O40-300000),33000)) -> 33000 | R40: =IF((O40-600000)<0,0,IF((O40-600000)<500000,0.15*(O40-600000),75000)) -> 75000 | S40: =IF((O40-1100000)<0,0,IF((O40-1100000)<500000,0.19*(O40-1100000),95000)) -> 95000 | T40: =IF((O40-1600000)<0,0,IF((O40-1600000)<1600000,0.21*(O40-1600000),336000)) -> 336000 | U40: =0.24*(O40-3200000) -> 1603681.7 | V40: =P40+Q40+R40+S40+T40+U40 -> 2163681.7 | W40: 12 | X40: =V40/W40 -> 180306.81 | Z40: =X40 -> 180306.81 | AA40: 180306.81 | AB40: =Z40-AA40 -> 0
A41: 36 | B41: DR CLINTON JAJA | C41: 527553.5 | D41: 12 | E41: =C41*D41 -> 6330642 | I41: =E41-F41-G41-H41 -> 6330642 | J41: 200000 | K41: 0.2 | L41: =I41*K41 -> 1266128.4 | M41: =J41+L41 -> 1466128.4 | N41: =F41+G41+H41+M41 -> 1466128.4 | O41: =E41-N41 -> 4864513.6 | P41: =IF(O41<300000,0.07*O41,21000) -> 21000 | Q41: =IF((O41-300000)<0,0,IF((O41-300000)<300000,0.11*(O41-300000),33000)) -> 33000 | R41: =IF((O41-600000)<0,0,IF((O41-600000)<500000,0.15*(O41-600000),75000)) -> 75000 | S41: =IF((O41-1100000)<0,0,IF((O41-1100000)<500000,0.19*(O41-1100000),95000)) -> 95000 | T41: =IF((O41-1600000)<0,0,IF((O41-1600000)<1600000,0.21*(O41-1600000),336000)) -> 336000 | U41: =24%*(O41-3200000) -> 399483.27 | V41: =P41+Q41+R41+S41+T41+U41 -> 959483.27 | W41: 12 | X41: =V41/W41 -> 79956.939 | Z41: =X41 -> 79956.939 | AA41: 79956.939 | AB41: =Z41-AA41 -> 0
...

Sheet  Excess Ded Paid
A2: S/N | B2: NAME | C2: INACCURATE TAX CHARGED | D2: ACCURATE TAX FIGURE | E2: EXCESS DEDUCTION
C3: N | D3: N | E3: N
A4: 1 | B4: DR AUGUSTINE C. OSIGWE | C4: 98996.103 | D4: 79796.103 | E4: =C4-D4 -> 19200
A5: 2 | B5: OMOJU OLUWASOLA EMMANUEL | C5: 79956.939 | D5: 75574.677 | E5: =C5-D5 -> 4382.2619
A6: 3 | B6: IBE EZECHI CYRIACUS | C6: 75574.677 | D6: 50985.978 | E6: =C6-D6 -> 24588.7
A7: 4 | B7: OSIKHEN LEO IGBANOI | C7: 50985.978 | D7: 49548.776 | E7: =C7-D7 -> 1437.2014
A8: 5 | B8: YUSUF IBRAHIM | C8: 53384.054 | D8: 41338.951 | E8: =C8-D8 -> 12045.102
A9: 6 | B9: MARYAM MUSA SADA | C9: 45414.456 | D9: 33825.987 | E9: =C9-D9 -> 11588.47
A10: 7 | B10: CHARITY EZENWAJIOBI | C10: 33825.987 | D10: 29984.871 | E10: =C10-D10 -> 3841.1156
A11: 8 | B11: MOHAMMED R. ADAMU | C11: 82627.951 | D11: 43492.373 | E11: =C11-D11 -> 39135.578
A12: 9 | B12: OKECHUKWU UCHENNA HULDA | C12: 43492.373 | D12: 34968.882 | E12: =C12-D12 -> 8523.491
A13: 10 | B13: TASSNEEM IBRAHIM | C13: 34968.882 | D13: 27105.987 | E13: =C13-D13 -> 7862.8959
A14: 11 | B14: ALIYU SANNI ABUBAKAR | C14: 180180.38 | D14: 58814.673 | E14: =C14-D14 -> 121365.71
A15: 12 | B15: CHINAKO N. ASOGWA | C15: 99907.951 | D15: 58631.44 | E15: =C15-D15 -> 41276.511
... A18: 15 | B18: ENENCHE JEREMIAH AGADA | C18: 31871.335 | D18: 29984.871 | E18: =C18-D18 -> 1886.4643
B19: TOTAL | C19: =SUM(C4:C18) -> 1028759.6 | D19: =SUM(D4:D18) -> 677146.05 | E19: =SUM(E4:E18) -> 351613.56

Sheet Changes in Gross & PAYE 
A1: NATIONAL INSTITUTE FOR LEGISLATIVE AND DEMOCRATIC STUDIES
A2: CHANGES IN GROSS SALARY AND PAYE TAX
E3: ='[1]FEB 08'!E11/'[1]FEB 08'!M11 -> #REF!
B4: STAFF NAME | C4: DESIGNATION | D4: GRADE LEVEL | E4: SALARY | F4: AREARS | G4: RESEARCH ALLOW. | H4: HARDSHIP ALLOW. | I4: DUTY ALLCE | J4: NEW GROSS SALARY | K4: OLD GROSS SALARY | L4: VARIATION IN GROSS SALARY | M4: NEW PAYE TAX | N4: OLD PAYE TAX | O4: VARIATION IN PAYE TAX
E5: N | F5: N | G5: N | H5: N | I5: N | M5: N
A6: S/N | B6: DG'S OFFICE
A7: 1 | B7: PROF. ABUBAKAR O. SULAIMAN | C7: DIRECTOR GENERAL | D7: CONSOL | E7: 1659751.2 | G7: =250000 -> 250000 | I7: 25235 | J7: =E7+F7+G7+H7+I7 -> 1934986.2 | K7: 1158849.8 | L7: =J7-K7 -> 776136.33 | M7: 350184.01 | N7: 201165.84 | O7: =M7-N7 -> 149018.17
A8: 2 | B8: RAHEEM USMAN AYIGORO | C8: SA-INFRASTRUCTURE | D8: 16 (9) | E8: 762373.17 | H8: =90000 -> 90000 | I8: 0 | J8: =E8+F8+G8+H8+I8 -> 852373.17 | K8: 541465.02 | L8: =J8-K8 -> 310908.14 | M8: 130612.26 | N8: 82627.951 | O8: =M8-N8 -> 47984.311
A9: 3 | B9: MARIAM MOHAMMED BELLO | C9: SA- SPECIAL DUTIES | D9: 16 (9) | E9: 762373.17 | H9: =90000 -> 90000 | I9: =100000+100000 -> 200000 | J9: =E9+F9+G9+H9+I9 -> 1052373.2 | K9: 741465.02 | L9: =J9-K9 -> 310908.14 | M9: 180722.31 | N9: 121027.95 | O9: =M9-N9 -> 59694.363
A10: 4 | B10: DR IKEME ARTHUR J.O | C10: DEPUTY DIRECTOR, M&E | D10: 16 (9) | E10: 762373.17 | G10: 180000 | I10: 0 | J10: =E10+F10+G10+H10+I10 -> 942373.17 | K10: 631465.02 | L10: =J10-K10 -> 310908.14 | M10: 147687.53 | N10: 99703.216 | O10: =M10-N10 -> 47984.311
A11: 5 | B11: MOSHOOD M. OLALERE | C11: PPS TO DG | D11: 16 (9) | E11: 762373.17 | H11: =80000+10000 -> 90000 | I11: 150000 | J11: =E11+F11+G11+H11+I11 -> 1002373.2 | K11: 691465.02 | L11: =J11-K11 -> 310908.14 | M11: 159207.53 | N11: 111223.22 | O11: =M11-N11 -> 47984.311
A12: 6 | B12: REKIYA IBRAHIM ATTAH | C12: DEPUTY DIRECTOR TRAINING | D12: 16 (9) | E12: 762373.17 | H12: =90000 -> 90000 | I12: 100000 | J12: =E12+F12+G12+H12+I12 -> 952373.17 | K12: 641465.02 | L12: =J12-K12 -> 310908.14 | M12: 161522.31 | N12: 101827.95 | O12: =M12-N12 -> 59694.363
A13: 7 | B13: ANDRAWUS MUSA | C13: ASST. DIRECTOR, STORES | D13: 15(9) | E13: 620675.58 | H13: =80000 -> 80000 | I13: 50000 | J13: =E13+F13+G13+H13+I13 -> 750675.58 | K13: 497553.5 | L13: =J13-K13 -> 253122.08 | M13: 113101.97 | N13: 74036.103 | O13: =M13-N13 -> 39065.863
A14: 8 | B14: DR FRANCIS NDUM OJIE | C14: AD, TRAINING & IC./SA TO DG | D14: 15(7) | E14: 582118.08 | G14: 160000 | I14: =100000 -> 100000 | J14: =E14+F14+G14+H14+I14 -> 842118.08 | K14: 604729.22 | L14: =J14-K14 -> 237388.86 | M14: 131263.11 | N14: 94625.782 | O14: =M14-N14 -> 36637.328
A15: 9 | B15: ALI ABDULLAHI | C15: CHIEF ICT OFFICER | D15: 14(11) | E15: 484373.75 | H15: =70000 -> 70000 | I15: =0 -> 0 | J15: =E15+F15+G15+H15+I15 -> 554373.75 | K15: 343333.04 | L15: =J15-K15 -> 211040.71 | M15: 77666.446 | N15: 44846.617 | O15: =M15-N15 -> 32819.829
A16: 10 | B16: EMILY EKHIDE | C16: RESEARCH FELLOW 1 | D16: 14(10) | E16: 470498 | G16: 140000 | I16: 50000 | J16: =E16+F16+G16+H16+I16 -> 660498 | K16: 463333.04 | L16: =J16-K16 -> 197164.96 | M16: 98255.433 | N16: 67626.609 | O16: =M16-N16 -> 30628.824
A17: 11 | B17: DORIS DAKDA AARON | C17: RESEARCH FELLOW I | D17: 14(8) | E17: 442746.5 | G17: =140000 -> 140000 | I17: 150000 | J17: =E17+F17+G17+H17+I17 -> 732746.5 | K17: 547211.37 | L17: =J17-K17 -> 185535.13 | M17: 112553.41 | N17: 83731.249 | O17: =M17-N17 -> 28822.159
A18: 12 | B18: ABDULSALAM S. MUSTAPHA | C18: ASST. MANAGER ICT | D18: 13(11) | E18: 441804.92 | H18: 70000 | J18: =E18+F18+G18+H18+I18 -> 511804.92 | K18: 326663.08 | L18: =J18-K18 -> 185141.84 | M18: 70147.087 | N18: 42046.064 | O18: =M18-N18 -> 28101.023
A19: 13 | B19: PERCY TERFA GBAHABO | C19: HEAD, NILDS LIAISON OFFICE | D19: 13(10) | E19: 428915.92 | G19: =120000 -> 120000 | I19: 0 | J19: =E19+F19+G19+H19+I19 -> 548915.92 | K19: 369177.65 | L19: =J19-K19 -> 179738.26 | M19: 77470.374 | N19: 49548.776 | O19: =M19-N19 -> 27921.598
A20: 14 | B20: HASSANA AHMED IBRAHIM | C20: PA- TRAINING | D20: 13 (9) | E20: 416026.92 | G20: =120000 -> 120000 | I20: =100000 -> 100000 | J20: =E20+F20+G20+H20+I20 -> 636026.92 | K20: 462001.06 | L20: =J20-K20 -> 174025.86 | M20: 94274.903 | N20: 67370.87 | O20: =M20-N20 -> 26904.033
A21: 15 | B21: ADUGBA RICHARD TERSEER | C21: PRINCIPAL INFO. OFFICER | D21: 12(9) | E21: 377895.17 | H21: =60000 -> 60000 | I21: 100000 | J21: =E21+F21+G21+H21+I21 -> 537895.17 | K21: 384537 | L21: =J21-K21 -> 153358.17 | M21: 76138.069 | N21: 52497.77 | O21: =M21-N21 -> 23640.299
A22: 16 | B22: LUCKY AGWOM | C22: PA-TECHNICAL | D22: 12(7) | E22: 353512.5 | G22: =100000 -> 100000 | I22: 100000 | J22: =E22+F22+G22+H22+I22 -> 553512.5 | K22: 400372.08 | L22: =J22-K22 -> 153140.42 | M22: 79511.115 | N22: 55538.105 | O22: =M22-N22 -> 23973.01
A23: 17 | B23: IDRIS IBRAHIM | C23: PRINCIPAL RESEARCH OFFICER | D23: 12(7) | E23: 353512.5 | G23: 110000 | I23: 0 | J23: =E23+F23+G23+H23+I23 -> 463512.5 | K23: 1015372.1 | L23: =J23-K23 -> -551859.58 | M23: 62231.115 | N23: 40149.175 | O23: =M23-N23 -> 22081.939
A24: 18 | B24: FARUQ ATOFARATI | C24: PA (SPECIAL DUTIES) TO DG | D24: 10(7) | E24: 293029.67 | H24: =50000+10000 -> 60000 | I24: 100000 | J24: =E24+F24+G24+H24+I24 -> 453029.67 | K24: 328602.08 | L24: =J24-K24 -> 124427.59 | M24: 61147.427 | N24: 42371.816 | O24: =M24-N24 -> 18775.611
A25: 19 | B25: ELIZABETH OGECHUKWU ONYEAKU | C25: ICT OFFICER | D25: 9(9) | E25: 270481.67 | H25: =50000+10000 -> 60000 | J25: =E25+F25+G25+H25+I25 -> 330481.67 | K25: 213508.01 | L25: =J25-K25 -> 116973.66 | M25: 39052.313 | N25: 23036.012 | O25: =M25-N25 -> 16016.301
A26: 20 | B26: VICTOR ASUKWO | C26: ICT OFFICER | D26: 9(9) | E26: 270481.67 | H26: =50000+10000 -> 60000 | J26: =E26+F26+G26+H26+I26 -> 330481.67 | K26: 213508.01 | L26: =J26-K26 -> 116973.66 | M26: 39052.313 | N26: 23036.012 | O26: =M26-N26 -> 16016.301
