Workbook

Sheet Feb. 2017
B3: STAFF PAYROLL FOR THE MONTH OF FEBRUARY, 2017
F4: ='[1]FEB 08'!E8/'[1]FEB 08'!M8 -> 0.22 | I4: ='[1]FEB 08'!F8/'[1]FEB 08'!Q8 -> 0.3
B5: STAFF NAME | T5: DEDUCTIONS | Y5: NET SALARY
D6: DESIGNATION | E6: SALARY | F6: BASIC | G6: SALARY AREARS | M6: PERSONAL | N6: MOTOR/ | O6: RESEARCH | P6: LEAVE | Q6: OUT FIT | R6: LEGISLATIVE | S6: GROSS | X6: Jan. 2016 | Y6: Feb. 2017
E7: LEVEL | F7: SALARY | G7: ADVANCE | H7: RENT | I7: UTILITY | J7: DOMESTIC | K7: ENTERT. | L7: FURNIT. | M7: ASSISTANT | N7: FUEL | O7: ALLOWANCE | P7: ALLCE | Q7: ALLCE | R7: DUTY ALLCE | S7: SALARY | T7: COOP SOCIETY | U7: COOP. LOAN RECOVERY | V7: PAYE | W7: TOTAL
A8: S/N | B8: DG OFFICE | F8: N | I8: N | S8: N | V8: N
A9: 1 | B9: DR LADI HAMALAI | D9: DIRECTOR GENERAL | E9: CONSOL | F9: 160488.75 | H9: 320977.5 | I9: 48146.63 | J9: 120366.57 | K9: 72219.94 | L9: 481466.25 | M9: 40122.19 | N9: 120366.57 | O9: 100000 | P9: 16048.88 | Q9: 25000 | R9: 25235 | S9: =SUM(F9:R9) -> 1530438.3 | V9: 113176.97 | W9: =T9+U9+V9 -> 113176.97 | X9: 1417261.3 | Y9: =S9-W9 -> 1417261.3
A10: 2 | B10: NWAJEI KANAYO | D10: COMMUNICATION ADVISER | E10: 16(7) | F10: 39662.25 | H10: =F10*300% -> 118986.75 | I10: =F10*7.5% -> 2974.6687 | J10: 40122.19 | K10: =F10*50% -> 19831.125 | L10: =F10*350% -> 138817.88 | N10: =F10*100% -> 39662.25 | O10: 100000 | P10: =F10*10% -> 3966.225 | Q10: 20000 | S10: =SUM(F10:R10) -> 524023.33 | T10: 50000 | U10: =105000 -> 105000 | V10: 21618.09 | W10: =T10+U10+V10 -> 176618.09 | X10: 347405.24 | Y10: =S10-W10 -> 347405.24
A11: 3 | B11: DR ABDULHAMID OBA YUSUF | D11: LEGAL ADVISER | S11: 484969.83 | V11: 21618.09 | W11: =T11+U11+V11 -> 21618.09 | X11: 463351.74 | Y11: =S11-W11 -> 463351.74
A12: 4 | B12: NWOSU MATHEW EZE | D12: MANAGER INT. AUDIT | E12: 15(9) | F12: 33507.5 | H12: =F12*300% -> 100522.5 | I12: =F12*7.5% -> 2513.0625 | J12: 40122.19 | K12: =F12*50% -> 16753.75 | L12: =F12*350% -> 117276.25 | M12: 0 | N12: =F12*100% -> 33507.5 | O12: 0 | P12: =F12*10% -> 3350.75 | Q12: 20000 | R12: 0 | S12: =SUM(F12:R12) -> 367553.5 | T12: 50000 | U12: 0 | V12: 15548.33 | W12: =T12+U12+V12 -> 65548.33 | X12: 198255.17 | Y12: =S12-W12 -> 302005.17
A13: 5 | B13: DR IKEME ARTHUR J. O | D13: MANAGER M&E | E13: 15(8) | F13: 32263.2 | H13: =F13*300% -> 96789.6 | I13: =F13*7.5% -> 2419.74 | J13: 40122.19 | K13: =F13*50% -> 16131.6 | L13: =F13*350% -> 112921.2 | N13: =F13*100% -> 32263.2 | O13: 0 | P13: =F13*10% -> 3226.32 | Q13: 20000 | R13: 0 | S13: =SUM(F13:R13) -> 356137.05 | V13: 15548.33 | W13: =T13+U13+V13 -> 15548.33 | X13: 340588.72 | Y13: =S13-W13 -> 340588.72
A14: 6 | B14: RICHARD KWALMI | D14: MANAGER ICT | E14: 15(7) | G14: 0 | S14: =385000+G14 -> 385000 | T14: 50000 | V14: 15548.33 | W14: =T14+U14+V14 -> 65548.33 | X14: 319451.67 | Y14: =S14-W14 -> 319451.67
A15: 7 | B15: AKINSANMI ADEJOKE OLUKEMI | D15: AM INFORMATION | E15: 15(7) | F15: 31018.84 | H15: =F15*300% -> 93056.52 | I15: =F15*7.5% -> 2326.413 | J15: 40122.19 | K15: =F15*50% -> 15509.42 | L15: =F15*350% -> 108565.94 | M15: 0 | N15: =F15*100% -> 31018.84 | P15: =F15*10% -> 3101.884 | Q15: 20000 | R15: 0 | S15: =SUM(F15:R15) -> 344720.05 | T15: 15000 | U15: =95833 -> 95833 | V15: 15548.33 | W15: =T15+U15+V15 -> 126381.33 | X15: 329171.72 | Y15: =S15-W15 -> 218338.72
A16: 8 | B16: ARCH. TIJO ZARA BORYO | D16: MANAGER, ASSETS/MAINT. | E16: 15(7) | S16: 344720 | V16: 15548.33 | W16: =T16+U16+V16 -> 15548.33 | X16: 0 | Y16: =S16-W16 -> 329171.67
A17: 9 | B17: YAHAYA SHAMSU | D17: AM LEGAL | E17: 13(8) | F17: 23891.12 | G17: 0 | H17: =F17*300% -> 71673.36 | I17: =F17*7.5% -> 1791.834 | K17: =F17*50% -> 11945.56 | L17: =F17*350% -> 83618.92 | N17: =F17*100% -> 23891.12 | P17: =F17*10% -> 2389.112 | Q17: 15000 | S17: =SUM(F17:R17) -> 234201.03 | V17: 7709 | W17: =T17+U17+V17 -> 7709 | X17: 226492.03 | Y17: =S17-W17 -> 226492.03
A18: 10 | B18: TOKUNBO ALFRED ADULOJU | D18: AM LIAISON OFFICE | E18: 13(7) | F18: 23074.99 | H18: =F18*300% -> 69224.97 | I18: =F18*7.5% -> 1730.6243 | K18: =F18*50% -> 11537.495 | L18: =F18*350% -> 80762.465 | N18: =F18*100% -> 23074.99 | P18: =F18*10% -> 2307.499 | Q18: 15000 | S18: =SUM(F18:R18) -> 226713.03 | T18: =20000 -> 20000 | U18: =91333 -> 91333 | V18: 7709 | W18: =T18+U18+V18 -> 119042 | X18: 199004.03 | Y18: =S18-W18 -> 107671.03
A19: 11 | B19: NGARA CHRISTOPHER OCHANJA | D19: OFFICER, SPECIAL DUTIES | E19: 13(7) | F19: 23074.99 | H19: =F19*300% -> 69224.97 | I19: =F19*7.5% -> 1730.6243 | K19: =F19*50% -> 11537.495 | L19: =F19*350% -> 80762.465 | N19: =F19*100% -> 23074.99 | O19: 0 | P19: =F19*10% -> 2307.499 | Q19: 15000 | R19: 0 | S19: =SUM(F19:R19) -> 226713.03 | T19: 20000 | U19: =34167 -> 34167 | V19: 3369.51 | W19: =T19+U19+V19 -> 57536.51 | X19: 209176.52 | Y19: =S19-W19 -> 169176.52
A20: 12 | B20: JOY HARUNA MAKERI | D20: PA DG | E20: 10(11) | F20: 19276.95 | H20: =F20*300% -> 57830.85 | I20: =F20*7.5% -> 1445.7713 | K20: =F20*50% -> 9638.475 | L20: =F20*350% -> 67469.325 | N20: =F20*100% -> 19276.95 | P20: =F20*10% -> 1927.695 | Q20: 10000 | S20: =SUM(F20:R20) -> 186866.02 | V20: 3369.51 | W20: =T20+U20+V20 -> 3369.51 | X20: 183496.51 | Y20: =S20-W20 -> 183496.51
A21: 13 | B21: DONALD E. MKPANAM | D21: AM ICT | E21: 13(10) | F21: 25523.45 | H21: =F21*300% -> 76570.35 | I21: =F21*7.5% -> 1914.2587 | K21: =F21*50% -> 12761.725 | L21: =F21*350% -> 89332.075 | N21: =F21*100% -> 25523.45 | P21: =F21*10% -> 2552.345 | Q21: 15000 | S21: =SUM(F21:R21) -> 249177.65 | V21: 7709.76 | W21: =T21+U21+V21 -> 7709.76 | X21: 241467.89 | Y21: =S21-W21 -> 241467.89
A22: 14 | B22: ABUBAKAR LAMIDO TANKO | D22: ICT OFFICER | E22: 10(9) | F22: 18281.64 | H22: =F22*300% -> 54844.92 | I22: =F22*7.5% -> 1371.123 | K22: 8643.17 | L22: =F22*350% -> 63985.74 | N22: =F22*100% -> 18281.64 | P22: =F22*10% -> 1828.164 | Q22: 10000 | S22: =SUM(F22:R22) -> 177236.4 | T22: 10000 | V22: 3369.51 | W22: =T22+U22+V22 -> 13369.51 | X22: 163866.89 | Y22: =S22-W22 -> 163866.89
A23: 15 | B23: HUSSEIN MUSA AGYE | D23: PROTOCOL OFFICER | E23: 13(7) | F23: 23074.99 | H23: =F23*300% -> 69224.97 | I23: =F23*7.5% -> 1730.6243 | J23: 0 | K23: =F23*50% -> 11537.495 | L23: =F23*350% -> 80762.465 | M23: 0 | N23: =F23*100% -> 23074.99 | O23: 0 | P23: =F23*10% -> 2307.499 | Q23: 15000 | R23: 0 | S23: =SUM(F23:R23) -> 226713.03 | T23: 50000 | U23: 42000 | V23: 3369.51 | W23: =T23+U23+V23 -> 95369.51 | X23: 131343.52 | Y23: =S23-W23 -> 131343.52
A24: 16 | B24: BASHIRU ABBA WALI | D24: ASSIT. INT. AUDIT | E24: 10(7) | F24: 17286.33 | H24: =F24*300% -> 51858.99 | I24: =F24*7.5% -> 1296.4748 | J24: 0 | K24: =F24*50% -> 8643.165 | L24: =F24*350% -> 60502.155 | M24: 0 | N24: =F24*100% -> 17286.33 | O24: 0 | P24: =F24*10% -> 1728.633 | Q24: 10000 | R24: 0 | S24: =SUM(F24:R24) -> 168602.08 | U24: =24917 -> 24917 | V24: 1484.37 | W24: =T24+U24+V24 -> 26401.37 | X24: 167117.71 | Y24: =S24-W24 -> 142200.71
A25: 17 | B25: ALI ABDULLAHI | D25: OFFICER ICT | E25: 10(9) | F25: 18281.64 | H25: =F25*300% -> 54844.92 | I25: =F25*7.5% -> 1371.123 | J25: 0 | K25: =F25*50% -> 9140.82 | L25: =F25*350% -> 63985.74 | M25: 0 | N25: =F25*100% -> 18281.64 | O25: 0 | P25: =F25*10% -> 1828.164 | Q25: 10000 | R25: 0 | S25: =SUM(F25:R25) -> 177734.05 | T25: =5000 -> 5000 | V25: 3369.51 | W25: =T25+U25+V25 -> 8369.51 | X25: 169364.54 | Y25: =S25-W25 -> 169364.54
A26: 18 | B26: UZODINMA EMMANUEL EZENWA | D26: INFORMATION ASST | E26: 10(7) | F26: 17286.33 | H26: =F26*300% -> 51858.99 | I26: =F26*7.5% -> 1296.4748 | J26: 0 | K26: =F26*50% -> 8643.165 | L26: =F26*350% -> 60502.155 | M26: 0 | N26: =F26*100% -> 17286.33 | O26: 0 | P26: =F26*10% -> 1728.633 | Q26: 10000 | R26: 0 | S26: =SUM(F26:R26) -> 168602.08 | T26: 30000 | V26: 1484.37 | W26: =T26+U26+V26 -> 31484.37 | X26: 137117.71 | Y26: =S26-W26 -> 137117.71
A27: 19 | B27: CHRISTIAN MADUABUCHI ODO | D27: ICT ASSISTANT | E27: 10(7) | F27: 17286.33 | H27: =F27*300% -> 51858.99 | I27: =F27*7.5% -> 1296.4748 | K27: =F27*50% -> 8643.165 | L27: =F27*350% -> 60502.155 | N27: =F27*100% -> 17286.33 | P27: =F27*10% -> 1728.633 | Q27: 10000 | S27: =SUM(F27:R27) -> 168602.08 | V27: 1484.37 | W27: =T27+U27+V27 -> 1484.37 | X27: 167117.71 | Y27: =S27-W27 -> 167117.71
A28: 20 | B28: Dahiru Abdullahi | D28: Nass Deployed | F28: 101161.25 | H28: 0 | I28: 0 | J28: 0 | K28: 0 | L28: 0 | M28: 0 | N28: 0 | O28: 0 | P28: 0 | Q28: 0 | R28: 0 | S28: =SUM(F28:R28) -> 101161.25 | V28: 0 | W28: =T28+U28+V28 -> 0 | X28: 101161.25 | Y28: =S28-W28 -> 101161.25
A29: 21 | B29: Moshood M. Olarele | D29: Nass Deployed | F29: 160520.62 | H29: 0 | I29: 0 | J29: 0 | K29: 0 | L29: 0 | M29: 0 | N29: 0 | O29: 0 | P29: 0 | Q29: 0 | R29: 0 | S29: =SUM(F29:R29) -> 160520.62 | T29: 5000 | V29: 0 | W29: =T29+U29+V29 -> 5000 | X29: 155520.62 | Y29: =S29-W29 -> 155520.62
A30: 22 | B30: Ibrahim Babangishiri | D30: Nass Deployed | F30: 101161.25 | H30: 0 | I30: 0 | J30: 0 | K30: 0 | L30: 0 | M30: 0 | N30: 0 | O30: 0 | P30: 0 | Q30: 0 | R30: 0 | S30: =SUM(F30:R30) -> 101161.25 | V30: 0 | W30: =T30+U30+V30 -> 0 | X30: 101161.25 | Y30: =S30-W30 -> 101161.25
A31: 23 | B31: Abdulmalik Dahiru | D31: Nass Deployed | F31: 101161.25 | H31: 0 | I31: 0 | J31: 0 | K31: 0 | L31: 0 | M31: 0 | N31: 0 | O31: 0 | P31: 0 | Q31: 0 | R31: 0 | S31: =SUM(F31:R31) -> 101161.25 | V31: 0 | W31: =T31+U31+V31 -> 0 | X31: 101161.25 | Y31: =S31-W31 -> 101161.25
A32: 24 | B32: Takwasa A. Galadima | D32: Nass Deployed | F32: 114649.42 | H32: 0 | I32: 0 | J32: 0 | K32: 0 | L32: 0 | M32: 0 | N32: 0 | O32: 0 | P32: 0 | Q32: 0 | R32: 0 | S32: =SUM(F32:R32) -> 114649.42 | T32: 10000 | V32: 0 | W32: =T32+U32+V32 -> 10000 | X32: 104649.42 | Y32: =S32-W32 -> 104649.42
C33: TOTAL | D33: 24 | F33: =SUM(F9:F32) -> 1101933.1 | G33: =SUM(G9:G32) -> 0 | H33: =SUM(H9:H32) -> 1409349.1 | I33: =SUM(I9:I32) -> 75355.921 | J33: =SUM(J9:J32) -> 280855.33 | K33: =SUM(K9:K32) -> 253117.57 | L33: =SUM(L9:L32) -> 1751233.2 | M33: =SUM(M9:M32) -> 40122.19 | ... Y33: =SUM(Y9:Y32) -> 6140543.1
B35: LEG. SUPPORT SEVICES
A36: 1 | B36: DR SHUIBU DANWANKA | D36: DD LEG. SP SERVICES | E36: 16(9) | F36: =F46 -> 42653.17 | H36: =F36*300% -> 127959.51 | I36: =F36*7.5% -> 3198.9877 | J36: 40122.19 | K36: =F36*50% -> 21326.585 | L36: =F36*350% -> 149286.1 | M36: 0 | N36: =F36*100% -> 42653.17 | O36: 100000 | P36: =F36*10% -> 4265.317 | Q36: 20000 | R36: 0 | S36: =SUM(F36:R36) -> 551465.02 | V36: 21618.09 | W36: =V36+U36+T36 -> 21618.09 | X36: 529846.93 | Y36: =S36-W36 -> 529846.93
A37: 2 | B37: IBRAHIM USMAN | D37: RESEARCH FELLOW II | E37: 13(11) | F37: 26339.52 | H37: =F37*300% -> 79018.56 | I37: =F37*7.5% -> 1975.464 | J37: =J61 -> 0 | K37: =F37*50% -> 13169.76 | L37: =F37*350% -> 92188.32 | M37: 0 | N37: =F37*100% -> 26339.52 | O37: 100000 | P37: =F37*10% -> 2633.952 | Q37: 15000 | R37: 0 | S37: =SUM(F37:R37) -> 356665.1 | T37: =7000 -> 7000 | V37: 7709.76 | W37: =V37+U37+T37 -> 14709.76 | X37: 348955.34 | Y37: =S37-W37 -> 341955.34
A38: 3 | B38: OFORDEME ADAOBI JULIA | D38: RESEARCH OFFICER | E38: 10(11) | F38: 19276.95 | H38: =F38*300% -> 57830.85 | I38: =F38*7.5% -> 1445.7713 | J38: 0 | K38: =F38*50% -> 9638.475 | L38: =F38*350% -> 67469.325 | M38: 0 | N38: =F38*100% -> 19276.95 | O38: 100000 | P38: =F38*10% -> 1927.695 | Q38: 10000 | R38: 0 | S38: =SUM(F38:R38) -> 286866.02 | V38: 3369.51 | W38: =V38+U38+T38 -> 3369.51 | X38: 283496.51 | Y38: =S38-W38 -> 283496.51
A39: 4 | B39: IKPEAZU CHINEDU ANITA | D39: RESEARCH OFFICER | E39: 10(11) | F39: 19276.95 | H39: =F39*300% -> 57830.85 | I39: =F39*7.5% -> 1445.7713 | J39: 0 | K39: =F39*50% -> 9638.475 | L39: =F39*350% -> 67469.325 | M39: 0 | N39: =F39*100% -> 19276.95 | O39: 100000 | P39: =F39*10% -> 1927.695 | Q39: 10000 | R39: 0 | S39: =SUM(F39:R39) -> 286866.02 | V39: 3369.51 | W39: =V39+U39+T39 -> 3369.51 | X39: 283496.51 | Y39: =S39-W39 -> 283496.51
A40: 5 | B40: ONYEAKU CHUKWUKA EDMOND | D40: RESEARCH OFFICER | E40: 10(9) | F40: 18281.64 | H40: =F40*300% -> 54844.92 | I40: =F40*7.5% -> 1371.123 | J40: =J25 -> 0 | K40: =F40*50% -> 9140.82 | L40: =F40*350% -> 63985.74 | M40: 0 | N40: =F40*100% -> 18281.64 | O40: 100000 | P40: =F40*10% -> 1828.164 | Q40: 10000 | R40: 0 | S40: =SUM(F40:R40) -> 277734.05 | T40: 0 | V40: 3369.51 | W40: =V40+U40+T40 -> 3369.51 | X40: 274364.54 | Y40: =S40-W40 -> 274364.54
A41: 6 | B41: Jibirin Ushama Ahmed | D41: Nass Deployed | F41: 125161.25 | S41: =SUM(F41:R41) -> 125161.25 | W41: =V41+U41+T41 -> 0 | X41: 125161.25 | Y41: =S41-W41 -> 125161.25
B42: TOTAL | D42: 6 | F42: =SUM(F36:F41) -> 250989.48 | G42: =SUM(G36:G41) -> 0 | H42: =SUM(H36:H41) -> 377484.69 | I42: =SUM(I36:I41) -> 9437.1172 | J42: =SUM(J36:J41) -> 40122.19 | K42: =SUM(K36:K41) -> 62914.115 | L42: =SUM(L36:L41) -> 440398.8 | M42: =SUM(M36:M41) -> 0 | ... T42: =SUM(T36:T41) -> 7000 | V42: =SUM(V36:V41) -> 39436.38 | W42: =SUM(W36:W41) -> 46436.38 | X42: =SUM(X36:X41) -> 1845321.1 | Y42: =SUM(Y36:Y41) -> 1838321.1
W43: =SUM(T43:V43)*0.075 -> 0
...

Sheet Sheet6
A1: 1 | B1: DR LADI HAMALAI | C1: DIRECTOR GENERAL | D1: CONSOL
A2: 2 | B2: PROF. OFFORNZE AMUCHEAZI | C2: LEGAL ADVISER | D2: 16(9)
A3: 3 | B3: NWAJEI KANAYO | C3: COMMUNICATION ADVISER | D3: 16(7)
A4: 4 | B4: NWOSU MATHEW EZE | C4: MANAGER INT. AUDIT | D4: 15(9)
A5: 5 | B5: CHIEDO AKALEU | C5: RESEARCH FELLOW II | D5: 15(8)
A6: 6 | B6: AKINSANMI ADEJOKE OLUKEMI | C6: AM INFORMATION | D6: 13(9)
A7: 7 | B7: BEDARI HARI | C7: LEGAL OFFICER | D7: 10(9)
A8: 8 | B8: NGARA CHRISTOPHER OCHANJA | C8: OFFICER, SPECIAL DUTIES | D8: 10(9)
A9: 9 | B9: JOY HARUNA MAKERI | C9: PA DG | D9: 10(9)
A10: 10 | B10: DONALD E. MKPANAM | C10: IT OFFICER | D10: 10(9)
B11: ABUBAKAR LAMIDO | C11: ICT OFFICER | D11: 10(7)
A12: 11 | B12: HUSSEIN MUSA AGYE | C12: PROTOCOL OFFICER | D12: 10(9)
A13: 12 | B13: BASHIRU ABBA WALI | C13: ASSIT. INT. AUDIT | D13: 8(9)
A14: 13 | B14: ALI ABDULLAHI | C14: OFFICER ICT | D14: 10(7)
A15: 14 | B15: UZODINMA EMMANUEL EZENWA | C15: INFORMATION ASST | D15: 8(9)
A16: 15 | B16: CHRISTIAN MADUABUCHI ODO | C16: ICT ASSISTANT | D16: 8(9)
B17: TOTAL | C17: 15
B20: LEG. SUPPORT SEVICES
A21: 1 | B21: PROF OKECHUKWU OKO | C21: DIR. LEG. SP SERVICES | D21: 17(9)
A22: 2 | B22: DR SHUIBU DANWANKA | C22: DD LEG. SP SERVICES | D22: 16(9)
A23: 3 | B23: IBRAHIM USMAN | C23: RESEARCH FELLOW II | D23: 13(9)
A24: 4 | B24: OFORDEME ADAOBI JULIA | C24: RESEARCH OFFICER | D24: 10(9)
A25: 5 | B25: IKPEAZU CHINEDU ANITA | C25: RESEARCH OFFICER | D25: 10(9)
A26: 6 | B26: ONYEAKU CHUKWUKA EDMOND | C26: RESEARCH OFFICER | D26: 10(7)
B27: TOTAL | C27: 6
B29: RESEARCH & TRAINING
A30: 1 | B30: DR ADEYEMI AKEEB FAJINGBESI | C30: DIR. RES. & TRAINING | D30: 17(7)
A31: 2 | B31: DR ASIMIYU G. ABIOLA | C31: DD RESEARCH | D31: 16(9)
A32: 3 | B32: DR KANAYO OGUJIUBA | C32: SRF SOCIAL SECTOR | D32: 15(9)
A33: 4 | B33: DR ADAM GAMBO SALEH | C33: INSTITUTE LIBRARIAN | D33: 15(7)
A34: 5 | B34: DR ANUMUDU CHARLES NNAMDI | C34: SRF I SOCIAL SECTOR | D34: 14(9)
A35: 6 | B35: CATHERINE E. IKOKOH | C35: RESEARCH FELLOW1 DOCU | D35: 14(9)
A36: 7 | C36: RESEARCH FELLOW I | D36: 14(7)
A37: 8 | B37: ABDULKADIR | C37: CHIEF LIBRARIAN | D37: 14(7)
A38: 9 | B38: DR ASEMOTA O. JOSEPH | C38: RESEARCH FELLOW I | D38: 14(7)
A39: 10 | B39: DR UMAR AMINU | C39: RESEARCH FELLOW II | D39: 13(9)
A40: 11 | C40: RESEARCH FELLOW II | D40: 13(8)
A41: 12 | B41: DR JAKE DABANG DAN AZUMI | C41: RESEARCH FELLOW I TRAINING | D41: 14(7)
A42: 13 | B42: TAIWO A. ADEREMI | C42: RESEARCH FELLOW II | D42: 13(7)
A43: 14 | B43: BETHEL UZOMA | C43: RESEARCH FELLOW II | D43: 13(7)
...

Sheet Sheet4
A1: S/N | B1: DG OFFICE | C1: RANK | D1: SALARY LEVEL | E1: AMOUNT
A2: 1 | B2: DR LADI HAMALAI | C2: DIRECTOR GENERAL | D2: CONSOL | E2: 250000
A3: 2 | B3: PROF. OFFORNZE AMUCHEAZI | C3: LEGAL ADVISER | D3: 16(9) | E3: 100000
A4: 3 | B4: NWAJEI KANAYO | C4: COMMUNICATION ADVISER | D4: 16(7) | E4: 100000
A5: 4 | B5: NWOSU MATHEW EZE | C5: MANAGER INT. AUDIT | D5: 15(9) | E5: 75000
A6: 5 | B6: CHIEDO AKALEU | C6: RESEARCH FELLOW II | D6: 15(8) | E6: 75000
A7: 6 | B7: AKINSANMI ADEJOKE OLUKEMI | C7: AM INFORMATION | D7: 13(9) | E7: 50000
A8: 7 | B8: BEDARI HARI | C8: LEGAL OFFICER | D8: 10(9) | E8: 30000
A9: 8 | B9: NGARA CHRISTOPHER OCHANJA | C9: OFFICER, SPECIAL DUTIES | D9: 10(9) | E9: 30000
A10: 9 | B10: JOY HARUNA MAKERI | C10: PA DG | D10: 10(9) | E10: 30000
A11: 10 | B11: DONALD E. MKPANAM | C11: IT OFFICER | D11: 10(9) | E11: 30000
A12: 11 | B12: HUSSEIN MUSA AGYE | C12: PROTOCOL OFFICER | D12: 10(9) | E12: 30000
A13: 12 | B13: BASHIRU ABBA WALI | C13: ASSIT. INT. AUDIT | D13: 8(9) | E13: 30000
... A16: 15 | B16: CHRISTIAN MADUABUCHI ODO | C16: ICT ASSISTANT | D16: 8(9) | E16: 30000
B17: TOTAL | E17: =SUM(E2:E16) -> 920000
B20: LEG. SUPPORT SEVICES
A21: 1 | B21: PROF OKECHUKWU OKO | C21: DIR. LEG. SP SERVICES | D21: 17(9) | E21: 200000
A22: 2 | B22: DR SHUIBU DANWANKA | C22: DD LEG. SP SERVICES | D22: 16(9) | E22: 100000
A23: 3 | B23: IBRAHIM USMAN | C23: RESEARCH FELLOW II | D23: 13(9) | E23: 50000
A24: 4 | B24: OFORDEME ADAOBI JULIA | C24: RESEARCH OFFICER | D24: 10(9) | E24: 30000
A25: 5 | B25: IKPEAZU CHINEDU ANITA | C25: RESEARCH OFFICER | D25: 10(9) | E25: 30000
A26: 6 | B26: ONYEAKU CHUKWUKA EDMOND | C26: RESEARCH OFFICER | D26: 10(7) | E26: 30000
B27: TOTAL | E27: =SUM(E21:E26) -> 440000
B29: RESEARCH & TRAINING
A30: 1 | B30: DR ADEYEMI AKEEB FAJINGBESI | C30: DIR. RES. & TRAINING | D30: 17(7) | E30: 200000
A31: 2 | B31: DR ASIMIYU G. ABIOLA | C31: DD RESEARCH | D31: 16(9) | E31: 100000
A32: 3 | B32: DR KANAYO OGUJIUBA | C32: SRF SOCIAL SECTOR | D32: 15(9) | E32: 75000
A33: 4 | B33: DR ADAM GAMBO SALEH | C33: INSTITUTE LIBRARIAN | D33: 15(7) | E33: 75000
A34: 5 | B34: DR ANUMUDU CHARLES NNAMDI | C34: SRF I SOCIAL SECTOR | D34: 14(9) | E34: 50000
A35: 6 | B35: CATHERINE E. IKOKOH | C35: RESEARCH FELLOW1 DOCU | D35: 14(9) | E35: 50000
A36: 7 | B36: DR CLINTON JAJA | C36: RESEARCH FELLOW I | D36: 14(7) | E36: 50000
A37: 8 | B37: ABDULKADIR I. AHMED | C37: CHIEF LIBRARIAN | D37: 14(7) | E37: 50000
A38: 9 | B38: DR ASEMOTA O. JOSEPH | C38: RESEARCH FELLOW I | D38: 14(7) | E38: 50000
A39: 10 | B39: DR UMAR AMINU | C39: RESEARCH FELLOW II | D39: 13(9) | E39: 50000
A40: 11 | B40: OGUCHE SAMUEL | C40: RESEARCH FELLOW II | D40: 13(8) | E40: 50000
A41: 12 | B41: DR JAKE DABANG DAN AZUMI | C41: RESEARCH FELLOW I TRAINING | D41: 14(7) | E41: 50000
... A54: 25 | B54: ANTHONY EDET | C54: OFFICER M&E | D54: 10(7) | E54: 30000
B55: TOTAL | E55: =SUM(E30:E54) -> 1340000
B59: FINANCE & ADMIN.
A60: 1 | B60: DR KABIR AHMED | C60: DIR. FINANCE & ADMIN | D60: 17(9) | E60: 200000
...

Sheet Sheet5
A1: S/N | B1: DG OFFICE | C1: RANK | D1: SALARY LEVEL | E1: AMOUNT
A2: 1 | B2: DR LADI HAMALAI | C2: DIRECTOR GENERAL | D2: CONSOL | E2: 250000
A3: 2 | B3: PROF. OFFORNZE AMUCHEAZI | C3: LEGAL ADVISER | D3: 16(9) | E3: 100000
A4: 3 | B4: NWAJEI KANAYO | C4: COMMUNICATION ADVISER | D4: 16(7) | E4: 100000
A5: 4 | B5: NWOSU MATHEW EZE | C5: MANAGER INT. AUDIT | D5: 15(9) | E5: 75000
A6: 5 | B6: CHIEDO AKALEU | C6: RESEARCH FELLOW II | D6: 15(8) | E6: 75000
A7: 6 | B7: AKINSANMI ADEJOKE OLUKEMI | C7: AM INFORMATION | D7: 13(9) | E7: 50000
A8: 7 | B8: BEDARI HARI | C8: LEGAL OFFICER | D8: 10(9) | E8: 30000
A9: 8 | B9: NGARA CHRISTOPHER OCHANJA | C9: OFFICER, SPECIAL DUTIES | D9: 10(9) | E9: 30000
A10: 9 | B10: JOY HARUNA MAKERI | C10: PA DG | D10: 10(9) | E10: 30000
A11: 10 | B11: DONALD E. MKPANAM | C11: IT OFFICER | D11: 10(9) | E11: 30000
A12: 11 | B12: HUSSEIN MUSA AGYE | C12: PROTOCOL OFFICER | D12: 10(9) | E12: 30000
A13: 12 | B13: BASHIRU ABBA WALI | C13: ASSIT. INT. AUDIT | D13: 8(9) | E13: 30000
... A16: 15 | B16: CHRISTIAN MADUABUCHI ODO | C16: ICT ASSISTANT | D16: 8(9) | E16: 30000
B17: TOTAL | E17: =SUM(E2:E16) -> 920000
B20: LEG. SUPPORT SEVICES
A21: 1 | B21: PROF OKECHUKWU OKO | C21: DIR. LEG. SP SERVICES | D21: 17(9) | E21: 200000
A22: 2 | B22: DR SHUIBU DANWANKA | C22: DD LEG. SP SERVICES | D22: 16(9) | E22: 100000
A23: 3 | B23: IBRAHIM USMAN | C23: RESEARCH FELLOW II | D23: 13(9) | E23: 50000
A24: 4 | B24: OFORDEME ADAOBI JULIA | C24: RESEARCH OFFICER | D24: 10(9) | E24: 30000
A25: 5 | B25: IKPEAZU CHINEDU ANITA | C25: RESEARCH OFFICER | D25: 10(9) | E25: 30000
A26: 6 | B26: ONYEAKU CHUKWUKA EDMOND | C26: RESEARCH OFFICER | D26: 10(7) | E26: 30000
B27: TOTAL | E27: =SUM(E21:E26) -> 440000
B29: RESEARCH & TRAINING
A30: 1 | B30: DR ADEYEMI AKEEB FAJINGBESI | C30: DIR. RES. & TRAINING | D30: 17(7) | E30: 200000
A31: 2 | B31: DR ASIMIYU G. ABIOLA | C31: DD RESEARCH | D31: 16(9) | E31: 100000
A32: 3 | B32: DR KANAYO OGUJIUBA | C32: SRF SOCIAL SECTOR | D32: 15(9) | E32: 75000
A33: 4 | B33: DR ADAM GAMBO SALEH | C33: INSTITUTE LIBRARIAN | D33: 15(7) | E33: 75000
A34: 5 | B34: DR ANUMUDU CHARLES NNAMDI | C34: SRF I SOCIAL SECTOR | D34: 14(9) | E34: 50000
A35: 6 | B35: CATHERINE E. IKOKOH | C35: RESEARCH FELLOW1 DOCU | D35: 14(9) | E35: 50000
A36: 7 | B36: DR CLINTON JAJA | C36: RESEARCH FELLOW I | D36: 14(7) | E36: 50000
A37: 8 | B37: ABDULKADIR I. AHMED | C37: CHIEF LIBRARIAN | D37: 14(7) | E37: 50000
A38: 9 | B38: DR ASEMOTA O. JOSEPH | C38: RESEARCH FELLOW I | D38: 14(7) | E38: 50000
A39: 10 | B39: DR UMAR AMINU | C39: RESEARCH FELLOW II | D39: 13(9) | E39: 50000
A40: 11 | B40: OGUCHE SAMUEL | C40: RESEARCH FELLOW II | D40: 13(8) | E40: 50000
A41: 12 | B41: DR JAKE DABANG DAN AZUMI | C41: RESEARCH FELLOW I TRAINING | D41: 14(7) | E41: 50000
... A54: 25 | B54: ANTHONY EDET | C54: OFFICER M&E | D54: 10(7) | E54: 30000
B55: TOTAL | E55: =SUM(E30:E54) -> 1340000
B59: FINANCE & ADMIN.
A60: 1 | B60: DR KABIR AHMED | C60: DIR. FINANCE & ADMIN | D60: 17(9) | E60: 200000
...

Sheet Enhanced welfare
A13: S/N | B13: NAMES | D13: DESIGNATION | E13: SCALE | F13: AMOUNT
A14: 1 | B14: OLATUNJI OYEDELE YUSUF | D14: SENIOR DRIVER | E14: 5(9) | F14: 100000
A15: 2 | B15: TASIU MOHAMMED | D15: SENIOR DRIVER | E15: 5(9) | F15: 100000
A16: 3 | B16: NAMADI IDRIS UMAR | D16: SENIOR DRIVER | E16: 5(9) | F16: 100000
A17: 4 | B17: DANJUMA KAGADAMA | D17: SENIOR DRIVER | E17: 5(9) | F17: 100000
A18: 5 | B18: MOHAMMED SIAKA | D18: SENIOR DRIVER | E18: 5(9) | F18: 100000
A19: 6 | B19: ALFRED ISABU | D19: SENIOR DRIVER | E19: 5(9) | F19: 100000
A20: 7 | B20: ALIYU YAKUBU | D20: SENIOR DRIVER | E20: 5(9) | F20: 100000
A21: 8 | B21: ABDULLAHI HARUNA | D21: SENIOR DRIVER | E21: 5(9) | F21: 100000
A22: 9 | B22: EJEME PATRICK | D22: DRIVER | E22: 4(10) | F22: 100000
A23: 10 | B23: OGABO OGAH USMAN | D23: DRIVER | E23: 4(10) | F23: 100000
A24: 11 | B24: ETSU UMARU | D24: DRIVER | E24: 4(10) | F24: 100000
A25: 12 | B25: MURTALA LAWAL | D25: DRIVER | E25: 4(10) | F25: 100000
... A30: 17 | B30: ABUBAKAR MUSA DANLAMI | D30: DRIVER | E30: 4(9) | F30: 100000
A31: 18 | B31: Ayuba Sule | D31: Gardener | F31: 100000
A32: 19 | B32: Abdulwahab Dahiru | D32: Admin. Assisatant | E32: 8(7) | F32: 300000
B33: TOTAL | F33: =SUM(F14:F32) -> 2100000

Sheet Get Together
A1: S/N | B1: DG OFFICE | F1: N | G1: SIGNATURE
A2: 1 | B2: PROF. OFFORNZE AMUCHEAZI | D2: LEGAL ADVISER | E2: 16(9) | F2: 100000
A3: 2 | B3: NWAJEI KANAYO | D3: COMMUNICATION ADVISER | E3: 16(7) | F3: 100000
A4: 3 | B4: NWOSU MATHEW EZE | D4: MANAGER INT. AUDIT | E4: 15(9) | F4: 80000
A5: 4 | B5: CHIEDO AKALEU | D5: RESEARCH FELLOW II | E5: 15(8) | F5: 80000
A6: 5 | B6: AKINSANMI ADEJOKE OLUKEMI | D6: AM INFORMATION | E6: 13(9) | F6: 50000
A7: 6 | B7: BEDARI HARI | D7: LEGAL OFFICER | E7: 10(9) | F7: 50000
A8: 7 | B8: NGARA CHRISTOPHER OCHANJA | D8: OFFICER, SPECIAL DUTIES | E8: 10(9) | F8: 50000
A9: 8 | B9: JOY HARUNA MAKERI | D9: PA DG | E9: 10(9) | F9: 50000
A10: 9 | B10: DONALD E. MKPANAM | D10: AM ICT | E10: 13(7) | F10: 50000
A11: 10 | B11: ABUBAKAR LAMIDO | D11: ICT OFFICER | E11: 10(7) | F11: 50000
A12: 11 | B12: HUSSEIN MUSA AGYE | D12: PROTOCOL OFFICER | E12: 10(9) | F12: 50000
A13: 12 | B13: BASHIRU ABBA WALI | D13: ASSIT. INT. AUDIT | E13: 8(9) | F13: 30000
... A17: 16 | B17: CHRISTIAN MADUABUCHI ODO | D17: ICT ASSISTANT | E17: 8(9) | F17: 30000
B18: TOTAL | F18: =SUM(F2:F17) -> 880000
B21: LEG. SUPPORT SEVICES
A22: 1 | B22: PROF OKECHUKWU OKO | D22: DIR. LEG. SP SERVICES | E22: 17(9) | F22: 100000
A23: 2 | B23: DR SHUIBU DANWANKA | D23: DD LEG. SP SERVICES | E23: 16(9) | F23: 100000
A24: 3 | B24: IBRAHIM USMAN | D24: RESEARCH FELLOW II | E24: 13(9) | F24: 50000
A25: 4 | B25: OFORDEME ADAOBI JULIA | D25: RESEARCH OFFICER | E25: 10(9) | F25: 30000
A26: 5 | B26: IKPEAZU CHINEDU ANITA | D26: RESEARCH OFFICER | E26: 10(9) | F26: 30000
A27: 6 | B27: ONYEAKU CHUKWUKA EDMOND | D27: RESEARCH OFFICER | E27: 10(7) | F27: 30000
B28: TOTAL | F28: =SUM(F22:F27) -> 340000
B30: RESEARCH & TRAINING
A31: 1 | B31: DR ADEYEMI AKEEB FAJINGBESI | D31: DIR. RES. & TRAINING | E31: 17(7) | F31: 100000
A32: 2 | B32: DR ASIMIYU G. ABIOLA | D32: DD RESEARCH | E32: 16(9) | F32: 100000
A33: 3 | B33: DR KANAYO OGUJIUBA | D33: SRF SOCIAL SECTOR | E33: 15(9) | F33: 80000
A34: 4 | B34: DR ADAM GAMBO SALEH | D34: INSTITUTE LIBRARIAN | E34: 15(7) | F34: 80000
A35: 5 | B35: CATHERINE E. IKOKOH | D35: RESEARCH FELLOW1 DOCU | E35: 14(9) | F35: 60000
A36: 6 | B36: DR CLINTON JAJA | D36: RESEARCH FELLOW I | E36: 14(7) | F36: 60000
A37: 7 | B37: ABDULKADIR I. AHMED | D37: CHIEF LIBRARIAN | E37: 14(7) | F37: 60000
A38: 8 | B38: DR ASEMOTA O. JOSEPH | D38: RESEARCH FELLOW I | E38: 14(7) | F38: 60000
A39: 9 | B39: DR UMAR AMINU | D39: RESEARCH FELLOW II | E39: 13(9) | F39: 50000
A40: 10 | B40: OGUCHE SAMUEL | D40: RESEARCH FELLOW II | E40: 13(8) | F40: 50000
A41: 11 | B41: DR JAKE DABANG DAN AZUMI | D41: RESEARCH FELLOW I TRAINING | E41: 14(7) | F41: 50000
A42: 12 | B42: TAIWO A. ADEREMI | D42: RESEARCH FELLOW II | E42: 13(7) | F42: 50000
... A53: 24 | B53: ANTHONY EDET | D53: OFFICER M&E | E53: 10(7) | F53: 30000
B54: TOTAL | F54: =SUM(F31:F53) -> 1210000
B58: FINANCE & ADMIN.
A59: 1 | B59: DR KABIR AHMED | D59: DIR. FINANCE & ADMIN | E59: 17(9) | F59: 100000
...

Sheet MEMO
A1: NATIONAL INSTITUTE FOR LEGISLATIVE STUDIES
A4: INTERNAL MEMO
A6: FROM : DDF
A7: THROUGH: DFA
A8: TO: DG
A9: 7TH MARCH, 2017
A11: Subject: Payroll for the month of February, 2017
A13: Find below the details of NILS Staff Payroll for the month of February, 2017
E15: JANUARY, 2017 | G15: FEBRUARY, 2017
E16: NO OF | F16: AMOUNT | G16: NO OF | H16: AMOUNT
E17: STAFF | F17: N | G17: STAFF | H17: N
A18: 1 | B18: Director General's Office | E18: 26 | F18: ='Feb. 2017'!X33 -> 5974704.4 | G18: 25 | H18: ='Feb. 2017'!Y33 -> 6140543.1
A19: 2 | B19: Leg. Support Services | E19: 6 | F19: ='Feb. 2017'!X42 -> 1845321.1 | G19: 6 | H19: ='Feb. 2017'!Y42 -> 1838321.1
A20: 3 | B20: Research & Training | E20: 25 | F20: ='Feb. 2017'!X69 -> 8383072.7 | G20: 24 | H20: ='Feb. 2017'!Y69 -> 8336309
A21: 4 | B21: Finance/ Admin & HR | E21: 55 | F21: ='Feb. 2017'!X126 -> 6295489.6 | G21: 54 | H21: ='Feb. 2017'!Y126 -> 6247901.6
E22: =SUM(E18:E21) -> 112 | F22: =SUM(F18:F21) -> 22498588 | G22: =SUM(G18:G21) -> 109 | H22: =SUM(H18:H21) -> 22563075
A24: VARIATION IN FEBRUARY 2017 OVER JANUARY,2017 SALARIES
A26: GROSS SALARY FOR FEBRUARY, 2017 | H26: ='Feb. 2017'!S127 -> 25746007
A27: DEDUCTIONS
A28: COOP SOCIETY DEDUCTIONS | G28: ='Feb. 2017'!T127 -> 1402200
A29: COOP ADVANCE RECOVERY | G29: ='Feb. 2017'!U127 -> 1064638
A30: PAYE DEDUCTIONS | G30: ='Feb. 2017'!V127 -> 716093.05
A31: TOTAL DEDUCTIONS FOR FEBRUARY | H31: =SUM(G28:G30) -> 3182931
A32: NET PAY AS PER FEBRUARY, 2017 PAYROLL | H32: =H26-H31-0.93 -> 22563075
A33: NET PAY AS PER JANUARY, 2017 PAYROLL | H33: =F22 -> 22498588
A34: NET INCREASE/ (DECREASE) IN PAY FOR FEBRUARY, 2017 | H34: =H32-H33 -> 64486.945
A36: The net Salary Increase/(Decrease) is reconciled as follows:
A37: Effect of termination of responsibility allowancws to Eze Nwosu and Chris Ngara | H37: -90000
A38: Effect of Salary adjustment to Dr Olarenwaju Niyi John eqivalence to SRF | H38: =444720-467553.5 -> -22833.5
A39: Effect of payment of responsibility allowance to Finance Officers (Rahila and Tondo) | H39: 100000
A40: Effect of Recruitment of Assets and Maintainance Manager Arch Tijo Z. Boryo | H40: 344720
A41: Effect of COOP Salary Advance/Loan Recovery and Savings | H41: -257920.83
A42: Effect of PAYE variations | H42: =-15548.33+6069.76 -> -9478.57
H44: =SUM(H37:H42) -> 64487.1
A45: The Director General is requested to consider and approve payment of N22,563,074.76 to Guaranty Trust Bank being February, 2017 Salary, N1,064,638.00 being NILS Coop Society deductions for February and N716,093.05 being PAYE TAX Deductions from Staff Salary for the month of February, 2017.
A48: Mshelia Madu Ibrahim
A49: Deputy Director, Finance & Accounts

Sheet 17.9
A1: SALARY DETAILS OF NILS DIRECTOR RESEARCH AND TRAINING
A2: GRADE LEVEL 17 STEP 7
D3: ANNUALLY | E3: MONTHLY
A4: Basic Salary | D4: =E4*12 -> 948475.68 | E4: =sUMMARY!F3 -> 79039.64
A5: Rent Subsidy | D5: =E5*12 -> 2845427 | E5: =sUMMARY!H3 -> 237118.92
A6: Utility | D6: =E6*12 -> 71135.676 | E6: =sUMMARY!I3 -> 5927.973
A7: Domestic Staff Allowance | D7: =E7*12 -> 962932.56 | E7: =sUMMARY!J3 -> 80244.38
A8: Entertainment Allowance | D8: =E8*12 -> 474237.84 | E8: =sUMMARY!K3 -> 39519.82
A9: Furniture Allowance | D9: =E9*12 -> 3319664.9 | E9: =sUMMARY!L3 -> 276638.74
A10: Research Allowance | D10: =E10*12 -> 0
A11: Motor Fuel Allowance | D11: =E11*12 -> 948475.68 | E11: =sUMMARY!N3 -> 79039.64
A12: Leave Allowance | D12: =E12*12 -> 94847.568 | E12: =sUMMARY!O3 -> 7903.964
A13: Outfit Allowance | D13: =E13*12 -> 240000 | E13: =sUMMARY!P3 -> 20000
A14: GROSS SALARY | D14: =E14*12 -> 9905196.9 | E14: =SUM(E4:E13) -> 825433.08

Sheet 16.9
A1: SALARY DETAILS OF NILS DEPUTY DIRECTORS
A2: GRADE LEVEL 16 STEP 7
D3: ANNUALLY | E3: MONTHLY
A4: Basic Salary | D4: =E4*12 -> #REF! | E4: ='Feb. 2017'!#REF! -> #REF!
A5: Rent Subsidy | D5: =E5*12 -> #REF! | E5: ='Feb. 2017'!#REF! -> #REF!
A6: Utility | D6: =E6*12 -> #REF! | E6: ='Feb. 2017'!#REF! -> #REF!
A7: Domestic Staff Allowance | D7: =E7*12 -> #REF! | E7: ='Feb. 2017'!#REF! -> #REF!
A8: Entertainment Allowance | D8: =E8*12 -> #REF! | E8: ='Feb. 2017'!#REF! -> #REF!
A9: Furniture Allowance | D9: =E9*12 -> #REF! | E9: ='Feb. 2017'!#REF! -> #REF!
A10: Motor Fuel Allowance | D10: =E10*12 -> #REF! | E10: ='Feb. 2017'!#REF! -> #REF!
A11: Leave Allowance | D11: =E11*12 -> #REF! | E11: ='Feb. 2017'!#REF! -> #REF!
A12: Outfit Allowance | D12: =E12*12 -> 240000 | E12: =sUMMARY!P3 -> 20000
A13: GROSS SALARY | D13: =E13*12 -> #REF! | E13: =SUM(E4:E12) -> #REF!

Sheet 15.9
A1: SALARY DETAILS OF NILS SENIOR RESEARCH FELLOWS
A2: GRADE LEVEL 15 STEP 9
D3: ANNUALLY | E3: MONTHLY
A4: Basic Salary | D4: =E4*12 -> 402090 | E4: ='Feb. 2017'!F47 -> 33507.5
A5: Rent Subsidy | D5: =E5*12 -> 1206270 | E5: ='Feb. 2017'!H47 -> 100522.5
A6: Utility | D6: =E6*12 -> 30156.72 | E6: 2513.06
A7: Domestic Staff Allowance | D7: =E7*12 -> 481466.28 | E7: 40122.19
A8: Entertainment Allowance | D8: =E8*12 -> 201045 | E8: 16753.75
A9: Furniture Allowance | D9: =E9*12 -> 1407315 | E9: 117276.25
A10: Motor Fuel Allowance | D10: =E10*12 -> 402090 | E10: 33507.5
A11: Research Allowance | D11: =E11*12 -> 1200000 | E11: 100000
A12: Leave Allowance | D12: =E12*12 -> 40209 | E12: 3350.75
A13: Outfit Allowance | D13: =E13*12 -> 240000 | E13: 20000
A14: GROSS SALARY | D14: =E14*12 -> 5610642 | E14: =SUM(E4:E13) -> 467553.5

Sheet 13.7
A1: SALARY DETAILS OF NILS RESEARCH FELLOW II
A2: GRADE LEVEL 13 STEP 8
D3: ANNUALLY | E3: MONTHLY
A4: Basic Salary | D4: =E4*12 -> 286693.44 | E4: =sUMMARY!F6 -> 23891.12
A5: Rent Subsidy | D5: =E5*12 -> 860080.32 | E5: =sUMMARY!H6 -> 71673.36
A6: Utility | D6: =E6*12 -> 21502.008 | E6: =sUMMARY!I6 -> 1791.834
A7: Domestic Staff Allowance | D7: =E7*12 -> 0 | E7: =sUMMARY!J6 -> 0
A8: Entertainment Allowance | D8: =E8*12 -> 143346.72 | E8: =sUMMARY!K6 -> 11945.56
A9: Furniture Allowance | D9: =E9*12 -> 1003427 | E9: =sUMMARY!L6 -> 83618.92
A10: Motor Fuel Allowance | D10: =E10*12 -> 286693.44 | E10: =sUMMARY!N6 -> 23891.12
A11: Research Allowance | D11: =E11*12 -> 0 | E11: 0
A12: Leave Allowance | D12: =E12*12 -> 28669.344 | E12: =sUMMARY!O6 -> 2389.112
A13: Outfit Allowance | D13: =E13*12 -> 180000 | E13: =sUMMARY!P6 -> 15000
A14: GROSS SALARY | D14: =E14*12 -> 2810412.3 | E14: =SUM(E4:E13) -> 234201.03

Sheet 12.7
D3: ANNUALLY | E3: MONTHLY
A4: Basic Salary | D4: =E4*12 -> 255527.52 | E4: =sUMMARY!F7 -> 21293.96
A5: Rent Subsidy | D5: =E5*12 -> 766582.56 | E5: =sUMMARY!H7 -> 63881.88
A6: Utility | D6: =E6*12 -> 19164.564 | E6: =sUMMARY!I7 -> 1597.047
A7: Domestic Staff Allowance | D7: =E7*12 -> 0 | E7: =sUMMARY!J6 -> 0
A8: Entertainment Allowance | D8: =E8*12 -> 127763.76 | E8: =sUMMARY!K7 -> 10646.98
A9: Furniture Allowance | D9: =E9*12 -> 894346.32 | E9: =sUMMARY!L7 -> 74528.86
A10: Motor Fuel Allowance | D10: =E10*12 -> 255527.52 | E10: =sUMMARY!N7 -> 21293.96
A11: Leave Allowance | D11: =E11*12 -> 25552.752 | E11: =sUMMARY!O7 -> 2129.396
A12: Outfit Allowance | D12: =E12*12 -> 120000 | E12: =sUMMARY!P7 -> 10000
A13: GROSS SALARY | D13: =E13*12 -> 2464465 | E13: =SUM(E4:E12) -> 205372.08

Sheet 10.7
A1: SALARY DETAILS OF NILS RESEARCH OFFICERS
A2: GRADE LEVEL 10 STEP 7
D3: ANNUALLY | E3: MONTHLY
A4: Basic Salary | D4: =E4*12 -> 207435.96 | E4: =sUMMARY!F8 -> 17286.33
A5: Rent Subsidy | D5: =E5*12 -> 622307.88 | E5: =sUMMARY!H8 -> 51858.99
A6: Utility | D6: =E6*12 -> 15557.697 | E6: =sUMMARY!I8 -> 1296.4748
A7: Domestic Staff Allowance | D7: =E7*12 -> 0 | E7: =sUMMARY!J6 -> 0
A8: Entertainment Allowance | D8: =E8*12 -> 103717.98 | E8: =sUMMARY!K8 -> 8643.165
A9: Furniture Allowance | D9: =E9*12 -> 726025.86 | E9: =sUMMARY!L8 -> 60502.155
A10: Motor Fuel Allowance | D10: =E10*12 -> 207435.96 | E10: =sUMMARY!N8 -> 17286.33
A11: Research Allowance | D11: =E11*12 -> 480000 | E11: 40000
A12: Leave Allowance | D12: =E12*12 -> 20743.596 | E12: =sUMMARY!O8 -> 1728.633
A13: Outfit Allowance | D13: =E13*12 -> 120000 | E13: =sUMMARY!P7 -> 10000
A14: GROSS SALARY | D14: =E14*12 -> 2503224.9 | E14: =SUM(E4:E13) -> 208602.08

Sheet 9.7
A1: SALARY DETAILS OF NILS RESEARCH ASSISTANTS
A2: GRADE LEVEL 9 STEP 7
D3: ANNUALLY | E3: MONTHLY
A4: Basic Salary | D4: =E4*12 -> 176833.68 | E4: =sUMMARY!F9 -> 14736.14
A5: Rent Subsidy | D5: =E5*12 -> 530501.04 | E5: =sUMMARY!H9 -> 44208.42
A6: Utility | D6: =E6*12 -> 13262.526 | E6: =sUMMARY!I9 -> 1105.2105
A7: Domestic Staff Allowance | D7: =E7*12 -> 0 | E7: =sUMMARY!J6 -> 0
A8: Entertainment Allowance | D8: =E8*12 -> 88416.84 | E8: =sUMMARY!K9 -> 7368.07
A9: Furniture Allowance | D9: =E9*12 -> 618917.88 | E9: =sUMMARY!L9 -> 51576.49
A10: Motor Fuel Allowance | D10: =E10*12 -> 176833.68 | E10: =sUMMARY!N9 -> 14736.14
A11: Research Assistants | D11: =E11*12 -> 480000 | E11: 40000
A12: Leave Allowance | D12: =E12*12 -> 17683.368 | E12: =sUMMARY!O9 -> 1473.614
A13: Outfit Allowance | D13: =E13*12 -> 120000 | E13: =sUMMARY!P7 -> 10000
A14: GROSS SALARY | D14: =E14*12 -> 2222449 | E14: =SUM(E4:E13) -> 185204.08

Sheet 8.7
A1: SALARY OF SECRTARY ON SCALE 8 STEP 7
D3: ANNUALLY | E3: MONTHLY
A4: Basic Salary | D4: =E4*12 -> 219379.68 | E4: ='Feb. 2017'!F68 -> 18281.64
A5: Rent Subsidy | D5: =E5*12 -> #REF! | E5: ='Feb. 2017'!#REF! -> #REF!
A6: Utility | D6: =E6*12 -> #REF! | E6: ='Feb. 2017'!#REF! -> #REF!
A7: Entertainment Allowance | D7: =E7*12 -> 103717.98 | E7: ='Feb. 2017'!K84 -> 8643.165
A8: Furniture Allowance | D8: =E8*12 -> #REF! | E8: ='Feb. 2017'!#REF! -> #REF!
A9: Motor Fuel Allowance | D9: =E9*12 -> 207435.96 | E9: ='Feb. 2017'!N84 -> 17286.33
A10: Leave Allowance | D10: =E10*12 -> #REF! | E10: ='Feb. 2017'!#REF! -> #REF!
A11: Outfit Allowance | D11: =E11*12 -> 120000 | E11: ='Feb. 2017'!Q84 -> 10000
A12: GROSS SALARY | D12: =E12*12 -> #REF! | E12: =SUM(E4:E11) -> #REF!

Sheet sUMMARY
F1: BASIC | G1: 28 DAYS ALCE | M1: PERSONAL | N1: MOTOR/ | O1: RESEARCH | P1: LEAVE | Q1: OUT FIT | R1: LEGISLATIVE | S1: GROSS | U1: MAR.2012 | V1: FEB. 2012
F2: SALARY | G2: IN LIEU | H2: RENT | I2: UTILITY | J2: DOMESTIC | K2: ENTERT. | L2: FURNIT. | M2: ASSISTANT | N2: FUEL | O2: ALLOWANCE | P2: ALLCE | Q2: ALLCE | R2: DUTY ALLCE | S2: SALARY | T2: PAYE
A3: DIRECTOR | E3: 17/8 | F3: 79039.64 | H3: =F3*300% -> 237118.92 | I3: =F3*7.5% -> 5927.973 | J3: 80244.38 | K3: =F3*50% -> 39519.82 | L3: =F3*350% -> 276638.74 | M3: 0 | N3: =F3*100% -> 79039.64 | O3: =F3*10% -> 7903.964 | P3: 20000 | Q3: 0 | R3: =SUM(F3:Q3) -> 825433.08
A4: DEPUTY DIRECTOR | E4: 16/8 | F4: 36784.71 | H4: =F4*300% -> 110354.13 | I4: =F4*7.5% -> 2758.8532 | J4: 80244.38 | K4: =F4*50% -> 18392.355 | L4: =F4*350% -> 128746.49 | N4: =F4*100% -> 36784.71 | O4: =F4*10% -> 3678.471 | P4: 20000 | Q4: 0 | R4: =SUM(F4:Q4) -> 437744.09
A5: RESEARCH FELLOW I | E5: 14(7) | F5: 24975.81 | G5: 0 | H5: =F5*300% -> 74927.43 | I5: =F5*7.5% -> 1873.1858 | J5: 0 | K5: =F5*50% -> 12487.905 | L5: =F5*350% -> 87415.335 | M5: 0 | N5: =F5*100% -> 24975.81 | O5: 100000 | P5: =F5*10% -> 2497.581 | Q5: 20000 | R5: 0 | S5: =SUM(F5:R5) -> 349153.06 | T5: 0 | U5: =S5-T5 -> 349153.06 | V5: 344720.6
A6: RESEARCH FELLOW II | E6: 13/7 | F6: 23891.12 | H6: =F6*300% -> 71673.36 | I6: =F6*7.5% -> 1791.834 | J6: 0 | K6: =F6*50% -> 11945.56 | L6: =F6*350% -> 83618.92 | M6: 0 | N6: =F6*100% -> 23891.12 | O6: =F6*10% -> 2389.112 | P6: 15000 | Q6: 0 | R6: =SUM(F6:Q6) -> 234201.03
A7: RESEARCH FELLOW | E7: 12/7 | F7: 21293.96 | H7: =F7*300% -> 63881.88 | I7: =F7*7.5% -> 1597.047 | J7: 0 | K7: =F7*50% -> 10646.98 | L7: =F7*350% -> 74528.86 | M7: 0 | N7: =F7*100% -> 21293.96 | O7: =F7*10% -> 2129.396 | P7: 10000 | Q7: 0 | R7: =SUM(F7:Q7) -> 205372.08
A8: RESEARCH OFFICER | E8: 10/7 | F8: 17286.33 | H8: =F8*300% -> 51858.99 | I8: =F8*7.5% -> 1296.4748 | J8: 0 | K8: =F8*50% -> 8643.165 | L8: =F8*350% -> 60502.155 | M8: 0 | N8: =F8*100% -> 17286.33 | O8: =F8*10% -> 1728.633 | P8: 10000 | Q8: 0 | R8: =SUM(F8:Q8) -> 168602.08
A9: RESEARCH ASSISTANTS | E9: 9/7 | F9: 14736.14 | H9: =F9*300% -> 44208.42 | I9: =F9*7.5% -> 1105.2105 | J9: 0 | K9: =F9*50% -> 7368.07 | L9: =F9*350% -> 51576.49 | M9: 0 | N9: =F9*100% -> 14736.14 | O9: =F9*10% -> 1473.614 | P9: 10000 | Q9: 0 | R9: =SUM(F9:Q9) -> 145204.08
E10: 8/7 | F10: 12351.94 | H10: =F10*300% -> 37055.82 | I10: =F10*7.5% -> 926.3955 | J10: 0 | K10: =F10*50% -> 6175.97 | L10: =F10*350% -> 43231.79 | M10: 0 | N10: =F10*100% -> 12351.94 | O10: =F10*10% -> 1235.194 | P10: 10000 | Q10: 0 | R10: =SUM(F10:Q10) -> 123329.05

Sheet 14.7
A1: SALARY DETAILS OF NILS CHIEF LIBRARIAN
A2: GRADE LEVEL 14 STEP 7
D3: ANNUALLY | E3: MONTHLY
A4: Basic Salary | D4: =E4*12 -> 299709.72 | E4: =sUMMARY!F5 -> 24975.81
A5: Rent Subsidy | D5: =E5*12 -> 899129.16 | E5: =sUMMARY!H5 -> 74927.43
A6: Utility | D6: =E6*12 -> 22478.229 | E6: =sUMMARY!I5 -> 1873.1858
A7: Domestic Staff Allowance | D7: =E7*12 -> 0 | E7: =sUMMARY!J6 -> 0
A8: Entertainment Allowance | D8: =E8*12 -> 149854.86 | E8: =sUMMARY!K5 -> 12487.905
A9: Furniture Allowance | D9: =E9*12 -> 1048984 | E9: =sUMMARY!L5 -> 87415.335
A10: Motor Fuel Allowance | D10: =E10*12 -> 299709.72 | E10: =sUMMARY!N5 -> 24975.81
A11: Research Allowance | D11: =E11*12 -> 0 | E11: 0
A12: Leave Allowance | D12: =E12*12 -> 29970.972 | E12: =sUMMARY!P5 -> 2497.581
A13: Outfit Allowance | D13: =E13*12 -> 240000 | E13: =sUMMARY!Q5 -> 20000
A14: GROSS SALARY | D14: =E14*12 -> 2989836.7 | E14: =SUM(E4:E13) -> 249153.06

Sheet Sheet2
A1: LIST OF STAFF THAT HAVE ASSUMED DUTY
A2: STAFF NAME
D3: DESIGNATION | E3: SALARY
E4: LEVEL
A5: DG OFFICE
A6: DR LADI HAMALAI | D6: DG | E6: CONSOL
A7: PROF. OFFORNZE AMUCHEAZI | D7: LEGAL ADVISER | E7: 16(7)
A8: MOHAMMED ISIAKA YAKUBU | D8: SPECIAL ASSISTANT | E8: 16(7)
A9: RICHARD KWALMI | D9: DSM | E9: 15(7)
A10: ABDULSALAM MUSTAFA | D10: ICT OFFICER | E10: 10(10)
A11: ALI ABDULLAHI | D11: 1CT ASSISTANT | E11: 8(2)
A13: LEG. SUPPORT SEVICES
A14: DR SHUIBU DANWANKA | D14: DD | E14: 16(7)
A16: RESEARCH & TRAINING
A17: DR ASIMIYU G. ABIOLA | D17: DD RESEARCH | E17: 16(7)
A18: SOLOMON A. BENJAMIN | D18: DD TRAINING | E18: 16(7)
A19: DR PATTERSON EKEOCHA | D19: SRF | E19: 15(9)
A21: FINANCE & ADMIN.
A22: DR KABIR AHMED | D22: DFA | E22: 17(7)
A23: IBRAHIM M. MSHELIA | D23: DD F&A | E23: 16(7)
A24: AMINU BELLO DUKKU | D24: DD ADMIN/HR | E24: 16(7)
A25: RAHILA AMOS | D25: OFFICER ACCTS | E25: 10(11)
A26: HUSSEIN MUSA AGYE | D26: PROTOCOL OFFICER | E26: 10(&)
A27: USMAN WAZIRI | D27: SEC. FINANCE | E27: 8(9)
A28: SALAMATU YAKUBU | D28: SECRETARY | E28: 8(9)
A29: IDAHOSA JANE CECILIA | D29: SECRETARY | E29: 8/(9)
A30: ESTHER WAMINAJE | D30: SECRETARY | E30: 8(9)
A31: ANTHONY EDET | D31: RECEPTIONIST | E31: 8(2)
A32: OLATUNJI OYEDELE YUSUF | D32: DRIVER | E32: 4(10)
A33: TASIU MOHAMMED | D33: DRIVER | E33: 4(10)
... A41: ABDULLAHI HARUNA | D41: DRIVER | E41: 3(8)
A42: ABDULWAHAB DAHIRU | D42: DISPATCH CLERK
A43: GIDEON B. LAMIDO | D43: DISPATCH CLERK
A44: JOHN JAMBU ASIGAN | D44: STEWARD
A45: AYUBA SULE | D45: STEWARD
A46: EWELIKWA IJEOMA NKOLIKWA | D46: STEWARD

Sheet 15.7
A1: SALARY DETAILS OF NILS LIBRARIAN
A2: GRADE LEVEL 15 STEP 7
B3: ANNUALLY | C3: MONTHLY
A4: Basic Salary | B4: =C4*12 -> 475947 | C4: 39662.25
A5: Rent Subsidy | B5: =C5*12 -> 1427841 | C5: 118986.75
A6: Utility | B6: =C6*12 -> 35696.04 | C6: 2974.67
A7: Domestic Staff Allowance | B7: =C7*12 -> #REF! | C7: ='Feb. 2017'!#REF! -> #REF!
A8: Entertainment Allowance | B8: =C8*12 -> 237973.56 | C8: 19831.13
A9: Furniture Allowance | B9: =C9*12 -> 1665814.6 | C9: 138817.88
A10: Motor Fuel Allowance | B10: =C10*12 -> 475947 | C10: 39662.25
A11: Research Allowance | B11: =C11*12 -> 0 | C11: 0
A12: Leave Allowance | B12: =C12*12 -> 47594.76 | C12: 3966.23
A13: Outfit Allowance | B13: =C13*12 -> #REF! | C13: ='Feb. 2017'!#REF! -> #REF!
A14: GROSS SALARY | B14: =SUM(B4:B13) -> #REF! | C14: =SUM(C4:C13) -> #REF!

Sheet 5.7
A1: SALARY DETAILS OF NILS SENIOR MOTOR DRIVER-MECHANIC
A2: GRADE LEVEL 5 STEP 7
D3: ANNUALLY | E3: MONTHLY
A4: Basic Salary | D4: =E4*12 -> #REF! | E4: ='Feb. 2017'!#REF! -> #REF!
A5: Rent Subsidy | D5: =E5*12 -> #REF! | E5: ='Feb. 2017'!#REF! -> #REF!
A6: Utility | D6: =E6*12 -> #REF! | E6: ='Feb. 2017'!#REF! -> #REF!
A7: Domestic Staff Allowance | D7: =E7*12 -> 0 | E7: =sUMMARY!J6 -> 0
A8: Entertainment Allowance | D8: =E8*12 -> #REF! | E8: ='Feb. 2017'!#REF! -> #REF!
A9: Furniture Allowance | D9: =E9*12 -> #REF! | E9: ='Feb. 2017'!#REF! -> #REF!
A10: Motor Fuel Allowance | D10: =E10*12 -> #REF! | E10: ='Feb. 2017'!#REF! -> #REF!
A11: Research Allowance | D11: =E11*12 -> 0 | E11: 0
A12: Leave Allowance | D12: =E12*12 -> #REF! | E12: ='Feb. 2017'!#REF! -> #REF!
A13: Outfit Allowance | D13: =E13*12 -> #REF! | E13: ='Feb. 2017'!#REF! -> #REF!
A14: GROSS SALARY | D14: =E14*12 -> #REF! | E14: =SUM(E4:E13) -> #REF!

Sheet Noninal roll
A2: NOMINAL ROLL AND 2012 PERSONEL COST ESTIMATION
A3: S/NO | B3: DESIGNATION | C3: SALARY LEVEL | D3: NUMBER | E3: ANNUAL SALARY | F3: TOTAL
A5: 1 | B5: DIRECTOR GENERAL | C5: CONS. | D5: 1 | E5: =1580439.5*12 -> 18965274 | F5: =E5*D5 -> 18965274
A6: 2 | B6: DIRECTORS | C6: 17(7) | D6: 4 | E6: 9607889.5 | F6: =E6*D6 -> 38431558
A7: 3 | B7: LEGAL ADVISER | C7: 16(7) | D7: 1 | E7: =424023.33*12 -> 5088280 | F7: =E7*D7 -> 5088280
A8: 4 | B8: SPECIAL ASSISTANT | C8: 16(7) | D8: 2 | E8: =424023.33*12 -> 5088280 | F8: =E8*D8 -> 10176560
A9: 5 | B9: DEUTY DIRECTORS | C9: 16(7) | D9: 10 | E9: 5088280 | F9: =E9*D9 -> 50882800
A10: 6 | B10: SENIOR RESEARCH FELLOWS | C10: 16(7) | D10: 10 | E10: 4136647.2 | F10: =E10*D10 -> 41366472
A11: 7 | B11: MANAGERS | C11: 15(7) | D11: 12 | E11: =344720.6*12 -> 4136647.2 | F11: =E11*D11 -> 49639766
A12: 8 | B12: RESEARCH FELLOW I | C12: 14(7) | D12: 10 | E12: =249153.06*12 -> 2989836.7 | F12: =E12*D12 -> 29898367
A13: 9 | B13: ASSISTANT MANAGERS | C13: 13(7) | D13: 8 | E13: 2810412.4 | F13: =E13*D13 -> 22483299
A14: 10 | B14: OFFICERS | C14: 10(7) | D14: 15 | E14: =168602.08*12 -> 2023225 | F14: =E14*D14 -> 30348374
A15: 11 | B15: OFFICE ASSISTANTS | C15: 8(7) | D15: 20 | E15: =123329.05*12 -> 1479948.6 | F15: =E15*D15 -> 29598972
A16: 12 | B16: SECRETARIES | C16: 8(9) | D16: 15 | E16: =130304.44*12 -> 1563653.3 | F16: =E16*D16 -> 23454799
A17: 13 | B17: DRIVERS | C17: 4(10) | D17: 20 | E17: =46676.06*12 -> 560112.72 | F17: =E17*D17 -> 11202254
D18: =SUM(D9:D17) -> 100 | F18: =SUM(F5:F17) -> 3.6153678e+08

Sheet Welfare List Mgt Staff
A2: STAFF NAME | D2: DESIGNATION | E2: GRADE | F2: AMOUNT | G2: SIGNATURE
F3: 300000
A4: PROF OKECHUKWU OKO | D4: DIR. LEG. SP SERVICES | E4: 17(7) | F4: 150000
A5: DR BADAYI M. SANI | D5: DIR. RES. & TRAINING | E5: 17(7) | F5: 150000
A6: DR KABIR AHMED | D6: DIR. FINANCE & ADMIN | E6: 17(7) | F6: 150000
A7: PROF. OFFORNZE AMUCHEAZI | D7: LEGAL ADVISER | E7: 16(7) | F7: 100000
A8: MOHAMMED ISIAKA YAKUBU | D8: HEAD PUBLICATION | E8: 16(7) | F8: 100000
A9: DR MOBOLAJI HAKEEM | D9: SPECIAL ASSISTANT | E9: 16(7) | F9: 100000
A10: DR SHUIBU DANWANKA | D10: DD LEG. SP SERVICES | E10: 16(7) | F10: 100000
A11: DR ASIMIYU G. ABIOLA | D11: DD RESEARCH | E11: 16(7) | F11: 100000
A12: IBRAHIM M. MSHELIA | D12: DD F&A | E12: 16(7) | F12: 100000
A13: AMINU BELLO DUKKU | D13: DD ADMIN/HR | E13: 16(7) | F13: 100000
A14: RICHARD KWALMI | D14: MICT | E14: 15(7) | F14: 80000
A15: ADAMU ISA ABBA | D15: INFO. MANAGER | E15: 15(7) | F15: 80000
... A22: EDET B. AKPAKPAN | D22: SABATICAL | E22: Sab. | F22: 80000
A23: TOTAL | F23: =SUM(F3:F22) -> 2170000

Sheet Welfare Support Staff
A1: S/N | B1: NAMES | E1: DESIGNATION | F1: GRADE | G1: AMOUNT | H1: SIGNATURE
A2: 1 | B2: AKINSANMI ADEJOKE OLUKEMI | E2: AM INFORMATION | F2: 13(7) | G2: 20000
A3: 2 | B3: FAROUK U. M ILLO | E3: PA DG | F3: 13(7) | G3: 20000
A4: 3 | B4: UMOLU ADAEZE OBIAMAKA | E4: INFO OFFICER | F4: 10(7) | G4: 20000
A5: 4 | B5: TONDO IORWUESE EDWARD | E5: OFFICER INT AUDIT | F5: 10(7) | G5: 20000
A6: 5 | B6: BEDARI HARI | E6: LEGAL OFFICER | F6: 10(7) | G6: 20000
A7: 6 | B7: NGARA CHRISTOPHER OCHANJA | C7: NGARA CHRISTOPHER OCHANJA | E7: OFFICER, SPECIAL DUTIES | F7: 10(7) | G7: 20000
A8: 7 | B8: JOY HARUNA MAKERI | E8: PA DG | F8: 10(7) | G8: 20000
A9: 8 | B9: BASHIRU ABBA WALI | E9: ASSIT. INT. AUDIT | F9: 8(7) | G9: 20000
A10: 9 | B10: ALI ABDULLAHI | E10: 1CT ASSISTANT | F10: 8(7) | G10: 20000
A11: 10 | B11: UZODINMA EMMANUEL EZENWA | E11: INFORMATION ASST | F11: 8(7) | G11: 20000
A12: 11 | B12: IBRAHIM TASSNEEM | E12: INFORMATION ASST | F12: 8(7) | G12: 20000
A13: 12 | B13: GLORIA NDIDI HELG | E13: CONFIDENTIAL SECRETARY | F13: 8(7) | G13: 20000
A14: 13 | B14: CHRISTIAN MADUABUCHI ODO | E14: ICT ASSISTANT | F14: 8(7) | G14: 20000
A15: 14 | B15: IBRAHIM USMAN | E15: RESEARCH FELLOW II | F15: 13(7) | G15: 20000
A16: 15 | B16: OFORDEME ADAOBI JULIA | E16: RESEARCH OFFICER | F16: 10(7) | G16: 20000
A17: 16 | B17: IKPEAZU CHINEDU ANITA | E17: RESEARCH OFFICER | F17: 10(7) | G17: 20000
A18: 17 | B18: ONYEAKU CHUKWUKA EDMOND | E18: RESEARCH ASSISTANT | F18: 9(7) | G18: 20000
A19: 18 | B19: DR ANUMUDU CHARLES NNAMDI | E19: SRF I SOCIAL SECTOR | F19: 14(7) | G19: 20000
... A77: 76 | B77: AYUBA SULE | E77: STEWARD | F77: - | G77: 10000
A78: 77 | B78: EWELIKWA IJEOMA NKOLIKWA | E78: DISPATCH CLERK | F78: 0 | G78: 10000
A79: 78 | B79: JUMMAI AJIYA | E79: STEWARD | F79: 0 | G79: 10000
A80: 79 | B80: HUSSAIN HAZEEM MOHAMMED | E80: DISPATCH CLERK | F80: - | G80: 10000
A81: 80 | B81: ABOMAN INNOCENT | E81: CLEANER | G81: 10000
A82: 81 | B82: AKEUSOLA SEGUN | E82: CLEANER | G82: 10000
A83: 82 | B83: EDACHE OGA | E83: DRIVER | G83: 10000
A84: 83 | B84: ONCHE ENOKELA ONCHE | E84: STEWARD | G84: 10000
G85: =SUM(G2:G84) -> 1390000

Sheet Welfare Deployed Staff
A1: EID EL KABIR TRANSPORT ALLOWANCE TO NILS DEPLOYED STAFF
A2: S/N | C2: DESIGNATION | D2: GRADE | E2: AMOUNT | F2: SIGNATURE
A3: 1 | B3: ARC OJO M.O | C3: DD & HEAD OF BUILDING | D3: 16(7) | E3: 100000
A4: 2 | B4: AMINCI THOMAS | C4: MANAGER LIB. & DOCUM. | D4: 15(7) | E4: 80000
A5: 3 | B5: AMINU F. HAMAJODA | C5: MANAGER INFORMATION | D5: 15(7) | E5: 80000
A6: 4 | B6: DAHIRU M. ABDULLAHI | C6: PROTOCOL OFFICER | D6: 10(7) | E6: 20000
A7: 5 | B7: MOSHOOD M. OLARELE | C7: ADMIN OFFICER | D7: 10(7) | E7: 20000
A8: 6 | B8: IBRAHIM A. BABANGISHIRI | C8: OFFICER INFORMATION | D8: 10(7) | E8: 20000
A9: 7 | B9: JIBRIN USHAMA AHMED | C9: OFFICER LEGAL | D9: 10(7) | E9: 20000
A10: 8 | B10: ENGR. EBI THOMPSON | C10: ASSISTANT CHIEF ENGINEER | D10: 13(7) | E10: 20000
A11: 9 | B11: ADEOGUN MORUF | C11: PRINCIPAL Q.S | D11: 10(7) | E11: 20000
B12: TOTAL | E12: =SUM(E3:E11) -> 380000

Sheet Sheet1
B1: 2013 END OF YEAR STAFF WELFARE TO ASSIST WITH TRANSPORTATION AND LOGISTICS.
E3: DESIGNATION | F3: SALARY | G3: BASIC
F4: LEVEL | G4: SALARY
B5: DG OFFICE | G5: N
A6: 1 | B6: DR LADI HAMALAI | E6: DIRECTOR GENERAL | F6: CONSOL | G6: 400000
A7: 2 | B7: PROF. OFFORNZE AMUCHEAZI | E7: LEGAL ADVISER | F7: 16(7) | G7: 200000
A8: 3 | B8: MOHAMMED ISIAKA YAKUBU | E8: HEAD PUBLICATION | F8: 16(7) | G8: 200000
A9: 4 | B9: DR MOBOLAJI HAKEEM | E9: SPECIAL ASSISTANT | F9: 16(70 | G9: 200000
A10: 5 | B10: RICHARD KWALMI | E10: MICT | F10: 15(7) | G10: 100000
A11: 6 | B11: ADAMU ISA ABBA | E11: INFO. MANAGER | F11: 15(7) | G11: 100000
A12: 7 | B12: NWOSU MATHEW EZE | E12: MANAGER INT. AUDIT | F12: 15(7) | G12: 100000
A13: 8 | B13: PRISCILLA CHUKWU | E13: MANAGER PROCUREMENT | F13: 15(7) | G13: 100000
A14: 9 | B14: DR ANAH O. PAMELA | E14: SRF | F14: 15((7) | G14: 100000
A15: 10 | B15: AKINSANMI ADEJOKE OLUKEMI | E15: AM INFORMATION | F15: 13(7) | G15: 80000
A16: 11 | B16: FAROUK U. M ILLO | E16: PA DG | F16: 13(7) | G16: 80000
A17: 12 | B17: UMOLU ADAEZE OBIAMAKA | E17: INFO OFFICER | F17: 10(7) | G17: 50000
... A19: 14 | B19: BEDARI HARI | E19: LEGAL OFFICER | F19: 10(7) | G19: 50000
A20: 15 | B20: NGARA CHRISTOPHER OCHANJA | C20: NGARA CHRISTOPHER OCHANJA | E20: OFFICER, SPECIAL DUTIES | F20: 10(7) | G20: 50000
A21: 16 | B21: JOY HARUNA MAKERI | C21: JOY HARUNA MAKERI | E21: PA DG | F21: 10(7) | G21: 50000
A22: 17 | B22: DONALD E. MKPANAM | E22: IT OFFICER | F22: 10(7) | G22: 50000
A23: 18 | B23: BASHIRU ABBA WALI | E23: ASSIT. INT. AUDIT | F23: 8(7) | G23: 50000
A24: 19 | B24: ALI ABDULLAHI | E24: 1CT ASSISTANT | F24: 8(7) | G24: 50000
A25: 20 | B25: UZODINMA EMMANUEL EZENWA | E25: INFORMATION ASST | F25: 8(7) | G25: 50000
A26: 21 | B26: IBRAHIM TASSNEEM | E26: INFORMATION ASST | F26: 8(7) | G26: 50000
A27: 22 | B27: GLORIA NDIDI HELG | E27: CONFIDENTIAL SECRETARY | F27: 8(7) | G27: 50000
A28: 23 | B28: CHRISTIAN MADUABUCHI ODO | E28: ICT ASSISTANT | F28: 8(7) | G28: 50000
B29: TOTAL | E29: 23 | G29: =SUM(G6:G28) -> 2260000
B30: LEG. SUPPORT SEVICES
A31: 1 | B31: PROF OKECHUKWU OKO | E31: DIR. LEG. SP SERVICES | F31: 17(7) | G31: 300000
A32: 2 | B32: DR SHUIBU DANWANKA | E32: DD LEG. SP SERVICES | F32: 16(7) | G32: 200000
A33: 3 | B33: IBRAHIM USMAN | E33: RESEARCH FELLOW II | F33: 13(7) | G33: 80000
A34: 4 | B34: OFORDEME ADAOBI JULIA | E34: RESEARCH OFFICER | F34: 10(7) | G34: 50000
A35: 5 | B35: IKPEAZU CHINEDU ANITA | C35: IKPEAZU CHINEDU ANITA | E35: RESEARCH OFFICER | F35: 10(7) | G35: 50000
A36: 6 | B36: ONYEAKU CHUKWUKA EDMOND | E36: RESEARCH ASSISTANT | F36: 9(7) | G36: 50000
B37: TOTAL | E37: 6 | G37: =SUM(G31:G36) -> 730000
A39: 1 | B39: DR BADAYI M. SANI | E39: DIR. RES. & TRAINING | F39: 17(7) | G39: 300000
A40: 2 | B40: DR ASIMIYU G. ABIOLA | E40: DD RESEARCH | F40: 16(7) | G40: 200000
A41: 3 | B41: DR KANAYO OGUJIUBA | E41: SRF SOCIAL SECTOR | F41: 15(9) | G41: 100000
A42: 4 | B42: DR ANUMUDU CHARLES NNAMDI | E42: SRF I SOCIAL SECTOR | F42: 14(7) | G42: 80000
A43: 5 | B43: CATHERINE E. IKOKOH | E43: RESEARCH FELLOW1 DOCU | F43: 14(7) | G43: 80000
...

Sheet Sheet3
