Workbook

Sheet JANUARY 2026
A1: NATIONAL INSTITUTE FOR LEGISLATIVE AND DEMOCRATIC STUDIES
A2: STAFF PAYROLL FOR THE MONTH OF FEBRUARY 2026
E3: ='[1]FEB 08'!E11/'[1]FEB 08'!M11 -> #REF!
B4: STAFF NAME | C4: DESIGNATION | D4: GRADE LEVEL | E4: BASIC SALARY | F4: ALLCE/ AREARS | G4: ALLOWANCE | H4: ALLOWANCE | I4: DUTY ALLCE | J4: GROSS SALARY | K4: AUCTION | L4: COOP 1 CONTR/SPEC SAVINGS | M4: COOP 1 LOAN RECOVERY | N4: COOP 2 CONTR/SPEC SAVINGS | O4: COOP 2 LOAN RECOVERY | P4: NHF DED. | Q4: PAYE | R4: EMPLOYEE PENSIONS | S4: TOTAL DEDUCTION | T4: JANUARY, 2026 | U4: FEBRUARY, 2026
E5: N | F5: N | G5: N | H5: N | I5: N | J5: N | K5: N | L5: N | M5: N | N5: N | P5: N | Q5: N | R5: N | S5: N | T5: N | U5: N
A6: S/N | B6: DG'S OFFICE
A7: 1 | B7: PROF. ABUBAKAR O. SULAIMAN | C7: DIRECTOR GENERAL | D7: CONSOL | E7: 1971137.1 | G7: =250000 -> 250000 | I7: 25235 | J7: =E7+F7+G7+H7+I7 -> 2246372.1 | P7: 0 | Q7: 427498.91 | S7: =SUM(K7:R7) -> 427498.91 | T7: 1818873.2 | U7: =J7-S7 -> 1818873.2
A8: 2 | B8: RAHEEM USMAN AYIGORO | C8: SA-INFRASTRUCTURE | D8: 16 (9) | E8: 905306.75 | H8: =90000 -> 90000 | I8: =100000 -> 100000 | J8: =E8+F8+G8+H8+I8 -> 1095306.8 | L8: =250000 -> 250000 | N8: 100000 | Q8: 167305.26 | R8: 72424.54 | S8: =SUM(K8:R8) -> 589729.8 | T8: 505576.95 | U8: =J8-S8 -> 505576.95
A9: 3 | B9: MARIAM MOHAMMED BELLO | C9: SA- SPECIAL DUTIES | D9: 16 (9) | E9: 905306.75 | H9: =90000 -> 90000 | I9: =200000+100000 -> 300000 | J9: =E9+F9+G9+H9+I9 -> 1295306.8 | P9: 0 | Q9: 224514.42 | S9: =SUM(K9:R9) -> 224514.42 | T9: 1070792.3 | U9: =J9-S9 -> 1070792.3
A10: 4 | B10: DR IKEME ARTHUR J.O | C10: DEPUTY DIRECTOR, M&E | D10: 16 (9) | E10: 905306.75 | G10: 180000 | I10: 0 | J10: =E10+F10+G10+H10+I10 -> 1085306.8 | L10: =50000 -> 50000 | P10: 13866.737 | Q10: 162322.79 | R10: 72424.54 | S10: =SUM(K10:R10) -> 298614.06 | T10: 786692.69 | U10: =J10-S10 -> 786692.69
A11: 5 | B11: ANDRAWUS MUSA | C11: DEP. DIRECTOR, STORES & PROCUREMENT | D11: 16(9) | E11: 905306.75 | H11: =90000 -> 90000 | I11: 50000 | J11: =E11+F11+G11+H11+I11 -> 1045306.8 | L11: =50000-40000 -> 10000 | M11: =90000+110000 -> 200000 | P11: 13866.737 | Q11: 155122.79 | R11: 72424.54 | S11: =SUM(K11:R11) -> 451414.06 | T11: 593892.69 | U11: =J11-S11 -> 593892.69
A12: 6 | B12: DR FRANCIS NDUM OJIE | C12: AD, TRAINING & IC./SA TO DG | D12: 15(9) | E12: 744477 | G12: 160000 | I12: =100000+100000 -> 200000 | J12: =E12+F12+G12+H12+I12 -> 1104477 | P12: 11475.263 | Q12: 169523.15 | R12: 59558.16 | S12: =SUM(K12:R12) -> 240556.57 | T12: 863920.43 | U12: =J12-S12 -> 863920.43
A13: 7 | B13: ALI ABDULLAHI | C13: ASST DIRECTOR ICT | D13: 15(7) | E13: 700713.92 | H13: =80000 -> 80000 | I13: =0 -> 0 | J13: =E13+F13+G13+H13+I13 -> 780713.92 | Q13: 112938.22 | R13: 56057.113 | S13: =SUM(K13:R13) -> 168995.34 | T13: 611718.58 | U13: =J13-S13 -> 611718.58
A14: 8 | B14: EMILY EKHIDE | C14: SENIOR RESEARCH FELLOW | D14: 15(9) | E14: 744477 | G14: 160000 | I14: =50000 -> 50000 | J14: =E14+F14+G14+H14+I14 -> 954477 | L14: =50000 -> 50000 | Q14: 143585.39 | R14: 59558.16 | S14: =SUM(K14:R14) -> 253143.55 | T14: 701333.45 | U14: =J14-S14 -> 701333.45
A15: 9 | B15: DORIS DAKDA AARON | C15: RESEARCH FELLOW I | D15: 14(10) | E15: 573911.08 | G15: =140000 -> 140000 | I15: =150000+100000 -> 250000 | J15: =E15+F15+G15+H15+I15 -> 963911.08 | L15: 150000 | M15: 0 | P15: 8926.6667 | Q15: 146132.88 | R15: 45912.887 | S15: =SUM(K15:R15) -> 350972.43 | T15: 612938.65 | U15: =J15-S15 -> 612938.65
A16: 10 | B16: ABDULSALAM S. MUSTAPHA | C16: ASST. DIRECTOR ICT | D16: 15(8) | E16: 722595.5 | H16: 80000 | I16: 50000 | J16: =E16+F16+G16+H16+I16 -> 852595.5 | N16: 10000 | O16: 57818.75 | Q16: 125561.81 | R16: 57807.64 | S16: =SUM(K16:R16) -> 251188.2 | T16: 659226.05 | U16: =J16-S16 -> 601407.3
A17: 11 | B17: PERCY TERFA GBAHABO | C17: RESEARCH FELLOW 1 | D17: 14(8) | E17: 542419.5 | G17: =140000 -> 140000 | I17: 0 | J17: =E17+F17+G17+H17+I17 -> 682419.5 | Q17: 97524.669 | R17: 43393.56 | S17: =SUM(K17:R17) -> 140918.23 | T17: 541501.27 | U17: =J17-S17 -> 541501.27
A18: 12 | B18: HASSANA AHMED IBRAHIM | C18: PA- TO DG | D18: 13(11) | E18: 541351.33 | G18: =120000 -> 120000 | I18: =100000+100000 -> 200000 | J18: =E18+F18+G18+H18+I18 -> 861351.33 | L18: =30000-20000 -> 10000 | M18: =127777.78 -> 127777.78 | P18: 8443.2708 | Q18: 128227.99 | R18: 43308.107 | S18: =SUM(K18:R18) -> 317757.15 | T18: 543594.18 | U18: =J18-S18 -> 543594.18
A19: 13 | B19: IKIP LEBO | C19: ASST CHIEF PROC. OFFICER | D19: 13 (9) | E19: 512098.92 | H19: 70000 | J19: =E19+F19+G19+H19+I19 -> 582098.92 | L19: 50000 | M19: 250000 | P19: 8008.9771 | Q19: 78461.965 | R19: 40967.913 | S19: =SUM(K19:R19) -> 427438.86 | T19: 154660.06 | U19: =J19-S19 -> 154660.06
A20: 14 | B20: ALABI ADESINA MUHYDEEN | C20: HEAD, NILDS LIAISON OFFICE | D20: 13 (9) | E20: 512098.92 | G20: 120000 | J20: =E20+F20+G20+H20+I20 -> 632098.92 | Q20: 88903.581 | R20: 40967.913 | S20: =SUM(K20:R20) -> 129871.49 | T20: 502227.42 | U20: =J20-S20 -> 502227.42
A21: 15 | B21: BASSEY NSONGURUA UDOFIA | C21: PRINC.CONF SEC 1/PPS | D21: 13(8) | E21: 497472.75 | H21: =70000 -> 70000 | I21: =250000 -> 250000 | J21: =E21+F21+G21+H21+I21 -> 817472.75 | L21: 20000 | M21: =68750 -> 68750 | P21: 7791.8313 | Q21: 121078.96 | R21: 39797.82 | S21: =SUM(K21:R21) -> 257418.61 | T21: 560054.14 | U21: =J21-S21 -> 560054.14
A22: 16 | B22: ADUGBA RICHARD TERSEER | C22: ASSIST. CHIEF INFO OFFICER | D22: 13(7) | E22: 482846.58 | H22: =70000 -> 70000 | I22: =100000+50000 -> 150000 | J22: =E22+F22+G22+H22+I22 -> 702846.58 | L22: =10000 -> 10000 | M22: 292813.77 | P22: 7574.6854 | Q22: 100695.95 | R22: 38627.727 | S22: =SUM(K22:R22) -> 449712.13 | T22: 253134.45 | U22: =J22-S22 -> 253134.45
A23: 17 | B23: LUCKY AGWOM | C23: RESEARCH ASSISTANT | D23: 12(9) | E23: 468828.17 | G23: =100000 -> 100000 | I23: =100000+100000 -> 200000 | J23: =E23+F23+G23+H23+I23 -> 768828.17 | L23: =50000+100000 -> 150000 | Q23: 114137.94 | R23: 37506.253 | S23: =SUM(K23:R23) -> 301644.2 | T23: 467183.97 | U23: =J23-S23 -> 467183.97
A24: 18 | B24: IDRIS IBRAHIM | C24: PRINCIPAL RESEARCH OFFICER | D24: 12(9) | E24: 468828.17 | F24: 3000 | G24: 110000 | I24: 0 | J24: =E24+F24+G24+H24+I24 -> 581828.17 | L24: 0 | N24: 30000 | P24: 7366.5729 | Q24: 75611.961 | R24: 37506.253 | S24: =SUM(K24:R24) -> 150484.79 | T24: 425343.38 | U24: =J24-S24 -> 431343.38
A25: 19 | B25: FARUQ ATOFARATI | C25: PA (SPECIAL DUTIES) TO DG | D25: 10(8) | E25: 381140.67 | H25: =50000+10000 -> 60000 | I25: =100000+100000 -> 200000 | J25: =E25+F25+G25+H25+I25 -> 641140.67 | L25: 150000 | Q25: 92416.894 | R25: 30491.253 | S25: =SUM(K25:R25) -> 272908.15 | T25: 368232.52 | U25: =J25-S25 -> 368232.52
A26: 20 | B26: RASHEEDAT DAIBU | C26: SENIOR INFO. OFFICER | D26: 10(9) | E26: 390135.83 | H26: 60000 | J26: =E26+F26+G26+H26+I26 -> 450135.83 | L26: 50000 | N26: 10000 | P26: 6154.2792 | Q26: 56798.724 | R26: 31210.867 | S26: =SUM(K26:R26) -> 154163.87 | T26: 295971.96 | U26: =J26-S26 -> 295971.96
A27: 21 | B27: VICTOR ASUKWO | C27: SENIOR ICT OFFICER | D27: 10(7) | E27: 372145.33 | H27: =50000+10000 -> 60000 | J27: =E27+F27+G27+H27+I27 -> 432145.33 | P27: 5889.4458 | Q27: 53867.167 | R27: 29771.627 | S27: =SUM(K27:R27) -> 89528.239 | T27: 397802 | U27: =J27-S27 -> 342617.09
A28: 22 | B28: NNANDI LIVINUS ATURE | C28: SENIOR RESEARCH OFFICER | D28: 10(8) | E28: 381140.67 | F28: 4500 | G28: =110000 -> 110000 | J28: =E28+F28+G28+H28+I28 -> 495640.67 | L28: =10000 -> 10000 | M28: 127777.78 | P28: 6021.8646 | Q28: 59832.959 | R28: 30491.253 | S28: =SUM(K28:R28) -> 234123.86 | T28: 252516.81 | U28: =J28-S28 -> 261516.81
A29: 23 | B29: ABDULRAHMAN A SULAIMAN | C29: STORE OFFICER | D29: 9(9) | E29: 347016.17 | H29: =60000 -> 60000 | J29: =E29+F29+G29+H29+I29 -> 407016.17 | L29: =20000 -> 20000 | M29: =17500 -> 17500 | N29: 50000 | Q29: 50765.877 | R29: 27761.293 | S29: =SUM(K29:R29) -> 166027.17 | T29: 247253.91 | U29: =J29-S29 -> 240989
A30: 24 | B30: DARE SHEU MAGBON | C30: ADMINISTRATION OFFICER | D30: 9(9) | E30: 347016.17 | H30: =60000 -> 60000 | J30: =E30+F30+G30+H30+I30 -> 407016.17 | L30: =30000+20000 -> 50000 | M30: 0 | Q30: 50765.877 | R30: 27761.293 | S30: =SUM(K30:R30) -> 128527.17 | T30: 278489 | U30: =J30-S30 -> 278489
A31: 25 | B31: ABUBAKAR SULAIMAN SODEEQ | C31: SENIOR M&E OFFICER | D31: 10(7) | E31: 372145.33 | H31: 60000 | J31: =E31+F31+G31+H31+I31 -> 432145.33 | M31: 0 | P31: 5889.4458 | Q31: 53867.167 | R31: 29771.627 | S31: =SUM(K31:R31) -> 89528.239 | T31: 342617.09 | U31: =J31-S31 -> 342617.09
A32: 26 | B32: JIMOH ADEBAYO ZAKA | C32: SENIOR INFO OFFICER | D32: 10(7) | E32: 372145.33 | H32: 60000 | J32: =E32+F32+G32+H32+I32 -> 432145.33 | L32: =20000 -> 20000 | M32: =161429.76+39000+50000 -> 250429.76 | P32: 5889.4458 | Q32: 53867.167 | R32: 29771.627 | S32: =SUM(K32:R32) -> 359958 | T32: 72187.334 | U32: =J32-S32 -> 72187.334
A33: 27 | B33: ABDULMUSHIN TAWFIQ LADAN | C33: ICT OFFICER | D33: 9(9) | E33: 347016.17 | H33: =60000 -> 60000 | J33: =E33+F33+G33+H33+I33 -> 407016.17 | M33: 0 | Q33: 50765.877 | R33: 27761.293 | S33: =SUM(K33:R33) -> 78527.171 | T33: 328489 | U33: =J33-S33 -> 328489
A34: 28 | B34: MOHAMMED BELLO | C34: SENIOR PROTOCOL OFFICER | D34: 10(7) | E34: 372145.33 | H34: 60000 | J34: =E34+F34+G34+H34+I34 -> 432145.33 | L34: =0 -> 0 | Q34: 54927.267 | R34: 29771.627 | S34: =SUM(K34:R34) -> 84698.894 | T34: 347446.44 | U34: =J34-S34 -> 347446.44
A35: 29 | B35: HOLINESS PAUL UDO | C35: ADMINISTRATION OFFICER, M&E | D35: 9(8) | E35: 338711.67 | F35: 3000 | H35: =60000 -> 60000 | J35: =E35+F35+G35+H35+I35 -> 401711.67 | L35: 50000 | P35: 5443.3354 | Q35: 45410.852 | R35: 27096.933 | S35: =SUM(K35:R35) -> 127951.12 | T35: 267760.55 | U35: =J35-S35 -> 273760.55
A36: 30 | B36: CHARITY UDO AKAN | C36: ADMINISTRATION OFFICER, M&E | D36: 9(8) | E36: 338711.67 | H36: =60000 -> 60000 | J36: =E36+F36+G36+H36+I36 -> 398711.67 | L36: 50000 | M36: 60625 | P36: 5443.3354 | Q36: 48410.852 | R36: 27096.933 | S36: =SUM(K36:R36) -> 191576.12 | T36: 207135.55 | U36: =J36-S36 -> 207135.55
A37: 31 | B37: SANI UMAR IBRAHIM | C37: STORE OFFICER | D37: 9(8) | E37: 338711.67 | H37: =60000 -> 60000 | J37: =E37+F37+G37+H37+I37 -> 398711.67 | Q37: 49390.652 | R37: 27096.933 | S37: =SUM(K37:R37) -> 76487.585 | T37: 322224.08 | U37: =J37-S37 -> 322224.08
A38: 32 | B38: FAHAD ABUBUKAR LONGMAN | C38: ICT OFFICER | D38: 9(8) | E38: 338711.67 | H38: =60000 -> 60000 | J38: =E38+F38+G38+H38+I38 -> 398711.67 | P38: 5443.3354 | Q38: 48410.852 | R38: 27096.933 | S38: =SUM(K38:R38) -> 80951.12 | T38: 317760.55 | U38: =J38-S38 -> 317760.55
A39: 33 | B39: HARUNA JIBRIL AMEH | C39: ASST. ADMIN. OFFICER | D39: 8(10) | E39: 308920.67 | H39: 50000 | J39: =E39+F39+G39+H39+I39 -> 358920.67 | L39: 20000 | M39: 0 | P39: 5013.7354 | Q39: 41754.79 | R39: 24713.653 | S39: =SUM(K39:R39) -> 91482.179 | T39: 267438.49 | U39: =J39-S39 -> 267438.49
A40: 34 | B40: RAMATU IBRAHIM ABDULRAHEEM | C40: INFORMATION OFFICER | D40: 8(9) | E40: 301910.75 | H40: 50000 | J40: =E40+F40+G40+H40+I40 -> 351910.75 | L40: 50000 | M40: 45833.33 | N40: 50000 | P40: 4909.1104 | Q40: 40612.78 | R40: 24152.86 | S40: =SUM(K40:R40) -> 215508.08 | T40: 136402.67 | U40: =J40-S40 -> 136402.67
...

Sheet MEMO
A2: NATIONAL INSTITUTE FOR LEGISLATIVE AND DEMOCRATIC STUDIES
A3: INTERNAL MEMO
A4: FROM : DEPUTY DIRECTOR, FINANCE AND ACCOUNTS
A5: THRU: DIRECTOR, FINANCE AND ACCOUNTS
A6: TO: DG
A7: 29TH JANUARY , 2021
A9: SUBJECT: PAYROLL FOR THE MONTH OF JANUARY, 2021
A10: Find below the details of NILDS Staff Payroll for the month of January, 2021
A13: TO: | C13: DIRECTOR, GENERAL
A14: THRU: | C14: DIRECTOR, FINANCE AND ACCOUNT
A15: FROM: | C15: DEPUTY DIRECTOR, FINANCE AND ACCOUNTS
A16: DATE: | C16: 26TH FEBRUARY 2026
A18: SUBJECT: PAYROLL FOR THE MONTH OF FEBRUARY 2026
A19: Find below the details of NILDS Staff Payroll for the Month of February 2026: | G19: NGN | H19: NGN
A20: GROSS SALARY FOR FEBRUARY 2026 | H20: ='JANUARY 2026'!J248 -> 1.2232428e+08
A22: DEDUCTIONS
A23: COOP SOCIETY 1 DEDUCTIONS ( CONTR.& SPEC. SAVINGS) | G23: ='JANUARY 2026'!L248 -> 8076500
A24: COOP 1 LOAN RECOVERY | G24: ='JANUARY 2026'!M248 -> 10045100
A25: COOP SOCIETY 2 DEDUCTIONS ( CONTR.& SPEC. SAVINGS) | G25: ='JANUARY 2026'!N248 -> 3165000
A26: COOP 1 LOAN RECOVERY | G26: ='JANUARY 2026'!O248 -> 999337.3
A27: NHF DEDUCTIONS | G27: ='JANUARY 2026'!P248 -> 677813.77
A28: PAYE DEDUCTIONS | G28: ='JANUARY 2026'!Q248 -> 17200699
A29: PENSION DEDUCTIONS | G29: ='JANUARY 2026'!R248 -> 7828601.9
A30: TOTAL DEDUCTIONS FOR FEBRUARY 2026 | H30: =SUM(G23:G29) -> 47993052
A31: NET PAY AS PER FEBRUARY 2026 PAYROLL | H31: =H20-H30 -> 74331223
A32: NET PAY AS PER JANUARY 2026 PAYROLL | H32: ='JANUARY 2026'!T248 -> 74388110
A33: NET INCREASE/ (DECREASE) IN PAY FOR FEBRUARY 2026 | H33: =H31-H32 -> -56886.837
A34: ANALYSED AS FOLLOWS:
A35: Effect of Cooperative 1 Adjustments for February 2026 | H35: -200500
A36: Effect of Cooperative 2 Adjustments for February 2026 | H36: =996037.3+180000-4000+3300+14000 -> 1189337.3
A37: Effect of Annual Tax Relief IFO Idris Ibrahim & 5 others | H37: -49000
A38: Effect of Cessation of payment to Jimoh Gobir Sulyman due to Suspension | H38: 354232.52
A39: Effect of promotions of Kolapo Quadri Abayomi & 3 others | H39: 136268.3
A40: Effect of promotion arrears IFO Kolapo Abayomi & 3 others | H40: -1370088.4
A41: Effect of regularization of hardship allowance of Yusuf Abdullahi & 6 others | H41: -70000
A42: Effect of steps regularisation of Jeremiah Agada & 1 other | H42: 11452.25
A43: Effect of removal of Promotion arrears to Victor Asukwo | H43: =55184.91 -> 55184.91
H44: =SUM(H35:H43) -> 56886.84
E47: JANUARY, 2025 | G47: FEBRUARY, 2026
E48: No. of Staff | F48: N | G48: No. of Staff | H48: N
...

Sheet Changes in PAYE (4)
A1: NATIONAL INSTITUTE FOR LEGISLATIVE AND DEMOCRATIC STUDIES
A2: NATIONAL ASSEMBLY ABUJA
A3: TAX COMPUTATION FOR 2022
A4: S/NO | B4: NAME | C4: N | D4: NO OF MONTHS | E4: ANNUAL SALARY GROSSED UP | F4: ANNUAL RENT RELIEF (20% MAX OF N500,000) | G4: NATIONAL HOUSING SCHEME = 2.5% OF BASIC SALARY | H4: PENSION CONTRIBUTION = 8% OF CONSOLIDATED | I4: NHIS | J4: TOTAL RELIEF | K4: CHARGEABLE INCOME | L4: ANNUAL TAX PAYABLE | N4: MONTHLY TAX PAYABLE | O4: OLD ACTUAL TAX PAYABLE | P4: INCREASE/DECREASE IN PAYE
A5: S/N | B5: DG'S OFFICE
A6: 1 | B6: PROF. ABUBAKAR O. SULAIMAN | C6: 2246372.1 | D6: 12 | E6: =C6*D6 -> 26956465 | H6: 0 | J6: =F6+G6+H6 -> 0 | K6: =E6-J6 -> 26956465 | L6: =IF(K6<=800000,0,IF(K6<=3000000,(K6-800000)*15%,IF(K6<=12000000,330000+(K6-3000000)*18%,IF(K6<=25000000,1950000+(K6-12000000)*21%,IF(K6<=50000000,4680000+(K6-25000000)*23%,10430000+(K6-50000000)*25%))))) -> 5129986.9 | M6: 12 | N6: =L6/M6 -> 427498.91 | O6: 427498.91 | P6: =N6-O6 -> 0
A7: 2 | B7: RAHEEM USMAN AYIGORO | C7: 1095306.8 | D7: 12 | E7: =C7*D7 -> 13143681 | G7: 0 | H7: 869094.48 | J7: =F7+G7+H7 -> 869094.48 | K7: =E7-J7 -> 12274587 | L7: =IF(K7<=800000,0,IF(K7<=3000000,(K7-800000)*15%,IF(K7<=12000000,330000+(K7-3000000)*18%,IF(K7<=25000000,1950000+(K7-12000000)*21%,IF(K7<=50000000,4680000+(K7-25000000)*23%,10430000+(K7-50000000)*25%))))) -> 2007663.2 | M7: 12 | N7: =L7/M7 -> 167305.26 | O7: 167305.26 | P7: =N7-O7 -> 0
A8: 3 | B8: MARIAM MOHAMMED BELLO | C8: 1295306.8 | D8: 12 | E8: =C8*D8 -> 15543681 | G8: 0 | H8: 0 | J8: =F8+G8+H8 -> 0 | K8: =E8-J8 -> 15543681 | L8: =IF(K8<=800000,0,IF(K8<=3000000,(K8-800000)*15%,IF(K8<=12000000,330000+(K8-3000000)*18%,IF(K8<=25000000,1950000+(K8-12000000)*21%,IF(K8<=50000000,4680000+(K8-25000000)*23%,10430000+(K8-50000000)*25%))))) -> 2694173 | M8: 12 | N8: =L8/M8 -> 224514.42 | O8: 224514.42 | P8: =N8-O8 -> 0
A9: 4 | B9: DR IKEME ARTHUR J.O | C9: 1085306.8 | D9: 12 | E9: =C9*D9 -> 13023681 | G9: 166400.85 | H9: 869094.48 | J9: =F9+G9+H9 -> 1035495.3 | K9: =E9-J9 -> 11988186 | L9: =IF(K9<=800000,0,IF(K9<=3000000,(K9-800000)*15%,IF(K9<=12000000,330000+(K9-3000000)*18%,IF(K9<=25000000,1950000+(K9-12000000)*21%,IF(K9<=50000000,4680000+(K9-25000000)*23%,10430000+(K9-50000000)*25%))))) -> 1947873.4 | M9: 12 | N9: =L9/M9 -> 162322.79 | O9: 162322.79 | P9: =N9-O9 -> 0
A10: 5 | B10: ANDRAWUS MUSA | C10: 1045306.8 | D10: 12 | E10: =C10*D10 -> 12543681 | G10: 166400.85 | H10: 869094.48 | J10: =F10+G10+H10 -> 1035495.3 | K10: =E10-J10 -> 11508186 | L10: =IF(K10<=800000,0,IF(K10<=3000000,(K10-800000)*15%,IF(K10<=12000000,330000+(K10-3000000)*18%,IF(K10<=25000000,1950000+(K10-12000000)*21%,IF(K10<=50000000,4680000+(K10-25000000)*23%,10430000+(K10-50000000)*25%))))) -> 1861473.4 | M10: 12 | N10: =L10/M10 -> 155122.79 | O10: 155122.79 | P10: =N10-O10 -> 0
A11: 6 | B11: DR FRANCIS NDUM OJIE | C11: 1104477 | D11: 12 | E11: =C11*D11 -> 13253724 | G11: 137703.15 | H11: 714697.92 | J11: =F11+G11+H11 -> 852401.07 | K11: =E11-J11 -> 12401323 | L11: =IF(K11<=800000,0,IF(K11<=3000000,(K11-800000)*15%,IF(K11<=12000000,330000+(K11-3000000)*18%,IF(K11<=25000000,1950000+(K11-12000000)*21%,IF(K11<=50000000,4680000+(K11-25000000)*23%,10430000+(K11-50000000)*25%))))) -> 2034277.8 | M11: 12 | N11: =L11/M11 -> 169523.15 | O11: 169523.15 | P11: =N11-O11 -> 0
A12: 7 | B12: ALI ABDULLAHI | C12: 780713.92 | D12: 12 | E12: =C12*D12 -> 9368567 | G12: 0 | H12: 672685.36 | J12: =F12+G12+H12 -> 672685.36 | K12: =E12-J12 -> 8695881.6 | L12: =IF(K12<=800000,0,IF(K12<=3000000,(K12-800000)*15%,IF(K12<=12000000,330000+(K12-3000000)*18%,IF(K12<=25000000,1950000+(K12-12000000)*21%,IF(K12<=50000000,4680000+(K12-25000000)*23%,10430000+(K12-50000000)*25%))))) -> 1355258.7 | M12: 12 | N12: =L12/M12 -> 112938.22 | O12: 112938.22 | P12: =N12-O12 -> 0
A13: 8 | B13: EMILY EKHIDE | C13: 954477 | D13: 12 | E13: =C13*D13 -> 11453724 | G13: 0 | H13: 714697.92 | J13: =F13+G13+H13 -> 714697.92 | K13: =E13-J13 -> 10739026 | L13: =IF(K13<=800000,0,IF(K13<=3000000,(K13-800000)*15%,IF(K13<=12000000,330000+(K13-3000000)*18%,IF(K13<=25000000,1950000+(K13-12000000)*21%,IF(K13<=50000000,4680000+(K13-25000000)*23%,10430000+(K13-50000000)*25%))))) -> 1723024.7 | M13: 12 | N13: =L13/M13 -> 143585.39 | O13: 143585.39 | P13: =N13-O13 -> 0
A14: 9 | B14: DORIS DAKDA AARON | C14: 963911.08 | D14: 12 | E14: =C14*D14 -> 11566933 | G14: 107120 | H14: 550954.64 | J14: =F14+G14+H14 -> 658074.64 | K14: =E14-J14 -> 10908858 | L14: =IF(K14<=800000,0,IF(K14<=3000000,(K14-800000)*15%,IF(K14<=12000000,330000+(K14-3000000)*18%,IF(K14<=25000000,1950000+(K14-12000000)*21%,IF(K14<=50000000,4680000+(K14-25000000)*23%,10430000+(K14-50000000)*25%))))) -> 1753594.5 | M14: 12 | N14: =L14/M14 -> 146132.88 | O14: 146132.88 | P14: =N14-O14 -> 0
A15: 10 | B15: ABDULSALAM S. MUSTAPHA | C15: 852595.5 | D15: 12 | E15: =C15*D15 -> 10231146 | G15: 0 | H15: 693691.68 | J15: =F15+G15+H15 -> 693691.68 | K15: =E15-J15 -> 9537454.3 | L15: =IF(K15<=800000,0,IF(K15<=3000000,(K15-800000)*15%,IF(K15<=12000000,330000+(K15-3000000)*18%,IF(K15<=25000000,1950000+(K15-12000000)*21%,IF(K15<=50000000,4680000+(K15-25000000)*23%,10430000+(K15-50000000)*25%))))) -> 1506741.8 | M15: 12 | N15: =L15/M15 -> 125561.81 | O15: 125561.81 | P15: =N15-O15 -> 0
A16: 11 | B16: PERCY TERFA GBAHABO | C16: 682419.5 | D16: 12 | E16: =C16*D16 -> 8189034 | G16: 0 | H16: 520722.72 | J16: =F16+G16+H16 -> 520722.72 | K16: =E16-J16 -> 7668311.3 | L16: =IF(K16<=800000,0,IF(K16<=3000000,(K16-800000)*15%,IF(K16<=12000000,330000+(K16-3000000)*18%,IF(K16<=25000000,1950000+(K16-12000000)*21%,IF(K16<=50000000,4680000+(K16-25000000)*23%,10430000+(K16-50000000)*25%))))) -> 1170296 | M16: 12 | N16: =L16/M16 -> 97524.669 | O16: 97524.669 | P16: =N16-O16 -> 0
A17: 12 | B17: HASSANA AHMED IBRAHIM | C17: 861351.33 | D17: 12 | E17: =C17*D17 -> 10336216 | G17: 101319.25 | H17: 519697.28 | J17: =F17+G17+H17 -> 621016.53 | K17: =E17-J17 -> 9715199.5 | L17: =IF(K17<=800000,0,IF(K17<=3000000,(K17-800000)*15%,IF(K17<=12000000,330000+(K17-3000000)*18%,IF(K17<=25000000,1950000+(K17-12000000)*21%,IF(K17<=50000000,4680000+(K17-25000000)*23%,10430000+(K17-50000000)*25%))))) -> 1538735.9 | M17: 12 | N17: =L17/M17 -> 128227.99 | O17: 128227.99 | P17: =N17-O17 -> 0
A18: 13 | B18: IKIP LEBO | C18: 582098.92 | D18: 12 | E18: =C18*D18 -> 6985187 | G18: 96107.725 | H18: 491614.96 | J18: =F18+G18+H18 -> 587722.69 | K18: =E18-J18 -> 6397464.3 | L18: =IF(K18<=800000,0,IF(K18<=3000000,(K18-800000)*15%,IF(K18<=12000000,330000+(K18-3000000)*18%,IF(K18<=25000000,1950000+(K18-12000000)*21%,IF(K18<=50000000,4680000+(K18-25000000)*23%,10430000+(K18-50000000)*25%))))) -> 941543.58 | M18: 12 | N18: =L18/M18 -> 78461.965 | O18: 78461.965 | P18: =N18-O18 -> 0
... A22: 17 | B22: LUCKY AGWOM | C22: 768828.17 | D22: 12 | E22: =C22*D22 -> 9225938 | G22: 0 | H22: 450075.04 | J22: =F22+G22+H22 -> 450075.04 | K22: =E22-J22 -> 8775863 | L22: =IF(K22<=800000,0,IF(K22<=3000000,(K22-800000)*15%,IF(K22<=12000000,330000+(K22-3000000)*18%,IF(K22<=25000000,1950000+(K22-12000000)*21%,IF(K22<=50000000,4680000+(K22-25000000)*23%,10430000+(K22-50000000)*25%))))) -> 1369655.3 | M22: 12 | N22: =L22/M22 -> 114137.94 | O22: 114137.94 | P22: =N22-O22 -> 0
A23: 18 | B23: IDRIS IBRAHIM | C23: 578828.17 | D23: 12 | E23: =C23*D23 -> 6945938 | F23: 200000 | G23: 88398.875 | H23: 450075.04 | J23: =F23+G23+H23 -> 738473.92 | K23: =E23-J23 -> 6207464.1 | L23: =IF(K23<=800000,0,IF(K23<=3000000,(K23-800000)*15%,IF(K23<=12000000,330000+(K23-3000000)*18%,IF(K23<=25000000,1950000+(K23-12000000)*21%,IF(K23<=50000000,4680000+(K23-25000000)*23%,10430000+(K23-50000000)*25%))))) -> 907343.54 | M23: 12 | N23: =L23/M23 -> 75611.961 | O23: 78611.961 | P23: =N23-O23 -> -3000
A24: 19 | B24: FARUQ ATOFARATI | C24: 641140.67 | D24: 12 | E24: =C24*D24 -> 7693688 | G24: 0 | H24: 365895.04 | J24: =F24+G24+H24 -> 365895.04 | K24: =E24-J24 -> 7327793 | L24: =IF(K24<=800000,0,IF(K24<=3000000,(K24-800000)*15%,IF(K24<=12000000,330000+(K24-3000000)*18%,IF(K24<=25000000,1950000+(K24-12000000)*21%,IF(K24<=50000000,4680000+(K24-25000000)*23%,10430000+(K24-50000000)*25%))))) -> 1109002.7 | M24: 12 | N24: =L24/M24 -> 92416.894 | O24: 92416.894 | P24: =N24-O24 -> 0
A25: 20 | B25: RASHEEDAT DAIBU | C25: 450135.83 | D25: 12 | E25: =C25*D25 -> 5401630 | G25: 73851.35 | H25: 374530.4 | J25: =F25+G25+H25 -> 448381.75 | K25: =E25-J25 -> 4953248.3 | L25: =IF(K25<=800000,0,IF(K25<=3000000,(K25-800000)*15%,IF(K25<=12000000,330000+(K25-3000000)*18%,IF(K25<=25000000,1950000+(K25-12000000)*21%,IF(K25<=50000000,4680000+(K25-25000000)*23%,10430000+(K25-50000000)*25%))))) -> 681584.69 | M25: 12 | N25: =L25/M25 -> 56798.724 | O25: 56798.724 | P25: =N25-O25 -> 0
A26: 21 | B26: ELIZABETH OGECHUKWU ONYEAKU | C26: 0 | D26: 12 | E26: =C26*D26 -> 0 | G26: 0 | H26: 0 | J26: =F26+G26+H26 -> 0 | K26: =E26-J26 -> 0 | L26: =IF(K26<=800000,0,IF(K26<=3000000,(K26-800000)*15%,IF(K26<=12000000,330000+(K26-3000000)*18%,IF(K26<=25000000,1950000+(K26-12000000)*21%,IF(K26<=50000000,4680000+(K26-25000000)*23%,10430000+(K26-50000000)*25%))))) -> 0 | M26: 12 | N26: =L26/M26 -> 0 | O26: 0 | P26: =N26-O26 -> 0
A27: 22 | B27: VICTOR ASUKWO | C27: 432145.33 | D27: 12 | E27: =C27*D27 -> 5185744 | G27: 70673.35 | H27: 357259.52 | J27: =F27+G27+H27 -> 427932.87 | K27: =E27-J27 -> 4757811.1 | L27: =IF(K27<=800000,0,IF(K27<=3000000,(K27-800000)*15%,IF(K27<=12000000,330000+(K27-3000000)*18%,IF(K27<=25000000,1950000+(K27-12000000)*21%,IF(K27<=50000000,4680000+(K27-25000000)*23%,10430000+(K27-50000000)*25%))))) -> 646406 | M27: 12 | N27: =L27/M27 -> 53867.167 | O27: 53867.167 | P27: =N27-O27 -> 0
A28: 23 | B28: NNANDI LIVINUS ATURE | C28: 491140.67 | D28: 12 | E28: =C28*D28 -> 5893688 | F28: 300000 | G28: 72262.375 | H28: 365895.04 | J28: =F28+G28+H28 -> 738157.41 | K28: =E28-J28 -> 5155530.6 | L28: =IF(K28<=800000,0,IF(K28<=3000000,(K28-800000)*15%,IF(K28<=12000000,330000+(K28-3000000)*18%,IF(K28<=25000000,1950000+(K28-12000000)*21%,IF(K28<=50000000,4680000+(K28-25000000)*23%,10430000+(K28-50000000)*25%))))) -> 717995.51 | M28: 12 | N28: =L28/M28 -> 59832.959 | O28: 64332.959 | P28: =N28-O28 -> -4500
A29: 24 | B29: ABDULRAHMAN A SULAIMAN | C29: 415320.67 | D29: 12 | E29: =C29*D29 -> 4983848 | G29: 0 | H29: 341107.84 | J29: =F29+G29+H29 -> 341107.84 | K29: =E29-J29 -> 4642740.2 | L29: =IF(K29<=800000,0,IF(K29<=3000000,(K29-800000)*15%,IF(K29<=12000000,330000+(K29-3000000)*18%,IF(K29<=25000000,1950000+(K29-12000000)*21%,IF(K29<=50000000,4680000+(K29-25000000)*23%,10430000+(K29-50000000)*25%))))) -> 625693.23 | M29: 12 | N29: =L29/M29 -> 52141.102 | O29: 52141.102 | P29: =N29-O29 -> 0
A30: 25 | B30: DARE SHEU MAGBON | C30: 407016.17 | D30: 12 | E30: =C30*D30 -> 4884194 | G30: 0 | H30: 333135.52 | J30: =F30+G30+H30 -> 333135.52 | K30: =E30-J30 -> 4551058.5 | L30: =IF(K30<=800000,0,IF(K30<=3000000,(K30-800000)*15%,IF(K30<=12000000,330000+(K30-3000000)*18%,IF(K30<=25000000,1950000+(K30-12000000)*21%,IF(K30<=50000000,4680000+(K30-25000000)*23%,10430000+(K30-50000000)*25%))))) -> 609190.53 | M30: 12 | N30: =L30/M30 -> 50765.877 | O30: 50765.877 | P30: =N30-O30 -> 0
A31: 26 | B31: ABUBAKAR SULAIMAN SODEEQ | C31: 432145.33 | D31: 12 | E31: =C31*D31 -> 5185744 | G31: 70673.35 | H31: 357259.52 | J31: =F31+G31+H31 -> 427932.87 | K31: =E31-J31 -> 4757811.1 | L31: =IF(K31<=800000,0,IF(K31<=3000000,(K31-800000)*15%,IF(K31<=12000000,330000+(K31-3000000)*18%,IF(K31<=25000000,1950000+(K31-12000000)*21%,IF(K31<=50000000,4680000+(K31-25000000)*23%,10430000+(K31-50000000)*25%))))) -> 646406 | M31: 12 | N31: =L31/M31 -> 53867.167 | O31: 53867.167 | P31: =N31-O31 -> 0
A32: 27 | B32: JIMOH ADEBAYO ZAKA | C32: 432145.33 | D32: 12 | E32: =C32*D32 -> 5185744 | G32: 70673.35 | H32: 357259.52 | J32: =F32+G32+H32 -> 427932.87 | K32: =E32-J32 -> 4757811.1 | L32: =IF(K32<=800000,0,IF(K32<=3000000,(K32-800000)*15%,IF(K32<=12000000,330000+(K32-3000000)*18%,IF(K32<=25000000,1950000+(K32-12000000)*21%,IF(K32<=50000000,4680000+(K32-25000000)*23%,10430000+(K32-50000000)*25%))))) -> 646406 | M32: 12 | N32: =L32/M32 -> 53867.167 | O32: 53867.167 | P32: =N32-O32 -> 0
A33: 28 | B33: ABDULMUSHIN TAWFIQ LADAN | C33: 407016.17 | D33: 12 | E33: =C33*D33 -> 4884194 | G33: 0 | H33: 333135.52 | J33: =F33+G33+H33 -> 333135.52 | K33: =E33-J33 -> 4551058.5 | L33: =IF(K33<=800000,0,IF(K33<=3000000,(K33-800000)*15%,IF(K33<=12000000,330000+(K33-3000000)*18%,IF(K33<=25000000,1950000+(K33-12000000)*21%,IF(K33<=50000000,4680000+(K33-25000000)*23%,10430000+(K33-50000000)*25%))))) -> 609190.53 | M33: 12 | N33: =L33/M33 -> 50765.877 | O33: 50765.877 | P33: =N33-O33 -> 0
A34: 29 | B34: MOHAMMED BELLO | C34: 432145.33 | D34: 12 | E34: =C34*D34 -> 5185744 | G34: 0 | H34: 357259.52 | J34: =F34+G34+H34 -> 357259.52 | K34: =E34-J34 -> 4828484.5 | L34: =IF(K34<=800000,0,IF(K34<=3000000,(K34-800000)*15%,IF(K34<=12000000,330000+(K34-3000000)*18%,IF(K34<=25000000,1950000+(K34-12000000)*21%,IF(K34<=50000000,4680000+(K34-25000000)*23%,10430000+(K34-50000000)*25%))))) -> 659127.21 | M34: 12 | N34: =L34/M34 -> 54927.267 | O34: 54927.267 | P34: =N34-O34 -> 0
A35: 30 | B35: HOLINESS PAUL UDO | C35: 398711.67 | D35: 12 | E35: =C35*D35 -> 4784540 | F35: 200000 | G35: 65320.025 | H35: 325163.2 | J35: =F35+G35+H35 -> 590483.22 | K35: =E35-J35 -> 4194056.8 | L35: =IF(K35<=800000,0,IF(K35<=3000000,(K35-800000)*15%,IF(K35<=12000000,330000+(K35-3000000)*18%,IF(K35<=25000000,1950000+(K35-12000000)*21%,IF(K35<=50000000,4680000+(K35-25000000)*23%,10430000+(K35-50000000)*25%))))) -> 544930.22 | M35: 12 | N35: =L35/M35 -> 45410.852 | O35: 48410.852 | P35: =N35-O35 -> -3000
A36: 31 | B36: CHARITY UDO AKAN | C36: 398711.67 | D36: 12 | E36: =C36*D36 -> 4784540 | G36: 65320.025 | H36: 325163.2 | J36: =F36+G36+H36 -> 390483.22 | K36: =E36-J36 -> 4394056.8 | L36: =IF(K36<=800000,0,IF(K36<=3000000,(K36-800000)*15%,IF(K36<=12000000,330000+(K36-3000000)*18%,IF(K36<=25000000,1950000+(K36-12000000)*21%,IF(K36<=50000000,4680000+(K36-25000000)*23%,10430000+(K36-50000000)*25%))))) -> 580930.22 | M36: 12 | N36: =L36/M36 -> 48410.852 | O36: 48410.852 | P36: =N36-O36 -> 0
A37: 32 | B37: SANI UMAR IBRAHIM | C37: 398711.67 | D37: 12 | E37: =C37*D37 -> 4784540 | G37: 0 | H37: 325163.2 | J37: =F37+G37+H37 -> 325163.2 | K37: =E37-J37 -> 4459376.8 | L37: =IF(K37<=800000,0,IF(K37<=3000000,(K37-800000)*15%,IF(K37<=12000000,330000+(K37-3000000)*18%,IF(K37<=25000000,1950000+(K37-12000000)*21%,IF(K37<=50000000,4680000+(K37-25000000)*23%,10430000+(K37-50000000)*25%))))) -> 592687.82 | M37: 12 | N37: =L37/M37 -> 49390.652 | O37: 49390.652 | P37: =N37-O37 -> 0
A38: 33 | B38: FAHAD ABUBUKAR LONGMAN | C38: 398711.67 | D38: 12 | E38: =C38*D38 -> 4784540 | G38: 65320.025 | H38: 325163.2 | J38: =F38+G38+H38 -> 390483.22 | K38: =E38-J38 -> 4394056.8 | L38: =IF(K38<=800000,0,IF(K38<=3000000,(K38-800000)*15%,IF(K38<=12000000,330000+(K38-3000000)*18%,IF(K38<=25000000,1950000+(K38-12000000)*21%,IF(K38<=50000000,4680000+(K38-25000000)*23%,10430000+(K38-50000000)*25%))))) -> 580930.22 | M38: 12 | N38: =L38/M38 -> 48410.852 | O38: 48410.852 | P38: =N38-O38 -> 0
A39: 34 | B39: HARUNA JIBRIL AMEH | C39: 358920.67 | D39: 12 | E39: =C39*D39 -> 4307048 | G39: 60164.825 | H39: 296563.84 | J39: =F39+G39+H39 -> 356728.66 | K39: =E39-J39 -> 3950319.3 | L39: =IF(K39<=800000,0,IF(K39<=3000000,(K39-800000)*15%,IF(K39<=12000000,330000+(K39-3000000)*18%,IF(K39<=25000000,1950000+(K39-12000000)*21%,IF(K39<=50000000,4680000+(K39-25000000)*23%,10430000+(K39-50000000)*25%))))) -> 501057.48 | M39: 12 | N39: =L39/M39 -> 41754.79 | O39: 41754.79 | P39: =N39-O39 -> 0
A40: 35 | B40: RAMATU IBRAHIM ABDULRAHEEM | C40: 351910.75 | D40: 12 | E40: =C40*D40 -> 4222929 | G40: 58909.325 | H40: 289834.32 | J40: =F40+G40+H40 -> 348743.65 | K40: =E40-J40 -> 3874185.4 | L40: =IF(K40<=800000,0,IF(K40<=3000000,(K40-800000)*15%,IF(K40<=12000000,330000+(K40-3000000)*18%,IF(K40<=25000000,1950000+(K40-12000000)*21%,IF(K40<=50000000,4680000+(K40-25000000)*23%,10430000+(K40-50000000)*25%))))) -> 487353.36 | M40: 12 | N40: =L40/M40 -> 40612.78 | O40: 40612.78 | P40: =N40-O40 -> 0
A41: 36 | B41: EDIDIONG EZEKIEL ATAT | C41: 344900.83 | D41: 12 | E41: =C41*D41 -> 4138810 | G41: 57653.825 | H41: 283104.8 | J41: =F41+G41+H41 -> 340758.63 | K41: =E41-J41 -> 3798051.4 | L41: =IF(K41<=800000,0,IF(K41<=3000000,(K41-800000)*15%,IF(K41<=12000000,330000+(K41-3000000)*18%,IF(K41<=25000000,1950000+(K41-12000000)*21%,IF(K41<=50000000,4680000+(K41-25000000)*23%,10430000+(K41-50000000)*25%))))) -> 473649.25 | M41: 12 | N41: =L41/M41 -> 39470.771 | O41: 39470.771 | P41: =N41-O41 -> 0
A42: 37 | B42: MAHMUD ADEWOLE HASSAN | C42: 344900.83 | D42: 12 | E42: =C42*D42 -> 4138810 | G42: 0 | H42: 283104.8 | J42: =F42+G42+H42 -> 283104.8 | K42: =E42-J42 -> 3855705.2 | L42: =IF(K42<=800000,0,IF(K42<=3000000,(K42-800000)*15%,IF(K42<=12000000,330000+(K42-3000000)*18%,IF(K42<=25000000,1950000+(K42-12000000)*21%,IF(K42<=50000000,4680000+(K42-25000000)*23%,10430000+(K42-50000000)*25%))))) -> 484026.94 | M42: 12 | N42: =L42/M42 -> 40335.578 | O42: 40335.578 | P42: =N42-O42 -> 0
A43: 38 | B43: YUSUF KABIRU TURAKI | C43: 344900.83 | D43: 12 | E43: =C43*D43 -> 4138810 | G43: 0 | H43: 283104.8 | J43: =F43+G43+H43 -> 283104.8 | K43: =E43-J43 -> 3855705.2 | L43: =IF(K43<=800000,0,IF(K43<=3000000,(K43-800000)*15%,IF(K43<=12000000,330000+(K43-3000000)*18%,IF(K43<=25000000,1950000+(K43-12000000)*21%,IF(K43<=50000000,4680000+(K43-25000000)*23%,10430000+(K43-50000000)*25%))))) -> 484026.94 | M43: 12 | N43: =L43/M43 -> 40335.578 | O43: 40335.578 | P43: =N43-O43 -> 0
...

Sheet FCTIRS Template
A1: PAY AS YOU EARN COMPUTATION
A2: NAME ORGANISATION:
A3: ASSESSMENT YEAR: | D3: 2026 | E3: ELIGIBLE DEDUCTIONS
A4: S/N | B4: EMPLOYEE NAME | C4: TAX IDENTIFICATION | D4: ANNUAL GROSS EMOLUMENTS | E4: ANNUAL RENT | F4: RENT | G4: NHF | H4: NHIS | I4: PENSION CONTRIBUTION | J4: TOTAL ELIGIBLE DEDUCTIONS | K4: CHARGEABLE INCOME | L4: 1ST 800,000 @ 0% | M4: NEXT 2,200,000 @ 15% | N4: NEXT 9,000,000 @ 18% | O4: NEXT 13,000,000 @ 21% | P4: NEXT 25000000 @ 23% | Q4: EXCESS OF 50000000 @ 25% | R4: ANNUAL TAX DUE | S4: MONTHLY TAX DUE
C5: FCT TAXPAYER ID | F5: RELIEF | G5: 2.5% of Annual Income | H5: 1.75% of Annual Emoluments | I5: 8% of the Gross Salary
D6: Enter Total Annual Earnings Here | F6: Lower of the 20% actual rent paid or N500,000 | G6: Leave as computed if dedeuctions tally, otherwise, enter correct deductions. Note: You may be required to show evidence of deductions and remittance
B7: DG'S OFFICE
A8: 1 | B8: PROF. ABUBAKAR O. SULAIMAN | F8: =MIN(0.2*E8,500000) -> 0 | J8: =SUM(F8:I8) -> 0 | K8: =(D8-J8) -> 0 | L8: =(K8*0%) -> 0 | M8: =IF((K8-800000)<=0,0,IF((K8-800000)>=2200000,2200000*15%,(K8-800000)*15%)) -> 0 | N8: =IF((K8-(3000000))<=0,0,IF((K8-(3000000))>=9000000,9000000*18%,(K8-(3000000))*18%)) -> 0 | O8: =IF((K8-(12000000))<=0,0,IF((K8-(12000000))>=13000000,13000000*21%,(K8-(12000000))*21%)) -> 0 | P8: =IF((K8-(25000000))<=0,0,IF((K8-(25000000))>=25000000,25000000*23%,(K8-(25000000))*23%)) -> 0 | Q8: =IF((K8-(50000000))<=0,0,(K8-(50000000))*25%) -> 0 | R8: =SUM(L8:Q8) -> 0 | S8: =R8/12 -> 0
A9: 2 | B9: RAHEEM USMAN AYIGORO | F9: =MIN(0.2*E9,500000) -> 0 | J9: =SUM(F9:I9) -> 0 | K9: =(D9-J9) -> 0 | L9: =(K9*0%) -> 0 | M9: =IF((K9-800000)<=0,0,IF((K9-800000)>=2200000,2200000*15%,(K9-800000)*15%)) -> 0 | N9: =IF((K9-(3000000))<=0,0,IF((K9-(3000000))>=9000000,9000000*18%,(K9-(3000000))*18%)) -> 0 | O9: =IF((K9-(12000000))<=0,0,IF((K9-(12000000))>=13000000,13000000*21%,(K9-(12000000))*21%)) -> 0 | P9: =IF((K9-(25000000))<=0,0,IF((K9-(25000000))>=25000000,25000000*23%,(K9-(25000000))*23%)) -> 0 | Q9: =IF((K9-(50000000))<=0,0,(K9-(50000000))*25%) -> 0 | R9: =SUM(L9:Q9) -> 0 | S9: =R9/12 -> 0
A10: 3 | B10: MARIAM MOHAMMED BELLO | F10: =MIN(0.2*E10,500000) -> 0 | J10: =SUM(F10:I10) -> 0 | K10: =(D10-J10) -> 0 | L10: =(K10*0%) -> 0 | M10: =IF((K10-800000)<=0,0,IF((K10-800000)>=2200000,2200000*15%,(K10-800000)*15%)) -> 0 | N10: =IF((K10-(3000000))<=0,0,IF((K10-(3000000))>=9000000,9000000*18%,(K10-(3000000))*18%)) -> 0 | O10: =IF((K10-(12000000))<=0,0,IF((K10-(12000000))>=13000000,13000000*21%,(K10-(12000000))*21%)) -> 0 | P10: =IF((K10-(25000000))<=0,0,IF((K10-(25000000))>=25000000,25000000*23%,(K10-(25000000))*23%)) -> 0 | Q10: =IF((K10-(50000000))<=0,0,(K10-(50000000))*25%) -> 0 | R10: =SUM(L10:Q10) -> 0 | S10: =R10/12 -> 0
A11: 4 | B11: DR IKEME ARTHUR J.O | F11: =MIN(0.2*E11,500000) -> 0 | J11: =SUM(F11:I11) -> 0 | K11: =(D11-J11) -> 0 | L11: =(K11*0%) -> 0 | M11: =IF((K11-800000)<=0,0,IF((K11-800000)>=2200000,2200000*15%,(K11-800000)*15%)) -> 0 | N11: =IF((K11-(3000000))<=0,0,IF((K11-(3000000))>=9000000,9000000*18%,(K11-(3000000))*18%)) -> 0 | O11: =IF((K11-(12000000))<=0,0,IF((K11-(12000000))>=13000000,13000000*21%,(K11-(12000000))*21%)) -> 0 | P11: =IF((K11-(25000000))<=0,0,IF((K11-(25000000))>=25000000,25000000*23%,(K11-(25000000))*23%)) -> 0 | Q11: =IF((K11-(50000000))<=0,0,(K11-(50000000))*25%) -> 0 | R11: =SUM(L11:Q11) -> 0 | S11: =R11/12 -> 0
A12: 5 | B12: ANDRAWUS MUSA | F12: =MIN(0.2*E12,500000) -> 0 | J12: =SUM(F12:I12) -> 0 | K12: =(D12-J12) -> 0 | L12: =(K12*0%) -> 0 | M12: =IF((K12-800000)<=0,0,IF((K12-800000)>=2200000,2200000*15%,(K12-800000)*15%)) -> 0 | N12: =IF((K12-(3000000))<=0,0,IF((K12-(3000000))>=9000000,9000000*18%,(K12-(3000000))*18%)) -> 0 | O12: =IF((K12-(12000000))<=0,0,IF((K12-(12000000))>=13000000,13000000*21%,(K12-(12000000))*21%)) -> 0 | P12: =IF((K12-(25000000))<=0,0,IF((K12-(25000000))>=25000000,25000000*23%,(K12-(25000000))*23%)) -> 0 | Q12: =IF((K12-(50000000))<=0,0,(K12-(50000000))*25%) -> 0 | R12: =SUM(L12:Q12) -> 0 | S12: =R12/12 -> 0
A13: 6 | B13: DR FRANCIS NDUM OJIE | F13: =MIN(0.2*E13,500000) -> 0 | J13: =SUM(F13:I13) -> 0 | K13: =(D13-J13) -> 0 | L13: =(K13*0%) -> 0 | M13: =IF((K13-800000)<=0,0,IF((K13-800000)>=2200000,2200000*15%,(K13-800000)*15%)) -> 0 | N13: =IF((K13-(3000000))<=0,0,IF((K13-(3000000))>=9000000,9000000*18%,(K13-(3000000))*18%)) -> 0 | O13: =IF((K13-(12000000))<=0,0,IF((K13-(12000000))>=13000000,13000000*21%,(K13-(12000000))*21%)) -> 0 | P13: =IF((K13-(25000000))<=0,0,IF((K13-(25000000))>=25000000,25000000*23%,(K13-(25000000))*23%)) -> 0 | Q13: =IF((K13-(50000000))<=0,0,(K13-(50000000))*25%) -> 0 | R13: =SUM(L13:Q13) -> 0 | S13: =R13/12 -> 0
A14: 7 | B14: ALI ABDULLAHI | F14: =MIN(0.2*E14,500000) -> 0 | J14: =SUM(F14:I14) -> 0 | K14: =(D14-J14) -> 0 | L14: =(K14*0%) -> 0 | M14: =IF((K14-800000)<=0,0,IF((K14-800000)>=2200000,2200000*15%,(K14-800000)*15%)) -> 0 | N14: =IF((K14-(3000000))<=0,0,IF((K14-(3000000))>=9000000,9000000*18%,(K14-(3000000))*18%)) -> 0 | O14: =IF((K14-(12000000))<=0,0,IF((K14-(12000000))>=13000000,13000000*21%,(K14-(12000000))*21%)) -> 0 | P14: =IF((K14-(25000000))<=0,0,IF((K14-(25000000))>=25000000,25000000*23%,(K14-(25000000))*23%)) -> 0 | Q14: =IF((K14-(50000000))<=0,0,(K14-(50000000))*25%) -> 0 | R14: =SUM(L14:Q14) -> 0 | S14: =R14/12 -> 0
A15: 8 | B15: EMILY EKHIDE | F15: =MIN(0.2*E15,500000) -> 0 | G15: =D15*2.5% -> 0 | J15: =SUM(J8:J14) -> 0 | K15: =(D15-J15) -> 0 | L15: =(K15*0%) -> 0 | M15: =IF((K15-800000)<=0,0,IF((K15-800000)>=2200000,2200000*15%,(K15-800000)*15%)) -> 0 | N15: =IF((K15-(3000000))<=0,0,IF((K15-(3000000))>=9000000,9000000*18%,(K15-(3000000))*18%)) -> 0 | O15: =IF((K15-(12000000))<=0,0,IF((K15-(12000000))>=13000000,13000000*21%,(K15-(12000000))*21%)) -> 0 | P15: =IF((K15-(25000000))<=0,0,IF((K15-(25000000))>=25000000,25000000*23%,(K15-(25000000))*23%)) -> 0 | Q15: =IF((K15-(50000000))<=0,0,(K15-(50000000))*25%) -> 0 | R15: =SUM(R8:R14) -> 0 | S15: =SUM(S8:S14) -> 0
A16: 9 | B16: DORIS DAKDA AARON | F16: =MIN(0.2*E16,500000) -> 0 | G16: =D16*2.5% -> 0 | H16: =D16*1.75% -> 0 | I16: =D16*8% -> 0 | J16: =SUM(F16:I16) -> 0 | K16: =(D16-J16) -> 0 | L16: =(K16*0%) -> 0 | M16: =IF((K16-800000)<=0,0,IF((K16-800000)>=2200000,2200000*15%,(K16-800000)*15%)) -> 0 | N16: =IF((K16-(3000000))<=0,0,IF((K16-(3000000))>=9000000,9000000*18%,(K16-(3000000))*18%)) -> 0 | O16: =IF((K16-(12000000))<=0,0,IF((K16-(12000000))>=13000000,13000000*21%,(K16-(12000000))*21%)) -> 0 | P16: =IF((K16-(25000000))<=0,0,IF((K16-(25000000))>=25000000,25000000*23%,(K16-(25000000))*23%)) -> 0 | Q16: =IF((K16-(50000000))<=0,0,(K16-(50000000))*25%) -> 0 | R16: =SUM(L16:Q16) -> 0 | S16: =R16/12 -> 0
A17: 10 | B17: ABDULSALAM S. MUSTAPHA | F17: =MIN(0.2*E17,500000) -> 0 | G17: =D17*2.5% -> 0 | H17: =D17*1.75% -> 0 | I17: =D17*8% -> 0 | J17: =SUM(F17:I17) -> 0 | K17: =(D17-J17) -> 0 | L17: =(K17*0%) -> 0 | M17: =IF((K17-800000)<=0,0,IF((K17-800000)>=2200000,2200000*15%,(K17-800000)*15%)) -> 0 | N17: =IF((K17-(3000000))<=0,0,IF((K17-(3000000))>=9000000,9000000*18%,(K17-(3000000))*18%)) -> 0 | O17: =IF((K17-(12000000))<=0,0,IF((K17-(12000000))>=13000000,13000000*21%,(K17-(12000000))*21%)) -> 0 | P17: =IF((K17-(25000000))<=0,0,IF((K17-(25000000))>=25000000,25000000*23%,(K17-(25000000))*23%)) -> 0 | Q17: =IF((K17-(50000000))<=0,0,(K17-(50000000))*25%) -> 0 | R17: =SUM(L17:Q17) -> 0 | S17: =R17/12 -> 0
A18: 11 | B18: PERCY TERFA GBAHABO | F18: =MIN(0.2*E18,500000) -> 0 | G18: =D18*2.5% -> 0 | H18: =D18*1.75% -> 0 | I18: =D18*8% -> 0 | J18: =SUM(F18:I18) -> 0 | K18: =(D18-J18) -> 0 | L18: =(K18*0%) -> 0 | M18: =IF((K18-800000)<=0,0,IF((K18-800000)>=2200000,2200000*15%,(K18-800000)*15%)) -> 0 | N18: =IF((K18-(3000000))<=0,0,IF((K18-(3000000))>=9000000,9000000*18%,(K18-(3000000))*18%)) -> 0 | O18: =IF((K18-(12000000))<=0,0,IF((K18-(12000000))>=13000000,13000000*21%,(K18-(12000000))*21%)) -> 0 | P18: =IF((K18-(25000000))<=0,0,IF((K18-(25000000))>=25000000,25000000*23%,(K18-(25000000))*23%)) -> 0 | Q18: =IF((K18-(50000000))<=0,0,(K18-(50000000))*25%) -> 0 | R18: =SUM(L18:Q18) -> 0 | S18: =R18/12 -> 0
A19: 12 | B19: HASSANA AHMED IBRAHIM | F19: =MIN(0.2*E19,500000) -> 0 | G19: =D19*2.5% -> 0 | H19: =D19*1.75% -> 0 | I19: =D19*8% -> 0 | J19: =SUM(F19:I19) -> 0 | K19: =(D19-J19) -> 0 | L19: =(K19*0%) -> 0 | M19: =IF((K19-800000)<=0,0,IF((K19-800000)>=2200000,2200000*15%,(K19-800000)*15%)) -> 0 | N19: =IF((K19-(3000000))<=0,0,IF((K19-(3000000))>=9000000,9000000*18%,(K19-(3000000))*18%)) -> 0 | O19: =IF((K19-(12000000))<=0,0,IF((K19-(12000000))>=13000000,13000000*21%,(K19-(12000000))*21%)) -> 0 | P19: =IF((K19-(25000000))<=0,0,IF((K19-(25000000))>=25000000,25000000*23%,(K19-(25000000))*23%)) -> 0 | Q19: =IF((K19-(50000000))<=0,0,(K19-(50000000))*25%) -> 0 | R19: =SUM(L19:Q19) -> 0 | S19: =R19/12 -> 0
A20: 13 | B20: IKIP LEBO | F20: =MIN(0.2*E20,500000) -> 0 | G20: =D20*2.5% -> 0 | H20: =D20*1.75% -> 0 | I20: =D20*8% -> 0 | J20: =SUM(F20:I20) -> 0 | K20: =(D20-J20) -> 0 | L20: =(K20*0%) -> 0 | M20: =IF((K20-800000)<=0,0,IF((K20-800000)>=2200000,2200000*15%,(K20-800000)*15%)) -> 0 | N20: =IF((K20-(3000000))<=0,0,IF((K20-(3000000))>=9000000,9000000*18%,(K20-(3000000))*18%)) -> 0 | O20: =IF((K20-(12000000))<=0,0,IF((K20-(12000000))>=13000000,13000000*21%,(K20-(12000000))*21%)) -> 0 | P20: =IF((K20-(25000000))<=0,0,IF((K20-(25000000))>=25000000,25000000*23%,(K20-(25000000))*23%)) -> 0 | Q20: =IF((K20-(50000000))<=0,0,(K20-(50000000))*25%) -> 0 | R20: =SUM(L20:Q20) -> 0 | S20: =R20/12 -> 0
A21: 14 | B21: ALABI ADESINA MUHYDEEN | F21: =MIN(0.2*E21,500000) -> 0 | G21: =D21*2.5% -> 0 | H21: =D21*1.75% -> 0 | I21: =D21*8% -> 0 | J21: =SUM(F21:I21) -> 0 | K21: =(D21-J21) -> 0 | L21: =(K21*0%) -> 0 | M21: =IF((K21-800000)<=0,0,IF((K21-800000)>=2200000,2200000*15%,(K21-800000)*15%)) -> 0 | N21: =IF((K21-(3000000))<=0,0,IF((K21-(3000000))>=9000000,9000000*18%,(K21-(3000000))*18%)) -> 0 | O21: =IF((K21-(12000000))<=0,0,IF((K21-(12000000))>=13000000,13000000*21%,(K21-(12000000))*21%)) -> 0 | P21: =IF((K21-(25000000))<=0,0,IF((K21-(25000000))>=25000000,25000000*23%,(K21-(25000000))*23%)) -> 0 | Q21: =IF((K21-(50000000))<=0,0,(K21-(50000000))*25%) -> 0 | R21: =SUM(L21:Q21) -> 0 | S21: =R21/12 -> 0
A22: 15 | B22: BASSEY NSONGURUA UDOFIA | F22: =MIN(0.2*E22,500000) -> 0 | G22: =D22*2.5% -> 0 | H22: =D22*1.75% -> 0 | I22: =D22*8% -> 0 | J22: =SUM(F22:I22) -> 0 | K22: =(D22-J22) -> 0 | L22: =(K22*0%) -> 0 | M22: =IF((K22-800000)<=0,0,IF((K22-800000)>=2200000,2200000*15%,(K22-800000)*15%)) -> 0 | N22: =IF((K22-(3000000))<=0,0,IF((K22-(3000000))>=9000000,9000000*18%,(K22-(3000000))*18%)) -> 0 | O22: =IF((K22-(12000000))<=0,0,IF((K22-(12000000))>=13000000,13000000*21%,(K22-(12000000))*21%)) -> 0 | P22: =IF((K22-(25000000))<=0,0,IF((K22-(25000000))>=25000000,25000000*23%,(K22-(25000000))*23%)) -> 0 | Q22: =IF((K22-(50000000))<=0,0,(K22-(50000000))*25%) -> 0 | R22: =SUM(L22:Q22) -> 0 | S22: =R22/12 -> 0
A23: 16 | B23: ADUGBA RICHARD TERSEER | F23: =MIN(0.2*E23,500000) -> 0 | G23: =D23*2.5% -> 0 | H23: =D23*1.75% -> 0 | I23: =D23*8% -> 0 | J23: =SUM(F23:I23) -> 0 | K23: =(D23-J23) -> 0 | L23: =(K23*0%) -> 0 | M23: =IF((K23-800000)<=0,0,IF((K23-800000)>=2200000,2200000*15%,(K23-800000)*15%)) -> 0 | N23: =IF((K23-(3000000))<=0,0,IF((K23-(3000000))>=9000000,9000000*18%,(K23-(3000000))*18%)) -> 0 | O23: =IF((K23-(12000000))<=0,0,IF((K23-(12000000))>=13000000,13000000*21%,(K23-(12000000))*21%)) -> 0 | P23: =IF((K23-(25000000))<=0,0,IF((K23-(25000000))>=25000000,25000000*23%,(K23-(25000000))*23%)) -> 0 | Q23: =IF((K23-(50000000))<=0,0,(K23-(50000000))*25%) -> 0 | R23: =SUM(L23:Q23) -> 0 | S23: =R23/12 -> 0
A24: 17 | B24: LUCKY AGWOM | F24: =MIN(0.2*E24,500000) -> 0 | G24: =D24*2.5% -> 0 | H24: =D24*1.75% -> 0 | I24: =D24*8% -> 0 | J24: =SUM(F24:I24) -> 0 | K24: =(D24-J24) -> 0 | L24: =(K24*0%) -> 0 | M24: =IF((K24-800000)<=0,0,IF((K24-800000)>=2200000,2200000*15%,(K24-800000)*15%)) -> 0 | N24: =IF((K24-(3000000))<=0,0,IF((K24-(3000000))>=9000000,9000000*18%,(K24-(3000000))*18%)) -> 0 | O24: =IF((K24-(12000000))<=0,0,IF((K24-(12000000))>=13000000,13000000*21%,(K24-(12000000))*21%)) -> 0 | P24: =IF((K24-(25000000))<=0,0,IF((K24-(25000000))>=25000000,25000000*23%,(K24-(25000000))*23%)) -> 0 | Q24: =IF((K24-(50000000))<=0,0,(K24-(50000000))*25%) -> 0 | R24: =SUM(L24:Q24) -> 0 | S24: =R24/12 -> 0
A25: 18 | B25: IDRIS IBRAHIM | F25: =MIN(0.2*E25,500000) -> 0 | G25: =D25*2.5% -> 0 | H25: =D25*1.75% -> 0 | I25: =D25*8% -> 0 | J25: =SUM(F25:I25) -> 0 | K25: =(D25-J25) -> 0 | L25: =(K25*0%) -> 0 | M25: =IF((K25-800000)<=0,0,IF((K25-800000)>=2200000,2200000*15%,(K25-800000)*15%)) -> 0 | N25: =IF((K25-(3000000))<=0,0,IF((K25-(3000000))>=9000000,9000000*18%,(K25-(3000000))*18%)) -> 0 | O25: =IF((K25-(12000000))<=0,0,IF((K25-(12000000))>=13000000,13000000*21%,(K25-(12000000))*21%)) -> 0 | P25: =IF((K25-(25000000))<=0,0,IF((K25-(25000000))>=25000000,25000000*23%,(K25-(25000000))*23%)) -> 0 | Q25: =IF((K25-(50000000))<=0,0,(K25-(50000000))*25%) -> 0 | R25: =SUM(L25:Q25) -> 0 | S25: =R25/12 -> 0
A26: 19 | B26: FARUQ ATOFARATI | F26: =MIN(0.2*E26,500000) -> 0 | G26: =D26*2.5% -> 0 | H26: =D26*1.75% -> 0 | I26: =D26*8% -> 0 | J26: =SUM(F26:I26) -> 0 | K26: =(D26-J26) -> 0 | L26: =(K26*0%) -> 0 | M26: =IF((K26-800000)<=0,0,IF((K26-800000)>=2200000,2200000*15%,(K26-800000)*15%)) -> 0 | N26: =IF((K26-(3000000))<=0,0,IF((K26-(3000000))>=9000000,9000000*18%,(K26-(3000000))*18%)) -> 0 | O26: =IF((K26-(12000000))<=0,0,IF((K26-(12000000))>=13000000,13000000*21%,(K26-(12000000))*21%)) -> 0 | P26: =IF((K26-(25000000))<=0,0,IF((K26-(25000000))>=25000000,25000000*23%,(K26-(25000000))*23%)) -> 0 | Q26: =IF((K26-(50000000))<=0,0,(K26-(50000000))*25%) -> 0 | R26: =SUM(L26:Q26) -> 0 | S26: =R26/12 -> 0
A27: 20 | B27: RASHEEDAT DAIBU | F27: =MIN(0.2*E27,500000) -> 0 | G27: =D27*2.5% -> 0 | H27: =D27*1.75% -> 0 | I27: =D27*8% -> 0 | J27: =SUM(F27:I27) -> 0 | K27: =(D27-J27) -> 0 | L27: =(K27*0%) -> 0 | M27: =IF((K27-800000)<=0,0,IF((K27-800000)>=2200000,2200000*15%,(K27-800000)*15%)) -> 0 | N27: =IF((K27-(3000000))<=0,0,IF((K27-(3000000))>=9000000,9000000*18%,(K27-(3000000))*18%)) -> 0 | O27: =IF((K27-(12000000))<=0,0,IF((K27-(12000000))>=13000000,13000000*21%,(K27-(12000000))*21%)) -> 0 | P27: =IF((K27-(25000000))<=0,0,IF((K27-(25000000))>=25000000,25000000*23%,(K27-(25000000))*23%)) -> 0 | Q27: =IF((K27-(50000000))<=0,0,(K27-(50000000))*25%) -> 0 | R27: =SUM(L27:Q27) -> 0 | S27: =R27/12 -> 0
... A48: 41 | B48: ALIYU GARBA LERE | F48: =MIN(0.2*E48,500000) -> 0 | G48: =D48*2.5% -> 0 | H48: =D48*1.75% -> 0 | I48: =D48*8% -> 0 | J48: =SUM(F48:I48) -> 0 | K48: =(D48-J48) -> 0 | L48: =(K48*0%) -> 0 | M48: =IF((K48-800000)<=0,0,IF((K48-800000)>=2200000,2200000*15%,(K48-800000)*15%)) -> 0 | N48: =IF((K48-(3000000))<=0,0,IF((K48-(3000000))>=9000000,9000000*18%,(K48-(3000000))*18%)) -> 0 | O48: =IF((K48-(12000000))<=0,0,IF((K48-(12000000))>=13000000,13000000*21%,(K48-(12000000))*21%)) -> 0 | P48: =IF((K48-(25000000))<=0,0,IF((K48-(25000000))>=25000000,25000000*23%,(K48-(25000000))*23%)) -> 0 | Q48: =IF((K48-(50000000))<=0,0,(K48-(50000000))*25%) -> 0 | R48: =SUM(L48:Q48) -> 0 | S48: =R48/12 -> 0
B50: INTERNAL AUDIT
A51: 1 | B51: OSANAIYE DAVID AKINYEMI
A52: 2 | B52: EVELYN ETONKE AGAN
A53: 3 | B53: JAMILA ABDUL
A54: 4 | B54: IJEOMA EWELUKWA
A55: 5 | B55: HASSAN ABDULHADI
A56: 6 | B56: YUSUF YUSUF DAYYABU
A57: 7 | B57: UDONSI QUEENETH CHIWENDU
B59: LEG. SUPPORT SEVICES
A60: 1 | B60: BETHEL UZOMA IHUGBA
A61: 2 | B61: OGUCHE SAMUEL
A62: 3 | B62: IBRAHIM USMAN
...

Sheet Rent Relief
A1: NATIONAL INSTITUTE FOR LEGISLATIVE AND DEMOCRATIC STUDIES
A2: STAFF ANNUAL RENT RELIEF
A4: S/N | B4: NAME | C4: GL | D4: ANNUAL RENT | E4: 20% OF ANNUAL RENT
B5: DG'S OFFICE | D5: N | E5: N
A6: 1 | B6: PROF. ABUBAKAR O. SULAIMAN | C6: CONSOL | E6: =D6*0.2 -> 0
A7: 2 | B7: RAHEEM USMAN AYIGORO | C7: 16 (9) | E7: =D7*0.2 -> 0
A8: 3 | B8: MARIAM MOHAMMED BELLO | C8: 16 (9) | E8: =D8*0.2 -> 0
A9: 4 | B9: DR IKEME ARTHUR J.O | C9: 16 (9) | E9: =D9*0.2 -> 0
A10: 5 | B10: ANDRAWUS MUSA | C10: 16(9) | E10: =D10*0.2 -> 0
A11: 6 | B11: DR FRANCIS NDUM OJIE | C11: 15(9) | E11: =D11*0.2 -> 0
A12: 7 | B12: ALI ABDULLAHI | C12: 15(7) | E12: =D12*0.2 -> 0
A13: 8 | B13: EMILY EKHIDE | C13: 15(9) | E13: =D13*0.2 -> 0
A14: 9 | B14: DORIS DAKDA AARON | C14: 14(10) | E14: =D14*0.2 -> 0
A15: 10 | B15: ABDULSALAM S. MUSTAPHA | C15: 15(8) | E15: =D15*0.2 -> 0
A16: 11 | B16: PERCY TERFA GBAHABO | C16: 14(8) | E16: =D16*0.2 -> 0
A17: 12 | B17: HASSANA AHMED IBRAHIM | C17: 13(11) | E17: =D17*0.2 -> 0
... A22: 17 | B22: LUCKY AGWOM | C22: 12(9) | E22: =D22*0.2 -> 0
A23: 18 | B23: IDRIS IBRAHIM | C23: 12(9) | D23: 1000000 | E23: =D23*0.2 -> 200000
A24: 19 | B24: FARUQ ATOFARATI | C24: 10(8) | E24: =D24*0.2 -> 0
A25: 20 | B25: RASHEEDAT DAIBU | C25: 10(9) | E25: =D25*0.2 -> 0
A26: 21 | B26: VICTOR ASUKWO | C26: 10(7) | E26: =D26*0.2 -> 0
A27: 22 | B27: NNANDI LIVINUS ATURE | C27: 10(8) | D27: 1500000 | E27: =D27*0.2 -> 300000
A28: 23 | B28: ABDULRAHMAN A SULAIMAN | C28: 9(10) | E28: =D28*0.2 -> 0
A29: 24 | B29: DARE SHEU MAGBON | C29: 9(9) | E29: =D29*0.2 -> 0
A30: 25 | B30: ABUBAKAR SULAIMAN SODEEQ | C30: 10(7) | E30: =D30*0.2 -> 0
A31: 26 | B31: JIMOH ADEBAYO ZAKA | C31: 10(7) | E31: =D31*0.2 -> 0
A32: 27 | B32: ABDULMUSHIN TAWFIQ LADAN | C32: 9(9) | E32: =D32*0.2 -> 0
A33: 28 | B33: MOHAMMED BELLO | C33: 10(7) | E33: =D33*0.2 -> 0
A34: 29 | B34: HOLINESS PAUL UDO | C34: 9(8) | D34: 1000000 | E34: =D34*0.2 -> 200000
A35: 30 | B35: CHARITY UDO AKAN | C35: 9(8) | E35: =D35*0.2 -> 0
A36: 31 | B36: SANI UMAR IBRAHIM | C36: 9(8) | E36: =D36*0.2 -> 0
A37: 32 | B37: FAHAD ABUBUKAR LONGMAN | C37: 9(8) | E37: =D37*0.2 -> 0
A38: 33 | B38: HARUNA JIBRIL AMEH | C38: 8(10) | E38: =D38*0.2 -> 0
A39: 34 | B39: RAMATU IBRAHIM ABDULRAHEEM | C39: 8(9) | E39: =D39*0.2 -> 0
A40: 35 | B40: EDIDIONG EZEKIEL ATAT | C40: 8(8) | E40: =D40*0.2 -> 0
A41: 36 | B41: MAHMUD ADEWOLE HASSAN | C41: 8(8) | E41: =D41*0.2 -> 0
A42: 37 | B42: YUSUF KABIRU TURAKI | C42: 8(8) | E42: =D42*0.2 -> 0
A43: 38 | B43: FATIMA OMAR IBRAHIM | C43: 8(8) | E43: =D43*0.2 -> 0
A44: 39 | B44: EBERE ANASTHESIA IGWE | C44: 8(8) | E44: =D44*0.2 -> 0
A45: 40 | B45: ALIYU GARBA LERE | C45: 8(8) | E45: =D45*0.2 -> 0
...

Sheet  Promotions
A1: NATIONAL INSTITUTE FOR LEGISLATIVE & DEMOCRATIC STUDIES
A2: ANALYSIS OF STAFF PROMOTION ARREARS
A4: SN | B4: Name of Employee | C4: Department | D4: Present Grade Level | E4: New Grade Level | F4: Gross Salary of Present Position | G4: Gross Salary of New Position | H4: Diference/Arrears | I4: Effective Date | J4: No of Months | K4: Total Amount of Arrears (Gross)
F5: N | G5: N | H5: N | K5: N
A6: 1 | B6: Patrick Adefuna | C6: DD&G | D6: '12/10 | E6: 13/7 | F6: 592662.67 | G6: ='[2]Peculiar Allowance'!$H$41+'[2] FGN 2024 MGT Monthly'!$H$41+120000 -> 602846.58 | H6: =G6-F6 -> 10183.917 | I6: 20th Dec 2025 | J6: =1+(12/31) -> 1.3870968 | K6: =H6*J6 -> 14126.078
A7: 2 | B7: Kolapo Quadri Abayomi | C7: CAEEP | D7: '10/10 | E7: 12/7 | F7: 499131.17 | G7: ='[2] FGN 2024 MGT Monthly'!$H$40+'[2]Peculiar Allowance'!$H$40+110000 -> 551159 | H7: =G7-F7 -> 52027.833 | I7: 24th June 2024 | J7: =19+(7/30) -> 19.233333 | K7: =H7*J7 -> 1000668.7
A8: 3 | B8: Charity Ezenwajiobi | C8: DD&G | D8: '8/12 | E8: 9/7 | F8: 415930.58 | G8: =330408.083333333+100000 -> 430408.08 | H8: =G8-F8 -> 14477.5 | I8: 1st June 2025 | J8: 8 | K8: =H8*J8 -> 115820
A9: 4 | B9: Sunday Adeyi | C9: Admin & HR | D9: '5/12 | E9: 7/5 | F9: 176217.75 | G9: 252750.58 | H9: =G9-F9 -> 76532.833 | I9: 28th Oct 2025 | J9: =3+(4/31) -> 3.1290323 | K9: =H9*J9 -> 239473.7
B10: TOTAL | H10: =SUM(H6:H6) -> 10183.917 | K10: =SUM(K6:K9) -> 1370088.4

Sheet Sheet20

Sheet 2026 ENHANCED WELFARE
A1: NATIONAL INSTITUTE FOR LEGISLATIVE AND DEMOCRATIC STUDIES
A2: STAFF ENHANCED WELFARE SCHEDULE 2026
B4: STAFF NAME | C4: DESIGNATION | D4: GRADE LEVEL | E4: AMOUNT | F4: Grade Level 01 - 13 | G4: Grade Level 14 - 17
E5: N | F5: N | G5: N
A6: S/N | B6: DG'S OFFICE
A7: 1 | B7: PROF. ABUBAKAR O. SULAIMAN | C7: DIRECTOR GENERAL | D7: CONSOL | E7: 2000000 | G7: =E7 -> 2000000
A8: 2 | B8: RAHEEM USMAN AYIGORO | C8: SA-INFRASTRUCTURE | D8: 16 (9) | E8: 700000 | G8: =E8 -> 700000
A9: 3 | B9: MARIAM MOHAMMED BELLO | C9: SA- SPECIAL DUTIES | D9: 16 (9) | E9: 700000 | G9: =E9 -> 700000
A10: 4 | B10: DR IKEME ARTHUR J.O | C10: DEPUTY DIRECTOR, M&E | D10: 16 (9) | E10: 700000 | G10: =E10 -> 700000
A11: 5 | B11: ANDRAWUS MUSA | C11: DEP. DIRECTOR, STORES & PROCUREMENT | D11: 16(9) | E11: 700000 | G11: =E11 -> 700000
A12: 6 | B12: DR FRANCIS NDUM OJIE | C12: AD, TRAINING & IC./SA TO DG | D12: 15(9) | E12: 700000 | G12: =E12 -> 700000
A13: 7 | B13: ALI ABDULLAHI | C13: ASST DIRECTOR ICT | D13: 15(7) | E13: 700000 | G13: =E13 -> 700000
A14: 8 | B14: EMILY EKHIDE | C14: SENIOR RESEARCH FELLOW | D14: 15(9) | E14: 700000 | G14: =E14 -> 700000
A15: 9 | B15: DORIS DAKDA AARON | C15: RESEARCH FELLOW I | D15: 14(10) | E15: 500000 | G15: =E15 -> 500000
A16: 10 | B16: ABDULSALAM S. MUSTAPHA | C16: ASST. DIRECTOR ICT | D16: 15(8) | E16: 500000 | G16: =E16 -> 500000
A17: 11 | B17: PERCY TERFA GBAHABO | C17: RESEARCH FELLOW 1 | D17: 14(8) | E17: 500000 | G17: =E17 -> 500000
A18: 12 | B18: HASSANA AHMED IBRAHIM | C18: PA- TO DG | D18: 13(11) | E18: 500000 | F18: =E18 -> 500000
A19: 13 | B19: IKIP LEBO | C19: ASST CHIEF PROC. OFFICER | D19: 13 (9) | E19: 500000 | F19: =E19 -> 500000
A20: 14 | B20: ALABI ADESINA MUHYDEEN | C20: HEAD, NILDS LIAISON OFFICE | D20: 13 (9) | E20: 500000 | F20: =E20 -> 500000
A21: 15 | B21: BASSEY NSONGURUA UDOFIA | C21: PRINC.CONF SEC 1/PPS | D21: 13(8) | E21: 500000 | F21: =E21 -> 500000
A22: 16 | B22: ADUGBA RICHARD TERSEER | C22: ASSIST. CHIEF INFO OFFICER | D22: 13(7) | E22: 500000 | F22: =E22 -> 500000
A23: 17 | B23: LUCKY AGWOM | C23: RESEARCH ASSISTANT | D23: 12(9) | E23: 400000 | F23: =E23 -> 400000
A24: 18 | B24: IDRIS IBRAHIM | C24: PRINCIPAL RESEARCH OFFICER | D24: 12(9) | E24: 400000 | F24: =E24 -> 400000
A25: 19 | B25: FARUQ ATOFARATI | C25: PA (SPECIAL DUTIES) TO DG | D25: 10(8) | E25: 300000 | F25: =E25 -> 300000
A26: 20 | B26: RASHEEDAT DAIBU | C26: SENIOR INFO. OFFICER | D26: 10(9) | E26: 300000 | F26: =E26 -> 300000
A27: 21 | B27: VICTOR ASUKWO | C27: SENIOR ICT OFFICER | D27: 10(7) | E27: 300000 | F27: =E27 -> 300000
A28: 22 | B28: NNANDI LIVINUS ATURE | C28: SENIOR RESEARCH OFFICER | D28: 10(8) | E28: 300000 | F28: =E28 -> 300000
A29: 23 | B29: ABDULRAHMAN A SULAIMAN | C29: STORE OFFICER | D29: 9(10) | E29: 300000 | F29: =E29 -> 300000
... A46: 40 | B46: ALIYU GARBA LERE | C46: ASSIST INFORMATION OFFICER | D46: 8(8) | E46: 300000 | F46: =E46 -> 300000
B47: TOTAL | C47: 40 | E47: =SUM(E7:E46) -> 18300000 | F47: =SUM(F7:F46) -> 9900000 | G47: =SUM(G7:G46) -> 8400000
B49: INTERNAL AUDIT
A50: 1 | B50: OSANAIYE DAVID AKINYEMI | C50: DIRECTOR INTERNAL AUDIT | D50: 17(9) | E50: 1000000 | G50: =E50 -> 1000000
A51: 2 | B51: EVELYN ETONKE AGAN | C51: ASST DIR AUDIT | D51: 15(8) | E51: 700000 | G51: =E51 -> 700000
A52: 3 | B52: JAMILA ABDUL | C52: SENIOR INTERNAL AUDITOR | D52: 10(9) | E52: 300000 | F52: =E52 -> 300000
A53: 4 | B53: IJEOMA EWELUKWA | C53: PRINCIPAL AUDIT OFFICER | D53: 12(8) | E53: 400000 | F53: =E53 -> 400000
A54: 5 | B54: HASSAN ABDULHADI | C54: SENIOR INTERNAL AUDITOR | D54: 9(8) | E54: 300000 | F54: =E54 -> 300000
A55: 6 | B55: YUSUF YUSUF DAYYABU | C55: INERNAL AUDIT OFFICER | D55: 9(9) | E55: 300000 | F55: =E55 -> 300000
A56: 7 | B56: UDONSI QUEENETH CHIWENDU | C56: ASSIST PROGRAMME OFFICER | D56: 8(8) | E56: 300000 | F56: =E56 -> 300000
C57: 7 | E57: =SUM(E50:E56) -> 3300000 | F57: =SUM(F50:F56) -> 1600000 | G57: =SUM(G50:G56) -> 1700000
B59: LEG. SUPPORT SEVICES
...

Sheet Sheet19

Sheet New Steps, Pensions & NHF
A1: NATIONAL INSTITUTE FOR LEGISLATIVE AND DEMOCRATIC STUDIES
A2: STAFF PAYROLL FOR THE MONTH OF JANUARY 2026
E3: ='[1]FEB 08'!E11/'[1]FEB 08'!M11 -> #REF!
B4: STAFF NAME | C4: DESIGNATION | D4: OLD GRADE LEVEL | E4: OLD BASIC SALARY | F4: NEW GRADE LEVEL | G4: NEW BASIC SALARY | H4: CHANGE IN STEPS (GROSS) | I4: OLD EMPLOYEE PENSIONS | J4: NEW EMPLOYEE PENSIONS | K4: CHANGES IN PENSIONS | L4: NEW ANNUAL PENSIONS | M4: NEW GRADE LEVEL | N4: NEW BASIC | O4: NHF 2.5% | P4: OLD NHF DED. | Q4: INCREASE IN NHF | R4: NHF ANNUAL
E5: N | G5: N | H5: N | I5: N | J5: N | K5: N | L5: N | P5: N
A6: S/N | B6: DG'S OFFICE
A7: 1 | B7: PROF. ABUBAKAR O. SULAIMAN | C7: DIRECTOR GENERAL | D7: CONSOL | E7: 1971137.1 | F7: CONSOL | G7: 1971137.1 | H7: =G7-E7 -> 0 | I7: 0 | K7: =J7-I7 -> 0 | L7: =J7*12 -> 0 | M7: CONSOL | O7: =N7*0.025 -> 0
A8: 2 | B8: RAHEEM USMAN AYIGORO | C8: SA-INFRASTRUCTURE | D8: 16 (9) | E8: 905306.75 | F8: 16 (9) | G8: 905306.75 | H8: =G8-E8 -> 0 | I8: 72424.54 | J8: =G8*0.08 -> 72424.54 | K8: =J8-I8 -> 0 | L8: =J8*12 -> 869094.48 | M8: 16 (9) | N8: 554669.5 | Q8: =O8-P8 -> 0 | R8: =O8*12 -> 0
A9: 3 | B9: MARIAM MOHAMMED BELLO | C9: SA- SPECIAL DUTIES | D9: 16 (9) | E9: 905306.75 | F9: 16 (9) | G9: 905306.75 | H9: =G9-E9 -> 0 | K9: =J9-I9 -> 0 | L9: =J9*12 -> 0 | M9: 16 (9) | O9: =N9*0.025 -> 0 | Q9: =O9-P9 -> 0 | R9: =O9*12 -> 0
A10: 4 | B10: DR IKEME ARTHUR J.O | C10: DEPUTY DIRECTOR, M&E | D10: 16 (9) | E10: 905306.75 | F10: 16 (9) | G10: 905306.75 | H10: =G10-E10 -> 0 | I10: 72424.54 | J10: =G10*0.08 -> 72424.54 | K10: =J10-I10 -> 0 | L10: =J10*12 -> 869094.48 | M10: 16 (9) | N10: 554669.5 | O10: =N10*0.025 -> 13866.737 | P10: 13866.737 | Q10: =O10-P10 -> 0 | R10: =O10*12 -> 166400.85
A11: 5 | B11: ANDRAWUS MUSA | C11: DEP. DIRECTOR, STORES & PROCUREMENT | D11: 16(8) | E11: 879008.92 | F11: 16(9) | G11: 905306.75 | H11: =G11-E11 -> 26297.833 | I11: 68216.887 | J11: =G11*0.08 -> 72424.54 | K11: =J11-I11 -> 4207.6533 | L11: =J11*12 -> 869094.48 | M11: 16(9) | N11: 554669.5 | O11: =N11*0.025 -> 13866.737 | P11: 13084.663 | Q11: =O11-P11 -> 782.075 | R11: =O11*12 -> 166400.85
A12: 6 | B12: DR FRANCIS NDUM OJIE | C12: AD, TRAINING & IC./SA TO DG | D12: 15(8) | E12: 722595.5 | F12: 15(9) | G12: 744477 | H12: =G12-E12 -> 21881.5 | I12: 57807.64 | J12: =G12*0.08 -> 59558.16 | K12: =J12-I12 -> 1750.52 | L12: =J12*12 -> 714697.92 | M12: 15(9) | N12: 459010.5 | O12: =N12*0.025 -> 11475.263 | P12: 11149.896 | Q12: =O12-P12 -> 325.36667 | R12: =O12*12 -> 137703.15
A13: 7 | B13: ALI ABDULLAHI | C13: ASST DIRECTOR ICT | D13: 15(7) | E13: 700713.92 | F13: 15(7) | G13: 700713.92 | H13: =G13-E13 -> 0 | I13: 56057.113 | J13: =G13*0.08 -> 56057.113 | K13: =J13-I13 -> 0 | L13: =J13*12 -> 672685.36 | M13: 15(7) | N13: 432981.08 | Q13: =O13-P13 -> 0 | R13: =O13*12 -> 0
A14: 8 | B14: EMILY EKHIDE | C14: SENIOR RESEARCH FELLOW | D14: 15(8) | E14: 722595.5 | F14: 15(9) | G14: 744477 | H14: =G14-E14 -> 21881.5 | I14: 57807.64 | J14: =G14*0.08 -> 59558.16 | K14: =J14-I14 -> 1750.52 | L14: =J14*12 -> 714697.92 | M14: 15(9) | N14: 459010.5 | Q14: =O14-P14 -> 0 | R14: =O14*12 -> 0
A15: 9 | B15: DORIS DAKDA AARON | C15: RESEARCH FELLOW I | D15: 14(9) | E15: 558165.25 | F15: 14(10) | G15: 573911.08 | H15: =G15-E15 -> 15745.833 | I15: 44653.22 | J15: =G15*0.08 -> 45912.887 | K15: =J15-I15 -> 1259.6667 | L15: =J15*12 -> 550954.64 | M15: 14(10) | N15: 357066.67 | O15: =N15*0.025 -> 8926.6667 | P15: 8692.8979 | Q15: =O15-P15 -> 233.76875 | R15: =O15*12 -> 107120
A16: 10 | B16: ABDULSALAM S. MUSTAPHA | C16: ASST. DIRECTOR ICT | D16: 15(7) | E16: 700713.92 | F16: 15(8) | G16: 722595.5 | H16: =G16-E16 -> 21881.583 | I16: 56057.113 | J16: =G16*0.08 -> 57807.64 | K16: =J16-I16 -> 1750.5267 | L16: =J16*12 -> 693691.68 | M16: 15(8) | N16: 445995.83 | Q16: =O16-P16 -> 0 | R16: =O16*12 -> 0
A17: 11 | B17: PERCY TERFA GBAHABO | C17: RESEARCH FELLOW 1 | D17: 14(7) | E17: 542419.5 | F17: 14(8) | G17: ='[2] FGN 2024 MGT Monthly'!$I$42+'[2]Peculiar Allowance'!$I$42 -> 542419.5 | H17: =G17-E17 -> 0 | I17: 42133.887 | J17: =G17*0.08 -> 43393.56 | K17: =J17-I17 -> 1259.6733 | L17: =J17*12 -> 520722.72 | M17: 14(8) | N17: 338365.25 | Q17: =O17-P17 -> 0 | R17: =O17*12 -> 0
A18: 12 | B18: HASSANA AHMED IBRAHIM | C18: PA- TO DG | D18: 13(10) | E18: 526725.08 | F18: 13(11) | G18: ='[2]Peculiar Allowance'!$L$41+'[2] FGN 2024 MGT Monthly'!$L$41 -> 541351.33 | H18: =G18-E18 -> 14626.25 | I18: 42138.007 | J18: =G18*0.08 -> 43308.107 | K18: =J18-I18 -> 1170.1 | L18: =J18*12 -> 519697.28 | M18: 13(11) | N18: 337730.83 | O18: =N18*0.025 -> 8443.2708 | P18: 8226.1229 | Q18: =O18-P18 -> 217.14792 | R18: =O18*12 -> 101319.25
