Workbook

Sheet JANUARY 2024
A1: NATIONAL INSTITUTE FOR LEGISLATIVE AND DEMOCRATIC STUDIES | H1: ='[1]FEB 08'!F8/'[1]FEB 08'!Q8 -> 0.3
A2: STAFF PAYROLL FOR THE MONTH OF JANUARY, 2024
E3: ='[1]FEB 08'!E11/'[1]FEB 08'!M11 -> #REF! | H3: ='[1]FEB 08'!F11/'[1]FEB 08'!Q11 -> #REF!
B4: STAFF NAME | C4: DESIGNATION | D4: GRADE LEVEL | E4: BASIC SALARY | F4: ALLCE/ AREARS | G4: RENT | H4: UTILITY | I4: DOMESTIC | J4: ENTERT. | K4: FURNIT. | L4: FUEL | M4: ALLOWANCE | N4: ALLOWANCE | O4: ALLCE | P4: ALLCE | Q4: DUTY ALLCE | R4: GROSS SALARY | S4: AUCTION | T4: COOP CONTR/SPEC SAVINGS | U4: COOP. LOAN RECOVERY | V4: NHF DED. | W4: PAYE | X4: TOTAL DEDUCTION | Y4: DECEMBER, 2023 | Z4: JANUARY, 2024
E5: N | G5: N | H5: N | I5: N | J5: N | K5: N | L5: N | M5: N | N5: N | O5: N | P5: N | Q5: N | R5: N | S5: N | T5: N | U5: N | V5: N | W5: N | X5: N | Y5: N | Z5: N
A6: S/N | B6: DG'S OFFICE
A7: 1 | B7: PROF. ABUBAKAR O. SULAIMAN | C7: DIRECTOR GENERAL | D7: CONSOL | E7: 160488.75 | G7: 320977.5 | H7: 48146.63 | I7: 120366.57 | J7: 72219.94 | K7: 0 | L7: 120366.57 | M7: =250000 -> 250000 | O7: 16048.88 | P7: 25000 | Q7: 25235 | R7: =Q7+P7+O7+N7+M7+L7+K7+J7+I7+H7+G7+F7+E7 -> 1158849.8 | W7: 201165.84 | X7: =W7+V7+U7+T7+S7 -> 201165.84 | Y7: 957684 | Z7: =R7-X7 -> 957684
A8: 2 | B8: RAHEEM USMAN AYIGORO | C8: SA-INFRASTRUCTURE | D8: 16 (9) | E8: =42653.17 -> 42653.17 | G8: =E8*300% -> 127959.51 | H8: =E8*7.5% -> 3198.9877 | I8: 40122.19 | J8: =E8*50% -> 21326.585 | K8: =E8*350% -> 149286.1 | L8: =E8*100% -> 42653.17 | N8: =90000 -> 90000 | O8: =E8*10% -> 4265.317 | P8: 20000 | Q8: 0 | R8: =Q8+P8+O8+N8+M8+L8+K8+J8+I8+H8+G8+F8+E8 -> 541465.02 | T8: =100000 -> 100000 | W8: 82627.951 | X8: =W8+V8+U8+T8+S8 -> 182627.95 | Y8: 358837.07 | Z8: =R8-X8 -> 358837.07
A9: 3 | B9: MARIAM MOHAMMED BELLO | C9: SA- SPECIAL DUTIES | D9: 16 (9) | E9: =42653.17 -> 42653.17 | G9: =E9*300% -> 127959.51 | H9: =E9*7.5% -> 3198.9877 | I9: 40122.19 | J9: =E9*50% -> 21326.585 | K9: =E9*350% -> 149286.1 | L9: =E9*100% -> 42653.17 | N9: =90000 -> 90000 | O9: =E9*10% -> 4265.317 | P9: 20000 | Q9: =100000+100000 -> 200000 | R9: =Q9+P9+O9+N9+M9+L9+K9+J9+I9+H9+G9+F9+E9 -> 741465.02 | W9: 121027.95 | X9: =W9+V9+U9+T9+S9 -> 121027.95 | Y9: 609350.49 | Z9: =R9-X9 -> 620437.07
A10: 4 | B10: DR IKEME ARTHUR J.O | C10: DEPUTY DIRECTOR, M&E | D10: 16 (9) | E10: =42653.17 -> 42653.17 | G10: =E10*300% -> 127959.51 | H10: =E10*7.5% -> 3198.9877 | I10: 40122.19 | J10: =E10*50% -> 21326.585 | K10: =E10*350% -> 149286.1 | L10: =E10*100% -> 42653.17 | M10: 180000 | O10: =E10*10% -> 4265.317 | P10: 20000 | Q10: 0 | R10: =Q10+P10+O10+N10+M10+L10+K10+J10+I10+H10+G10+F10+E10 -> 631465.02 | T10: =50000 -> 50000 | U10: 103000 | V10: =0.025*E10 -> 1066.3293 | W10: 99703.216 | X10: =W10+V10+U10+T10+S10 -> 253769.55 | Y10: 469602.37 | Z10: =R10-X10 -> 377695.48
A11: 5 | B11: MOSHOOD M. OLALERE | C11: DEPUTY DIR. GENERAL SERVICE | D11: 16 (9) | E11: =42653.17 -> 42653.17 | G11: =E11*300% -> 127959.51 | H11: =E11*7.5% -> 3198.9877 | I11: 40122.19 | J11: =E11*50% -> 21326.585 | K11: =E11*350% -> 149286.1 | L11: =E11*100% -> 42653.17 | N11: =80000+10000 -> 90000 | O11: =E11*10% -> 4265.317 | P11: 20000 | Q11: 150000 | R11: =Q11+P11+O11+N11+M11+L11+K11+J11+I11+H11+G11+F11+E11 -> 691465.02 | T11: =20000+60000 -> 80000 | U11: ='[2]OCTOBER 2023 '!$D$193 -> 230499.8 | V11: =0.025*E11 -> 1066.3293 | W11: 111223.22 | X11: =W11+V11+U11+T11+S11 -> 422789.35 | Y11: 257582.57 | Z11: =R11-X11 -> 268675.68
A12: 6 | B12: REKIYA IBRAHIM ATTAH | C12: DEPUTY DIRECTOR TRAINING | D12: 16 (9) | E12: =42653.17 -> 42653.17 | G12: =E12*300% -> 127959.51 | H12: =E12*7.5% -> 3198.9877 | I12: 40122.19 | J12: =E12*50% -> 21326.585 | K12: =E12*350% -> 149286.1 | L12: =E12*100% -> 42653.17 | N12: =90000 -> 90000 | O12: =E12*10% -> 4265.317 | P12: 20000 | Q12: 100000 | R12: =SUM(E12:Q12) -> 641465.02 | T12: =50000 -> 50000 | U12: =91666.67 -> 91666.67 | W12: 101827.95 | X12: =W12+V12+U12+T12+S12 -> 243494.62 | Y12: 386883.82 | Z12: =R12-X12 -> 397970.4
A13: 7 | B13: ANDRAWUS MUSA | C13: ASST. DIRECTOR, STORES | D13: 15(9) | E13: 33507.5 | G13: =E13*300% -> 100522.5 | H13: =E13*7.5% -> 2513.0625 | I13: =40122.19 -> 40122.19 | J13: =E13*50% -> 16753.75 | K13: =E13*350% -> 117276.25 | L13: =E13*100% -> 33507.5 | N13: =80000 -> 80000 | O13: =E13*10% -> 3350.75 | P13: 20000 | Q13: 50000 | R13: =Q13+P13+O13+N13+M13+L13+K13+J13+I13+H13+G13+F13+E13 -> 497553.5 | T13: =50000-40000 -> 10000 | U13: =90000+110000 -> 200000 | V13: =0.025*E13 -> 837.6875 | W13: 74036.103 | X13: =W13+V13+U13+T13+S13 -> 284873.79 | Y13: 212679.72 | Z13: =R13-X13 -> 212679.71
A14: 8 | B14: DR FRANCIS NDUM OJIE | C14: AD, TRAINING & IC./SA TO DG | D14: 15(7) | E14: 31019.84 | G14: =E14*300% -> 93059.52 | H14: =E14*7.5% -> 2326.488 | I14: =40122.19 -> 40122.19 | J14: =E14*50% -> 15509.92 | K14: =E14*350% -> 108569.44 | L14: =E14*100% -> 31019.84 | M14: 160000 | O14: =E14*10% -> 3101.984 | P14: 20000 | Q14: =100000 -> 100000 | R14: =SUM(E14:Q14) -> 604729.22 | V14: =0.025*E14 -> 775.496 | W14: 94625.782 | X14: =W14+V14+U14+T14+S14 -> 95401.278 | Y14: 509246.91 | Z14: =R14-X14 -> 509327.94
A15: 9 | B15: ALI ABDULLAHI | C15: CHIEF ICT OFFICER | D15: 14(11) | E15: 27611.23 | G15: =E15*300% -> 82833.69 | H15: =E15*7.5% -> 2070.8422 | I15: 0 | J15: =E15*50% -> 13805.615 | K15: =E15*350% -> 96639.305 | L15: =E15*100% -> 27611.23 | N15: =70000 -> 70000 | O15: =E15*10% -> 2761.123 | P15: 20000 | Q15: =0 -> 0 | R15: =Q15+P15+O15+N15+M15+L15+K15+J15+I15+H15+G15+F15+E15 -> 343333.04 | W15: 44846.617 | X15: =W15+V15+U15+T15+S15 -> 44846.617 | Y15: 298486.42 | Z15: =R15-X15 -> 298486.42
A16: 10 | B16: EMILY EKHIDE | C16: RESEARCH FELLOW 1 | D16: 14(10) | E16: 27611.23 | G16: =E16*300% -> 82833.69 | H16: =E16*7.5% -> 2070.8422 | I16: 0 | J16: =E16*50% -> 13805.615 | K16: =E16*350% -> 96639.305 | L16: =E16*100% -> 27611.23 | M16: 140000 | O16: =E16*10% -> 2761.123 | P16: 20000 | Q16: 50000 | R16: =SUM(E16:Q16) -> 463333.04 | T16: =50000 -> 50000 | W16: 46666.667 | X16: =W16+V16+U16+T16+S16 -> 96666.667 | Y16: 339193.16 | Z16: =R16-X16 -> 366666.37
A17: 11 | B17: DORIS DAKDA AARON | C17: RESEARCH FELLOW I | D17: 14(8) | E17: ='[3]December 2022'!$E$126 -> 25854.1 | G17: =E17*300% -> 77562.3 | H17: =E17*7.5% -> 1939.0575 | J17: =E17*50% -> 12927.05 | K17: =E17*350% -> 90489.35 | L17: =E17*100% -> 25854.1 | M17: =140000 -> 140000 | O17: =E17*10% -> 2585.41 | P17: 20000 | Q17: 150000 | R17: =SUM(E17:Q17) -> 547211.37 | T17: 70000 | W17: 46666.667 | X17: =W17+V17+U17+T17+S17 -> 116666.67 | Y17: 321708.62 | Z17: =R17-X17 -> 430544.7
A18: 12 | B18: ABDULSALAM S. MUSTAPHA | C18: ASST. MANAGER ICT | D18: 13(11) | E18: 26339.3 | G18: =E18*300% -> 79017.9 | H18: =E18*7.5% -> 1975.4475 | I18: 0 | J18: =E18*50% -> 13169.65 | K18: =E18*350% -> 92187.55 | L18: =E18*100% -> 26339.3 | N18: 70000 | O18: =E18*10% -> 2633.93 | P18: 15000 | R18: =SUM(E18:Q18) -> 326663.08 | W18: 42046.064 | X18: =42046.06 -> 42046.06 | Y18: 284617.02 | Z18: =R18-X18 -> 284617.02
A19: 13 | B19: PERCY TERFA GBAHABO | C19: HEAD, NILDS LIAISON OFFICE | D19: 13(10) | E19: =25523.45 -> 25523.45 | G19: =E19*300% -> 76570.35 | H19: =E19*7.5% -> 1914.2587 | I19: 0 | J19: =E19*50% -> 12761.725 | K19: =E19*350% -> 89332.075 | L19: =E19*100% -> 25523.45 | M19: =120000 -> 120000 | O19: =E19*10% -> 2552.345 | P19: 15000 | Q19: 0 | R19: =Q19+P19+O19+N19+M19+L19+K19+J19+I19+H19+G19+F19+E19 -> 369177.65 | T19: =50000 -> 50000 | U19: 0 | W19: 46666.667 | X19: =W19+V19+U19+T19+S19 -> 96666.667 | Y19: 265334.39 | Z19: =R19-X19 -> 272510.99
A20: 14 | B20: HASSANA AHMED IBRAHIM | C20: PA- TO DG | D20: 13 (9) | E20: 24741.26 | G20: =E20*300% -> 74223.78 | H20: =E20*7.5% -> 1855.5945 | J20: =E20*50% -> 12370.63 | K20: =E20*350% -> 86594.41 | L20: =E20*100% -> 24741.26 | M20: =120000 -> 120000 | O20: =E20*10% -> 2474.126 | P20: 15000 | Q20: =100000 -> 100000 | R20: =Q20+P20+O20+N20+M20+L20+K20+J20+I20+H20+G20+F20+E20 -> 462001.06 | T20: =30000-20000 -> 10000 | U20: =95833.33 -> 95833.33 | V20: =0.025*E20 -> 618.5315 | W20: 46666.667 | X20: =W20+V20+U20+T20+S20 -> 153118.53 | Y20: 281897.16 | Z20: =R20-X20 -> 308882.53
A21: 15 | B21: ADUGBA RICHARD TERSEER | C21: PRINCIPAL INFO. OFFICER | D21: 12(9) | E21: =22837.82 -> 22837.82 | G21: =E21*300% -> 68513.46 | H21: =E21*7.5% -> 1712.8365 | J21: =E21*50% -> 11418.91 | K21: =E21*350% -> 79932.37 | L21: =E21*100% -> 22837.82 | N21: =60000 -> 60000 | O21: =E21*10% -> 2283.782 | P21: 15000 | Q21: 100000 | R21: =Q21+P21+O21+N21+M21+L21+K21+J21+I21+H21+G21+F21+E21 -> 384537 | T21: =20000 -> 20000 | U21: =111833.33 -> 111833.33 | W21: 52497.77 | X21: =W21+V21+U21+T21+S21 -> 184331.1 | Y21: 193954.07 | Z21: =R21-X21 -> 200205.9
A22: 16 | B22: LUCKY AGWOM | C22: RESEARCH ASSISTANT | D22: 12(7) | E22: =20749 -> 20749 | G22: =E22*300% -> 62247 | H22: =E22*7.5% -> 1556.175 | J22: =E22*50% -> 10374.5 | K22: =E22*350% -> 72621.5 | L22: =E22*100% -> 20749 | M22: =100000 -> 100000 | O22: =E22*10% -> 2074.9 | P22: 10000 | Q22: 100000 | R22: =SUM(E22:Q22) -> 400372.08 | T22: 52000 | W22: 46666.667 | X22: =W22+V22+U22+T22+S22 -> 98666.667 | Y22: 344833.97 | Z22: =R22-X22 -> 301705.41
A23: 17 | B23: IDRIS IBRAHIM | C23: PRINCIPAL RESEARCH OFFICER | D23: 12(7) | E23: 20749 | F23: =700000 -> 700000 | G23: 62247 | H23: 1556.175 | I23: 0 | J23: 10374.5 | K23: 72621.5 | L23: 20749 | M23: 110000 | O23: 2074.9 | P23: 15000 | Q23: 0 | R23: =SUM(E23:Q23) -> 1015372.1 | T23: 0 | W23: 46666.667 | X23: =W23+V23+U23+T23+S23 -> 46666.667 | Z23: =R23-X23 -> 968705.41
A24: 18 | B24: FARUQ ATOFARATI | C24: PA (SPECIAL DUTIES) TO DG | D24: 10(7) | E24: =17286.33 -> 17286.33 | G24: =E24*300% -> 51858.99 | H24: =E24*7.5% -> 1296.4748 | J24: =E24*50% -> 8643.165 | K24: =E24*350% -> 60502.155 | L24: =E24*100% -> 17286.33 | N24: =50000+10000 -> 60000 | O24: =E24*10% -> 1728.633 | P24: 10000 | Q24: 100000 | R24: =SUM(E24:Q24) -> 328602.08 | W24: 42371.816 | X24: =W24+V24+U24+T24+S24 -> 42371.816 | Y24: 286230.26 | Z24: =R24-X24 -> 286230.26
A25: 19 | B25: ELIZABETH OGECHUKWU ONYEAKU | C25: ICT OFFICER | D25: 9(9) | E25: 15641.2 | G25: =E25*300% -> 46923.6 | H25: =E25*7.5% -> 1173.09 | J25: =E25*50% -> 7820.6 | K25: =E25*350% -> 54744.2 | L25: =E25*100% -> 15641.2 | N25: =50000+10000 -> 60000 | O25: =E25*10% -> 1564.12 | P25: 10000 | R25: =Q25+P25+O25+N25+M25+L25+K25+J25+I25+H25+G25+F25+E25 -> 213508.01 | T25: 10000 | U25: =20000 -> 20000 | W25: 23036.012 | X25: =W25+V25+U25+T25+S25 -> 53036.012 | Y25: 153563.13 | Z25: =R25-X25 -> 160472
A26: 20 | B26: VICTOR ASUKWO | C26: ICT OFFICER | D26: 9(9) | E26: 15641.2 | G26: =E26*300% -> 46923.6 | H26: =E26*7.5% -> 1173.09 | J26: =E26*50% -> 7820.6 | K26: =E26*350% -> 54744.2 | L26: =E26*100% -> 15641.2 | N26: =50000+10000 -> 60000 | O26: =E26*10% -> 1564.12 | P26: 10000 | R26: =Q26+P26+O26+N26+M26+L26+K26+J26+I26+H26+G26+F26+E26 -> 213508.01 | W26: 23036.012 | X26: =W26+V26+U26+T26+S26 -> 23036.012 | Y26: 187017.56 | Z26: =R26-X26 -> 190472
A27: 21 | B27: NNANDI LIVINUS ATURE | C27: RESEARCH ASSISTANT | D27: 9(9) | E27: 15641.2 | G27: =E27*300% -> 46923.6 | H27: =E27*7.5% -> 1173.09 | J27: =E27*50% -> 7820.6 | K27: =E27*350% -> 54744.2 | L27: =E27*100% -> 15641.2 | M27: =100000 -> 100000 | O27: =E27*10% -> 1564.12 | P27: 10000 | R27: =SUM(E27:Q27) -> 253508.01 | T27: =10000 -> 10000 | U27: =95833.33 -> 95833.33 | W27: 29756.012 | X27: =W27+V27+U27+T27+S27 -> 135589.34 | Y27: 114464.23 | Z27: =R27-X27 -> 117918.67
A28: 22 | B28: ABDULRAHMAN A SULAIMAN | C28: STORE OFFICER | D28: 9(8) | E28: =15188.67 -> 15188.67 | G28: =E28*300% -> 45566.01 | H28: =E28*7.5% -> 1139.1502 | J28: =E28*50% -> 7594.335 | K28: =E28*350% -> 53160.345 | L28: =E28*100% -> 15188.67 | N28: =60000 -> 60000 | O28: =E28*10% -> 1518.867 | P28: 10000 | R28: =SUM(E28:Q28) -> 209356.05 | T28: =20000 -> 20000 | U28: =17500 -> 17500 | W28: 22338.483 | X28: =W28+V28+U28+T28+S28 -> 59838.483 | Y28: 146063.2 | Z28: =R28-X28 -> 149517.56
A29: 23 | B29: DARE SHEU MAGBON | C29: ADMINISTRATION OFFICER | D29: 9(7) | E29: =14736.14 -> 14736.14 | G29: =E29*300% -> 44208.42 | H29: =E29*7.5% -> 1105.2105 | J29: =E29*50% -> 7368.07 | K29: =E29*350% -> 51576.49 | L29: =E29*100% -> 14736.14 | N29: =60000 -> 60000 | O29: =E29*10% -> 1473.614 | P29: 10000 | R29: =SUM(E29:Q29) -> 205204.08 | T29: =30000+20000 -> 50000 | U29: 0 | W29: 21640.953 | X29: =W29+V29+U29+T29+S29 -> 71640.953 | Y29: 138329.89 | Z29: =R29-X29 -> 133563.13
A30: 24 | B30: ABUBAKAR SULAIMAN SODEEQ | C30: ADMINISTRATION OFFICER | D30: 9(7) | E30: =14736.14 -> 14736.14 | G30: =E30*300% -> 44208.42 | H30: =E30*7.5% -> 1105.2105 | J30: =E30*50% -> 7368.07 | K30: =E30*350% -> 51576.49 | L30: =E30*100% -> 14736.14 | N30: =60000 -> 60000 | O30: =E30*10% -> 1473.614 | P30: 10000 | R30: =SUM(E30:Q30) -> 205204.08 | U30: 0 | W30: 21640.953 | X30: =W30+V30+U30+T30+S30 -> 21640.953 | Y30: 159773.23 | Z30: =R30-X30 -> 183563.13
A31: 25 | B31: JIMOH ADEBAYO ZAKA | C31: ASST. OFFICER/COMM | D31: 9(8) | E31: 15188.67 | G31: =E31*300% -> 45566.01 | H31: =E31*7.5% -> 1139.1502 | J31: =E31*50% -> 7594.335 | K31: =E31*350% -> 53160.345 | L31: =E31*100% -> 15188.67 | N31: =60000 -> 60000 | O31: =E31*10% -> 1518.867 | P31: 10000 | R31: =Q31+P31+O31+N31+M31+L31+K31+J31+I31+H31+G31+F31+E31 -> 209356.05 | T31: =50000 -> 50000 | U31: 50000 | W31: 22338.483 | X31: =W31+V31+U31+T31+S31 -> 122338.48 | Y31: 87017.565 | Z31: =R31-X31 -> 87017.565
A32: 26 | B32: MOHAMMED BELLO | C32: PROTOCOL ASSISTANT | D32: 8(9) | E32: 13112.16 | G32: =E32*300% -> 39336.48 | H32: =E32*7.5% -> 983.412 | J32: =E32*50% -> 6556.08 | K32: =E32*350% -> 45892.56 | L32: =E32*100% -> 13112.16 | N32: =50000 -> 50000 | O32: =E32*10% -> 1311.216 | P32: 10000 | R32: =SUM(E32:Q32) -> 180304.07 | T32: =0 -> 0 | U32: =26666.67 -> 26666.67 | W32: 17572.885 | X32: =W32+V32+U32+T32+S32 -> 44239.555 | Y32: 133106.72 | Z32: =R32-X32 -> 136064.51
A33: 27 | B33: HARUNA JIBRIL AMEH | C33: ASST. ADMIN. OFFICER | D33: 8(8) | E33: =12732 -> 12732 | G33: 37055.82 | H33: 926.3955 | J33: 6175.97 | K33: 43231.79 | L33: 12351.94 | N33: 50000 | O33: 1235.194 | P33: 10000 | R33: 173329.05 | T33: 20000 | U33: 0 | W33: 16512.682 | X33: =W33+V33+U33+T33+S33 -> 36512.682 | Y33: 136816.37 | Z33: =R33-X33 -> 136816.37
B34: TOTAL | C34: 27 | E34: =SUM(E7:E33) -> 810202.04 | F34: =SUM(F7:F33) -> 700000 | G34: =SUM(G7:G33) -> 2268977.2 | H34: =SUM(H7:H33) -> 96846.622 | I34: =SUM(I7:I33) -> 401221.9 | J34: =SUM(J7:J33) -> 396886.55 | K34: =SUM(K7:K33) -> 2272666.3 | L34: =SUM(L7:L33) -> 769699.8 | ... X34: =SUM(X7:X33) -> 3295070.2 | Y34: 7198101.1 | Z34: =SUM(Z7:Z33) -> 8717267.3
B36: INTERNAL AUDIT
A37: 1 | B37: OSANAIYE DAVID AKINYEMI | C37: DIRECTOR INTERNAL AUDIT | D37: 17(9) | E37: 81740.02 | G37: =E37*300% -> 245220.06 | H37: =E37*7.5% -> 6130.5015 | I37: 80244.38 | J37: =E37*50% -> 40870.01 | K37: =E37*350% -> 286090.07 | L37: =E37*100% -> 81740.02 | N37: =100000 -> 100000 | O37: =E37*10% -> 8174.002 | P37: 20000 | R37: =SUM(E37:Q37) -> 950209.06 | S37: ='JANUARY 2024'!F196 -> 0 | T37: 200000 | U37: 0 | W37: 161106.81 | X37: =W37+V37+U37+T37+S37 -> 361106.81 | Y37: 689102.26 | Z37: =R37-X37 -> 589102.26
A38: 2 | B38: JAMILA ABDUL | C38: AUDITOR II | D38: 8(8) | E38: =12732 -> 12732 | G38: =E38*300% -> 38196 | H38: =E38*7.5% -> 954.9 | J38: =E38*50% -> 6366 | K38: =E38*350% -> 44562 | L38: =E38*100% -> 12732 | N38: =50000 -> 50000 | O38: =E38*10% -> 1273.2 | P38: 10000 | R38: =(Q38+P38+O38+N38+M38+L38+K38+J38+I38+H38+G38+F38+E38) -> 176816.1 | T38: =20000 -> 20000 | V38: 0 | W38: 17042.714 | X38: =W38+V38+U38+T38+S38 -> 37042.714 | Y38: 136816.37 | Z38: =R38-X38 -> 139773.39
A39: 3 | B39: IJEOMA EWELUKWA | C39: AUDIT OFFICER | D39: 10(8) | E39: 17784.1 | G39: =E39*300% -> 53352.3 | H39: =E39*7.5% -> 1333.8075 | J39: =E39*50% -> 8892.05 | K39: =E39*350% -> 62244.35 | L39: =E39*100% -> 17784.1 | N39: =50000+10000 -> 60000 | O39: =E39*10% -> 1778.41 | P39: 10000 | R39: =SUM(E39:Q39) -> 233169.12 | T39: =10000 -> 10000 | W39: 26339.078 | X39: =W39+V39+U39+T39+S39 -> 36339.078 | Y39: 193030.35 | Z39: =R39-X39 -> 196830.04
C40: 3 | E40: =SUM(E37:E39) -> 112256.12 | F40: =SUM(F37:F39) -> 0 | G40: =SUM(G37:G39) -> 336768.36 | H40: =SUM(H37:H39) -> 8419.209 | I40: =SUM(I37:I39) -> 80244.38 | J40: =SUM(J37:J39) -> 56128.06 | K40: =SUM(K37:K39) -> 392896.42 | L40: =SUM(L37:L39) -> 112256.12 | ... X40: =SUM(X37:X39) -> 434488.6 | Y40: 1018949 | Z40: =SUM(Z37:Z39) -> 925705.68
B42: LEG. SUPPORT SEVICES
...

Sheet Sheet4
A1: S/N | B1: DG'S OFFICE
A2: 1 | B2: PROF. ABUBAKAR O. SULAIMAN | C2: DIRECTOR GENERAL | D2: CONSOL
A3: 2 | B3: RAHEEM USMAN AYIGORO | C3: SA-INFRASTRUCTURE | D3: 16 (9)
A4: 3 | B4: MARIAM MOHAMMED BELLO | C4: SA- SPECIAL DUTIES | D4: 16(8)
A5: 4 | B5: DR IKEME ARTHUR J.O | C5: DEPUTY DIRECTOR, M&E | D5: 16(8)
A6: 5 | B6: MOSHOOD M. OLALERE | C6: DEPUTY DIR. GENERAL SERVICE | D6: 16(8)
A7: 6 | B7: REKIYA IBRAHIM ATTAH | C7: DEPUTY DIRECTOR TRAINING | D7: 16(8)
A8: 7 | B8: ANDRAWUS MUSA | C8: ASST. DIRECTOR, STORES | D8: 15(9)
A9: 8 | B9: DR FRANCIS NDUM OJIE | C9: AD, TRAINING & IC./SA TO DG | D9: 15(7)
A10: 9 | B10: ALI ABDULLAHI | C10: CHIEF ICT OFFICER | D10: 14(10)
A11: 10 | B11: EMILY EKHIDE | C11: RESEARCH FELLOW 1 | D11: 14(9)
A12: 11 | B12: ABDULSALAM S. MUSTAPHA | C12: ASST. MANAGER ICT | D12: 13(11)
A13: 12 | B13: PERCY TERFA GBAHABO | C13: HEAD, NILDS LIAISON OFFICE | D13: 13(9)
... A25: 24 | B25: HARUNA JIBRIL AMEH | C25: ASST. ADMIN. OFFICER | D25: 8(7)
B26: TOTAL | C26: 24
B28: INTERNAL AUDIT
A29: 1 | B29: OSANAIYE DAVID AKINYEMI | C29: DIRECTOR INTERNAL AUDIT | D29: 17(9)
A30: 2 | B30: JAMILA ABDUL | C30: AUDITOR II | D30: 8(7)
A31: 3 | B31: IJEOMA EWELUKWA | C31: AUDIT OFFICER | D31: 10(7)
C32: 3
B34: LEG. SUPPORT SEVICES
A35: 1 | B35: PROF. EDOBA BRIGHT OMOREGBE | C35: AG. DLSS | D35: 17(9)
A36: 2 | B36: DR CLINTON JAJA | C36: SENIOR RESEARCH FELLOW | D36: 15(9)
A37: 3 | B37: BETHEL UZOMA IHUGBA | C37: DEPUTY DIRECTOR, LEGAL RESEARCH | D37: 16(7)
A38: 4 | B38: OGUCHE SAMUEL | C38: SNR RESEARCH FELLOW | D38: 15(9)
A39: 5 | B39: IBRAHIM USMAN | C39: SNR RESEARCH FELLOW | D39: 15(8)
A40: 6 | B40: DR MOHAMMED O. AMALI | C40: SNR RESEARCH FELLOW | D40: 15(7)
A41: 7 | B41: YAHAYA SHAMSU | C41: RESEARCH FELLOW 1 | D41: 14(10)
A42: 8 | B42: DORIS DAKDA AARON | C42: RESEARCH FELLOW I | D42: 14(8)
A43: 9 | B43: BILKIS S. LAWAL-GAMBARI | C43: RESEARCH OFFICER | D43: 10(7)
A44: 10 | B44: ZAINAB AKINDE | C44: RESEARCH OFFICER | D44: 9(7)
A45: 11 | B45: ABDULLAHI AHMAD USMAN | C45: RESEARCH OFFICER | D45: 9(7)
A46: 12 | B46: GUNAT NANSAK MARK | C46: RESEARCH OFFICER | D46: 9(7)
B47: TOTAL | C47: 12
B49: LEGAL SERVICES
A50: 1 | B50: DR SHUIBU DANWANKA | C50: DIRECTOR LEGAL SERVICES | D50: 17(9)
A51: 2 | B51: ABDULSALAM BAKO | C51: MANAGER, LEGAL SERVICES | D51: 15 (8)
B52: TOTAL | C52: 2
B54: DEMOCRACY & GOVERNANCE
A55: 1 | B55: DR. ADEWALE ADEREMI | C55: DIRECTOR, DEMOCRATIC STUDIES | D55: 17(9)
...

Sheet MEMO 1
A2: NATIONAL INSTITUTE FOR LEGISLATIVE AND DEMOCRATIC STUDIES
A3: INTERNAL MEMO
A4: FROM : DEPUTY DIRECTOR, FINANCE AND ACCOUNTS
A5: THRU: DIRECTOR, FINANCE AND ACCOUNTS
A6: TO: DG
A7: 29TH JANUARY , 2021
A9: SUBJECT: PAYROLL FOR THE MONTH OF JANUARY, 2021
A10: Find below the details of NILDS Staff Payroll for the month of January, 2021
A13: TO: | C13: DIRECTOR, GENERAL
A14: THRU: | C14: DIRECTOR, FINANCE AND ACCOUNT
A15: FROM: | C15: DEPUTY DIRECTOR, FINANCE AND ACCOUNTS
A16: DATE: | C16: 30TH JANUARY 2024
A18: SUBJECT: PAYROLL FOR THE MONTH OF JANUARY 2024
A19: Find below the details of NILDS Staff Payroll for the Month of January 2024: | G19: NGN | H19: NGN
A20: GROSS SALARY FOR JANUARY, 2024 | H20: ='JANUARY 2024'!R194 -> 53058224
A22: DEDUCTIONS
A23: COOP SOCIETY DEDUCTIONS ( CONTR.& SPEC. SAVINGS) | G23: ='JANUARY 2024'!T194 -> 5135500
A24: COOP LOAN RECOVERY | G24: ='JANUARY 2024'!U194 -> 7215945.7
A25: PAYE DEDUCTIONS | G25: ='JANUARY 2024'!W194 -> 7445494.6
A26: NHF DEDUCTIONS | G26: ='JANUARY 2024'!V194 -> 23031.314
A27: TOTAL DEDUCTIONS FOR JANUARY 2024 | H27: =G23+G24+G25+G26 -> 19819972
A28: NET PAY AS PER JANUARY, 2024 PAYROLL | H28: =H20-H27 -> 33238252
A29: NET PAY AS PER DECEMBER, 2023 PAYROLL | H29: ='JANUARY 2024'!Y194 -> 33766937
A30: NET INCREASE/ (DECREASE) IN PAY FOR JANUARY, 2024 | H30: =H28-H29 -> -528685.11
A31: ANALYSED AS FOLLOWS:
A32: Effect of Cooperative Adjustment for January, 2024 | H32: 570000
A33: Net Effect of Yearly Increment in Steps | H33: -620870.14
A34: Effect of Conversion of Dr Idris Ibrahim to Permanent Staff | H34: =-275222.9-586933.33 -> -862156.23
A35: Effect of Placement of Abubakar Suleiman & Rafiu Mustapha | H35: =-20302-26129.81 -> -46431.81
A36: Net effect of Leg. Duty Allowance to Dr. Doris Aaron | H36: -121199.98
A37: Effect of Removal of Promotion Arrears of Dr. Bethel Ighuba & 3 others | H37: =1609343.27 -> 1609343.3
H38: =SUM(H32:H37) -> 528685.11
E40: DECEMBER, 2023 | G40: JANUARY, 2024
E41: No. of Staff | F41: N | G41: No. of Staff | H41: N
A42: 1 | B42: Director General's Office | E42: 33 | F42: ='JANUARY 2024'!Y34 -> 7198101.1 | G42: ='JANUARY 2024'!C34 -> 27 | H42: ='JANUARY 2024'!Z34 -> 8717267.3
A43: 2 | B43: Internal Audit | E43: 2 | F43: ='JANUARY 2024'!Y40 -> 1018949 | G43: ='JANUARY 2024'!C40 -> 3 | H43: ='JANUARY 2024'!Z40 -> 925705.68
A44: 3 | B44: Legis. Support Services | E44: 11 | F44: ='JANUARY 2024'!Y54 -> 3378453.8 | G44: ='JANUARY 2024'!C54 -> 11 | H44: ='JANUARY 2024'!Z54 -> 2615777.9
A45: 4 | B45: Legal Services | E45: 2 | F45: ='JANUARY 2024'!Y59 -> 808634.33 | G45: ='JANUARY 2024'!C59 -> 2 | H45: ='JANUARY 2024'!Z59 -> 808634.33
A46: 5 | B46: Democracy and Governance | E46: 13 | F46: ='JANUARY 2024'!Y72 -> 2562691.9 | G46: ='JANUARY 2024'!C72 -> 12 | H46: ='JANUARY 2024'!Z72 -> 2519533.8
A47: 6 | B47: Studies | E47: 4 | F47: ='JANUARY 2024'!Y82 -> 2073779.4 | G47: ='JANUARY 2024'!C82 -> 7 | H47: ='JANUARY 2024'!Z82 -> 2118161.3
...

Sheet ENHANCED WELFARE 2024
A1: NATIONAL INSTITUTE FOR LEGISLATIVE AND DEMOCRATIC STUDIES
A2: STAFF ENHANCED WELFARE SCHEDULE 2024
B4: STAFF NAME | C4: DESIGNATION | D4: GRADE LEVEL | E4: AMOUNT | F4: Grade Level 01 - 13 | G4: Grade Level 14 - 17
E5: N | F5: N | G5: N
A6: S/N | B6: DG'S OFFICE
A7: 1 | B7: PROF. ABUBAKAR O. SULAIMAN | C7: DIRECTOR GENERAL | D7: CONSOL | E7: 2000000 | G7: =E7 -> 2000000
A8: 2 | B8: RAHEEM USMAN AYIGORO | C8: SA-INFRASTRUCTURE | D8: 16 (9) | E8: 350000 | G8: =E8 -> 350000
A9: 3 | B9: MARIAM MOHAMMED BELLO | C9: SA- SPECIAL DUTIES | D9: 16 (9) | E9: 700000 | G9: =E9 -> 700000
A10: 4 | B10: DR IKEME ARTHUR J.O | C10: DEPUTY DIRECTOR, M&E | D10: 16 (9) | E10: 700000 | G10: =E10 -> 700000
A11: 5 | B11: MOSHOOD M. OLALERE | C11: DEPUTY DIR. GENERAL SERVICE | D11: 16 (9) | E11: 700000 | G11: =E11 -> 700000
A12: 6 | B12: REKIYA IBRAHIM ATTAH | C12: DEPUTY DIRECTOR TRAINING | D12: 16 (9) | E12: 700000 | G12: =E12 -> 700000
A13: 7 | B13: ANDRAWUS MUSA | C13: ASST. DIRECTOR, STORES | D13: 15(9) | E13: 700000 | G13: =E13 -> 700000
A14: 8 | B14: DR FRANCIS NDUM OJIE | C14: AD, TRAINING & IC./SA TO DG | D14: 15(7) | E14: 700000 | G14: =E14 -> 700000
A15: 9 | B15: ALI ABDULLAHI | C15: CHIEF ICT OFFICER | D15: 14(11) | E15: 500000 | G15: =E15 -> 500000
A16: 10 | B16: EMILY EKHIDE | C16: RESEARCH FELLOW 1 | D16: 14(10) | E16: 500000 | G16: =E16 -> 500000
A17: 11 | B17: ABDULSALAM S. MUSTAPHA | C17: ASST. MANAGER ICT | D17: 13(11) | E17: 500000 | F17: =E17 -> 500000
A18: 12 | B18: PERCY TERFA GBAHABO | C18: HEAD, NILDS LIAISON OFFICE | D18: 13(10) | E18: 500000 | F18: =E18 -> 500000
A19: 13 | B19: HASSANA AHMED IBRAHIM | C19: PA- TO DG | D19: 13 (9) | E19: 500000 | F19: =E19 -> 500000
A20: 14 | B20: ADUGBA RICHARD TERSEER | C20: PRINCIPAL INFO. OFFICER | D20: 12(9) | E20: 400000 | F20: =E20 -> 400000
A21: 15 | B21: LUCKY AGWOM | C21: RESEARCH ASSISTANT | D21: 12(7) | E21: 400000 | F21: =E21 -> 400000
A22: 16 | B22: FARUQ ATOFARATI | C22: PA (SPECIAL DUTIES) TO DG | D22: 10(7) | E22: 300000 | F22: =E22 -> 300000
A23: 17 | B23: ELIZABETH OGECHUKWU ONYEAKU | C23: ICT OFFICER | D23: 9(9) | E23: 300000 | F23: =E23 -> 300000
A24: 18 | B24: VICTOR ASUKWO | C24: ICT OFFICER | D24: 9(9) | E24: 300000 | F24: =E24 -> 300000
A25: 19 | B25: ABDULRAHMAN A SULAIMAN | C25: STORE OFFICER | D25: 9(8) | E25: 300000 | F25: =E25 -> 300000
A26: 20 | B26: DARE SHEU MAGBON | C26: ADMINISTRATION OFFICER | D26: 9(7) | E26: 300000 | F26: =E26 -> 300000
A27: 21 | B27: JIMOH ADEBAYO ZAKA | C27: ASST. OFFICER/COMM | D27: 9(8) | E27: 300000 | F27: =E27 -> 300000
A28: 22 | B28: MOHAMMED BELLO | C28: PROTOCOL ASSISTANT | D28: 8(9) | E28: 300000 | F28: =E28 -> 300000
... A30: 24 | B30: HARUNA JIBRIL AMEH | C30: ASST. ADMIN. OFFICER | D30: 8(8) | E30: 300000 | F30: =E30 -> 300000
B31: TOTAL | C31: 24 | E31: =SUM(E7:E30) -> 12550000 | F31: =SUM(F7:F30) -> 5000000 | G31: =SUM(G7:G30) -> 7550000
B33: INTERNAL AUDIT
A34: 1 | B34: OSANAIYE DAVID AKINYEMI | C34: DIRECTOR INTERNAL AUDIT | D34: 17(9) | E34: 1000000 | G34: =E34 -> 1000000
A35: 2 | B35: JAMILA ABDUL | C35: AUDITOR II | D35: 8(8) | E35: 300000 | F35: =E35 -> 300000
A36: 3 | B36: IJEOMA EWELUKWA | C36: AUDIT OFFICER | D36: 10(8) | E36: 300000 | F36: =E36 -> 300000
C37: 3 | E37: =SUM(E34:E36) -> 1600000 | F37: =SUM(F34:F36) -> 600000 | G37: =SUM(G34:G36) -> 1000000
B39: LEG. SUPPORT SEVICES
A40: 1 | B40: PROF. EDOBA BRIGHT OMOREGBE | C40: AG. DLSS | D40: 17(9) | E40: 1000000 | G40: =E40 -> 1000000
A41: 2 | B41: DR CLINTON JAJA | C41: SENIOR RESEARCH FELLOW | D41: 15(9) | E41: 700000 | G41: =E41 -> 700000
A42: 3 | B42: BETHEL UZOMA IHUGBA | C42: DEPUTY DIRECTOR, LEGAL RESEARCH | D42: 16(8) | E42: 700000 | G42: =E42 -> 700000
A43: 4 | B43: OGUCHE SAMUEL | C43: SNR RESEARCH FELLOW | D43: 15(9) | E43: 700000 | G43: =E43 -> 700000
A44: 5 | B44: IBRAHIM USMAN | C44: SNR RESEARCH FELLOW | D44: 15(9) | E44: 700000 | G44: =E44 -> 700000
...

Sheet PROMOTIONS 
A1: NATIONAL INSTITUTE FOR LEGISLATIVE AND DEMOCRATIC STUDIES | G1: ='[1]FEB 08'!F8/'[1]FEB 08'!Q8 -> 0.3
A2: STAFF PAYROLL FOR THE MONTH OF NOVEMBER 2023
E3: ='[1]FEB 08'!E11/'[1]FEB 08'!M11 -> #REF! | G3: ='[1]FEB 08'!F11/'[1]FEB 08'!Q11 -> #REF!
B4: STAFF NAME | C4: DESIGNATION | D4: CURRENT GRADE LEVEL | E4: BASIC SALARY | F4: RENT | G4: UTILITY | H4: DOMESTIC | I4: ENTERT. | J4: FURNIT. | K4: FUEL | L4: ALLOWANCE | M4: ALLOWANCE | N4: ALLCE | O4: ALLCE | P4: DUTY ALLCE | Q4: CURRENT GROSS SALARY | R4: NEW GRADE LEVEL | S4: NEW GROSS SALARY | T4: INCREMENT IN GROSS SALARY | U4: CURRENT NHF | V4: NEW NHF | W4: CURRENT PAYE | X4: NEW PAYE | Y4: INCREMENT IN PAYE | Z4: NET SALARY INCREMENT | AA4: NO OF MONTHS | AB4: ARREARS
E5: N | F5: N | G5: N | H5: N | I5: N | J5: N | K5: N | L5: N | M5: N | N5: N | O5: N | P5: N | Q5: N | S5: N | U5: N | W5: N
A6: S/N | B6: DG'S OFFICE
A7: 1 | B7: SHEU MAGABON DARE | C7: ADMIN ASSISTANT | D7: 8(10) | E7: 13492.21 | G7: =E7*300% -> 40476.63 | H7: =E7*7.5% -> 1011.9157 | J7: =E7*50% -> 6746.105 | K7: =E7*350% -> 47222.735 | L7: =E7*100% -> 13492.21 | N7: =50000 -> 50000 | O7: =E7*10% -> 1349.221 | P7: 10000 | Q7: =SUM(E7:Q7) -> 183791.03 | R7: 9(7) | S7: =205204.08 -> 205204.08 | T7: =205204.08-183791.03 -> 21413.05 | W7: 18102.9 | X7: =21640.88 -> 21640.88 | Y7: =X7-W7 -> 3537.98 | Z7: =T7-Y7 -> 17875.07 | AA7: =8/30 -> 0.26666667 | AB7: =Z7*AA7 -> 4766.6853
B8: TOTAL | E8: =SUM(E7:E7) -> 13492.21 | F8: =SUM(F7:F7) -> 0 | G8: =SUM(G7:G7) -> 40476.63 | H8: =SUM(H7:H7) -> 1011.9157 | I8: =SUM(I7:I7) -> 0 | J8: =SUM(J7:J7) -> 6746.105 | K8: =SUM(K7:K7) -> 47222.735 | L8: =SUM(L7:L7) -> 13492.21 | ... P8: =SUM(P7:P7) -> 10000 | Q8: =E8+F8+G8+H8+I8+J8+K8+L8+M8+N8+O8+P8 -> 183791.03 | S8: =SUM(S7:S7) -> 205204.08 | T8: =SUM(T7:T7) -> 21413.05 | U8: =SUM(U7:U7) -> 0 | V8: =SUM(V7:V7) -> 0 | W8: =SUM(W7:W7) -> 18102.9 | X8: =SUM(X7:X7) -> 21640.88 | Y8: =SUM(Y7:Y7) -> 3537.98 | Z8: =SUM(Z7:Z7) -> 17875.07 | AB8: =SUM(AB7:AB7) -> 4766.6853
B10: LEG. SUPPORT SEVICES
A11: 2 | B11: BETHEL UZOMA IHUGBA | C11: SNR RESEARCH FELLOW | D11: 15(9) | E11: 33507.5 | G11: =E11*300% -> 100522.5 | H11: =E11*7.5% -> 2513.0625 | I11: 40122.19 | J11: =E11*50% -> 16753.75 | K11: =E11*350% -> 117276.25 | L11: =E11*100% -> 33507.5 | M11: =160000 -> 160000 | O11: =E11*10% -> 3350.75 | P11: 20000 | Q11: =SUM(E11:Q11) -> 527553.5 | R11: 16(7) | S11: ='SALARY STRUCTURE'!H19+180000 -> 604023.33 | T11: =604023.33-527553.5 -> 76469.83 | U11: =837.69 -> 837.69 | V11: =1028.94 -> 1028.94 | W11: =79956.94 -> 79956.94 | X11: =94639.15 -> 94639.15 | Y11: =X11-W11 -> 14682.21 | Z11: =T11-Y11 -> 61787.62 | AA11: 9 | AB11: =Z11*AA11 -> 556088.58
A12: 3 | B12: DR MOHAMMED O. AMALI | C12: RESEARCH FELLOW I | D12: 14(10) | E12: 27611.23 | G12: =E12*300% -> 82833.69 | H12: =E12*7.5% -> 2070.8422 | J12: =E12*50% -> 13805.615 | K12: =E12*350% -> 96639.305 | L12: =E12*100% -> 27611.23 | M12: =140000 -> 140000 | O12: =E12*10% -> 2761.123 | P12: 20000 | Q12: =SUM(E12:Q12) -> 413333.04 | R12: 15(7) | S12: ='SALARY STRUCTURE'!H18+160000 -> 504720.17 | T12: =504720.05-413333.04 -> 91387.01 | U12: 0 | W12: 57889.865 | X12: =75436.17 -> 75436.17 | Y12: =X12-W12 -> 17546.305 | Z12: =T12-Y12 -> 73840.705 | AA12: 0 | AB12: =Z12*AA12 -> 0
B13: TOTAL | E13: =SUM(E11:E12) -> 61118.73 | F13: =SUM(F11:F12) -> 0 | G13: =SUM(G11:G12) -> 183356.19 | H13: =SUM(H11:H12) -> 4583.9047 | I13: =SUM(I11:I12) -> 40122.19 | J13: =SUM(J11:J12) -> 30559.365 | K13: =SUM(K11:K12) -> 213915.55 | L13: =SUM(L11:L12) -> 61118.73 | ... AB13: =SUM(AB11:AB12) -> 556088.58
T14: =S14-Q14 -> 0
Y15: =X15-W15 -> 0 | Z15: =T15-Y15 -> 0 | AB15: =Z15*AA15 -> 0
B16: FINANCE & ACCOUNTS | Y16: =X16-W16 -> 0 | Z16: =T16-Y16 -> 0 | AB16: =Z16*AA16 -> 0
A17: 3 | B17: RAHILA NURUDEEN HABU | C17: ASST. DIRECTOR, ACCOUNTS | D17: 15(9) | E17: 33507.5 | G17: =E17*300% -> 100522.5 | H17: =E17*7.5% -> 2513.0625 | I17: 40122.19 | J17: =E17*50% -> 16753.75 | K17: =E17*350% -> 117276.25 | L17: =E17*100% -> 33507.5 | M17: =80000 -> 80000 | N17: =E17*10% -> 3350.75 | O17: 20000 | P17: 100000 | Q17: =SUM(E17:P17) -> 547553.5 | R17: 16(7) | S17: ='SALARY STRUCTURE'!H19+190000 -> 614023.33 | T17: =S17-Q17 -> 66469.831 | U17: =837.69 -> 837.69 | V17: =1028.94 -> 1028.94 | W17: =83626.1 -> 83626.1 | X17: =96398.31 -> 96398.31 | Y17: =X17-W17 -> 12772.21 | Z17: =T17-Y17 -> 53697.621 | AA17: 11 | AB17: =Z17*AA17 -> 590673.83
B18: OJOGIWA ABISOLA GANIAT | C18: ASST. CHIEF BUDGET OFFICER | D18: 13(10) | E18: 25523.45 | G18: =E18*300% -> 76570.35 | H18: =E18*7.5% -> 1914.2587 | J18: =E18*50% -> 12761.725 | K18: =E18*350% -> 89332.075 | L18: =E18*100% -> 25523.45 | N18: =70000 -> 70000 | O18: =E18*10% -> 2552.345 | P18: 15000 | Q18: =SUM(E18:Q18) -> 319177.65 | R18: 14 (7) | S18: ='JANUARY 2024'!R127 -> 335272.06 | T18: =327211.37-319177.65 -> 8033.72 | U18: 638.09 | V18: 690.28 | W18: 40684.6 | X18: 42034.24 | Y18: =X18-W18 -> 1349.64 | Z18: =T18-Y18 -> 6684.08 | AA18: 0 | AB18: =Z18*AA18 -> 0
B19: TOTAL | E19: =SUM(E17:E17) -> 33507.5 | F19: =SUM(F17:F17) -> 0 | G19: =SUM(G17:G17) -> 100522.5 | H19: =SUM(H17:H17) -> 2513.0625 | I19: =SUM(I17:I17) -> 40122.19 | J19: =SUM(J17:J17) -> 16753.75 | K19: =SUM(K17:K17) -> 117276.25 | L19: =SUM(L17:L17) -> 33507.5 | M19: =SUM(#REF!) -> #REF! | N19: =SUM(M17:M17) -> 80000 | O19: =SUM(N17:N17) -> 3350.75 | P19: =SUM(O17:O17) -> 20000 | Q19: =SUM(P17:P17) -> 100000 | S19: =SUM(S17:S17) -> 614023.33 | T19: =SUM(T17:T17) -> 66469.831 | U19: =SUM(U17:U17) -> 837.69 | V19: =SUM(V17:V17) -> 1028.94 | W19: =SUM(W17:W17) -> 83626.1 | X19: =SUM(X17:X17) -> 96398.31 | Y19: =SUM(Y17:Y17) -> 12772.21 | Z19: =SUM(Z17:Z17) -> 53697.621 | AB19: =SUM(AB17:AB17) -> 590673.83
B21: FINANCE & ACCOUNTS
A22: 15 | B22: YUNUSA ABDULMUMINI ELEOJO | C22: SENIOR DRIVER | D22: 5(11) | E22: 5428.12 | F22: =E22*300% -> 16284.36 | G22: =E22*7.5% -> 407.109 | I22: =E22*50% -> 2714.06 | J22: =E22*350% -> 18998.42 | K22: =E22*100% -> 5428.12 | M22: =20000 -> 20000 | N22: =E22*10% -> 542.812 | O22: 5000 | P22: =7000 -> 7000 | Q22: =SUM(E22:P22) -> 81803.001 | R22: 7(3) | S22: ='SALARY STRUCTURE'!#REF!+30000 -> #REF! | T22: =S22-Q22 -> #REF! | W22: 4365.3308 | X22: ='[6]October 2023'!$Z$164 -> 8312.59 | Y22: =X22-W22 -> 3947.2592 | Z22: =T22-Y22 -> #REF! | AA22: =(10/31)+2 -> 2.3225806 | AB22: =Z22*AA22 -> #REF!
A23: 16 | B23: JOHN GIMAH | C23: SENIOR DRIVER | D23: 5(11) | E23: 5428.12 | F23: =E23*300% -> 16284.36 | G23: =E23*7.5% -> 407.109 | I23: =E23*50% -> 2714.06 | J23: =E23*350% -> 18998.42 | K23: =E23*100% -> 5428.12 | M23: =20000 -> 20000 | N23: =E23*10% -> 542.812 | O23: 5000 | P23: =7000 -> 7000 | Q23: =SUM(E23:P23) -> 81803.001 | R23: 7(3) | S23: ='SALARY STRUCTURE'!#REF!+30000 -> #REF! | T23: =S23-Q23 -> #REF! | W23: =4365.33075466667 -> 4365.3308 | X23: ='[6]October 2023'!$Z$164 -> 8312.59 | Y23: =X23-W23 -> 3947.2592 | Z23: =T23-Y23 -> #REF! | AA23: =(17/31)+1 -> 1.5483871 | AB23: =Z23*AA23 -> #REF!
A24: 17 | B24: ABUBAKAR MUSA DANLAMI | C24: SENIOR DRIVER | D24: 5(12) | E24: =5598.92 -> 5598.92 | F24: =E24*300% -> 16796.76 | G24: =E24*7.5% -> 419.919 | I24: =E24*50% -> 2799.46 | J24: =E24*350% -> 19596.22 | K24: =E24*100% -> 5598.92 | M24: =20000 -> 20000 | N24: =E24*10% -> 559.892 | O24: 5000 | P24: =7000 -> 7000 | Q24: =SUM(E24:P24) -> 83370.091 | R24: 7(3) | S24: 115104.92 | T24: =S24-Q24 -> 31734.826 | W24: 4504.4109 | X24: ='[6]October 2023'!$Z$164 -> 8312.59 | Y24: =X24-W24 -> 3808.1791 | Z24: =T24-Y24 -> 27926.647 | AA24: 8 | AB24: =Z24*AA24 -> 223413.17
L25: =226713.38+70000 -> 296713.38
B27: GRAND TOTAL | E27: =E19+E13+E8 -> 108118.44 | F27: =F19+F13+F8 -> 0 | G27: =G19+G13+G8 -> 324355.32 | H27: =H19+H13+H8 -> 8108.883 | I27: =I19+I13+I8 -> 80244.38 | J27: =J19+J13+J8 -> 54059.22 | K27: =K19+K13+K8 -> 378414.54 | L27: =L19+L13+L8 -> 108118.44 | ... AB27: =AB19+AB13+AB8 -> 1151529.1

Sheet CHRISTMAS WELFARE
A1: NATIONAL INSTITUTE FOR LEGISLATIVE AND DEMOCRATIC STUDIES
A2: STAFF CHRISTMAS WELFARE DECEMBER 2023
E3: ='[1]FEB 08'!E11/'[1]FEB 08'!M11 -> #REF!
B4: STAFF NAME | C4: DESIGNATION | D4: GRADE LEVEL | E4: AMOUNT
E5: N
A6: S/N | B6: DG'S OFFICE
A7: 1 | B7: PROF. ABUBAKAR O. SULAIMAN | C7: DIRECTOR GENERAL | D7: CONSOL | E7: 540000
A8: 2 | B8: RAHEEM USMAN AYIGORO | C8: SA-INFRASTRUCTURE | D8: 16 (9) | E8: 180000
A9: 3 | B9: MARIAM MOHAMMED BELLO | C9: SA- SPECIAL DUTIES | D9: 16(8) | E9: 180000
A10: 4 | B10: DR IKEME ARTHUR J.O | C10: DEPUTY DIRECTOR, M&E | D10: 16(8) | E10: 180000
A11: 5 | B11: MOSHOOD M. OLALERE | C11: DEPUTY DIR. GENERAL SERVICE | D11: 16(8) | E11: 180000
A12: 6 | B12: REKIYA IBRAHIM ATTAH | C12: DEPUTY DIRECTOR TRAINING | D12: 16(8) | E12: 180000
A13: 7 | B13: ANDRAWUS MUSA | C13: ASST. DIRECTOR, STORES | D13: 15(9) | E13: 126000
A14: 8 | B14: DR FRANCIS NDUM OJIE | C14: AD, TRAINING & IC./SA TO DG | D14: 15(7) | E14: 126000
A15: 9 | B15: ALI ABDULLAHI | C15: CHIEF ICT OFFICER | D15: 14(10) | E15: =90000 -> 90000
A16: 10 | B16: EMILY EKHIDE | C16: RESEARCH FELLOW 1 | D16: 14(9) | E16: =90000 -> 90000
A17: 11 | B17: ABDULSALAM S. MUSTAPHA | C17: ASST. MANAGER ICT | D17: 13(11) | E17: =90000 -> 90000
A18: 12 | B18: PERCY TERFA GBAHABO | C18: HEAD, NILDS LIAISON OFFICE | D18: 13(9) | E18: =90000 -> 90000
A19: 13 | B19: HASSANA AHMED IBRAHIM | C19: PA- TO DG | D19: 13 (8) | E19: =90000 -> 90000
A20: 14 | B20: ADUGBA RICHARD TERSEER | C20: PRINCIPAL INFO. OFFICER | D20: 12(8) | E20: 54000
A21: 15 | B21: LUCKY AGWOM | C21: RESEARCH ASSISTANT | D21: 12(7) | E21: 54000
A22: 16 | B22: FARUQ ATOFARATI | C22: PA (SPECIAL DUTIES) TO DG | D22: 10(7) | E22: 54000
A23: 17 | B23: ELIZABETH OGECHUKWU ONYEAKU | C23: ICT OFFICER | D23: 9(8) | E23: 54000
A24: 18 | B24: VICTOR ASUKWO | C24: ICT OFFICER | D24: 9(8) | E24: 54000
A25: 19 | B25: ABDULRAHMAN A SULAIMAN | C25: STORE OFFICER | D25: 9(7) | E25: 54000
A26: 20 | B26: DARE SHEU MAGBON | C26: ADMINISTRATION OFFICER | D26: 9(7) | E26: 54000
A27: 21 | B27: JIMOH ADEBAYO ZAKA | C27: ASST. OFFICER/COMM | D27: 9(8) | E27: 54000
A28: 22 | B28: MOHAMMED BELLO | C28: PROTOCOL ASSISTANT | D28: 8(8) | E28: 54000
A29: 23 | B29: SULEIMAN ABUBAKAR SODEEQ | C29: ASST. ADMIN. OFFICER | D29: 8(8) | E29: 54000
A30: 24 | B30: HARUNA JIBRIL AMEH | C30: ASST. ADMIN. OFFICER | D30: 8(7) | E30: 54000
B31: TOTAL | C31: 24 | E31: =SUM(E7:E30) -> 2736000
B33: INTERNAL AUDIT
A34: 1 | B34: OSANAIYE DAVID AKINYEMI | C34: DIRECTOR INTERNAL AUDIT | D34: 17(9) | E34: 270000
A35: 2 | B35: JAMILA ABDUL | C35: AUDITOR II | D35: 8(7) | E35: 54000
A36: 3 | B36: IJEOMA EWELUKWA | C36: AUDIT OFFICER | D36: 10(7) | E36: 54000
C37: 3 | E37: =SUM(E34:E36) -> 378000
B39: LEG. SUPPORT SEVICES
A40: 1 | B40: PROF. EDOBA BRIGHT OMOREGBE | C40: AG. DLSS | D40: 17(9) | E40: 270000
A41: 2 | B41: BETHEL UZOMA IHUGBA | C41: DEPUTY DIRECTOR, LEGAL RESEARCH | D41: 16(7) | E41: =180000 -> 180000
A42: 3 | B42: DR CLINTON JAJA | C42: SENIOR RESEARCH FELLOW | D42: 15(9) | E42: 126000
...

Sheet CHRISTMAS WELFARE 1

Sheet HALF 2023 (2)
A1: NATIONAL INSTITUTE FOR LEGISLATIVE AND DEMOCRATIC STUDIES
A2: STAFF PAYROLL FOR THE MONTH OF DECEMBER 2023
B4: STAFF NAME | C4: DESIGNATION | D4: GRADE LEVEL | E4: CONS. SALARY | F4: HALF SALARY
E5: N | F5: N
A6: S/N | B6: DG'S OFFICE
A7: 1 | B7: PROF. ABUBAKAR O. SULAIMAN | C7: DIRECTOR GENERAL | D7: CONSOL | E7: 1158849.8 | F7: =E7/2 -> 579424.92
A8: 2 | B8: RAHEEM USMAN AYIGORO | C8: SA-INFRASTRUCTURE | D8: 16 (9) | E8: 541465.02 | F8: =E8/2 -> 270732.51
A9: 3 | B9: MARIAM MOHAMMED BELLO | C9: SA- SPECIAL DUTIES | D9: 16(8) | E9: 727744 | F9: =E9/2 -> 363872
A10: 4 | B10: DR IKEME ARTHUR J.O | C10: DEPUTY DIRECTOR, M&E | D10: 16(8) | E10: 617744 | F10: =E10/2 -> 308872
A11: 5 | B11: MOSHOOD M. OLALERE | C11: DEPUTY DIR. GENERAL SERVICE | D11: 16(8) | E11: 677744 | F11: =E11/2 -> 338872
A12: 6 | B12: REKIYA IBRAHIM ATTAH | C12: DEPUTY DIRECTOR TRAINING | D12: 16(8) | E12: 627744 | F12: =E12/2 -> 313872
A13: 7 | B13: ANDRAWUS MUSA | C13: ASST. DIRECTOR, STORES | D13: 15(9) | E13: 497553.5 | F13: =E13/2 -> 248776.75
A14: 8 | B14: DR FRANCIS NDUM OJIE | C14: AD, TRAINING & IC./SA TO DG | D14: 15(7) | E14: 604729.22 | F14: =E14/2 -> 302364.61
A15: 9 | B15: ALI ABDULLAHI | C15: CHIEF ICT OFFICER | D15: 14(10) | E15: 343333.04 | F15: =E15/2 -> 171666.52
A16: 10 | B16: EMILY EKHIDE | C16: RESEARCH FELLOW 1 | D16: 14(9) | E16: 455272.06 | F16: =E16/2 -> 227636.03
A17: 11 | B17: ABDULSALAM S. MUSTAPHA | C17: ASST. MANAGER ICT | D17: 13(11) | E17: 326663.08 | F17: =E17/2 -> 163331.54
A18: 12 | B18: PERCY TERFA GBAHABO | C18: HEAD, NILDS LIAISON OFFICE | D18: 13(9) | E18: 362001.06 | F18: =E18/2 -> 181000.53
... A30: 24 | B30: HARUNA JIBRIL AMEH | C30: ASST. ADMIN. OFFICER | D30: 8(7) | E30: 173329.05 | F30: =E30/2 -> 86664.525
B31: TOTAL | C31: 24 | E31: 10062524 | F31: =SUM(F7:F30) -> 5028878.8
B33: INTERNAL AUDIT
A34: 1 | B34: OSANAIYE DAVID AKINYEMI | C34: DIRECTOR INTERNAL AUDIT | D34: 17(9) | E34: 950209.06 | F34: =E34/2 -> 475104.53
A35: 2 | B35: JAMILA ABDUL | C35: AUDITOR II | D35: 8(7) | E35: 173329.05 | F35: =E35/2 -> 86664.525
A36: 3 | B36: IJEOMA EWELUKWA | C36: AUDIT OFFICER | D36: 10(7) | E36: 228602.08 | F36: =E36/2 -> 114301.04
C37: 3 | E37: 1352140.2 | F37: =SUM(F34:F36) -> 676070.1
B39: LEG. SUPPORT SEVICES
A40: 1 | B40: PROF. EDOBA BRIGHT OMOREGBE | C40: AG. DLSS | D40: 17(9) | E40: 1050209.1 | F40: =E40/2 -> 525104.53
A41: 2 | B41: DR CLINTON JAJA | C41: SENIOR RESEARCH FELLOW | D41: 15(9) | E41: 527553.5 | F41: =E41/2 -> 263776.75
A42: 3 | B42: BETHEL UZOMA IHUGBA | C42: DEPUTY DIRECTOR, LEGAL RESEARCH | D42: 16(7) | E42: 604023.33 | F42: =E42/2 -> 302011.66
A43: 4 | B43: OGUCHE SAMUEL | C43: SNR RESEARCH FELLOW | D43: 15(9) | E43: 527553.5 | F43: =E43/2 -> 263776.75
A44: 5 | B44: IBRAHIM USMAN | C44: SNR RESEARCH FELLOW | D44: 15(8) | E44: 516137.05 | F44: =E44/2 -> 258068.53
A45: 6 | B45: DR MOHAMMED O. AMALI | C45: SNR RESEARCH FELLOW | D45: 15(7) | E45: 504720.05 | F45: =E45/2 -> 252360.02
A46: 7 | B46: YAHAYA SHAMSU | C46: RESEARCH FELLOW 1 | D46: 14(10) | E46: 413333.04 | F46: =E46/2 -> 206666.52
A47: 8 | B47: DORIS DAKDA AARON | C47: RESEARCH FELLOW I | D47: 14(8) | E47: 397211.37 | F47: =E47/2 -> 198605.68
A48: 9 | B48: BILKIS S. LAWAL-GAMBARI | C48: RESEARCH OFFICER | D48: 10(7) | E48: 268602.08 | F48: =E48/2 -> 134301.04
A49: 10 | B49: ZAINAB AKINDE | C49: RESEARCH OFFICER | D49: 9(7) | E49: 245204.08 | F49: =E49/2 -> 122602.04
A50: 11 | B50: ABDULLAHI AHMAD USMAN | C50: RESEARCH OFFICER | D50: 9(7) | E50: 245204.08 | F50: =E50/2 -> 122602.04
A51: 12 | B51: GUNAT NANSAK MARK | C51: RESEARCH OFFICER | D51: 9(7) | E51: 245204.08 | F51: =E51/2 -> 122602.04
B52: TOTAL | C52: 12 | E52: 6101043.8 | F52: =SUM(F40:F51) -> 2772477.6
B54: LEGAL SERVICES
A55: 1 | B55: DR SHUIBU DANWANKA | C55: DIRECTOR LEGAL SERVICES | D55: 17(9) | E55: 1050209.1 | F55: =E55/2 -> 525104.53
...

Sheet Sheet3

Sheet NEW ENROLMENT IN NOVEMBER (2)
A1: NATIONAL INSTITUTE FOR LEGISLATIVE AND DEMOCRATIC STUDIES | G1: ='[1]FEB 08'!F8/'[1]FEB 08'!Q8 -> 0.3
A2: STAFF PAYROLL FOR THE MONTH OF NOVEMBER 2023
E3: ='[1]FEB 08'!E11/'[1]FEB 08'!M11 -> #REF! | G3: ='[1]FEB 08'!F11/'[1]FEB 08'!Q11 -> #REF!
B4: STAFF NAME | C4: DESIGNATION | D4: GRADE LEVEL | E4: BASIC SALARY | F4: ALLCE/ AREARS | G4: RENT | H4: UTILITY | I4: DOMESTIC | J4: ENTERT. | K4: FURNIT. | L4: FUEL | M4: ALLOWANCE | N4: ALLOWANCE | O4: ALLCE | P4: ALLCE | Q4: DUTY ALLCE | R4: GROSS SALARY | S4: PAYE | T4: TOTAL DEDUCTION | U4: OCTOBER, 2023 | V4: NOVEMBER, 2023 | W4: NO OF MONTHS | X4: ARREARS
E5: N | F5: N | G5: N | H5: N | I5: N | J5: N | K5: N | L5: N | M5: N | N5: N | O5: N | P5: N | Q5: N | S5: N
A6: S/N | B6: DG'S OFFICE
A7: 3 | B7: ABDULSALAM S. MUSTAPHA | C7: ASST. MANAGER ICT | D7: 13(11) | E7: 26339.3 | G7: =E7*300% -> 79017.9 | H7: =E7*7.5% -> 1975.4475 | I7: 0 | J7: =E7*50% -> 13169.65 | K7: =E7*350% -> 92187.55 | L7: =E7*100% -> 26339.3 | M7: 70000 | O7: =E7*10% -> 2633.93 | P7: 15000 | R7: =SUM(E7:Q7) -> 326663.08 | S7: =42046.06 -> 42046.06 | T7: =42046.06 -> 42046.06 | V7: =R7-T7 -> 284617.02 | W7: 1 | X7: =V7*W7 -> 284617.02
B8: TOTAL | E8: =SUM(E7:E7) -> 26339.3 | F8: =SUM(F7:F7) -> 0 | G8: =SUM(G7:G7) -> 79017.9 | H8: =SUM(H7:H7) -> 1975.4475 | I8: =SUM(I7:I7) -> 0 | J8: =SUM(J7:J7) -> 13169.65 | K8: =SUM(K7:K7) -> 92187.55 | L8: =SUM(L7:L7) -> 26339.3 | ... P8: =SUM(P7:P7) -> 15000 | R8: =SUM(R7) -> 326663.08 | S8: =SUM(S7:S7) -> 42046.06 | T8: =SUM(T7:T7) -> 42046.06 | U8: =SUM(U7:U7) -> 0 | V8: =SUM(V7:V7) -> 284617.02 | X8: =SUM(X7:X7) -> 284617.02
B10: DEM. & GOVERNANCE
A11: 10 | B11: KOLAPO Q. ABAYOMI | C11: RESEARCH OFFICER | D11: 10(7) | E11: 17286.33 | G11: =E11*300% -> 51858.99 | H11: =E11*7.5% -> 1296.4748 | J11: =E11*50% -> 8643.165 | K11: =E11*350% -> 60502.155 | L11: =E11*100% -> 17286.33 | M11: 100000 | O11: =E11*10% -> 1728.633 | P11: 10000 | R11: =SUM(E11:Q11) -> 268602.08 | S11: =32291.82 -> 32291.82 | T11: =32291.82 -> 32291.82 | V11: =R11-T11 -> 236310.26 | W11: =(25/31)+2 -> 2.8064516 | X11: =V11*W11 -> 663193.3
B12: TOTAL | E12: =SUM(E11:E11) -> 17286.33 | F12: =SUM(F11:F11) -> 0 | G12: =SUM(G11:G11) -> 51858.99 | H12: =SUM(H11:H11) -> 1296.4748 | I12: =SUM(I11:I11) -> 0 | J12: =SUM(J11:J11) -> 8643.165 | K12: =SUM(K11:K11) -> 60502.155 | L12: =SUM(L11:L11) -> 17286.33 | ... X12: =SUM(X11:X11) -> 663193.3
B14: GRAND TOTAL | E14: =E8+E12 -> 43625.63 | F14: =F8+F12 -> 0 | G14: =G8+G12 -> 130876.89 | H14: =H8+H12 -> 3271.9222 | I14: =I8+I12 -> 0 | J14: =J8+J12 -> 21812.815 | K14: =K8+K12 -> 152689.71 | L14: =L8+L12 -> 43625.63 | ... V14: =V8+V12 -> 520927.28 | X14: =X8+X12 -> 947810.32

Sheet Regularisation IN NOVEMBER (3)
A1: NATIONAL INSTITUTE FOR LEGISLATIVE AND DEMOCRATIC STUDIES | G1: ='[1]FEB 08'!F8/'[1]FEB 08'!Q8 -> 0.3
A2: STAFF PAYROLL FOR THE MONTH OF NOVEMBER 2023
E3: ='[1]FEB 08'!E11/'[1]FEB 08'!M11 -> #REF! | G3: ='[1]FEB 08'!F11/'[1]FEB 08'!Q11 -> #REF!
B4: STAFF NAME | C4: DESIGNATION | D4: GRADE LEVEL | E4: BASIC SALARY | F4: ALLCE/ AREARS | G4: RENT | H4: UTILITY | I4: DOMESTIC | J4: ENTERT. | K4: FURNIT. | L4: FUEL | M4: ALLOWANCE | N4: ALLOWANCE | O4: ALLCE | P4: ALLCE | Q4: DUTY ALLCE | R4: GROSS SALARY | S4: NEW GRADE LEVEL | T4: NEW GROSS SALARY | U4: INCREMENT IN GROSS SALARY | V4: CURRENT NHF | W4: NEW NHF | X4: CURRENT PAYE | Y4: NEW PAYE | Z4: INCREMENT IN PAYE | AA4: NET SALARY INCREMENT | AB4: NO OF MONTHS | AC4: ARREARS | AD4: ARREARS PAID IN OCTOBER | AE4: SHORTFALL IN ARREARS
E5: N | F5: N | G5: N | H5: N | I5: N | J5: N | K5: N | L5: N | M5: N | N5: N | O5: N | P5: N | Q5: N | S5: N
A6: S/N | B6: ADMIN & HR
A8: 40 | B8: YUNUSA ABDULMUMINI ELEOJO | C8: CHIEF MOTOR DRIVER MECH. | D8: 7(3) | E8: 5428.12 | G8: =E8*300% -> 16284.36 | H8: =E8*7.5% -> 407.109 | J8: =E8*50% -> 2714.06 | K8: =E8*350% -> 18998.42 | L8: =E8*100% -> 5428.12 | N8: =20000 -> 20000 | O8: =E8*10% -> 542.812 | P8: 5000 | Q8: =7000 -> 7000 | R8: =SUM(E8:Q8) -> 81803.001 | S8: 7(3) | T8: =122105 -> 122105 | U8: =T8-R8 -> 40301.999 | X8: 4365.3308 | Y8: =9152.6 -> 9152.6 | Z8: =Y8-X8 -> 4787.2692 | AA8: =U8-Z8 -> 35514.73 | AB8: =(11/31)+3 -> 3.3548387 | AC8: =AA8*AB8 -> 119146.19 | AD8: =66227.57 -> 66227.57 | AE8: =AC8-AD8 -> 52918.62
A9: 41 | B9: JOHN GIMAH | C9: CHIEF MOTOR DRIVER MECH. | D9: 7(3) | E9: 5428.12 | G9: =E9*300% -> 16284.36 | H9: =E9*7.5% -> 407.109 | J9: =E9*50% -> 2714.06 | K9: =E9*350% -> 18998.42 | L9: =E9*100% -> 5428.12 | N9: =20000 -> 20000 | O9: =E9*10% -> 542.812 | P9: 5000 | Q9: =7000 -> 7000 | R9: =SUM(E9:Q9) -> 81803.001 | S9: 7(3) | T9: =122105 -> 122105 | U9: =T9-R9 -> 40301.999 | X9: =4365.33075466667 -> 4365.3308 | Y9: =9152.6 -> 9152.6 | Z9: =Y9-X9 -> 4787.2692 | AA9: =U9-Z9 -> 35514.73 | AB9: =(17/31)+2 -> 2.5483871 | AC9: =AA9*AB9 -> 90505.279 | AD9: 44151.71 | AE9: =AC9-AD9 -> 46353.569
A10: 42 | B10: ABUBAKAR MUSA DANLAMI | C10: CHIEF MOTOR DRIVER MECH. | D10: 7(3) | E10: 5598.92 | G10: =E10*300% -> 16796.76 | H10: =E10*7.5% -> 419.919 | J10: =E10*50% -> 2799.46 | K10: =E10*350% -> 19596.22 | L10: =E10*100% -> 5598.92 | N10: =20000 -> 20000 | O10: =E10*10% -> 559.892 | P10: 5000 | Q10: =7000 -> 7000 | R10: =SUM(E10:Q10) -> 83370.091 | S10: 7(3) | T10: =122105 -> 122105 | U10: =T10-R10 -> 38734.909 | X10: 4504.4109 | Y10: =9152.6 -> 9152.6 | Z10: =Y10-X10 -> 4648.1891 | AA10: =U10-Z10 -> 34086.72 | AB10: 9 | AC10: =AA10*AB10 -> 306780.48 | AD10: 216693.09 | AE10: =AC10-AD10 -> 90087.389
AE11: =SUM(AE8:AE10) -> 189359.58
A13: 40 | B13: YUNUSA ABDULMUMINI ELEOJO | C13: CHIEF MOTOR DRIVER MECH. | D13: 7(3) | E13: =8730.79 -> 8730.79 | G13: =E13*300% -> 26192.37 | H13: =E13*7.5% -> 654.80925 | J13: =E13*50% -> 4365.395 | K13: =E13*350% -> 30557.765 | L13: =E13*100% -> 8730.79 | N13: 30000 | O13: =E13*10% -> 873.079 | P13: 5000 | Q13: =7000 -> 7000 | R13: =SUM(E13:Q13) -> 122105 | T13: =10000+5000+5000 -> 20000 | U13: =15625 -> 15625 | W13: =[7]PROMOTIONS!$X$42 -> 8312.59 | X13: =W13+V13+U13+T13+S13 -> 43937.59 | Y13: 106043.97 | Z13: =R13-X13 -> 78167.408
A14: 41 | B14: JOHN GIMAH | C14: CHIEF MOTOR DRIVER MECH. | D14: 7(3) | E14: =8730.79 -> 8730.79 | G14: =E14*300% -> 26192.37 | H14: =E14*7.5% -> 654.80925 | J14: =E14*50% -> 4365.395 | K14: =E14*350% -> 30557.765 | L14: =E14*100% -> 8730.79 | N14: 30000 | O14: =E14*10% -> 873.079 | P14: 5000 | Q14: =7000 -> 7000 | R14: =SUM(E14:Q14) -> 122105 | T14: 20000 | U14: 18333.33 | W14: =[7]PROMOTIONS!$X$42 -> 8312.59 | X14: =W14+V14+U14+T14+S14 -> 46645.92 | Y14: 80609.452 | Z14: =R14-X14 -> 75459.078
A15: 42 | B15: ABUBAKAR MUSA DANLAMI | C15: CHIEF MOTOR DRIVER MECH. | D15: 7(3) | E15: =8730.79 -> 8730.79 | G15: =E15*300% -> 26192.37 | H15: =E15*7.5% -> 654.80925 | J15: =E15*50% -> 4365.395 | K15: =E15*350% -> 30557.765 | L15: =E15*100% -> 8730.79 | N15: 30000 | O15: =E15*10% -> 873.079 | P15: 5000 | Q15: =7000 -> 7000 | R15: =SUM(E15:Q15) -> 122105 | T15: =3000+5000+5000 -> 13000 | U15: =44000 -> 44000 | W15: =[7]PROMOTIONS!$X$42 -> 8312.59 | X15: =W15+V15+U15+T15+S15 -> 65312.59 | Y15: 239903.58 | Z15: =R15-X15 -> 56792.408
B16: GRAND TOTAL | E16: =E8+E14 -> 14158.91 | F16: =F8+F14 -> 0 | G16: =G8+G14 -> 42476.73 | H16: =H8+H14 -> 1061.9182 | I16: =I8+I14 -> 0 | J16: =J8+J14 -> 7079.455 | K16: =K8+K14 -> 49556.185 | L16: =L8+L14 -> 14158.91 | ... V16: =V8+V14 -> 0 | X16: =X8+X14 -> 51011.251

Sheet Sheet2

Sheet PROMOTIONS
A1: NATIONAL INSTITUTE FOR LEGISLATIVE AND DEMOCRATIC STUDIES | G1: ='[1]FEB 08'!F8/'[1]FEB 08'!Q8 -> 0.3
A2: STAFF PAYROLL FOR THE MONTH OF OCTOBER 2023
E3: ='[1]FEB 08'!E11/'[1]FEB 08'!M11 -> #REF! | G3: ='[1]FEB 08'!F11/'[1]FEB 08'!Q11 -> #REF!
B4: STAFF NAME | C4: DESIGNATION | D4: CURRENT GRADE LEVEL | E4: BASIC SALARY | F4: RENT | G4: UTILITY | H4: DOMESTIC | I4: ENTERT. | J4: FURNIT. | K4: FUEL | L4: ALLOWANCE | M4: ALLOWANCE | N4: ALLCE | O4: ALLCE | P4: DUTY ALLCE | Q4: CURRENT GROSS SALARY | R4: NEW GRADE LEVEL | S4: NEW GROSS SALARY | T4: INCREMENT IN GROSS SALARY | U4: CURRENT NHF | V4: NEW NHF | W4: CURRENT PAYE | X4: NEW PAYE | Y4: INCREMENT IN PAYE | Z4: NET SALARY INCREMENT | AA4: NO OF MONTHS | AB4: ARREARS
E5: N | F5: N | G5: N | H5: N | I5: N | J5: N | K5: N | L5: N | M5: N | N5: N | O5: N | P5: N | Q5: N | S5: N | U5: N | W5: N
A6: S/N | B6: DG'S OFFICE
A7: 1 | B7: ABDULRAHMAN A SULAIMAN | C7: ASSISTANT STORES OFFICER | D7: 8(10) | E7: 13492.21 | F7: =E7*300% -> 40476.63 | G7: =E7*7.5% -> 1011.9157 | I7: =E7*50% -> 6746.105 | J7: =E7*350% -> 47222.735 | K7: =E7*100% -> 13492.21 | M7: =50000 -> 50000 | N7: =E7*10% -> 1349.221 | O7: 10000 | Q7: =SUM(E7:P7) -> 183791.03 | R7: 9(7) | S7: ='SALARY STRUCTURE'!H13+60000 -> 205203.67 | T7: =S7-Q7 -> 21412.64 | W7: 18102.903 | X7: ='[6]October 2023'!$Z$29 -> 21640.883 | Y7: =X7-W7 -> 3537.9799 | Z7: =T7-Y7 -> 17874.66 | AA7: =(19/31)+4 -> 4.6129032 | AB7: =Z7*AA7 -> 82454.077
B8: TOTAL | C8: 1 | E8: =SUM(E7:E7) -> 13492.21 | F8: =SUM(F7:F7) -> 40476.63 | G8: =SUM(G7:G7) -> 1011.9157 | H8: =SUM(H7:H7) -> 0 | I8: =SUM(I7:I7) -> 6746.105 | J8: =SUM(J7:J7) -> 47222.735 | K8: =SUM(K7:K7) -> 13492.21 | L8: =SUM(L7:L7) -> 0 | ... Q8: =SUM(Q7:Q7) -> 183791.03 | S8: =SUM(S7:S7) -> 205203.67 | T8: =SUM(T7:T7) -> 21412.64 | U8: =SUM(U7:U7) -> 0 | V8: =SUM(V7:V7) -> 0 | W8: =SUM(W7:W7) -> 18102.903 | X8: =SUM(X7:X7) -> 21640.883 | Y8: =SUM(Y7:Y7) -> 3537.9799 | Z8: =SUM(Z7:Z7) -> 17874.66 | AB8: =SUM(AB7:AB7) -> 82454.077
B10: LEG. SUPPORT SEVICES
A11: 2 | B11: DORIS DAKDA AARON | C11: RESEARCH FELLOW II | D11: 13(10) | E11: 25523.45 | F11: =E11*300% -> 76570.35 | G11: =E11*7.5% -> 1914.2587 | I11: =E11*50% -> 12761.725 | J11: =E11*350% -> 89332.075 | K11: =E11*100% -> 25523.45 | L11: =120000 -> 120000 | N11: =E11*10% -> 2552.345 | O11: 15000 | Q11: =SUM(E11:P11) -> 369177.65 | R11: 14(8) | S11: ='SALARY STRUCTURE'!I17+140000 -> 397211.25 | T11: =S11-Q11 -> 28033.596 | U11: 638.08625 | V11: =690.28 -> 690.28 | W11: 49548.776 | X11: ='[6]October 2023'!$Z$50 -> 54812.469 | Y11: =X11-W11 -> 5263.6924 | Z11: =T11-Y11 -> 22769.904 | AA11: =(18/31)+1 -> 1.5806452 | AB11: =Z11*AA11 -> 35991.138
B12: TOTAL | C12: 1 | E12: =SUM(E11:E11) -> 25523.45 | F12: =SUM(F11:F11) -> 76570.35 | G12: =SUM(G11:G11) -> 1914.2587 | H12: =SUM(H11:H11) -> 0 | I12: =SUM(I11:I11) -> 12761.725 | J12: =SUM(J11:J11) -> 89332.075 | K12: =SUM(K11:K11) -> 25523.45 | L12: =SUM(L11:L11) -> 120000 | ... Q12: =SUM(Q11:Q11) -> 369177.65 | S12: =SUM(S11:S11) -> 397211.25 | T12: =SUM(T11:T11) -> 28033.596 | U12: =SUM(U11:U11) -> 638.08625 | V12: =SUM(V11:V11) -> 690.28 | W12: =SUM(W11:W11) -> 49548.776 | X12: =SUM(X11:X11) -> 54812.469 | Y12: =SUM(Y11:Y11) -> 5263.6924 | Z12: =SUM(Z11:Z11) -> 22769.904 | AB12: =SUM(AB11:AB11) -> 35991.138
T13: =S13-Q13 -> 0
B14: DEMOCRACY & GOVERNANCE | T14: =S14-Q14 -> 0
A15: 3 | B15: NGARA CHRISTOPHER OCHANJA | C15: RESEARCH FELLOW 1 | D15: 14(11) | E15: =28489.81 -> 28489.81 | F15: =E15*300% -> 85469.43 | G15: =E15*7.5% -> 2136.7357 | I15: =E15*50% -> 14244.905 | J15: =E15*350% -> 99714.335 | K15: =E15*100% -> 28489.81 | L15: 140000 | N15: =E15*10% -> 2848.981 | O15: 20000 | P15: 0 | Q15: =SUM(E15:P15) -> 421394.01 | R15: 15(7) | S15: ='SALARY STRUCTURE'!H18+160000 -> 504720.17 | T15: =S15-Q15 -> 83326.16 | U15: 712.24525 | V15: =837.69 -> 837.69 | W15: 59441.782 | X15: ='[6]October 2023'!$Z$85 -> 75440.405 | Y15: =X15-W15 -> 15998.623 | Z15: =T15-Y15 -> 67327.537 | AA15: =9 -> 9 | AB15: =Z15*AA15 -> 605947.83
A16: 4 | B16: EJALONIBU GANIYU LAYI | C16: RESEARCH FELLOW 11 | D16: 13(10) | E16: 25523.45 | F16: =E16*300% -> 76570.35 | G16: =E16*7.5% -> 1914.2587 | I16: =E16*50% -> 12761.725 | J16: =E16*350% -> 89332.075 | K16: =E16*100% -> 25523.45 | L16: =120000 -> 120000 | N16: =E16*10% -> 2552.345 | O16: 15000 | Q16: =SUM(E16:P16) -> 369177.65 | R16: 14(8) | S16: ='SALARY STRUCTURE'!I17+140000 -> 397211.25 | T16: =S16-Q16 -> 28033.596 | W16: 49548.776 | X16: ='[6]October 2023'!$Z$62 -> 54931.227 | Y16: =X16-W16 -> 5382.4505 | Z16: =T16-Y16 -> 22651.146 | AA16: =(7/31)+2 -> 2.2258065 | AB16: =Z16*AA16 -> 50417.066
B17: TOTAL | C17: 2 | E17: =SUM(E15:E16) -> 54013.26 | F17: =SUM(F15:F16) -> 162039.78 | G17: =SUM(G15:G16) -> 4050.9945 | H17: =SUM(H15:H16) -> 0 | I17: =SUM(I15:I16) -> 27006.63 | J17: =SUM(J15:J16) -> 189046.41 | K17: =SUM(K15:K16) -> 54013.26 | L17: =SUM(L15:L16) -> 260000 | ... Q17: =SUM(Q15:Q16) -> 790571.66 | S17: =SUM(S15:S16) -> 901931.42 | T17: =SUM(T15:T16) -> 111359.76 | U17: =SUM(U15:U16) -> 712.24525 | V17: =SUM(V15:V16) -> 837.69 | W17: =SUM(W15:W16) -> 108990.56 | X17: =SUM(X15:X16) -> 130371.63 | Y17: =SUM(Y15:Y16) -> 21381.073 | Z17: =SUM(Z15:Z16) -> 89978.683 | AB17: =SUM(AB15:AB16) -> 656364.9
Y18: =X18-W18 -> 0 | Z18: =T18-Y18 -> 0 | AB18: =Z18*AA18 -> 0
B19: DEPARTMENT OF STUDIES | Y19: =X19-W19 -> 0 | Z19: =T19-Y19 -> 0 | AB19: =Z19*AA19 -> 0
A20: 5 | B20: ANTHONY EDET | C20: ASST. MGR M&E | D20: 13(10) | E20: 25523.45 | F20: =E20*300% -> 76570.35 | G20: =E20*7.5% -> 1914.2587 | H20: 0 | I20: =E20*50% -> 12761.725 | J20: =E20*350% -> 89332.075 | K20: =E20*100% -> 25523.45 | L20: =120000 -> 120000 | N20: =E20*10% -> 2552.345 | O20: 15000 | P20: 0 | Q20: =SUM(E20:P20) -> 369177.65 | R20: 14(8) | S20: ='SALARY STRUCTURE'!I17+140000 -> 397211.25 | T20: =S20-Q20 -> 28033.596 | U20: 638.08625 | W20: 49548.776 | X20: ='[6]October 2023'!$Z$78 -> 54931.227 | Y20: =X20-W20 -> 5382.4505 | Z20: =T20-Y20 -> 22651.146 | AA20: =9 -> 9 | AB20: =Z20*AA20 -> 203860.31
B21: TOTAL | C21: 1 | E21: =SUM(E20:E20) -> 25523.45 | F21: =SUM(F20:F20) -> 76570.35 | G21: =SUM(G20:G20) -> 1914.2587 | H21: =SUM(H20:H20) -> 0 | I21: =SUM(I20:I20) -> 12761.725 | J21: =SUM(J20:J20) -> 89332.075 | K21: =SUM(K20:K20) -> 25523.45 | L21: =SUM(L20:L20) -> 120000 | ... Q21: =SUM(Q20:Q20) -> 369177.65 | S21: =SUM(S20:S20) -> 397211.25 | U21: =SUM(U20:U20) -> 638.08625 | W21: =SUM(W20:W20) -> 49548.776 | X21: =SUM(X20:X20) -> 54931.227 | Y21: =SUM(Y20:Y20) -> 5382.4505 | Z21: =SUM(Z20:Z20) -> 22651.146 | AB21: =SUM(AB20:AB20) -> 203860.31
Y22: =X22-W22 -> 0 | Z22: =T22-Y22 -> 0 | AB22: =Z22*AA22 -> 0
B23: ECON. DEV. & SOC. RESEARCH | Y23: =X23-W23 -> 0 | Z23: =T23-Y23 -> 0 | AB23: =Z23*AA23 -> 0
A24: 6 | B24: OMOJU OLUWASOLA EMMANUEL | C24: RESEARCH FELLOW I | D24: 14(10) | E24: 27611.23 | F24: =E24*300% -> 82833.69 | G24: =E24*7.5% -> 2070.8422 | I24: =E24*50% -> 13805.615 | J24: =E24*350% -> 96639.305 | K24: =E24*100% -> 27611.23 | L24: 140000 | N24: =E24*10% -> 2761.123 | O24: 20000 | Q24: =SUM(E24:P24) -> 413333.04 | R24: 15(7) | S24: ='SALARY STRUCTURE'!H18+160000 -> 504720.17 | T24: =S24-Q24 -> 91387.131 | W24: 58026.609 | X24: ='[6]October 2023'!$Z$86 -> 75572.939 | Y24: =X24-W24 -> 17546.329 | Z24: =T24-Y24 -> 73840.802 | AA24: 1 | AB24: =Z24*AA24 -> 73840.802
A25: 7 | B25: OKUNGBOWA OSARETIN GODSPOWER | C25: RESEARCH FELLOW 11 | D25: 13(9) | E25: 24741.26 | F25: =E25*300% -> 74223.78 | G25: =E25*7.5% -> 1855.5945 | H25: 0 | I25: =E25*50% -> 12370.63 | J25: =E25*350% -> 86594.41 | K25: =E25*100% -> 24741.26 | L25: =120000 -> 120000 | N25: =E25*10% -> 2474.126 | O25: 15000 | P25: 0 | Q25: =SUM(E25:P25) -> 362001.06 | R25: 14(7) | S25: ='SALARY STRUCTURE'!H17+140000 -> 389153.42 | T25: =S25-Q25 -> 27152.356 | W25: 48170.87 | X25: ='[6]October 2023'!$Z$89 -> 53384.123 | Y25: =X25-W25 -> 5213.2524 | Z25: =T25-Y25 -> 21939.104 | AA25: =(19/31)+2 -> 2.6129032 | AB25: =Z25*AA25 -> 57324.755
B26: TOTAL | C26: 2 | E26: =SUM(E24:E25) -> 52352.49 | F26: =SUM(F24:F25) -> 157057.47 | G26: =SUM(G24:G25) -> 3926.4367 | H26: =SUM(H24:H25) -> 0 | I26: =SUM(I24:I25) -> 26176.245 | J26: =SUM(J24:J25) -> 183233.71 | K26: =SUM(K24:K25) -> 52352.49 | L26: =SUM(L24:L25) -> 260000 | ... Q26: =SUM(Q24:Q25) -> 775334.1 | S26: =SUM(S24:S25) -> 893873.58 | T26: =SUM(T24:T25) -> 118539.49 | U26: =SUM(U24:U25) -> 0 | V26: =SUM(V24:V25) -> 0 | W26: =SUM(W24:W25) -> 106197.48 | X26: =SUM(X24:X25) -> 128957.06 | Y26: =SUM(Y24:Y25) -> 22759.582 | Z26: =SUM(Z24:Z25) -> 95779.906 | AB26: =SUM(AB24:AB25) -> 131165.56
T27: =S27-Q27 -> 0 | Y27: =X27-W27 -> 0 | Z27: =T27-Y27 -> 0 | AB27: =Z27*AA27 -> 0
B28: TRAINING & INT''L COOP | T28: =S28-Q28 -> 0 | Y28: =X28-W28 -> 0 | Z28: =T28-Y28 -> 0 | AB28: =Z28*AA28 -> 0
A29: 8 | B29: DR FRANCIS NDUM OJIE | C29: CHIEF TRAINING OFFICER | D29: 14(10) | E29: 27611.23 | F29: =E29*300% -> 82833.69 | G29: =E29*7.5% -> 2070.8422 | I29: =E29*50% -> 13805.615 | J29: =E29*350% -> 96639.305 | K29: =E29*100% -> 27611.23 | L29: 140000 | N29: =E29*10% -> 2761.123 | O29: 20000 | P29: =100000 -> 100000 | Q29: =SUM(E29:P29) -> 513333.04 | R29: 15(7) | S29: ='SALARY STRUCTURE'!H18+160000+100000 -> 604720.17 | T29: =S29-Q29 -> 91387.131 | U29: 690.28075 | V29: =837.69 -> 837.69 | W29: =77098.29 -> 77098.29 | X29: ='[6]October 2023'!$Z$97 -> 94644.622 | Y29: =X29-W29 -> 17546.332 | Z29: =T29-Y29 -> 73840.8 | AA29: =3 -> 3 | AB29: =Z29*AA29 -> 221522.4
A30: 9 | B30: MOHAMMED R. ADAMU | C30: PRINCIPAL CONF. SECRETARY | D30: 13(10) | E30: 25523.45 | F30: =E30*300% -> 76570.35 | G30: =E30*7.5% -> 1914.2587 | H30: 0 | I30: =E30*50% -> 12761.725 | J30: =E30*350% -> 89332.075 | K30: =E30*100% -> 25523.45 | M30: 70000 | N30: =E30*10% -> 2552.345 | O30: 15000 | P30: 0 | Q30: =SUM(E30:P30) -> 319177.65 | R30: 14(8) | S30: ='SALARY STRUCTURE'!I17+70000 -> 327211.25 | T30: =S30-Q30 -> 8033.5963 | W30: 40698.125 | X30: ='[6]October 2023'!$Z$129 -> 42047.769 | Y30: =X30-W30 -> 1349.6442 | Z30: =T30-Y30 -> 6683.9521 | AA30: 7 | AB30: =Z30*AA30 -> 46787.665
A31: 10 | B31: TASSNEEM IBRAHIM | C31: ASSIST. INFO.OFFICER | D31: 8(10) | E31: 13492.21 | F31: 40476.63 | G31: 1011.9157 | I31: 6746.105 | J31: 47222.735 | K31: 13492.21 | M31: 50000 | N31: 1349.221 | O31: 10000 | Q31: 183791.03 | R31: 10(7) | S31: ='SALARY STRUCTURE'!H14+60000 -> 228601.58 | T31: =S31-Q31 -> 44810.557 | W31: 18102.903 | X31: ='[6]October 2023'!$Z$30 -> 25571.733 | Y31: =X31-W31 -> 7468.8299 | Z31: =T31-Y31 -> 37341.727 | AA31: 1 | AB31: =Z31*AA31 -> 37341.727
B32: TOTAL | C32: 3 | E32: =SUM(E29:E31) -> 66626.89 | F32: =SUM(F29:F31) -> 199880.67 | G32: =SUM(G29:G31) -> 4997.0167 | H32: =SUM(H29:H31) -> 0 | I32: =SUM(I29:I31) -> 33313.445 | J32: =SUM(J29:J31) -> 233194.11 | K32: =SUM(K29:K31) -> 66626.89 | L32: =SUM(L29:L31) -> 140000 | ... Q32: =SUM(Q29:Q31) -> 1016301.7 | S32: =SUM(S29:S31) -> 1160533 | T32: =S32-Q32 -> 144231.28 | U32: =SUM(U29:U31) -> 690.28075 | W32: =SUM(W29:W31) -> 135899.32 | X32: =SUM(X29:X31) -> 162264.12 | Y32: =SUM(Y29:Y31) -> 26364.806 | Z32: =SUM(Z29:Z31) -> 117866.48 | AB32: =SUM(AB29:AB31) -> 305651.79
Y33: =X33-W33 -> 0 | Z33: =T33-Y33 -> 0 | AB33: =Z33*AA33 -> 0
B34: FINANCE & ACCOUNTS | Y34: =X34-W34 -> 0 | Z34: =T34-Y34 -> 0 | AB34: =Z34*AA34 -> 0
