Workbook

Sheet JANUARY 2026
A1: NATIONAL INSTITUTE FOR LEGISLATIVE AND DEMOCRATIC STUDIES
A2: STAFF PAYROLL FOR THE MONTH OF JANUARY 2026
E3: ='[1]FEB 08'!E11/'[1]FEB 08'!M11 -> #REF!
B4: STAFF NAME | C4: DESIGNATION | D4: GRADE LEVEL | E4: BASIC SALARY | F4: ALLCE/ AREARS | G4: ALLOWANCE | H4: ALLOWANCE | I4: DUTY ALLCE | J4: GROSS SALARY | K4: AUCTION | L4: COOP 1 CONTR/SPEC SAVINGS | M4: COOP 1 LOAN RECOVERY | N4: COOP 2 CONTR/SPEC SAVINGS | O4: NHF DED. | P4: PAYE | Q4: EMPLOYEE PENSIONS | R4: TOTAL DEDUCTION | S4: DECEMBER, 2025 | T4: JANUARY, 2026
E5: N | F5: N | G5: N | H5: N | I5: N | J5: N | K5: N | L5: N | M5: N | O5: N | P5: N | Q5: N | R5: N | S5: N | T5: N
A6: S/N | B6: DG'S OFFICE
A7: 1 | B7: PROF. ABUBAKAR O. SULAIMAN | C7: DIRECTOR GENERAL | D7: CONSOL | E7: 1971137.1 | G7: =250000 -> 250000 | I7: 25235 | J7: =E7+F7+G7+H7+I7 -> 2246372.1 | O7: 0 | P7: 427498.91 | R7: =P7+O7+M7+N7+L7+K7+Q7 -> 427498.91 | S7: 1836402 | T7: =J7-R7 -> 1818873.2
A8: 2 | B8: RAHEEM USMAN AYIGORO | C8: SA-INFRASTRUCTURE | D8: 16 (9) | E8: 905306.75 | H8: =90000 -> 90000 | I8: =100000 -> 100000 | J8: =E8+F8+G8+H8+I8 -> 1095306.8 | L8: =250000 -> 250000 | N8: 100000 | P8: 167305.26 | Q8: 72424.54 | R8: =P8+O8+M8+N8+L8+K8+Q8 -> 589729.8 | S8: 497822.16 | T8: =J8-R8 -> 505576.95
A9: 3 | B9: MARIAM MOHAMMED BELLO | C9: SA- SPECIAL DUTIES | D9: 16 (9) | E9: 905306.75 | H9: =90000 -> 90000 | I9: =200000+100000 -> 300000 | J9: =E9+F9+G9+H9+I9 -> 1295306.8 | O9: 0 | P9: 224514.42 | R9: =P9+O9+M9+N9+L9+K9+Q9 -> 224514.42 | S9: 1067941.2 | T9: =J9-R9 -> 1070792.3
A10: 4 | B10: DR IKEME ARTHUR J.O | C10: DEPUTY DIRECTOR, M&E | D10: 16 (9) | E10: 905306.75 | G10: 180000 | I10: 0 | J10: =E10+F10+G10+H10+I10 -> 1085306.8 | L10: =50000 -> 50000 | O10: 13866.737 | P10: 162322.79 | Q10: 72424.54 | R10: =P10+O10+M10+N10+L10+K10+Q10 -> 298614.06 | S10: 778537.84 | T10: =J10-R10 -> 786692.69
A11: 5 | B11: ANDRAWUS MUSA | C11: DEP. DIRECTOR, STORES & PROCUREMENT | D11: 16(9) | E11: 905306.75 | H11: =90000 -> 90000 | I11: 50000 | J11: =E11+F11+G11+H11+I11 -> 1045306.8 | L11: =50000-40000 -> 10000 | M11: =90000+110000 -> 200000 | O11: 13866.737 | P11: 155122.79 | Q11: 72424.54 | R11: =P11+O11+M11+N11+L11+K11+Q11 -> 451414.06 | S11: 569000.89 | T11: =J11-R11 -> 593892.69
A12: 6 | B12: DR FRANCIS NDUM OJIE | C12: AD, TRAINING & IC./SA TO DG | D12: 15(9) | E12: 744477 | G12: 160000 | I12: =100000+100000 -> 200000 | J12: =E12+F12+G12+H12+I12 -> 1104477 | O12: 11475.263 | P12: 169523.15 | Q12: 59558.16 | R12: =P12+O12+M12+N12+L12+K12+Q12 -> 240556.57 | S12: 840352.81 | T12: =J12-R12 -> 863920.43
A13: 7 | B13: ALI ABDULLAHI | C13: ASST DIRECTOR ICT | D13: 15(7) | E13: 700713.92 | H13: =80000 -> 80000 | I13: =0 -> 0 | J13: =E13+F13+G13+H13+I13 -> 780713.92 | P13: 112938.22 | Q13: 56057.113 | R13: =P13+O13+M13+N13+L13+K13+Q13 -> 168995.34 | S13: 605150.2 | T13: =J13-R13 -> 611718.58
A14: 8 | B14: EMILY EKHIDE | C14: SENIOR RESEARCH FELLOW | D14: 15(9) | E14: 744477 | G14: 160000 | I14: =50000 -> 50000 | J14: =E14+F14+G14+H14+I14 -> 954477 | L14: =50000 -> 50000 | P14: 143585.39 | Q14: 59558.16 | R14: =P14+O14+M14+N14+L14+K14+Q14 -> 253143.55 | S14: 678161.92 | T14: =J14-R14 -> 701333.45
A15: 9 | B15: DORIS DAKDA AARON | C15: RESEARCH FELLOW I | D15: 14(10) | E15: 573911.08 | G15: =140000 -> 140000 | I15: =150000+100000 -> 250000 | J15: =E15+F15+G15+H15+I15 -> 963911.08 | L15: 150000 | M15: 0 | O15: 8926.6667 | P15: 146132.88 | Q15: 45912.887 | R15: =P15+O15+M15+N15+L15+K15+Q15 -> 350972.43 | S15: 592678.16 | T15: =J15-R15 -> 612938.65
A16: 10 | B16: ABDULSALAM S. MUSTAPHA | C16: ASST. DIRECTOR ICT | D16: 15(8) | E16: 722595.5 | H16: 80000 | I16: 50000 | J16: =E16+F16+G16+H16+I16 -> 852595.5 | N16: 10000 | P16: 125561.81 | Q16: 57807.64 | R16: =P16+O16+M16+N16+L16+K16+Q16 -> 193369.45 | S16: 637256.03 | T16: =J16-R16 -> 659226.05
A17: 11 | B17: PERCY TERFA GBAHABO | C17: RESEARCH FELLOW 1 | D17: 14(8) | E17: 542419.5 | G17: =140000 -> 140000 | I17: 0 | J17: =E17+F17+G17+H17+I17 -> 682419.5 | P17: 97524.669 | Q17: 43393.56 | R17: =P17+O17+M17+N17+L17+K17+Q17 -> 140918.23 | S17: 538909.56 | T17: =J17-R17 -> 541501.27
A18: 12 | B18: HASSANA AHMED IBRAHIM | C18: PA- TO DG | D18: 13(11) | E18: 541351.33 | G18: =120000 -> 120000 | I18: =100000+100000 -> 200000 | J18: =E18+F18+G18+H18+I18 -> 861351.33 | L18: =30000-20000 -> 10000 | M18: =127777.78 -> 127777.78 | O18: 8443.2708 | P18: 128227.99 | Q18: 43308.107 | R18: =P18+O18+M18+N18+L18+K18+Q18 -> 317757.15 | S18: 527015.2 | T18: =J18-R18 -> 543594.18
A19: 13 | B19: IKIP LEBO | C19: ASST CHIEF PROC. OFFICER | D19: 13 (9) | E19: 512098.92 | H19: 70000 | J19: =E19+F19+G19+H19+I19 -> 582098.92 | L19: 50000 | M19: 250000 | O19: 8008.9771 | P19: 78461.965 | Q19: 40967.913 | R19: =P19+O19+M19+N19+L19+K19+Q19 -> 427438.86 | S19: 141398.88 | T19: =J19-R19 -> 154660.06
A20: 14 | B20: ALABI ADESINA MUHYDEEN | C20: HEAD, NILDS LIAISON OFFICE | D20: 13 (9) | E20: 512098.92 | G20: 120000 | J20: =E20+F20+G20+H20+I20 -> 632098.92 | P20: 88903.581 | Q20: 40967.913 | R20: =P20+O20+M20+N20+L20+K20+Q20 -> 129871.49 | S20: 488094.68 | T20: =J20-R20 -> 502227.42
A21: 15 | B21: BASSEY NSONGURUA UDOFIA | C21: PRINC.CONF SEC 1/PPS | D21: 13(8) | E21: 497472.75 | H21: =70000 -> 70000 | I21: =250000 -> 250000 | J21: =E21+F21+G21+H21+I21 -> 817472.75 | L21: 20000 | M21: =68750 -> 68750 | O21: 7791.8313 | P21: 121078.96 | Q21: 39797.82 | R21: =P21+O21+M21+N21+L21+K21+Q21 -> 257418.61 | S21: 540487.46 | T21: =J21-R21 -> 560054.14
A22: 16 | B22: ADUGBA RICHARD TERSEER | C22: ASSIST. CHIEF INFO OFFICER | D22: 13(7) | E22: 482846.58 | H22: =70000 -> 70000 | I22: =100000+50000 -> 150000 | J22: =E22+F22+G22+H22+I22 -> 702846.58 | L22: =10000 -> 10000 | M22: 292813.77 | O22: 7574.6854 | P22: 100695.95 | Q22: 38627.727 | R22: =P22+O22+M22+N22+L22+K22+Q22 -> 449712.13 | S22: 244123.33 | T22: =J22-R22 -> 253134.45
A23: 17 | B23: LUCKY AGWOM | C23: RESEARCH ASSISTANT | D23: 12(9) | E23: 468828.17 | G23: =100000 -> 100000 | I23: =100000+100000 -> 200000 | J23: =E23+F23+G23+H23+I23 -> 768828.17 | L23: =50000+100000 -> 150000 | P23: 114137.94 | Q23: 37506.253 | R23: =P23+O23+M23+N23+L23+K23+Q23 -> 301644.2 | S23: 451957.36 | T23: =J23-R23 -> 467183.97
A24: 18 | B24: IDRIS IBRAHIM | C24: PRINCIPAL RESEARCH OFFICER | D24: 12(9) | E24: 468828.17 | G24: 110000 | I24: 0 | J24: =E24+F24+G24+H24+I24 -> 578828.17 | L24: 0 | N24: 30000 | O24: 7366.5729 | P24: 78611.961 | Q24: 37506.253 | R24: =P24+O24+M24+N24+L24+K24+Q24 -> 153484.79 | S24: 411276.19 | T24: =J24-R24 -> 425343.38
A25: 19 | B25: FARUQ ATOFARATI | C25: PA (SPECIAL DUTIES) TO DG | D25: 10(8) | E25: 381140.67 | H25: =50000+10000 -> 60000 | I25: =100000+100000 -> 200000 | J25: =E25+F25+G25+H25+I25 -> 641140.67 | L25: 150000 | P25: 92416.894 | Q25: 30491.253 | R25: =P25+O25+M25+N25+L25+K25+Q25 -> 272908.15 | S25: 364738.06 | T25: =J25-R25 -> 368232.52
A26: 20 | B26: RASHEEDAT DAIBU | C26: SENIOR INFO. OFFICER | D26: 10(9) | E26: 390135.83 | H26: 60000 | J26: =E26+F26+G26+H26+I26 -> 450135.83 | L26: 50000 | N26: 10000 | O26: 6154.2792 | P26: 56798.724 | Q26: 31210.867 | R26: =P26+O26+M26+N26+L26+K26+Q26 -> 154163.87 | S26: 287116.19 | T26: =J26-R26 -> 295971.96
A27: 21 | B27: VICTOR ASUKWO | C27: SENIOR ICT OFFICER | D27: 10(7) | E27: 372145.33 | F27: 67298.667 | H27: =50000+10000 -> 60000 | J27: =E27+F27+G27+H27+I27 -> 499444 | O27: 5889.4458 | P27: 65980.927 | Q27: 29771.627 | R27: =P27+O27+M27+N27+L27+K27+Q27 -> 101642 | S27: 394160.16 | T27: =J27-R27 -> 397802
A28: 22 | B28: NNANDI LIVINUS ATURE | C28: SENIOR RESEARCH OFFICER | D28: 10(8) | E28: 381140.67 | G28: =110000 -> 110000 | J28: =E28+F28+G28+H28+I28 -> 491140.67 | L28: =10000 -> 10000 | M28: 127777.78 | O28: 6021.8646 | P28: 64332.959 | Q28: 30491.253 | R28: =P28+O28+M28+N28+L28+K28+Q28 -> 238623.86 | S28: 251434.71 | T28: =J28-R28 -> 252516.81
A29: 23 | B29: ABDULRAHMAN A SULAIMAN | C29: STORE OFFICER | D29: 9(10) | E29: 355320.67 | H29: =60000 -> 60000 | J29: =E29+F29+G29+H29+I29 -> 415320.67 | L29: =20000 -> 20000 | M29: =17500 -> 17500 | N29: 50000 | P29: 52141.102 | Q29: 28425.653 | R29: =P29+O29+M29+N29+L29+K29+Q29 -> 168066.76 | S29: 240271.27 | T29: =J29-R29 -> 247253.91
A30: 24 | B30: DARE SHEU MAGBON | C30: ADMINISTRATION OFFICER | D30: 9(9) | E30: 347016.17 | H30: =60000 -> 60000 | J30: =E30+F30+G30+H30+I30 -> 407016.17 | L30: =30000+20000 -> 50000 | M30: 0 | P30: 50765.877 | Q30: 27761.293 | R30: =P30+O30+M30+N30+L30+K30+Q30 -> 128527.17 | S30: 271598.04 | T30: =J30-R30 -> 278489
A31: 25 | B31: ABUBAKAR SULAIMAN SODEEQ | C31: SENIOR M&E OFFICER | D31: 10(7) | E31: 372145.33 | H31: 60000 | J31: =E31+F31+G31+H31+I31 -> 432145.33 | M31: 0 | O31: 5889.4458 | P31: 53867.167 | Q31: 29771.627 | R31: =P31+O31+M31+N31+L31+K31+Q31 -> 89528.239 | S31: 339932.12 | T31: =J31-R31 -> 342617.09
A32: 26 | B32: JIMOH ADEBAYO ZAKA | C32: SENIOR INFO OFFICER | D32: 10(7) | E32: 372145.33 | H32: 60000 | J32: =E32+F32+G32+H32+I32 -> 432145.33 | L32: =20000 -> 20000 | M32: =161429.76+39000+50000 -> 250429.76 | O32: 5889.4458 | P32: 53867.167 | Q32: 29771.627 | R32: =P32+O32+M32+N32+L32+K32+Q32 -> 359958 | S32: 69502.357 | T32: =J32-R32 -> 72187.334
A33: 27 | B33: ABDULMUSHIN TAWFIQ LADAN | C33: ICT OFFICER | D33: 9(9) | E33: 347016.17 | H33: =60000 -> 60000 | J33: =E33+F33+G33+H33+I33 -> 407016.17 | M33: 0 | P33: 50765.877 | Q33: 27761.293 | R33: =P33+O33+M33+N33+L33+K33+Q33 -> 78527.171 | S33: 321853.15 | T33: =J33-R33 -> 328489
A34: 28 | B34: MOHAMMED BELLO | C34: SENIOR PROTOCOL OFFICER | D34: 10(7) | E34: 372145.33 | H34: 60000 | J34: =E34+F34+G34+H34+I34 -> 432145.33 | L34: =0 -> 0 | P34: 54927.267 | Q34: 29771.627 | R34: =P34+O34+M34+N34+L34+K34+Q34 -> 84698.894 | S34: 346192.86 | T34: =J34-R34 -> 347446.44
A35: 29 | B35: HOLINESS PAUL UDO | C35: ADMINISTRATION OFFICER, M&E | D35: 9(8) | E35: 338711.67 | H35: =60000 -> 60000 | J35: =E35+F35+G35+H35+I35 -> 398711.67 | L35: 50000 | O35: 5443.3354 | P35: 48410.852 | Q35: 27096.933 | R35: =P35+O35+M35+N35+L35+K35+Q35 -> 130951.12 | S35: 256765.88 | T35: =J35-R35 -> 267760.55
A36: 30 | B36: CHARITY UDO AKAN | C36: ADMINISTRATION OFFICER, M&E | D36: 9(8) | E36: 338711.67 | H36: =60000 -> 60000 | J36: =E36+F36+G36+H36+I36 -> 398711.67 | L36: 50000 | M36: 60625 | O36: 5443.3354 | P36: 48410.852 | Q36: 27096.933 | R36: =P36+O36+M36+N36+L36+K36+Q36 -> 191576.12 | S36: 199480.69 | T36: =J36-R36 -> 207135.55
A37: 31 | B37: SANI UMAR IBRAHIM | C37: STORE OFFICER | D37: 9(8) | E37: 338711.67 | H37: =60000 -> 60000 | J37: =E37+F37+G37+H37+I37 -> 398711.67 | P37: 49390.652 | Q37: 27096.933 | R37: =P37+O37+M37+N37+L37+K37+Q37 -> 76487.585 | S37: 315426.23 | T37: =J37-R37 -> 322224.08
A38: 32 | B38: FAHAD ABUBUKAR LONGMAN | C38: ICT OFFICER | D38: 9(8) | E38: 338711.67 | H38: =60000 -> 60000 | J38: =E38+F38+G38+H38+I38 -> 398711.67 | O38: 5443.3354 | P38: 48410.852 | Q38: 27096.933 | R38: =P38+O38+M38+N38+L38+K38+Q38 -> 80951.12 | S38: 310106.43 | T38: =J38-R38 -> 317760.55
A39: 33 | B39: HARUNA JIBRIL AMEH | C39: ASST. ADMIN. OFFICER | D39: 8(10) | E39: 308920.67 | H39: 50000 | J39: =E39+F39+G39+H39+I39 -> 358920.67 | L39: 20000 | M39: 0 | O39: 5013.7354 | P39: 41754.79 | Q39: 24713.653 | R39: =P39+O39+M39+N39+L39+K39+Q39 -> 91482.179 | S39: 260618.79 | T39: =J39-R39 -> 267438.49
A40: 34 | B40: RAMATU IBRAHIM ABDULRAHEEM | C40: INFORMATION OFFICER | D40: 8(9) | E40: 301910.75 | H40: 50000 | J40: =E40+F40+G40+H40+I40 -> 351910.75 | L40: 50000 | M40: 45833.33 | N40: 50000 | O40: 4909.1104 | P40: 40612.78 | Q40: 24152.86 | R40: =P40+O40+M40+N40+L40+K40+Q40 -> 215508.08 | S40: 129524.41 | T40: =J40-R40 -> 136402.67
...

Sheet MEMO
A2: NATIONAL INSTITUTE FOR LEGISLATIVE AND DEMOCRATIC STUDIES
A3: INTERNAL MEMO
A4: FROM : DEPUTY DIRECTOR, FINANCE AND ACCOUNTS
A5: THRU: DIRECTOR, FINANCE AND ACCOUNTS
A6: TO: DG
A7: 29TH JANUARY , 2021
A9: SUBJECT: PAYROLL FOR THE MONTH OF JANUARY, 2021
A10: Find below the details of NILDS Staff Payroll for the month of January, 2021
A13: TO: | C13: DIRECTOR, GENERAL
A14: THRU: | C14: DIRECTOR, FINANCE AND ACCOUNT
A15: FROM: | C15: DEPUTY DIRECTOR, FINANCE AND ACCOUNTS
A16: DATE: | C16: 26TH JANUARY 2026
A18: SUBJECT: PAYROLL FOR THE MONTH OF JANUARY 2026
A19: Find below the details of NILDS Staff Payroll for the Month of January 2026: | G19: NGN | H19: NGN
A20: GROSS SALARY FOR JANUARY 2026 | H20: ='JANUARY 2026'!J249 -> 1.2122022e+08
A22: DEDUCTIONS
A23: COOP SOCIETY 1 DEDUCTIONS ( CONTR.& SPEC. SAVINGS) | G23: ='JANUARY 2026'!L249 -> 8086500
A24: COOP 1 LOAN RECOVERY | G24: ='JANUARY 2026'!M249 -> 10235600
A25: COOP SOCIETY 2 DEDUCTIONS ( CONTR.& SPEC. SAVINGS) | G25: ='JANUARY 2026'!N249 -> 2975000
A26: NHF DEDUCTIONS | G26: ='JANUARY 2026'!O249 -> 677813.77
A27: PAYE DEDUCTIONS | G27: ='JANUARY 2026'!P249 -> 17007534
A28: PENSION DEDUCTIONS | G28: ='JANUARY 2026'!Q249 -> 7849660.5
A29: TOTAL DEDUCTIONS FOR JANUARY 2026 | H29: =G23+G24+G25+G27+G26+G28 -> 46832109
A30: NET PAY AS PER JANUARY 2026 PAYROLL | H30: =H20-H29 -> 74388110
A31: NET PAY AS PER DECEMBER 2025 PAYROLL | H31: ='JANUARY 2026'!S249 -> 73541205
A32: NET INCREASE/ (DECREASE) IN PAY FOR JANUARY 2026 | H32: =H30-H31 -> 846905.16
A33: ANALYSED AS FOLLOWS:
A34: Effect of Cooperative 1 Adjustments for January 2026 | H34: 485541.67
A35: Effect of Cooperative 2 Adjustments for January 2026 | H35: =190000-50000 -> 140000
A36: Effect of Annual Steps increase within Grade Levels | H36: -2102396.8
A37: Effect of Changes in Pensions due to changes in steps | H37: 126177.23
A38: Effect of Changes in NHF due to changes in steps | H38: =13714.8 -> 13714.8
A39: Effect of Changes in PAYE Tax due to the Implementation of New Tax Laws | H39: -205647.52
A40: Effect of the Stoppage of payment to Muhammed Osolafia due to voluntary retirement | H40: =578828.16 -> 578828.16
A41: Effect of regularisation of deductions of Bakari Husseini & 1 other | H41: =52361.12 -> 52361.12
A42: Effect of removal of arrears of change of cadre from Ene Vincent-Orugbo | H42: =64516.13 -> 64516.13
H43: =SUM(H34:H42) -> -846905.16
E46: DECEMBER, 2025 | G46: JANUARY, 2026
E47: No. of Staff | F47: N | G47: No. of Staff | H47: N
A48: 1 | B48: Director General's Office | E48: 32 | F48: ='JANUARY 2026'!S47 -> 17180157 | G48: ='JANUARY 2026'!C47 -> 40 | H48: ='JANUARY 2026'!T47 -> 17467625
...

Sheet Changes in PAYE (4)
A1: NATIONAL INSTITUTE FOR LEGISLATIVE AND DEMOCRATIC STUDIES
A2: NATIONAL ASSEMBLY ABUJA
A3: TAX COMPUTATION FOR 2022
A4: S/NO | B4: NAME | C4: N | D4: NO OF MONTHS | E4: ANNUAL SALARY GROSSED UP | F4: ANNUAL RENT RELIEF (20% MAX OF N500,000) | G4: NATIONAL HOUSING SCHEME = 2.5% OF BASIC SALARY | H4: PENSION CONTRIBUTION = 8% OF CONSOLIDATED | I4: NHIS | J4: TOTAL RELIEF | K4: CHARGEABLE INCOME | L4: ANNUAL TAX PAYABLE | N4: MONTHLY TAX PAYABLE | O4: OLD ACTUAL TAX PAYABLE | P4: INCREASE/DECREASE IN PAYE
A5: S/N | B5: DG'S OFFICE
A6: 1 | B6: PROF. ABUBAKAR O. SULAIMAN | C6: 2246372.1 | D6: 12 | E6: =C6*D6 -> 26956465 | H6: 0 | J6: =F6+G6+H6 -> 0 | K6: =E6-J6 -> 26956465 | L6: =IF(K6<=800000,0,IF(K6<=3000000,(K6-800000)*15%,IF(K6<=12000000,330000+(K6-3000000)*18%,IF(K6<=25000000,1950000+(K6-12000000)*21%,IF(K6<=50000000,4680000+(K6-25000000)*23%,10430000+(K6-50000000)*25%))))) -> 5129986.9 | M6: 12 | N6: =L6/M6 -> 427498.91 | O6: 409970.11 | P6: =N6-O6 -> 17528.806
A7: 2 | B7: RAHEEM USMAN AYIGORO | C7: 1095306.8 | D7: 12 | E7: =C7*D7 -> 13143681 | G7: 0 | H7: 869094.48 | J7: =F7+G7+H7 -> 869094.48 | K7: =E7-J7 -> 12274587 | L7: =IF(K7<=800000,0,IF(K7<=3000000,(K7-800000)*15%,IF(K7<=12000000,330000+(K7-3000000)*18%,IF(K7<=25000000,1950000+(K7-12000000)*21%,IF(K7<=50000000,4680000+(K7-25000000)*23%,10430000+(K7-50000000)*25%))))) -> 2007663.2 | M7: 12 | N7: =L7/M7 -> 167305.26 | O7: 175060.05 | P7: =N7-O7 -> -7754.7869
A8: 3 | B8: MARIAM MOHAMMED BELLO | C8: 1295306.8 | D8: 12 | E8: =C8*D8 -> 15543681 | G8: 0 | H8: 0 | J8: =F8+G8+H8 -> 0 | K8: =E8-J8 -> 15543681 | L8: =IF(K8<=800000,0,IF(K8<=3000000,(K8-800000)*15%,IF(K8<=12000000,330000+(K8-3000000)*18%,IF(K8<=25000000,1950000+(K8-12000000)*21%,IF(K8<=50000000,4680000+(K8-25000000)*23%,10430000+(K8-50000000)*25%))))) -> 2694173 | M8: 12 | N8: =L8/M8 -> 224514.42 | O8: 227365.56 | P8: =N8-O8 -> -2851.1452
A9: 4 | B9: DR IKEME ARTHUR J.O | C9: 1085306.8 | D9: 12 | E9: =C9*D9 -> 13023681 | G9: 166400.85 | H9: 869094.48 | J9: =F9+G9+H9 -> 1035495.3 | K9: =E9-J9 -> 11988186 | L9: =IF(K9<=800000,0,IF(K9<=3000000,(K9-800000)*15%,IF(K9<=12000000,330000+(K9-3000000)*18%,IF(K9<=25000000,1950000+(K9-12000000)*21%,IF(K9<=50000000,4680000+(K9-25000000)*23%,10430000+(K9-50000000)*25%))))) -> 1947873.4 | M9: 12 | N9: =L9/M9 -> 162322.79 | O9: 170477.64 | P9: =N9-O9 -> -8154.8523
A10: 5 | B10: ANDRAWUS MUSA | C10: 1045306.8 | D10: 12 | E10: =C10*D10 -> 12543681 | G10: 166400.85 | H10: 869094.48 | J10: =F10+G10+H10 -> 1035495.3 | K10: =E10-J10 -> 11508186 | L10: =IF(K10<=800000,0,IF(K10<=3000000,(K10-800000)*15%,IF(K10<=12000000,330000+(K10-3000000)*18%,IF(K10<=25000000,1950000+(K10-12000000)*21%,IF(K10<=50000000,4680000+(K10-25000000)*23%,10430000+(K10-50000000)*25%))))) -> 1861473.4 | M10: 12 | N10: =L10/M10 -> 155122.79 | O10: 158706.48 | P10: =N10-O10 -> -3583.6962
A11: 6 | B11: DR FRANCIS NDUM OJIE | C11: 1104477 | D11: 12 | E11: =C11*D11 -> 13253724 | G11: 137703.15 | H11: 714697.92 | J11: =F11+G11+H11 -> 852401.07 | K11: =E11-J11 -> 12401323 | L11: =IF(K11<=800000,0,IF(K11<=3000000,(K11-800000)*15%,IF(K11<=12000000,330000+(K11-3000000)*18%,IF(K11<=25000000,1950000+(K11-12000000)*21%,IF(K11<=50000000,4680000+(K11-25000000)*23%,10430000+(K11-50000000)*25%))))) -> 2034277.8 | M11: 12 | N11: =L11/M11 -> 169523.15 | O11: 173285.16 | P11: =N11-O11 -> -3762.0045
A12: 7 | B12: ALI ABDULLAHI | C12: 780713.92 | D12: 12 | E12: =C12*D12 -> 9368567 | G12: 0 | H12: 672685.36 | J12: =F12+G12+H12 -> 672685.36 | K12: =E12-J12 -> 8695881.6 | L12: =IF(K12<=800000,0,IF(K12<=3000000,(K12-800000)*15%,IF(K12<=12000000,330000+(K12-3000000)*18%,IF(K12<=25000000,1950000+(K12-12000000)*21%,IF(K12<=50000000,4680000+(K12-25000000)*23%,10430000+(K12-50000000)*25%))))) -> 1355258.7 | M12: 12 | N12: =L12/M12 -> 112938.22 | O12: 119506.61 | P12: =N12-O12 -> -6568.3825
A13: 8 | B13: EMILY EKHIDE | C13: 954477 | D13: 12 | E13: =C13*D13 -> 11453724 | G13: 0 | H13: 714697.92 | J13: =F13+G13+H13 -> 714697.92 | K13: =E13-J13 -> 10739026 | L13: =IF(K13<=800000,0,IF(K13<=3000000,(K13-800000)*15%,IF(K13<=12000000,330000+(K13-3000000)*18%,IF(K13<=25000000,1950000+(K13-12000000)*21%,IF(K13<=50000000,4680000+(K13-25000000)*23%,10430000+(K13-50000000)*25%))))) -> 1723024.7 | M13: 12 | N13: =L13/M13 -> 143585.39 | O13: 146625.94 | P13: =N13-O13 -> -3040.5446
A14: 9 | B14: DORIS DAKDA AARON | C14: 963911.08 | D14: 12 | E14: =C14*D14 -> 11566933 | G14: 107120 | H14: 550954.64 | J14: =F14+G14+H14 -> 658074.64 | K14: =E14-J14 -> 10908858 | L14: =IF(K14<=800000,0,IF(K14<=3000000,(K14-800000)*15%,IF(K14<=12000000,330000+(K14-3000000)*18%,IF(K14<=25000000,1950000+(K14-12000000)*21%,IF(K14<=50000000,4680000+(K14-25000000)*23%,10430000+(K14-50000000)*25%))))) -> 1753594.5 | M14: 12 | N14: =L14/M14 -> 146132.88 | O14: 152140.98 | P14: =N14-O14 -> -6008.101
A15: 10 | B15: ABDULSALAM S. MUSTAPHA | C15: 852595.5 | D15: 12 | E15: =C15*D15 -> 10231146 | G15: 0 | H15: 693691.68 | J15: =F15+G15+H15 -> 693691.68 | K15: =E15-J15 -> 9537454.3 | L15: =IF(K15<=800000,0,IF(K15<=3000000,(K15-800000)*15%,IF(K15<=12000000,330000+(K15-3000000)*18%,IF(K15<=25000000,1950000+(K15-12000000)*21%,IF(K15<=50000000,4680000+(K15-25000000)*23%,10430000+(K15-50000000)*25%))))) -> 1506741.8 | M15: 12 | N15: =L15/M15 -> 125561.81 | O15: 127400.77 | P15: =N15-O15 -> -1838.9581
A16: 11 | B16: PERCY TERFA GBAHABO | C16: 682419.5 | D16: 12 | E16: =C16*D16 -> 8189034 | G16: 0 | H16: 520722.72 | J16: =F16+G16+H16 -> 520722.72 | K16: =E16-J16 -> 7668311.3 | L16: =IF(K16<=800000,0,IF(K16<=3000000,(K16-800000)*15%,IF(K16<=12000000,330000+(K16-3000000)*18%,IF(K16<=25000000,1950000+(K16-12000000)*21%,IF(K16<=50000000,4680000+(K16-25000000)*23%,10430000+(K16-50000000)*25%))))) -> 1170296 | M16: 12 | N16: =L16/M16 -> 97524.669 | O16: 101376.05 | P16: =N16-O16 -> -3851.385
A17: 12 | B17: HASSANA AHMED IBRAHIM | C17: 861351.33 | D17: 12 | E17: =C17*D17 -> 10336216 | G17: 101319.25 | H17: 519697.28 | J17: =F17+G17+H17 -> 621016.53 | K17: =E17-J17 -> 9715199.5 | L17: =IF(K17<=800000,0,IF(K17<=3000000,(K17-800000)*15%,IF(K17<=12000000,330000+(K17-3000000)*18%,IF(K17<=25000000,1950000+(K17-12000000)*21%,IF(K17<=50000000,4680000+(K17-25000000)*23%,10430000+(K17-50000000)*25%))))) -> 1538735.9 | M17: 12 | N17: =L17/M17 -> 128227.99 | O17: 131567.97 | P17: =N17-O17 -> -3339.9777
A18: 13 | B18: IKIP LEBO | C18: 582098.92 | D18: 12 | E18: =C18*D18 -> 6985187 | G18: 96107.725 | H18: 491614.96 | J18: =F18+G18+H18 -> 587722.69 | K18: =E18-J18 -> 6397464.3 | L18: =IF(K18<=800000,0,IF(K18<=3000000,(K18-800000)*15%,IF(K18<=12000000,330000+(K18-3000000)*18%,IF(K18<=25000000,1950000+(K18-12000000)*21%,IF(K18<=50000000,4680000+(K18-25000000)*23%,10430000+(K18-50000000)*25%))))) -> 941543.58 | M18: 12 | N18: =L18/M18 -> 78461.965 | O18: 78484.222 | P18: =N18-O18 -> -22.256902
... A25: 20 | B25: RASHEEDAT DAIBU | C25: 450135.83 | D25: 12 | E25: =C25*D25 -> 5401630 | G25: 73851.35 | H25: 374530.4 | J25: =F25+G25+H25 -> 448381.75 | K25: =E25-J25 -> 4953248.3 | L25: =IF(K25<=800000,0,IF(K25<=3000000,(K25-800000)*15%,IF(K25<=12000000,330000+(K25-3000000)*18%,IF(K25<=25000000,1950000+(K25-12000000)*21%,IF(K25<=50000000,4680000+(K25-25000000)*23%,10430000+(K25-50000000)*25%))))) -> 681584.69 | M25: 12 | N25: =L25/M25 -> 56798.724 | O25: 57511.354 | P25: =N25-O25 -> -712.63028
A26: 21 | B26: ELIZABETH OGECHUKWU ONYEAKU | C26: 0 | D26: 12 | E26: =C26*D26 -> 0 | G26: 0 | H26: 0 | J26: =F26+G26+H26 -> 0 | K26: =E26-J26 -> 0 | L26: =IF(K26<=800000,0,IF(K26<=3000000,(K26-800000)*15%,IF(K26<=12000000,330000+(K26-3000000)*18%,IF(K26<=25000000,1950000+(K26-12000000)*21%,IF(K26<=50000000,4680000+(K26-25000000)*23%,10430000+(K26-50000000)*25%))))) -> 0 | M26: 12 | N26: =L26/M26 -> 0 | P26: =N26-O26 -> 0
A27: 22 | B27: VICTOR ASUKWO | C27: 499444 | D27: 12 | E27: =C27*D27 -> 5993328 | G27: 70673.35 | H27: 357259.52 | J27: =F27+G27+H27 -> 427932.87 | K27: =E27-J27 -> 5565395.1 | L27: =IF(K27<=800000,0,IF(K27<=3000000,(K27-800000)*15%,IF(K27<=12000000,330000+(K27-3000000)*18%,IF(K27<=25000000,1950000+(K27-12000000)*21%,IF(K27<=50000000,4680000+(K27-25000000)*23%,10430000+(K27-50000000)*25%))))) -> 791771.12 | M27: 12 | N27: =L27/M27 -> 65980.927 | O27: 69102.189 | P27: =N27-O27 -> -3121.2623
A28: 23 | B28: NNANDI LIVINUS ATURE | C28: 491140.67 | D28: 12 | E28: =C28*D28 -> 5893688 | G28: 72262.375 | H28: 365895.04 | J28: =F28+G28+H28 -> 438157.41 | K28: =E28-J28 -> 5455530.6 | L28: =IF(K28<=800000,0,IF(K28<=3000000,(K28-800000)*15%,IF(K28<=12000000,330000+(K28-3000000)*18%,IF(K28<=25000000,1950000+(K28-12000000)*21%,IF(K28<=50000000,4680000+(K28-25000000)*23%,10430000+(K28-50000000)*25%))))) -> 771995.51 | M28: 12 | N28: =L28/M28 -> 64332.959 | O28: 56180.845 | P28: =N28-O28 -> 8152.1135
A29: 24 | B29: ABDULRAHMAN A SULAIMAN | C29: 415320.67 | D29: 12 | E29: =C29*D29 -> 4983848 | G29: 0 | H29: 341107.84 | J29: =F29+G29+H29 -> 341107.84 | K29: =E29-J29 -> 4642740.2 | L29: =IF(K29<=800000,0,IF(K29<=3000000,(K29-800000)*15%,IF(K29<=12000000,330000+(K29-3000000)*18%,IF(K29<=25000000,1950000+(K29-12000000)*21%,IF(K29<=50000000,4680000+(K29-25000000)*23%,10430000+(K29-50000000)*25%))))) -> 625693.23 | M29: 12 | N29: =L29/M29 -> 52141.102 | O29: 51483.602 | P29: =N29-O29 -> 657.50005
A30: 25 | B30: DARE SHEU MAGBON | C30: 407016.17 | D30: 12 | E30: =C30*D30 -> 4884194 | G30: 0 | H30: 333135.52 | J30: =F30+G30+H30 -> 333135.52 | K30: =E30-J30 -> 4551058.5 | L30: =IF(K30<=800000,0,IF(K30<=3000000,(K30-800000)*15%,IF(K30<=12000000,330000+(K30-3000000)*18%,IF(K30<=25000000,1950000+(K30-12000000)*21%,IF(K30<=50000000,4680000+(K30-25000000)*23%,10430000+(K30-50000000)*25%))))) -> 609190.53 | M30: 12 | N30: =L30/M30 -> 50765.877 | O30: 50016.695 | P30: =N30-O30 -> 749.18173
A31: 26 | B31: ABUBAKAR SULAIMAN SODEEQ | C31: 432145.33 | D31: 12 | E31: =C31*D31 -> 5185744 | G31: 70673.35 | H31: 357259.52 | J31: =F31+G31+H31 -> 427932.87 | K31: =E31-J31 -> 4757811.1 | L31: =IF(K31<=800000,0,IF(K31<=3000000,(K31-800000)*15%,IF(K31<=12000000,330000+(K31-3000000)*18%,IF(K31<=25000000,1950000+(K31-12000000)*21%,IF(K31<=50000000,4680000+(K31-25000000)*23%,10430000+(K31-50000000)*25%))))) -> 646406 | M31: 12 | N31: =L31/M31 -> 53867.167 | O31: 56180.845 | P31: =N31-O31 -> -2313.6783
A32: 27 | B32: JIMOH ADEBAYO ZAKA | C32: 432145.33 | D32: 12 | E32: =C32*D32 -> 5185744 | G32: 70673.35 | H32: 357259.52 | J32: =F32+G32+H32 -> 427932.87 | K32: =E32-J32 -> 4757811.1 | L32: =IF(K32<=800000,0,IF(K32<=3000000,(K32-800000)*15%,IF(K32<=12000000,330000+(K32-3000000)*18%,IF(K32<=25000000,1950000+(K32-12000000)*21%,IF(K32<=50000000,4680000+(K32-25000000)*23%,10430000+(K32-50000000)*25%))))) -> 646406 | M32: 12 | N32: =L32/M32 -> 53867.167 | O32: 56180.845 | P32: =N32-O32 -> -2313.6783
A33: 28 | B33: ABDULMUSHIN TAWFIQ LADAN | C33: 407016.17 | D33: 12 | E33: =C33*D33 -> 4884194 | G33: 0 | H33: 333135.52 | J33: =F33+G33+H33 -> 333135.52 | K33: =E33-J33 -> 4551058.5 | L33: =IF(K33<=800000,0,IF(K33<=3000000,(K33-800000)*15%,IF(K33<=12000000,330000+(K33-3000000)*18%,IF(K33<=25000000,1950000+(K33-12000000)*21%,IF(K33<=50000000,4680000+(K33-25000000)*23%,10430000+(K33-50000000)*25%))))) -> 609190.53 | M33: 12 | N33: =L33/M33 -> 50765.877 | O33: 49761.581 | P33: =N33-O33 -> 1004.296
A34: 29 | B34: MOHAMMED BELLO | C34: 432145.33 | D34: 12 | E34: =C34*D34 -> 5185744 | G34: 0 | H34: 357259.52 | J34: =F34+G34+H34 -> 357259.52 | K34: =E34-J34 -> 4828484.5 | L34: =IF(K34<=800000,0,IF(K34<=3000000,(K34-800000)*15%,IF(K34<=12000000,330000+(K34-3000000)*18%,IF(K34<=25000000,1950000+(K34-12000000)*21%,IF(K34<=50000000,4680000+(K34-25000000)*23%,10430000+(K34-50000000)*25%))))) -> 659127.21 | M34: 12 | N34: =L34/M34 -> 54927.267 | O34: 56180.845 | P34: =N34-O34 -> -1253.578
A35: 30 | B35: HOLINESS PAUL UDO | C35: 398711.67 | D35: 12 | E35: =C35*D35 -> 4784540 | G35: 65320.025 | H35: 325163.2 | J35: =F35+G35+H35 -> 390483.22 | K35: =E35-J35 -> 4394056.8 | L35: =IF(K35<=800000,0,IF(K35<=3000000,(K35-800000)*15%,IF(K35<=12000000,330000+(K35-3000000)*18%,IF(K35<=25000000,1950000+(K35-12000000)*21%,IF(K35<=50000000,4680000+(K35-25000000)*23%,10430000+(K35-50000000)*25%))))) -> 580930.22 | M35: 12 | N35: =L35/M35 -> 48410.852 | O35: 48549.774 | P35: =N35-O35 -> -138.92224
A36: 31 | B36: CHARITY UDO AKAN | C36: 398711.67 | D36: 12 | E36: =C36*D36 -> 4784540 | G36: 65320.025 | H36: 325163.2 | J36: =F36+G36+H36 -> 390483.22 | K36: =E36-J36 -> 4394056.8 | L36: =IF(K36<=800000,0,IF(K36<=3000000,(K36-800000)*15%,IF(K36<=12000000,330000+(K36-3000000)*18%,IF(K36<=25000000,1950000+(K36-12000000)*21%,IF(K36<=50000000,4680000+(K36-25000000)*23%,10430000+(K36-50000000)*25%))))) -> 580930.22 | M36: 12 | N36: =L36/M36 -> 48410.852 | O36: 48549.951 | P36: =N36-O36 -> -139.09888
A37: 32 | B37: SANI UMAR IBRAHIM | C37: 398711.67 | D37: 12 | E37: =C37*D37 -> 4784540 | G37: 0 | H37: 325163.2 | J37: =F37+G37+H37 -> 325163.2 | K37: =E37-J37 -> 4459376.8 | L37: =IF(K37<=800000,0,IF(K37<=3000000,(K37-800000)*15%,IF(K37<=12000000,330000+(K37-3000000)*18%,IF(K37<=25000000,1950000+(K37-12000000)*21%,IF(K37<=50000000,4680000+(K37-25000000)*23%,10430000+(K37-50000000)*25%))))) -> 592687.82 | M37: 12 | N37: =L37/M37 -> 49390.652 | O37: 48550.127 | P37: =N37-O37 -> 840.52485
A38: 33 | B38: FAHAD ABUBUKAR LONGMAN | C38: 398711.67 | D38: 12 | E38: =C38*D38 -> 4784540 | G38: 65320.025 | H38: 325163.2 | J38: =F38+G38+H38 -> 390483.22 | K38: =E38-J38 -> 4394056.8 | L38: =IF(K38<=800000,0,IF(K38<=3000000,(K38-800000)*15%,IF(K38<=12000000,330000+(K38-3000000)*18%,IF(K38<=25000000,1950000+(K38-12000000)*21%,IF(K38<=50000000,4680000+(K38-25000000)*23%,10430000+(K38-50000000)*25%))))) -> 580930.22 | M38: 12 | N38: =L38/M38 -> 48410.852 | O38: 48550.127 | P38: =N38-O38 -> -139.27552
... A46: 41 | B46: ALIYU GARBA LERE | C46: 344900.83 | D46: 12 | E46: =C46*D46 -> 4138810 | G46: 0 | H46: 283104.8 | J46: =F46+G46+H46 -> 283104.8 | K46: =E46-J46 -> 3855705.2 | L46: =IF(K46<=800000,0,IF(K46<=3000000,(K46-800000)*15%,IF(K46<=12000000,330000+(K46-3000000)*18%,IF(K46<=25000000,1950000+(K46-12000000)*21%,IF(K46<=50000000,4680000+(K46-25000000)*23%,10430000+(K46-50000000)*25%))))) -> 484026.94 | M46: 12 | N46: =L46/M46 -> 40335.578 | O46: 40063.241 | P46: =N46-O46 -> 272.33669
B47: TOTAL | C47: =SUM(C6:C46) -> 26032451 | E47: =SUM(E6:E46) -> 312389414 | F47: =SUM(F6:F46) -> 0 | G47: =SUM(G6:G46) -> 1778670.7 | H47: =SUM(H6:H46) -> 16947335 | I47: =SUM(I6:I46) -> 0 | J47: =SUM(J6:J46) -> 18726005 | K47: =SUM(K6:K46) -> 2.9366341e+08 | L47: =SUM(L6:L46) -> 45073825 | ... P47: =SUM(P6:P46) -> -47758.25
B49: INTERNAL AUDIT
A50: 1 | B50: OSANAIYE DAVID AKINYEMI | C50: 1847106.4 | D50: 12 | E50: =C50*D50 -> 22165277 | G50: 0 | H50: 1677222.2 | J50: =F50+G50+H50 -> 1677222.2 | K50: =E50-J50 -> 20488055 | L50: =IF(K50<=800000,0,IF(K50<=3000000,(K50-800000)*15%,IF(K50<=12000000,330000+(K50-3000000)*18%,IF(K50<=25000000,1950000+(K50-12000000)*21%,IF(K50<=50000000,4680000+(K50-25000000)*23%,10430000+(K50-50000000)*25%))))) -> 3732491.5 | M50: 12 | N50: =L50/M50 -> 311040.96 | O50: 306475.54 | P50: =N50-O50 -> 4565.4156
A51: 2 | B51: EVELYN ETONKE AGAN | C51: 802595.5 | D51: 12 | E51: =C51*D51 -> 9631146 | G51: 0 | H51: 693691.68 | J51: =F51+G51+H51 -> 693691.68 | K51: =E51-J51 -> 8937454.3 | L51: =IF(K51<=800000,0,IF(K51<=3000000,(K51-800000)*15%,IF(K51<=12000000,330000+(K51-3000000)*18%,IF(K51<=25000000,1950000+(K51-12000000)*21%,IF(K51<=50000000,4680000+(K51-25000000)*23%,10430000+(K51-50000000)*25%))))) -> 1398741.8 | M51: 12 | N51: =L51/M51 -> 116561.81 | O51: 117800.77 | P51: =N51-O51 -> -1238.9581
A52: 3 | B52: JAMILA ABDUL | C52: 450135.83 | D52: 12 | E52: =C52*D52 -> 5401630 | G52: 73851.35 | H52: 374530.4 | J52: =F52+G52+H52 -> 448381.75 | K52: =E52-J52 -> 4953248.3 | L52: =IF(K52<=800000,0,IF(K52<=3000000,(K52-800000)*15%,IF(K52<=12000000,330000+(K52-3000000)*18%,IF(K52<=25000000,1950000+(K52-12000000)*21%,IF(K52<=50000000,4680000+(K52-25000000)*23%,10430000+(K52-50000000)*25%))))) -> 681584.69 | M52: 12 | N52: =L52/M52 -> 56798.724 | O52: 57511.354 | P52: =N52-O52 -> -712.63028
A53: 4 | B53: IJEOMA EWELUKWA | C53: 514993.58 | D53: 12 | E53: =C53*D53 -> 6179923 | G53: 0 | H53: 436793.84 | J53: =F53+G53+H53 -> 436793.84 | K53: =E53-J53 -> 5743129.2 | L53: =IF(K53<=800000,0,IF(K53<=3000000,(K53-800000)*15%,IF(K53<=12000000,330000+(K53-3000000)*18%,IF(K53<=25000000,1950000+(K53-12000000)*21%,IF(K53<=50000000,4680000+(K53-25000000)*23%,10430000+(K53-50000000)*25%))))) -> 823763.25 | M53: 12 | N53: =L53/M53 -> 68646.937 | O53: 66777.482 | P53: =N53-O53 -> 1869.455
A54: 5 | B54: HASSAN ABDULHADI | C54: 398711.67 | D54: 12 | E54: =C54*D54 -> 4784540 | G54: 65320.025 | H54: 325163.2 | J54: =F54+G54+H54 -> 390483.22 | K54: =E54-J54 -> 4394056.8 | L54: =IF(K54<=800000,0,IF(K54<=3000000,(K54-800000)*15%,IF(K54<=12000000,330000+(K54-3000000)*18%,IF(K54<=25000000,1950000+(K54-12000000)*21%,IF(K54<=50000000,4680000+(K54-25000000)*23%,10430000+(K54-50000000)*25%))))) -> 580930.22 | M54: 12 | N54: =L54/M54 -> 48410.852 | O54: 48549.774 | P54: =N54-O54 -> -138.92224
...

Sheet New Steps, Pensions & NHF
A1: NATIONAL INSTITUTE FOR LEGISLATIVE AND DEMOCRATIC STUDIES
A2: STAFF PAYROLL FOR THE MONTH OF JANUARY 2026
E3: ='[1]FEB 08'!E11/'[1]FEB 08'!M11 -> #REF!
B4: STAFF NAME | C4: DESIGNATION | D4: OLD GRADE LEVEL | E4: OLD BASIC SALARY | F4: NEW GRADE LEVEL | G4: NEW BASIC SALARY | H4: CHANGE IN STEPS (GROSS) | I4: OLD EMPLOYEE PENSIONS | J4: NEW EMPLOYEE PENSIONS | K4: CHANGES IN PENSIONS | L4: NEW ANNUAL PENSIONS | M4: NEW GRADE LEVEL | N4: NEW BASIC | O4: NHF 2.5% | P4: OLD NHF DED. | Q4: INCREASE IN NHF | R4: NHF ANNUAL
E5: N | G5: N | H5: N | I5: N | J5: N | K5: N | L5: N | P5: N
A6: S/N | B6: DG'S OFFICE
A7: 1 | B7: PROF. ABUBAKAR O. SULAIMAN | C7: DIRECTOR GENERAL | D7: CONSOL | E7: 1971137.1 | F7: CONSOL | G7: 1971137.1 | H7: =G7-E7 -> 0 | I7: 0 | K7: =J7-I7 -> 0 | L7: =J7*12 -> 0 | M7: CONSOL | O7: =N7*0.025 -> 0
A8: 2 | B8: RAHEEM USMAN AYIGORO | C8: SA-INFRASTRUCTURE | D8: 16 (9) | E8: 905306.75 | F8: 16 (9) | G8: 905306.75 | H8: =G8-E8 -> 0 | I8: 72424.54 | J8: =G8*0.08 -> 72424.54 | K8: =J8-I8 -> 0 | L8: =J8*12 -> 869094.48 | M8: 16 (9) | N8: 554669.5 | Q8: =O8-P8 -> 0 | R8: =O8*12 -> 0
A9: 3 | B9: MARIAM MOHAMMED BELLO | C9: SA- SPECIAL DUTIES | D9: 16 (9) | E9: 905306.75 | F9: 16 (9) | G9: 905306.75 | H9: =G9-E9 -> 0 | K9: =J9-I9 -> 0 | L9: =J9*12 -> 0 | M9: 16 (9) | O9: =N9*0.025 -> 0 | Q9: =O9-P9 -> 0 | R9: =O9*12 -> 0
A10: 4 | B10: DR IKEME ARTHUR J.O | C10: DEPUTY DIRECTOR, M&E | D10: 16 (9) | E10: 905306.75 | F10: 16 (9) | G10: 905306.75 | H10: =G10-E10 -> 0 | I10: 72424.54 | J10: =G10*0.08 -> 72424.54 | K10: =J10-I10 -> 0 | L10: =J10*12 -> 869094.48 | M10: 16 (9) | N10: 554669.5 | O10: =N10*0.025 -> 13866.737 | P10: 13866.737 | Q10: =O10-P10 -> 0 | R10: =O10*12 -> 166400.85
A11: 5 | B11: ANDRAWUS MUSA | C11: DEP. DIRECTOR, STORES & PROCUREMENT | D11: 16(8) | E11: 879008.92 | F11: 16(9) | G11: 905306.75 | H11: =G11-E11 -> 26297.833 | I11: 68216.887 | J11: =G11*0.08 -> 72424.54 | K11: =J11-I11 -> 4207.6533 | L11: =J11*12 -> 869094.48 | M11: 16(9) | N11: 554669.5 | O11: =N11*0.025 -> 13866.737 | P11: 13084.663 | Q11: =O11-P11 -> 782.075 | R11: =O11*12 -> 166400.85
A12: 6 | B12: DR FRANCIS NDUM OJIE | C12: AD, TRAINING & IC./SA TO DG | D12: 15(8) | E12: 722595.5 | F12: 15(9) | G12: 744477 | H12: =G12-E12 -> 21881.5 | I12: 57807.64 | J12: =G12*0.08 -> 59558.16 | K12: =J12-I12 -> 1750.52 | L12: =J12*12 -> 714697.92 | M12: 15(9) | N12: 459010.5 | O12: =N12*0.025 -> 11475.263 | P12: 11149.896 | Q12: =O12-P12 -> 325.36667 | R12: =O12*12 -> 137703.15
A13: 7 | B13: ALI ABDULLAHI | C13: ASST DIRECTOR ICT | D13: 15(7) | E13: 700713.92 | F13: 15(7) | G13: 700713.92 | H13: =G13-E13 -> 0 | I13: 56057.113 | J13: =G13*0.08 -> 56057.113 | K13: =J13-I13 -> 0 | L13: =J13*12 -> 672685.36 | M13: 15(7) | N13: 432981.08 | Q13: =O13-P13 -> 0 | R13: =O13*12 -> 0
A14: 8 | B14: EMILY EKHIDE | C14: SENIOR RESEARCH FELLOW | D14: 15(8) | E14: 722595.5 | F14: 15(9) | G14: 744477 | H14: =G14-E14 -> 21881.5 | I14: 57807.64 | J14: =G14*0.08 -> 59558.16 | K14: =J14-I14 -> 1750.52 | L14: =J14*12 -> 714697.92 | M14: 15(9) | N14: 459010.5 | Q14: =O14-P14 -> 0 | R14: =O14*12 -> 0
A15: 9 | B15: DORIS DAKDA AARON | C15: RESEARCH FELLOW I | D15: 14(9) | E15: 558165.25 | F15: 14(10) | G15: 573911.08 | H15: =G15-E15 -> 15745.833 | I15: 44653.22 | J15: =G15*0.08 -> 45912.887 | K15: =J15-I15 -> 1259.6667 | L15: =J15*12 -> 550954.64 | M15: 14(10) | N15: 357066.67 | O15: =N15*0.025 -> 8926.6667 | P15: 8692.8979 | Q15: =O15-P15 -> 233.76875 | R15: =O15*12 -> 107120
A16: 10 | B16: ABDULSALAM S. MUSTAPHA | C16: ASST. DIRECTOR ICT | D16: 15(7) | E16: 700713.92 | F16: 15(8) | G16: 722595.5 | H16: =G16-E16 -> 21881.583 | I16: 56057.113 | J16: =G16*0.08 -> 57807.64 | K16: =J16-I16 -> 1750.5267 | L16: =J16*12 -> 693691.68 | M16: 15(8) | N16: 445995.83 | Q16: =O16-P16 -> 0 | R16: =O16*12 -> 0
A17: 11 | B17: PERCY TERFA GBAHABO | C17: RESEARCH FELLOW 1 | D17: 14(7) | E17: 542419.5 | F17: 14(8) | G17: ='[21] FGN 2024 MGT Monthly'!$I$42+'[21]Peculiar Allowance'!$I$42 -> 542419.5 | H17: =G17-E17 -> 0 | I17: 42133.887 | J17: =G17*0.08 -> 43393.56 | K17: =J17-I17 -> 1259.6733 | L17: =J17*12 -> 520722.72 | M17: 14(8) | N17: 338365.25 | Q17: =O17-P17 -> 0 | R17: =O17*12 -> 0
A18: 12 | B18: HASSANA AHMED IBRAHIM | C18: PA- TO DG | D18: 13(10) | E18: 526725.08 | F18: 13(11) | G18: ='[21]Peculiar Allowance'!$L$41+'[21] FGN 2024 MGT Monthly'!$L$41 -> 541351.33 | H18: =G18-E18 -> 14626.25 | I18: 42138.007 | J18: =G18*0.08 -> 43308.107 | K18: =J18-I18 -> 1170.1 | L18: =J18*12 -> 519697.28 | M18: 13(11) | N18: 337730.83 | O18: =N18*0.025 -> 8443.2708 | P18: 8226.1229 | Q18: =O18-P18 -> 217.14792 | R18: =O18*12 -> 101319.25
A19: 13 | B19: IKIP LEBO | C19: ASST CHIEF PROC. OFFICER | D19: 13 (8) | E19: 497472.75 | F19: 13 (9) | G19: ='[21] FGN 2024 MGT Monthly'!$J$41+'[21]Peculiar Allowance'!$J$41 -> 512098.92 | H19: =G19-E19 -> 14626.167 | I19: 39797.82 | J19: =G19*0.08 -> 40967.913 | K19: =J19-I19 -> 1170.0933 | L19: =J19*12 -> 491614.96 | M19: 13 (9) | N19: ='[21] FGN 2024 MGT Monthly'!$J$41 -> 320359.08 | O19: =N19*0.025 -> 8008.9771 | P19: 7791.8313 | Q19: =O19-P19 -> 217.14583 | R19: =O19*12 -> 96107.725
A20: 14 | B20: ALABI ADESINA MUHYDEEN | C20: HEAD, NILDS LIAISON OFFICE | D20: 13 (8) | E20: 497472.75 | F20: 13 (9) | G20: ='[21] FGN 2024 MGT Monthly'!$J$41+'[21]Peculiar Allowance'!$J$41 -> 512098.92 | H20: =G20-E20 -> 14626.167 | I20: 39797.82 | J20: =G20*0.08 -> 40967.913 | K20: =J20-I20 -> 1170.0933 | L20: =J20*12 -> 491614.96 | M20: 13 (9) | N20: ='[21] FGN 2024 MGT Monthly'!$J$41 -> 320359.08 | Q20: =O20-P20 -> 0 | R20: =O20*12 -> 0
A21: 15 | B21: BASSEY NSONGURUA UDOFIA | C21: PRINC.CONF SEC 1/PPS | D21: 13(7) | E21: 482846.58 | F21: 13(8) | G21: 497472.75 | H21: =G21-E21 -> 14626.167 | I21: 42138.007 | J21: =G21*0.08 -> 39797.82 | K21: =J21-I21 -> -2340.1867 | L21: =J21*12 -> 477573.84 | M21: 13(8) | N21: 311673.25 | O21: =N21*0.025 -> 7791.8313 | P21: 7777.3604 | Q21: =O21-P21 -> 14.470833 | R21: =O21*12 -> 93501.975
A22: 16 | B22: ADUGBA RICHARD TERSEER | C22: ASSIST. CHIEF INFO OFFICER | D22: 13(7) | E22: 482846.58 | F22: 13(7) | G22: 482846.58 | H22: =G22-E22 -> 0 | I22: 42138.007 | J22: =G22*0.08 -> 38627.727 | K22: =J22-I22 -> -3510.28 | L22: =J22*12 -> 463532.72 | M22: 13(7) | N22: 302987.42 | O22: =N22*0.025 -> 7574.6854 | P22: 7571.9667 | Q22: =O22-P22 -> 2.71875 | R22: =O22*12 -> 90896.225
A23: 17 | B23: LUCKY AGWOM | C23: RESEARCH ASSISTANT | D23: 12(8) | E23: 454993.58 | F23: 12(9) | G23: 468828.17 | H23: =G23-E23 -> 13834.583 | I23: 36399.487 | J23: =G23*0.08 -> 37506.253 | K23: =J23-I23 -> 1106.7667 | L23: =J23*12 -> 450075.04 | M23: 12(9) | N23: 294662.92 | Q23: =O23-P23 -> 0 | R23: =O23*12 -> 0
A24: 18 | B24: IDRIS IBRAHIM | C24: PRINCIPAL RESEARCH OFFICER | D24: 12(8) | E24: 454993.58 | F24: 12(9) | G24: 468828.17 | H24: =G24-E24 -> 13834.583 | I24: 36399.487 | J24: =G24*0.08 -> 37506.253 | K24: =J24-I24 -> 1106.7667 | L24: =J24*12 -> 450075.04 | M24: 12(9) | N24: 294662.92 | O24: =N24*0.025 -> 7366.5729 | P24: 7161.1771 | Q24: =O24-P24 -> 205.39583 | R24: =O24*12 -> 88398.875
A25: 19 | B25: FARUQ ATOFARATI | C25: PA (SPECIAL DUTIES) TO DG | D25: 10(7) | E25: 381140.67 | F25: 10(8) | G25: 381140.67 | H25: =G25-E25 -> 0 | I25: 30491.253 | J25: =G25*0.08 -> 30491.253 | K25: =J25-I25 -> 0 | L25: =J25*12 -> 365895.04 | M25: 10(8) | N25: 240874.58 | Q25: =O25-P25 -> 0 | R25: =O25*12 -> 0
A26: 20 | B26: RASHEEDAT DAIBU | C26: SENIOR INFO. OFFICER | D26: 10(8) | E26: 381140.67 | F26: 10(9) | G26: 390135.83 | H26: =G26-E26 -> 8995.1667 | I26: 30491.253 | J26: =G26*0.08 -> 31210.867 | K26: =J26-I26 -> 719.61333 | L26: =J26*12 -> 374530.4 | M26: 10(9) | N26: 246171.17 | O26: =N26*0.025 -> 6154.2792 | P26: 6021.8646 | Q26: =O26-P26 -> 132.41458 | R26: =O26*12 -> 73851.35
A27: 21 | B27: ELIZABETH OGECHUKWU ONYEAKU | C27: ICT OFFICER | D27: 9(10) | H27: =G27-E27 -> 0 | J27: =G27*0.08 -> 0 | K27: =J27-I27 -> 0 | L27: =J27*12 -> 0 | Q27: =O27-P27 -> 0 | R27: =O27*12 -> 0
A28: 22 | B28: VICTOR ASUKWO | C28: SENIOR ICT OFFICER | D28: 10(7) | E28: 372145.33 | F28: 10(7) | G28: 372145.33 | H28: =G28-E28 -> 0 | I28: 30491.253 | J28: =G28*0.08 -> 29771.627 | K28: =J28-I28 -> -719.62667 | L28: =J28*12 -> 357259.52 | M28: 10(7) | N28: ='[21] FGN 2024 MGT Monthly'!$H$39 -> 235577.83 | O28: =N28*0.025 -> 5889.4458 | P28: 5690.3938 | Q28: =O28-P28 -> 199.05208 | R28: =O28*12 -> 70673.35
A29: 23 | B29: NNANDI LIVINUS ATURE | C29: SENIOR RESEARCH OFFICER | D29: 10(7) | E29: 372145.33 | F29: 10(8) | G29: 381140.67 | H29: =G29-E29 -> 8995.3333 | I29: 30491.253 | J29: =G29*0.08 -> 30491.253 | K29: =J29-I29 -> 0 | L29: =J29*12 -> 365895.04 | M29: 10(8) | N29: 240874.58 | O29: =N29*0.025 -> 6021.8646 | P29: 6260.74 | Q29: =O29-P29 -> -238.87542 | R29: =O29*12 -> 72262.375
A30: 24 | B30: ABDULRAHMAN A SULAIMAN | C30: STORE OFFICER | D30: 9(9) | E30: 347016.17 | F30: 9(10) | G30: ='[21]Peculiar Allowance'!$K$38+'[21] FGN 2024 MGT Monthly'!$K$38 -> 355320.67 | H30: =G30-E30 -> 8304.5 | I30: 27761.293 | J30: =G30*0.08 -> 28425.653 | K30: =J30-I30 -> 664.36 | L30: =J30*12 -> 341107.84 | M30: 9(10) | N30: 227615.75 | Q30: =O30-P30 -> 0 | R30: =O30*12 -> 0
A31: 25 | B31: DARE SHEU MAGBON | C31: ADMINISTRATION OFFICER | D31: 9(8) | E31: 338711.67 | F31: 9(9) | G31: 347016.17 | H31: =G31-E31 -> 8304.5 | I31: 27096.933 | J31: =G31*0.08 -> 27761.293 | K31: =J31-I31 -> 664.36 | L31: =J31*12 -> 333135.52 | M31: 9(9) | N31: 222674.58 | Q31: =O31-P31 -> 0 | R31: =O31*12 -> 0
A32: 26 | B32: ABUBAKAR SULAIMAN SODEEQ | C32: SENIOR M&E OFFICER | D32: 10(7) | E32: 372145.33 | F32: 10(7) | G32: 372145.33 | H32: =G32-E32 -> 0 | I32: 29771.627 | J32: =G32*0.08 -> 29771.627 | K32: =J32-I32 -> -5.8207661e-11 | L32: =J32*12 -> 357259.52 | M32: 10(7) | N32: ='[21] FGN 2024 MGT Monthly'!$H$39 -> 235577.83 | O32: =N32*0.025 -> 5889.4458 | P32: 6260.744 | Q32: =O32-P32 -> -371.29817 | R32: =O32*12 -> 70673.35
A33: 27 | B33: JIMOH ADEBAYO ZAKA | C33: SENIOR INFO OFFICER | D33: 10(7) | E33: 372145.33 | F33: 10(7) | G33: 372145.33 | H33: =G33-E33 -> 0 | I33: 29771.627 | J33: =G33*0.08 -> 29771.627 | K33: =J33-I33 -> -5.8207661e-11 | L33: =J33*12 -> 357259.52 | M33: 10(7) | N33: ='[21] FGN 2024 MGT Monthly'!$H$39 -> 235577.83 | O33: =N33*0.025 -> 5889.4458 | P33: 6260.744 | Q33: =O33-P33 -> -371.29817 | R33: =O33*12 -> 70673.35
A34: 28 | B34: ABDULMUSHIN TAWFIQ LADAN | C34: ICT OFFICER | D34: 9(8) | E34: 338711.67 | F34: 9(9) | G34: 347016.17 | H34: =G34-E34 -> 8304.5 | I34: 27096.933 | J34: =G34*0.08 -> 27761.293 | K34: =J34-I34 -> 664.36 | L34: =J34*12 -> 333135.52 | M34: 9(9) | N34: 222674.58 | Q34: =O34-P34 -> 0 | R34: =O34*12 -> 0
A35: 29 | B35: MOHAMMED BELLO | C35: SENIOR PROTOCOL OFFICER | D35: 10(7) | E35: 372145.33 | F35: 10(7) | G35: 372145.33 | H35: =G35-E35 -> 0 | I35: 29771.627 | J35: =G35*0.08 -> 29771.627 | K35: =J35-I35 -> -5.8207661e-11 | L35: =J35*12 -> 357259.52 | M35: 10(7) | N35: ='[21] FGN 2024 MGT Monthly'!$H$39 -> 235577.83 | Q35: =O35-P35 -> 0 | R35: =O35*12 -> 0
A36: 30 | B36: HOLINESS PAUL UDO | C36: ADMINISTRATION OFFICER, M&E | D36: 9(7) | E36: 330407.08 | F36: 9(8) | G36: 338711.67 | H36: =G36-E36 -> 8304.5833 | I36: 29771.627 | J36: =G36*0.08 -> 27096.933 | K36: =J36-I36 -> -2674.6933 | L36: =J36*12 -> 325163.2 | M36: 9(8) | N36: 217733.42 | O36: =N36*0.025 -> 5443.3354 | P36: 5319.8 | Q36: =O36-P36 -> 123.53542 | R36: =O36*12 -> 65320.025
A37: 31 | B37: CHARITY UDO AKAN | C37: ADMINISTRATION OFFICER, M&E | D37: 9(7) | E37: 330408.08 | F37: 9(8) | G37: 338711.67 | H37: =G37-E37 -> 8303.5833 | I37: 26432.647 | J37: =G37*0.08 -> 27096.933 | K37: =J37-I37 -> 664.28667 | L37: =J37*12 -> 325163.2 | M37: 9(8) | N37: 217733.42 | O37: =N37*0.025 -> 5443.3354 | P37: 5319.8 | Q37: =O37-P37 -> 123.53542 | R37: =O37*12 -> 65320.025
A38: 32 | B38: SANI UMAR IBRAHIM | C38: STORE OFFICER | D38: 9(7) | E38: 330409.08 | F38: 9(8) | G38: 338711.67 | H38: =G38-E38 -> 8302.5833 | I38: 26432.727 | J38: =G38*0.08 -> 27096.933 | K38: =J38-I38 -> 664.20667 | L38: =J38*12 -> 325163.2 | M38: 9(8) | N38: 217733.42 | Q38: =O38-P38 -> 0 | R38: =O38*12 -> 0
A39: 33 | B39: FAHAD ABUBUKAR LONGMAN | C39: ICT OFFICER | D39: 9(7) | E39: 330409.08 | F39: 9(8) | G39: 338711.67 | H39: =G39-E39 -> 8302.5833 | I39: 26432.727 | J39: =G39*0.08 -> 27096.933 | K39: =J39-I39 -> 664.20667 | L39: =J39*12 -> 325163.2 | M39: 9(8) | N39: 217733.42 | O39: =N39*0.025 -> 5443.3354 | P39: 5319.8 | Q39: =O39-P39 -> 123.53542 | R39: =O39*12 -> 65320.025
A40: 34 | B40: HARUNA JIBRIL AMEH | C40: ASST. ADMIN. OFFICER | D40: 8(9) | E40: 301910.75 | F40: 8(10) | G40: 308920.67 | H40: =G40-E40 -> 7009.9167 | I40: 24152.86 | J40: =G40*0.08 -> 24713.653 | K40: =J40-I40 -> 560.79333 | L40: =J40*12 -> 296563.84 | M40: 8(10) | N40: 200549.42 | O40: =N40*0.025 -> 5013.7354 | P40: 4909.1104 | Q40: =O40-P40 -> 104.625 | R40: =O40*12 -> 60164.825
...

Sheet Basic & Pensions (2)
A1: NATIONAL INSTITUTE FOR LEGISLATIVE AND DEMOCRATIC STUDIES
A2: STAFF PAYROLL FOR THE MONTH OF JANUARY, 2026
E3: ='[1]FEB 08'!E11/'[1]FEB 08'!M11 -> #REF!
B4: STAFF NAME | C4: DESIGNATION | D4: GRADE LEVEL | E4: OLD CUM BASIC SALARY | F4: NEW BASIC SALARY | G4: PECULIAR ALLOW | H4: NEW CUM BASIC SALARY | I4: INCREASE IN CUM BASIC SALARY | J4: OLD EMPLOYEE PENSION 8% | K4: NEW EMPLOYEE PENSION 8% | L4: INCREASE IN DEDUCTION | M4: OLD NHF | N4: NEW NHF | O4: INCREASE IN NHF | P4: ANNUAL NEW EMPLOYEE PENSIONS | Q4: ANNUAL NEW NHF
E5: N | F5: N | G5: N | H5: N | I5: N | J5: N | K5: N | L5: N | M5: N | N5: N | O5: N | P5: N | Q5: N
E6: A | F6: B | G6: C | H6: D | I6: E | J6: F | K6: G | L6: H | M6: I | N6: J | O6: K | P6: L | Q6: M
A7: S/N | B7: DG'S OFFICE | H7: (B+C) | I7: (D-A) | J7: (8% of A) | K7: (8% of D) | L7: (G-F) | N7: (2.5% of B) | O7: (J-I) | P7: (J-I) | Q7: (J-I)
A8: 1 | B8: PROF. ABUBAKAR O. SULAIMAN | C8: DIRECTOR GENERAL | D8: CONSOL | E8: 1659751.2 | F8: 1086777.1 | G8: 884360 | H8: =F8+G8 -> 1971137.1 | I8: =H8-E8 -> 311385.92 | L8: =K8-J8 -> 0 | O8: =N8-M8 -> 0 | P8: =K8*12 -> 0 | Q8: =N8*12 -> 0
A9: 2 | B9: RAHEEM USMAN AYIGORO | C9: SA-INFRASTRUCTURE | D9: 16 (9) | E9: 762373.17 | F9: 554669.5 | G9: 350637.25 | H9: =F9+G9 -> 905306.75 | I9: =H9-E9 -> 142933.58 | J9: 60989.853 | K9: =H9*0.08 -> 72424.54 | L9: =K9-J9 -> 11434.687 | O9: =N9-M9 -> 0 | P9: =K9*12 -> 869094.48 | Q9: =N9*12 -> 0
A10: 3 | B10: MARIAM MOHAMMED BELLO | C10: SA- SPECIAL DUTIES | D10: 16 (9) | E10: 762373.17 | F10: 554669.5 | G10: 350637.25 | H10: =F10+G10 -> 905306.75 | I10: =H10-E10 -> 142933.58 | L10: =K10-J10 -> 0 | O10: =N10-M10 -> 0 | P10: =K10*12 -> 0 | Q10: =N10*12 -> 0
A11: 4 | B11: DR IKEME ARTHUR J.O | C11: DEPUTY DIRECTOR, M&E | D11: 16 (9) | E11: 762373.17 | F11: 554669.5 | G11: 350637.25 | H11: =F11+G11 -> 905306.75 | I11: =H11-E11 -> 142933.58 | J11: 60989.853 | K11: =H11*0.08 -> 72424.54 | L11: =K11-J11 -> 11434.687 | M11: 10293.398 | N11: =0.025*F11 -> 13866.737 | O11: =N11-M11 -> 3573.3396 | P11: =K11*12 -> 869094.48 | Q11: =N11*12 -> 166400.85
A12: 5 | B12: ANDRAWUS MUSA | C12: DEP. DIRECTOR, STORES & PROCUREMENT | D12: 16(8) | E12: 716034 | F12: ='[19] FGN 2024 MGT Monthly'!$I$44 -> 539028 | G12: ='[19]Peculiar Allowance'!$I$44 -> 339980.92 | H12: =F12+G12 -> 879008.92 | I12: =H12-E12 -> 162974.92 | J12: 59136.287 | K12: =H12*0.08 -> 70320.713 | L12: =K12-J12 -> 11184.427 | M12: 10293.398 | N12: =0.025*F12 -> 13475.7 | O12: =N12-M12 -> 3182.3021 | P12: =K12*12 -> 843848.56 | Q12: =N12*12 -> 161708.4
A13: 6 | B13: DR FRANCIS NDUM OJIE | C13: AD, TRAINING & IC./SA TO DG | D13: 15(8) | E13: 601396.83 | F13: 445995.83 | G13: 276599.67 | H13: =F13+G13 -> 722595.5 | I13: =H13-E13 -> 121198.67 | J13: 46569.447 | K13: =H13*0.08 -> 57807.64 | L13: =K13-J13 -> 11238.193 | M13: 7859.6313 | N13: =0.025*F13 -> 11149.896 | O13: =N13-M13 -> 3290.2646 | P13: =K13*12 -> 693691.68 | Q13: =N13*12 -> 133798.75
A14: 7 | B14: ALI ABDULLAHI | C14: CHIEF ICT OFFICER | D14: 14(11) | E14: 484373.75 | F14: 366417.5 | G14: 223239.5 | H14: =F14+G14 -> 589657 | I14: =H14-E14 -> 105283.25 | J14: 38749.9 | K14: =H14*0.08 -> 47172.56 | L14: =K14-J14 -> 8422.66 | O14: =N14-M14 -> 0 | P14: =K14*12 -> 566070.72 | Q14: =N14*12 -> 0
A15: 8 | B15: EMILY EKHIDE | C15: SENIOR RESEARCH FELLOW | D15: 15(8) | E15: 601396.83 | F15: ='[18] FGN 2024 MGT Monthly'!$I$43 -> 445995.83 | G15: 276599.67 | H15: =F15+G15 -> 722595.5 | I15: =H15-E15 -> 121198.67 | J15: 46569.45 | K15: =H15*0.08 -> 57807.64 | L15: =K15-J15 -> 11238.19 | O15: =N15-M15 -> 0 | P15: =K15*12 -> 693691.68 | Q15: =N15*12 -> 0
A16: 9 | B16: DORIS DAKDA AARON | C16: RESEARCH FELLOW I | D16: 14(9) | E16: 456622.25 | F16: 347715.92 | G16: 210449.33 | H16: =F16+G16 -> 558165.25 | I16: =H16-E16 -> 101543 | J16: 35419.72 | K16: =H16*0.08 -> 44653.22 | L16: =K16-J16 -> 9233.5 | O16: =N16-M16 -> 0 | P16: =K16*12 -> 535838.64 | Q16: =N16*12 -> 0
A17: 10 | B17: ABDULSALAM S. MUSTAPHA | C17: ASST. DIRECTOR ICT | D17: 15(7) | E17: 582118.08 | F17: 432981.08 | G17: 267732.83 | H17: =F17+G17 -> 700713.92 | I17: =H17-E17 -> 118595.83 | J17: 46569.45 | K17: =H17*0.08 -> 56057.113 | L17: =K17-J17 -> 9487.6633 | O17: =N17-M17 -> 0 | P17: =K17*12 -> 672685.36 | Q17: =N17*12 -> 0
A18: 11 | B18: PERCY TERFA GBAHABO | C18: HEAD, NILDS LIAISON OFFICE | D18: 13(11) | E18: 441804.92 | F18: 337730.83 | G18: 203620.5 | H18: =F18+G18 -> 541351.33 | I18: =H18-E18 -> 99546.417 | J18: 34313.273 | K18: =H18*0.08 -> 43308.107 | L18: =K18-J18 -> 8994.8333 | O18: =N18-M18 -> 0 | P18: =K18*12 -> 519697.28 | Q18: =N18*12 -> 0
A19: 12 | B19: HASSANA AHMED IBRAHIM | C19: PA- TO DG | D19: 13 (10) | E19: 428915.92 | F19: 329044.92 | G19: 197680.17 | H19: =F19+G19 -> 526725.08 | I19: =H19-E19 -> 97809.167 | J19: 33282.153 | K19: =H19*0.08 -> 42138.007 | L19: =K19-J19 -> 8855.8533 | M19: 5607.1771 | N19: =0.025*F19 -> 8226.1229 | O19: =N19-M19 -> 2618.9458 | P19: =K19*12 -> 505656.08 | Q19: =N19*12 -> 98713.475
A20: 13 | B20: IKIP LEBO | C20: ASST CHIEF PROC. OFFICER | D20: 13 (8) | E20: 403138 | F20: 311673.25 | G20: 185799.5 | H20: =F20+G20 -> 497472.75 | I20: =H20-E20 -> 94334.75 | J20: 31219.913 | K20: =H20*0.08 -> 39797.82 | L20: =K20-J20 -> 8577.9067 | M20: 5967.3062 | N20: =0.025*F20 -> 7791.8313 | O20: =N20-M20 -> 1824.525 | P20: =K20*12 -> 477573.84 | Q20: =N20*12 -> 93501.975
A21: 14 | B21: ALABI ADESINA MUHYDEEN | C21: HEAD, NILDS LIAISON OFFICE | D21: 13 (8) | E21: 403138 | F21: 311673.25 | G21: 185799.5 | H21: =F21+G21 -> 497472.75 | I21: =H21-E21 -> 94334.75 | J21: 31219.913 | K21: =H21*0.08 -> 39797.82 | L21: =K21-J21 -> 8577.9067 | O21: =N21-M21 -> 0 | P21: =K21*12 -> 477573.84 | Q21: =N21*12 -> 0
A22: 15 | B22: BASSEY NSONGURUA UDOFIA | C22: PRINC.CONF SEC/PPS | D22: 12(11) | E22: 402278 | F22: ='[18] FGN 2024 MGT Monthly'!$L$40 -> 311094.42 | G22: 185402.75 | H22: =F22+G22 -> 496497.17 | I22: =H22-E22 -> 94219.167 | J22: 31206.92 | K22: =H22*0.08 -> 39719.773 | L22: =K22-J22 -> 8512.8533 | M22: 5257.5625 | N22: =0.025*F22 -> 7777.3604 | O22: =N22-M22 -> 2519.7979 | P22: =K22*12 -> 476637.28 | Q22: =N22*12 -> 93328.325
A23: 16 | B23: ADUGBA RICHARD TERSEER | C23: PRINCIPAL INFO. OFFICER | D23: 12(10) | E23: 390086.5 | F23: 302878.67 | G23: 179784 | H23: =F23+G23 -> 482662.67 | I23: =H23-E23 -> 92576.167 | J23: 30231.613 | K23: =H23*0.08 -> 38613.013 | L23: =K23-J23 -> 8381.4 | N23: =0.025*F23 -> 7571.9667 | O23: =N23-M23 -> 7571.9667 | P23: =K23*12 -> 463356.16 | Q23: =N23*12 -> 90863.6
A24: 17 | B24: LUCKY AGWOM | C24: RESEARCH ASSISTANT | D24: 12(8) | E24: 365704 | F24: 286447.08 | G24: 168546.5 | H24: =F24+G24 -> 454993.58 | I24: =H24-E24 -> 89289.583 | J24: 28281 | K24: =H24*0.08 -> 36399.487 | L24: =K24-J24 -> 8118.4867 | O24: =N24-M24 -> 0 | P24: =K24*12 -> 436793.84 | Q24: =N24*12 -> 0
A25: 18 | B25: IDRIS IBRAHIM | C25: PRINCIPAL RESEARCH OFFICER | D25: 12(8) | E25: 365704 | F25: 286447.08 | G25: 168546.5 | H25: =F25+G25 -> 454993.58 | I25: =H25-E25 -> 89289.583 | J25: 28281 | K25: =H25*0.08 -> 36399.487 | L25: =K25-J25 -> 8118.4867 | O25: =N25-M25 -> 0 | P25: =K25*12 -> 436793.84 | Q25: =N25*12 -> 0
A26: 19 | B26: FARUQ ATOFARATI | C26: PA (SPECIAL DUTIES) TO DG | D26: 10(7) | E26: 293029.67 | F26: 240874.58 | G26: 140266.08 | H26: =F26+G26 -> 381140.67 | I26: =H26-E26 -> 88111 | J26: 23442.373 | K26: =H26*0.08 -> 30491.253 | L26: =K26-J26 -> 7048.88 | O26: =N26-M26 -> 0 | P26: =K26*12 -> 365895.04 | Q26: =N26*12 -> 0
A27: 20 | B27: RASHEEDAT DAIBU | C27: SENIOR INFO. OFFICER | D27: 10(8) | E27: 300965.58 | F27: 240874.58 | G27: 140266.08 | H27: =F27+G27 -> 381140.67 | I27: =H27-E27 -> 80175.083 | J27: 23442.373 | K27: =H27*0.08 -> 30491.253 | L27: =K27-J27 -> 7048.88 | N27: =0.025*F27 -> 6021.8646 | O27: =N27-M27 -> 6021.8646 | P27: =K27*12 -> 365895.04 | Q27: =N27*12 -> 72262.375
A28: 21 | B28: ELIZABETH OGECHUKWU ONYEAKU | C28: ICT OFFICER | D28: 9(10) | E28: 277798 | F28: 227615.75 | G28: 127704.92 | H28: =F28+G28 -> 355320.67 | I28: =H28-E28 -> 77522.667 | J28: 21638.533 | K28: =H28*0.08 -> 28425.653 | L28: =K28-J28 -> 6787.12 | N28: =0.025*F28 -> 5690.3938 | O28: =N28-M28 -> 5690.3938 | P28: =K28*12 -> 341107.84 | Q28: =N28*12 -> 68284.725
A29: 22 | B29: VICTOR ASUKWO | C29: ICT OFFICER | D29: 9(10) | E29: 277798 | F29: 227615.75 | G29: 127704.92 | H29: =F29+G29 -> 355320.67 | I29: =H29-E29 -> 77522.667 | J29: 21638.533 | K29: =H29*0.08 -> 28425.653 | L29: =K29-J29 -> 6787.12 | N29: =0.025*F29 -> 5690.3938 | O29: =N29-M29 -> 5690.3938 | P29: =K29*12 -> 341107.84 | Q29: =N29*12 -> 68284.725
A30: 23 | B30: NNANDI LIVINUS ATURE | C30: RESEARCH ASSISTANT | D30: 9(10) | E30: 277798 | F30: 227615.75 | G30: 127704.92 | H30: =F30+G30 -> 355320.67 | I30: =H30-E30 -> 77522.667 | J30: 21638.533 | K30: =H30*0.08 -> 28425.653 | L30: =K30-J30 -> 6787.12 | O30: =N30-M30 -> 0 | P30: =K30*12 -> 341107.84 | Q30: =N30*12 -> 0
A31: 24 | B31: ABDULRAHMAN A SULAIMAN | C31: STORE OFFICER | D31: 9(9) | E31: 270481.67 | F31: 222674.58 | G31: 124341.58 | H31: =F31+G31 -> 347016.17 | I31: =H31-E31 -> 76534.5 | J31: 21053.227 | K31: =H31*0.08 -> 27761.293 | L31: =K31-J31 -> 6708.0667 | O31: =N31-M31 -> 0 | P31: =K31*12 -> 333135.52 | Q31: =N31*12 -> 0
A32: 25 | B32: DARE SHEU MAGBON | C32: ADMINISTRATION OFFICER | D32: 9(8) | E32: 263165.33 | F32: 217733.42 | G32: 120978.25 | H32: =F32+G32 -> 338711.67 | I32: =H32-E32 -> 75546.333 | J32: 20467.92 | K32: =H32*0.08 -> 27096.933 | L32: =K32-J32 -> 6629.0133 | O32: =N32-M32 -> 0 | P32: =K32*12 -> 325163.2 | Q32: =N32*12 -> 0
A33: 26 | B33: ABUBAKAR SULAIMAN SODEEQ | C33: ADMINISTRATION OFFICER | D33: 9(8) | E33: 263165.33 | F33: 217733.42 | G33: 120978.25 | H33: =F33+G33 -> 338711.67 | I33: =H33-E33 -> 75546.333 | J33: 20467.92 | K33: =H33*0.08 -> 27096.933 | L33: =K33-J33 -> 6629.0133 | O33: =N33-M33 -> 0 | P33: =K33*12 -> 325163.2 | Q33: =N33*12 -> 0
A34: 27 | B34: JIMOH ADEBAYO ZAKA | C34: ASST. OFFICER/COMM | D34: 9(10) | E34: 277798 | F34: 227615.75 | G34: 127704.92 | H34: =F34+G34 -> 355320.67 | I34: =H34-E34 -> 77522.667 | J34: 21638.533 | K34: =H34*0.08 -> 28425.653 | L34: =K34-J34 -> 6787.12 | M34: 3653.5 | N34: =0.025*F34 -> 5690.3938 | O34: =N34-M34 -> 2036.8937 | P34: =K34*12 -> 341107.84 | Q34: =N34*12 -> 68284.725
A35: 28 | B35: ABDULMUSHIN TAWFIQ LADAN | C35: ICT OFFICER | D35: 9(8) | E35: 263165.33 | F35: 217733.42 | G35: 120978.25 | H35: =F35+G35 -> 338711.67 | I35: =H35-E35 -> 75546.333 | J35: 20467.92 | K35: =H35*0.08 -> 27096.933 | L35: =K35-J35 -> 6629.0133 | O35: =N35-M35 -> 0 | P35: =K35*12 -> 325163.2 | Q35: =N35*12 -> 0
A36: 29 | B36: MOHAMMED BELLO | C36: PROTOCOL ASSISTANT | D36: 9(8) | E36: 263165.33 | F36: 217733.42 | G36: 120978.25 | H36: =F36+G36 -> 338711.67 | I36: =H36-E36 -> 75546.333 | J36: 20467.92 | K36: =H36*0.08 -> 27096.933 | L36: =K36-J36 -> 6629.0133 | O36: =N36-M36 -> 0 | P36: =K36*12 -> 325163.2 | Q36: =N36*12 -> 0
A37: 30 | B37: HARUNA JIBRIL AMEH | C37: ASST. ADMIN. OFFICER | D37: 8(9) | E37: 230631.92 | F37: 196364.42 | G37: 105546.33 | H37: =F37+G37 -> 301910.75 | I37: =H37-E37 -> 71278.833 | J37: 17956.78 | K37: =H37*0.08 -> 24152.86 | L37: =K37-J37 -> 6196.08 | N37: =0.025*F37 -> 4909.1104 | O37: =N37-M37 -> 4909.1104 | P37: =K37*12 -> 289834.32 | Q37: =N37*12 -> 58909.325
A38: 31 | B38: RAMATU IBRAHIM ABDULRAHEEM | C38: INFORMATION OFFICER | D38: 8(8) | E38: 224459.75 | F38: 192179.42 | G38: 102721.42 | H38: =F38+G38 -> 294900.83 | I38: =H38-E38 -> 70441.083 | J38: 17463.007 | K38: =H38*0.08 -> 23592.067 | L38: =K38-J38 -> 6129.06 | N38: =0.025*F38 -> 4804.4854 | O38: =N38-M38 -> 4804.4854 | P38: =K38*12 -> 283104.8 | Q38: =N38*12 -> 57653.825
B39: TOTAL | C39: 31 | E39: =SUM(E8:E38) -> 14073004 | F39: =SUM(F8:F38) -> 10680274 | G39: =SUM(G8:G38) -> 6613927.2 | H39: =SUM(H8:H38) -> 17294201 | I39: =SUM(I8:I38) -> 3221197.1 | J39: =SUM(J8:J38) -> 914813.32 | K39: =SUM(K8:K38) -> 1153420.6 | L39: =SUM(L8:L38) -> 238607.23 | ... Q39: =SUM(Q8:Q38) -> 1231995.1
B41: INTERNAL AUDIT
...

Sheet Sheet18

Sheet 2025 Promotions (2)
A1: NATIONAL INSTITUTE FOR LEGISLATIVE & DEMOCRATIC STUDIES
A2: 2025 ANALYSIS OF STAFF PROMOTION ARREARS
A4: SN | B4: Name of Employee | C4: Department | D4: Present Grade Level | E4: New Grade Level | F4: Consolidated Salary of Present Position | G4: Consolidated Salary of New Position | H4: Diference/Arrears | I4: Effective Date | J4: No of Months | K4: Total Amount of Arrears (Gross)
F5: N | G5: N | H5: N | K5: N
A6: 13 | B6: Victor Etim Asukwo | C6: DG's Office | D6: 9/10 | E6: 10/7 | F6: 415320.67 | G6: 432145.33 | H6: =G6-F6 -> 16824.667 | I6: 6th August 2025 | J6: 4 | K6: =J6*H6 -> 67298.667
B7: TOTAL | H7: =SUM(H6:H6) -> 16824.667 | K7: =SUM(K6:K6) -> 67298.667

Sheet Christmas Welfare 2025 (2)
A1: NATIONAL INSTITUTE FOR LEGISLATIVE AND DEMOCRATIC STUDIES
A2: STAFF CHRISTMAS WELFARE DECEMBER 2025
B4: STAFF NAME | C4: DESIGNATION | D4: GRADE LEVEL | E4: AMOUNT
A6: S/N | B6: DG'S OFFICE | E6: N
A7: 1 | B7: PROF. ABUBAKAR O. SULAIMAN | C7: DIRECTOR GENERAL | D7: CONSOL | E7: 648000
A8: 2 | B8: RAHEEM USMAN AYIGORO | C8: SA-INFRASTRUCTURE | D8: 16 (9) | E8: 216000
A9: 3 | B9: MARIAM MOHAMMED BELLO | C9: SA- SPECIAL DUTIES | D9: 16 (9) | E9: 216000
A10: 4 | B10: DR IKEME ARTHUR J.O | C10: DEPUTY DIRECTOR, M&E | D10: 16 (9) | E10: 216000
A11: 5 | B11: ANDRAWUS MUSA | C11: DEP. DIRECTOR, STORES & PROCUREMENT | D11: 16(8) | E11: 216000
A12: 6 | B12: DR FRANCIS NDUM OJIE | C12: AD, TRAINING & IC./SA TO DG | D12: 15(8) | E12: 151200
A13: 7 | B13: ALI ABDULLAHI | C13: ASST DIRECTOR ICT | D13: 15(7) | E13: 151200
A14: 8 | B14: EMILY EKHIDE | C14: SENIOR RESEARCH FELLOW | D14: 15(8) | E14: 151200
A15: 9 | B15: DORIS DAKDA AARON | C15: RESEARCH FELLOW I | D15: 14(9) | E15: 108000
A16: 10 | B16: ABDULSALAM S. MUSTAPHA | C16: ASST. DIRECTOR ICT | D16: 15(7) | E16: 151200
A17: 11 | B17: PERCY TERFA GBAHABO | C17: RESEARCH FELLOW 1 | D17: 14(7) | E17: 108000
A18: 12 | B18: HASSANA AHMED IBRAHIM | C18: PA- TO DG | D18: 13(10) | E18: 108000
... A46: 40 | B46: ALIYU GARBA LERE | C46: ASSIST INFORMATION OFFICER | D46: 8(7) | E46: 64800
B47: TOTAL | C47: 40 | E47: =SUM(E7:E46) -> 4579200
B49: INTERNAL AUDIT
A50: 1 | B50: OSANAIYE DAVID AKINYEMI | C50: DIRECTOR INTERNAL AUDIT | D50: 17(9) | E50: 324000
A51: 2 | B51: EVELYN ETONKE AGAN | C51: ASST DIR AUDIT | D51: 15(7) | E51: 151200
A52: 3 | B52: JAMILA ABDUL | C52: SENIOR INTERNAL AUDITOR | D52: 10(8) | E52: 81600
A53: 4 | B53: IJEOMA EWELUKWA | C53: PRINCIPAL AUDIT OFFICER | D53: 12(7) | E53: 81600
A54: 5 | B54: HASSAN ABDULHADI | C54: SENIOR INTERNAL AUDITOR | D54: 9(7) | E54: 64800
A55: 6 | B55: YUSUF YUSUF DAYYABU | C55: INERNAL AUDIT OFFICER | D55: 9(8) | E55: 64800
A56: 7 | B56: UDONSI QUEENETH CHIWENDU | C56: ASSIST PROGRAMME OFFICER | D56: 8(7) | E56: 64800
C57: 7 | E57: =SUM(E50:E56) -> 832800
B59: LEG. SUPPORT SEVICES
A60: 1 | B60: BETHEL UZOMA IHUGBA | C60: AG. DIRECTOR, AEEP | D60: 17(7) | E60: 324000
A61: 2 | B61: OGUCHE SAMUEL | C61: SNR RESEARCH FELLOW | D61: 15(9) | E61: 151200
A62: 3 | B62: IBRAHIM USMAN | C62: SNR RESEARCH FELLOW | D62: 15(9) | E62: 151200
A63: 4 | B63: DR MOHAMMED O. AMALI | C63: SNR RESEARCH FELLOW | D63: 15(8) | E63: 151200
A64: 5 | B64: YAHAYA SHAMSU | C64: SNR RESEARCH FELLOW | D64: 15(7) | E64: 151200
A65: 6 | B65: CHIDEBE MATHEW NWANKWO | C65: SNR RESEARCH FELLOW | D65: 15(7) | E65: 151200
A66: 7 | B66: UMAR MUSA PADAH | C66: PRINC. RESEARCH OFFICER | D66: 12(7) | E66: 81600
A67: 8 | B67: BILKIS S. LAWAL-GAMBARI | C67: RESEARCH OFFICER | D67: 10(9) | E67: 81600
A68: 9 | B68: UMOH USENOBONG EMMANUEL | C68: SENIOR RESEARCH OFFICER | D68: 10(7) | E68: 81600
