Workbook

Sheet April 2013
A3: STAFF PAYROLL FOR THE MONTH OF APRIL, 2013
F4: ='[1]FEB 08'!E8/'[1]FEB 08'!M8 -> 0.22 | I4: ='[1]FEB 08'!F8/'[1]FEB 08'!Q8 -> 0.3
A5: STAFF NAME | T5: DEDUCTIONS | Y5: NET SALARY
D6: DESIGNATION | E6: SALARY | F6: BASIC | G6: Salary | M6: PERSONAL | N6: MOTOR/ | O6: RESEARCH | P6: LEAVE | Q6: OUT FIT | R6: LEGISLATIVE | S6: GROSS | X6: Mar,13 | Y6: Apr, 13
E7: LEVEL | F7: SALARY | G7: Arears | H7: RENT | I7: UTILITY | J7: DOMESTIC | K7: ENTERT. | L7: FURNIT. | M7: ASSISTANT | N7: FUEL | O7: ALLOWANCE | P7: ALLCE | Q7: ALLCE | R7: DUTY ALLCE | S7: SALARY | T7: SALARY ADV. | U7: PENSION | V7: PAYE | W7: TOTAL
A8: DG OFFICE | F8: N | I8: N | S8: N | V8: N
A9: DR LADI HAMALAI | D9: DIRECTOR GENERAL | E9: CONSOL | F9: 160488.75 | H9: 320977.5 | I9: 48146.63 | J9: 120366.57 | K9: 72219.94 | L9: 481466.25 | M9: 40122.19 | N9: 120366.57 | O9: 150000 | P9: 16048.88 | Q9: 25000 | R9: 25235 | S9: =SUM(F9:R9) -> 1580438.3 | U9: =SUM(F9+H9+N9)*0.075 -> 45137.462 | V9: 113176.97 | W9: =V9+U9+T9 -> 158314.43 | X9: 1422123.9 | Y9: =S9-W9 -> 1422123.8
A10: PROF. OFFORNZE AMUCHEAZI | D10: LEGAL ADVISER | E10: 16(7) | F10: =F33 -> 39662.25 | H10: =H33 -> 118986.75 | I10: =I33 -> 2974.6687 | J10: =J33 -> 40122.19 | K10: =F10*50% -> 19831.125 | L10: =F10*350% -> 138817.88 | M10: 0 | N10: =F10*100% -> 39662.25 | O10: 0 | P10: =F10*10% -> 3966.225 | Q10: 20000 | R10: 0 | S10: =SUM(F10:R10) -> 424023.33 | U10: =SUM(F10+H10+N10)*0.075 -> 14873.344 | V10: 21618.09 | W10: =V10+U10+T10 -> 36491.434 | X10: 387531.9 | Y10: =S10-W10 -> 387531.9
A11: MOHAMMED ISIAKA YAKUBU | D11: SPECIAL ASSISTANT | E11: 16(7) | F11: =F10 -> 39662.25 | H11: =H10 -> 118986.75 | I11: =I10 -> 2974.6687 | J11: 40122.19 | K11: 19831.13 | L11: 138817.88 | M11: 0 | N11: 39662.25 | O11: 0 | P11: 3966.23 | Q11: =Q10 -> 20000 | R11: 0 | S11: 424023.33 | T11: 0 | U11: =SUM(F11+H11+N11)*0.075 -> 14873.344 | V11: 21618.09 | W11: =V11+U11+T11 -> 36491.434 | X11: 387531.9 | Y11: =S11-W11 -> 387531.9
A12: RICHARD KWALMI | D12: MICT | E12: 15(7) | F12: 31018.9 | H12: =F12*300% -> 93056.7 | I12: =F12*7.5% -> 2326.4175 | J12: =J9/3 -> 40122.19 | K12: =F12*50% -> 15509.45 | L12: =F12*350% -> 108566.15 | M12: 0 | N12: =F12*100% -> 31018.9 | O12: 0 | P12: =F12*10% -> 3101.89 | Q12: 20000 | R12: 0 | S12: =SUM(F12:R12) -> 344720.6 | U12: =SUM(F12+H12+N12)*0.075 -> 11632.087 | V12: 15548.33 | W12: =V12+U12+T12 -> 27180.417 | X12: 317540.18 | Y12: =S12-W12 -> 317540.18
A13: ADAMU ISA ABBA | D13: INFO. MANAGER | E13: 15(7) | F13: 31018.9 | H13: =F13*300% -> 93056.7 | I13: =F13*7.5% -> 2326.4175 | J13: 40122.19 | K13: =F13*50% -> 15509.45 | L13: =F13*350% -> 108566.15 | M13: 0 | N13: =F13*100% -> 31018.9 | O13: 0 | P13: =F13*10% -> 3101.89 | Q13: 20000 | R13: 0 | S13: =SUM(F13:R13) -> 344720.6 | U13: =SUM(F13+H13+N13)*0.075 -> 11632.087 | V13: 15548.33 | W13: =V13+U13+T13 -> 27180.417 | X13: 317540.18 | Y13: =S13-W13 -> 317540.18
A14: NWOSU MATHEW EZE | D14: MANAGER INT. AUDIT | E14: 15(7) | F14: 31018.9 | H14: =F14*300% -> 93056.7 | I14: =F14*7.5% -> 2326.4175 | J14: =J15 -> 40122.19 | K14: =F14*50% -> 15509.45 | L14: =F14*350% -> 108566.15 | M14: 0 | N14: =F14*100% -> 31018.9 | O14: 0 | P14: =F14*10% -> 3101.89 | Q14: 20000 | R14: 0 | S14: =SUM(F14:R14) -> 344720.6 | U14: =SUM(F14+H14+N14)*0.075 -> 11632.087 | V14: 15548.33 | W14: =V14+U14+T14 -> 27180.417 | X14: 202633.52 | Y14: =S14-W14 -> 317540.18 | Z14: =Y14-X14 -> 114906.66
A15: PRISCILLA CHUKWU | D15: MANAGER PROCUREMENT | E15: 15(7) | F15: 31018.9 | G15: 50000 | H15: =F15*300% -> 93056.7 | I15: =F15*7.5% -> 2326.4175 | J15: =J67 -> 40122.19 | K15: =F15*50% -> 15509.45 | L15: =F15*350% -> 108566.15 | M15: 0 | N15: =F15*100% -> 31018.9 | O15: 0 | P15: =F15*10% -> 3101.89 | Q15: 20000 | R15: 0 | S15: =SUM(F15:R15) -> 394720.6 | U15: =SUM(F15+H15+N15)*0.075 -> 11632.087 | V15: 15548.33 | W15: =V15+U15+T15 -> 27180.417 | X15: 426310.27 | Y15: =S15-W15 -> 367540.18 | Z15: =Y15-X15 -> -58770.09
A16: KENNETH OKEREAFOR | D16: AM MICT | E16: 13(7) | F16: 23891.12 | H16: =F16*300% -> 71673.36 | I16: =F16*7.5% -> 1791.834 | J16: 0 | K16: =F16*50% -> 11945.56 | L16: =F16*350% -> 83618.92 | M16: 0 | N16: =F16*100% -> 23891.12 | O16: 0 | P16: =F16*10% -> 2389.112 | Q16: 15000 | R16: 0 | S16: =SUM(F16:R16) -> 234201.03 | U16: 0 | V16: 0 | W16: =V16+U16+T16 -> 0 | X16: 0 | Y16: 0 | Z16: =Y16-X16 -> 0
A17: AKINSANMI ADEJOKE OLUKEMI | D17: AM INFORMATION | E17: 13(7) | F17: 23891.12 | H17: =F17*300% -> 71673.36 | I17: =F17*7.5% -> 1791.834 | J17: 0 | K17: =F17*50% -> 11945.56 | L17: =F17*350% -> 83618.92 | M17: 0 | N17: =F17*100% -> 23891.12 | O17: 0 | P17: =F17*10% -> 2389.112 | Q17: 15000 | R17: 0 | S17: =SUM(F17:R17) -> 234201.03 | U17: =SUM(F17+H17+N17)*0.075 -> 8959.17 | V17: 7709 | W17: =V17+U17+T17 -> 16668.17 | X17: 217532.86 | Y17: =S17-W17 -> 217532.86
A18: FAROUK U. M ILLO | D18: PA DG | E18: 13(7) | F18: 23891.12 | G18: 0 | H18: =F18*300% -> 71673.36 | I18: =F18*7.5% -> 1791.834 | J18: 0 | K18: =F18*50% -> 11945.56 | L18: =F18*350% -> 83618.92 | M18: 0 | N18: =F18*100% -> 23891.12 | O18: 80000 | P18: =F18*10% -> 2389.112 | Q18: 15000 | R18: 0 | S18: =SUM(F18:R18) -> 314201.03 | U18: =SUM(F18+H18+N18)*0.075 -> 8959.17 | V18: 7709 | W18: =V18+U18+T18 -> 16668.17 | X18: 297532.86 | Y18: =S18-W18 -> 297532.86
A19: UMOLU ADAEZE OBIAMAKA | D19: INFO OFFICER | E19: 10(7) | F19: 17286.33 | H19: =F19*300% -> 51858.99 | I19: =F19*7.5% -> 1296.4748 | J19: 0 | K19: =F19*50% -> 8643.165 | L19: =F19*350% -> 60502.155 | M19: 0 | N19: =F19*100% -> 17286.33 | O19: 0 | P19: =F19*10% -> 1728.633 | Q19: 10000 | R19: 0 | S19: =SUM(F19:R19) -> 168602.08 | U19: =SUM(F19+H19+N19)*0.075 -> 6482.3738 | V19: 3369.51 | W19: =V19+U19+T19 -> 9851.8838 | X19: 158750.19 | Y19: =S19-W19 -> 158750.19
A20: TONDO IORWUESEEDWARD | D20: OFFICER INT AUDIT | E20: 10(7) | F20: 17286.33 | H20: =F20*300% -> 51858.99 | I20: =F20*7.5% -> 1296.4748 | J20: 0 | K20: =F20*50% -> 8643.165 | L20: =F20*350% -> 60502.155 | M20: 0 | N20: =F20*100% -> 17286.33 | O20: 0 | P20: =F20*10% -> 1728.633 | Q20: 10000 | R20: 0 | S20: =SUM(F20:R20) -> 168602.08 | U20: =SUM(F20+H20+N20)*0.075 -> 6482.3738 | V20: 3369.51 | W20: =V20+U20+T20 -> 9851.8838 | X20: 158750.19 | Y20: =S20-W20 -> 158750.19
A21: MUSTAFA ABUBAKAR RUFAU | D21: OFFICER SPECIAL DUTIES | E21: 10(7) | F21: 17286.33 | G21: 0 | H21: =F21*300% -> 51858.99 | I21: =F21*7.5% -> 1296.4748 | J21: 0 | K21: =F21*50% -> 8643.165 | L21: =F21*350% -> 60502.155 | M21: 0 | N21: =F21*100% -> 17286.33 | O21: 40000 | P21: =F21*10% -> 1728.633 | Q21: 10000 | R21: 0 | S21: =SUM(F21:R21) -> 208602.08 | U21: =SUM(F21+H21+N21)*0.075 -> 6482.3738 | V21: 3369.51 | W21: =V21+U21+T21 -> 9851.8838 | X21: 198750.19 | Y21: =S21-W21 -> 198750.19
A22: BEDARI HARI | D22: LEGAL OFFICER | E22: 10(7) | F22: 17286.33 | G22: 0 | H22: =F22*300% -> 51858.99 | I22: =F22*7.5% -> 1296.4748 | J22: 0 | K22: =F22*50% -> 8643.165 | L22: =F22*350% -> 60502.155 | M22: 0 | N22: =F22*100% -> 17286.33 | O22: 0 | P22: =F22*10% -> 1728.633 | Q22: 10000 | R22: 0 | S22: =SUM(F22:R22) -> 168602.08 | U22: =SUM(F22+H22+N22)*0.075 -> 6482.3738 | V22: 3369.51 | W22: =V22+U22+T22 -> 9851.8838 | X22: 158750.19 | Y22: =S22-W22 -> 158750.19
A23: BASHIRU ABBA WALI | D23: ASSIT. INT. AUDIT | E23: 8(7) | F23: 12351.94 | H23: =F23*300% -> 37055.82 | I23: =F23*7.5% -> 926.3955 | J23: 0 | K23: =F23*50% -> 6175.97 | L23: =F23*350% -> 43231.79 | M23: 0 | N23: =F23*100% -> 12351.94 | O23: 0 | P23: =F23*10% -> 1235.194 | Q23: 10000 | R23: 0 | S23: =SUM(F23:R23) -> 123329.05 | T23: 0 | U23: =SUM(F23+H23+N23)*0.075 -> 4631.9775 | V23: 1484.37 | W23: =V23+U23+T23 -> 6116.3475 | X23: 117212.7 | Y23: =S23-W23 -> 117212.7
A24: ALI ABDULLAHI | D24: 1CT ASSISTANT | E24: 8(7) | F24: 12351.94 | H24: =F24*300% -> 37055.82 | I24: =F24*7.5% -> 926.3955 | J24: 0 | K24: =F24*50% -> 6175.97 | L24: =F24*350% -> 43231.79 | M24: 0 | N24: =F24*100% -> 12351.94 | O24: 0 | P24: =F24*10% -> 1235.194 | Q24: 10000 | R24: 0 | S24: =SUM(F24:R24) -> 123329.05 | U24: =SUM(F24+H24+N24)*0.075 -> 4631.9775 | V24: 1484.37 | W24: =V24+U24+T24 -> 6116.3475 | X24: 117212.7 | Y24: =S24-W24 -> 117212.7
A25: UZODINMA EMMANUEL EZENWA | D25: INFORMATION ASST | E25: 8(7) | F25: 12351.94 | H25: =F25*300% -> 37055.82 | I25: =F25*7.5% -> 926.3955 | J25: 0 | K25: =F25*50% -> 6175.97 | L25: =F25*350% -> 43231.79 | M25: 0 | N25: =F25*100% -> 12351.94 | O25: 0 | P25: =F25*10% -> 1235.194 | Q25: 10000 | R25: 0 | S25: =SUM(F25:R25) -> 123329.05 | U25: =SUM(F25+H25+N25)*0.075 -> 4631.9775 | V25: 1484.37 | W25: =V25+U25+T25 -> 6116.3475 | X25: 117212.7 | Y25: =S25-W25 -> 117212.7
A26: IBRAHIM TASSNEEM | D26: INFORMATION ASST | E26: 8(7) | F26: 12351.94 | H26: =F26*300% -> 37055.82 | I26: =F26*7.5% -> 926.3955 | J26: 0 | K26: =F26*50% -> 6175.97 | L26: =F26*350% -> 43231.79 | M26: 0 | N26: =F26*100% -> 12351.94 | O26: 0 | P26: =F26*10% -> 1235.194 | Q26: 10000 | R26: 0 | S26: =SUM(F26:R26) -> 123329.05 | U26: =SUM(F26+H26+N26)*0.075 -> 4631.9775 | V26: 1484.37 | W26: =V26+U26+T26 -> 6116.3475 | X26: 117212.7 | Y26: =S26-W26 -> 117212.7
A27: GLORIA NDIDI HELG | D27: CONFIDENTIAL SECRETARY | E27: 8(7) | F27: 12351.94 | H27: =F27*300% -> 37055.82 | I27: =F27*7.5% -> 926.3955 | J27: 0 | K27: =F27*50% -> 6175.97 | L27: =F27*350% -> 43231.79 | M27: 0 | N27: =F27*100% -> 12351.94 | O27: 0 | P27: =F27*10% -> 1235.194 | Q27: 10000 | R27: 0 | S27: =SUM(F27:R27) -> 123329.05 | U27: =SUM(F27+H27+N27)*0.075 -> 4631.9775 | V27: 1484.37 | W27: =V27+U27+T27 -> 6116.3475 | X27: 234425.4 | Y27: =S27-W27 -> 117212.7
A28: TOTAL | D28: 18 | F28: =SUM(F9:F27) -> 566467.23 | G28: =SUM(G9:G27) -> 50000 | H28: =SUM(H9:H27) -> 1538912.9 | I28: =SUM(I9:I27) -> 78595.016 | J28: =SUM(J9:J27) -> 361099.71 | K28: =SUM(K9:K27) -> 275209.18 | L28: =SUM(L9:L27) -> 1902390.9 | M28: =SUM(M9:M27) -> 40122.19 | ... Y28: =SUM(Y9:Y27) -> 5293478.4 | Z28: =Y28-X28 -> -61076.117
U29: =SUM(F29+H29+N29)*0.075 -> 0 | W29: =SUM(T29:V29)*0.075 -> 0
U30: =SUM(F30+H30+N30)*0.075 -> 0 | W30: =SUM(T30:V30)*0.075 -> 0
A31: LEG. SUPPORT SEVICES | U31: =SUM(F31+H31+N31)*0.075 -> 0 | W31: =SUM(T31:V31)*0.075 -> 0
A32: PROF OKECHUKWU OKO | D32: DIR. LEG. SP SERVICES | E32: 17(7) | F32: 76339.3 | H32: =F32*300% -> 229017.9 | I32: =F32*7.5% -> 5725.4475 | J32: 80244.38 | K32: =F32*50% -> 38169.65 | L32: =F32*350% -> 267187.55 | M32: 0 | N32: =F32*100% -> 76339.3 | O32: 150000 | P32: =F32*10% -> 7633.93 | Q32: 20000 | R32: 0 | S32: =SUM(F32:R32) -> 950657.46 | U32: =SUM(F32+H32+N32)*0.075 -> 28627.237 | V32: 52776.63 | W32: =V32+U32+T32 -> 81403.867 | X32: 869253.59 | Y32: =S32-W32 -> 869253.59
A33: DR SHUIBU DANWANKA | D33: DD LEG. SP SERVICES | E33: 16(7) | F33: 39662.25 | H33: =F33*300% -> 118986.75 | I33: =F33*7.5% -> 2974.6687 | J33: =J12 -> 40122.19 | K33: =F33*50% -> 19831.125 | L33: =F33*350% -> 138817.88 | M33: 0 | N33: =F33*100% -> 39662.25 | O33: 100000 | P33: =F33*10% -> 3966.225 | Q33: 20000 | R33: 0 | S33: =SUM(F33:R33) -> 524023.33 | U33: =SUM(F33+H33+N33)*0.075 -> 14873.344 | V33: 21618.09 | W33: =V33+U33+T33 -> 36491.434 | X33: 487531.9 | Y33: =S33-W33 -> 487531.9
A34: DR ANAH O. PAMELA | D34: SRF | E34: 15((9) | F34: 33507.5 | H34: =F34*300% -> 100522.5 | I34: =F34*7.5% -> 2513.0625 | J34: =J13 -> 40122.19 | K34: =F34*50% -> 16753.75 | L34: =F34*350% -> 117276.25 | M34: 0 | N34: =F34*100% -> 33507.5 | O34: 100000 | P34: =F34*10% -> 3350.75 | Q34: 20000 | R34: 0 | S34: =SUM(F34:R34) -> 467553.5 | U34: =SUM(F34+H34+N34)*0.075 -> 12565.312 | V34: 15548.33 | W34: =V34+U34+T34 -> 28113.643 | X34: 439439.86 | Y34: =S34-W34 -> 439439.86
A35: IBRAHIM USMAN | D35: RESEARCH FELLOW II | E35: 13(7) | F35: 23891.12 | G35: 0 | H35: =F35*300% -> 71673.36 | I35: =F35*7.5% -> 1791.834 | J35: =J50 -> 0 | K35: =F35*50% -> 11945.56 | L35: =F35*350% -> 83618.92 | M35: 0 | N35: =F35*100% -> 23891.12 | O35: 80000 | P35: =F35*10% -> 2389.112 | Q35: 15000 | R35: 0 | S35: =SUM(F35:R35) -> 314201.03 | U35: =SUM(F35+H35+N35)*0.075 -> 8959.17 | V35: 7709.76 | W35: =V35+U35+T35 -> 16668.93 | X35: 297532.1 | Y35: =S35-W35 -> 297532.1
A36: OFORDEME ADAOBI JULIA | D36: RESEARCH OFFICER | E36: 10(7) | F36: 17286.33 | G36: 0 | H36: =F36*300% -> 51858.99 | I36: =F36*7.5% -> 1296.4748 | J36: 0 | K36: =F36*50% -> 8643.165 | L36: =F36*350% -> 60502.155 | M36: 0 | N36: =F36*100% -> 17286.33 | O36: 40000 | P36: =F36*10% -> 1728.633 | Q36: 10000 | R36: 0 | S36: =SUM(F36:R36) -> 208602.08 | U36: =SUM(F36+H36+N36)*0.075 -> 6482.3738 | V36: 3369.51 | W36: =V36+U36+T36 -> 9851.8838 | X36: 198750.19 | Y36: =S36-W36 -> 198750.19
A37: IKPEAZU CHINEDU ANITA | D37: RESEARCH OFFICER | E37: 10(7) | F37: 17286.33 | H37: =F37*300% -> 51858.99 | I37: =F37*7.5% -> 1296.4748 | J37: 0 | K37: =F37*50% -> 8643.165 | L37: =F37*350% -> 60502.155 | M37: 0 | N37: =F37*100% -> 17286.33 | O37: 40000 | P37: =F37*10% -> 1728.633 | Q37: 10000 | R37: 0 | S37: =SUM(F37:R37) -> 208602.08 | U37: =SUM(F37+H37+N37)*0.075 -> 6482.3738 | V37: 3369.51 | W37: =V37+U37+T37 -> 9851.8838 | X37: 198750.19 | Y37: =S37-W37 -> 198750.19
A38: ONYEAKU CHUKWUKA EDMOND | D38: RESEARCH ASSISTANT | E38: 9(7) | F38: 14736.14 | G38: 0 | H38: =F38*300% -> 44208.42 | I38: =F38*7.5% -> 1105.2105 | J38: =J24 -> 0 | K38: =F38*50% -> 7368.07 | L38: =F38*350% -> 51576.49 | M38: 0 | N38: =F38*100% -> 14736.14 | O38: 40000 | P38: =F38*10% -> 1473.614 | Q38: 10000 | R38: 0 | S38: =SUM(F38:R38) -> 185204.08 | T38: 0 | U38: =SUM(F38+H38+N38)*0.075 -> 5526.0525 | V38: 2443.88 | W38: =V38+U38+T38 -> 7969.9325 | X38: 177234.15 | Y38: 177234.15
A39: TOTAL | D39: 7 | F39: =SUM(F32:F38) -> 222708.97 | G39: =SUM(G32:G38) -> 0 | H39: =SUM(H32:H38) -> 668126.91 | I39: =SUM(I32:I38) -> 16703.173 | J39: =SUM(J32:J38) -> 160488.76 | K39: =SUM(K32:K38) -> 111354.49 | L39: =SUM(L32:L38) -> 779481.4 | M39: =SUM(M32:M38) -> 0 | ... Y39: =SUM(Y32:Y38) -> 2668492
U40: =SUM(F40+H40+N40)*0.075 -> 0 | W40: =SUM(T40:V40)*0.075 -> 0
A41: RESEARCH & TRAINING | U41: =SUM(F41+H41+N41)*0.075 -> 0 | W41: =SUM(T41:V41)*0.075 -> 0
A42: DR BADAYI M. SANI | D42: DIR. RES. & TRAINING | E42: 17(7) | F42: 76339.3 | G42: 0 | H42: =F42*300% -> 229017.9 | I42: =F42*7.5% -> 5725.4475 | J42: 80244.38 | K42: =F42*50% -> 38169.65 | L42: =F42*350% -> 267187.55 | M42: 0 | N42: =F42*100% -> 76339.3 | O42: 150000 | P42: =F42*10% -> 7633.93 | Q42: 20000 | R42: 0 | S42: =SUM(F42:R42) -> 950657.46 | U42: =SUM(F42+H42+N42)*0.075 -> 28627.237 | V42: 52776.63 | W42: =V42+U42+T42 -> 81403.867 | X42: 1738507.2 | Y42: =S42-W42 -> 869253.59
...

Sheet MEMO
A1: NATIONAL INSTITUTE FOR LEGISLATIVE STUDIES
A4: INTERNAL MEMO
A6: FROM : DDF
A7: THROUGH: DFA
A8: TO: DG
A9: DATE: 22ND APRIL, 2013
A11: Subject: Payroll for the Month of April, 2013
A13: Find below the details of NILS Staff Payroll for the month of April, 2013:
E15: MARCH, 2013 | G15: APRIL, 2013
E16: NO OF | F16: AMOUNT | G16: NO OF | H16: AMOUNT
E17: STAFF | F17: N | G17: STAFF | H17: N
A18: 1 | B18: Director General's Office | E18: 18 | F18: ='April 2013'!X28 -> 5354554.5 | G18: 18 | H18: ='April 2013'!Y28 -> 5293478.4
A19: 2 | B19: Leg. Support Services | E19: 7 | F19: ='April 2013'!X39 -> 2668492 | G19: 7 | H19: ='April 2013'!Y39 -> 2668492
A20: 3 | B20: Research & Training | E20: 20 | F20: ='April 2013'!X61 -> 9843677.4 | G20: 20 | H20: ='April 2013'!Y61 -> 5850265.5
A21: 4 | B21: Finance/ Admin & HR | E21: 46 | F21: ='April 2013'!X109 -> 5818174.1 | G21: 46 | H21: ='April 2013'!Y109 -> 5807245.1
A22: 5 | B22: Casual Staff/NYSC | E22: 14 | F22: ='April 2013'!X130 -> 1024285 | G22: 14 | H22: ='April 2013'!Y130 -> 780000
A23: 6 | B23: NASS Deployed Staff | E23: 9 | F23: ='April 2013'!X142 -> 1386405.7 | G23: 9 | H23: ='April 2013'!Y142 -> 1593238
E24: =SUM(E18:E23) -> 114 | F24: =SUM(F18:F23) -> 26095589 | G24: =SUM(G18:G23) -> 114 | H24: =SUM(H18:H23) -> 21992719
A26: VARIATION IN MARCH , 2013 OVER FEBRUARY,2013 SALARIES
A28: NET PAY AS PER APRIL, 2013 PAYROLL | H28: =H24 -> 21992719
A29: NET PAY AS PER MARCH, 2013 PAYROLL | H29: =F24 -> 26095589
A30: NET INCREASE IN PAY FOR MARCH, 2013 | H30: =H28-H29 -> -4102869.7
A32: The net Salary Decrease is reconciled as follows:
A33: Effect of Stoppage of Priscilla Salary Reinstatement in March | G33: -108770.09
A34: Refund of Salary Underpayment to Priscilla in March | G34: 50000
A35: Effect of completion of Salary Advance deduction to staff | G35: 309828.72
A36: Refund of Salary Advance Over deduction to Dr Kanayo | G36: 155851.16
A37: Effect of stoppage of Salary Arears toLibrary Officer Asogwa | G37: -156160.86
A38: Payment of 28 days allowance in Lieu of Hotel to Library Officer | G38: 252000
A39: Stoppage of the Arears of Newly recruited Cleaner & NYSC | G39: -274285
A40: Payment of 13th Month allowance to AM Library | G40: 206832.29
A41: Payment of Uncredited Feb/March NYSC Allce to Ihedoro S. N. | G41: 30000
A42: Effect of stoppage of Feb non Remmitance to Gloria Helg | G42: -117234.15
A43: Effect of Stoppage of 13th Month Salary to Research Div. | G43: -4450953.3
A44: NET INCREASE IN PAY FOR MARCH, 2013 | H44: =SUM(G33:G43) -> -4102891.3
A46: The Director General is requested to consider and approve payment of N21,992,718.92 to First Bank for April, 2013 Salary,N667,813.76 to Various Pension Fund Administrators of Staff and N703,252.08 as PAYE TAX Deductions from Staff Salary for April, 2013
A49: Mshelia Madu Ibrahim
A50: Deputy Director, Finance & Accounts

Sheet 17.7
A1: SALARY DETAILS OF NILS DIRECTOR RESEARCH AND TRAINING
A2: GRADE LEVEL 17 STEP 7
D3: ANNUALLY | E3: MONTHLY
A4: Basic Salary | D4: =E4*12 -> 916071.6 | E4: =sUMMARY!F3 -> 76339.3
A5: Rent Subsidy | D5: =E5*12 -> 2748214.8 | E5: =sUMMARY!H3 -> 229017.9
A6: Utility | D6: =E6*12 -> 68705.37 | E6: =sUMMARY!I3 -> 5725.4475
A7: Domestic Staff Allowance | D7: =E7*12 -> 962932.56 | E7: =sUMMARY!J3 -> 80244.38
A8: Entertainment Allowance | D8: =E8*12 -> 458035.8 | E8: =sUMMARY!K3 -> 38169.65
A9: Furniture Allowance | D9: =E9*12 -> 3206250.6 | E9: =sUMMARY!L3 -> 267187.55
A10: Research Allowance | D10: =E10*12 -> 1800000 | E10: 150000
A11: Motor Fuel Allowance | D11: =E11*12 -> 916071.6 | E11: =sUMMARY!N3 -> 76339.3
A12: Leave Allowance | D12: =E12*12 -> 91607.16 | E12: =sUMMARY!O3 -> 7633.93
A13: Outfit Allowance | D13: =E13*12 -> 240000 | E13: =sUMMARY!P3 -> 20000
A14: GROSS SALARY | D14: =E14*12 -> 11407889 | E14: =SUM(E4:E13) -> 950657.46

Sheet 16.7
A1: SALARY DETAILS OF NILS DEPUTY DIRECTORS
A2: GRADE LEVEL 16 STEP 7
D3: ANNUALLY | E3: MONTHLY
A4: Basic Salary | D4: =E4*12 -> 475947 | E4: ='April 2013'!F10 -> 39662.25
A5: Rent Subsidy | D5: =E5*12 -> 1427841 | E5: ='April 2013'!H10 -> 118986.75
A6: Utility | D6: =E6*12 -> 35696.025 | E6: ='April 2013'!I10 -> 2974.6687
A7: Domestic Staff Allowance | D7: =E7*12 -> 481466.28 | E7: ='April 2013'!J10 -> 40122.19
A8: Entertainment Allowance | D8: =E8*12 -> 237973.5 | E8: ='April 2013'!K10 -> 19831.125
A9: Furniture Allowance | D9: =E9*12 -> 1665814.5 | E9: ='April 2013'!L10 -> 138817.88
A10: Motor Fuel Allowance | D10: =E10*12 -> 475947 | E10: ='April 2013'!N10 -> 39662.25
A11: Leave Allowance | D11: =E11*12 -> 47594.7 | E11: ='April 2013'!P10 -> 3966.225
A12: Outfit Allowance | D12: =E12*12 -> 240000 | E12: =sUMMARY!P3 -> 20000
A13: GROSS SALARY | D13: =E13*12 -> 5088280 | E13: =SUM(E4:E12) -> 424023.33

Sheet 15.9
A1: SALARY DETAILS OF NILS SENIOR RESEARCH FELLOWS
A2: GRADE LEVEL 15 STEP 9
D3: ANNUALLY | E3: MONTHLY
A4: Basic Salary | D4: =E4*12 -> #REF! | E4: ='April 2013'!#REF! -> #REF!
A5: Rent Subsidy | D5: =E5*12 -> #REF! | E5: ='April 2013'!#REF! -> #REF!
A6: Utility | D6: =E6*12 -> #REF! | E6: ='April 2013'!#REF! -> #REF!
A7: Domestic Staff Allowance | D7: =E7*12 -> #REF! | E7: ='April 2013'!#REF! -> #REF!
A8: Entertainment Allowance | D8: =E8*12 -> #REF! | E8: ='April 2013'!#REF! -> #REF!
A9: Furniture Allowance | D9: =E9*12 -> #REF! | E9: ='April 2013'!#REF! -> #REF!
A10: Motor Fuel Allowance | D10: =E10*12 -> #REF! | E10: ='April 2013'!#REF! -> #REF!
A11: Research Allowance | D11: =E11*12 -> 1200000 | E11: 100000
A12: Leave Allowance | D12: =E12*12 -> #REF! | E12: ='April 2013'!#REF! -> #REF!
A13: Outfit Allowance | D13: =E13*12 -> #REF! | E13: ='April 2013'!#REF! -> #REF!
A14: GROSS SALARY | D14: =E14*12 -> #REF! | E14: =SUM(E4:E13) -> #REF!

Sheet 13.7
A1: SALARY DETAILS OF NILS ASSISTANT MANAGER
A2: GRADE LEVEL 13 STEP 7
D3: ANNUALLY | E3: MONTHLY
A4: Basic Salary | D4: =E4*12 -> 286693.44 | E4: =sUMMARY!F5 -> 23891.12
A5: Rent Subsidy | D5: =E5*12 -> 860080.32 | E5: =sUMMARY!H5 -> 71673.36
A6: Utility | D6: =E6*12 -> 21502.008 | E6: =sUMMARY!I5 -> 1791.834
A7: Domestic Staff Allowance | D7: =E7*12 -> 0 | E7: =sUMMARY!J5 -> 0
A8: Entertainment Allowance | D8: =E8*12 -> 143346.72 | E8: =sUMMARY!K5 -> 11945.56
A9: Furniture Allowance | D9: =E9*12 -> 1003427 | E9: =sUMMARY!L5 -> 83618.92
A10: Motor Fuel Allowance | D10: =E10*12 -> 286693.44 | E10: =sUMMARY!N5 -> 23891.12
A11: Research Allowance | D11: =E11*12 -> 0 | E11: 0
A12: Leave Allowance | D12: =E12*12 -> 28669.344 | E12: =sUMMARY!O5 -> 2389.112
A13: Outfit Allowance | D13: =E13*12 -> 180000 | E13: =sUMMARY!P5 -> 15000
A14: GROSS SALARY | D14: =E14*12 -> 2810412.3 | E14: =SUM(E4:E13) -> 234201.03

Sheet 12.7
D3: ANNUALLY | E3: MONTHLY
A4: Basic Salary | D4: =E4*12 -> 255527.52 | E4: =sUMMARY!F6 -> 21293.96
A5: Rent Subsidy | D5: =E5*12 -> 766582.56 | E5: =sUMMARY!H6 -> 63881.88
A6: Utility | D6: =E6*12 -> 19164.564 | E6: =sUMMARY!I6 -> 1597.047
A7: Domestic Staff Allowance | D7: =E7*12 -> 0 | E7: =sUMMARY!J5 -> 0
A8: Entertainment Allowance | D8: =E8*12 -> 127763.76 | E8: =sUMMARY!K6 -> 10646.98
A9: Furniture Allowance | D9: =E9*12 -> 894346.32 | E9: =sUMMARY!L6 -> 74528.86
A10: Motor Fuel Allowance | D10: =E10*12 -> 255527.52 | E10: =sUMMARY!N6 -> 21293.96
A11: Leave Allowance | D11: =E11*12 -> 25552.752 | E11: =sUMMARY!O6 -> 2129.396
A12: Outfit Allowance | D12: =E12*12 -> 120000 | E12: =sUMMARY!P6 -> 10000
A13: GROSS SALARY | D13: =E13*12 -> 2464465 | E13: =SUM(E4:E12) -> 205372.08

Sheet 10.7
A1: SALARY DETAILS OF NILS RESEARCH OFFICERS
A2: GRADE LEVEL 10 STEP 7
D3: ANNUALLY | E3: MONTHLY
A4: Basic Salary | D4: =E4*12 -> 207435.96 | E4: =sUMMARY!F7 -> 17286.33
A5: Rent Subsidy | D5: =E5*12 -> 622307.88 | E5: =sUMMARY!H7 -> 51858.99
A6: Utility | D6: =E6*12 -> 15557.697 | E6: =sUMMARY!I7 -> 1296.4748
A7: Domestic Staff Allowance | D7: =E7*12 -> 0 | E7: =sUMMARY!J5 -> 0
A8: Entertainment Allowance | D8: =E8*12 -> 103717.98 | E8: =sUMMARY!K7 -> 8643.165
A9: Furniture Allowance | D9: =E9*12 -> 726025.86 | E9: =sUMMARY!L7 -> 60502.155
A10: Motor Fuel Allowance | D10: =E10*12 -> 207435.96 | E10: =sUMMARY!N7 -> 17286.33
A11: Research Allowance | D11: =E11*12 -> 480000 | E11: 40000
A12: Leave Allowance | D12: =E12*12 -> 20743.596 | E12: =sUMMARY!O7 -> 1728.633
A13: Outfit Allowance | D13: =E13*12 -> 120000 | E13: =sUMMARY!P6 -> 10000
A14: GROSS SALARY | D14: =E14*12 -> 2503224.9 | E14: =SUM(E4:E13) -> 208602.08

Sheet 9.7
A1: SALARY DETAILS OF NILS RESEARCH ASSISTANTS
A2: GRADE LEVEL 9 STEP 7
D3: ANNUALLY | E3: MONTHLY
A4: Basic Salary | D4: =E4*12 -> 176833.68 | E4: =sUMMARY!F8 -> 14736.14
A5: Rent Subsidy | D5: =E5*12 -> 530501.04 | E5: =sUMMARY!H8 -> 44208.42
A6: Utility | D6: =E6*12 -> 13262.526 | E6: =sUMMARY!I8 -> 1105.2105
A7: Domestic Staff Allowance | D7: =E7*12 -> 0 | E7: =sUMMARY!J5 -> 0
A8: Entertainment Allowance | D8: =E8*12 -> 88416.84 | E8: =sUMMARY!K8 -> 7368.07
A9: Furniture Allowance | D9: =E9*12 -> 618917.88 | E9: =sUMMARY!L8 -> 51576.49
A10: Motor Fuel Allowance | D10: =E10*12 -> 176833.68 | E10: =sUMMARY!N8 -> 14736.14
A11: Research Assistants | D11: =E11*12 -> 480000 | E11: 40000
A12: Leave Allowance | D12: =E12*12 -> 17683.368 | E12: =sUMMARY!O8 -> 1473.614
A13: Outfit Allowance | D13: =E13*12 -> 120000 | E13: =sUMMARY!P6 -> 10000
A14: GROSS SALARY | D14: =E14*12 -> 2222449 | E14: =SUM(E4:E13) -> 185204.08

Sheet 8.7
A1: SALARY OF SECRTARY ON SCALE 8 STEP 7
D3: ANNUALLY | E3: MONTHLY
A4: Basic Salary | D4: =E4*12 -> 148223.28 | E4: ='April 2013'!F91 -> 12351.94
A5: Rent Subsidy | D5: =E5*12 -> 444669.84 | E5: ='April 2013'!H80 -> 37055.82
A6: Utility | D6: =E6*12 -> 11116.746 | E6: ='April 2013'!I85 -> 926.3955
A7: Entertainment Allowance | D7: =E7*12 -> 74111.64 | E7: ='April 2013'!K81 -> 6175.97
A8: Furniture Allowance | D8: =E8*12 -> 518781.48 | E8: ='April 2013'!L80 -> 43231.79
A9: Motor Fuel Allowance | D9: =E9*12 -> 148223.28 | E9: ='April 2013'!N81 -> 12351.94
A10: Leave Allowance | D10: =E10*12 -> 14822.328 | E10: ='April 2013'!P78 -> 1235.194
A11: Outfit Allowance | D11: =E11*12 -> 120000 | E11: ='April 2013'!Q81 -> 10000
A12: GROSS SALARY | D12: =E12*12 -> 1479948.6 | E12: =SUM(E4:E11) -> 123329.05

Sheet sUMMARY
F1: BASIC | G1: 28 DAYS ALCE | M1: PERSONAL | N1: MOTOR/ | O1: RESEARCH | P1: LEAVE | Q1: OUT FIT | R1: LEGISLATIVE | S1: GROSS | U1: MAR.2012 | V1: FEB. 2012
F2: SALARY | G2: IN LIEU | H2: RENT | I2: UTILITY | J2: DOMESTIC | K2: ENTERT. | L2: FURNIT. | M2: ASSISTANT | N2: FUEL | O2: ALLOWANCE | P2: ALLCE | Q2: ALLCE | R2: DUTY ALLCE | S2: SALARY | T2: PAYE
A3: DIRECTOR | E3: 17/7 | F3: 76339.3 | H3: =F3*300% -> 229017.9 | I3: =F3*7.5% -> 5725.4475 | J3: 80244.38 | K3: =F3*50% -> 38169.65 | L3: =F3*350% -> 267187.55 | M3: 0 | N3: =F3*100% -> 76339.3 | O3: =F3*10% -> 7633.93 | P3: 20000 | Q3: 0 | R3: =SUM(F3:Q3) -> 800657.46
A4: RESEARCH FELLOW I | E4: 14(7) | F4: 24975.81 | G4: 0 | H4: =F4*300% -> 74927.43 | I4: =F4*7.5% -> 1873.1858 | J4: 0 | K4: =F4*50% -> 12487.905 | L4: =F4*350% -> 87415.335 | M4: 0 | N4: =F4*100% -> 24975.81 | O4: 100000 | P4: =F4*10% -> 2497.581 | Q4: 20000 | R4: 0 | S4: =SUM(F4:R4) -> 349153.06 | T4: 0 | U4: =S4-T4 -> 349153.06 | V4: 344720.6
A5: RESEARCH FELLOW II | E5: 13/7 | F5: 23891.12 | H5: =F5*300% -> 71673.36 | I5: =F5*7.5% -> 1791.834 | J5: 0 | K5: =F5*50% -> 11945.56 | L5: =F5*350% -> 83618.92 | M5: 0 | N5: =F5*100% -> 23891.12 | O5: =F5*10% -> 2389.112 | P5: 15000 | Q5: 0 | R5: =SUM(F5:Q5) -> 234201.03
A6: RESEARCH FELLOW | E6: 12/7 | F6: 21293.96 | H6: =F6*300% -> 63881.88 | I6: =F6*7.5% -> 1597.047 | J6: 0 | K6: =F6*50% -> 10646.98 | L6: =F6*350% -> 74528.86 | M6: 0 | N6: =F6*100% -> 21293.96 | O6: =F6*10% -> 2129.396 | P6: 10000 | Q6: 0 | R6: =SUM(F6:Q6) -> 205372.08
A7: RESEARCH OFFICER | E7: 10/7 | F7: 17286.33 | H7: =F7*300% -> 51858.99 | I7: =F7*7.5% -> 1296.4748 | J7: 0 | K7: =F7*50% -> 8643.165 | L7: =F7*350% -> 60502.155 | M7: 0 | N7: =F7*100% -> 17286.33 | O7: =F7*10% -> 1728.633 | P7: 10000 | Q7: 0 | R7: =SUM(F7:Q7) -> 168602.08
A8: RESEARCH ASSISTANTS | E8: 9/7 | F8: 14736.14 | H8: =F8*300% -> 44208.42 | I8: =F8*7.5% -> 1105.2105 | J8: 0 | K8: =F8*50% -> 7368.07 | L8: =F8*350% -> 51576.49 | M8: 0 | N8: =F8*100% -> 14736.14 | O8: =F8*10% -> 1473.614 | P8: 10000 | Q8: 0 | R8: =SUM(F8:Q8) -> 145204.08
E9: 8/7 | F9: 12351.94 | H9: =F9*300% -> 37055.82 | I9: =F9*7.5% -> 926.3955 | J9: 0 | K9: =F9*50% -> 6175.97 | L9: =F9*350% -> 43231.79 | M9: 0 | N9: =F9*100% -> 12351.94 | O9: =F9*10% -> 1235.194 | P9: 10000 | Q9: 0 | R9: =SUM(F9:Q9) -> 123329.05

Sheet 14.7
A1: SALARY DETAILS OF NILS RESEARCH FELLOW I
A2: GRADE LEVEL 14 STEP 7
D3: ANNUALLY | E3: MONTHLY
A4: Basic Salary | D4: =E4*12 -> 299709.72 | E4: =sUMMARY!F4 -> 24975.81
A5: Rent Subsidy | D5: =E5*12 -> 899129.16 | E5: =sUMMARY!H4 -> 74927.43
A6: Utility | D6: =E6*12 -> 22478.229 | E6: =sUMMARY!I4 -> 1873.1858
A7: Domestic Staff Allowance | D7: =E7*12 -> 0 | E7: =sUMMARY!J5 -> 0
A8: Entertainment Allowance | D8: =E8*12 -> 149854.86 | E8: =sUMMARY!K4 -> 12487.905
A9: Furniture Allowance | D9: =E9*12 -> 1048984 | E9: =sUMMARY!L4 -> 87415.335
A10: Motor Fuel Allowance | D10: =E10*12 -> 299709.72 | E10: =sUMMARY!N4 -> 24975.81
A11: Research Allowance | D11: =E11*12 -> 1200000 | E11: =sUMMARY!O4 -> 100000
A12: Leave Allowance | D12: =E12*12 -> 29970.972 | E12: =sUMMARY!P4 -> 2497.581
A13: Outfit Allowance | D13: =E13*12 -> 240000 | E13: =sUMMARY!Q4 -> 20000
A14: GROSS SALARY | D14: =E14*12 -> 4189836.7 | E14: =SUM(E4:E13) -> 349153.06

Sheet Sheet2
A1: LIST OF STAFF THAT HAVE ASSUMED DUTY
A2: STAFF NAME
D3: DESIGNATION | E3: SALARY
E4: LEVEL
A5: DG OFFICE
A6: DR LADI HAMALAI | D6: DG | E6: CONSOL
A7: PROF. OFFORNZE AMUCHEAZI | D7: LEGAL ADVISER | E7: 16(7)
A8: MOHAMMED ISIAKA YAKUBU | D8: SPECIAL ASSISTANT | E8: 16(7)
A9: RICHARD KWALMI | D9: DSM | E9: 15(7)
A10: ABDULSALAM MUSTAFA | D10: ICT OFFICER | E10: 10(10)
A11: ALI ABDULLAHI | D11: 1CT ASSISTANT | E11: 8(2)
A13: LEG. SUPPORT SEVICES
A14: DR SHUIBU DANWANKA | D14: DD | E14: 16(7)
A16: RESEARCH & TRAINING
A17: DR ASIMIYU G. ABIOLA | D17: DD RESEARCH | E17: 16(7)
A18: SOLOMON A. BENJAMIN | D18: DD TRAINING | E18: 16(7)
A19: DR PATTERSON EKEOCHA | D19: SRF | E19: 15(9)
A21: FINANCE & ADMIN.
A22: DR KABIR AHMED | D22: DFA | E22: 17(7)
A23: IBRAHIM M. MSHELIA | D23: DD F&A | E23: 16(7)
A24: AMINU BELLO DUKKU | D24: DD ADMIN/HR | E24: 16(7)
A25: RAHILA AMOS | D25: OFFICER ACCTS | E25: 10(11)
A26: HUSSEIN MUSA AGYE | D26: PROTOCOL OFFICER | E26: 10(&)
A27: USMAN WAZIRI | D27: SEC. FINANCE | E27: 8(9)
A28: SALAMATU YAKUBU | D28: SECRETARY | E28: 8(9)
A29: IDAHOSA JANE CECILIA | D29: SECRETARY | E29: 8/(9)
A30: ESTHER WAMINAJE | D30: SECRETARY | E30: 8(9)
A31: ANTHONY EDET | D31: RECEPTIONIST | E31: 8(2)
A32: OLATUNJI OYEDELE YUSUF | D32: DRIVER | E32: 4(10)
A33: TASIU MOHAMMED | D33: DRIVER | E33: 4(10)
... A41: ABDULLAHI HARUNA | D41: DRIVER | E41: 3(8)
A42: ABDULWAHAB DAHIRU | D42: DISPATCH CLERK
A43: GIDEON B. LAMIDO | D43: DISPATCH CLERK
A44: JOHN JAMBU ASIGAN | D44: STEWARD
A45: AYUBA SULE | D45: STEWARD
A46: EWELIKWA IJEOMA NKOLIKWA | D46: STEWARD

Sheet 5.7
A1: SALARY DETAILS OF NILS SENIOR MOTOR DRIVER-MECHANIC
A2: GRADE LEVEL 5 STEP 7
D3: ANNUALLY | E3: MONTHLY
A4: Basic Salary | D4: =E4*12 -> #REF! | E4: ='April 2013'!#REF! -> #REF!
A5: Rent Subsidy | D5: =E5*12 -> #REF! | E5: ='April 2013'!#REF! -> #REF!
A6: Utility | D6: =E6*12 -> #REF! | E6: ='April 2013'!#REF! -> #REF!
A7: Domestic Staff Allowance | D7: =E7*12 -> 0 | E7: =sUMMARY!J5 -> 0
A8: Entertainment Allowance | D8: =E8*12 -> #REF! | E8: ='April 2013'!#REF! -> #REF!
A9: Furniture Allowance | D9: =E9*12 -> #REF! | E9: ='April 2013'!#REF! -> #REF!
A10: Motor Fuel Allowance | D10: =E10*12 -> #REF! | E10: ='April 2013'!#REF! -> #REF!
A11: Research Allowance | D11: =E11*12 -> 0 | E11: 0
A12: Leave Allowance | D12: =E12*12 -> #REF! | E12: ='April 2013'!#REF! -> #REF!
A13: Outfit Allowance | D13: =E13*12 -> #REF! | E13: ='April 2013'!#REF! -> #REF!
A14: GROSS SALARY | D14: =E14*12 -> #REF! | E14: =SUM(E4:E13) -> #REF!

Sheet Noninal roll
A2: NOMINAL ROLL AND 2012 PERSONEL COST ESTIMATION
A3: S/NO | B3: DESIGNATION | C3: SALARY LEVEL | D3: NUMBER | E3: ANNUAL SALARY | F3: TOTAL
A5: 1 | B5: DIRECTOR GENERAL | C5: CONS. | D5: 1 | E5: =1580439.5*12 -> 18965274 | F5: =E5*D5 -> 18965274
A6: 2 | B6: DIRECTORS | C6: 17(7) | D6: 4 | E6: 9607889.5 | F6: =E6*D6 -> 38431558
A7: 3 | B7: LEGAL ADVISER | C7: 16(7) | D7: 1 | E7: =424023.33*12 -> 5088280 | F7: =E7*D7 -> 5088280
A8: 4 | B8: SPECIAL ASSISTANT | C8: 16(7) | D8: 2 | E8: =424023.33*12 -> 5088280 | F8: =E8*D8 -> 10176560
A9: 5 | B9: DEUTY DIRECTORS | C9: 16(7) | D9: 10 | E9: 5088280 | F9: =E9*D9 -> 50882800
A10: 6 | B10: SENIOR RESEARCH FELLOWS | C10: 16(7) | D10: 10 | E10: 4136647.2 | F10: =E10*D10 -> 41366472
A11: 7 | B11: MANAGERS | C11: 15(7) | D11: 12 | E11: =344720.6*12 -> 4136647.2 | F11: =E11*D11 -> 49639766
A12: 8 | B12: RESEARCH FELLOW I | C12: 14(7) | D12: 10 | E12: =249153.06*12 -> 2989836.7 | F12: =E12*D12 -> 29898367
A13: 9 | B13: ASSISTANT MANAGERS | C13: 13(7) | D13: 8 | E13: 2810412.4 | F13: =E13*D13 -> 22483299
A14: 10 | B14: OFFICERS | C14: 10(7) | D14: 15 | E14: =168602.08*12 -> 2023225 | F14: =E14*D14 -> 30348374
A15: 11 | B15: OFFICE ASSISTANTS | C15: 8(7) | D15: 20 | E15: =123329.05*12 -> 1479948.6 | F15: =E15*D15 -> 29598972
A16: 12 | B16: SECRETARIES | C16: 8(9) | D16: 15 | E16: =130304.44*12 -> 1563653.3 | F16: =E16*D16 -> 23454799
A17: 13 | B17: DRIVERS | C17: 4(10) | D17: 20 | E17: =46676.06*12 -> 560112.72 | F17: =E17*D17 -> 11202254
D18: =SUM(D9:D17) -> 100 | F18: =SUM(F5:F17) -> 3.6153678e+08

Sheet Sheet1
A1: STAFF NAME
A2: DG OFFICE
A3: DR LADI HAMALAI | D3: DIRECTOR GENERAL | E3: CONSOL
A4: PROF. OFFORNZE AMUCHEAZI | D4: LEGAL ADVISER | E4: 16(7)
A5: MOHAMMED ISIAKA YAKUBU | D5: SPECIAL ASSISTANT | E5: 16(7)
A6: RICHARD KWALMI | D6: MICT | E6: 15(7)
A7: ADAMU ISA ABBA | D7: INFO. MANAGER | E7: 15(7)
A8: NWOSU MATHEW EZE | D8: MANAGER INT. AUDIT | E8: 15(7)
A9: KENNETH OKEREAFOR | D9: AM MICT | E9: 13(7)
A10: AKINSANMI ADEJOKE OLUKEMI | D10: AM INFORMATION | E10: 13(7)
A11: FAROUK U. M ILLO | D11: PA DG | E11: 13(7)
A12: UMOLU ADAEZE OBIAMAKA | D12: INFO OFFICER | E12: 10(7)
A13: TONDO IORWUESEEDWARD | D13: OFFICER INT AUDIT | E13: 10(7)
A14: MUSTAFA ABUBAKAR RUFAU | D14: OFFICER SPECIAL DUTIES | E14: 10(7)
... A100: JIBRIN USHAMA AHMED | D100: OFFICER LEGAL | E100: 10(7)
