Workbook

Sheet NOVEMBER 2023
A1: NATIONAL INSTITUTE FOR LEGISLATIVE AND DEMOCRATIC STUDIES | H1: ='[1]FEB 08'!F8/'[1]FEB 08'!Q8 -> 0.3
A2: STAFF PAYROLL FOR THE MONTH OF NOVEMBER 2023
E3: ='[1]FEB 08'!E11/'[1]FEB 08'!M11 -> #REF! | H3: ='[1]FEB 08'!F11/'[1]FEB 08'!Q11 -> #REF!
B4: STAFF NAME | C4: DESIGNATION | D4: GRADE LEVEL | E4: BASIC SALARY | F4: ALLCE/ AREARS | G4: RENT | H4: UTILITY | I4: DOMESTIC | J4: ENTERT. | K4: FURNIT. | L4: FUEL | M4: ALLOWANCE | N4: ALLOWANCE | O4: ALLCE | P4: ALLCE | Q4: DUTY ALLCE | R4: GROSS SALARY | S4: AUCTION | T4: COOP CONTR/SPEC SAVINGS | U4: COOP. LOAN RECOVERY | V4: NHF DED. | W4: PAYE | X4: TOTAL DEDUCTION | Y4: OCTOBER, 2023 | Z4: NOVEMBER, 2023
E5: N | G5: N | H5: N | I5: N | J5: N | K5: N | L5: N | M5: N | N5: N | O5: N | P5: N | Q5: N | R5: N | S5: N | T5: N | U5: N | V5: N | W5: N | X5: N | Y5: N | Z5: N
A6: S/N | B6: DG'S OFFICE
A7: 1 | B7: PROF. ABUBAKAR O. SULAIMAN | C7: DIRECTOR GENERAL | D7: CONSOL | E7: 160488.75 | G7: 320977.5 | H7: 48146.63 | I7: 120366.57 | J7: 72219.94 | K7: 0 | L7: 120366.57 | M7: =250000 -> 250000 | O7: 16048.88 | P7: 25000 | Q7: 25235 | R7: =Q7+P7+O7+N7+M7+L7+K7+J7+I7+H7+G7+F7+E7 -> 1158849.8 | W7: 201165.84 | X7: =W7+V7+U7+T7+S7 -> 201165.84 | Y7: 957684 | Z7: =R7-X7 -> 957684
A8: 2 | B8: RAHEEM USMAN AYIGORO | C8: SA-INFRASTRUCTURE | D8: 16 (9) | E8: =42653.17 -> 42653.17 | G8: =E8*300% -> 127959.51 | H8: =E8*7.5% -> 3198.9877 | I8: 40122.19 | J8: =E8*50% -> 21326.585 | K8: =E8*350% -> 149286.1 | L8: =E8*100% -> 42653.17 | N8: =90000 -> 90000 | O8: =E8*10% -> 4265.317 | P8: 20000 | Q8: 0 | R8: =Q8+P8+O8+N8+M8+L8+K8+J8+I8+H8+G8+F8+E8 -> 541465.02 | T8: =100000 -> 100000 | W8: 82627.951 | X8: =W8+V8+U8+T8+S8 -> 182627.95 | Y8: 358837.07 | Z8: =R8-X8 -> 358837.07
A9: 3 | B9: e | C9: SA- SPECIAL DUTIES | D9: 16(8) | E9: 41157.69 | G9: =E9*300% -> 123473.07 | H9: =E9*7.5% -> 3086.8268 | I9: 40122.19 | J9: =E9*50% -> 20578.845 | K9: =E9*350% -> 144051.92 | L9: =E9*100% -> 41157.69 | N9: =90000 -> 90000 | O9: =E9*10% -> 4115.769 | P9: 20000 | Q9: =100000+100000 -> 200000 | R9: =Q9+P9+O9+N9+M9+L9+K9+J9+I9+H9+G9+F9+E9 -> 727744 | W9: 118393.51 | X9: =W9+V9+U9+T9+S9 -> 118393.51 | Y9: 609350.49 | Z9: =R9-X9 -> 609350.49
A10: 4 | B10: DR IKEME ARTHUR J.O | C10: DEPUTY DIRECTOR, M&E | D10: 16(8) | E10: =41157.69 -> 41157.69 | G10: =E10*300% -> 123473.07 | H10: =E10*7.5% -> 3086.8268 | I10: 40122.19 | J10: =E10*50% -> 20578.845 | K10: =E10*350% -> 144051.92 | L10: =E10*100% -> 41157.69 | M10: 180000 | O10: =E10*10% -> 4115.769 | P10: 20000 | Q10: 0 | R10: =Q10+P10+O10+N10+M10+L10+K10+J10+I10+H10+G10+F10+E10 -> 617744 | T10: =50000 -> 50000 | U10: 0 | V10: 1028.9423 | W10: 97112.68 | X10: =W10+V10+U10+T10+S10 -> 148141.62 | Y10: 309185.7 | Z10: =R10-X10 -> 469602.37
A11: 5 | B11: MOSHOOD M. OLALERE | C11: DEPUTY DIR. GENERAL SERVICE | D11: 16(8) | E11: =41157.69 -> 41157.69 | G11: =E11*300% -> 123473.07 | H11: =E11*7.5% -> 3086.8268 | I11: 40122.19 | J11: =E11*50% -> 20578.845 | K11: =E11*350% -> 144051.92 | L11: =E11*100% -> 41157.69 | N11: =80000+10000 -> 90000 | O11: =E11*10% -> 4115.769 | P11: 20000 | Q11: 150000 | R11: =Q11+P11+O11+N11+M11+L11+K11+J11+I11+H11+G11+F11+E11 -> 677744 | T11: =20000+60000 -> 80000 | U11: ='[2]OCTOBER 2023 '!$D$193 -> 230499.8 | V11: 1028.9423 | W11: =108632.68 -> 108632.68 | X11: =W11+V11+U11+T11+S11 -> 420161.42 | Y11: 257582.57 | Z11: =R11-X11 -> 257582.57
A12: 6 | B12: REKIYA IBRAHIM ATTAH | C12: DEPUTY DIRECTOR TRAINING | D12: 16(8) | E12: 41157.69 | G12: =E12*300% -> 123473.07 | H12: =E12*7.5% -> 3086.8268 | I12: 40122.19 | J12: =E12*50% -> 20578.845 | K12: =E12*350% -> 144051.92 | L12: =E12*100% -> 41157.69 | N12: =90000 -> 90000 | O12: =E12*10% -> 4115.769 | P12: 20000 | Q12: 100000 | R12: =SUM(E12:Q12) -> 627744 | T12: =50000 -> 50000 | U12: =91666.67 -> 91666.67 | W12: =99193.51 -> 99193.51 | X12: =W12+V12+U12+T12+S12 -> 240860.18 | Y12: 306083.81 | Z12: =R12-X12 -> 386883.82
A13: 7 | B13: ANDRAWUS MUSA | C13: ASST. DIRECTOR, STORES | D13: 15(9) | E13: 33507.5 | G13: =E13*300% -> 100522.5 | H13: =E13*7.5% -> 2513.0625 | I13: =40122.19 -> 40122.19 | J13: =E13*50% -> 16753.75 | K13: =E13*350% -> 117276.25 | L13: =E13*100% -> 33507.5 | N13: =80000 -> 80000 | O13: =E13*10% -> 3350.75 | P13: 20000 | Q13: 50000 | R13: =Q13+P13+O13+N13+M13+L13+K13+J13+I13+H13+G13+F13+E13 -> 497553.5 | T13: =50000-40000 -> 10000 | U13: =90000+110000 -> 200000 | V13: 837.6875 | W13: =74036.1 -> 74036.1 | X13: =W13+V13+U13+T13+S13 -> 284873.79 | Y13: 212679.72 | Z13: =R13-X13 -> 212679.72
A14: 8 | B14: DR FRANCIS NDUM OJIE | C14: AD, TRAINING & IC./SA TO DG | D14: 15(7) | E14: 31019.84 | G14: =E14*300% -> 93059.52 | H14: =E14*7.5% -> 2326.488 | I14: =40122.19 -> 40122.19 | J14: =E14*50% -> 15509.92 | K14: =E14*350% -> 108569.44 | L14: =E14*100% -> 31019.84 | M14: 160000 | O14: =E14*10% -> 3101.984 | P14: 20000 | Q14: =100000 -> 100000 | R14: =SUM(E14:Q14) -> 604729.22 | V14: =PROMOTIONS!V29 -> 837.69 | W14: =[3]PROMOTIONS!$X$29 -> 94644.622 | X14: =W14+V14+U14+T14+S14 -> 95482.312 | Y14: 730769.31 | Z14: =R14-X14 -> 509246.91
A15: 9 | B15: ALI ABDULLAHI | C15: CHIEF ICT OFFICER | D15: 14(10) | E15: 27611.23 | G15: =E15*300% -> 82833.69 | H15: =E15*7.5% -> 2070.8422 | I15: 0 | J15: =E15*50% -> 13805.615 | K15: =E15*350% -> 96639.305 | L15: =E15*100% -> 27611.23 | N15: =70000 -> 70000 | O15: =E15*10% -> 2761.123 | P15: 20000 | Q15: =0 -> 0 | R15: =Q15+P15+O15+N15+M15+L15+K15+J15+I15+H15+G15+F15+E15 -> 343333.04 | W15: 44846.62 | X15: =W15+V15+U15+T15+S15 -> 44846.62 | Y15: 298486.42 | Z15: =R15-X15 -> 298486.42
A16: 10 | B16: ABDULSALAM S. MUSTAPHA | C16: ASST. MANAGER ICT | D16: 13(11) | E16: 26339.3 | F16: ='NEW ENROLMENT IN NOVEMBER (2)'!X7 -> 284617.02 | G16: =E16*300% -> 79017.9 | H16: =E16*7.5% -> 1975.4475 | I16: 0 | J16: =E16*50% -> 13169.65 | K16: =E16*350% -> 92187.55 | L16: =E16*100% -> 26339.3 | N16: 70000 | O16: =E16*10% -> 2633.93 | P16: 15000 | R16: =SUM(E16:Q16) -> 611280.09 | W16: =42046.06 -> 42046.06 | X16: =42046.06 -> 42046.06 | Y16: 0 | Z16: =R16-X16 -> 569234.03
A17: 11 | B17: PERCY TERFA GBAHABO | C17: HEAD, NILDS LIAISON OFFICE | D17: 13(9) | E17: 24741.26 | G17: =E17*300% -> 74223.78 | H17: =E17*7.5% -> 1855.5945 | I17: 0 | J17: =E17*50% -> 12370.63 | K17: =E17*350% -> 86594.41 | L17: =E17*100% -> 24741.26 | M17: =120000 -> 120000 | O17: =E17*10% -> 2474.126 | P17: 15000 | Q17: 0 | R17: =Q17+P17+O17+N17+M17+L17+K17+J17+I17+H17+G17+F17+E17 -> 362001.06 | T17: =50000 -> 50000 | U17: 0 | W17: 46666.667 | X17: =W17+V17+U17+T17+S17 -> 96666.667 | Y17: 265334.39 | Z17: =R17-X17 -> 265334.39
A18: 12 | B18: HASSANA AHMED IBRAHIM | C18: PA- TO DG | D18: 13 (8) | E18: =23891.12 -> 23891.12 | G18: =E18*300% -> 71673.36 | H18: =E18*7.5% -> 1791.834 | J18: =E18*50% -> 11945.56 | K18: =E18*350% -> 83618.92 | L18: =E18*100% -> 23891.12 | M18: =120000 -> 120000 | O18: =E18*10% -> 2389.112 | P18: 15000 | Q18: =100000 -> 100000 | R18: =Q18+P18+O18+N18+M18+L18+K18+J18+I18+H18+G18+F18+E18 -> 454201.03 | T18: =30000-20000 -> 10000 | U18: =95833.33 -> 95833.33 | V18: 597.278 | W18: =65873.26 -> 65873.26 | X18: =W18+V18+U18+T18+S18 -> 172303.87 | Y18: 281897.16 | Z18: =R18-X18 -> 281897.16
A19: 13 | B19: ADUGBA RICHARD TERSEER | C19: PRINCIPAL INFO. OFFICER | D19: 12(8) | E19: 21520.88 | G19: =E19*300% -> 64562.64 | H19: =E19*7.5% -> 1614.066 | J19: =E19*50% -> 10760.44 | K19: =E19*350% -> 75323.08 | L19: =E19*100% -> 21520.88 | N19: =60000 -> 60000 | O19: =E19*10% -> 2152.088 | P19: 15000 | R19: =Q19+P19+O19+N19+M19+L19+K19+J19+I19+H19+G19+F19+E19 -> 272454.07 | T19: =20000 -> 20000 | U19: =111833.33 -> 111833.33 | W19: 32008.563 | X19: =W19+V19+U19+T19+S19 -> 163841.89 | Y19: 108612.18 | Z19: =R19-X19 -> 108612.18
A20: 14 | B20: LUCKY AGWOM | C20: RESEARCH ASSISTANT | D20: 12(7) | E20: =20749 -> 20749 | G20: =E20*300% -> 62247 | H20: =E20*7.5% -> 1556.175 | J20: =E20*50% -> 10374.5 | K20: =E20*350% -> 72621.5 | L20: =E20*100% -> 20749 | M20: =100000 -> 100000 | O20: =E20*10% -> 2074.9 | P20: 10000 | Q20: 100000 | R20: =SUM(E20:Q20) -> 400372.08 | W20: =55538.11 -> 55538.11 | X20: =W20+V20+U20+T20+S20 -> 55538.11 | Y20: 201544.33 | Z20: =R20-X20 -> 344833.97
A21: 15 | B21: ELIZABETH OGECHUKWU ONYEAKU | C21: ICT OFFICER | D21: 9(8) | E21: 14736.14 | G21: 44208.42 | H21: 1105.2105 | J21: 7368.07 | K21: 51576.49 | L21: 14736.14 | N21: 60000 | O21: 1473.614 | P21: 10000 | R21: =Q21+P21+O21+N21+M21+L21+K21+J21+I21+H21+G21+F21+E21 -> 205204.08 | T21: 10000 | U21: =20000 -> 20000 | W21: 21640.953 | X21: =W21+V21+U21+T21+S21 -> 51640.953 | Y21: 153563.13 | Z21: =R21-X21 -> 153563.13
A22: 16 | B22: VICTOR ASUKWO | C22: ICT OFFICER | D22: 9(8) | E22: =15188.67 -> 15188.67 | G22: =E22*300% -> 45566.01 | H22: =E22*7.5% -> 1139.1502 | J22: =E22*50% -> 7594.335 | K22: =E22*350% -> 53160.345 | L22: =E22*100% -> 15188.67 | N22: =50000+10000 -> 60000 | O22: =E22*10% -> 1518.867 | P22: 10000 | R22: =Q22+P22+O22+N22+M22+L22+K22+J22+I22+H22+G22+F22+E22 -> 209356.05 | W22: 22338.483 | X22: =W22+V22+U22+T22+S22 -> 22338.483 | Y22: 187017.56 | Z22: =R22-X22 -> 187017.56
A23: 17 | B23: ABDULRAHMAN A SULAIMAN | C23: STORE OFFICER | D23: 9(7) | E23: 14736.14 | G23: =E23*300% -> 44208.42 | H23: =E23*7.5% -> 1105.2105 | J23: =E23*50% -> 7368.07 | K23: =E23*350% -> 51576.49 | L23: =E23*100% -> 14736.14 | N23: =60000 -> 60000 | O23: =E23*10% -> 1473.614 | P23: 10000 | R23: =SUM(E23:Q23) -> 205204.08 | T23: =20000 -> 20000 | U23: =17500 -> 17500 | W23: =[3]PROMOTIONS!$X$7 -> 21640.883 | X23: =W23+V23+U23+T23+S23 -> 59140.883 | Y23: 228517.28 | Z23: =R23-X23 -> 146063.2
A24: 18 | B24: DARE SHEU MAGBON | C24: ASSIST. PG | D24: 8(10) | E24: 13492.21 | G24: =E24*300% -> 40476.63 | H24: =E24*7.5% -> 1011.9157 | J24: =E24*50% -> 6746.105 | K24: =E24*350% -> 47222.735 | L24: =E24*100% -> 13492.21 | N24: =50000 -> 50000 | O24: =E24*10% -> 1349.221 | P24: 10000 | R24: =SUM(E24:Q24) -> 183791.03 | T24: =30000+20000 -> 50000 | U24: 0 | W24: 18102.903 | X24: =W24+V24+U24+T24+S24 -> 68102.903 | Y24: 115688.12 | Z24: =R24-X24 -> 115688.12
A25: 19 | B25: JIMOH ADEBAYO ZAKA | C25: ASST. OFFICER/COMM | D25: 9(8) | E25: 15188.67 | G25: =E25*300% -> 45566.01 | H25: =E25*7.5% -> 1139.1502 | J25: =E25*50% -> 7594.335 | K25: =E25*350% -> 53160.345 | L25: =E25*100% -> 15188.67 | N25: =60000 -> 60000 | O25: =E25*10% -> 1518.867 | P25: 10000 | R25: =Q25+P25+O25+N25+M25+L25+K25+J25+I25+H25+G25+F25+E25 -> 209356.05 | T25: =50000 -> 50000 | U25: 50000 | V25: 0 | W25: 22338.483 | X25: =W25+V25+U25+T25+S25 -> 122338.48 | Y25: 87017.565 | Z25: =R25-X25 -> 87017.565
A26: 20 | B26: MOHAMMED BELLO | C26: PROTOCOL ASSISTANT | D26: 8(8) | E26: =12732 -> 12732 | G26: =E26*300% -> 38196 | H26: =E26*7.5% -> 954.9 | J26: =E26*50% -> 6366 | K26: =E26*350% -> 44562 | L26: =E26*100% -> 12732 | N26: =50000 -> 50000 | O26: =E26*10% -> 1273.2 | P26: 10000 | R26: =SUM(E26:Q26) -> 176816.1 | T26: =0 -> 0 | U26: =26666.67 -> 26666.67 | W26: 17042.714 | X26: =W26+V26+U26+T26+S26 -> 43709.384 | Y26: 133106.72 | Z26: =R26-X26 -> 133106.72
A27: 21 | B27: SULEIMAN ABUBAKAR SODEEQ | C27: ASST. ADMIN. OFFICER | D27: 8(8) | E27: =12732 -> 12732 | G27: =E27*300% -> 38196 | H27: =E27*7.5% -> 954.9 | J27: =E27*50% -> 6366 | K27: =E27*350% -> 44562 | L27: =E27*100% -> 12732 | N27: =50000 -> 50000 | O27: =E27*10% -> 1273.2 | P27: 10000 | R27: =SUM(E27:Q27) -> 176816.1 | T27: =0 -> 0 | W27: 17042.866 | X27: =W27+V27+U27+T27+S27 -> 17042.866 | Y27: 159773.23 | Z27: =R27-X27 -> 159773.23
A28: 22 | B28: HARUNA JIBRIL AMEH | C28: ASST. ADMIN. OFFICER | D28: 8(7) | E28: 12351.94 | G28: 37055.82 | H28: 926.3955 | J28: 6175.97 | K28: 43231.79 | L28: 12351.94 | N28: 50000 | O28: 1235.194 | P28: 10000 | R28: 173329.05 | T28: 20000 | U28: 0 | V28: 0 | W28: 16512.682 | X28: =W28+V28+U28+T28+S28 -> 36512.682 | Y28: 136816.37 | Z28: =R28-X28 -> 136816.37
B29: TOTAL | C29: 22 | E29: =SUM(E7:E28) -> 688310.58 | F29: =SUM(F7:F28) -> 284617.02 | G29: =SUM(G7:G28) -> 1904443 | H29: =SUM(H7:H28) -> 87733.267 | I29: =SUM(I7:I28) -> 401221.9 | J29: =SUM(J7:J28) -> 336130.85 | K29: =SUM(K7:K28) -> 1847376.4 | L29: =SUM(L7:L28) -> 648188.4 | ... Z29: =SUM(Z7:Z28) -> 6749311
B31: INTERNAL AUDIT
A32: 1 | B32: OSANAIYE DAVID AKINYEMI | C32: DIRECTOR INTERNAL AUDIT | D32: 17(9) | E32: 81740.02 | G32: =E32*300% -> 245220.06 | H32: =E32*7.5% -> 6130.5015 | I32: 80244.38 | J32: =E32*50% -> 40870.01 | K32: =E32*350% -> 286090.07 | L32: =E32*100% -> 81740.02 | N32: =100000 -> 100000 | O32: =E32*10% -> 8174.002 | P32: 20000 | R32: =SUM(E32:Q32) -> 950209.06 | S32: ='NOVEMBER 2023'!F195 -> 0 | T32: =100000 -> 100000 | U32: 0 | W32: 161106.81 | X32: =W32+V32+U32+T32+S32 -> 261106.81 | Y32: 689102.26 | Z32: =R32-X32 -> 689102.26
A33: 2 | B33: JAMILA ABDUL | C33: AUDITOR II | D33: 8(7) | E33: 12351.94 | G33: =E33*300% -> 37055.82 | H33: =E33*7.5% -> 926.3955 | J33: =E33*50% -> 6175.97 | K33: =E33*350% -> 43231.79 | L33: =E33*100% -> 12351.94 | N33: =50000 -> 50000 | O33: =E33*10% -> 1235.194 | P33: 10000 | R33: =(Q33+P33+O33+N33+M33+L33+K33+J33+I33+H33+G33+F33+E33) -> 173329.05 | T33: =20000 -> 20000 | V33: 0 | W33: 16512.682 | X33: =W33+V33+U33+T33+S33 -> 36512.682 | Y33: 136816.37 | Z33: =R33-X33 -> 136816.37
A34: 3 | B34: IJEOMA EWELUKWA | C34: AUDIT OFFICER | D34: 10(7) | E34: =17286.33 -> 17286.33 | F34: ='PROMOTIONS IN NOVEMBER'!AB7 -> 176135.08 | G34: =E34*300% -> 51858.99 | H34: =E34*7.5% -> 1296.4748 | J34: =E34*50% -> 8643.165 | K34: =E34*350% -> 60502.155 | L34: =E34*100% -> 17286.33 | N34: =50000+10000 -> 60000 | O34: =E34*10% -> 1728.633 | P34: 10000 | R34: =SUM(E34:Q34) -> 404737.16 | T34: =10000 -> 10000 | W34: ='PROMOTIONS IN NOVEMBER'!X7 -> 25571.73 | X34: =W34+V34+U34+T34+S34 -> 35571.73 | Y34: 177017.56 | Z34: =R34-X34 -> 369165.43
C35: 3 | E35: =SUM(E32:E34) -> 111378.29 | F35: =SUM(F32:F34) -> 176135.08 | G35: =SUM(G32:G34) -> 334134.87 | H35: =SUM(H32:H34) -> 8353.3718 | I35: =SUM(I32:I34) -> 80244.38 | J35: =SUM(J32:J34) -> 55689.145 | K35: =SUM(K32:K34) -> 389824.02 | L35: =SUM(L32:L34) -> 111378.29 | ... Z35: =SUM(Z32:Z34) -> 1195084.1
B37: LEG. SUPPORT SEVICES
A38: 1 | B38: PROF. EDOBA BRIGHT OMOREGBE | C38: AG. DLSS | D38: 17(9) | E38: 81740.02 | G38: =E38*300% -> 245220.06 | H38: =E38*7.5% -> 6130.5015 | I38: 80244.38 | J38: =E38*50% -> 40870.01 | K38: =E38*350% -> 286090.07 | L38: =E38*100% -> 81740.02 | M38: =200000 -> 200000 | O38: =E38*10% -> 8174.002 | P38: 20000 | R38: =SUM(E38:Q38) -> 1050209.1 | T38: =200000 -> 200000 | U38: =380000 -> 380000 | W38: 180306.81 | X38: =W38+V38+U38+T38+S38 -> 760306.81 | Y38: 289902.26 | Z38: =R38-X38 -> 289902.26
A39: 2 | B39: DR CLINTON JAJA | C39: SENIOR RESEARCH FELLOW | D39: 15(9) | E39: 33507.5 | F39: =527553.5 -> 527553.5 | G39: =E39*300% -> 100522.5 | H39: =E39*7.5% -> 2513.0625 | I39: 40122.19 | J39: =E39*50% -> 16753.75 | K39: =E39*350% -> 117276.25 | L39: =E39*100% -> 33507.5 | M39: =160000 -> 160000 | O39: =E39*10% -> 3350.75 | P39: 20000 | Q39: 0 | R39: =SUM(E39:Q39) -> 1055107 | T39: =50000*2 -> 100000 | U39: =385000*2 -> 770000 | W39: =79956.9391466667*2 -> 159913.88 | X39: =W39+V39+U39+T39+S39 -> 1029913.9 | Z39: =R39-X39 -> 25193.124
A40: 3 | B40: BETHEL UZOMA IHUGBA | C40: SNR RESEARCH FELLOW | D40: 15(9) | E40: 33507.5 | G40: =E40*300% -> 100522.5 | H40: =E40*7.5% -> 2513.0625 | I40: 40122.19 | J40: =E40*50% -> 16753.75 | K40: =E40*350% -> 117276.25 | L40: =E40*100% -> 33507.5 | M40: =160000 -> 160000 | O40: =E40*10% -> 3350.75 | P40: 20000 | R40: =SUM(E40:Q40) -> 527553.5 | T40: =80000+23000 -> 103000 | U40: =246905.96 -> 246905.96 | W40: 79956.939 | X40: =W40+V40+U40+T40+S40 -> 429862.9 | Y40: 97690.603 | Z40: =R40-X40 -> 97690.603
A41: 4 | B41: OGUCHE SAMUEL | C41: SNR RESEARCH FELLOW | D41: 15(9) | E41: 33507.5 | G41: =E41*300% -> 100522.5 | H41: =E41*7.5% -> 2513.0625 | I41: 40122.19 | J41: =E41*50% -> 16753.75 | K41: =E41*350% -> 117276.25 | L41: =E41*100% -> 33507.5 | M41: =160000 -> 160000 | O41: =E41*10% -> 3350.75 | P41: 20000 | R41: =SUM(E41:Q41) -> 527553.5 | T41: =30000 -> 30000 | U41: =176288.88 -> 176288.88 | W41: 79956.939 | X41: =W41+V41+U41+T41+S41 -> 286245.82 | Y41: 241307.68 | Z41: =R41-X41 -> 241307.68
A42: 5 | B42: IBRAHIM USMAN | C42: SNR RESEARCH FELLOW | D42: 15(8) | E42: 32263.2 | G42: =E42*300% -> 96789.6 | H42: =E42*7.5% -> 2419.74 | I42: =40122.19 -> 40122.19 | J42: =E42*50% -> 16131.6 | K42: =E42*350% -> 112921.2 | L42: =E42*100% -> 32263.2 | M42: =140000+20000 -> 160000 | O42: =E42*10% -> 3226.32 | P42: 20000 | Q42: 0 | R42: =SUM(E42:Q42) -> 516137.05 | V42: 806.58 | W42: =77764.98 -> 77764.98 | X42: =W42+V42+U42+T42+S42 -> 78571.56 | Y42: 437565.49 | Z42: =R42-X42 -> 437565.49
...

Sheet MEMO 1
A2: NATIONAL INSTITUTE FOR LEGISLATIVE AND DEMOCRATIC STUDIES
A3: INTERNAL MEMO
A4: FROM : DEPUTY DIRECTOR, FINANCE AND ACCOUNTS
A5: THRU: DIRECTOR, FINANCE AND ACCOUNTS
A6: TO: DG
A7: 29TH JANUARY , 2021
A9: SUBJECT: PAYROLL FOR THE MONTH OF JANUARY, 2021
A10: Find below the details of NILDS Staff Payroll for the month of January, 2021
A13: TO: | C13: DIRECTOR, GENERAL
A14: THRU: | C14: DIRECTOR, FINANCE AND ACCOUNT
A15: FROM: | C15: DEPUTY DIRECTOR, FINANCE AND ACCOUNTS
A16: DATE: | C16: 27TH NOVEMBER, 2023
A18: SUBJECT: PAYROLL FOR THE MONTH OF NOVEMBER, 2023
A19: Find below the details of NILDS Staff Payroll for the Month of November 2023: | G19: NGN | H19: NGN
A20: GROSS SALARY FOR NOVEMBER, 2023 | H20: ='NOVEMBER 2023'!R193 -> 52355467
A22: DEDUCTIONS
A23: COOP SOCIETY DEDUCTIONS ( CONTR.& SPEC. SAVINGS) | G23: ='NOVEMBER 2023'!T193 -> 4808500
A24: COOP LOAN RECOVERY | G24: ='NOVEMBER 2023'!U193 -> 7343362.4
A25: PAYE DEDUCTIONS | G25: ='NOVEMBER 2023'!W193 -> 6999867.5
A26: NHF DEDUCTIONS | G26: ='NOVEMBER 2023'!V193 -> 23299.424
A27: TOTAL DEDUCTIONS FOR NOVEMBER, 2023 | H27: =G23+G24+G25+G26 -> 19175029
A28: NET PAY AS PER NOVEMBER, 2023 PAYROLL | H28: =H20-H27 -> 33180438
A29: NET PAY AS PER OCTOBER, 2023 PAYROLL | H29: ='NOVEMBER 2023'!Y193 -> 33407268
A30: NET INCREASE/ (DECREASE) IN PAY FOR NOVEMBER, 2023 | H30: =H28-H29 -> -226829.77
A31: ANALYSED AS FOLLOWS:
A32: Effect of Cooperative adjustment for November, 2023 | H32: =-120416.63 -> -120416.63
A33: Net Effect of Reinstatement of Abdulsalam Mustapha & 1 Other including Arrears | H33: =-520927.28-663193.3-284617.02 -> -1468737.6
A34: Net Effect of Reinstatement of Dr. Shuaibu Danwanka & 1 Other | H34: =-598077.82-177017.56 -> -775095.38
A35: Effect of Removal Promotion Arrears of Abdulwahab Dahiru and 17 Others | H35: =2102520.88 -> 2102520.9
A36: Effect of Removal 1st 28 days to Saheed Ayinla Ajia and 4 others | H36: =1228966.65 -> 1228966.6
A37: Effect of Promotion of Abisola Ojogiwa & 2 others | H37: =-16425.11-192147.86 -> -208572.97
A38: Effect of Regularisation of Salary of John Gimah & 2 Others | H38: =-307745.54 -> -307745.54
A39: Net Effect of Lucky Agwom & 1 other as DG's Aides | H39: -224089.64
H40: =SUM(H32:H39) -> 226829.77
E42: OCTOBER, 2023 | G42: NOVEMBER, 2023
E43: No. of Staff | F43: N | G43: No. of Staff | H43: N
A44: 1 | B44: Director General's Office | E44: 33 | F44: ='NOVEMBER 2023'!Y29 -> 6099547.1 | G44: ='NOVEMBER 2023'!C29 -> 22 | H44: ='NOVEMBER 2023'!Z29 -> 6749311
A45: 2 | B45: Internal Audit | E45: 2 | F45: ='NOVEMBER 2023'!Y35 -> 1002936.2 | G45: ='NOVEMBER 2023'!C35 -> 3 | H45: ='NOVEMBER 2023'!Z35 -> 1195084.1
A46: 3 | B46: Legis. Support Services | E46: 11 | F46: ='NOVEMBER 2023'!Y50 -> 2790088.4 | G46: ='NOVEMBER 2023'!C50 -> 12 | H46: ='NOVEMBER 2023'!Z50 -> 2789135.8
A47: 4 | B47: Legal Services | E47: 2 | F47: ='NOVEMBER 2023'!Y55 -> 178732.07 | G47: ='NOVEMBER 2023'!C55 -> 2 | H47: ='NOVEMBER 2023'!Z55 -> 808634.33
...

Sheet PROMOTIONS IN NOVEMBER
A1: NATIONAL INSTITUTE FOR LEGISLATIVE AND DEMOCRATIC STUDIES | G1: ='[1]FEB 08'!F8/'[1]FEB 08'!Q8 -> 0.3
A2: STAFF PAYROLL FOR THE MONTH OF NOVEMBER 2023
E3: ='[1]FEB 08'!E11/'[1]FEB 08'!M11 -> #REF! | G3: ='[1]FEB 08'!F11/'[1]FEB 08'!Q11 -> #REF!
B4: STAFF NAME | C4: DESIGNATION | D4: CURRENT GRADE LEVEL | E4: BASIC SALARY | F4: RENT | G4: UTILITY | H4: DOMESTIC | I4: ENTERT. | J4: FURNIT. | K4: FUEL | L4: ALLOWANCE | M4: ALLOWANCE | N4: ALLCE | O4: ALLCE | P4: DUTY ALLCE | Q4: CURRENT GROSS SALARY | R4: NEW GRADE LEVEL | S4: NEW GROSS SALARY | T4: INCREMENT IN GROSS SALARY | U4: CURRENT NHF | V4: NEW NHF | W4: CURRENT PAYE | X4: NEW PAYE | Y4: INCREMENT IN PAYE | Z4: NET SALARY INCREMENT | AA4: NO OF MONTHS | AB4: ARREARS
E5: N | F5: N | G5: N | H5: N | I5: N | J5: N | K5: N | L5: N | M5: N | N5: N | O5: N | P5: N | Q5: N | S5: N | U5: N | W5: N
A6: S/N | B6: DG'S OFFICE
A7: 1 | B7: IJEOMA EWELUKWA | C7: STORES OFFICER | D7: 9(8) | E7: =15188.67 -> 15188.67 | G7: =E7*300% -> 45566.01 | H7: =E7*7.5% -> 1139.1502 | J7: =E7*50% -> 7594.335 | K7: =E7*350% -> 53160.345 | L7: =E7*100% -> 15188.67 | N7: =50000+10000 -> 60000 | O7: =E7*10% -> 1518.867 | P7: 10000 | Q7: =SUM(E7:Q7) -> 209356.05 | R7: 10(7) | S7: ='SALARY STRUCTURE'!H14+60000 -> 228601.58 | T7: =228601.58-209356.05 -> 19245.53 | W7: =22338.48 -> 22338.48 | X7: =25571.73 -> 25571.73 | Y7: =X7-W7 -> 3233.25 | Z7: =T7-Y7 -> 16012.28 | AA7: =11 -> 11 | AB7: =Z7*AA7 -> 176135.08
B8: TOTAL | E8: =SUM(E7:E7) -> 15188.67 | F8: =SUM(F7:F7) -> 0 | G8: =SUM(G7:G7) -> 45566.01 | H8: =SUM(H7:H7) -> 1139.1502 | I8: =SUM(I7:I7) -> 0 | J8: =SUM(J7:J7) -> 7594.335 | K8: =SUM(K7:K7) -> 53160.345 | L8: =SUM(L7:L7) -> 15188.67 | ... P8: =SUM(P7:P7) -> 10000 | Q8: =SUM(E8:Q8) -> 209356.05 | S8: =SUM(S7:S7) -> 228601.58 | T8: =SUM(T7:T7) -> 19245.53 | U8: =SUM(U7:U7) -> 0 | V8: =SUM(V7:V7) -> 0 | W8: =SUM(W7:W7) -> 22338.48 | X8: =SUM(X7:X7) -> 25571.73 | Y8: =SUM(Y7:Y7) -> 3233.25 | Z8: =SUM(Z7:Z7) -> 16012.28 | AB8: =SUM(AB7:AB7) -> 176135.08
B10: LEG. SUPPORT SEVICES
A11: 2 | B11: BETHEL UZOMA IHUGBA | C11: SNR RESEARCH FELLOW | D11: 15(9) | E11: 33507.5 | G11: =E11*300% -> 100522.5 | H11: =E11*7.5% -> 2513.0625 | I11: 40122.19 | J11: =E11*50% -> 16753.75 | K11: =E11*350% -> 117276.25 | L11: =E11*100% -> 33507.5 | M11: =160000 -> 160000 | O11: =E11*10% -> 3350.75 | P11: 20000 | Q11: =SUM(E11:Q11) -> 527553.5 | R11: 16(7) | S11: ='SALARY STRUCTURE'!H19+180000 -> 604023.33 | T11: =604023.33-527553.5 -> 76469.83 | U11: =837.69 -> 837.69 | V11: =1028.94 -> 1028.94 | W11: =79956.94 -> 79956.94 | X11: =94639.15 -> 94639.15 | Y11: =X11-W11 -> 14682.21 | Z11: =T11-Y11 -> 61787.62 | AA11: 8 | AB11: =Z11*AA11 -> 494300.96
A12: 3 | B12: DR MOHAMMED O. AMALI | C12: RESEARCH FELLOW I | D12: 14(10) | E12: 27611.23 | G12: =E12*300% -> 82833.69 | H12: =E12*7.5% -> 2070.8422 | J12: =E12*50% -> 13805.615 | K12: =E12*350% -> 96639.305 | L12: =E12*100% -> 27611.23 | M12: =140000 -> 140000 | O12: =E12*10% -> 2761.123 | P12: 20000 | Q12: =SUM(E12:Q12) -> 413333.04 | R12: 15(7) | S12: ='SALARY STRUCTURE'!H18+160000 -> 504720.17 | T12: =504720.05-413333.04 -> 91387.01 | U12: 0 | W12: 57889.865 | X12: =75436.17 -> 75436.17 | Y12: =X12-W12 -> 17546.305 | Z12: =T12-Y12 -> 73840.705 | AA12: =4/30 -> 0.13333333 | AB12: =Z12*AA12 -> 9845.4273
B13: TOTAL | E13: =SUM(E11:E12) -> 61118.73 | F13: =SUM(F11:F12) -> 0 | G13: =SUM(G11:G12) -> 183356.19 | H13: =SUM(H11:H12) -> 4583.9047 | I13: =SUM(I11:I12) -> 40122.19 | J13: =SUM(J11:J12) -> 30559.365 | K13: =SUM(K11:K12) -> 213915.55 | L13: =SUM(L11:L12) -> 61118.73 | ... AB13: =SUM(AB11:AB12) -> 504146.39
T14: =S14-Q14 -> 0
Y15: =X15-W15 -> 0 | Z15: =T15-Y15 -> 0 | AB15: =Z15*AA15 -> 0
B16: FINANCE & ACCOUNTS | Y16: =X16-W16 -> 0 | Z16: =T16-Y16 -> 0 | AB16: =Z16*AA16 -> 0
A17: 3 | B17: RAHILA NURUDEEN HABU | C17: ASST. DIRECTOR, ACCOUNTS | D17: 15(9) | E17: 33507.5 | G17: =E17*300% -> 100522.5 | H17: =E17*7.5% -> 2513.0625 | I17: 40122.19 | J17: =E17*50% -> 16753.75 | K17: =E17*350% -> 117276.25 | L17: =E17*100% -> 33507.5 | M17: =80000 -> 80000 | N17: =E17*10% -> 3350.75 | O17: 20000 | P17: 100000 | Q17: =SUM(E17:P17) -> 547553.5 | R17: 16(7) | S17: ='SALARY STRUCTURE'!H19+190000 -> 614023.33 | T17: =S17-Q17 -> 66469.831 | U17: =837.69 -> 837.69 | V17: =1028.94 -> 1028.94 | W17: =83626.1 -> 83626.1 | X17: =96398.31 -> 96398.31 | Y17: =X17-W17 -> 12772.21 | Z17: =T17-Y17 -> 53697.621 | AA17: 10 | AB17: =Z17*AA17 -> 536976.21
B18: OJOGIWA ABISOLA GANIAT | C18: ASST. CHIEF BUDGET OFFICER | D18: 13(10) | E18: 25523.45 | G18: =E18*300% -> 76570.35 | H18: =E18*7.5% -> 1914.2587 | J18: =E18*50% -> 12761.725 | K18: =E18*350% -> 89332.075 | L18: =E18*100% -> 25523.45 | N18: =70000 -> 70000 | O18: =E18*10% -> 2552.345 | P18: 15000 | Q18: =SUM(E18:Q18) -> 319177.65 | R18: 14 (7) | S18: ='NOVEMBER 2023'!R126 -> 327211.37 | T18: =327211.37-319177.65 -> 8033.72 | U18: 638.09 | V18: 690.28 | W18: 40684.6 | X18: 42034.24 | Y18: =X18-W18 -> 1349.64 | Z18: =T18-Y18 -> 6684.08 | AA18: 0 | AB18: =Z18*AA18 -> 0
B19: TOTAL | E19: =SUM(E17:E17) -> 33507.5 | F19: =SUM(F17:F17) -> 0 | G19: =SUM(G17:G17) -> 100522.5 | H19: =SUM(H17:H17) -> 2513.0625 | I19: =SUM(I17:I17) -> 40122.19 | J19: =SUM(J17:J17) -> 16753.75 | K19: =SUM(K17:K17) -> 117276.25 | L19: =SUM(L17:L17) -> 33507.5 | M19: =SUM(#REF!) -> #REF! | N19: =SUM(M17:M17) -> 80000 | O19: =SUM(N17:N17) -> 3350.75 | P19: =SUM(O17:O17) -> 20000 | Q19: =SUM(P17:P17) -> 100000 | S19: =SUM(S17:S17) -> 614023.33 | T19: =SUM(T17:T17) -> 66469.831 | U19: =SUM(U17:U17) -> 837.69 | V19: =SUM(V17:V17) -> 1028.94 | W19: =SUM(W17:W17) -> 83626.1 | X19: =SUM(X17:X17) -> 96398.31 | Y19: =SUM(Y17:Y17) -> 12772.21 | Z19: =SUM(Z17:Z17) -> 53697.621 | AB19: =SUM(AB17:AB17) -> 536976.21
B21: FINANCE & ACCOUNTS
A22: 15 | B22: YUNUSA ABDULMUMINI ELEOJO | C22: SENIOR DRIVER | D22: 5(11) | E22: 5428.12 | F22: =E22*300% -> 16284.36 | G22: =E22*7.5% -> 407.109 | I22: =E22*50% -> 2714.06 | J22: =E22*350% -> 18998.42 | K22: =E22*100% -> 5428.12 | M22: =20000 -> 20000 | N22: =E22*10% -> 542.812 | O22: 5000 | P22: =7000 -> 7000 | Q22: =SUM(E22:P22) -> 81803.001 | R22: 7(3) | S22: ='SALARY STRUCTURE'!#REF!+30000 -> #REF! | T22: =S22-Q22 -> #REF! | W22: 4365.3308 | X22: ='[7]October 2023'!$Z$164 -> 8312.59 | Y22: =X22-W22 -> 3947.2592 | Z22: =T22-Y22 -> #REF! | AA22: =(10/31)+2 -> 2.3225806 | AB22: =Z22*AA22 -> #REF!
A23: 16 | B23: JOHN GIMAH | C23: SENIOR DRIVER | D23: 5(11) | E23: 5428.12 | F23: =E23*300% -> 16284.36 | G23: =E23*7.5% -> 407.109 | I23: =E23*50% -> 2714.06 | J23: =E23*350% -> 18998.42 | K23: =E23*100% -> 5428.12 | M23: =20000 -> 20000 | N23: =E23*10% -> 542.812 | O23: 5000 | P23: =7000 -> 7000 | Q23: =SUM(E23:P23) -> 81803.001 | R23: 7(3) | S23: ='SALARY STRUCTURE'!#REF!+30000 -> #REF! | T23: =S23-Q23 -> #REF! | W23: =4365.33075466667 -> 4365.3308 | X23: ='[7]October 2023'!$Z$164 -> 8312.59 | Y23: =X23-W23 -> 3947.2592 | Z23: =T23-Y23 -> #REF! | AA23: =(17/31)+1 -> 1.5483871 | AB23: =Z23*AA23 -> #REF!
A24: 17 | B24: ABUBAKAR MUSA DANLAMI | C24: SENIOR DRIVER | D24: 5(12) | E24: =5598.92 -> 5598.92 | F24: =E24*300% -> 16796.76 | G24: =E24*7.5% -> 419.919 | I24: =E24*50% -> 2799.46 | J24: =E24*350% -> 19596.22 | K24: =E24*100% -> 5598.92 | M24: =20000 -> 20000 | N24: =E24*10% -> 559.892 | O24: 5000 | P24: =7000 -> 7000 | Q24: =SUM(E24:P24) -> 83370.091 | R24: 7(3) | S24: 115104.92 | T24: =S24-Q24 -> 31734.826 | W24: 4504.4109 | X24: ='[7]October 2023'!$Z$164 -> 8312.59 | Y24: =X24-W24 -> 3808.1791 | Z24: =T24-Y24 -> 27926.647 | AA24: 8 | AB24: =Z24*AA24 -> 223413.17
L25: =226713.38+70000 -> 296713.38
B27: GRAND TOTAL | E27: =E19+E13+E8 -> 109814.9 | F27: =F19+F13+F8 -> 0 | G27: =G19+G13+G8 -> 329444.7 | H27: =H19+H13+H8 -> 8236.1175 | I27: =I19+I13+I8 -> 80244.38 | J27: =J19+J13+J8 -> 54907.45 | K27: =K19+K13+K8 -> 384352.15 | L27: =L19+L13+L8 -> 109814.9 | ... AB27: =AB19+AB13+AB8 -> 1217257.7

Sheet NEW ENROLMENT IN NOVEMBER (2)
A1: NATIONAL INSTITUTE FOR LEGISLATIVE AND DEMOCRATIC STUDIES | G1: ='[1]FEB 08'!F8/'[1]FEB 08'!Q8 -> 0.3
A2: STAFF PAYROLL FOR THE MONTH OF NOVEMBER 2023
E3: ='[1]FEB 08'!E11/'[1]FEB 08'!M11 -> #REF! | G3: ='[1]FEB 08'!F11/'[1]FEB 08'!Q11 -> #REF!
B4: STAFF NAME | C4: DESIGNATION | D4: GRADE LEVEL | E4: BASIC SALARY | F4: ALLCE/ AREARS | G4: RENT | H4: UTILITY | I4: DOMESTIC | J4: ENTERT. | K4: FURNIT. | L4: FUEL | M4: ALLOWANCE | N4: ALLOWANCE | O4: ALLCE | P4: ALLCE | Q4: DUTY ALLCE | R4: GROSS SALARY | S4: PAYE | T4: TOTAL DEDUCTION | U4: OCTOBER, 2023 | V4: NOVEMBER, 2023 | W4: NO OF MONTHS | X4: ARREARS
E5: N | F5: N | G5: N | H5: N | I5: N | J5: N | K5: N | L5: N | M5: N | N5: N | O5: N | P5: N | Q5: N | S5: N
A6: S/N | B6: DG'S OFFICE
A7: 3 | B7: ABDULSALAM S. MUSTAPHA | C7: ASST. MANAGER ICT | D7: 13(11) | E7: 26339.3 | G7: =E7*300% -> 79017.9 | H7: =E7*7.5% -> 1975.4475 | I7: 0 | J7: =E7*50% -> 13169.65 | K7: =E7*350% -> 92187.55 | L7: =E7*100% -> 26339.3 | M7: 70000 | O7: =E7*10% -> 2633.93 | P7: 15000 | R7: =SUM(E7:Q7) -> 326663.08 | S7: =42046.06 -> 42046.06 | T7: =42046.06 -> 42046.06 | V7: =R7-T7 -> 284617.02 | W7: 1 | X7: =V7*W7 -> 284617.02
B8: TOTAL | E8: =SUM(E7:E7) -> 26339.3 | F8: =SUM(F7:F7) -> 0 | G8: =SUM(G7:G7) -> 79017.9 | H8: =SUM(H7:H7) -> 1975.4475 | I8: =SUM(I7:I7) -> 0 | J8: =SUM(J7:J7) -> 13169.65 | K8: =SUM(K7:K7) -> 92187.55 | L8: =SUM(L7:L7) -> 26339.3 | ... P8: =SUM(P7:P7) -> 15000 | R8: =SUM(R7) -> 326663.08 | S8: =SUM(S7:S7) -> 42046.06 | T8: =SUM(T7:T7) -> 42046.06 | U8: =SUM(U7:U7) -> 0 | V8: =SUM(V7:V7) -> 284617.02 | X8: =SUM(X7:X7) -> 284617.02
B10: DEM. & GOVERNANCE
A11: 10 | B11: KOLAPO Q. ABAYOMI | C11: RESEARCH OFFICER | D11: 10(7) | E11: 17286.33 | G11: =E11*300% -> 51858.99 | H11: =E11*7.5% -> 1296.4748 | J11: =E11*50% -> 8643.165 | K11: =E11*350% -> 60502.155 | L11: =E11*100% -> 17286.33 | M11: 100000 | O11: =E11*10% -> 1728.633 | P11: 10000 | R11: =SUM(E11:Q11) -> 268602.08 | S11: =32291.82 -> 32291.82 | T11: =32291.82 -> 32291.82 | V11: =R11-T11 -> 236310.26 | W11: =(25/31)+2 -> 2.8064516 | X11: =V11*W11 -> 663193.3
B12: TOTAL | E12: =SUM(E11:E11) -> 17286.33 | F12: =SUM(F11:F11) -> 0 | G12: =SUM(G11:G11) -> 51858.99 | H12: =SUM(H11:H11) -> 1296.4748 | I12: =SUM(I11:I11) -> 0 | J12: =SUM(J11:J11) -> 8643.165 | K12: =SUM(K11:K11) -> 60502.155 | L12: =SUM(L11:L11) -> 17286.33 | ... X12: =SUM(X11:X11) -> 663193.3
B14: GRAND TOTAL | E14: =E8+E12 -> 43625.63 | F14: =F8+F12 -> 0 | G14: =G8+G12 -> 130876.89 | H14: =H8+H12 -> 3271.9222 | I14: =I8+I12 -> 0 | J14: =J8+J12 -> 21812.815 | K14: =K8+K12 -> 152689.71 | L14: =L8+L12 -> 43625.63 | ... V14: =V8+V12 -> 520927.28 | X14: =X8+X12 -> 947810.32

Sheet Regularisation IN NOVEMBER (3)
A1: NATIONAL INSTITUTE FOR LEGISLATIVE AND DEMOCRATIC STUDIES | G1: ='[1]FEB 08'!F8/'[1]FEB 08'!Q8 -> 0.3
A2: STAFF PAYROLL FOR THE MONTH OF NOVEMBER 2023
E3: ='[1]FEB 08'!E11/'[1]FEB 08'!M11 -> #REF! | G3: ='[1]FEB 08'!F11/'[1]FEB 08'!Q11 -> #REF!
B4: STAFF NAME | C4: DESIGNATION | D4: GRADE LEVEL | E4: BASIC SALARY | F4: ALLCE/ AREARS | G4: RENT | H4: UTILITY | I4: DOMESTIC | J4: ENTERT. | K4: FURNIT. | L4: FUEL | M4: ALLOWANCE | N4: ALLOWANCE | O4: ALLCE | P4: ALLCE | Q4: DUTY ALLCE | R4: GROSS SALARY | S4: NEW GRADE LEVEL | T4: NEW GROSS SALARY | U4: INCREMENT IN GROSS SALARY | V4: CURRENT NHF | W4: NEW NHF | X4: CURRENT PAYE | Y4: NEW PAYE | Z4: INCREMENT IN PAYE | AA4: NET SALARY INCREMENT | AB4: NO OF MONTHS | AC4: ARREARS | AD4: ARREARS PAID IN OCTOBER | AE4: SHORTFALL IN ARREARS
E5: N | F5: N | G5: N | H5: N | I5: N | J5: N | K5: N | L5: N | M5: N | N5: N | O5: N | P5: N | Q5: N | S5: N
A6: S/N | B6: ADMIN & HR
A8: 40 | B8: YUNUSA ABDULMUMINI ELEOJO | C8: CHIEF MOTOR DRIVER MECH. | D8: 7(3) | E8: 5428.12 | G8: =E8*300% -> 16284.36 | H8: =E8*7.5% -> 407.109 | J8: =E8*50% -> 2714.06 | K8: =E8*350% -> 18998.42 | L8: =E8*100% -> 5428.12 | N8: =20000 -> 20000 | O8: =E8*10% -> 542.812 | P8: 5000 | Q8: =7000 -> 7000 | R8: =SUM(E8:Q8) -> 81803.001 | S8: 7(3) | T8: =122105 -> 122105 | U8: =T8-R8 -> 40301.999 | X8: 4365.3308 | Y8: =9152.6 -> 9152.6 | Z8: =Y8-X8 -> 4787.2692 | AA8: =U8-Z8 -> 35514.73 | AB8: =(11/31)+3 -> 3.3548387 | AC8: =AA8*AB8 -> 119146.19 | AD8: =66227.57 -> 66227.57 | AE8: =AC8-AD8 -> 52918.62
A9: 41 | B9: JOHN GIMAH | C9: CHIEF MOTOR DRIVER MECH. | D9: 7(3) | E9: 5428.12 | G9: =E9*300% -> 16284.36 | H9: =E9*7.5% -> 407.109 | J9: =E9*50% -> 2714.06 | K9: =E9*350% -> 18998.42 | L9: =E9*100% -> 5428.12 | N9: =20000 -> 20000 | O9: =E9*10% -> 542.812 | P9: 5000 | Q9: =7000 -> 7000 | R9: =SUM(E9:Q9) -> 81803.001 | S9: 7(3) | T9: =122105 -> 122105 | U9: =T9-R9 -> 40301.999 | X9: =4365.33075466667 -> 4365.3308 | Y9: =9152.6 -> 9152.6 | Z9: =Y9-X9 -> 4787.2692 | AA9: =U9-Z9 -> 35514.73 | AB9: =(17/31)+2 -> 2.5483871 | AC9: =AA9*AB9 -> 90505.279 | AD9: 44151.71 | AE9: =AC9-AD9 -> 46353.569
A10: 42 | B10: ABUBAKAR MUSA DANLAMI | C10: CHIEF MOTOR DRIVER MECH. | D10: 7(3) | E10: 5598.92 | G10: =E10*300% -> 16796.76 | H10: =E10*7.5% -> 419.919 | J10: =E10*50% -> 2799.46 | K10: =E10*350% -> 19596.22 | L10: =E10*100% -> 5598.92 | N10: =20000 -> 20000 | O10: =E10*10% -> 559.892 | P10: 5000 | Q10: =7000 -> 7000 | R10: =SUM(E10:Q10) -> 83370.091 | S10: 7(3) | T10: =122105 -> 122105 | U10: =T10-R10 -> 38734.909 | X10: 4504.4109 | Y10: =9152.6 -> 9152.6 | Z10: =Y10-X10 -> 4648.1891 | AA10: =U10-Z10 -> 34086.72 | AB10: 9 | AC10: =AA10*AB10 -> 306780.48 | AD10: 216693.09 | AE10: =AC10-AD10 -> 90087.389
AE11: =SUM(AE8:AE10) -> 189359.58
A13: 40 | B13: YUNUSA ABDULMUMINI ELEOJO | C13: CHIEF MOTOR DRIVER MECH. | D13: 7(3) | E13: =8730.79 -> 8730.79 | G13: =E13*300% -> 26192.37 | H13: =E13*7.5% -> 654.80925 | J13: =E13*50% -> 4365.395 | K13: =E13*350% -> 30557.765 | L13: =E13*100% -> 8730.79 | N13: 30000 | O13: =E13*10% -> 873.079 | P13: 5000 | Q13: =7000 -> 7000 | R13: =SUM(E13:Q13) -> 122105 | T13: =10000+5000+5000 -> 20000 | U13: =15625 -> 15625 | W13: =[3]PROMOTIONS!$X$42 -> 8312.59 | X13: =W13+V13+U13+T13+S13 -> 43937.59 | Y13: 106043.97 | Z13: =R13-X13 -> 78167.408
A14: 41 | B14: JOHN GIMAH | C14: CHIEF MOTOR DRIVER MECH. | D14: 7(3) | E14: =8730.79 -> 8730.79 | G14: =E14*300% -> 26192.37 | H14: =E14*7.5% -> 654.80925 | J14: =E14*50% -> 4365.395 | K14: =E14*350% -> 30557.765 | L14: =E14*100% -> 8730.79 | N14: 30000 | O14: =E14*10% -> 873.079 | P14: 5000 | Q14: =7000 -> 7000 | R14: =SUM(E14:Q14) -> 122105 | T14: 20000 | U14: 18333.33 | W14: =[3]PROMOTIONS!$X$42 -> 8312.59 | X14: =W14+V14+U14+T14+S14 -> 46645.92 | Y14: 80609.452 | Z14: =R14-X14 -> 75459.078
A15: 42 | B15: ABUBAKAR MUSA DANLAMI | C15: CHIEF MOTOR DRIVER MECH. | D15: 7(3) | E15: =8730.79 -> 8730.79 | G15: =E15*300% -> 26192.37 | H15: =E15*7.5% -> 654.80925 | J15: =E15*50% -> 4365.395 | K15: =E15*350% -> 30557.765 | L15: =E15*100% -> 8730.79 | N15: 30000 | O15: =E15*10% -> 873.079 | P15: 5000 | Q15: =7000 -> 7000 | R15: =SUM(E15:Q15) -> 122105 | T15: =3000+5000+5000 -> 13000 | U15: =44000 -> 44000 | W15: =[3]PROMOTIONS!$X$42 -> 8312.59 | X15: =W15+V15+U15+T15+S15 -> 65312.59 | Y15: 239903.58 | Z15: =R15-X15 -> 56792.408
B16: GRAND TOTAL | E16: =E8+E14 -> 14158.91 | F16: =F8+F14 -> 0 | G16: =G8+G14 -> 42476.73 | H16: =H8+H14 -> 1061.9182 | I16: =I8+I14 -> 0 | J16: =J8+J14 -> 7079.455 | K16: =K8+K14 -> 49556.185 | L16: =L8+L14 -> 14158.91 | ... V16: =V8+V14 -> 0 | X16: =X8+X14 -> 51011.251

Sheet Sheet2

Sheet PROMOTIONS
A1: NATIONAL INSTITUTE FOR LEGISLATIVE AND DEMOCRATIC STUDIES | G1: ='[1]FEB 08'!F8/'[1]FEB 08'!Q8 -> 0.3
A2: STAFF PAYROLL FOR THE MONTH OF OCTOBER 2023
E3: ='[1]FEB 08'!E11/'[1]FEB 08'!M11 -> #REF! | G3: ='[1]FEB 08'!F11/'[1]FEB 08'!Q11 -> #REF!
B4: STAFF NAME | C4: DESIGNATION | D4: CURRENT GRADE LEVEL | E4: BASIC SALARY | F4: RENT | G4: UTILITY | H4: DOMESTIC | I4: ENTERT. | J4: FURNIT. | K4: FUEL | L4: ALLOWANCE | M4: ALLOWANCE | N4: ALLCE | O4: ALLCE | P4: DUTY ALLCE | Q4: CURRENT GROSS SALARY | R4: NEW GRADE LEVEL | S4: NEW GROSS SALARY | T4: INCREMENT IN GROSS SALARY | U4: CURRENT NHF | V4: NEW NHF | W4: CURRENT PAYE | X4: NEW PAYE | Y4: INCREMENT IN PAYE | Z4: NET SALARY INCREMENT | AA4: NO OF MONTHS | AB4: ARREARS
E5: N | F5: N | G5: N | H5: N | I5: N | J5: N | K5: N | L5: N | M5: N | N5: N | O5: N | P5: N | Q5: N | S5: N | U5: N | W5: N
A6: S/N | B6: DG'S OFFICE
A7: 1 | B7: ABDULRAHMAN A SULAIMAN | C7: ASSISTANT STORES OFFICER | D7: 8(10) | E7: 13492.21 | F7: =E7*300% -> 40476.63 | G7: =E7*7.5% -> 1011.9157 | I7: =E7*50% -> 6746.105 | J7: =E7*350% -> 47222.735 | K7: =E7*100% -> 13492.21 | M7: =50000 -> 50000 | N7: =E7*10% -> 1349.221 | O7: 10000 | Q7: =SUM(E7:P7) -> 183791.03 | R7: 9(7) | S7: ='SALARY STRUCTURE'!H13+60000 -> 205203.67 | T7: =S7-Q7 -> 21412.64 | W7: 18102.903 | X7: ='[7]October 2023'!$Z$29 -> #REF! | Y7: =X7-W7 -> #REF! | Z7: =T7-Y7 -> #REF! | AA7: =(19/31)+4 -> 4.6129032 | AB7: =Z7*AA7 -> #REF!
B8: TOTAL | C8: 1 | E8: =SUM(E7:E7) -> 13492.21 | F8: =SUM(F7:F7) -> 40476.63 | G8: =SUM(G7:G7) -> 1011.9157 | H8: =SUM(H7:H7) -> 0 | I8: =SUM(I7:I7) -> 6746.105 | J8: =SUM(J7:J7) -> 47222.735 | K8: =SUM(K7:K7) -> 13492.21 | L8: =SUM(L7:L7) -> 0 | ... Q8: =SUM(Q7:Q7) -> 183791.03 | S8: =SUM(S7:S7) -> 205203.67 | T8: =SUM(T7:T7) -> 21412.64 | U8: =SUM(U7:U7) -> 0 | V8: =SUM(V7:V7) -> 0 | W8: =SUM(W7:W7) -> 18102.903 | X8: =SUM(X7:X7) -> #REF! | Y8: =SUM(Y7:Y7) -> #REF! | Z8: =SUM(Z7:Z7) -> #REF! | AB8: =SUM(AB7:AB7) -> #REF!
B10: LEG. SUPPORT SEVICES
A11: 2 | B11: DORIS DAKDA AARON | C11: RESEARCH FELLOW II | D11: 13(10) | E11: 25523.45 | F11: =E11*300% -> 76570.35 | G11: =E11*7.5% -> 1914.2587 | I11: =E11*50% -> 12761.725 | J11: =E11*350% -> 89332.075 | K11: =E11*100% -> 25523.45 | L11: =120000 -> 120000 | N11: =E11*10% -> 2552.345 | O11: 15000 | Q11: =SUM(E11:P11) -> 369177.65 | R11: 14(8) | S11: ='SALARY STRUCTURE'!I17+140000 -> 397211.25 | T11: =S11-Q11 -> 28033.596 | U11: 638.08625 | V11: =690.28 -> 690.28 | W11: 49548.776 | X11: ='[7]October 2023'!$Z$50 -> #REF! | Y11: =X11-W11 -> #REF! | Z11: =T11-Y11 -> #REF! | AA11: =(18/31)+1 -> 1.5806452 | AB11: =Z11*AA11 -> #REF!
B12: TOTAL | C12: 1 | E12: =SUM(E11:E11) -> 25523.45 | F12: =SUM(F11:F11) -> 76570.35 | G12: =SUM(G11:G11) -> 1914.2587 | H12: =SUM(H11:H11) -> 0 | I12: =SUM(I11:I11) -> 12761.725 | J12: =SUM(J11:J11) -> 89332.075 | K12: =SUM(K11:K11) -> 25523.45 | L12: =SUM(L11:L11) -> 120000 | ... Q12: =SUM(Q11:Q11) -> 369177.65 | S12: =SUM(S11:S11) -> 397211.25 | T12: =SUM(T11:T11) -> 28033.596 | U12: =SUM(U11:U11) -> 638.08625 | V12: =SUM(V11:V11) -> 690.28 | W12: =SUM(W11:W11) -> 49548.776 | X12: =SUM(X11:X11) -> #REF! | Y12: =SUM(Y11:Y11) -> #REF! | Z12: =SUM(Z11:Z11) -> #REF! | AB12: =SUM(AB11:AB11) -> #REF!
T13: =S13-Q13 -> 0
B14: DEMOCRACY & GOVERNANCE | T14: =S14-Q14 -> 0
A15: 3 | B15: NGARA CHRISTOPHER OCHANJA | C15: RESEARCH FELLOW 1 | D15: 14(11) | E15: =28489.81 -> 28489.81 | F15: =E15*300% -> 85469.43 | G15: =E15*7.5% -> 2136.7357 | I15: =E15*50% -> 14244.905 | J15: =E15*350% -> 99714.335 | K15: =E15*100% -> 28489.81 | L15: 140000 | N15: =E15*10% -> 2848.981 | O15: 20000 | P15: 0 | Q15: =SUM(E15:P15) -> 421394.01 | R15: 15(7) | S15: ='SALARY STRUCTURE'!H18+160000 -> 504720.17 | T15: =S15-Q15 -> 83326.16 | U15: 712.24525 | V15: =837.69 -> 837.69 | W15: 59441.782 | X15: ='[7]October 2023'!$Z$85 -> 75440.405 | Y15: =X15-W15 -> 15998.623 | Z15: =T15-Y15 -> 67327.537 | AA15: =9 -> 9 | AB15: =Z15*AA15 -> 605947.83
A16: 4 | B16: EJALONIBU GANIYU LAYI | C16: RESEARCH FELLOW 11 | D16: 13(10) | E16: 25523.45 | F16: =E16*300% -> 76570.35 | G16: =E16*7.5% -> 1914.2587 | I16: =E16*50% -> 12761.725 | J16: =E16*350% -> 89332.075 | K16: =E16*100% -> 25523.45 | L16: =120000 -> 120000 | N16: =E16*10% -> 2552.345 | O16: 15000 | Q16: =SUM(E16:P16) -> 369177.65 | R16: 14(8) | S16: ='SALARY STRUCTURE'!I17+140000 -> 397211.25 | T16: =S16-Q16 -> 28033.596 | W16: 49548.776 | X16: ='[7]October 2023'!$Z$62 -> #REF! | Y16: =X16-W16 -> #REF! | Z16: =T16-Y16 -> #REF! | AA16: =(7/31)+2 -> 2.2258065 | AB16: =Z16*AA16 -> #REF!
B17: TOTAL | C17: 2 | E17: =SUM(E15:E16) -> 54013.26 | F17: =SUM(F15:F16) -> 162039.78 | G17: =SUM(G15:G16) -> 4050.9945 | H17: =SUM(H15:H16) -> 0 | I17: =SUM(I15:I16) -> 27006.63 | J17: =SUM(J15:J16) -> 189046.41 | K17: =SUM(K15:K16) -> 54013.26 | L17: =SUM(L15:L16) -> 260000 | ... Q17: =SUM(Q15:Q16) -> 790571.66 | S17: =SUM(S15:S16) -> 901931.42 | T17: =SUM(T15:T16) -> 111359.76 | U17: =SUM(U15:U16) -> 712.24525 | V17: =SUM(V15:V16) -> 837.69 | W17: =SUM(W15:W16) -> 108990.56 | X17: =SUM(X15:X16) -> #REF! | Y17: =SUM(Y15:Y16) -> #REF! | Z17: =SUM(Z15:Z16) -> #REF! | AB17: =SUM(AB15:AB16) -> #REF!
Y18: =X18-W18 -> 0 | Z18: =T18-Y18 -> 0 | AB18: =Z18*AA18 -> 0
B19: DEPARTMENT OF STUDIES | Y19: =X19-W19 -> 0 | Z19: =T19-Y19 -> 0 | AB19: =Z19*AA19 -> 0
A20: 5 | B20: ANTHONY EDET | C20: ASST. MGR M&E | D20: 13(10) | E20: 25523.45 | F20: =E20*300% -> 76570.35 | G20: =E20*7.5% -> 1914.2587 | H20: 0 | I20: =E20*50% -> 12761.725 | J20: =E20*350% -> 89332.075 | K20: =E20*100% -> 25523.45 | L20: =120000 -> 120000 | N20: =E20*10% -> 2552.345 | O20: 15000 | P20: 0 | Q20: =SUM(E20:P20) -> 369177.65 | R20: 14(8) | S20: ='SALARY STRUCTURE'!I17+140000 -> 397211.25 | T20: =S20-Q20 -> 28033.596 | U20: 638.08625 | W20: 49548.776 | X20: ='[7]October 2023'!$Z$78 -> #REF! | Y20: =X20-W20 -> #REF! | Z20: =T20-Y20 -> #REF! | AA20: =9 -> 9 | AB20: =Z20*AA20 -> #REF!
B21: TOTAL | C21: 1 | E21: =SUM(E20:E20) -> 25523.45 | F21: =SUM(F20:F20) -> 76570.35 | G21: =SUM(G20:G20) -> 1914.2587 | H21: =SUM(H20:H20) -> 0 | I21: =SUM(I20:I20) -> 12761.725 | J21: =SUM(J20:J20) -> 89332.075 | K21: =SUM(K20:K20) -> 25523.45 | L21: =SUM(L20:L20) -> 120000 | ... Q21: =SUM(Q20:Q20) -> 369177.65 | S21: =SUM(S20:S20) -> 397211.25 | U21: =SUM(U20:U20) -> 638.08625 | W21: =SUM(W20:W20) -> 49548.776 | X21: =SUM(X20:X20) -> #REF! | Y21: =SUM(Y20:Y20) -> #REF! | Z21: =SUM(Z20:Z20) -> #REF! | AB21: =SUM(AB20:AB20) -> #REF!
Y22: =X22-W22 -> 0 | Z22: =T22-Y22 -> 0 | AB22: =Z22*AA22 -> 0
B23: ECON. DEV. & SOC. RESEARCH | Y23: =X23-W23 -> 0 | Z23: =T23-Y23 -> 0 | AB23: =Z23*AA23 -> 0
A24: 6 | B24: OMOJU OLUWASOLA EMMANUEL | C24: RESEARCH FELLOW I | D24: 14(10) | E24: 27611.23 | F24: =E24*300% -> 82833.69 | G24: =E24*7.5% -> 2070.8422 | I24: =E24*50% -> 13805.615 | J24: =E24*350% -> 96639.305 | K24: =E24*100% -> 27611.23 | L24: 140000 | N24: =E24*10% -> 2761.123 | O24: 20000 | Q24: =SUM(E24:P24) -> 413333.04 | R24: 15(7) | S24: ='SALARY STRUCTURE'!H18+160000 -> 504720.17 | T24: =S24-Q24 -> 91387.131 | W24: 58026.609 | X24: ='[7]October 2023'!$Z$86 -> #REF! | Y24: =X24-W24 -> #REF! | Z24: =T24-Y24 -> #REF! | AA24: 1 | AB24: =Z24*AA24 -> #REF!
A25: 7 | B25: OKUNGBOWA OSARETIN GODSPOWER | C25: RESEARCH FELLOW 11 | D25: 13(9) | E25: 24741.26 | F25: =E25*300% -> 74223.78 | G25: =E25*7.5% -> 1855.5945 | H25: 0 | I25: =E25*50% -> 12370.63 | J25: =E25*350% -> 86594.41 | K25: =E25*100% -> 24741.26 | L25: =120000 -> 120000 | N25: =E25*10% -> 2474.126 | O25: 15000 | P25: 0 | Q25: =SUM(E25:P25) -> 362001.06 | R25: 14(7) | S25: ='SALARY STRUCTURE'!H17+140000 -> 389153.42 | T25: =S25-Q25 -> 27152.356 | W25: 48170.87 | X25: ='[7]October 2023'!$Z$89 -> #REF! | Y25: =X25-W25 -> #REF! | Z25: =T25-Y25 -> #REF! | AA25: =(19/31)+2 -> 2.6129032 | AB25: =Z25*AA25 -> #REF!
B26: TOTAL | C26: 2 | E26: =SUM(E24:E25) -> 52352.49 | F26: =SUM(F24:F25) -> 157057.47 | G26: =SUM(G24:G25) -> 3926.4367 | H26: =SUM(H24:H25) -> 0 | I26: =SUM(I24:I25) -> 26176.245 | J26: =SUM(J24:J25) -> 183233.71 | K26: =SUM(K24:K25) -> 52352.49 | L26: =SUM(L24:L25) -> 260000 | ... Q26: =SUM(Q24:Q25) -> 775334.1 | S26: =SUM(S24:S25) -> 893873.58 | T26: =SUM(T24:T25) -> 118539.49 | U26: =SUM(U24:U25) -> 0 | V26: =SUM(V24:V25) -> 0 | W26: =SUM(W24:W25) -> 106197.48 | X26: =SUM(X24:X25) -> #REF! | Y26: =SUM(Y24:Y25) -> #REF! | Z26: =SUM(Z24:Z25) -> #REF! | AB26: =SUM(AB24:AB25) -> #REF!
T27: =S27-Q27 -> 0 | Y27: =X27-W27 -> 0 | Z27: =T27-Y27 -> 0 | AB27: =Z27*AA27 -> 0
B28: TRAINING & INT''L COOP | T28: =S28-Q28 -> 0 | Y28: =X28-W28 -> 0 | Z28: =T28-Y28 -> 0 | AB28: =Z28*AA28 -> 0
A29: 8 | B29: DR FRANCIS NDUM OJIE | C29: CHIEF TRAINING OFFICER | D29: 14(10) | E29: 27611.23 | F29: =E29*300% -> 82833.69 | G29: =E29*7.5% -> 2070.8422 | I29: =E29*50% -> 13805.615 | J29: =E29*350% -> 96639.305 | K29: =E29*100% -> 27611.23 | L29: 140000 | N29: =E29*10% -> 2761.123 | O29: 20000 | P29: =100000 -> 100000 | Q29: =SUM(E29:P29) -> 513333.04 | R29: 15(7) | S29: ='SALARY STRUCTURE'!H18+160000+100000 -> 604720.17 | T29: =S29-Q29 -> 91387.131 | U29: 690.28075 | V29: =837.69 -> 837.69 | W29: =77098.29 -> 77098.29 | X29: ='[7]October 2023'!$Z$97 -> #REF! | Y29: =X29-W29 -> #REF! | Z29: =T29-Y29 -> #REF! | AA29: =3 -> 3 | AB29: =Z29*AA29 -> #REF!
A30: 9 | B30: MOHAMMED R. ADAMU | C30: PRINCIPAL CONF. SECRETARY | D30: 13(10) | E30: 25523.45 | F30: =E30*300% -> 76570.35 | G30: =E30*7.5% -> 1914.2587 | H30: 0 | I30: =E30*50% -> 12761.725 | J30: =E30*350% -> 89332.075 | K30: =E30*100% -> 25523.45 | M30: 70000 | N30: =E30*10% -> 2552.345 | O30: 15000 | P30: 0 | Q30: =SUM(E30:P30) -> 319177.65 | R30: 14(8) | S30: ='SALARY STRUCTURE'!I17+70000 -> 327211.25 | T30: =S30-Q30 -> 8033.5963 | W30: 40698.125 | X30: ='[7]October 2023'!$Z$129 -> #REF! | Y30: =X30-W30 -> #REF! | Z30: =T30-Y30 -> #REF! | AA30: 7 | AB30: =Z30*AA30 -> #REF!
A31: 10 | B31: TASSNEEM IBRAHIM | C31: ASSIST. INFO.OFFICER | D31: 8(10) | E31: 13492.21 | F31: 40476.63 | G31: 1011.9157 | I31: 6746.105 | J31: 47222.735 | K31: 13492.21 | M31: 50000 | N31: 1349.221 | O31: 10000 | Q31: 183791.03 | R31: 10(7) | S31: ='SALARY STRUCTURE'!H14+60000 -> 228601.58 | T31: =S31-Q31 -> 44810.557 | W31: 18102.903 | X31: ='[7]October 2023'!$Z$30 -> #REF! | Y31: =X31-W31 -> #REF! | Z31: =T31-Y31 -> #REF! | AA31: 1 | AB31: =Z31*AA31 -> #REF!
B32: TOTAL | C32: 3 | E32: =SUM(E29:E31) -> 66626.89 | F32: =SUM(F29:F31) -> 199880.67 | G32: =SUM(G29:G31) -> 4997.0167 | H32: =SUM(H29:H31) -> 0 | I32: =SUM(I29:I31) -> 33313.445 | J32: =SUM(J29:J31) -> 233194.11 | K32: =SUM(K29:K31) -> 66626.89 | L32: =SUM(L29:L31) -> 140000 | ... Q32: =SUM(Q29:Q31) -> 1016301.7 | S32: =SUM(S29:S31) -> 1160533 | T32: =S32-Q32 -> 144231.28 | U32: =SUM(U29:U31) -> 690.28075 | W32: =SUM(W29:W31) -> 135899.32 | X32: =SUM(X29:X31) -> #REF! | Y32: =SUM(Y29:Y31) -> #REF! | Z32: =SUM(Z29:Z31) -> #REF! | AB32: =SUM(AB29:AB31) -> #REF!
Y33: =X33-W33 -> 0 | Z33: =T33-Y33 -> 0 | AB33: =Z33*AA33 -> 0
B34: FINANCE & ACCOUNTS | Y34: =X34-W34 -> 0 | Z34: =T34-Y34 -> 0 | AB34: =Z34*AA34 -> 0
A35: 11 | B35: RAHILA SALIHU | C35: ASST. CHIEF ACCOUNTOFFICER | D35: 13(10) | E35: 25523.45 | F35: =E35*300% -> 76570.35 | G35: =E35*7.5% -> 1914.2587 | I35: =E35*50% -> 12761.725 | J35: =E35*350% -> 89332.075 | K35: =E35*100% -> 25523.45 | M35: =70000 -> 70000 | N35: =E35*10% -> 2552.345 | O35: 15000 | Q35: =SUM(E35:P35) -> 319177.65 | R35: 14(8) | S35: ='SALARY STRUCTURE'!I17+70000 -> 327211.25 | T35: =S35-Q35 -> 8033.5963 | U35: 638.08625 | V35: =690.28 -> 690.28 | W35: 40684.599 | X35: ='[7]October 2023'!$Z$118 -> #REF! | Y35: =X35-W35 -> #REF! | Z35: =T35-Y35 -> #REF! | AA35: =9 -> 9 | AB35: =Z35*AA35 -> #REF!
B36: TOTAL | C36: 1 | E36: =SUM(E35:E35) -> 25523.45 | F36: =SUM(F35:F35) -> 76570.35 | G36: =SUM(G35:G35) -> 1914.2587 | H36: =SUM(H35:H35) -> 0 | I36: =SUM(I35:I35) -> 12761.725 | J36: =SUM(J35:J35) -> 89332.075 | K36: =SUM(K35:K35) -> 25523.45 | L36: =SUM(L35:L35) -> 0 | ... Q36: =SUM(Q35:Q35) -> 319177.65 | S36: =SUM(S35:S35) -> 327211.25 | T36: =SUM(T35:T35) -> 8033.5963 | U36: =SUM(U35:U35) -> 638.08625 | V36: =SUM(V35:V35) -> 690.28 | W36: =SUM(W35:W35) -> 40684.599 | X36: =SUM(X35:X35) -> #REF! | Y36: =SUM(Y35:Y35) -> #REF! | Z36: =SUM(Z35:Z35) -> #REF! | AB36: =SUM(AB35:AB35) -> #REF!
L37: =226713.38+70000 -> 296713.38
B38: ADMIN & HUMAN RESOURCE
A39: 12 | B39: ABDULWAHAB DAHIRU | C39: ADMIN OFFICER | D39: 10(10) | E39: 18779.3 | F39: =E39*300% -> 56337.9 | G39: =E39*7.5% -> 1408.4475 | I39: =E39*50% -> 9389.65 | J39: =E39*350% -> 65727.55 | K39: =E39*100% -> 18779.3 | M39: =60000 -> 60000 | N39: =E39*10% -> 1877.93 | O39: 10000 | Q39: =SUM(E39:P39) -> 242300.08 | R39: 12(7) | S39: ='SALARY STRUCTURE'!H15+60000 -> 265371.75 | T39: =S39-Q39 -> 23071.673 | U39: 469.4825 | V39: =570.95 -> 570.95 | W39: 27794.207 | X39: ='[7]October 2023'!$Z$134 -> #REF! | Y39: =X39-W39 -> #REF! | Z39: =T39-Y39 -> #REF! | AA39: 9 | AB39: =Z39*AA39 -> #REF!
A40: 13 | B40: ODEH SUZIE | C40: ADMIN. OFFICER | D40: 10(10) | E40: =18779.3 -> 18779.3 | F40: =E40*300% -> 56337.9 | G40: =E40*7.5% -> 1408.4475 | I40: =E40*50% -> 9389.65 | J40: =E40*350% -> 65727.55 | K40: =E40*100% -> 18779.3 | M40: 60000 | N40: =E40*10% -> 1877.93 | O40: 10000 | Q40: =SUM(E40:P40) -> 242300.08 | R40: 12(7) | S40: ='SALARY STRUCTURE'!H15+60000 -> 265371.75 | T40: =S40-Q40 -> 23071.673 | U40: 0 | W40: 27873.08 | X40: ='[7]October 2023'!$Z$24 -> #REF! | Y40: =X40-W40 -> #REF! | Z40: =T40-Y40 -> #REF! | AA40: 1 | AB40: =Z40*AA40 -> #REF!
A41: 14 | B41: BUKOLA HAUWA SHIRU | C41: ADMIN. ASST. | D41: 8(10) | E41: 13492.21 | F41: =E41*300% -> 40476.63 | G41: =E41*7.5% -> 1011.9157 | I41: =E41*50% -> 6746.105 | J41: =E41*350% -> 47222.735 | K41: =E41*100% -> 13492.21 | M41: =50000 -> 50000 | N41: =E41*10% -> 1349.221 | O41: 10000 | Q41: =SUM(E41:P41) -> 183791.03 | R41: 9(7) | S41: ='SALARY STRUCTURE'!H13+60000 -> 205203.67 | T41: =S41-Q41 -> 21412.64 | W41: 18102.903 | X41: ='[7]October 2023'!$Z$145 -> #REF! | Y41: =X41-W41 -> #REF! | Z41: =T41-Y41 -> #REF! | AA41: 2 | AB41: =Z41*AA41 -> #REF!
...

Sheet SALARY STRUCTURE
A1: NATIONAL INSTITUTE FOR LEGISLATIVE STUDIES
A2: TABLE OF MONTHLY CONSOLIDATED SALARY AND ALLOWANCES SCALES
B3: STEP 1 | C3: STEP 2 | D3: STEP 3 | E3: STEP 4 | F3: STEP 5 | G3: STEP 6 | H3: STEP 7 | I3: STEP 8 | J3: STEP 9 | K3: STEP 10 | L3: STEP 11 | M3: STEP 12 | N3: STEP 13 | O3: STEP 14 | P3: STEP 15
A4: CONLESS LEVEL | B4: N | C4: N | D4: N | E4: N | F4: N | G4: N | H4: N | I4: N | J4: N | K4: N | L4: N | M4: N | N4: N | O4: N | P4: N
A5: ,01 | B5: 32012.167 | C5: 32710.5 | D5: 33408.75 | E5: 34107.083 | F5: 34805.5 | G5: 35503.75 | H5: 36202.083 | I5: 36900.333 | J5: 37598.667 | K5: 38297.083 | L5: 38995.333 | M5: 39693.667 | N5: 40391.917 | O5: 41090.167 | P5: 41788.667
A6: ,02 | B6: 32532.167 | C6: 33445.167 | D6: 34358.333 | E6: 35271.25 | F6: 36184.25 | G6: 37097.417 | H6: 38010.333 | I6: 38923.417 | J6: 39836.417 | K6: 40749.417 | L6: 41662.5 | M6: 42575.5 | N6: 43488.667 | O6: 44401.583 | P6: 45314.583
A7: ,03 | B7: 32976.25 | C7: 34098.417 | D7: 35220.667 | E7: 36343 | F7: 37465.167 | G7: 38587.417 | H7: 39709.667 | I7: 40823.583 | J7: 41954.083 | K7: 43076.417 | L7: 44198.667 | M7: 45445.833 | N7: 46443.167 | O7: 47565.333 | P7: 48687.5
A8: ,04 | B8: 34542.5 | C8: 35890.833 | D8: 37238.917 | E8: 38587.167 | F8: 39935.5 | G8: 41283.75 | H8: 42631.917 | I8: 43980 | J8: 45328.333 | K8: 46676.417 | L8: 48024.667 | M8: 49373 | N8: 50721.167 | O8: 52069.417 | P8: 53417.5
A9: ,05 | B9: 39140.333 | C9: 40706.583 | D9: 42272.833 | E9: 43839.083 | F9: 45405.5 | G9: 46971.75 | H9: 48538 | I9: 50104.417 | J9: 51670.667 | K9: 53236.917 | L9: 54803.167 | M9: 56369.583 | N9: 57936 | O9: 59502.083 | P9: 61068.333
A10: ,06 | B10: 47723.333 | C10: 49632.5 | D10: 51541.75 | E10: 53450.917 | F10: 55360.167 | G10: 57269.417 | H10: 59178.667 | I10: 61087.833 | J10: 62997.083 | K10: 64906.25 | L10: 66815.5 | M10: 68724.667 | N10: 70633.917 | O10: 72543.167 | P10: 74452.417
A11: ,07 | B11: 79244.583 | C11: 82174.667 | D11: 85104.917 | E11: 88034.917 | F11: 106590 | G11: 93895 | H11: 96825.167 | I11: 99755.167 | J11: 102685.33 | K11: 105615.33 | L11: 108545.5 | M11: 111468 | N11: 114405.67 | O11: 117335.83 | P11: 120265.83
A12: ,08 | B12: 102403.75 | C12: 105891.25 | D12: 109378.75 | E12: 112866.25 | F12: 116353.67 | G12: 119841.17 | H12: 123328.67 | I12: 126816.17 | J12: 130303.67 | K12: 133791.17 | L12: 137278.67 | M12: 140766.17 | N12: 144253.67 | O12: 147741.17 | P12: 151228.67
A13: ,09 | B13: 120290 | C13: 124442.17 | D13: 128594.58 | E13: 132746.75 | F13: 136899.08 | G13: 141051.25 | H13: 145203.67 | I13: 149355.83 | J13: 153508 | K13: 157660.33 | L13: 161812.5 | M13: 165964.92 | N13: 170117.08 | O13: 174269.42 | P13: 178421.58
A14: ,10 | B14: 141204.92 | C14: 145770.92 | D14: 150337.08 | E14: 154903.33 | F14: 159469.42 | G14: 164035.5 | H14: 168601.58 | I14: 173167.67 | J14: 177733.75 | K14: 182299.92 | L14: 186865.92 | M14: 191432.17 | N14: 195998.33 | O14: 200564.42 | P14: 205130.5
A15: ,12 | B15: 162876.25 | C15: 169958.92 | D15: 177039.92 | E15: 184124.08 | F15: 191206.58 | G15: 198289.25 | H15: 205371.75 | I15: 212454.42 | J15: 219536.92 | K15: 226619.58 | L15: 233702.08
A16: ,13 | B16: 181786.42 | C16: 189274.25 | D16: 198324.58 | E16: 204249.92 | F16: 211737.67 | G16: 219225.5 | H16: 226713.33 | I16: 234201.17 | J16: 242001.42 | K16: 249176.75 | L16: 256664.58
A17: ,14 | B17: 200784.08 | C17: 208845.17 | D17: 216904.67 | E17: 224967.17 | F17: 233028.33 | G17: 241089.25 | H17: 249153.42 | I17: 257211.25 | J17: 265272.42 | K17: 273333.42 | L17: 281394.42
A18: ,15 | B18: 276221.25 | C18: 287637.83 | D18: 299054.25 | E18: 312760.25 | F18: 321887.17 | G18: 333303.75 | H18: 344720.17 | I18: 356136.75 | J18: 367553.17
A19: ,16 | B19: 341699.58 | C19: 355420.17 | D19: 369154.92 | E19: 382861.42 | F19: 396582.08 | G19: 410302.67 | H19: 424023.33 | I19: 437743.92 | J19: 451464.58
A20: ,17 | B20: 652000 | C20: 676776.17 | D20: 701552.17 | E20: 726328.33 | F20: 751104.42 | G20: 775880.5 | H20: 800656.58 | I20: 825432.67 | J20: 850208.75

Sheet Wage Grant
A1: NATIONAL INSTITUTE FOR LEGISLATIVE AND DEMOCRATIC STUDIES
A2: GRANT OF WAGE AWARD TO FEDERAL GOVERNMENT WORKERS
A3: SCHEDULE FOR FOUR (4) MONTHS SEPTEMBER TO DECEMBER 2023
A5: S/N | B5: STAFF NAME | C5: DESIGNATION | D5: GRADE LEVEL | E5: SEPTEMBER | F5: OCTOBER | G5: NOVEMBER | H5: DECEMBER | I5: SEPT. TO DEC. 2023
B6: DG'S OFFICE
A7: 1 | B7: PROF. ABUBAKAR O. SULAIMAN | C7: DIRECTOR GENERAL | D7: N/A | E7: 35000 | F7: 35000 | G7: 35000 | H7: 35000 | I7: =E7+F7+G7+H7 -> 140000
A8: 2 | B8: DR JAKE DABANG DAN AZUMI | C8: DEPUTY DIR. TECHNICAL | D8: 16(9) | E8: 35000 | F8: 35000 | G8: 35000 | H8: 35000 | I8: =E8+F8+G8+H8 -> 140000
A9: 3 | B9: RAHEEM USMAN AYIGORO | C9: SA-INFRASTRUCTURE | D9: 16 (9) | E9: 35000 | F9: 35000 | G9: 35000 | H9: 35000 | I9: =E9+F9+G9+H9 -> 140000
A10: 4 | B10: MARIAM MOHAMMED BELLO | C10: SA- SPECIAL DUTIES | D10: 16(8) | E10: 35000 | F10: 35000 | G10: 35000 | H10: 35000 | I10: =E10+F10+G10+H10 -> 140000
A11: 5 | B11: AKINSANMI ADEJOKE OLUKEMI | C11: DEPUTY DIR. INFO/PROTOCOL | D11: 16(8) | E11: 35000 | F11: 35000 | G11: 35000 | H11: 35000 | I11: =E11+F11+G11+H11 -> 140000
A12: 6 | B12: DR IKEME ARTHUR J.O | C12: DEPUTY DIRECTOR, M&E | D12: 16(8) | E12: 35000 | F12: 35000 | G12: 35000 | H12: 35000 | I12: =E12+F12+G12+H12 -> 140000
A13: 7 | B13: MOSHOOD M. OLALERE | C13: DEPUTY DIR. GENERAL SERVICE | D13: 16(8) | E13: 35000 | F13: 35000 | G13: 35000 | H13: 35000 | I13: =E13+F13+G13+H13 -> 140000
A14: 8 | B14: ANDRAWUS MUSA | C14: ASST. DIRECTOR, STORES | D14: 15(9) | E14: 35000 | F14: 35000 | G14: 35000 | H14: 35000 | I14: =E14+F14+G14+H14 -> 140000
A15: 9 | B15: DONALD E. MKPANAM | C15: CHIEF ICT OFFICER | D15: 14(10) | E15: 35000 | F15: 35000 | G15: 35000 | H15: 35000 | I15: =E15+F15+G15+H15 -> 140000
A16: 11 | B16: ALI ABDULLAHI | C16: CHIEF ICT OFFICER | D16: 14(10) | E16: 35000 | F16: 35000 | G16: 35000 | H16: 35000 | I16: =E16+F16+G16+H16 -> 140000
A17: 12 | B17: PERCY TERFA GBAHABO | C17: HEAD, NILDS LIAISON OFFICE | D17: 13(9) | E17: 35000 | F17: 35000 | G17: 35000 | H17: 35000 | I17: =E17+F17+G17+H17 -> 140000
A18: 13 | B18: HASSANA AHMED IBRAHIM | C18: PA- TO DG | D18: 13 (8) | E18: 35000 | F18: 35000 | G18: 35000 | H18: 35000 | I18: =E18+F18+G18+H18 -> 140000
... A27: 23 | B27: HARUNA JIBRIL AMEH | C27: ASST. ADMIN. OFFICER | D27: 8(7) | E27: 35000 | F27: 35000 | G27: 35000 | H27: 35000 | I27: =E27+F27+G27+H27 -> 140000
B28: TOTAL FOR DG'S OFFICE | E28: =SUM(E7:E27) -> 735000 | F28: =SUM(F7:F27) -> 735000 | G28: =SUM(G7:G27) -> 735000 | H28: =SUM(H7:H27) -> 735000 | I28: =SUM(I7:I27) -> 2940000
B30: INTERNAL AUDIT
A31: 1 | B31: OSANAIYE DAVID AKINYEMI | C31: DIRECTOR INTERNAL AUDIT | D31: 17(9) | E31: 35000 | F31: 35000 | G31: 35000 | H31: 35000 | I31: =E31+F31+G31+H31 -> 140000
A32: 2 | B32: JAMILA ABDUL | C32: AUDITOR II | D32: 8(7) | E32: 35000 | F32: 35000 | G32: 35000 | H32: 35000 | I32: =E32+F32+G32+H32 -> 140000
B33: TOTAL FOR AUDIT | E33: =SUM(E31:E32) -> 70000 | F33: =SUM(F31:F32) -> 70000 | G33: =SUM(G31:G32) -> 70000 | H33: =SUM(H31:H32) -> 70000 | I33: =SUM(I31:I32) -> 280000
B35: LEG. SUPPORT SEVICES
A36: 1 | B36: PROF. EDOBA BRIGHT OMOREGBE | C36: AG. DLSS | D36: 17(9) | E36: 35000 | F36: 35000 | G36: 35000 | H36: 35000 | I36: =E36+F36+G36+H36 -> 140000
A37: 2 | B37: DR CLINTON JAJA | C37: SENIOR RESEARCH FELLOW | D37: 15(9) | E37: 35000 | F37: 35000 | G37: 35000 | H37: 35000 | I37: =E37+F37+G37+H37 -> 140000
A38: 3 | B38: BETHEL UZOMA IHUGBA | C38: SNR RESEARCH FELLOW | D38: 15(9) | E38: 35000 | F38: 35000 | G38: 35000 | H38: 35000 | I38: =E38+F38+G38+H38 -> 140000
A39: 4 | B39: OGUCHE SAMUEL | C39: SNR RESEARCH FELLOW | D39: 15(9) | E39: 35000 | F39: 35000 | G39: 35000 | H39: 35000 | I39: =E39+F39+G39+H39 -> 140000
A40: 5 | B40: IBRAHIM USMAN | C40: SNR RESEARCH FELLOW | D40: 15(8) | E40: 35000 | F40: 35000 | G40: 35000 | H40: 35000 | I40: =E40+F40+G40+H40 -> 140000
A41: 6 | B41: DR MOHAMMED O. AMALI | C41: RESEARCH FELLOW I | D41: 14(10) | E41: 35000 | F41: 35000 | G41: 35000 | H41: 35000 | I41: =E41+F41+G41+H41 -> 140000
A42: 7 | B42: YAHAYA SHAMSU | C42: RESEARCH FELLOW 1 | D42: 14(10) | E42: 35000 | F42: 35000 | G42: 35000 | H42: 35000 | I42: =E42+F42+G42+H42 -> 140000
A43: 8 | B43: OFORDEME ADAOBI JULIA | C43: RESEARCH FELLOW 1 | D43: 14(9) | E43: 35000 | F43: 35000 | G43: 35000 | H43: 35000 | I43: =E43+F43+G43+H43 -> 140000
A44: 9 | B44: DORIS DAKDA AARON | C44: RESEARCH FELLOW II | D44: 13(10) | E44: 35000 | F44: 35000 | G44: 35000 | H44: 35000 | I44: =E44+F44+G44+H44 -> 140000
A45: 10 | B45: BILKIS S. LAWAL-GAMBARI | C45: RESEARCH OFFICER | D45: 10(7) | E45: 35000 | F45: 35000 | G45: 35000 | H45: 35000 | I45: =E45+F45+G45+H45 -> 140000
A46: 11 | B46: ZAINAB AKINDE | C46: RESEARCH OFFICER | D46: 9(7) | E46: 35000 | F46: 35000 | G46: 35000 | H46: 35000 | I46: =E46+F46+G46+H46 -> 140000
A47: 12 | B47: ABDULLAHI AHMAD USMAN | C47: RESEARCH OFFICER | D47: 9(7) | E47: 35000 | F47: 35000 | G47: 35000 | H47: 35000 | I47: =E47+F47+G47+H47 -> 140000
A48: 13 | B48: GUNAT NANSAK MARK | C48: RESEARCH OFFICER | D48: 9(7) | E48: 35000 | F48: 35000 | G48: 35000 | H48: 35000 | I48: =E48+F48+G48+H48 -> 140000
B49: TOTAL FOR LEGIS. SUPPORT SERVICES | E49: =SUM(E36:E48) -> 455000 | F49: =SUM(F36:F48) -> 455000 | G49: =SUM(G36:G48) -> 455000 | H49: =SUM(H36:H48) -> 455000 | I49: =SUM(I36:I48) -> 1820000
B51: LEGAL SERVICES
A52: 1 | B52: DR SHUIBU DANWANKA | C52: DIRECTOR LEGAL SERVICES | D52: 17(9) | E52: 35000 | F52: 35000 | G52: 35000 | H52: 35000 | I52: =E52+F52+G52+H52 -> 140000
...

Sheet Wage Grant (2)
A1: NATIONAL INSTITUTE FOR LEGISLATIVE AND DEMOCRATIC STUDIES
A2: GRANT OF WAGE AWARD TO FEDERAL GOVERNMENT WORKERS
A3: SCHEDULE FOR FOUR (4) MONTHS SEPTEMBER TO DECEMBER 2023
A5: S/N | B5: STAFF NAME | C5: DESIGNATION | D5: SEPTEMBER, 2023 | E5: OCTOBER, 2023 | F5: NOVEMBER, 2023 | G5: DECEMBER, 2023 | H5: SEPT. TO DEC. 2023
A6: 1 | B6: Mohammed Etudaiye | C6: Office Assistant | D6: 35000 | E6: 35000 | F6: 35000 | G6: 35000 | H6: =D6+E6+F6+G6 -> 140000
A7: 2 | B7: Saratu Adamu Attajiri | C7: Office Assistant | D7: 35000 | E7: 35000 | F7: 35000 | G7: 35000 | H7: =D7+E7+F7+G7 -> 140000
A8: 3 | B8: Elizabeth Ogechukwu Onyeaku | C8: Consultant | D8: 35000 | E8: 35000 | F8: 35000 | G8: 35000 | H8: =D8+E8+F8+G8 -> 140000
A9: 4 | B9: Saratu Adamu Attajiri | C9: Office Assistant | D9: 35000 | E9: 35000 | F9: 35000 | G9: 35000 | H9: =D9+E9+F9+G9 -> 140000
A10: 5 | B10: Aboaman Innocent | C10: Casual | D10: 35000 | E10: 35000 | F10: 35000 | G10: 35000 | H10: =D10+E10+F10+G10 -> 140000
A11: 6 | B11: Kusai E. Richard | C11: Plumber | D11: 35000 | E11: 35000 | F11: 35000 | G11: 35000 | H11: =D11+E11+F11+G11 -> 140000
A12: 7 | B12: Bulus Ishaya | C12: Gardener | D12: 35000 | E12: 35000 | F12: 35000 | G12: 35000 | H12: =D12+E12+F12+G12 -> 140000
