Workbook

Sheet JANURAY, 2021
B3: STAFF PAYROLL FOR THE MONTH OF JANUARY, 2021
E4: ='[1]FEB 08'!E8/'[1]FEB 08'!M8 -> 0.22 | H4: ='[1]FEB 08'!F8/'[1]FEB 08'!Q8 -> 0.3
B5: STAFF NAME | T5: DEDUCTIONS | Z5: NET SALARY
C6: DESIGNATION | D6: SALARY | E6: BASIC | L6: MOTOR/ | M6: RESEARCH | O6: LEAVE | P6: OUT FIT | Q6: LEGISLATIVE | R6: GROSS | Y6: DECEMBER,2020 | Z6: JANUARY,2021
D7: LEVEL | E7: SALARY | F7: SALARY/ALLOWCE AREARS | G7: RENT | H7: UTILITY | I7: DOMESTIC | J7: ENTERT. | K7: FURNIT. | L7: FUEL | M7: ALLOWANCE | O7: ALLCE | P7: ALLCE | Q7: DUTY ALLCE | R7: SALARY | T7: COOP SOCIETY | U7: COOP. LOAN RECOVERY | V7: NHF DEDUCTION | W7: PAYE | X7: TOTAL
A8: S/N | B8: DG OFFICE | E8: N | H8: N | R8: N | W8: N
A9: 1 | B9: PROF. ABUBAKAR O. SULAIMAN | C9: DIRECTOR GENERAL | D9: CONSOL | E9: 160488.75 | G9: 320977.5 | H9: 48146.63 | I9: 120366.57 | J9: 72219.94 | K9: 0 | L9: 120366.57 | M9: =200000 -> 200000 | O9: 16048.88 | P9: 25000 | Q9: 25235 | R9: =SUM(E9:Q9) -> 1108849.8 | W9: 113176.97 | X9: =T9+U9+V9+W9 -> 113176.97 | Y9: 995672.87 | Z9: =R9-X9 -> 995672.87
A10: 2 | B10: DR ADEYEMI AKEEB FAJINGBESI | C10: DIR. SPECIAL DUTIES, DG OFFICE | D10: 17(9) | E10: 81740.02 | G10: =E10*300% -> 245220.06 | H10: =E10*7.5% -> 6130.5015 | I10: 80244.38 | J10: =E10*50% -> 40870.01 | K10: =E10*350% -> 286090.07 | L10: =E10*100% -> 81740.02 | M10: =150000 -> 150000 | O10: =E10*10% -> 8174.002 | P10: 20000 | Q10: 0 | R10: =SUM(E10:Q10) -> 1000209.1 | T10: 200000 | U10: =59722.22 -> 59722.22 | V10: ='[2]Jan 2021'!$H$38 -> 806.58 | W10: 52776.63 | X10: =SUM(T10:W10) -> 313305.43 | Y10: 685666.71 | Z10: =R10-X10 -> 686903.63
A11: 3 | B11: AKINSANMI ADEJOKE OLUKEMI | C11: AM INFORMATION | D11: 15(9) | E11: 33507.5 | G11: =E11*300% -> 100522.5 | H11: =E11*7.5% -> 2513.0625 | I11: 40122.19 | J11: =E11*50% -> 16753.75 | K11: =E11*350% -> 117276.25 | L11: =E11*100% -> 33507.5 | M11: =100000 -> 100000 | O11: =E11*10% -> 3350.75 | P11: 20000 | Q11: =100000 -> 100000 | R11: =SUM(E11:Q11) -> 567553.5 | T11: =0 -> 0 | U11: 0 | V11: ='[2]Jan 2021'!$H$29 -> 806.58 | W11: 15548.33 | X11: =T11+U11+V11+W11 -> 16354.91 | Y11: 551167.48 | Z11: =R11-X11 -> 551198.59
A12: 4 | B12: DR IKEME ARTHUR J.O | C12: SNR RESEARCH FELLOW | D12: 15(9) | E12: =33507.5 -> 33507.5 | G12: =E12*300% -> 100522.5 | H12: =E12*7.5% -> 2513.0625 | I12: 40122.19 | J12: =E12*50% -> 16753.75 | K12: =E12*350% -> 117276.25 | L12: =E12*100% -> 33507.5 | M12: =100000 -> 100000 | O12: =E12*10% -> 3350.75 | P12: 20000 | Q12: 0 | R12: =SUM(E12:Q12) -> 467553.5 | T12: 50000 | U12: =212642 -> 212642 | V12: ='[3]DECEMBER 2019'!$H$38 -> 837.6875 | W12: 15548.33 | X12: =SUM(T12:W12) -> 279028.02 | Y12: 188525.48 | Z12: =R12-X12 -> 188525.48
A13: 5 | B13: MOSHOOD M. OLALERE | C13: MANAGER ADMIN DG's OFFICE | D13: 15(9) | E13: =33507.5 -> 33507.5 | G13: =E13*300% -> 100522.5 | H13: =E13*7.5% -> 2513.0625 | I13: 40122.19 | J13: =E13*50% -> 16753.75 | K13: =E13*350% -> 117276.25 | L13: =E13*100% -> 33507.5 | M13: =100000 -> 100000 | O13: =E13*10% -> 3350.75 | P13: 20000 | Q13: 0 | R13: =SUM(E13:Q13) -> 467553.5 | T13: =5000 -> 5000 | U13: =179017.51 -> 179017.51 | V13: ='[3]DECEMBER 2019'!$H$35 -> 837.6875 | W13: 15548.33 | X13: =T13+U13+V13+W13 -> 200403.53 | Y13: 267149.97 | Z13: =R13-X13 -> 267149.97
A14: 6 | B14: SARAFADEEN ALABELEWE | C14: SA ADMINISTRATION | D14: 16(9) | E14: =42653.17 -> 42653.17 | G14: =E14*300% -> 127959.51 | H14: =E14*7.5% -> 3198.9877 | I14: 40122.19 | J14: =E14*50% -> 21326.585 | K14: =E14*350% -> 149286.1 | L14: =E14*100% -> 42653.17 | M14: =100000 -> 100000 | O14: =E14*10% -> 4265.317 | P14: 20000 | R14: =SUM(E14:Q14) -> 551465.02 | T14: =100000 -> 100000 | U14: =137500 -> 137500 | W14: 21618.09 | X14: =T14+U14+V14+W14 -> 259118.09 | Y14: 278625.91 | Z14: =R14-X14 -> 292346.93
A15: 7 | B15: DR ABDULSALAM NASIRU NAEEM | C15: SA ACADEMICS | D15: 16(7) | E15: =39662.25 -> 39662.25 | G15: =E15*300% -> 118986.75 | H15: =E15*7.5% -> 2974.6687 | I15: 40122.19 | J15: =E15*50% -> 19831.125 | K15: =E15*350% -> 138817.88 | L15: =E15*100% -> 39662.25 | M15: =150000 -> 150000 | O15: =E15*10% -> 3966.225 | P15: 20000 | Q15: =100000 -> 100000 | R15: =SUM(E15:Q15) -> 674023.33 | W15: =21618.09 -> 21618.09 | X15: =T15+U15+V15+W15 -> 21618.09 | Y15: 590588.72 | Z15: =R15-X15 -> 652405.24
A16: 8 | B16: TOKUNBO ALFRED ADULOJU | C16: AM LIAISON OFFICE | D16: 13(10) | E16: =25523.45 -> 25523.45 | G16: =E16*300% -> 76570.35 | H16: =E16*7.5% -> 1914.2587 | J16: =E16*50% -> 12761.725 | K16: =E16*350% -> 89332.075 | L16: =E16*100% -> 25523.45 | M16: =100000 -> 100000 | O16: =E16*10% -> 2552.345 | P16: 15000 | Q16: =100000 -> 100000 | R16: =SUM(E16:Q16) -> 449177.65 | T16: =100000 -> 100000 | U16: =0 -> 0 | V16: ='[2]Jan 2021'!$H$22 -> 806.58 | W16: 7709.76 | X16: =T16+U16+V16+W16 -> 108516.34 | Y16: 333672.77 | Z16: =R16-X16 -> 340661.31
A17: 9 | B17: HUSSEIN EGYE MUSA | C17: AM PROTOCOL | D17: 13(10) | E17: =25523.45 -> 25523.45 | G17: =E17*300% -> 76570.35 | H17: =E17*7.5% -> 1914.2587 | J17: =E17*50% -> 12761.725 | K17: =E17*350% -> 89332.075 | L17: =E17*100% -> 25523.45 | M17: =100000 -> 100000 | O17: =E17*10% -> 2552.345 | P17: 15000 | Q17: 50000 | R17: =SUM(E17:Q17) -> 399177.65 | T17: 10000 | U17: =103000 -> 103000 | V17: 0 | W17: 7709.76 | X17: =T17+U17+V17+W17 -> 120709.76 | Y17: 271291.3 | Z17: =R17-X17 -> 278467.89
A18: 10 | B18: DONALD E. MKPANAM | C18: AM ICT | D18: 13(11) | E18: 26339.3 | G18: =E18*300% -> 79017.9 | H18: =E18*7.5% -> 1975.4475 | J18: =E18*50% -> 13169.65 | K18: =E18*350% -> 92187.55 | L18: =E18*100% -> 26339.3 | M18: =100000 -> 100000 | O18: =E18*10% -> 2633.93 | P18: 15000 | Q18: 0 | R18: =SUM(E18:Q18) -> 356663.08 | V18: ='[2]Jan 2021'!$H$31 -> 457.041 | W18: 7709.76 | X18: =T18+U18+V18+W18 -> 8166.801 | Y18: 348294.83 | Z18: =R18-X18 -> 348496.28
A19: 11 | B19: JOY HARUNA MAKERI | C19: AM TRAINING | D19: 13(10) | E19: =25523.45 -> 25523.45 | G19: =E19*300% -> 76570.35 | H19: =E19*7.5% -> 1914.2587 | J19: =E19*50% -> 12761.725 | K19: =E19*350% -> 89332.075 | L19: =E19*100% -> 25523.45 | M19: 150000 | O19: =E19*10% -> 2552.345 | P19: 15000 | Q19: =50000+100000 -> 150000 | R19: =SUM(E19:Q19) -> 549177.65 | W19: =7709.76 -> 7709.76 | X19: =SUM(T19:W19) -> 7709.76 | Y19: 534291.3 | Z19: =R19-X19 -> 541467.89
A20: 12 | B20: ALI ABDULLAHI | C20: AM ICT | D20: 13(11) | E20: =26339.3 -> 26339.3 | F20: 0 | G20: =E20*300% -> 79017.9 | H20: =E20*7.5% -> 1975.4475 | I20: 0 | J20: =E20*50% -> 13169.65 | K20: =E20*350% -> 92187.55 | L20: =E20*100% -> 26339.3 | M20: =100000 -> 100000 | O20: =E20*10% -> 2633.93 | P20: 15000 | Q20: =0 -> 0 | R20: =SUM(E20:Q20) -> 356663.08 | W20: =7709.76 -> 7709.76 | X20: =T20+U20+V20+W20 -> 7709.76 | Y20: 348953.32 | Z20: =R20-X20 -> 348953.32
A21: 13 | B21: ADUGBA RICHARD TERSEER | C21: INFORMATION OFFICER | D21: 10(9) | E21: =18281.64 -> 18281.64 | G21: =E21*300% -> 54844.92 | H21: =E21*7.5% -> 1371.123 | J21: =E21*50% -> 9140.82 | K21: =E21*350% -> 63985.74 | L21: =E21*100% -> 18281.64 | M21: =100000 -> 100000 | O21: =E21*10% -> 1828.164 | P21: 10000 | R21: =SUM(E21:Q21) -> 277734.05 | T21: =50000 -> 50000 | U21: =111833.33 -> 111833.33 | W21: 3369.51 | X21: =T21+U21+V21+W21 -> 165202.84 | Y21: 107965.36 | Z21: =R21-X21 -> 112531.21
A22: 14 | B22: CHRISTIAN MADUABUCHI ODO | C22: ICT OFFICER | D22: 10(11) | E22: =19276.95 -> 19276.95 | G22: =E22*300% -> 57830.85 | H22: =E22*7.5% -> 1445.7713 | J22: =E22*50% -> 9638.475 | K22: =E22*350% -> 67469.325 | L22: =E22*100% -> 19276.95 | M22: =100000 -> 100000 | O22: =E22*10% -> 1927.695 | P22: 10000 | R22: =SUM(E22:Q22) -> 286866.02 | T22: =20000 -> 20000 | U22: =82500 -> 82500 | V22: ='[2]Jan 2021'!$H$50 -> 646.3525 | W22: 3369.51 | X22: =T22+U22+V22+W22 -> 106515.86 | Y22: 175961.08 | Z22: =R22-X22 -> 180350.15
A23: 15 | B23: VICTOR ASUKWO | C23: ICT OFFICER | D23: 8 (9) | E23: =13112.16 -> 13112.16 | G23: =E23*300% -> 39336.48 | H23: =E23*7.5% -> 983.412 | J23: =E23*50% -> 6556.08 | K23: =E23*350% -> 45892.56 | L23: =E23*100% -> 13112.16 | M23: =100000 -> 100000 | O23: =E23*10% -> 1311.216 | P23: 10000 | R23: =SUM(E23:Q23) -> 230304.07 | T23: =10000 -> 10000 | W23: 1484.37 | X23: =T23+U23+V23+W23 -> 11484.37 | Y23: 215331.73 | Z23: =R23-X23 -> 218819.7
A24: 16 | B24: SULEIMAN ABUBAKAR SODEEQ | C24: ASST. ADMIN. OFFICER | D24: 8(7) | E24: =12351.94 -> 12351.94 | F24: =0 -> 0 | G24: =E24*300% -> 37055.82 | H24: =E24*7.5% -> 926.3955 | J24: =E24*50% -> 6175.97 | K24: =E24*350% -> 43231.79 | L24: =E24*100% -> 12351.94 | M24: =100000 -> 100000 | O24: =E24*10% -> 1235.194 | P24: 10000 | R24: =SUM(E24:Q24) -> 223329.05 | W24: =1235.19 -> 1235.19 | X24: =SUM(T24:W24) -> 1235.19 | Y24: 222093.86 | Z24: =R24-X24 -> 222093.86
A25: 17 | B25: YAKUB OLUWATOYIN USMAN | C25: ASST. ADMIN. OFFICER | D25: 8(7) | E25: =12351.94 -> 12351.94 | F25: =0 -> 0 | G25: =E25*300% -> 37055.82 | H25: =E25*7.5% -> 926.3955 | J25: =E25*50% -> 6175.97 | K25: =E25*350% -> 43231.79 | L25: =E25*100% -> 12351.94 | M25: =100000 -> 100000 | O25: =E25*10% -> 1235.194 | P25: 10000 | R25: =SUM(E25:Q25) -> 223329.05 | T25: =10000 -> 10000 | W25: =1235.19 -> 1235.19 | X25: =SUM(T25:W25) -> 11235.19 | Y25: 112093.86 | Z25: =R25-X25 -> 212093.86
A26: 18 | B26: ANTHONY EDET | C26: ASST. MGR M&E | D26: 13(8) | E26: =23891.12 -> 23891.12 | F26: =ARREARS!V9 -> 423372 | G26: =E26*300% -> 71673.36 | H26: =E26*7.5% -> 1791.834 | I26: 0 | J26: =E26*50% -> 11945.56 | K26: =E26*350% -> 83618.92 | L26: =E26*100% -> 23891.12 | M26: =100000 -> 100000 | O26: =E26*10% -> 2389.112 | P26: 15000 | Q26: 0 | R26: =SUM(E26:Q26) -> 757573.03 | T26: 10000 | V26: ='[2]Jan 2021'!$H$42 -> 638.08625 | W26: =7709.76+ARREARS!AJ9 -> 59792.76 | X26: =SUM(T26:W26) -> 70430.846 | Y26: 277568.26 | Z26: =R26-X26 -> 687142.18
A27: 19 | B27: EGUATU U. ONYEJELEM | C27: OFFICER M&E | D27: 10(9) | E27: =18281.64 -> 18281.64 | G27: =E27*300% -> 54844.92 | H27: =E27*7.5% -> 1371.123 | J27: =E27*50% -> 9140.82 | K27: =E27*350% -> 63985.74 | L27: =E27*100% -> 18281.64 | M27: =100000 -> 100000 | O27: =E27*10% -> 1828.164 | P27: 10000 | R27: =SUM(E27:Q27) -> 277734.05 | T27: =20000 -> 20000 | U27: =87500+43750 -> 131250 | W27: 3369.51 | X27: =SUM(T27:W27) -> 154619.51 | Y27: 118548.69 | Z27: =R27-X27 -> 123114.54
A28: 20 | B28: ODEH SUZIE | C28: ADMIN. OFFICER, LIASION OFFICE | D28: 10(8) | E28: =17784 -> 17784 | F28: =0 -> 0 | G28: =E28*300% -> 53352 | H28: =E28*7.5% -> 1333.8 | J28: =E28*50% -> 8892 | K28: =E28*350% -> 62244 | L28: =E28*100% -> 17784 | M28: 100000 | O28: =E28*10% -> 1778.4 | P28: 10000 | R28: =SUM(E28:Q28) -> 273168.2 | T28: =30000+20000 -> 50000 | V28: =0 -> 0 | W28: 3369.51 | X28: =T28+U28+V28+W28 -> 53369.51 | Y28: 255232.57 | Z28: =R28-X28 -> 219798.69
B29: TOTAL | C29: 20 | E29: =SUM(E9:E28) -> 689647.03 | F29: =SUM(F9:F28) -> 423372 | G29: =SUM(G9:G28) -> 1908452.3 | H29: =SUM(H9:H28) -> 87833.501 | I29: =SUM(I9:I28) -> 401221.9 | J29: =SUM(J9:J28) -> 336799.08 | K29: =SUM(K9:K28) -> 1852054 | L29: =SUM(L9:L28) -> 649524.85 | M29: =SUM(M9:M28) -> 2250000 | O29: =SUM(O9:O28) -> 68964.708 | P29: =SUM(P9:P28) -> 305000 | Q29: =SUM(Q9:Q28) -> 525235 | R29: =SUM(R9:R28) -> 9498104.4 | T29: =SUM(T9:T28) -> 635000 | U29: =SUM(U9:U28) -> 1017465.1 | V29: =SUM(V9:V28) -> 5836.5948 | W29: =SUM(W9:W28) -> 371609.12 | X29: =SUM(X9:X28) -> 2029910.8 | Y29: =SUM(Y9:Y28) -> 6878696.1 | Z29: =SUM(Z9:Z28) -> 7468193.6
B31: INTERNAL AUDIT
A32: 1 | B32: NWOSU MATHEW EZE | C32: Ag. DIRECTOR INT. AUDIT | D32: 17(8) | E32: =79039.64 -> 79039.64 | G32: =E32*300% -> 237118.92 | H32: =E32*7.5% -> 5927.973 | I32: =80244.38 -> 80244.38 | J32: =E32*50% -> 39519.82 | K32: =E32*350% -> 276638.74 | L32: =E32*100% -> 79039.64 | M32: =100000 -> 100000 | O32: =E32*10% -> 7903.964 | P32: 20000 | Q32: 0 | R32: =SUM(E32:Q32) -> 925433.08 | T32: =100000 -> 100000 | U32: =287500 -> 287500 | V32: ='[2]Jan 2021'!$H$26 -> 837.6875 | W32: =52776.63 -> 52776.63 | X32: =T32+U32+V32+W32 -> 441114.32 | Y32: 459351.89 | Z32: =R32-X32 -> 484318.76
A33: 2 | B33: BASHIRU ABBA WALI | C33: OFF. INT. AUDIT | D33: 10(10) | E33: =18779.3 -> 18779.3 | G33: =E33*300% -> 56337.9 | H33: =E33*7.5% -> 1408.4475 | I33: 0 | J33: =E33*50% -> 9389.65 | K33: =E33*350% -> 65727.55 | L33: =E33*100% -> 18779.3 | M33: =100000 -> 100000 | O33: =E33*10% -> 1877.93 | P33: 10000 | Q33: 0 | R33: =0 -> 0 | T33: =0 -> 0 | U33: =0 -> 0 | W33: =0 -> 0 | X33: =T33+U33+V33+W33 -> 0 | Y33: 278930.57 | Z33: =R33-X33 -> 0
C34: 2 | E34: =SUM(E32:E33) -> 97818.94 | G34: =SUM(G32:G33) -> 293456.82 | H34: =SUM(H32:H33) -> 7336.4205 | I34: =SUM(I32:I33) -> 80244.38 | J34: =SUM(J32:J33) -> 48909.47 | K34: =SUM(K32:K33) -> 342366.29 | L34: =SUM(L32:L33) -> 97818.94 | M34: =SUM(M32:M33) -> 200000 | O34: =SUM(O32:O33) -> 9781.894 | P34: =SUM(P32:P33) -> 30000 | Q34: =SUM(Q32:Q33) -> 0 | R34: =SUM(R32:R33) -> 925433.08 | T34: =SUM(T32:T33) -> 100000 | U34: =SUM(U32:U33) -> 287500 | V34: =SUM(V32:V33) -> 837.6875 | W34: =SUM(W32:W33) -> 52776.63 | X34: =SUM(X32:X33) -> 441114.32 | Y34: =SUM(Y32:Y33) -> 738282.45 | Z34: =SUM(Z32:Z33) -> 484318.76
B36: LEG. SUPPORT SEVICES
A37: 1 | B37: PROF. EDOBA BRIGHT OMOREGBE | C37: AG. DLSS | D37: 17(9) | E37: =81740.02 -> 81740.02 | G37: =E37*300% -> 245220.06 | H37: =E37*7.5% -> 6130.5015 | I37: 80244.38 | J37: =E37*50% -> 40870.01 | K37: =E37*350% -> 286090.07 | L37: =E37*100% -> 81740.02 | M37: =150000 -> 150000 | O37: =E37*10% -> 8174.002 | P37: 20000 | R37: =SUM(E37:Q37) -> 1000209.1 | T37: =100000+2000 -> 102000 | W37: =52776.63 -> 52776.63 | X37: =W37+T37+U37+V37 -> 154776.63 | Y37: 922656.45 | Z37: =R37-X37 -> 845432.43
A38: 2 | B38: DR CLINTON JAJA | C38: SENIOR RESEARCH FELLOW | D38: 15(9) | E38: =33507.5 -> 33507.5 | G38: =E38*300% -> 100522.5 | H38: =E38*7.5% -> 2513.0625 | I38: 40122.19 | J38: =E38*50% -> 16753.75 | K38: =E38*350% -> 117276.25 | L38: =E38*100% -> 33507.5 | M38: =150000 -> 150000 | O38: =E38*10% -> 3350.75 | P38: 20000 | Q38: 0 | R38: =SUM(E38:Q38) -> 517553.5 | T38: 50000 | U38: =240909.11 -> 240909.11 | W38: 15548.33 | X38: =SUM(T38:W38) -> 306457.44 | Y38: 211096.06 | Z38: =R38-X38 -> 211096.06
A39: 3 | B39: BETHEL UZOMA IHUGBA | C39: SNR RESEARCH FELLOW | D39: 15(9) | E39: =33507.5 -> 33507.5 | G39: =E39*300% -> 100522.5 | H39: =E39*7.5% -> 2513.0625 | I39: 40122.19 | J39: =E39*50% -> 16753.75 | K39: =E39*350% -> 117276.25 | L39: =E39*100% -> 33507.5 | M39: =150000 -> 150000 | O39: =E39*10% -> 3350.75 | P39: 20000 | R39: =SUM(E39:Q39) -> 517553.5 | T39: =30000+13000 -> 43000 | U39: =246905.96 -> 246905.96 | W39: 15548.33 | X39: =W39+T39+U39+V39 -> 305454.29 | Y39: 200682.76 | Z39: =R39-X39 -> 212099.21
A40: 4 | B40: OGUCHE SAMUEL | C40: RESEARCH FELLOW I | D40: 14(11) | E40: 28489.81 | G40: =E40*300% -> 85469.43 | H40: =E40*7.5% -> 2136.7357 | J40: =E40*50% -> 14244.905 | K40: =E40*350% -> 99714.335 | L40: =E40*100% -> 28489.81 | M40: =150000 -> 150000 | O40: =E40*10% -> 2848.981 | P40: 20000 | R40: =SUM(E40:Q40) -> 431394.01 | T40: =30000 -> 30000 | U40: =179165.6+26250 -> 205415.6 | W40: 7709.76 | X40: =SUM(T40:W40) -> 243125.36 | Y40: 188268.65 | Z40: =R40-X40 -> 188268.65
A41: 5 | B41: IBRAHIM USMAN | C41: RESEARCH FELLOW I | D41: 14(11) | E41: =28489.81 -> 28489.81 | G41: =E41*300% -> 85469.43 | H41: =E41*7.5% -> 2136.7357 | I41: 0 | J41: =E41*50% -> 14244.905 | K41: =E41*350% -> 99714.335 | L41: =E41*100% -> 28489.81 | M41: =150000 -> 150000 | O41: =E41*10% -> 2848.981 | P41: 20000 | Q41: 0 | R41: =SUM(E41:Q41) -> 431394.01 | V41: ='[2]Jan 2021'!$H$27 -> 991.55625 | W41: 7709.76 | X41: =W41+T41+U41+V41 -> 8701.3162 | Y41: 414932.99 | Z41: =R41-X41 -> 422692.69
A42: 6 | B42: DR MOHAMMED O. AMALI | C42: RESEARCH FELLOW I | D42: 14(8) | E42: =25854.1 -> 25854.1 | F42: =ARREARS!V12 -> 14304 | G42: =E42*300% -> 77562.3 | H42: =E42*7.5% -> 1939.0575 | J42: =E42*50% -> 12927.05 | K42: =E42*350% -> 90489.35 | L42: =E42*100% -> 25854.1 | M42: =150000 -> 150000 | O42: =E42*10% -> 2585.41 | P42: 20000 | R42: =SUM(E42:Q42) -> 421515.37 | T42: =15000 -> 15000 | U42: =106666.67 -> 106666.67 | W42: 7709.76 | X42: =W42+T42+U42+V42 -> 129376.43 | Y42: 262624.63 | Z42: =R42-X42 -> 292138.94
A43: 7 | B43: YAHAYA SHAMSU | C43: AM LEGAL | D43: 13(11) | E43: =26339.3 -> 26339.3 | G43: =E43*300% -> 79017.9 | H43: =E43*7.5% -> 1975.4475 | J43: =E43*50% -> 13169.65 | K43: =E43*350% -> 92187.55 | L43: =E43*100% -> 26339.3 | M43: =150000 -> 150000 | O43: =E43*10% -> 2633.93 | P43: 15000 | R43: =SUM(E43:Q43) -> 406663.08 | V43: 0 | W43: 7709.76 | X43: =W43+U43+T43+V43 -> 7709.76 | Y43: 398953.32 | Z43: =R43-X43 -> 398953.32
A44: 8 | B44: OFORDEME ADAOBI JULIA | C44: RESEARCH FELLOW 11 | D44: 13(9) | E44: =24741.26 -> 24741.26 | G44: =E44*300% -> 74223.78 | H44: =E44*7.5% -> 1855.5945 | I44: 0 | J44: =E44*50% -> 12370.63 | K44: =E44*350% -> 86594.41 | L44: =E44*100% -> 24741.26 | M44: =150000 -> 150000 | O44: =E44*10% -> 2474.126 | P44: 15000 | Q44: 0 | R44: =SUM(E44:Q44) -> 392001.06 | W44: 7709.76 | X44: =W44+T44+U44+V44 -> 7709.76 | Y44: 376493.27 | Z44: =R44-X44 -> 384291.3
...

Sheet TAX DIFFERENCES
B3: STAFF PAYROLL FOR THE MONTH OF JANUARY, 2021
F4: ='[1]FEB 08'!E8/'[1]FEB 08'!M8 -> 0.22 | I4: ='[1]FEB 08'!F8/'[1]FEB 08'!Q8 -> 0.3
B5: STAFF NAME | S5: DEDUCTIONS | Y5: NET SALARY
D6: DESIGNATION | E6: SALARY | F6: BASIC | M6: MOTOR/ | N6: RESEARCH | O6: LEAVE | P6: OUT FIT | Q6: LEGISLATIVE | R6: GROSS | X6: DECEMBER,2020 | Y6: JANUARY,2021
E7: LEVEL | F7: SALARY | G7: SALARY/ALLOWCE AREARS | H7: RENT | I7: UTILITY | J7: DOMESTIC | K7: ENTERT. | L7: FURNIT. | M7: FUEL | N7: ALLOWANCE | O7: ALLCE | P7: ALLCE | Q7: DUTY ALLCE | R7: SALARY | S7: COOP SOCIETY | T7: COOP. LOAN RECOVERY | U7: NHF DEDUCTION | V7: PAYE | W7: TOTAL | Z7: DEC. 2020 PAYE | AA7: DIFFERENCE
A8: S/N | B8: DG OFFICE | F8: N | I8: N | R8: N | V8: N
A9: 1 | B9: PROF. ABUBAKAR O. SULAIMAN | D9: DIRECTOR GENERAL | E9: CONSOL | F9: 160488.75 | H9: 320977.5 | I9: 48146.63 | J9: 120366.57 | K9: 72219.94 | L9: 0 | M9: 120366.57 | N9: =200000 -> 200000 | O9: 16048.88 | P9: 25000 | Q9: 25235 | R9: =SUM(F9:Q9) -> 1108849.8 | V9: 113176.97 | W9: =S9+T9+U9+V9 -> 113176.97 | X9: 995672.87 | Y9: =R9-W9 -> 995672.87 | Z9: 113176.97 | AA9: =V9-Z9 -> 0
A10: 2 | B10: AKINSANMI ADEJOKE OLUKEMI | D10: AM INFORMATION | E10: 15(9) | F10: 33507.5 | H10: =F10*300% -> 100522.5 | I10: =F10*7.5% -> 2513.0625 | J10: 40122.19 | K10: =F10*50% -> 16753.75 | L10: =F10*350% -> 117276.25 | M10: =F10*100% -> 33507.5 | N10: =100000 -> 100000 | O10: =F10*10% -> 3350.75 | P10: 20000 | Q10: =100000 -> 100000 | R10: =SUM(F10:Q10) -> 567553.5 | S10: =0 -> 0 | T10: 0 | U10: ='[3]DECEMBER 2019'!$H$29 -> 837.6875 | V10: 15548.33 | W10: =S10+T10+U10+V10 -> 16386.018 | X10: 551167.48 | Y10: =R10-W10 -> 551167.48 | Z10: 15548.33 | AA10: =V10-Z10 -> 0
A11: 3 | B11: DR IKEME ARTHUR J.O | D11: SNR RESEARCH FELLOW | E11: 15(9) | F11: =33507.5 -> 33507.5 | H11: =F11*300% -> 100522.5 | I11: =F11*7.5% -> 2513.0625 | J11: 40122.19 | K11: =F11*50% -> 16753.75 | L11: =F11*350% -> 117276.25 | M11: =F11*100% -> 33507.5 | N11: =100000 -> 100000 | O11: =F11*10% -> 3350.75 | P11: 20000 | Q11: 0 | R11: =SUM(F11:Q11) -> 467553.5 | S11: 50000 | T11: =212642 -> 212642 | U11: ='[3]DECEMBER 2019'!$H$38 -> 837.6875 | V11: 15548.33 | W11: =SUM(S11:V11) -> 279028.02 | X11: 188525.48 | Y11: =R11-W11 -> 188525.48 | Z11: 15548.33 | AA11: =V11-Z11 -> 0
A12: 4 | B12: MOSHOOD M. OLALERE | D12: MANAGER ADMIN DG's OFFICE | E12: 15(9) | F12: =33507.5 -> 33507.5 | H12: =F12*300% -> 100522.5 | I12: =F12*7.5% -> 2513.0625 | J12: 40122.19 | K12: =F12*50% -> 16753.75 | L12: =F12*350% -> 117276.25 | M12: =F12*100% -> 33507.5 | N12: =100000 -> 100000 | O12: =F12*10% -> 3350.75 | P12: 20000 | Q12: 0 | R12: =SUM(F12:Q12) -> 467553.5 | S12: =5000 -> 5000 | T12: =179017.51 -> 179017.51 | U12: ='[3]DECEMBER 2019'!$H$35 -> 837.6875 | V12: 15548.33 | W12: =S12+T12+U12+V12 -> 200403.53 | X12: 267149.97 | Y12: =R12-W12 -> 267149.97 | Z12: 15548.33 | AA12: =V12-Z12 -> 0
A13: 5 | B13: SARAFADEEN ALABELEWE | D13: SA ADMINISTRATION | E13: 16(9) | F13: =42653.17 -> 42653.17 | H13: =F13*300% -> 127959.51 | I13: =F13*7.5% -> 3198.9877 | J13: 40122.19 | K13: =F13*50% -> 21326.585 | L13: =F13*350% -> 149286.1 | M13: =F13*100% -> 42653.17 | N13: =100000 -> 100000 | O13: =F13*10% -> 4265.317 | P13: 20000 | R13: =SUM(F13:Q13) -> 551465.02 | S13: =100000 -> 100000 | T13: =137500 -> 137500 | V13: 21618.09 | W13: =S13+T13+U13+V13 -> 259118.09 | X13: 278625.91 | Y13: =R13-W13 -> 292346.93 | Z13: 21618.09 | AA13: =V13-Z13 -> 0
A14: 6 | B14: DR ABDULSALAM NASIRU NAEEM | D14: SA ACADEMICS | E14: 16(7) | F14: =39662.25 -> 39662.25 | H14: =F14*300% -> 118986.75 | I14: =F14*7.5% -> 2974.6687 | J14: 40122.19 | K14: =F14*50% -> 19831.125 | L14: =F14*350% -> 138817.88 | M14: =F14*100% -> 39662.25 | N14: =150000 -> 150000 | O14: =F14*10% -> 3966.225 | P14: 20000 | Q14: =100000 -> 100000 | R14: =SUM(F14:Q14) -> 674023.33 | V14: 21618.09 | W14: =S14+T14+U14+V14 -> 21618.09 | X14: 590588.72 | Y14: =R14-W14 -> 652405.24 | Z14: 15548.33 | AA14: =V14-Z14 -> 6069.76
A15: 7 | B15: TOKUNBO ALFRED ADULOJU | D15: AM LIAISON OFFICE | E15: 13(10) | F15: =25523.45 -> 25523.45 | H15: =F15*300% -> 76570.35 | I15: =F15*7.5% -> 1914.2587 | K15: =F15*50% -> 12761.725 | L15: =F15*350% -> 89332.075 | M15: =F15*100% -> 25523.45 | N15: =100000 -> 100000 | O15: =F15*10% -> 2552.345 | P15: 15000 | Q15: =100000 -> 100000 | R15: =SUM(F15:Q15) -> 449177.65 | S15: =100000 -> 100000 | T15: =0 -> 0 | U15: ='[3]DECEMBER 2019'!$H$22 -> 618.5315 | V15: 7709.76 | W15: =S15+T15+U15+V15 -> 108328.29 | X15: 333672.77 | Y15: =R15-W15 -> 340849.36 | Z15: 7709.76 | AA15: =V15-Z15 -> 0
A16: 8 | B16: HUSSEIN EGYE MUSA | D16: AM PROTOCOL | E16: 13(10) | F16: =25523.45 -> 25523.45 | H16: =F16*300% -> 76570.35 | I16: =F16*7.5% -> 1914.2587 | K16: =F16*50% -> 12761.725 | L16: =F16*350% -> 89332.075 | M16: =F16*100% -> 25523.45 | N16: =100000 -> 100000 | O16: =F16*10% -> 2552.345 | P16: 15000 | Q16: 50000 | R16: =SUM(F16:Q16) -> 399177.65 | S16: 10000 | T16: =103000 -> 103000 | U16: 0 | V16: 7709.76 | W16: =S16+T16+U16+V16 -> 120709.76 | X16: 271291.3 | Y16: =R16-W16 -> 278467.89 | Z16: 7709.76 | AA16: =V16-Z16 -> 0
A17: 9 | B17: DONALD E. MKPANAM | D17: AM ICT | E17: 13(11) | F17: 26339.3 | H17: =F17*300% -> 79017.9 | I17: =F17*7.5% -> 1975.4475 | K17: =F17*50% -> 13169.65 | L17: =F17*350% -> 92187.55 | M17: =F17*100% -> 26339.3 | N17: =100000 -> 100000 | O17: =F17*10% -> 2633.93 | P17: 15000 | Q17: 0 | R17: =SUM(F17:Q17) -> 356663.08 | U17: ='[3]DECEMBER 2019'!$H$31 -> 658.4825 | V17: 7709.76 | W17: =S17+T17+U17+V17 -> 8368.2425 | X17: 348294.83 | Y17: =R17-W17 -> 348294.83 | Z17: 7709.76 | AA17: =V17-Z17 -> 0
A18: 10 | B18: JOY HARUNA MAKERI | D18: AM TRAINING | E18: 13(10) | F18: =25523.45 -> 25523.45 | H18: =F18*300% -> 76570.35 | I18: =F18*7.5% -> 1914.2587 | K18: =F18*50% -> 12761.725 | L18: =F18*350% -> 89332.075 | M18: =F18*100% -> 25523.45 | N18: 150000 | O18: =F18*10% -> 2552.345 | P18: 15000 | Q18: =50000+100000 -> 150000 | R18: =SUM(F18:Q18) -> 549177.65 | V18: 7709.76 | W18: =SUM(S18:V18) -> 7709.76 | X18: 534291.3 | Y18: =R18-W18 -> 541467.89 | Z18: 7709.76 | AA18: =V18-Z18 -> 0
A19: 11 | B19: ALI ABDULLAHI | D19: AM ICT | E19: 13(11) | F19: =26339.3 -> 26339.3 | G19: 0 | H19: =F19*300% -> 79017.9 | I19: =F19*7.5% -> 1975.4475 | J19: 0 | K19: =F19*50% -> 13169.65 | L19: =F19*350% -> 92187.55 | M19: =F19*100% -> 26339.3 | N19: =100000 -> 100000 | O19: =F19*10% -> 2633.93 | P19: 15000 | Q19: =0 -> 0 | R19: =SUM(F19:Q19) -> 356663.08 | V19: 7709.76 | W19: =S19+T19+U19+V19 -> 7709.76 | X19: 348953.32 | Y19: =R19-W19 -> 348953.32 | Z19: 7709.76 | AA19: =V19-Z19 -> 0
A20: 12 | B20: ADUGBA RICHARD TERSEER | D20: INFORMATION OFFICER | E20: 10(9) | F20: =18281.64 -> 18281.64 | H20: =F20*300% -> 54844.92 | I20: =F20*7.5% -> 1371.123 | K20: =F20*50% -> 9140.82 | L20: =F20*350% -> 63985.74 | M20: =F20*100% -> 18281.64 | N20: =100000 -> 100000 | O20: =F20*10% -> 1828.164 | P20: 10000 | R20: =SUM(F20:Q20) -> 277734.05 | S20: =50000 -> 50000 | T20: =111833.33 -> 111833.33 | V20: 3369.51 | W20: =S20+T20+U20+V20 -> 165202.84 | X20: 107965.36 | Y20: =R20-W20 -> 112531.21 | Z20: 3369.51 | AA20: =V20-Z20 -> 0
A21: 13 | B21: CHRISTIAN MADUABUCHI ODO | D21: ICT OFFICER | E21: 10(11) | F21: =19276.95 -> 19276.95 | H21: =F21*300% -> 57830.85 | I21: =F21*7.5% -> 1445.7713 | K21: =F21*50% -> 9638.475 | L21: =F21*350% -> 67469.325 | M21: =F21*100% -> 19276.95 | N21: =100000 -> 100000 | O21: =F21*10% -> 1927.695 | P21: 10000 | R21: =SUM(F21:Q21) -> 286866.02 | S21: =20000 -> 20000 | T21: =82500 -> 82500 | U21: ='[3]DECEMBER 2019'!$H$51 -> 469.4825 | V21: 3369.51 | W21: =S21+T21+U21+V21 -> 106338.99 | X21: 175961.08 | Y21: =R21-W21 -> 180527.02 | Z21: 3369.51 | AA21: =V21-Z21 -> 0
A22: 14 | B22: VICTOR ASUKWO | D22: ICT OFFICER | E22: 8 (9) | F22: =13112.16 -> 13112.16 | H22: =F22*300% -> 39336.48 | I22: =F22*7.5% -> 983.412 | K22: =F22*50% -> 6556.08 | L22: =F22*350% -> 45892.56 | M22: =F22*100% -> 13112.16 | N22: =100000 -> 100000 | O22: =F22*10% -> 1311.216 | P22: 10000 | R22: =SUM(F22:Q22) -> 230304.07 | S22: =10000 -> 10000 | V22: 1484.37 | W22: =S22+T22+U22+V22 -> 11484.37 | X22: 215331.73 | Y22: =R22-W22 -> 218819.7 | Z22: 1484.37 | AA22: =V22-Z22 -> 0
A23: 15 | B23: SULEIMAN ABUBAKAR SODEEQ | E23: 8(7) | F23: =12351.94 -> 12351.94 | G23: =0 -> 0 | H23: =F23*300% -> 37055.82 | I23: =F23*7.5% -> 926.3955 | K23: =F23*50% -> 6175.97 | L23: =F23*350% -> 43231.79 | M23: =F23*100% -> 12351.94 | N23: =100000 -> 100000 | O23: =F23*10% -> 1235.194 | P23: 10000 | R23: =SUM(F23:Q23) -> 223329.05 | V23: 1235.19 | W23: =SUM(S23:V23) -> 1235.19 | X23: 222093.86 | Y23: =R23-W23 -> 222093.86 | Z23: 1235.19 | AA23: =V23-Z23 -> 0
A24: 16 | B24: YAKUB OLUWATOYIN USMAN | E24: 8(7) | F24: =12351.94 -> 12351.94 | G24: =0 -> 0 | H24: =F24*300% -> 37055.82 | I24: =F24*7.5% -> 926.3955 | K24: =F24*50% -> 6175.97 | L24: =F24*350% -> 43231.79 | M24: =F24*100% -> 12351.94 | N24: =100000 -> 100000 | O24: =F24*10% -> 1235.194 | P24: 10000 | R24: =SUM(F24:Q24) -> 223329.05 | S24: =10000 -> 10000 | V24: 1235.19 | W24: =SUM(S24:V24) -> 11235.19 | X24: 112093.86 | Y24: =R24-W24 -> 212093.86 | Z24: 1235.19 | AA24: =V24-Z24 -> 0
A25: 17 | B25: ANTHONY EDET | D25: ASST. MGR M&E | E25: 13(8) | F25: =23891.12 -> 23891.12 | H25: =F25*300% -> 71673.36 | I25: =F25*7.5% -> 1791.834 | J25: 0 | K25: =F25*50% -> 11945.56 | L25: =F25*350% -> 83618.92 | M25: =F25*100% -> 23891.12 | N25: =100000 -> 100000 | O25: =F25*10% -> 2389.112 | P25: 15000 | Q25: 0 | R25: =SUM(F25:Q25) -> 334201.03 | S25: 10000 | U25: ='[3]DECEMBER 2019'!$H$43 -> 494.3655 | V25: 7709.76 | W25: =SUM(S25:V25) -> 18204.126 | X25: 277568.26 | Y25: =R25-W25 -> 315996.9 | Z25: 3369.51 | AA25: =V25-Z25 -> 4340.25
A26: 18 | B26: EGUATU U. ONYEJELEM | D26: OFFICER M&E | E26: 10(9) | F26: =18281.64 -> 18281.64 | H26: =F26*300% -> 54844.92 | I26: =F26*7.5% -> 1371.123 | K26: =F26*50% -> 9140.82 | L26: =F26*350% -> 63985.74 | M26: =F26*100% -> 18281.64 | N26: =100000 -> 100000 | O26: =F26*10% -> 1828.164 | P26: 10000 | R26: =SUM(F26:Q26) -> 277734.05 | S26: =20000 -> 20000 | T26: =87500+43750 -> 131250 | V26: 3369.51 | W26: =SUM(S26:V26) -> 154619.51 | X26: 118548.69 | Y26: =R26-W26 -> 123114.54 | Z26: 3369.51 | AA26: =V26-Z26 -> 0
A27: 19 | B27: ODEH SUZIE | D27: ADMIN. OFFICER, LIASION OFFICE | E27: 10(8) | F27: =17784 -> 17784 | G27: =0 -> 0 | H27: =F27*300% -> 53352 | I27: =F27*7.5% -> 1333.8 | K27: =F27*50% -> 8892 | L27: =F27*350% -> 62244 | M27: =F27*100% -> 17784 | N27: 100000 | O27: =F27*10% -> 1778.4 | P27: 10000 | R27: =SUM(F27:Q27) -> 273168.2 | S27: =30000+20000 -> 50000 | U27: =0 -> 0 | V27: 3369.51 | W27: =S27+T27+U27+V27 -> 53369.51 | X27: 255232.57 | Y27: =R27-W27 -> 219798.69 | Z27: 3369.51 | AA27: =V27-Z27 -> 0
B28: TOTAL | D28: 19 | F28: =SUM(F9:F27) -> 607907.01 | G28: =SUM(G9:G27) -> 0 | H28: =SUM(H9:H27) -> 1663232.3 | I28: =SUM(I9:I27) -> 81702.999 | J28: =SUM(J9:J27) -> 320977.52 | K28: =SUM(K9:K27) -> 295929.07 | L28: =SUM(L9:L27) -> 1565963.9 | M28: =SUM(M9:M27) -> 567784.83 | ... U28: =SUM(U9:U27) -> 4753.9245 | V28: 266749.49 | W28: =SUM(W9:W27) -> 1664246.3 | X28: 6193029.4 | Y28: =SUM(Y9:Y27) -> 6410277.1 | Z28: 256339.48 | AA28: =V28-Z28 -> 10410.01
AA29: =V29-Z29 -> 0
B30: INTERNAL AUDIT | AA30: =V30-Z30 -> 0
A31: 1 | B31: NWOSU MATHEW EZE | D31: Ag. DIRECTOR INT. AUDIT | E31: 17(8) | F31: =79039.64 -> 79039.64 | H31: =F31*300% -> 237118.92 | I31: =F31*7.5% -> 5927.973 | J31: =80244.38 -> 80244.38 | K31: =F31*50% -> 39519.82 | L31: =F31*350% -> 276638.74 | M31: =F31*100% -> 79039.64 | N31: =100000 -> 100000 | O31: =F31*10% -> 7903.964 | P31: 20000 | Q31: 0 | R31: =SUM(F31:Q31) -> 925433.08 | S31: =100000 -> 100000 | T31: =287500 -> 287500 | U31: ='[3]DECEMBER 2019'!$H$26 -> 1028.9423 | V31: 52776.63 | W31: =S31+T31+U31+V31 -> 441305.57 | X31: 459351.89 | Y31: =R31-W31 -> 484127.5 | Z31: 52776.63 | AA31: =V31-Z31 -> 0
A32: 2 | B32: BASHIRU ABBA WALI | D32: OFF. INT. AUDIT | E32: 10(10) | F32: =18779.3 -> 18779.3 | H32: =F32*300% -> 56337.9 | I32: =F32*7.5% -> 1408.4475 | J32: 0 | K32: =F32*50% -> 9389.65 | L32: =F32*350% -> 65727.55 | M32: =F32*100% -> 18779.3 | N32: =100000 -> 100000 | O32: =F32*10% -> 1877.93 | P32: 10000 | Q32: 0 | R32: =0 -> 0 | S32: =0 -> 0 | T32: =0 -> 0 | V32: 0 | W32: =S32+T32+U32+V32 -> 0 | X32: 278930.57 | Y32: =R32-W32 -> 0 | Z32: 0 | AA32: =V32-Z32 -> 0
C33: TOTAL | D33: 2 | F33: =SUM(F31:F32) -> 97818.94 | G33: =SUM(G31:G32) -> 0 | H33: =SUM(H31:H32) -> 293456.82 | I33: =SUM(I31:I32) -> 7336.4205 | J33: =SUM(J31:J32) -> 80244.38 | K33: =SUM(K31:K32) -> 48909.47 | L33: =SUM(L31:L32) -> 342366.29 | M33: =SUM(M31:M32) -> 97818.94 | ... U33: =SUM(U31:U32) -> 1028.9423 | V33: 52776.63 | W33: =SUM(W31:W32) -> 441305.57 | X33: 738282.45 | Y33: =R33-W33 -> 484127.5 | Z33: 52776.63 | AA33: =V33-Z33 -> 0
AA34: =V34-Z34 -> 0
B35: LEG. SUPPORT SEVICES | AA35: =V35-Z35 -> 0
A36: 1 | B36: PROF. EDOBA BRIGHT OMOREGBE | D36: AG. DLSS | E36: 17(9) | F36: =81740.02 -> 81740.02 | H36: =F36*300% -> 245220.06 | I36: =F36*7.5% -> 6130.5015 | J36: 80244.38 | K36: =F36*50% -> 40870.01 | L36: =F36*350% -> 286090.07 | M36: =F36*100% -> 81740.02 | N36: =150000 -> 150000 | O36: =F36*10% -> 8174.002 | P36: 20000 | R36: =SUM(F36:Q36) -> 1000209.1 | S36: =100000+2000 -> 102000 | V36: 52776.63 | W36: =V36+S36+T36+U36 -> 154776.63 | X36: 922656.45 | Y36: =R36-W36 -> 845432.43 | Z36: 52776.63 | AA36: =V36-Z36 -> 0
A37: 2 | B37: DR CLINTON JAJA | D37: SENIOR RESEARCH FELLOW | E37: 15(9) | F37: =33507.5 -> 33507.5 | H37: =F37*300% -> 100522.5 | I37: =F37*7.5% -> 2513.0625 | J37: 40122.19 | K37: =F37*50% -> 16753.75 | L37: =F37*350% -> 117276.25 | M37: =F37*100% -> 33507.5 | N37: =150000 -> 150000 | O37: =F37*10% -> 3350.75 | P37: 20000 | Q37: 0 | R37: =SUM(F37:Q37) -> 517553.5 | S37: 50000 | T37: =240909.11 -> 240909.11 | V37: 15548.33 | W37: =SUM(S37:V37) -> 306457.44 | X37: 211096.06 | Y37: =R37-W37 -> 211096.06 | Z37: 15548.33 | AA37: =V37-Z37 -> 0
A38: 3 | B38: BETHEL UZOMA IHUGBA | D38: SNR RESEARCH FELLOW | E38: 15(9) | F38: =33507.5 -> 33507.5 | H38: =F38*300% -> 100522.5 | I38: =F38*7.5% -> 2513.0625 | J38: 40122.19 | K38: =F38*50% -> 16753.75 | L38: =F38*350% -> 117276.25 | M38: =F38*100% -> 33507.5 | N38: =150000 -> 150000 | O38: =F38*10% -> 3350.75 | P38: 20000 | R38: =SUM(F38:Q38) -> 517553.5 | S38: =30000+13000 -> 43000 | T38: =246905.96 -> 246905.96 | V38: 15548.33 | W38: =V38+S38+T38+U38 -> 305454.29 | X38: 200682.76 | Y38: =R38-W38 -> 212099.21 | Z38: 15548.33 | AA38: =V38-Z38 -> 0
A39: 4 | B39: OGUCHE SAMUEL | D39: RESEARCH FELLOW I | E39: 14(11) | F39: 28489.81 | H39: =F39*300% -> 85469.43 | I39: =F39*7.5% -> 2136.7357 | K39: =F39*50% -> 14244.905 | L39: =F39*350% -> 99714.335 | M39: =F39*100% -> 28489.81 | N39: =150000 -> 150000 | O39: =F39*10% -> 2848.981 | P39: 20000 | R39: =SUM(F39:Q39) -> 431394.01 | S39: =30000 -> 30000 | T39: =179165.6+26250 -> 205415.6 | V39: 7709.76 | W39: =SUM(S39:V39) -> 243125.36 | X39: 188268.65 | Y39: =R39-W39 -> 188268.65 | Z39: 7709.76 | AA39: =V39-Z39 -> 0
A40: 5 | B40: IBRAHIM USMAN | D40: RESEARCH FELLOW I | E40: 14(11) | F40: =28489.81 -> 28489.81 | H40: =F40*300% -> 85469.43 | I40: =F40*7.5% -> 2136.7357 | J40: 0 | K40: =F40*50% -> 14244.905 | L40: =F40*350% -> 99714.335 | M40: =F40*100% -> 28489.81 | N40: =150000 -> 150000 | O40: =F40*10% -> 2848.981 | P40: 20000 | Q40: 0 | R40: =SUM(F40:Q40) -> 431394.01 | U40: ='[3]DECEMBER 2019'!$H$27 -> 690.28075 | V40: 7709.76 | W40: =V40+S40+T40+U40 -> 8400.0408 | X40: 414932.99 | Y40: =R40-W40 -> 422993.97 | Z40: 7709.76 | AA40: =V40-Z40 -> 0
A41: 6 | B41: DR MOHAMMED O. AMALI | D41: RESEARCH FELLOW I | E41: 14(9) | F41: =27611.23 -> 27611.23 | H41: =F41*300% -> 82833.69 | I41: =F41*7.5% -> 2070.8422 | K41: =F41*50% -> 13805.615 | L41: =F41*350% -> 96639.305 | M41: =F41*100% -> 27611.23 | N41: =150000 -> 150000 | O41: =F41*10% -> 2761.123 | P41: 15000 | R41: =SUM(F41:Q41) -> 418333.04 | S41: =15000 -> 15000 | T41: =106666.67 -> 106666.67 | V41: 7709.76 | W41: =V41+S41+T41+U41 -> 129376.43 | X41: 262624.63 | Y41: =R41-W41 -> 288956.61 | Z41: 7709.76 | AA41: =V41-Z41 -> 0
A42: 7 | B42: YAHAYA SHAMSU | D42: AM LEGAL | E42: 13(11) | F42: =26339.3 -> 26339.3 | H42: =F42*300% -> 79017.9 | I42: =F42*7.5% -> 1975.4475 | K42: =F42*50% -> 13169.65 | L42: =F42*350% -> 92187.55 | M42: =F42*100% -> 26339.3 | N42: =150000 -> 150000 | O42: =F42*10% -> 2633.93 | P42: 15000 | R42: =SUM(F42:Q42) -> 406663.08 | U42: 0 | V42: 7709.76 | W42: =V42+T42+S42+U42 -> 7709.76 | X42: 398953.32 | Y42: =R42-W42 -> 398953.32 | Z42: 7709.76 | AA42: =V42-Z42 -> 0
...

Sheet ANNUAL INCREMENT
B3: STAFF PAYROLL FOR THE MONTH OF DECEMBER, 2020
F4: ='[1]FEB 08'!E8/'[1]FEB 08'!M8 -> 0.22 | I4: ='[1]FEB 08'!F8/'[1]FEB 08'!Q8 -> 0.3
B5: STAFF NAME | U5: DEDUCTIONS | AA5: NET SALARY
D6: DESIGNATION | E6: SALARY | F6: BASIC | M6: MOTOR/ | N6: RESEARCH | O6: LEAVE | P6: OUT FIT | Q6: LEGISLATIVE | R6: DECEMBER 2020 GROSS | S6: JANUARY 2021 GROSS | T6: ANNUAL INCREMENT/PROMOTION | Z6: NOVEMBER,2020 | AA6: DECEMBER,2020
E7: LEVEL | F7: SALARY | G7: SALARY/ALLOWCE AREARS | H7: RENT | I7: UTILITY | J7: DOMESTIC | K7: ENTERT. | L7: FURNIT. | M7: FUEL | N7: ALLOWANCE | O7: ALLCE | P7: ALLCE | Q7: DUTY ALLCE | R7: SALARY | S7: SALARY | U7: COOP SOCIETY | V7: COOP. LOAN RECOVERY | W7: NHF DEDUCTION | X7: PAYE | Y7: TOTAL
A8: S/N | B8: DG OFFICE | F8: N | I8: N | R8: N | S8: N | X8: N
A9: 1 | B9: PROF. ABUBAKAR O. SULAIMAN | D9: DIRECTOR GENERAL | E9: CONSOL | F9: 160488.75 | H9: 320977.5 | I9: 48146.63 | J9: 120366.57 | K9: 72219.94 | L9: 0 | M9: 120366.57 | N9: =200000 -> 200000 | O9: 16048.88 | P9: 25000 | Q9: 25235 | R9: =SUM(F9:Q9) -> 1108849.8 | S9: 1108849.8 | T9: =S9-R9 -> 0 | X9: 113176.97 | Y9: =U9+V9+W9+X9 -> 113176.97 | Z9: 995672.87 | AA9: =R9-Y9 -> 995672.87
A10: 2 | B10: AKINSANMI ADEJOKE OLUKEMI | D10: AM INFORMATION | E10: 15(9) | F10: 33507.5 | H10: =F10*300% -> 100522.5 | I10: =F10*7.5% -> 2513.0625 | J10: 40122.19 | K10: =F10*50% -> 16753.75 | L10: =F10*350% -> 117276.25 | M10: =F10*100% -> 33507.5 | N10: =100000 -> 100000 | O10: =F10*10% -> 3350.75 | P10: 20000 | Q10: =100000 -> 100000 | R10: =SUM(F10:Q10) -> 567553.5 | S10: 567553.5 | T10: =S10-R10 -> 0 | U10: =0 -> 0 | V10: 0 | W10: ='[3]DECEMBER 2019'!$H$29 -> 837.6875 | X10: 15548.33 | Y10: =U10+V10+W10+X10 -> 16386.018 | Z10: 551167.48 | AA10: =R10-Y10 -> 551167.48
A11: 3 | B11: DR IKEME ARTHUR J.O | D11: SNR RESEARCH FELLOW | E11: 15(9) | F11: =33507.5 -> 33507.5 | H11: =F11*300% -> 100522.5 | I11: =F11*7.5% -> 2513.0625 | J11: 40122.19 | K11: =F11*50% -> 16753.75 | L11: =F11*350% -> 117276.25 | M11: =F11*100% -> 33507.5 | N11: =100000 -> 100000 | O11: =F11*10% -> 3350.75 | P11: 20000 | Q11: 0 | R11: =SUM(F11:Q11) -> 467553.5 | S11: 467553.5 | T11: =S11-R11 -> 0 | U11: 50000 | V11: =212642 -> 212642 | W11: ='[3]DECEMBER 2019'!$H$38 -> 837.6875 | X11: 15548.33 | Y11: =SUM(U11:X11) -> 279028.02 | Z11: 188525.48 | AA11: =R11-Y11 -> 188525.48
A12: 4 | B12: MOSHOOD M. OLALERE | D12: MANAGER ADMIN DG's OFFICE | E12: 15(9) | F12: =33507.5 -> 33507.5 | H12: =F12*300% -> 100522.5 | I12: =F12*7.5% -> 2513.0625 | J12: 40122.19 | K12: =F12*50% -> 16753.75 | L12: =F12*350% -> 117276.25 | M12: =F12*100% -> 33507.5 | N12: =100000 -> 100000 | O12: =F12*10% -> 3350.75 | P12: 20000 | Q12: 0 | R12: =SUM(F12:Q12) -> 467553.5 | S12: 467553.5 | T12: =S12-R12 -> 0 | U12: =5000 -> 5000 | V12: =179017.51 -> 179017.51 | W12: ='[3]DECEMBER 2019'!$H$35 -> 837.6875 | X12: 15548.33 | Y12: =U12+V12+W12+X12 -> 200403.53 | Z12: 267149.97 | AA12: =R12-Y12 -> 267149.97
A13: 5 | B13: SARAFADEEN ALABELEWE | D13: SA ADMINISTRATION | E13: 16(8) | F13: =41157.69 -> 41157.69 | H13: =F13*300% -> 123473.07 | I13: =F13*7.5% -> 3086.8268 | J13: 40122.19 | K13: =F13*50% -> 20578.845 | L13: =F13*350% -> 144051.92 | M13: =F13*100% -> 41157.69 | N13: =100000 -> 100000 | O13: =F13*10% -> 4115.769 | P13: 20000 | R13: =SUM(F13:Q13) -> 537744 | S13: 551465.02 | T13: =S13-R13 -> 13721.029 | U13: =100000 -> 100000 | V13: =137500 -> 137500 | X13: 21618.09 | Y13: =U13+V13+W13+X13 -> 259118.09 | Z13: 278625.91 | AA13: =R13-Y13 -> 278625.91
A14: 6 | B14: DR ABDULSALAM NASIRU NAEEM | D14: SA ACADEMICS | E14: 15(8) | F14: =32263.2 -> 32263.2 | H14: =F14*300% -> 96789.6 | I14: =F14*7.5% -> 2419.74 | J14: 40122.19 | K14: =F14*50% -> 16131.6 | L14: =F14*350% -> 112921.2 | M14: =F14*100% -> 32263.2 | N14: =150000 -> 150000 | O14: =F14*10% -> 3226.32 | P14: 20000 | Q14: =100000 -> 100000 | R14: =SUM(F14:Q14) -> 606137.05 | S14: 674023.33 | T14: =S14-R14 -> 67886.284 | X14: 15548.33 | Y14: =U14+V14+W14+X14 -> 15548.33 | Z14: 590588.72 | AA14: =R14-Y14 -> 590588.72
A15: 7 | B15: TOKUNBO ALFRED ADULOJU | D15: AM LIAISON OFFICE | E15: 13(9) | F15: =24741.26 -> 24741.26 | H15: =F15*300% -> 74223.78 | I15: =F15*7.5% -> 1855.5945 | K15: =F15*50% -> 12370.63 | L15: =F15*350% -> 86594.41 | M15: =F15*100% -> 24741.26 | N15: =100000 -> 100000 | O15: =F15*10% -> 2474.126 | P15: 15000 | Q15: =100000 -> 100000 | R15: =SUM(F15:Q15) -> 442001.06 | S15: 449177.65 | T15: =S15-R15 -> 7176.5933 | U15: =100000 -> 100000 | V15: =0 -> 0 | W15: ='[3]DECEMBER 2019'!$H$22 -> 618.5315 | X15: 7709.76 | Y15: =U15+V15+W15+X15 -> 108328.29 | Z15: 264922.77 | AA15: =R15-Y15 -> 333672.77
A16: 8 | B16: HUSSEIN EGYE MUSA | D16: AM PROTOCOL | E16: 13(9) | F16: =24741.26 -> 24741.26 | H16: =F16*300% -> 74223.78 | I16: =F16*7.5% -> 1855.5945 | K16: =F16*50% -> 12370.63 | L16: =F16*350% -> 86594.41 | M16: =F16*100% -> 24741.26 | N16: =100000 -> 100000 | O16: =F16*10% -> 2474.126 | P16: 15000 | Q16: 50000 | R16: =SUM(F16:Q16) -> 392001.06 | S16: 399177.65 | T16: =S16-R16 -> 7176.5933 | U16: 10000 | V16: =103000 -> 103000 | W16: 0 | X16: 7709.76 | Y16: =U16+V16+W16+X16 -> 120709.76 | Z16: 271291.3 | AA16: =R16-Y16 -> 271291.3
A17: 9 | B17: DONALD E. MKPANAM | D17: AM ICT | E17: 13(11) | F17: 26339.3 | H17: =F17*300% -> 79017.9 | I17: =F17*7.5% -> 1975.4475 | K17: =F17*50% -> 13169.65 | L17: =F17*350% -> 92187.55 | M17: =F17*100% -> 26339.3 | N17: =100000 -> 100000 | O17: =F17*10% -> 2633.93 | P17: 15000 | Q17: 0 | R17: =SUM(F17:Q17) -> 356663.08 | S17: 356663.08 | T17: =S17-R17 -> 0 | W17: ='[3]DECEMBER 2019'!$H$31 -> 658.4825 | X17: 7709.76 | Y17: =U17+V17+W17+X17 -> 8368.2425 | Z17: 348294.83 | AA17: =R17-Y17 -> 348294.83
A18: 10 | B18: JOY HARUNA MAKERI | D18: AM TRAINING | E18: 13(9) | F18: =24741.26 -> 24741.26 | H18: =F18*300% -> 74223.78 | I18: =F18*7.5% -> 1855.5945 | K18: =F18*50% -> 12370.63 | L18: =F18*350% -> 86594.41 | M18: =F18*100% -> 24741.26 | N18: 150000 | O18: =F18*10% -> 2474.126 | P18: 15000 | Q18: =50000+100000 -> 150000 | R18: =SUM(F18:Q18) -> 542001.06 | S18: 549177.65 | T18: =S18-R18 -> 7176.5933 | X18: =7709.76 -> 7709.76 | Y18: =SUM(U18:X18) -> 7709.76 | Z18: 534291.3 | AA18: =R18-Y18 -> 534291.3
A19: 11 | B19: ALI ABDULLAHI | D19: AM ICT | E19: 13(11) | F19: =26339.3 -> 26339.3 | G19: 0 | H19: =F19*300% -> 79017.9 | I19: =F19*7.5% -> 1975.4475 | J19: 0 | K19: =F19*50% -> 13169.65 | L19: =F19*350% -> 92187.55 | M19: =F19*100% -> 26339.3 | N19: =100000 -> 100000 | O19: =F19*10% -> 2633.93 | P19: 15000 | Q19: =0 -> 0 | R19: =SUM(F19:Q19) -> 356663.08 | S19: 356663.08 | T19: =S19-R19 -> 0 | X19: =7709.76 -> 7709.76 | Y19: =U19+V19+W19+X19 -> 7709.76 | Z19: 348953.32 | AA19: =R19-Y19 -> 348953.32
A20: 12 | B20: ADUGBA RICHARD TERSEER | D20: INFORMATION OFFICER | E20: 10(8) | F20: =17784 -> 17784 | H20: =F20*300% -> 53352 | I20: =F20*7.5% -> 1333.8 | K20: =F20*50% -> 8892 | L20: =F20*350% -> 62244 | M20: =F20*100% -> 17784 | N20: =100000 -> 100000 | O20: =F20*10% -> 1778.4 | P20: 10000 | R20: =SUM(F20:Q20) -> 273168.2 | S20: 277734.05 | T20: =S20-R20 -> 4565.847 | U20: =50000 -> 50000 | V20: =111833.33 -> 111833.33 | X20: 3369.51 | Y20: =U20+V20+W20+X20 -> 165202.84 | Z20: 107965.36 | AA20: =R20-Y20 -> 107965.36
A21: 13 | B21: CHRISTIAN MADUABUCHI ODO | D21: ICT OFFICER | E21: 10(10) | F21: =18779.3 -> 18779.3 | H21: =F21*300% -> 56337.9 | I21: =F21*7.5% -> 1408.4475 | K21: =F21*50% -> 9389.65 | L21: =F21*350% -> 65727.55 | M21: =F21*100% -> 18779.3 | N21: =100000 -> 100000 | O21: =F21*10% -> 1877.93 | P21: 10000 | R21: =SUM(F21:Q21) -> 282300.08 | S21: 286866.02 | T21: =S21-R21 -> 4565.9388 | U21: =20000 -> 20000 | V21: =82500 -> 82500 | W21: ='[3]DECEMBER 2019'!$H$51 -> 469.4825 | X21: 3369.51 | Y21: =U21+V21+W21+X21 -> 106338.99 | Z21: 175961.08 | AA21: =R21-Y21 -> 175961.08
A22: 14 | B22: VICTOR ASUKWO | D22: ICT OFFICER | E22: 8 (8) | F22: =12732 -> 12732 | H22: =F22*300% -> 38196 | I22: =F22*7.5% -> 954.9 | K22: =F22*50% -> 6366 | L22: =F22*350% -> 44562 | M22: =F22*100% -> 12732 | N22: =100000 -> 100000 | O22: =F22*10% -> 1273.2 | P22: 10000 | R22: =SUM(F22:Q22) -> 226816.1 | S22: 230304.07 | T22: =S22-R22 -> 3487.968 | U22: =10000 -> 10000 | X22: 1484.37 | Y22: =U22+V22+W22+X22 -> 11484.37 | Z22: 215331.73 | AA22: =R22-Y22 -> 215331.73
A23: 15 | B23: SULEIMAN ABUBAKAR SODEEQ | E23: 8(7) | F23: =12351.94 -> 12351.94 | G23: =0 -> 0 | H23: =F23*300% -> 37055.82 | I23: =F23*7.5% -> 926.3955 | K23: =F23*50% -> 6175.97 | L23: =F23*350% -> 43231.79 | M23: =F23*100% -> 12351.94 | N23: =100000 -> 100000 | O23: =F23*10% -> 1235.194 | P23: 10000 | R23: =SUM(F23:Q23) -> 223329.05 | S23: 223329.05 | T23: =S23-R23 -> 0 | X23: =1235.19 -> 1235.19 | Y23: =SUM(U23:X23) -> 1235.19 | Z23: 222093.86 | AA23: =R23-Y23 -> 222093.86
A24: 16 | B24: YAKUB OLUWATOYIN USMAN | E24: 8(7) | F24: =12351.94 -> 12351.94 | G24: =0 -> 0 | H24: =F24*300% -> 37055.82 | I24: =F24*7.5% -> 926.3955 | K24: =F24*50% -> 6175.97 | L24: =F24*350% -> 43231.79 | M24: =F24*100% -> 12351.94 | N24: =100000 -> 100000 | O24: =F24*10% -> 1235.194 | P24: 10000 | R24: =SUM(F24:Q24) -> 223329.05 | S24: 223329.05 | T24: =S24-R24 -> 0 | U24: =10000 -> 10000 | V24: =100000 -> 100000 | X24: =1235.19 -> 1235.19 | Y24: =SUM(U24:X24) -> 111235.19 | Z24: 10093.859 | AA24: =R24-Y24 -> 112093.86
A25: 17 | B25: ANTHONY EDET | D25: OFFICER M&E | E25: 10(12) | F25: =19774.62 -> 19774.62 | H25: =F25*300% -> 59323.86 | I25: =F25*7.5% -> 1483.0965 | J25: 0 | K25: =F25*50% -> 9887.31 | L25: =F25*350% -> 69211.17 | M25: =F25*100% -> 19774.62 | N25: =100000 -> 100000 | O25: =F25*10% -> 1977.462 | P25: 10000 | Q25: 0 | R25: =SUM(F25:Q25) -> 291432.14 | S25: 334201.03 | T25: =S25-R25 -> 42768.888 | U25: 10000 | W25: ='[3]DECEMBER 2019'!$H$43 -> 494.3655 | X25: 3369.51 | Y25: =SUM(U25:X25) -> 13863.876 | Z25: 277568.26 | AA25: =R25-Y25 -> 277568.26
A26: 18 | B26: EGUATU U. ONYEJELEM | D26: OFFICER M&E | E26: 10(8) | F26: =17784 -> 17784 | H26: =F26*300% -> 53352 | I26: =F26*7.5% -> 1333.8 | K26: =F26*50% -> 8892 | L26: =F26*350% -> 62244 | M26: =F26*100% -> 17784 | N26: =100000 -> 100000 | O26: =F26*10% -> 1778.4 | P26: 10000 | R26: =SUM(F26:Q26) -> 273168.2 | S26: 277734.05 | T26: =S26-R26 -> 4565.847 | U26: =20000 -> 20000 | V26: =87500+43750 -> 131250 | X26: 3369.51 | Y26: =SUM(U26:X26) -> 154619.51 | Z26: 118548.69 | AA26: =R26-Y26 -> 118548.69
A27: 19 | B27: ODEH SUZIE | D27: ADMIN. OFFICER, LIASION OFFICE | E27: 10(7) | F27: 17286.33 | G27: 0 | H27: 51858.99 | I27: 1296.4748 | K27: 8643.165 | L27: 60502.155 | M27: 17286.33 | N27: 100000 | O27: 1728.633 | P27: 10000 | R27: 268602.08 | S27: 273168.2 | T27: =S27-R27 -> 4566.1222 | U27: 10000 | W27: =0 -> 0 | X27: 3369.51 | Y27: =U27+V27+W27+X27 -> 13369.51 | Z27: 255232.57 | AA27: =R27-Y27 -> 255232.57
B28: TOTAL | D28: 19 | F28: =SUM(F9:F27) -> 590178.65 | G28: =SUM(G9:G27) -> 0 | H28: =SUM(H9:H27) -> 1610047.2 | I28: =SUM(I9:I27) -> 80373.372 | J28: =SUM(J9:J27) -> 320977.52 | K28: =SUM(K9:K27) -> 287064.89 | L28: =SUM(L9:L27) -> 1503914.7 | M28: =SUM(M9:M27) -> 550056.47 | ... R28: =SUM(R9:R27) -> 7906865.6 | S28: 8074523.3 | T28: =SUM(T9:T27) -> 167657.7 | U28: =SUM(U9:U27) -> 395000 | V28: =SUM(V9:V27) -> 1057742.8 | W28: =SUM(W9:W27) -> 4753.9245 | X28: =SUM(X9:X27) -> 256339.48 | Y28: =SUM(Y9:Y27) -> 1713836.2 | Z28: 6022279.4 | AA28: =SUM(AA9:AA27) -> 6193029.4
B30: INTERNAL AUDIT
A31: 1 | B31: NWOSU MATHEW EZE | D31: Ag. DIRECTOR INT. AUDIT | E31: 17(7) | F31: =76339.3 -> 76339.3 | H31: =F31*300% -> 229017.9 | I31: =F31*7.5% -> 5725.4475 | J31: =80244.38 -> 80244.38 | K31: =F31*50% -> 38169.65 | L31: =F31*350% -> 267187.55 | M31: =F31*100% -> 76339.3 | N31: =100000 -> 100000 | O31: =F31*10% -> 7633.93 | P31: 20000 | Q31: 0 | R31: =SUM(F31:Q31) -> 900657.46 | S31: 925433.08 | T31: =S31-R31 -> 24775.619 | U31: =100000 -> 100000 | V31: =287500 -> 287500 | W31: ='[3]DECEMBER 2019'!$H$26 -> 1028.9423 | X31: =52776.63 -> 52776.63 | Y31: =U31+V31+W31+X31 -> 441305.57 | Z31: 459351.89 | AA31: =R31-Y31 -> 459351.89
A32: 2 | B32: BASHIRU ABBA WALI | D32: OFF. INT. AUDIT | E32: 10(10) | F32: =18779.3 -> 18779.3 | H32: =F32*300% -> 56337.9 | I32: =F32*7.5% -> 1408.4475 | J32: 0 | K32: =F32*50% -> 9389.65 | L32: =F32*350% -> 65727.55 | M32: =F32*100% -> 18779.3 | N32: =100000 -> 100000 | O32: =F32*10% -> 1877.93 | P32: 10000 | Q32: 0 | R32: =SUM(F32:Q32) -> 282300.08 | S32: 0 | U32: =0 -> 0 | V32: =0 -> 0 | X32: =3369.51 -> 3369.51 | Y32: =U32+V32+W32+X32 -> 3369.51 | Z32: 245930.57 | AA32: =R32-Y32 -> 278930.57
C33: TOTAL | D33: 2 | F33: =SUM(F31:F32) -> 95118.6 | G33: =SUM(G31:G32) -> 0 | H33: =SUM(H31:H32) -> 285355.8 | I33: =SUM(I31:I32) -> 7133.895 | J33: =SUM(J31:J32) -> 80244.38 | K33: =SUM(K31:K32) -> 47559.3 | L33: =SUM(L31:L32) -> 332915.1 | M33: =SUM(M31:M32) -> 95118.6 | ... R33: =SUM(R31:R32) -> 1182957.5 | S33: 925433.08 | T33: =SUM(T31:T32) -> 24775.619 | U33: =SUM(U31:U32) -> 100000 | V33: =SUM(V31:V32) -> 287500 | W33: =SUM(W31:W32) -> 1028.9423 | X33: =SUM(X31:X32) -> 56146.14 | Y33: =SUM(Y31:Y32) -> 444675.08 | Z33: 705282.45 | AA33: =R33-Y33 -> 738282.45
B35: LEG. SUPPORT SEVICES
A36: 1 | B36: PROF. EDOBA BRIGHT OMOREGBE | D36: AG. DLSS | E36: 17(8) | F36: =79039.64 -> 79039.64 | H36: =F36*300% -> 237118.92 | I36: =F36*7.5% -> 5927.973 | J36: 80244.38 | K36: =F36*50% -> 39519.82 | L36: =F36*350% -> 276638.74 | M36: =F36*100% -> 79039.64 | N36: =150000 -> 150000 | O36: =F36*10% -> 7903.964 | P36: 20000 | R36: =SUM(F36:Q36) -> 975433.08 | S36: 1000209.1 | T36: =S36-R36 -> 24775.986 | U36: 0 | X36: =52776.63 -> 52776.63 | Y36: =X36+U36+V36+W36 -> 52776.63 | Z36: 922656.45 | AA36: =R36-Y36 -> 922656.45
A37: 2 | B37: DR CLINTON JAJA | D37: SENIOR RESEARCH FELLOW | E37: 15(9) | F37: =33507.5 -> 33507.5 | H37: =F37*300% -> 100522.5 | I37: =F37*7.5% -> 2513.0625 | J37: 40122.19 | K37: =F37*50% -> 16753.75 | L37: =F37*350% -> 117276.25 | M37: =F37*100% -> 33507.5 | N37: =150000 -> 150000 | O37: =F37*10% -> 3350.75 | P37: 20000 | Q37: 0 | R37: =SUM(F37:Q37) -> 517553.5 | S37: 517553.5 | T37: =S37-R37 -> 0 | U37: 50000 | V37: =240909.11 -> 240909.11 | X37: 15548.33 | Y37: =SUM(U37:X37) -> 306457.44 | Z37: 211096.06 | AA37: =R37-Y37 -> 211096.06
A38: 3 | B38: BETHEL UZOMA IHUGBA | D38: SNR RESEARCH FELLOW | E38: 15(8) | F38: =32263.2 -> 32263.2 | H38: =F38*300% -> 96789.6 | I38: =F38*7.5% -> 2419.74 | J38: 40122.19 | K38: =F38*50% -> 16131.6 | L38: =F38*350% -> 112921.2 | M38: =F38*100% -> 32263.2 | N38: =150000 -> 150000 | O38: =F38*10% -> 3226.32 | P38: 20000 | R38: =SUM(F38:Q38) -> 506137.05 | S38: 517553.5 | T38: =S38-R38 -> 11416.452 | U38: =30000+13000 -> 43000 | V38: =246905.96 -> 246905.96 | X38: 15548.33 | Y38: =X38+U38+V38+W38 -> 305454.29 | Z38: 200682.76 | AA38: =R38-Y38 -> 200682.76
A39: 4 | B39: OGUCHE SAMUEL | D39: RESEARCH FELLOW I | E39: 14(11) | F39: 28489.81 | H39: =F39*300% -> 85469.43 | I39: =F39*7.5% -> 2136.7357 | K39: =F39*50% -> 14244.905 | L39: =F39*350% -> 99714.335 | M39: =F39*100% -> 28489.81 | N39: =150000 -> 150000 | O39: =F39*10% -> 2848.981 | P39: 20000 | R39: =SUM(F39:Q39) -> 431394.01 | S39: 431394.01 | T39: =S39-R39 -> 0 | U39: =30000 -> 30000 | V39: =179165.6+26250 -> 205415.6 | X39: 7709.76 | Y39: =SUM(U39:X39) -> 243125.36 | Z39: 188268.65 | AA39: =R39-Y39 -> 188268.65
A40: 5 | B40: IBRAHIM USMAN | D40: RESEARCH FELLOW I | E40: 14(10) | F40: =27611.23 -> 27611.23 | H40: =F40*300% -> 82833.69 | I40: =F40*7.5% -> 2070.8422 | J40: 0 | K40: =F40*50% -> 13805.615 | L40: =F40*350% -> 96639.305 | M40: =F40*100% -> 27611.23 | N40: =150000 -> 150000 | O40: =F40*10% -> 2761.123 | P40: 20000 | Q40: 0 | R40: =SUM(F40:Q40) -> 423333.04 | S40: 431394.01 | T40: =S40-R40 -> 8060.9715 | W40: ='[3]DECEMBER 2019'!$H$27 -> 690.28075 | X40: 7709.76 | Y40: =X40+U40+V40+W40 -> 8400.0408 | Z40: 414932.99 | AA40: =R40-Y40 -> 414932.99
A41: 6 | B41: DR MOHAMMED O. AMALI | D41: RESEARCH FELLOW II | E41: 13(9) | F41: =24741.26 -> 24741.26 | H41: =F41*300% -> 74223.78 | I41: =F41*7.5% -> 1855.5945 | K41: =F41*50% -> 12370.63 | L41: =F41*350% -> 86594.41 | M41: =F41*100% -> 24741.26 | N41: =150000 -> 150000 | O41: =F41*10% -> 2474.126 | P41: 15000 | R41: =SUM(F41:Q41) -> 392001.06 | S41: 407211.37 | T41: =S41-R41 -> 15210.307 | U41: =15000 -> 15000 | V41: =106666.67 -> 106666.67 | X41: 7709.76 | Y41: =X41+U41+V41+W41 -> 129376.43 | Z41: 369291.3 | AA41: =R41-Y41 -> 262624.63
A42: 7 | B42: YAHAYA SHAMSU | D42: AM LEGAL | E42: 13(11) | F42: =26339.3 -> 26339.3 | H42: =F42*300% -> 79017.9 | I42: =F42*7.5% -> 1975.4475 | K42: =F42*50% -> 13169.65 | L42: =F42*350% -> 92187.55 | M42: =F42*100% -> 26339.3 | N42: =150000 -> 150000 | O42: =F42*10% -> 2633.93 | P42: 15000 | R42: =SUM(F42:Q42) -> 406663.08 | S42: 406663.08 | T42: =S42-R42 -> 0 | W42: 0 | X42: 7709.76 | Y42: =X42+V42+U42+W42 -> 7709.76 | Z42: 398953.32 | AA42: =R42-Y42 -> 398953.32
A43: 8 | B43: OFORDEME ADAOBI JULIA | D43: RESEARCH FELLOW 11 | E43: 13(8) | F43: 23891.12 | H43: =F43*300% -> 71673.36 | I43: =F43*7.5% -> 1791.834 | J43: 0 | K43: =F43*50% -> 11945.56 | L43: =F43*350% -> 83618.92 | M43: =F43*100% -> 23891.12 | N43: =150000 -> 150000 | O43: =F43*10% -> 2389.112 | P43: 15000 | Q43: 0 | R43: =SUM(F43:Q43) -> 384201.03 | S43: 392001.06 | T43: =S43-R43 -> 7800.0345 | X43: =7707.76 -> 7707.76 | Y43: =X43+U43+V43+W43 -> 7707.76 | Z43: 376493.27 | AA43: =R43-Y43 -> 376493.27
A44: 9 | B44: IKPEAZU CHINEDU ANITA | D44: RESEARCH FELLOW II | E44: 13(9) | F44: =24741.26 -> 24741.26 | H44: =F44*300% -> 74223.78 | I44: =F44*7.5% -> 1855.5945 | J44: 0 | K44: =F44*50% -> 12370.63 | L44: =F44*350% -> 86594.41 | M44: =F44*100% -> 24741.26 | N44: =150000 -> 150000 | O44: =F44*10% -> 2474.126 | P44: 15000 | Q44: 0 | R44: =SUM(F44:Q44) -> 392001.06 | S44: 399177.65 | T44: =S44-R44 -> 7176.5933 | X44: 7709.76 | Y44: =X44+U44+V44+W44 -> 7709.76 | Z44: 384291.3 | AA44: =R44-Y44 -> 384291.3
...

Sheet ARREARS
B3: STAFF PAYROLL FOR THE MONTH OF DECEMBER, 2020
F4: ='[1]FEB 08'!E8/'[1]FEB 08'!M8 -> 0.22 | I4: ='[1]FEB 08'!F8/'[1]FEB 08'!Q8 -> 0.3
B5: STAFF NAME | W5: DEDUCTIONS | AC5: NET SALARY
D6: DESIGNATION | E6: SALARY | F6: BASIC | M6: MOTOR/ | N6: RESEARCH | O6: LEAVE | P6: OUT FIT | Q6: LEGISLATIVE | R6: MONTHLY SALARY AMOUNT PAID IN 2020 | S6: MONTHLY SALARY SUPPOSED TO BE PAID SUPPOSED TO BE PAID | T6: DIFF. PER MONTH | U6: NUMBER OF MONTHS INVOLVED | V6: TOTAL ARREAS | AB6: NOVEMBER,2020 | AC6: DECEMBER,2020
E7: LEVEL | F7: SALARY | G7: SALARY/ALLOWCE AREARS | H7: RENT | I7: UTILITY | J7: DOMESTIC | K7: ENTERT. | L7: FURNIT. | M7: FUEL | N7: ALLOWANCE | O7: ALLCE | P7: ALLCE | Q7: DUTY ALLCE | R7: SALARY | S7: SALARY | T7: SALARY | V7: SALARY | W7: COOP SOCIETY | X7: COOP. LOAN RECOVERY | Y7: NHF DEDUCTION | Z7: PAYE | AA7: TOTAL
A8: S/N | B8: DG OFFICE | F8: N | I8: N | R8: N | S8: N | T8: N | V8: N | Z8: N
A9: 1 | B9: ANTHONY EDET | D9: OFFICER M&E | E9: 10(12) | F9: =19774.62 -> 19774.62 | H9: =F9*300% -> 59323.86 | I9: =F9*7.5% -> 1483.0965 | J9: 0 | K9: =F9*50% -> 9887.31 | L9: =F9*350% -> 69211.17 | M9: =F9*100% -> 19774.62 | N9: =100000 -> 100000 | O9: =F9*10% -> 1977.462 | P9: 10000 | Q9: 0 | R9: =191432 -> 191432 | S9: =226713 -> 226713 | T9: =S9-R9 -> 35281 | U9: 12 | V9: =T9*U9 -> 423372 | W9: 10000 | Y9: ='[3]DECEMBER 2019'!$H$43 -> 494.3655 | Z9: 3369.51 | AA9: =SUM(W9:Z9) -> 13863.876 | AB9: 277568.26 | AC9: =R9-AA9 -> 177568.12 | AG9: =3369.51 -> 3369.51 | AH9: =7709.76 -> 7709.76 | AI9: =AH9-AG9 -> 4340.25 | AJ9: =AI9*12 -> 52083
B10: TOTAL | D10: 19 | F10: =SUM(F9:F9) -> 19774.62 | G10: =SUM(G9:G9) -> 0 | H10: =SUM(H9:H9) -> 59323.86 | I10: =SUM(I9:I9) -> 1483.0965 | J10: =SUM(J9:J9) -> 0 | K10: =SUM(K9:K9) -> 9887.31 | L10: =SUM(L9:L9) -> 69211.17 | M10: =SUM(M9:M9) -> 19774.62 | ... R10: =SUM(R9:R9) -> 191432 | V10: =SUM(V9) -> 423372 | W10: =SUM(W9:W9) -> 10000 | X10: =SUM(X9:X9) -> 0 | Y10: =SUM(Y9:Y9) -> 494.3655 | Z10: =SUM(Z9:Z9) -> 3369.51 | AA10: =SUM(AA9:AA9) -> 13863.876 | AB10: 6022279.4 | AC10: =SUM(AC9:AC9) -> 177568.12
B11: LEG. SUPPORT SEVICES
A12: 1 | B12: DR MOHAMMED O. AMALI | D12: RESEARCH FELLOW II | E12: 13(9) | F12: =24741.26 -> 24741.26 | H12: =F12*300% -> 74223.78 | I12: =F12*7.5% -> 1855.5945 | K12: =F12*50% -> 12370.63 | L12: =F12*350% -> 86594.41 | M12: =F12*100% -> 24741.26 | N12: =150000 -> 150000 | O12: =F12*10% -> 2474.126 | P12: 15000 | R12: =242001 -> 242001 | S12: =249153 -> 249153 | T12: =S12-R12 -> 7152 | U12: =2 -> 2 | V12: =T12*U12 -> 14304 | W12: =15000 -> 15000 | X12: =106666.67 -> 106666.67 | Z12: 7709.76 | AA12: =Z12+W12+X12+Y12 -> 129376.43 | AB12: 369291.3 | AC12: =R12-AA12 -> 112624.57 | AG12: =7709.76 -> 7709.76 | AH12: =7709.76 -> 7709.76 | AI12: =AH12-AG12 -> 0
A13: 2 | B13: DORIS DAKDA AARON | D13: RESEARCH OFFICER | E13: 10(9) | F13: =18281.64 -> 18281.64 | H13: =F13*300% -> 54844.92 | I13: =F13*7.5% -> 1371.123 | K13: =F13*50% -> 9140.82 | L13: =F13*350% -> 63985.74 | M13: =F13*100% -> 18281.64 | N13: =150000 -> 150000 | O13: =F13*10% -> 1828.164 | P13: 10000 | R13: =177734 -> 177734 | S13: =226713 -> 226713 | T13: =S13-R13 -> 48979 | U13: 5 | V13: =T13*U13 -> 244895 | W13: =50000+10000 -> 60000 | Y13: ='[3]DECEMBER 2019'!$H$52 -> 457.041 | Z13: 3369.51 | AA13: =Z13+W13+X13+Y13 -> 63826.551 | AB13: 263907.5 | AC13: =R13-AA13 -> 113907.45
B14: TOTAL | D14: 11 | F14: =SUM(F12:F13) -> 43022.9 | H14: =SUM(H12:H13) -> 129068.7 | I14: =SUM(I12:I13) -> 3226.7175 | J14: =SUM(J12:J13) -> 0 | K14: =SUM(K12:K13) -> 21511.45 | L14: =SUM(L12:L13) -> 150580.15 | M14: =SUM(M12:M13) -> 43022.9 | N14: =SUM(N12:N13) -> 300000 | O14: =SUM(O12:O13) -> 4302.29 | ... R14: =SUM(R12:R13) -> 419735 | V14: =SUM(V12:V13) -> 259199 | W14: =SUM(W12:W13) -> 75000 | X14: =SUM(X12:X13) -> 106666.67 | Y14: =SUM(Y12:Y13) -> 457.041 | Z14: =SUM(Z12:Z13) -> 11079.27 | AA14: =SUM(AA12:AA13) -> 193202.98 | AB14: 3902139.3 | AC14: =R14-AA14 -> 226532.02 | AG14: =3369.51 -> 3369.51 | AH14: =7709.76 -> 7709.76 | AI14: =AH14-AG14 -> 4340.25 | AJ14: =AI14*5 -> 21701.25
B16: DEMOCRATIC STUDIES
A17: 1 | B17: NGARA CHRISTOPHER OCHANJA | D17: RESEARCH FELLOW 11 | E17: 13(10) | F17: =25523.45 -> 25523.45 | H17: =F17*300% -> 76570.35 | I17: =F17*7.5% -> 1914.2587 | K17: =F17*50% -> 12761.725 | L17: =F17*350% -> 89332.075 | M17: =F17*100% -> 25523.45 | N17: =150000 -> 150000 | O17: =F17*10% -> 2552.345 | P17: 15000 | Q17: 0 | R17: =249177 -> 249177 | S17: =257211 -> 257211 | T17: =S17-R17 -> 8034 | U17: =12 -> 12 | V17: =T17*U17 -> 96408 | W17: =20000 -> 20000 | X17: =163103.59 -> 163103.59 | Y17: ='[3]DECEMBER 2019'!$H$50 -> 638.08625 | Z17: =7709.76 -> 7709.76 | AA17: =W17+X17+Y17+Z17 -> 191451.44 | AB17: 207726.22 | AC17: =R17-AA17 -> 57725.564 | AG17: =7709.76 -> 7709.76 | AH17: =7709.76 -> 7709.76 | AI17: =AH17-AG17 -> 0
A18: 2 | B18: EJALONIBU GANIYU LAYI | D18: RESEARCH OFFICER | E18: 10(9) | F18: =18281.64 -> 18281.64 | G18: =0 -> 0 | H18: =F18*300% -> 54844.92 | I18: =F18*7.5% -> 1371.123 | K18: =F18*50% -> 9140.82 | L18: =F18*350% -> 63985.74 | M18: =F18*100% -> 18281.64 | N18: =150000 -> 150000 | O18: =F18*10% -> 1828.164 | P18: 10000 | R18: =177734 -> 177734 | S18: =226713 -> 226713 | T18: =S18-R18 -> 48979 | U18: 5 | V18: =T18*U18 -> 244895 | W18: =110000 -> 110000 | Z18: 3369.51 | AA18: =W18+X18+Y18+Z18 -> 113369.51 | AB18: 214364.54 | AC18: =R18-AA18 -> 64364.49 | AG18: =3369.51 -> 3369.51 | AH18: =7709.76 -> 7709.76 | AI18: =AH18-AG18 -> 4340.25 | AJ18: =AI18*5 -> 21701.25
B19: TOTAL | D19: 4 | F19: =SUM(F17:F18) -> 43805.09 | G19: =SUM(G17:G18) -> 0 | H19: =SUM(H17:H18) -> 131415.27 | I19: =SUM(I17:I18) -> 3285.3817 | J19: =SUM(J17:J18) -> 0 | K19: =SUM(K17:K18) -> 21902.545 | L19: =SUM(L17:L18) -> 153317.82 | M19: =SUM(M17:M18) -> 43805.09 | ... R19: =SUM(R17:R18) -> 426911 | V19: =SUM(V17:V18) -> 341303 | W19: =SUM(W17:W18) -> 130000 | X19: =SUM(X17:X18) -> 163103.59 | Y19: =SUM(Y17:Y18) -> 638.08625 | Z19: =SUM(Z17:Z18) -> 11079.27 | AA19: =SUM(R19:Z19) -> 1073034.9 | AB19: 1428432.7 | AC19: =SUM(AC17:AC18) -> 122090.05
B21: POST GRADUATE SCHOOL
B22: DR AUGUSTINE C. OSIGWE | D22: RESEARCH FELLOW I | E22: 14(9) | R22: =265272 -> 265272 | S22: =344720 -> 344720 | T22: =S22-R22 -> 79448 | U22: 3 | V22: =T22*U22 -> 238344 | AG22: =7709.76 -> 7709.76 | AH22: =15548.33 -> 15548.33 | AI22: =AH22-AG22 -> 7838.57 | AJ22: =AI22*3 -> 23515.71
A23: 1 | B23: UZODINMA EMMANUEL EZENWA | D23: PROGRAMME OFFICER | E23: 10(10) | F23: =18779.3 -> 18779.3 | H23: =F23*300% -> 56337.9 | I23: =F23*7.5% -> 1408.4475 | J23: 0 | K23: =F23*50% -> 9389.65 | L23: =F23*350% -> 65727.55 | M23: =F23*100% -> 18779.3 | N23: =150000 -> 150000 | O23: =F23*10% -> 1877.93 | P23: 10000 | Q23: 0 | R23: =182300 -> 182300 | S23: =226713 -> 226713 | T23: =S23-R23 -> 44413 | U23: 12 | V23: =T23*U23 -> 532956 | W23: =0 -> 0 | X23: =0 -> 0 | Y23: ='[3]DECEMBER 2019'!$H$48 -> 469.4825 | Z23: 3369.51 | AA23: =W23+X23+Y23+Z23 -> 3838.9925 | AB23: 328461.08 | AC23: =R23-AA23 -> 178461.01 | AG23: =3369.51 -> 3369.51 | AH23: =7709.76 -> 7709.76 | AI23: =AH23-AG23 -> 4340.25 | AJ23: =AI23*12 -> 52083
B24: TOTAL | D24: 4 | F24: =SUM(F23:F23) -> 18779.3 | H24: =SUM(H23:H23) -> 56337.9 | I24: =SUM(I23:I23) -> 1408.4475 | J24: =SUM(J23:J23) -> 0 | K24: =SUM(K23:K23) -> 9389.65 | L24: =SUM(L23:L23) -> 65727.55 | M24: =SUM(M23:M23) -> 18779.3 | N24: =SUM(N23:N23) -> 150000 | O24: =SUM(O23:O23) -> 1877.93 | ... R24: =SUM(R23:R23) -> 182300 | V24: =SUM(V22:V23) -> 771300 | W24: =SUM(W23:W23) -> 0 | X24: =SUM(X23:X23) -> 0 | Y24: =SUM(Y23:Y23) -> 469.4825 | Z24: =SUM(Z23:Z23) -> 3369.51 | AA24: =SUM(AA23:AA23) -> 3838.9925 | AB24: 1188810.1 | AC24: =SUM(AC23:AC23) -> 178461.01 | AJ24: =SUM(AJ22:AJ23) -> 75598.71
B26: ECONOMIC AND SOCIAL DEV.
A27: 1 | B27: TERFA WILLIAMS ABRAHAM | D27: RESEARCH FELLOW I | E27: 14(11) | F27: 28489.81 | H27: =F27*300% -> 85469.43 | I27: =F27*7.5% -> 2136.7357 | K27: =F27*50% -> 14244.905 | L27: =F27*350% -> 99714.335 | M27: =F27*100% -> 28489.81 | N27: =150000 -> 150000 | O27: =F27*10% -> 2848.981 | P27: 20000 | R27: =281394 -> 281394 | S27: =344720 -> 344720 | T27: =S27-R27 -> 63326 | U27: 3 | V27: =T27*U27 -> 189978 | Z27: 7709.76 | AA27: =SUM(W27:Z27) -> 7709.76 | AB27: 423684.25 | AC27: =R27-AA27 -> 273684.24 | AG27: =7709.76 -> 7709.76 | AH27: =15548.33 -> 15548.33 | AI27: =AH27-AG27 -> 7838.57 | AJ27: =AI27*3 -> 23515.71
