Workbook

Sheet April, 2022
B3: STAFF PAYROLL FOR THE MONTH OF APRIL 2022
E4: ='[1]FEB 08'!E8/'[1]FEB 08'!M8 -> 0.22 | H4: ='[1]FEB 08'!F8/'[1]FEB 08'!Q8 -> 0.3
B5: STAFF NAME | T5: DEDUCTIONS | Z5: NET SALARY
C6: DESIGNATION | D6: SALARY | E6: BASIC | L6: MOTOR/ | M6: RESEARCH | N6: HARDSHIP | O6: LEAVE | P6: OUT FIT | Q6: LEGISLATIVE | R6: GROSS | Y6: MARCH,2022 | Z6: APRIL,2022
D7: LEVEL | E7: SALARY | F7: SALARY/ALLOWCE AREARS | G7: RENT | H7: UTILITY | I7: DOMESTIC | J7: ENTERT. | K7: FURNIT. | L7: FUEL | M7: ALLOWANCE | N7: ALLOWANCE | O7: ALLCE | P7: ALLCE | Q7: DUTY ALLCE | R7: SALARY | S7: AUCTION | T7: COOP SOCIETY | U7: COOP. LOAN RECOVERY | V7: NHF DEDUCTION | W7: PAYE | X7: TOTAL
A8: S/N | B8: DG OFFICE | E8: N | H8: N | R8: N | W8: N
A9: 1 | B9: PROF. ABUBAKAR O. SULAIMAN | C9: DIRECTOR GENERAL | D9: CONSOL | E9: 160488.75 | G9: 320977.5 | H9: 48146.63 | I9: 120366.57 | J9: 72219.94 | K9: 0 | L9: 120366.57 | M9: =250000 -> 250000 | O9: 16048.88 | P9: 25000 | Q9: 25235 | R9: =Q9+P9+O9+N9+M9+L9+K9+J9+I9+H9+G9+F9+E9 -> 1158849.8 | W9: 113176.97 | X9: =W9+V9+U9+T9+S9 -> 113176.97 | Y9: 1045672.9 | Z9: =R9-X9 -> 1045672.9
A10: 2 | B10: DR ADEYEMI AKEEB FAJINGBESI | C10: DIR. SPECIAL DUTIES, DG OFFICE | D10: 17(9) | E10: 81740.02 | G10: =E10*300% -> 245220.06 | H10: =E10*7.5% -> 6130.5015 | I10: 80244.38 | J10: =E10*50% -> 40870.01 | K10: =E10*350% -> 286090.07 | L10: =E10*100% -> 81740.02 | M10: =200000 -> 200000 | O10: =E10*10% -> 8174.002 | P10: 20000 | Q10: 0 | R10: =Q10+P10+O10+N10+M10+L10+K10+J10+I10+H10+G10+F10+E10 -> 1050209.1 | T10: 200000 | U10: =59722.22 -> 59722.22 | V10: ='[2]April 2022'!$H$34 -> 2043.5005 | W10: 52776.63 | X10: =W10+V10+U10+T10+S10 -> 314542.35 | Y10: 735666.71 | Z10: =R10-X10 -> 735666.71
A11: 3 | B11: DR JAKE DABANG DAN AZUMI | C11: DEPUTY DIRECTOR TRAINING | D11: 16(8) | E11: 41157.69 | G11: =E11*300% -> 123473.07 | H11: =E11*7.5% -> 3086.8268 | I11: 40122.19 | J11: =E11*50% -> 20578.845 | K11: =E11*350% -> 144051.92 | L11: =E11*100% -> 41157.69 | M11: =180000 -> 180000 | O11: =E11*10% -> 4115.769 | P11: 20000 | Q11: 150000 | R11: =Q11+P11+O11+N11+M11+L11+K11+J11+I11+H11+G11+F11+E11 -> 767744 | V11: ='[2]April 2022'!$H$26 -> 1028.9423 | W11: =21618.09 -> 21618.09 | X11: =W11+V11+U11+T11+S11 -> 22647.032 | Y11: 745134.35 | Z11: =R11-X11 -> 745096.96
A12: 4 | B12: DR ABDULSALAM NASIRU NAEEM | C12: SA ACADEMICS | D12: 16(8) | E12: 41157.69 | G12: =E12*300% -> 123473.07 | H12: =E12*7.5% -> 3086.8268 | I12: 40122.19 | J12: =E12*50% -> 20578.845 | K12: =E12*350% -> 144051.92 | L12: =E12*100% -> 41157.69 | M12: =180000 -> 180000 | O12: =E12*10% -> 4115.769 | P12: 20000 | Q12: =100000 -> 100000 | R12: =Q12+P12+O12+N12+M12+L12+K12+J12+I12+H12+G12+F12+E12 -> 717744 | W12: =21618.09 -> 21618.09 | X12: =W12+V12+U12+T12+S12 -> 21618.09 | Y12: 696125.91 | Z12: =R12-X12 -> 696125.91
A13: 5 | B13: RAHEEM USMAN AYIGORO | C13: SA-INFRASTRUCTURE | D13: 16 (8) | E13: 41157.69 | G13: =E13*300% -> 123473.07 | H13: =E13*7.5% -> 3086.8268 | I13: 40122.19 | J13: =E13*50% -> 20578.845 | K13: =E13*350% -> 144051.92 | L13: =E13*100% -> 41157.69 | N13: =90000 -> 90000 | O13: =E13*10% -> 4115.769 | P13: 20000 | Q13: 0 | R13: =Q13+P13+O13+N13+M13+L13+K13+J13+I13+H13+G13+F13+E13 -> 527744 | T13: =100000+2000 -> 102000 | W13: =21618.09 -> 21618.09 | X13: =W13+V13+U13+T13+S13 -> 123618.09 | Y13: 506125.91 | Z13: =R13-X13 -> 404125.91
A14: 6 | B14: AKINSANMI ADEJOKE OLUKEMI | C14: HEAD INFORMATION/PROTOCOL | D14: 15(9) | E14: 33507.5 | G14: =E14*300% -> 100522.5 | H14: =E14*7.5% -> 2513.0625 | I14: 40122.19 | J14: =E14*50% -> 16753.75 | K14: =E14*350% -> 117276.25 | L14: =E14*100% -> 33507.5 | N14: =80000 -> 80000 | O14: =E14*10% -> 3350.75 | P14: 20000 | Q14: =100000 -> 100000 | R14: =Q14+P14+O14+N14+M14+L14+K14+J14+I14+H14+G14+F14+E14 -> 547553.5 | T14: =0 -> 0 | U14: 0 | V14: ='[2]April 2022'!$H$25 -> 837.6875 | W14: 15548.33 | X14: =W14+V14+U14+T14+S14 -> 16386.018 | Y14: 531167.48 | Z14: =R14-X14 -> 531167.48
A15: 7 | B15: DR IKEME ARTHUR J.O | C15: SNR RESEARCH FELLOW | D15: 15(9) | E15: 33507.5 | G15: =E15*300% -> 100522.5 | H15: =E15*7.5% -> 2513.0625 | I15: 40122.19 | J15: =E15*50% -> 16753.75 | K15: =E15*350% -> 117276.25 | L15: =E15*100% -> 33507.5 | N15: =80000 -> 80000 | O15: =E15*10% -> 3350.75 | P15: 20000 | Q15: 0 | R15: =Q15+P15+O15+N15+M15+L15+K15+J15+I15+H15+G15+F15+E15 -> 447553.5 | T15: =50000 -> 50000 | U15: =160416.67 -> 160416.67 | V15: ='[3]DECEMBER 2019'!$H$38 -> 837.6875 | W15: 15548.33 | X15: =W15+V15+U15+T15+S15 -> 226802.69 | Y15: 220750.82 | Z15: =R15-X15 -> 220750.82
A16: 8 | B16: MOSHOOD M. OLALERE | C16: MANAGER ADMIN DG's OFFICE | D16: 15(9) | E16: 33507.5 | G16: =E16*300% -> 100522.5 | H16: =E16*7.5% -> 2513.0625 | I16: 40122.19 | J16: =E16*50% -> 16753.75 | K16: =E16*350% -> 117276.25 | L16: =E16*100% -> 33507.5 | N16: =80000 -> 80000 | O16: =E16*10% -> 3350.75 | P16: 20000 | Q16: 0 | R16: =Q16+P16+O16+N16+M16+L16+K16+J16+I16+H16+G16+F16+E16 -> 447553.5 | T16: =20000 -> 20000 | U16: =179017.51 -> 179017.51 | V16: ='[3]DECEMBER 2019'!$H$35 -> 837.6875 | W16: 15548.33 | X16: =W16+V16+U16+T16+S16 -> 215403.53 | Y16: 232149.97 | Z16: =R16-X16 -> 232149.97
A17: 9 | B17: ANDRAWUS MUSA | C17: ASST. DIRECTOR, STORE | D17: 15(9) | E17: 33507.5 | G17: =E17*300% -> 100522.5 | H17: =E17*7.5% -> 2513.0625 | I17: =40122.19 -> 40122.19 | J17: =E17*50% -> 16753.75 | K17: =E17*350% -> 117276.25 | L17: =E17*100% -> 33507.5 | N17: =80000 -> 80000 | O17: =E17*10% -> 3350.75 | P17: 20000 | Q17: 0 | R17: =SUM(E17:Q17) -> 447553.5 | T17: =50000 -> 50000 | U17: =90000 -> 90000 | V17: ='[2]April 2022'!$H$28 -> 837.6875 | W17: =15548.33 -> 15548.33 | X17: =W17+V17+U17+T17+S17 -> 156386.02 | Y17: 291198.59 | Z17: =R17-X17 -> 291167.48
A18: 10 | B18: AYOBOLU OLAJIDE OLUFUNSHO | C18: ASST.DIR., INFORMATION | D18: 15 (7) | E18: 31018.84 | G18: =E18*300% -> 93056.52 | H18: =E18*7.5% -> 2326.413 | I18: 40122.19 | J18: =E18*50% -> 15509.42 | K18: =E18*350% -> 108565.94 | L18: =E18*100% -> 31018.84 | N18: =80000 -> 80000 | O18: =E18*10% -> 3101.884 | P18: 20000 | Q18: 0 | R18: =Q18+P18+O18+N18+M18+L18+K18+J18+I18+H18+G18+F18+E18 -> 424720.05 | T18: =50000 -> 50000 | U18: =59583.33 -> 59583.33 | W18: 15548.33 | X18: =W18+V18+U18+T18+S18 -> 125131.66 | Y18: 299588.39 | Z18: =R18-X18 -> 299588.39
A19: 11 | B19: HUSSEIN EGYE MUSA | C19: CHIEF PROTOCOL OFFICER | D19: 14(9) | E19: 26732.65 | G19: =E19*300% -> 80197.95 | H19: =E19*7.5% -> 2004.9488 | J19: =E19*50% -> 13366.325 | K19: =E19*350% -> 93564.275 | L19: =E19*100% -> 26732.65 | N19: =70000 -> 70000 | O19: =E19*10% -> 2673.265 | P19: 20000 | Q19: 50000 | R19: =Q19+P19+O19+N19+M19+L19+K19+J19+I19+H19+G19+F19+E19 -> 385272.06 | T19: 50000 | U19: =150000 -> 150000 | V19: 0 | W19: 7709.76 | X19: =W19+V19+U19+T19+S19 -> 207709.76 | Y19: 177562.3 | Z19: =R19-X19 -> 177562.3
A20: 12 | B20: DONALD E. MKPANAM | C20: CHIEF ICT OFFICER | D20: 14(9) | E20: 26732.65 | G20: =E20*300% -> 80197.95 | H20: =E20*7.5% -> 2004.9488 | J20: =E20*50% -> 13366.325 | K20: =E20*350% -> 93564.275 | L20: =E20*100% -> 26732.65 | N20: =70000 -> 70000 | O20: =E20*10% -> 2673.265 | P20: 20000 | Q20: 0 | R20: =Q20+P20+O20+N20+M20+L20+K20+J20+I20+H20+G20+F20+E20 -> 335272.06 | V20: ='[2]April 2022'!$H$27 -> 668.31625 | W20: 7709.76 | X20: =W20+V20+U20+T20+S20 -> 8378.0763 | Y20: 326903.82 | Z20: =R20-X20 -> 326893.99
A21: 13 | B21: JOY HARUNA MAKERI | C21: RESEARCH FELLOW 1 TRAINING | D21: 14(9) | E21: 26732.65 | G21: =E21*300% -> 80197.95 | H21: =E21*7.5% -> 2004.9488 | J21: =E21*50% -> 13366.325 | K21: =E21*350% -> 93564.275 | L21: =E21*100% -> 26732.65 | M21: =140000 -> 140000 | O21: =E21*10% -> 2673.265 | P21: 20000 | Q21: =50000+100000 -> 150000 | R21: =Q21+P21+O21+N21+M21+L21+K21+J21+I21+H21+G21+F21+E21 -> 555272.06 | W21: =7709.76 -> 7709.76 | X21: =W21+V21+U21+T21+S21 -> 7709.76 | Y21: 547562.3 | Z21: =R21-X21 -> 547562.3
A22: 14 | B22: ALI ABDULLAHI | C22: ASST. CHIEF ICT OFFICER | D22: 13(11) | E22: 26339.3 | G22: =E22*300% -> 79017.9 | H22: =E22*7.5% -> 1975.4475 | I22: 0 | J22: =E22*50% -> 13169.65 | K22: =E22*350% -> 92187.55 | L22: =E22*100% -> 26339.3 | N22: =70000 -> 70000 | O22: =E22*10% -> 2633.93 | P22: 15000 | Q22: =0 -> 0 | R22: =Q22+P22+O22+N22+M22+L22+K22+J22+I22+H22+G22+F22+E22 -> 326663.08 | W22: =7709.76 -> 7709.76 | X22: =W22+V22+U22+T22+S22 -> 7709.76 | Y22: 318953.32 | Z22: =R22-X22 -> 318953.32
A23: 15 | B23: MARIAM MOHAMMED BELLO | C23: SA- SPECIAL DUTIES | D23: 13 (7) | E23: =39662.25 -> 39662.25 | G23: =E23*300% -> 118986.75 | H23: =E23*7.5% -> 2974.6687 | I23: 0 | J23: =E23*50% -> 19831.125 | K23: =E23*350% -> 138817.88 | L23: =E23*100% -> 39662.25 | N23: =90000 -> 90000 | O23: =E23*10% -> 3966.225 | P23: 15000 | Q23: =100000+100000 -> 200000 | R23: =Q23+P23+O23+N23+M23+L23+K23+J23+I23+H23+G23+F23+E23 -> 668901.14 | W23: 21618.09 | X23: =W23+V23+U23+T23+S23 -> 21618.09 | Y23: 489003.27 | Z23: =R23-X23 -> 647283.05
A24: 16 | B24: PERCY TERFA GBAHABO | C24: HEAD, NILDS LIAISON OFFICE | D24: 13(8) | E24: 23891.12 | G24: =E24*300% -> 71673.36 | H24: =E24*7.5% -> 1791.834 | I24: 0 | J24: =E24*50% -> 11945.56 | K24: =E24*350% -> 83618.92 | L24: =E24*100% -> 23891.12 | M24: =120000 -> 120000 | O24: =E24*10% -> 2389.112 | P24: 15000 | Q24: 0 | R24: =Q24+P24+O24+N24+M24+L24+K24+J24+I24+H24+G24+F24+E24 -> 354201.03 | T24: =70000 -> 70000 | U24: =98464.26 -> 98464.26 | W24: =7709.76 -> 7709.76 | X24: =W24+V24+U24+T24+S24 -> 176174.02 | Y24: 238027.01 | Z24: =R24-X24 -> 178027.01
A25: 17 | B25: ADUGBA RICHARD TERSEER | C25: INFORMATION OFFICER | D25: 10(10) | E25: 18779.3 | G25: =E25*300% -> 56337.9 | H25: =E25*7.5% -> 1408.4475 | J25: =E25*50% -> 9389.65 | K25: =E25*350% -> 65727.55 | L25: =E25*100% -> 18779.3 | N25: =60000 -> 60000 | O25: =E25*10% -> 1877.93 | P25: 10000 | R25: =Q25+P25+O25+N25+M25+L25+K25+J25+I25+H25+G25+F25+E25 -> 242300.08 | T25: =20000 -> 20000 | U25: =111833.33 -> 111833.33 | W25: 3369.51 | X25: =W25+V25+U25+T25+S25 -> 135202.84 | Y25: 107097.24 | Z25: =R25-X25 -> 107097.24
A26: 18 | B26: CHRISTIAN MADUABUCHI ODO | C26: PRINCIPAL ICT OFFICER | D26: 12(8) | E26: =21520.88 -> 21520.88 | G26: =E26*300% -> 64562.64 | H26: =E26*7.5% -> 1614.066 | J26: =E26*50% -> 10760.44 | K26: =E26*350% -> 75323.08 | L26: =E26*100% -> 21520.88 | N26: =60000 -> 60000 | O26: =E26*10% -> 2152.088 | P26: 15000 | R26: =Q26+P26+O26+N26+M26+L26+K26+J26+I26+H26+G26+F26+E26 -> 272454.07 | T26: =20000 -> 20000 | U26: =82500 -> 82500 | V26: ='[2]April 2022'!$H$45 -> 538.022 | W26: 3369.51 | X26: =W26+V26+U26+T26+S26 -> 106407.53 | Y26: 166102.64 | Z26: =R26-X26 -> 166046.54
A27: 19 | B27: HASSANA AHMED IBRAHIM | C27: PA- TO DG | D27: 13 (7) | E27: 23074.99 | G27: =E27*300% -> 69224.97 | H27: =E27*7.5% -> 1730.6243 | J27: =E27*50% -> 11537.495 | K27: =E27*350% -> 80762.465 | L27: =E27*100% -> 23074.99 | M27: =100000 -> 100000 | O27: =E27*10% -> 2307.499 | P27: 10000 | Q27: =100000 -> 100000 | R27: =Q27+P27+O27+N27+M27+L27+K27+J27+I27+H27+G27+F27+E27 -> 421713.03 | T27: =30000 -> 30000 | V27: ='[2]April 2022'!$H$52 -> 576.87475 | W27: =7709.76 -> 7709.76 | X27: =W27+V27+U27+T27+S27 -> 38286.635 | Y27: 383558.67 | Z27: =R27-X27 -> 383426.4
A28: 20 | B28: VICTOR ASUKWO | C28: ICT OFFICER | D28: 8 (10) | E28: 13492.21 | G28: =E28*300% -> 40476.63 | H28: =E28*7.5% -> 1011.9157 | J28: =E28*50% -> 6746.105 | K28: =E28*350% -> 47222.735 | L28: =E28*100% -> 13492.21 | N28: =50000 -> 50000 | O28: =E28*10% -> 1349.221 | P28: 10000 | R28: =Q28+P28+O28+N28+M28+L28+K28+J28+I28+H28+G28+F28+E28 -> 183791.03 | W28: 1484.37 | X28: =W28+V28+U28+T28+S28 -> 1484.37 | Y28: 182306.66 | Z28: =R28-X28 -> 182306.66
A29: 21 | B29: SULEIMAN ABUBAKAR SODEEQ | C29: ASST. ADMIN. OFFICER | D29: 8(7) | E29: 12351.94 | G29: =E29*300% -> 37055.82 | H29: =E29*7.5% -> 926.3955 | J29: =E29*50% -> 6175.97 | K29: =E29*350% -> 43231.79 | L29: =E29*100% -> 12351.94 | N29: =50000 -> 50000 | O29: =E29*10% -> 1235.194 | P29: 10000 | R29: =Q29+P29+O29+N29+M29+L29+K29+J29+I29+H29+G29+F29+E29 -> 173329.05 | W29: =1484.37 -> 1484.37 | X29: =W29+V29+U29+T29+S29 -> 1484.37 | Y29: 171844.68 | Z29: =R29-X29 -> 171844.68
A30: 22 | B30: YAKUB OLUWATOYIN USMAN | C30: ASST. ADMIN. OFFICER | D30: 10(8) | E30: 17784.1 | G30: =E30*300% -> 53352.3 | H30: =E30*7.5% -> 1333.8075 | J30: =E30*50% -> 8892.05 | K30: =E30*350% -> 62244.35 | L30: =E30*100% -> 17784.1 | N30: =60000 -> 60000 | O30: =E30*10% -> 1778.41 | P30: 10000 | R30: =Q30+P30+O30+N30+M30+L30+K30+J30+I30+H30+G30+F30+E30 -> 233169.12 | T30: =10000 -> 10000 | U30: =34333.33 -> 34333.33 | W30: =1484.37 -> 1484.37 | X30: =W30+V30+U30+T30+S30 -> 45817.7 | Y30: 187351.42 | Z30: =R30-X30 -> 187351.42
A31: 23 | B31: ANTHONY EDET | C31: ASST. MGR M&E | D31: 13(9) | E31: 24741.26 | G31: =E31*300% -> 74223.78 | H31: =E31*7.5% -> 1855.5945 | I31: 0 | J31: =E31*50% -> 12370.63 | K31: =E31*350% -> 86594.41 | L31: =E31*100% -> 24741.26 | N31: =70000 -> 70000 | O31: =E31*10% -> 2474.126 | P31: 15000 | Q31: 0 | R31: =Q31+P31+O31+N31+M31+L31+K31+J31+I31+H31+G31+F31+E31 -> 312001.06 | T31: 20000 | U31: =68750 -> 68750 | V31: ='[2]April 2022'!$H$38 -> 618.5315 | W31: =7709.76 -> 7709.76 | X31: =W31+V31+U31+T31+S31 -> 97078.291 | Y31: 214944.02 | Z31: =R31-X31 -> 214922.77
A32: 24 | B32: EGUATU U. ONYEJELEM | C32: OFFICER M&E | D32: 10(10) | E32: 18779.3 | G32: =E32*300% -> 56337.9 | H32: =E32*7.5% -> 1408.4475 | J32: =E32*50% -> 9389.65 | K32: =E32*350% -> 65727.55 | L32: =E32*100% -> 18779.3 | N32: =60000 -> 60000 | O32: =E32*10% -> 1877.93 | P32: 10000 | R32: =Q32+P32+O32+N32+M32+L32+K32+J32+I32+H32+G32+F32+E32 -> 242300.08 | T32: =20000 -> 20000 | U32: =87500+43750 -> 131250 | W32: 3369.51 | X32: =W32+V32+U32+T32+S32 -> 154619.51 | Y32: 87680.567 | Z32: =R32-X32 -> 87680.567
A33: 25 | B33: ODEH SUZIE | C33: ADMIN. OFFICER, LIASION OFFICE | D33: 10(9) | E33: 18281.64 | G33: =E33*300% -> 54844.92 | H33: =E33*7.5% -> 1371.123 | J33: =E33*50% -> 9140.82 | K33: =E33*350% -> 63985.74 | L33: =E33*100% -> 18281.64 | N33: 60000 | O33: =E33*10% -> 1828.164 | P33: 10000 | R33: =Q33+P33+O33+N33+M33+L33+K33+J33+I33+H33+G33+F33+E33 -> 237734.05 | T33: =30000 -> 30000 | V33: =0 -> 0 | W33: 3369.51 | X33: =W33+V33+U33+T33+S33 -> 33369.51 | Y33: 204364.54 | Z33: =R33-X33 -> 204364.54
A34: 26 | B34: IJEOMA NKOLIKWA | C34: ASSISTANT STORES OFFICER | D34: 8(10) | E34: 13492.21 | G34: =E34*300% -> 40476.63 | H34: =E34*7.5% -> 1011.9157 | J34: =E34*50% -> 6746.105 | K34: =E34*350% -> 47222.735 | L34: =E34*100% -> 13492.21 | N34: =50000 -> 50000 | O34: =E34*10% -> 1349.221 | P34: 10000 | R34: =SUM(E34:Q34) -> 183791.03 | T34: =10000 -> 10000 | W34: 1484.37 | X34: =W34+V34+U34+T34+S34 -> 11484.37 | Y34: 172306.66 | Z34: =R34-X34 -> 172306.66
A35: 27 | B35: ABDULRAHMAN A SULAIMAN | C35: ASSISTANT STORES OFFICER | D35: 8 (9) | E35: 13112.16 | G35: =E35*300% -> 39336.48 | H35: =E35*7.5% -> 983.412 | J35: =E35*50% -> 6556.08 | K35: =E35*350% -> 45892.56 | L35: =E35*100% -> 13112.16 | N35: =50000 -> 50000 | O35: =E35*10% -> 1311.216 | P35: 10000 | R35: =SUM(E35:Q35) -> 180304.07 | T35: =20000 -> 20000 | W35: =(1484.37) -> 1484.37 | X35: =W35+V35+U35+T35+S35 -> 21484.37 | Y35: 158819.7 | Z35: =R35-X35 -> 158819.7
A36: 28 | B36: TASSNEEM IBRAHIM | C36: ASSIST. INFORMATION | D36: 8(9) | E36: 13112.16 | G36: =E36*300% -> 39336.48 | H36: =E36*7.5% -> 983.412 | J36: =E36*50% -> 6556.08 | K36: =E36*350% -> 45892.56 | L36: =E36*100% -> 13112.16 | N36: =50000 -> 50000 | O36: =E36*10% -> 1311.216 | P36: 10000 | R36: =Q36+P36+O36+N36+M36+L36+K36+J36+I36+H36+G36+F36+E36 -> 180304.07 | T36: =50000 -> 50000 | U36: =17166.67 -> 17166.67 | V36: =0 -> 0 | W36: =1484.37 -> 1484.37 | X36: =W36+V36+U36+T36+S36 -> 68651.04 | Y36: 111653.03 | Z36: =R36-X36 -> 111653.03
A37: 29 | B37: JIMOH ADEBAYO ZAKA | C37: ASST. OFFICER/COMM | D37: 8(7) | E37: 12351.94 | G37: =E37*300% -> 37055.82 | H37: =E37*7.5% -> 926.3955 | J37: =E37*50% -> 6175.97 | K37: =E37*350% -> 43231.79 | L37: =E37*100% -> 12351.94 | N37: =50000 -> 50000 | O37: =E37*10% -> 1235.194 | P37: 10000 | R37: =Q37+P37+O37+N37+M37+L37+K37+J37+I37+H37+G37+F37+E37 -> 173329.05 | T37: =50000 -> 50000 | V37: =0 -> 0 | W37: =1484.37 -> 1484.37 | X37: =W37+V37+U37+T37+S37 -> 51484.37 | Y37: 121844.68 | Z37: =R37-X37 -> 121844.68
A38: 30 | B38: HABEEBA K MUHAMMAD SALIHU | C38: ASST. OFFICER/COMM | D38: 8(7) | E38: 12351.94 | G38: =E38*300% -> 37055.82 | H38: =E38*7.5% -> 926.3955 | J38: =E38*50% -> 6175.97 | K38: =E38*350% -> 43231.79 | L38: =E38*100% -> 12351.94 | N38: =50000 -> 50000 | O38: =E38*10% -> 1235.194 | P38: 10000 | R38: =Q38+P38+O38+N38+M38+L38+K38+J38+I38+H38+G38+F38+E38 -> 173329.05 | V38: =0 -> 0 | W38: =1484.37 -> 1484.37 | X38: =W38+V38+U38+T38+S38 -> 1484.37 | Y38: 171844.68 | Z38: =R38-X38 -> 171844.68
B39: TOTAL | C39: 30 | E39: =SUM(E9:E38) -> 934067.33 | G39: =SUM(G9:G38) -> 2641713.2 | H39: =SUM(H9:H38) -> 106165.02 | I39: =SUM(I9:I38) -> 521588.47 | J39: =SUM(J9:J38) -> 459009.23 | K39: =SUM(K9:K38) -> 2707525 | L39: =SUM(L9:L38) -> 893945.15 | M39: =SUM(M9:M38) -> 1170000 | N39: =SUM(N9:N38) -> 1510000 | ... R39: =SUM(R9:R38) -> 12372655 | T39: =SUM(T9:T38) -> 872000 | U39: =SUM(U9:U38) -> 1243037.3 | V39: =SUM(V9:V38) -> 8824.9372 | W39: =SUM(W9:W38) -> 409488.93 | X39: =SUM(X9:X38) -> 2533351.2 | Y39: 9843312.2 | Z39: =SUM(Z9:Z38) -> 9839304
B41: INTERNAL AUDIT
A42: 1 | B42: OSANAIYE DAVID AKINYEMI | C42: DIRECTOR INTERNAL AUDIT | D42: 17(8) | E42: 79039.64 | G42: =E42*300% -> 237118.92 | H42: =E42*7.5% -> 5927.973 | I42: 80244.38 | J42: =E42*50% -> 39519.82 | K42: =E42*350% -> 276638.74 | L42: =E42*100% -> 79039.64 | N42: =100000 -> 100000 | O42: =E42*10% -> 7903.964 | P42: 20000 | R42: =SUM(E42:Q42) -> 925433.08 | T42: =100000 -> 100000 | W42: =(52776.63) -> 52776.63 | X42: =W42+V42+U42+T42+S42 -> 152776.63 | Y42: 772656.45 | Z42: =R42-X42 -> 772656.45
A43: 2 | B43: JAMILA ABDUL | C43: AUDITOR II | D43: 8(7) | E43: 12351.94 | G43: =E43*300% -> 37055.82 | H43: =E43*7.5% -> 926.3955 | J43: =E43*50% -> 6175.97 | K43: =E43*350% -> 43231.79 | L43: =E43*100% -> 12351.94 | N43: =50000 -> 50000 | O43: =E43*10% -> 1235.194 | P43: 10000 | R43: =(Q43+P43+O43+N43+M43+L43+K43+J43+I43+H43+G43+F43+E43)*12/30 -> 69331.62 | V43: =0 -> 0 | W43: 1484.37 | X43: =W43+V43+U43+T43+S43 -> 1484.37 | Z43: =R43-X43 -> 67847.25
...

Sheet List
B3: STAFF PAYROLL FOR THE MONTH OF APRIL 2022
E4: ='[1]FEB 08'!E8/'[1]FEB 08'!M8 -> 0.22 | H4: ='[1]FEB 08'!F8/'[1]FEB 08'!Q8 -> 0.3
B5: STAFF NAME | T5: DEDUCTIONS | Z5: NET SALARY
C6: DESIGNATION | D6: SALARY | E6: BASIC | L6: MOTOR/ | M6: RESEARCH | N6: HARDSHIP | O6: LEAVE | P6: OUT FIT | Q6: LEGISLATIVE | R6: GROSS | Y6: MARCH,2022 | Z6: APRIL,2022
D7: LEVEL | E7: SALARY | F7: SALARY/ALLOWCE AREARS | G7: RENT | H7: UTILITY | I7: DOMESTIC | J7: ENTERT. | K7: FURNIT. | L7: FUEL | M7: ALLOWANCE | N7: ALLOWANCE | O7: ALLCE | P7: ALLCE | Q7: DUTY ALLCE | R7: SALARY | S7: AUCTION | T7: COOP SOCIETY | U7: COOP. LOAN RECOVERY | V7: NHF DEDUCTION | W7: PAYE | X7: TOTAL
A8: S/N | B8: DG OFFICE | E8: N | H8: N | R8: N | W8: N
A9: 1 | B9: PROF. ABUBAKAR O. SULAIMAN | C9: DIRECTOR GENERAL | D9: CONSOL | E9: 160488.75 | G9: 320977.5 | H9: 48146.63 | I9: 120366.57 | J9: 72219.94 | K9: 0 | L9: 120366.57 | M9: =250000 -> 250000 | O9: 16048.88 | P9: 25000 | Q9: 25235 | R9: =Q9+P9+O9+N9+M9+L9+K9+J9+I9+H9+G9+F9+E9 -> 1158849.8 | W9: 113176.97 | X9: =W9+V9+U9+T9+S9 -> 113176.97 | Y9: 1045672.9 | Z9: =R9-X9 -> 1045672.9
A10: 2 | B10: DR ADEYEMI AKEEB FAJINGBESI | C10: DIR. SPECIAL DUTIES, DG OFFICE | D10: 17(9) | E10: 81740.02 | G10: =E10*300% -> 245220.06 | H10: =E10*7.5% -> 6130.5015 | I10: 80244.38 | J10: =E10*50% -> 40870.01 | K10: =E10*350% -> 286090.07 | L10: =E10*100% -> 81740.02 | M10: =200000 -> 200000 | O10: =E10*10% -> 8174.002 | P10: 20000 | Q10: 0 | R10: =Q10+P10+O10+N10+M10+L10+K10+J10+I10+H10+G10+F10+E10 -> 1050209.1 | T10: 200000 | U10: =59722.22 -> 59722.22 | V10: ='[2]April 2022'!$H$34 -> 2043.5005 | W10: 52776.63 | X10: =W10+V10+U10+T10+S10 -> 314542.35 | Y10: 735666.71 | Z10: =R10-X10 -> 735666.71
A11: 3 | B11: DR JAKE DABANG DAN AZUMI | C11: DEPUTY DIRECTOR TRAINING | D11: 16(8) | E11: 41157.69 | G11: =E11*300% -> 123473.07 | H11: =E11*7.5% -> 3086.8268 | I11: 40122.19 | J11: =E11*50% -> 20578.845 | K11: =E11*350% -> 144051.92 | L11: =E11*100% -> 41157.69 | M11: =180000 -> 180000 | O11: =E11*10% -> 4115.769 | P11: 20000 | Q11: 150000 | R11: =Q11+P11+O11+N11+M11+L11+K11+J11+I11+H11+G11+F11+E11 -> 767744 | V11: ='[2]April 2022'!$H$26 -> 1028.9423 | W11: =21618.09 -> 21618.09 | X11: =W11+V11+U11+T11+S11 -> 22647.032 | Y11: 745134.35 | Z11: =R11-X11 -> 745096.96
A12: 4 | B12: DR ABDULSALAM NASIRU NAEEM | C12: SA ACADEMICS | D12: 16(8) | E12: 41157.69 | G12: =E12*300% -> 123473.07 | H12: =E12*7.5% -> 3086.8268 | I12: 40122.19 | J12: =E12*50% -> 20578.845 | K12: =E12*350% -> 144051.92 | L12: =E12*100% -> 41157.69 | M12: =180000 -> 180000 | O12: =E12*10% -> 4115.769 | P12: 20000 | Q12: =100000 -> 100000 | R12: =Q12+P12+O12+N12+M12+L12+K12+J12+I12+H12+G12+F12+E12 -> 717744 | W12: =21618.09 -> 21618.09 | X12: =W12+V12+U12+T12+S12 -> 21618.09 | Y12: 696125.91 | Z12: =R12-X12 -> 696125.91
A13: 5 | B13: RAHEEM USMAN AYIGORO | C13: SA-INFRASTRUCTURE | D13: 16 (8) | E13: 41157.69 | G13: =E13*300% -> 123473.07 | H13: =E13*7.5% -> 3086.8268 | I13: 40122.19 | J13: =E13*50% -> 20578.845 | K13: =E13*350% -> 144051.92 | L13: =E13*100% -> 41157.69 | N13: =90000 -> 90000 | O13: =E13*10% -> 4115.769 | P13: 20000 | Q13: 0 | R13: =Q13+P13+O13+N13+M13+L13+K13+J13+I13+H13+G13+F13+E13 -> 527744 | T13: =100000+2000 -> 102000 | W13: =21618.09 -> 21618.09 | X13: =W13+V13+U13+T13+S13 -> 123618.09 | Y13: 506125.91 | Z13: =R13-X13 -> 404125.91
A14: 6 | B14: AKINSANMI ADEJOKE OLUKEMI | C14: HEAD INFORMATION/PROTOCOL | D14: 15(9) | E14: 33507.5 | G14: =E14*300% -> 100522.5 | H14: =E14*7.5% -> 2513.0625 | I14: 40122.19 | J14: =E14*50% -> 16753.75 | K14: =E14*350% -> 117276.25 | L14: =E14*100% -> 33507.5 | N14: =80000 -> 80000 | O14: =E14*10% -> 3350.75 | P14: 20000 | Q14: =100000 -> 100000 | R14: =Q14+P14+O14+N14+M14+L14+K14+J14+I14+H14+G14+F14+E14 -> 547553.5 | T14: =0 -> 0 | U14: 0 | V14: ='[2]April 2022'!$H$25 -> 837.6875 | W14: 15548.33 | X14: =W14+V14+U14+T14+S14 -> 16386.018 | Y14: 531167.48 | Z14: =R14-X14 -> 531167.48
A15: 7 | B15: DR IKEME ARTHUR J.O | C15: SNR RESEARCH FELLOW | D15: 15(9) | E15: 33507.5 | G15: =E15*300% -> 100522.5 | H15: =E15*7.5% -> 2513.0625 | I15: 40122.19 | J15: =E15*50% -> 16753.75 | K15: =E15*350% -> 117276.25 | L15: =E15*100% -> 33507.5 | N15: =80000 -> 80000 | O15: =E15*10% -> 3350.75 | P15: 20000 | Q15: 0 | R15: =Q15+P15+O15+N15+M15+L15+K15+J15+I15+H15+G15+F15+E15 -> 447553.5 | T15: =50000 -> 50000 | U15: =160416.67 -> 160416.67 | V15: ='[3]DECEMBER 2019'!$H$38 -> 837.6875 | W15: 15548.33 | X15: =W15+V15+U15+T15+S15 -> 226802.69 | Y15: 220750.82 | Z15: =R15-X15 -> 220750.82
A16: 8 | B16: MOSHOOD M. OLALERE | C16: MANAGER ADMIN DG's OFFICE | D16: 15(9) | E16: 33507.5 | G16: =E16*300% -> 100522.5 | H16: =E16*7.5% -> 2513.0625 | I16: 40122.19 | J16: =E16*50% -> 16753.75 | K16: =E16*350% -> 117276.25 | L16: =E16*100% -> 33507.5 | N16: =80000 -> 80000 | O16: =E16*10% -> 3350.75 | P16: 20000 | Q16: 0 | R16: =Q16+P16+O16+N16+M16+L16+K16+J16+I16+H16+G16+F16+E16 -> 447553.5 | T16: =20000 -> 20000 | U16: =179017.51 -> 179017.51 | V16: ='[3]DECEMBER 2019'!$H$35 -> 837.6875 | W16: 15548.33 | X16: =W16+V16+U16+T16+S16 -> 215403.53 | Y16: 232149.97 | Z16: =R16-X16 -> 232149.97
A17: 9 | B17: ANDRAWUS MUSA | C17: ASST. DIRECTOR, STORE | D17: 15(9) | E17: 33507.5 | G17: =E17*300% -> 100522.5 | H17: =E17*7.5% -> 2513.0625 | I17: =40122.19 -> 40122.19 | J17: =E17*50% -> 16753.75 | K17: =E17*350% -> 117276.25 | L17: =E17*100% -> 33507.5 | N17: =80000 -> 80000 | O17: =E17*10% -> 3350.75 | P17: 20000 | Q17: 0 | R17: =SUM(E17:Q17) -> 447553.5 | T17: =50000 -> 50000 | U17: =90000 -> 90000 | V17: ='[2]April 2022'!$H$28 -> 837.6875 | W17: =15548.33 -> 15548.33 | X17: =W17+V17+U17+T17+S17 -> 156386.02 | Y17: 291198.59 | Z17: =R17-X17 -> 291167.48
A18: 10 | B18: AYOBOLU OLAJIDE OLUFUNSHO | C18: ASST.DIR., INFORMATION | D18: 15 (7) | E18: 31018.84 | G18: =E18*300% -> 93056.52 | H18: =E18*7.5% -> 2326.413 | I18: 40122.19 | J18: =E18*50% -> 15509.42 | K18: =E18*350% -> 108565.94 | L18: =E18*100% -> 31018.84 | N18: =80000 -> 80000 | O18: =E18*10% -> 3101.884 | P18: 20000 | Q18: 0 | R18: =Q18+P18+O18+N18+M18+L18+K18+J18+I18+H18+G18+F18+E18 -> 424720.05 | T18: =50000 -> 50000 | U18: =59583.33 -> 59583.33 | W18: 15548.33 | X18: =W18+V18+U18+T18+S18 -> 125131.66 | Y18: 299588.39 | Z18: =R18-X18 -> 299588.39
A19: 11 | B19: HUSSEIN EGYE MUSA | C19: CHIEF PROTOCOL OFFICER | D19: 14(9) | E19: 26732.65 | G19: =E19*300% -> 80197.95 | H19: =E19*7.5% -> 2004.9488 | J19: =E19*50% -> 13366.325 | K19: =E19*350% -> 93564.275 | L19: =E19*100% -> 26732.65 | N19: =70000 -> 70000 | O19: =E19*10% -> 2673.265 | P19: 20000 | Q19: 50000 | R19: =Q19+P19+O19+N19+M19+L19+K19+J19+I19+H19+G19+F19+E19 -> 385272.06 | T19: 50000 | U19: =150000 -> 150000 | V19: 0 | W19: 7709.76 | X19: =W19+V19+U19+T19+S19 -> 207709.76 | Y19: 177562.3 | Z19: =R19-X19 -> 177562.3
A20: 12 | B20: DONALD E. MKPANAM | C20: CHIEF ICT OFFICER | D20: 14(9) | E20: 26732.65 | G20: =E20*300% -> 80197.95 | H20: =E20*7.5% -> 2004.9488 | J20: =E20*50% -> 13366.325 | K20: =E20*350% -> 93564.275 | L20: =E20*100% -> 26732.65 | N20: =70000 -> 70000 | O20: =E20*10% -> 2673.265 | P20: 20000 | Q20: 0 | R20: =Q20+P20+O20+N20+M20+L20+K20+J20+I20+H20+G20+F20+E20 -> 335272.06 | V20: ='[2]April 2022'!$H$27 -> 668.31625 | W20: 7709.76 | X20: =W20+V20+U20+T20+S20 -> 8378.0763 | Y20: 326903.82 | Z20: =R20-X20 -> 326893.99
A21: 13 | B21: JOY HARUNA MAKERI | C21: RESEARCH FELLOW 1 TRAINING | D21: 14(9) | E21: 26732.65 | G21: =E21*300% -> 80197.95 | H21: =E21*7.5% -> 2004.9488 | J21: =E21*50% -> 13366.325 | K21: =E21*350% -> 93564.275 | L21: =E21*100% -> 26732.65 | M21: =140000 -> 140000 | O21: =E21*10% -> 2673.265 | P21: 20000 | Q21: =50000+100000 -> 150000 | R21: =Q21+P21+O21+N21+M21+L21+K21+J21+I21+H21+G21+F21+E21 -> 555272.06 | W21: =7709.76 -> 7709.76 | X21: =W21+V21+U21+T21+S21 -> 7709.76 | Y21: 547562.3 | Z21: =R21-X21 -> 547562.3
A22: 14 | B22: ALI ABDULLAHI | C22: ASST. CHIEF ICT OFFICER | D22: 13(11) | E22: 26339.3 | G22: =E22*300% -> 79017.9 | H22: =E22*7.5% -> 1975.4475 | I22: 0 | J22: =E22*50% -> 13169.65 | K22: =E22*350% -> 92187.55 | L22: =E22*100% -> 26339.3 | N22: =70000 -> 70000 | O22: =E22*10% -> 2633.93 | P22: 15000 | Q22: =0 -> 0 | R22: =Q22+P22+O22+N22+M22+L22+K22+J22+I22+H22+G22+F22+E22 -> 326663.08 | W22: =7709.76 -> 7709.76 | X22: =W22+V22+U22+T22+S22 -> 7709.76 | Y22: 318953.32 | Z22: =R22-X22 -> 318953.32
A23: 15 | B23: MARIAM MOHAMMED BELLO | C23: SA- SPECIAL DUTIES | D23: 13 (7) | E23: =39662.25 -> 39662.25 | G23: =E23*300% -> 118986.75 | H23: =E23*7.5% -> 2974.6687 | I23: 0 | J23: =E23*50% -> 19831.125 | K23: =E23*350% -> 138817.88 | L23: =E23*100% -> 39662.25 | N23: =90000 -> 90000 | O23: =E23*10% -> 3966.225 | P23: 15000 | Q23: =100000+100000 -> 200000 | R23: =Q23+P23+O23+N23+M23+L23+K23+J23+I23+H23+G23+F23+E23 -> 668901.14 | W23: 21618.09 | X23: =W23+V23+U23+T23+S23 -> 21618.09 | Y23: 489003.27 | Z23: =R23-X23 -> 647283.05
A24: 16 | B24: PERCY TERFA GBAHABO | C24: HEAD, NILDS LIAISON OFFICE | D24: 13(8) | E24: 23891.12 | G24: =E24*300% -> 71673.36 | H24: =E24*7.5% -> 1791.834 | I24: 0 | J24: =E24*50% -> 11945.56 | K24: =E24*350% -> 83618.92 | L24: =E24*100% -> 23891.12 | M24: =120000 -> 120000 | O24: =E24*10% -> 2389.112 | P24: 15000 | Q24: 0 | R24: =Q24+P24+O24+N24+M24+L24+K24+J24+I24+H24+G24+F24+E24 -> 354201.03 | T24: =70000 -> 70000 | U24: =98464.26 -> 98464.26 | W24: =7709.76 -> 7709.76 | X24: =W24+V24+U24+T24+S24 -> 176174.02 | Y24: 238027.01 | Z24: =R24-X24 -> 178027.01
A25: 17 | B25: ADUGBA RICHARD TERSEER | C25: INFORMATION OFFICER | D25: 10(10) | E25: 18779.3 | G25: =E25*300% -> 56337.9 | H25: =E25*7.5% -> 1408.4475 | J25: =E25*50% -> 9389.65 | K25: =E25*350% -> 65727.55 | L25: =E25*100% -> 18779.3 | N25: =60000 -> 60000 | O25: =E25*10% -> 1877.93 | P25: 10000 | R25: =Q25+P25+O25+N25+M25+L25+K25+J25+I25+H25+G25+F25+E25 -> 242300.08 | T25: =20000 -> 20000 | U25: =111833.33 -> 111833.33 | W25: 3369.51 | X25: =W25+V25+U25+T25+S25 -> 135202.84 | Y25: 107097.24 | Z25: =R25-X25 -> 107097.24
A26: 18 | B26: CHRISTIAN MADUABUCHI ODO | C26: PRINCIPAL ICT OFFICER | D26: 12(8) | E26: =21520.88 -> 21520.88 | G26: =E26*300% -> 64562.64 | H26: =E26*7.5% -> 1614.066 | J26: =E26*50% -> 10760.44 | K26: =E26*350% -> 75323.08 | L26: =E26*100% -> 21520.88 | N26: =60000 -> 60000 | O26: =E26*10% -> 2152.088 | P26: 15000 | R26: =Q26+P26+O26+N26+M26+L26+K26+J26+I26+H26+G26+F26+E26 -> 272454.07 | T26: =20000 -> 20000 | U26: =82500 -> 82500 | V26: ='[2]April 2022'!$H$45 -> 538.022 | W26: 3369.51 | X26: =W26+V26+U26+T26+S26 -> 106407.53 | Y26: 166102.64 | Z26: =R26-X26 -> 166046.54
A27: 19 | B27: HASSANA AHMED IBRAHIM | C27: PA- TO DG | D27: 13 (7) | E27: 23074.99 | G27: =E27*300% -> 69224.97 | H27: =E27*7.5% -> 1730.6243 | J27: =E27*50% -> 11537.495 | K27: =E27*350% -> 80762.465 | L27: =E27*100% -> 23074.99 | M27: =100000 -> 100000 | O27: =E27*10% -> 2307.499 | P27: 10000 | Q27: =100000 -> 100000 | R27: =Q27+P27+O27+N27+M27+L27+K27+J27+I27+H27+G27+F27+E27 -> 421713.03 | T27: =30000 -> 30000 | V27: ='[2]April 2022'!$H$52 -> 576.87475 | W27: =7709.76 -> 7709.76 | X27: =W27+V27+U27+T27+S27 -> 38286.635 | Y27: 383558.67 | Z27: =R27-X27 -> 383426.4
A28: 20 | B28: VICTOR ASUKWO | C28: ICT OFFICER | D28: 8 (10) | E28: 13492.21 | G28: =E28*300% -> 40476.63 | H28: =E28*7.5% -> 1011.9157 | J28: =E28*50% -> 6746.105 | K28: =E28*350% -> 47222.735 | L28: =E28*100% -> 13492.21 | N28: =50000 -> 50000 | O28: =E28*10% -> 1349.221 | P28: 10000 | R28: =Q28+P28+O28+N28+M28+L28+K28+J28+I28+H28+G28+F28+E28 -> 183791.03 | W28: 1484.37 | X28: =W28+V28+U28+T28+S28 -> 1484.37 | Y28: 182306.66 | Z28: =R28-X28 -> 182306.66
A29: 21 | B29: SULEIMAN ABUBAKAR SODEEQ | C29: ASST. ADMIN. OFFICER | D29: 8(7) | E29: 12351.94 | G29: =E29*300% -> 37055.82 | H29: =E29*7.5% -> 926.3955 | J29: =E29*50% -> 6175.97 | K29: =E29*350% -> 43231.79 | L29: =E29*100% -> 12351.94 | N29: =50000 -> 50000 | O29: =E29*10% -> 1235.194 | P29: 10000 | R29: =Q29+P29+O29+N29+M29+L29+K29+J29+I29+H29+G29+F29+E29 -> 173329.05 | W29: =1484.37 -> 1484.37 | X29: =W29+V29+U29+T29+S29 -> 1484.37 | Y29: 171844.68 | Z29: =R29-X29 -> 171844.68
A30: 22 | B30: YAKUB OLUWATOYIN USMAN | C30: ASST. ADMIN. OFFICER | D30: 10(8) | E30: 17784.1 | G30: =E30*300% -> 53352.3 | H30: =E30*7.5% -> 1333.8075 | J30: =E30*50% -> 8892.05 | K30: =E30*350% -> 62244.35 | L30: =E30*100% -> 17784.1 | N30: =60000 -> 60000 | O30: =E30*10% -> 1778.41 | P30: 10000 | R30: =Q30+P30+O30+N30+M30+L30+K30+J30+I30+H30+G30+F30+E30 -> 233169.12 | T30: =10000 -> 10000 | U30: =34333.33 -> 34333.33 | W30: =1484.37 -> 1484.37 | X30: =W30+V30+U30+T30+S30 -> 45817.7 | Y30: 187351.42 | Z30: =R30-X30 -> 187351.42
A31: 23 | B31: ANTHONY EDET | C31: ASST. MGR M&E | D31: 13(9) | E31: 24741.26 | G31: =E31*300% -> 74223.78 | H31: =E31*7.5% -> 1855.5945 | I31: 0 | J31: =E31*50% -> 12370.63 | K31: =E31*350% -> 86594.41 | L31: =E31*100% -> 24741.26 | N31: =70000 -> 70000 | O31: =E31*10% -> 2474.126 | P31: 15000 | Q31: 0 | R31: =Q31+P31+O31+N31+M31+L31+K31+J31+I31+H31+G31+F31+E31 -> 312001.06 | T31: 20000 | U31: =68750 -> 68750 | V31: ='[2]April 2022'!$H$38 -> 618.5315 | W31: =7709.76 -> 7709.76 | X31: =W31+V31+U31+T31+S31 -> 97078.291 | Y31: 214944.02 | Z31: =R31-X31 -> 214922.77
A32: 24 | B32: EGUATU U. ONYEJELEM | C32: OFFICER M&E | D32: 10(10) | E32: 18779.3 | G32: =E32*300% -> 56337.9 | H32: =E32*7.5% -> 1408.4475 | J32: =E32*50% -> 9389.65 | K32: =E32*350% -> 65727.55 | L32: =E32*100% -> 18779.3 | N32: =60000 -> 60000 | O32: =E32*10% -> 1877.93 | P32: 10000 | R32: =Q32+P32+O32+N32+M32+L32+K32+J32+I32+H32+G32+F32+E32 -> 242300.08 | T32: =20000 -> 20000 | U32: =87500+43750 -> 131250 | W32: 3369.51 | X32: =W32+V32+U32+T32+S32 -> 154619.51 | Y32: 87680.567 | Z32: =R32-X32 -> 87680.567
A33: 25 | B33: ODEH SUZIE | C33: ADMIN. OFFICER, LIASION OFFICE | D33: 10(9) | E33: 18281.64 | G33: =E33*300% -> 54844.92 | H33: =E33*7.5% -> 1371.123 | J33: =E33*50% -> 9140.82 | K33: =E33*350% -> 63985.74 | L33: =E33*100% -> 18281.64 | N33: 60000 | O33: =E33*10% -> 1828.164 | P33: 10000 | R33: =Q33+P33+O33+N33+M33+L33+K33+J33+I33+H33+G33+F33+E33 -> 237734.05 | T33: =30000 -> 30000 | V33: =0 -> 0 | W33: 3369.51 | X33: =W33+V33+U33+T33+S33 -> 33369.51 | Y33: 204364.54 | Z33: =R33-X33 -> 204364.54
A34: 26 | B34: IJEOMA NKOLIKWA | C34: ASSISTANT STORES OFFICER | D34: 8(10) | E34: 13492.21 | G34: =E34*300% -> 40476.63 | H34: =E34*7.5% -> 1011.9157 | J34: =E34*50% -> 6746.105 | K34: =E34*350% -> 47222.735 | L34: =E34*100% -> 13492.21 | N34: =50000 -> 50000 | O34: =E34*10% -> 1349.221 | P34: 10000 | R34: =SUM(E34:Q34) -> 183791.03 | T34: =10000 -> 10000 | W34: 1484.37 | X34: =W34+V34+U34+T34+S34 -> 11484.37 | Y34: 172306.66 | Z34: =R34-X34 -> 172306.66
A35: 27 | B35: ABDULRAHMAN A SULAIMAN | C35: ASSISTANT STORES OFFICER | D35: 8 (9) | E35: 13112.16 | G35: =E35*300% -> 39336.48 | H35: =E35*7.5% -> 983.412 | J35: =E35*50% -> 6556.08 | K35: =E35*350% -> 45892.56 | L35: =E35*100% -> 13112.16 | N35: =50000 -> 50000 | O35: =E35*10% -> 1311.216 | P35: 10000 | R35: =SUM(E35:Q35) -> 180304.07 | T35: =20000 -> 20000 | W35: =(1484.37) -> 1484.37 | X35: =W35+V35+U35+T35+S35 -> 21484.37 | Y35: 158819.7 | Z35: =R35-X35 -> 158819.7
A36: 28 | B36: TASSNEEM IBRAHIM | C36: ASSIST. INFORMATION | D36: 8(9) | E36: 13112.16 | G36: =E36*300% -> 39336.48 | H36: =E36*7.5% -> 983.412 | J36: =E36*50% -> 6556.08 | K36: =E36*350% -> 45892.56 | L36: =E36*100% -> 13112.16 | N36: =50000 -> 50000 | O36: =E36*10% -> 1311.216 | P36: 10000 | R36: =Q36+P36+O36+N36+M36+L36+K36+J36+I36+H36+G36+F36+E36 -> 180304.07 | T36: =50000 -> 50000 | U36: =17166.67 -> 17166.67 | V36: =0 -> 0 | W36: =1484.37 -> 1484.37 | X36: =W36+V36+U36+T36+S36 -> 68651.04 | Y36: 111653.03 | Z36: =R36-X36 -> 111653.03
A37: 29 | B37: JIMOH ADEBAYO ZAKA | C37: ASST. OFFICER/COMM | D37: 8(7) | E37: 12351.94 | G37: =E37*300% -> 37055.82 | H37: =E37*7.5% -> 926.3955 | J37: =E37*50% -> 6175.97 | K37: =E37*350% -> 43231.79 | L37: =E37*100% -> 12351.94 | N37: =50000 -> 50000 | O37: =E37*10% -> 1235.194 | P37: 10000 | R37: =Q37+P37+O37+N37+M37+L37+K37+J37+I37+H37+G37+F37+E37 -> 173329.05 | T37: =50000 -> 50000 | V37: =0 -> 0 | W37: =1484.37 -> 1484.37 | X37: =W37+V37+U37+T37+S37 -> 51484.37 | Y37: 121844.68 | Z37: =R37-X37 -> 121844.68
A38: 30 | B38: HABEEBA K MUHAMMAD SALIHU | C38: ASST. OFFICER/COMM | D38: 8(7) | E38: 12351.94 | G38: =E38*300% -> 37055.82 | H38: =E38*7.5% -> 926.3955 | J38: =E38*50% -> 6175.97 | K38: =E38*350% -> 43231.79 | L38: =E38*100% -> 12351.94 | N38: =50000 -> 50000 | O38: =E38*10% -> 1235.194 | P38: 10000 | R38: =Q38+P38+O38+N38+M38+L38+K38+J38+I38+H38+G38+F38+E38 -> 173329.05 | V38: =0 -> 0 | W38: =1484.37 -> 1484.37 | X38: =W38+V38+U38+T38+S38 -> 1484.37 | Y38: 171844.68 | Z38: =R38-X38 -> 171844.68
B39: TOTAL | C39: 30 | E39: =SUM(E9:E38) -> 934067.33 | G39: =SUM(G9:G38) -> 2641713.2 | H39: =SUM(H9:H38) -> 106165.02 | I39: =SUM(I9:I38) -> 521588.47 | J39: =SUM(J9:J38) -> 459009.23 | K39: =SUM(K9:K38) -> 2707525 | L39: =SUM(L9:L38) -> 893945.15 | M39: =SUM(M9:M38) -> 1170000 | N39: =SUM(N9:N38) -> 1510000 | ... R39: =SUM(R9:R38) -> 12372655 | T39: =SUM(T9:T38) -> 872000 | U39: =SUM(U9:U38) -> 1243037.3 | V39: =SUM(V9:V38) -> 8824.9372 | W39: =SUM(W9:W38) -> 409488.93 | X39: =SUM(X9:X38) -> 2533351.2 | Y39: 9843312.2 | Z39: =SUM(Z9:Z38) -> 9839304
B41: INTERNAL AUDIT
A42: 1 | B42: OSANAIYE DAVID AKINYEMI | C42: DIRECTOR INTERNAL AUDIT | D42: 17(8) | E42: 79039.64 | G42: =E42*300% -> 237118.92 | H42: =E42*7.5% -> 5927.973 | I42: 80244.38 | J42: =E42*50% -> 39519.82 | K42: =E42*350% -> 276638.74 | L42: =E42*100% -> 79039.64 | N42: =100000 -> 100000 | O42: =E42*10% -> 7903.964 | P42: 20000 | R42: =SUM(E42:Q42) -> 925433.08 | T42: =100000 -> 100000 | W42: =(52776.63) -> 52776.63 | X42: =W42+V42+U42+T42+S42 -> 152776.63 | Y42: 772656.45 | Z42: =R42-X42 -> 772656.45
A43: 2 | B43: JAMILA ABDUL | C43: AUDITOR II | D43: 8(7) | E43: 12351.94 | G43: =E43*300% -> 37055.82 | H43: =E43*7.5% -> 926.3955 | J43: =E43*50% -> 6175.97 | K43: =E43*350% -> 43231.79 | L43: =E43*100% -> 12351.94 | N43: =50000 -> 50000 | O43: =E43*10% -> 1235.194 | P43: 10000 | R43: =(Q43+P43+O43+N43+M43+L43+K43+J43+I43+H43+G43+F43+E43)*12/30 -> 69331.62 | V43: =0 -> 0 | W43: 1484.37 | X43: =W43+V43+U43+T43+S43 -> 1484.37 | Z43: =R43-X43 -> 67847.25
...

Sheet MEMO 1
A2: NATIONAL INSTITUTE FOR LEGISLATIVE AND DEMOCRATIC STUDIES
B3: INTERNAL MEMO
A4: INTERNAL MEMO
A6: FROM : DEPUTY DIRECTOR, FINANCE AND ACCOUNTS
A7: THRU: DIRECTOR, FINANCE AND ACCOUNTS
A8: TO: DG
A9: 29TH JANUARY , 2021
A11: SUBJECT: PAYROLL FOR THE MONTH OF JANUARY, 2021
A12: Find below the details of NILDS Staff Payroll for the month of January, 2021
A14: TO: | C14: DIRECTOR, GENERAL
A15: THRU: | C15: DIRECTOR, FINANCE AND ACCOUNT
A16: FROM: | C16: ASST. DIRECTOR, FINANCE AND ACCOUNTS
A17: DATE: | C17: 30th APRIL, 2022
A18: SUBJECT: PAYROLL FOR THE MONTH OF APRIL, 2022
A19: Find below the details of NILDS Staff Payroll for the month of March, 2022
A20: GROSS SALARY FOR APRIL, 2022 | H20: ='April, 2022'!R192 -> 51044021
A21: DEDUCTIONS
A22: COOP SOCIETY DEDUCTIONS | G22: ='April, 2022'!T192 -> 5074500
A23: COOP LOAN RECOVERY | G23: ='April, 2022'!U192 -> 6538580.7
A24: PAYE DEDUCTIONS | G24: ='April, 2022'!W192 -> 1499928.3
A25: NHF DEDUCTIONS | G25: ='April, 2022'!V192 -> 26877.441
A26: TOTAL DEDUCTIONS FOR APRIL, 2022 | H26: =G22+G23+G24+G25 -> 13139886
A27: NET PAY AS PER APRIL, 2022 PAYROLL | H27: =H20-H26 -> 37904134
A28: NET PAY AS PER MARCH, 2022 PAYROLL | H28: ='April, 2022'!Y192 -> 37262687
A29: NET INCREASE/ (DECREASE) IN PAY FOR APRIL, 2022 | H29: =H27-H28 -> 641447.78
A30: ANALYSED AS FOLLOWS:
A31: Effect of Cooperative adjustment for April 2022 | H31: =162612.64+107638.89 -> 270251.53
A32: Net effect of removal of payment of 14 days salary to Emily Ekhide | H32: =70790.75 -> 70790.75
A33: Net effect of NHF adjustment | H33: =809.41 -> 809.41
A34: Net effect of salary adjustment of Maryam Bello from PA to SA | H34: =-158279.78 -> -158279.78
A35: Net effect of salary adjustment of Livinus Nnandi from grade 8 to 9 & 2 months arrears | H35: =-65625 -> -65625
A36: Net effect of enrolment of new Staff Jamila Abdul & 7 others in payrol on pro-rata | H36: =-759394.69 -> -759394.69
H37: =SUM(H31:H36) -> -641447.78
E38: MARCH, 2022 | G38: APRIL, 2022
E39: No. of Staff | F39: N | G39: No. of Staff | H39: N
A40: 1 | B40: Director General's Office | E40: 31 | F40: ='April, 2022'!Y39 -> 9843312.2 | G40: 30 | H40: ='April, 2022'!Z39 -> 9839304
A41: 2 | B41: Internal Audit | E41: 1 | F41: ='April, 2022'!Y44 -> 772656.45 | G41: 2 | H41: ='April, 2022'!Z44 -> 840503.7
A42: 3 | B42: Legis. Support Services | E42: 9 | F42: ='April, 2022'!Y57 -> 3234095.2 | G42: 10 | H42: ='April, 2022'!Z57 -> 3330671.2
A43: 4 | B43: Legal Services | E43: 2 | F43: ='April, 2022'!Y62 -> 1273021.2 | G43: 2 | H43: ='April, 2022'!Z62 -> 1273021.2
A44: 5 | B44: Democracy and Governance | E44: 12 | F44: ='April, 2022'!Y79 -> 2957372.4 | G44: 14 | H44: ='April, 2022'!Z79 -> 3197709.3
...

Sheet Annual Increement
B3: STAFF PAYROLL FOR THE MONTH OF DECEMBER, 2021
F4: ='[1]FEB 08'!E8/'[1]FEB 08'!M8 -> 0.22 | I4: ='[1]FEB 08'!F8/'[1]FEB 08'!Q8 -> 0.3
B5: STAFF NAME
D6: DESIGNATION | E6: SALARY | F6: BASIC | M6: MOTOR/ | N6: RESEARCH | O6: HARDSHIP | P6: LEAVE | Q6: OUT FIT | R6: LEGISLATIVE | S6: NEW GROSS | T6: OLD GROSS | U6: DIFFERENCE
E7: LEVEL | F7: SALARY | G7: SALARY/ALLOWCE AREARS | H7: RENT | I7: UTILITY | J7: DOMESTIC | K7: ENTERT. | L7: FURNIT. | M7: FUEL | N7: ALLOWANCE | O7: ALLOWANCE | P7: ALLCE | Q7: ALLCE | R7: DUTY ALLCE | S7: SALARY | T7: SALARY | W7: OLD PAYE | X7: NEW PAYE | Y7: DIFFERENCE
A8: S/N | B8: DG OFFICE | F8: N | I8: N | S8: N | T8: N | U8: N | W8: N | X8: N | Y8: N
A9: 1 | B9: PROF. ABUBAKAR O. SULAIMAN | D9: DIRECTOR GENERAL | E9: CONSOL | F9: 160488.75 | H9: 320977.5 | I9: 48146.63 | J9: 120366.57 | K9: 72219.94 | L9: 0 | M9: 120366.57 | N9: =250000 -> 250000 | P9: 16048.88 | Q9: 25000 | R9: 25235 | S9: =R9+Q9+P9+O9+N9+M9+L9+K9+J9+I9+H9+G9+F9 -> 1158849.8 | T9: 1158849.8 | U9: =S9-T9 -> 0 | W9: 113176.97 | X9: 113176.97 | Y9: =X9-W9 -> 0
A10: 2 | B10: DR ADEYEMI AKEEB FAJINGBESI | D10: DIR. SPECIAL DUTIES, DG OFFICE | E10: 17(9) | F10: 81740.02 | H10: =F10*300% -> 245220.06 | I10: =F10*7.5% -> 6130.5015 | J10: 80244.38 | K10: =F10*50% -> 40870.01 | L10: =F10*350% -> 286090.07 | M10: =F10*100% -> 81740.02 | N10: =200000 -> 200000 | P10: =F10*10% -> 8174.002 | Q10: 20000 | R10: 0 | S10: =R10+Q10+P10+O10+N10+M10+L10+K10+J10+I10+H10+G10+F10 -> 1050209.1 | T10: 1050209.1 | U10: =S10-T10 -> 0 | W10: 52776.63 | X10: 52776.63 | Y10: =X10-W10 -> 0
A11: 3 | B11: SARAFADEEN ALABELEWE | D11: SA- ADMIN | E11: 16(9) | F11: =42653.17 -> 42653.17 | H11: =F11*300% -> 127959.51 | I11: =F11*7.5% -> 3198.9877 | J11: 40122.19 | K11: =F11*50% -> 21326.585 | L11: =F11*350% -> 149286.1 | M11: =F11*100% -> 42653.17 | O11: =90000 -> 90000 | P11: =F11*10% -> 4265.317 | Q11: 20000 | S11: =R11+Q11+P11+O11+N11+M11+L11+K11+J11+I11+H11+G11+F11 -> 541465.02 | T11: 541465.02 | U11: =S11-T11 -> 0 | W11: 21618.09 | X11: 21618.09 | Y11: =X11-W11 -> 0
A12: 4 | B12: DR JAKE DABANG DAN AZUMI | D12: DEPUTY DIRECTOR TRAINING | E12: 16(8) | F12: =41157.69 -> 41157.69 | H12: =F12*300% -> 123473.07 | I12: =F12*7.5% -> 3086.8268 | J12: 40122.19 | K12: =F12*50% -> 20578.845 | L12: =F12*350% -> 144051.92 | M12: =F12*100% -> 41157.69 | N12: =180000 -> 180000 | P12: =F12*10% -> 4115.769 | Q12: 20000 | R12: 150000 | S12: =R12+Q12+P12+O12+N12+M12+L12+K12+J12+I12+H12+G12+F12 -> 767744 | T12: 754023.33 | U12: =S12-T12 -> 13720.662 | W12: =21618.09 -> 21618.09 | X12: 21618.09 | Y12: =X12-W12 -> 0
A13: 5 | B13: DR ABDULSALAM NASIRU NAEEM | D13: SA ACADEMICS | E13: 16(8) | F13: =41157.69 -> 41157.69 | H13: =F13*300% -> 123473.07 | I13: =F13*7.5% -> 3086.8268 | J13: 40122.19 | K13: =F13*50% -> 20578.845 | L13: =F13*350% -> 144051.92 | M13: =F13*100% -> 41157.69 | N13: =180000 -> 180000 | P13: =F13*10% -> 4115.769 | Q13: 20000 | R13: =100000 -> 100000 | S13: =R13+Q13+P13+O13+N13+M13+L13+K13+J13+I13+H13+G13+F13 -> 717744 | T13: 704023.33 | U13: =S13-T13 -> 13720.662 | W13: =21618.09 -> 21618.09 | X13: 21618.09 | Y13: =X13-W13 -> 0
A14: 6 | B14: RAHEEM USMAN AYIGORO | D14: SA-INFRASTRUCTURE | E14: 16 (8) | F14: =41157.69 -> 41157.69 | H14: =F14*300% -> 123473.07 | I14: =F14*7.5% -> 3086.8268 | J14: 40122.19 | K14: =F14*50% -> 20578.845 | L14: =F14*350% -> 144051.92 | M14: =F14*100% -> 41157.69 | O14: =90000 -> 90000 | P14: =F14*10% -> 4115.769 | Q14: 20000 | R14: 0 | S14: =R14+Q14+P14+O14+N14+M14+L14+K14+J14+I14+H14+G14+F14 -> 527744 | T14: 514023.33 | U14: =S14-T14 -> 13720.662 | W14: =21618.09 -> 21618.09 | X14: 21618.09 | Y14: =X14-W14 -> 0
A15: 7 | B15: AKINSANMI ADEJOKE OLUKEMI | D15: HEAD INFORMATION/PROTOCOL | E15: 15(9) | F15: 33507.5 | H15: =F15*300% -> 100522.5 | I15: =F15*7.5% -> 2513.0625 | J15: 40122.19 | K15: =F15*50% -> 16753.75 | L15: =F15*350% -> 117276.25 | M15: =F15*100% -> 33507.5 | O15: =80000 -> 80000 | P15: =F15*10% -> 3350.75 | Q15: 20000 | R15: =100000 -> 100000 | S15: =R15+Q15+P15+O15+N15+M15+L15+K15+J15+I15+H15+G15+F15 -> 547553.5 | T15: 547553.5 | U15: =S15-T15 -> 0 | W15: 15548.33 | X15: 15548.33 | Y15: =X15-W15 -> 0
A16: 8 | B16: DR IKEME ARTHUR J.O | D16: SNR RESEARCH FELLOW | E16: 15(9) | F16: =33507.5 -> 33507.5 | H16: =F16*300% -> 100522.5 | I16: =F16*7.5% -> 2513.0625 | J16: 40122.19 | K16: =F16*50% -> 16753.75 | L16: =F16*350% -> 117276.25 | M16: =F16*100% -> 33507.5 | O16: =80000 -> 80000 | P16: =F16*10% -> 3350.75 | Q16: 20000 | R16: 0 | S16: =R16+Q16+P16+O16+N16+M16+L16+K16+J16+I16+H16+G16+F16 -> 447553.5 | T16: 447553.5 | U16: =S16-T16 -> 0 | W16: 15548.33 | X16: 15548.33 | Y16: =X16-W16 -> 0
A17: 9 | B17: MOSHOOD M. OLALERE | D17: MANAGER ADMIN DG's OFFICE | E17: 15(9) | F17: =33507.5 -> 33507.5 | H17: =F17*300% -> 100522.5 | I17: =F17*7.5% -> 2513.0625 | J17: 40122.19 | K17: =F17*50% -> 16753.75 | L17: =F17*350% -> 117276.25 | M17: =F17*100% -> 33507.5 | O17: =80000 -> 80000 | P17: =F17*10% -> 3350.75 | Q17: 20000 | R17: 0 | S17: =R17+Q17+P17+O17+N17+M17+L17+K17+J17+I17+H17+G17+F17 -> 447553.5 | T17: 447553.5 | U17: =S17-T17 -> 0 | W17: 15548.33 | X17: 15548.33 | Y17: =X17-W17 -> 0
A18: 10 | B18: ANDRAWUS MUSA | D18: ASST. DIRECTOR, STORE | E18: 15(9) | F18: =33507.5 -> 33507.5 | H18: =F18*300% -> 100522.5 | I18: =F18*7.5% -> 2513.0625 | J18: =40122.19 -> 40122.19 | K18: =F18*50% -> 16753.75 | L18: =F18*350% -> 117276.25 | M18: =F18*100% -> 33507.5 | O18: =80000 -> 80000 | P18: =F18*10% -> 3350.75 | Q18: 20000 | R18: 0 | S18: =SUM(F18:R18) -> 447553.5 | T18: 436137.05 | U18: =S18-T18 -> 11416.452 | W18: =15548.33 -> 15548.33 | X18: 15548.33 | Y18: =X18-W18 -> 0
A19: 11 | B19: AYOBOLU OLAJIDE OLUFUNSHO | D19: ASST.DIR., INFORMATION | E19: 15 (7) | F19: 31018.84 | H19: =F19*300% -> 93056.52 | I19: =F19*7.5% -> 2326.413 | J19: 40122.19 | K19: =F19*50% -> 15509.42 | L19: =F19*350% -> 108565.94 | M19: =F19*100% -> 31018.84 | O19: =80000 -> 80000 | P19: =F19*10% -> 3101.884 | Q19: 20000 | R19: 0 | S19: =R19+Q19+P19+O19+N19+M19+L19+K19+J19+I19+H19+G19+F19 -> 424720.05 | T19: 424720.05 | U19: =S19-T19 -> 0 | W19: 15548.33 | X19: 15548.33 | Y19: =X19-W19 -> 0
A20: 12 | B20: HUSSEIN EGYE MUSA | D20: CHIEF PROTOCOL OFFICER | E20: 14(9) | F20: =26732.65 -> 26732.65 | H20: =F20*300% -> 80197.95 | I20: =F20*7.5% -> 2004.9488 | K20: =F20*50% -> 13366.325 | L20: =F20*350% -> 93564.275 | M20: =F20*100% -> 26732.65 | O20: =70000 -> 70000 | P20: =F20*10% -> 2673.265 | Q20: 20000 | R20: 50000 | S20: =R20+Q20+P20+O20+N20+M20+L20+K20+J20+I20+H20+G20+F20 -> 385272.06 | T20: 377211.37 | U20: =S20-T20 -> 8060.6963 | W20: 7709.76 | X20: 7709.76 | Y20: =X20-W20 -> 0
A21: 13 | B21: DONALD E. MKPANAM | D21: CHIEF ICT OFFICER | E21: 14(9) | F21: =26732.65 -> 26732.65 | H21: =F21*300% -> 80197.95 | I21: =F21*7.5% -> 2004.9488 | K21: =F21*50% -> 13366.325 | L21: =F21*350% -> 93564.275 | M21: =F21*100% -> 26732.65 | O21: =70000 -> 70000 | P21: =F21*10% -> 2673.265 | Q21: 20000 | R21: 0 | S21: =R21+Q21+P21+O21+N21+M21+L21+K21+J21+I21+H21+G21+F21 -> 335272.06 | T21: 327211.37 | U21: =S21-T21 -> 8060.6963 | W21: 7709.76 | X21: 7709.76 | Y21: =X21-W21 -> 0
A22: 14 | B22: JOY HARUNA MAKERI | D22: RESEARCH FELLOW 1 TRAINING | E22: 14(9) | F22: =26732.65 -> 26732.65 | H22: =F22*300% -> 80197.95 | I22: =F22*7.5% -> 2004.9488 | K22: =F22*50% -> 13366.325 | L22: =F22*350% -> 93564.275 | M22: =F22*100% -> 26732.65 | N22: =140000 -> 140000 | P22: =F22*10% -> 2673.265 | Q22: 20000 | R22: =50000+100000 -> 150000 | S22: =R22+Q22+P22+O22+N22+M22+L22+K22+J22+I22+H22+G22+F22 -> 555272.06 | T22: 547211.37 | U22: =S22-T22 -> 8060.6963 | W22: =7709.76 -> 7709.76 | X22: 7709.76 | Y22: =X22-W22 -> 0
A23: 15 | B23: ALI ABDULLAHI | D23: ASST. CHIEF ICT OFFICER | E23: 13(11) | F23: =26339.3 -> 26339.3 | H23: =F23*300% -> 79017.9 | I23: =F23*7.5% -> 1975.4475 | J23: 0 | K23: =F23*50% -> 13169.65 | L23: =F23*350% -> 92187.55 | M23: =F23*100% -> 26339.3 | O23: =70000 -> 70000 | P23: =F23*10% -> 2633.93 | Q23: 15000 | R23: =0 -> 0 | S23: =R23+Q23+P23+O23+N23+M23+L23+K23+J23+I23+H23+G23+F23 -> 326663.08 | T23: 326663.08 | U23: =S23-T23 -> 0 | W23: =7709.76 -> 7709.76 | X23: 7709.76 | Y23: =X23-W23 -> 0
A24: 16 | B24: MARIAM MOHAMMED BELLO | D24: PA- SPECIAL DUTIES | E24: 13 (7) | F24: =23074.99 -> 23074.99 | H24: =F24*300% -> 69224.97 | I24: =F24*7.5% -> 1730.6243 | J24: =265272 -> 265272 | K24: =F24*50% -> 11537.495 | L24: =F24*350% -> 80762.465 | M24: =F24*100% -> 23074.99 | O24: =70000 -> 70000 | P24: =F24*10% -> 2307.499 | Q24: 15000 | R24: =100000+100000 -> 200000 | S24: =R24+Q24+P24+O24+N24+M24+L24+K24+J24+I24+H24+G24+F24 -> 761985.03 | T24: 761985.03 | U24: =S24-T24 -> 0 | W24: =7709.76 -> 7709.76 | X24: 7709.76 | Y24: =X24-W24 -> 0
A25: 17 | B25: PERCY TERFA GBAHABO | D25: HEAD, NILDS LIAISON OFFICE | E25: 13(8) | F25: =23891.12 -> 23891.12 | H25: =F25*300% -> 71673.36 | I25: =F25*7.5% -> 1791.834 | J25: 0 | K25: =F25*50% -> 11945.56 | L25: =F25*350% -> 83618.92 | M25: =F25*100% -> 23891.12 | N25: =120000 -> 120000 | P25: =F25*10% -> 2389.112 | Q25: 15000 | R25: 0 | S25: =R25+Q25+P25+O25+N25+M25+L25+K25+J25+I25+H25+G25+F25 -> 354201.03 | T25: 346713.03 | U25: =S25-T25 -> 7487.9928 | W25: =7709.76 -> 7709.76 | X25: 7709.76 | Y25: =X25-W25 -> 0
A26: 18 | B26: ADUGBA RICHARD TERSEER | D26: INFORMATION OFFICER | E26: 10(10) | F26: =18779.3 -> 18779.3 | H26: =F26*300% -> 56337.9 | I26: =F26*7.5% -> 1408.4475 | K26: =F26*50% -> 9389.65 | L26: =F26*350% -> 65727.55 | M26: =F26*100% -> 18779.3 | O26: =60000 -> 60000 | P26: =F26*10% -> 1877.93 | Q26: 10000 | S26: =R26+Q26+P26+O26+N26+M26+L26+K26+J26+I26+H26+G26+F26 -> 242300.08 | T26: 237734.05 | U26: =S26-T26 -> 4566.0305 | W26: 3369.51 | X26: 3369.51 | Y26: =X26-W26 -> 0
A27: 19 | B27: CHRISTIAN MADUABUCHI ODO | D27: PRINCIPAL ICT OFFICER | E27: 12(8) | F27: =21520.88 -> 21520.88 | H27: =F27*300% -> 64562.64 | I27: =F27*7.5% -> 1614.066 | K27: =F27*50% -> 10760.44 | L27: =F27*350% -> 75323.08 | M27: =F27*100% -> 21520.88 | O27: =60000 -> 60000 | P27: =F27*10% -> 2152.088 | Q27: 15000 | S27: =R27+Q27+P27+O27+N27+M27+L27+K27+J27+I27+H27+G27+F27 -> 272454.07 | T27: 265372.07 | U27: =S27-T27 -> 7081.999 | W27: 3369.51 | X27: 3369.51 | Y27: =X27-W27 -> 0
A28: 20 | B28: HASSANA AHMED IBRAHIM | D28: PA- TO DG | E28: 10(9) | F28: =18281.64 -> 18281.64 | H28: =F28*300% -> 54844.92 | I28: =F28*7.5% -> 1371.123 | K28: =F28*50% -> 9140.82 | L28: =F28*350% -> 63985.74 | M28: =F28*100% -> 18281.64 | N28: =100000 -> 100000 | P28: =F28*10% -> 1828.164 | Q28: 10000 | R28: =100000 -> 100000 | S28: =R28+Q28+P28+O28+N28+M28+L28+K28+J28+I28+H28+G28+F28 -> 377734.05 | T28: 373168.2 | U28: =S28-T28 -> 4565.847 | W28: 3369.51 | X28: 3369.51 | Y28: =X28-W28 -> 0
A29: 21 | B29: VICTOR ASUKWO | D29: ICT OFFICER | E29: 8 (10) | F29: =13492.21 -> 13492.21 | H29: =F29*300% -> 40476.63 | I29: =F29*7.5% -> 1011.9157 | K29: =F29*50% -> 6746.105 | L29: =F29*350% -> 47222.735 | M29: =F29*100% -> 13492.21 | O29: =50000 -> 50000 | P29: =F29*10% -> 1349.221 | Q29: 10000 | S29: =R29+Q29+P29+O29+N29+M29+L29+K29+J29+I29+H29+G29+F29 -> 183791.03 | T29: 180304.07 | U29: =S29-T29 -> 3486.9587 | W29: 1484.37 | X29: 1484.37 | Y29: =X29-W29 -> 0
A30: 22 | B30: SULEIMAN ABUBAKAR SODEEQ | D30: ASST. ADMIN. OFFICER | E30: 8(7) | F30: =12351.94 -> 12351.94 | H30: =F30*300% -> 37055.82 | I30: =F30*7.5% -> 926.3955 | K30: =F30*50% -> 6175.97 | L30: =F30*350% -> 43231.79 | M30: =F30*100% -> 12351.94 | O30: =50000 -> 50000 | P30: =F30*10% -> 1235.194 | Q30: 10000 | S30: =R30+Q30+P30+O30+N30+M30+L30+K30+J30+I30+H30+G30+F30 -> 173329.05 | T30: 173329.05 | U30: =S30-T30 -> 0 | W30: =1484.37 -> 1484.37 | X30: 1484.37 | Y30: =X30-W30 -> 0
A31: 23 | B31: YAKUB OLUWATOYIN USMAN | D31: ASST. ADMIN. OFFICER | E31: 10(8) | F31: =17784.1 -> 17784.1 | H31: =F31*300% -> 53352.3 | I31: =F31*7.5% -> 1333.8075 | K31: =F31*50% -> 8892.05 | L31: =F31*350% -> 62244.35 | M31: =F31*100% -> 17784.1 | O31: =60000 -> 60000 | P31: =F31*10% -> 1778.41 | Q31: 10000 | S31: =R31+Q31+P31+O31+N31+M31+L31+K31+J31+I31+H31+G31+F31 -> 233169.12 | T31: 228602.08 | U31: =S31-T31 -> 4567.0397 | W31: =1484.37 -> 1484.37 | X31: 1484.37 | Y31: =X31-W31 -> 0
A32: 24 | B32: ANTHONY EDET | D32: ASST. MGR M&E | E32: 13(9) | F32: =24741.26 -> 24741.26 | H32: =F32*300% -> 74223.78 | I32: =F32*7.5% -> 1855.5945 | J32: 0 | K32: =F32*50% -> 12370.63 | L32: =F32*350% -> 86594.41 | M32: =F32*100% -> 24741.26 | O32: =70000 -> 70000 | P32: =F32*10% -> 2474.126 | Q32: 15000 | R32: 0 | S32: =R32+Q32+P32+O32+N32+M32+L32+K32+J32+I32+H32+G32+F32 -> 312001.06 | T32: 304201.03 | U32: =S32-T32 -> 7800.0345 | W32: =7709.76 -> 7709.76 | X32: 7709.76 | Y32: =X32-W32 -> 0
A33: 25 | B33: EGUATU U. ONYEJELEM | D33: OFFICER M&E | E33: 10(10) | F33: =18779.3 -> 18779.3 | H33: =F33*300% -> 56337.9 | I33: =F33*7.5% -> 1408.4475 | K33: =F33*50% -> 9389.65 | L33: =F33*350% -> 65727.55 | M33: =F33*100% -> 18779.3 | O33: =60000 -> 60000 | P33: =F33*10% -> 1877.93 | Q33: 10000 | S33: =R33+Q33+P33+O33+N33+M33+L33+K33+J33+I33+H33+G33+F33 -> 242300.08 | T33: 237734.05 | U33: =S33-T33 -> 4566.0305 | W33: 3369.51 | X33: 3369.51 | Y33: =X33-W33 -> 0
A34: 26 | B34: ODEH SUZIE | D34: ADMIN. OFFICER, LIASION OFFICE | E34: 10(9) | F34: =18281.64 -> 18281.64 | H34: =F34*300% -> 54844.92 | I34: =F34*7.5% -> 1371.123 | K34: =F34*50% -> 9140.82 | L34: =F34*350% -> 63985.74 | M34: =F34*100% -> 18281.64 | O34: 60000 | P34: =F34*10% -> 1828.164 | Q34: 10000 | S34: =R34+Q34+P34+O34+N34+M34+L34+K34+J34+I34+H34+G34+F34 -> 237734.05 | T34: 233168.2 | U34: =S34-T34 -> 4565.847 | W34: 3369.51 | X34: 3369.51 | Y34: =X34-W34 -> 0
A35: 27 | B35: IJEOMA NKOLIKWA | D35: ASSISTANT STORES OFFICER | E35: 8(10) | F35: =13492.21 -> 13492.21 | H35: =F35*300% -> 40476.63 | I35: =F35*7.5% -> 1011.9157 | K35: =F35*50% -> 6746.105 | L35: =F35*350% -> 47222.735 | M35: =F35*100% -> 13492.21 | O35: =50000 -> 50000 | P35: =F35*10% -> 1349.221 | Q35: 10000 | S35: =SUM(F35:R35) -> 183791.03 | T35: 180304.07 | U35: =S35-T35 -> 3486.9587 | W35: 1484.37 | X35: 1484.37 | Y35: =X35-W35 -> 0
A36: 28 | B36: ABDULRAHMAN A SULAIMAN | D36: ASSISTANT STORES OFFICER | E36: 8 (9) | F36: =13112.16 -> 13112.16 | H36: =F36*300% -> 39336.48 | I36: =F36*7.5% -> 983.412 | K36: =F36*50% -> 6556.08 | L36: =F36*350% -> 45892.56 | M36: =F36*100% -> 13112.16 | O36: =50000 -> 50000 | P36: =F36*10% -> 1311.216 | Q36: 10000 | S36: =SUM(F36:R36) -> 180304.07 | T36: 176816.1 | U36: =S36-T36 -> 3487.968 | W36: =(1484.37) -> 1484.37 | X36: 1484.37 | Y36: =X36-W36 -> 0
A37: 29 | B37: TASSNEEM IBRAHIM | D37: ASSIST. INFORMATION | E37: 8(9) | F37: =13112.16 -> 13112.16 | H37: =F37*300% -> 39336.48 | I37: =F37*7.5% -> 983.412 | K37: =F37*50% -> 6556.08 | L37: =F37*350% -> 45892.56 | M37: =F37*100% -> 13112.16 | O37: =50000 -> 50000 | P37: =F37*10% -> 1311.216 | Q37: 10000 | S37: =R37+Q37+P37+O37+N37+M37+L37+K37+J37+I37+H37+G37+F37 -> 180304.07 | T37: 176816.1 | U37: =S37-T37 -> 3487.968 | W37: =1484.37 -> 1484.37 | X37: 1484.37 | Y37: =X37-W37 -> 0
A38: 30 | B38: JIMOH ADEBAYO ZAKA | D38: ASST. OFFICER/COMM | E38: 8(7) | F38: =12351.94 -> 12351.94 | H38: =F38*300% -> 37055.82 | I38: =F38*7.5% -> 926.3955 | K38: =F38*50% -> 6175.97 | L38: =F38*350% -> 43231.79 | M38: =F38*100% -> 12351.94 | O38: =50000 -> 50000 | P38: =F38*10% -> 1235.194 | Q38: 10000 | S38: =R38+Q38+P38+O38+N38+M38+L38+K38+J38+I38+H38+G38+F38 -> 173329.05 | T38: 173329.05 | U38: =S38-T38 -> 0 | W38: =1484.37 -> 1484.37 | X38: 1484.37 | Y38: =X38-W38 -> 0
B39: TOTAL | D39: 30 | F39: =SUM(F9:F38) -> 942987.95 | G39: =SUM(G9:G38) -> 0 | H39: =SUM(H9:H38) -> 2668475.1 | I39: =SUM(I9:I38) -> 106834.07 | J39: =SUM(J9:J38) -> 826982.66 | K39: =SUM(K9:K38) -> 463469.54 | L39: =SUM(L9:L38) -> 2738747.2 | M39: =SUM(M9:M38) -> 902865.77 | ... S39: =SUM(S9:S38) -> 12789896 | T39: 12388713 | U39: =SUM(U9:U38) -> 135911.2 | W39: =SUM(W9:W38) -> 411374.07 | X39: 411374.07 | Y39: =X39-W39 -> 0
U40: =S40-T40 -> 0 | Y40: =X40-W40 -> 0
B41: INTERNAL AUDIT | U41: =S41-T41 -> 0 | Y41: =X41-W41 -> 0
A42: 1 | B42: OSANAIYE DAVID AKINYEMI | D42: DIRECTOR INTERNAL AUDIT | E42: 17(8) | F42: =79039.64 -> 79039.64 | H42: =F42*300% -> 237118.92 | I42: =F42*7.5% -> 5927.973 | J42: 80244.38 | K42: =F42*50% -> 39519.82 | L42: =F42*350% -> 276638.74 | M42: =F42*100% -> 79039.64 | O42: =100000 -> 100000 | P42: =F42*10% -> 7903.964 | Q42: 20000 | S42: =SUM(F42:R42) -> 925433.08 | T42: 900657.46 | U42: =S42-T42 -> 24775.619 | W42: =(52776.63) -> 52776.63 | X42: 52776.63 | Y42: =X42-W42 -> 0
...

Sheet Enhanced Welfare 2022
B3: STAFF PAYROLL FOR THE MONTH OF FEBRUARY 2022
B5: STAFF NAME
D6: DESIGNATION | E6: SALARY
E7: LEVEL | G7: 15 and Above | H7: 9 to 14 | I7: 8 and Below
A8: S/N | B8: DG OFFICE | F8: N | H8: N | I8: N
A9: 1 | B9: PROF. ABUBAKAR O. SULAIMAN | D9: DIRECTOR GENERAL | E9: CONSOL | F9: =2000000 -> 2000000 | G9: =F9 -> 2000000
A10: 2 | B10: DR ADEYEMI AKEEB FAJINGBESI | D10: DIR. SPECIAL DUTIES, DG OFFICE | E10: 17(9) | F10: =1000000 -> 1000000 | G10: =F10 -> 1000000
A11: 3 | B11: DR JAKE DABANG DAN AZUMI | D11: DEPUTY DIRECTOR TRAINING | E11: 16(8) | F11: =700000 -> 700000 | G11: =F11 -> 700000
A12: 4 | B12: DR ABDULSALAM NASIRU NAEEM | D12: SA ACADEMICS | E12: 16(8) | F12: =700000 -> 700000 | G12: =F12 -> 700000
A13: 5 | B13: RAHEEM USMAN AYIGORO | D13: SA-INFRASTRUCTURE | E13: 16 (8) | F13: =350000 -> 350000 | G13: =F13 -> 350000
A14: 6 | B14: AKINSANMI ADEJOKE OLUKEMI | D14: HEAD INFORMATION/PROTOCOL | E14: 15(9) | F14: =700000 -> 700000 | G14: =F14 -> 700000
A15: 7 | B15: DR IKEME ARTHUR J.O | D15: SNR RESEARCH FELLOW | E15: 15(9) | F15: =700000 -> 700000 | G15: =F15 -> 700000
A16: 8 | B16: MOSHOOD M. OLALERE | D16: MANAGER ADMIN DG's OFFICE | E16: 15(9) | F16: =700000 -> 700000 | G16: =F16 -> 700000
A17: 9 | B17: ANDRAWUS MUSA | D17: ASST. DIRECTOR, STORE | E17: 15(9) | F17: =700000 -> 700000 | G17: =F17 -> 700000
A18: 10 | B18: AYOBOLU OLAJIDE OLUFUNSHO | D18: ASST.DIR., INFORMATION | E18: 15 (7) | F18: =700000 -> 700000 | G18: =F18 -> 700000
A19: 11 | B19: HUSSEIN EGYE MUSA | D19: CHIEF PROTOCOL OFFICER | E19: 14(9) | F19: 500000 | H19: 500000
A20: 12 | B20: DONALD E. MKPANAM | D20: CHIEF ICT OFFICER | E20: 14(9) | F20: 500000 | H20: 500000
A21: 13 | B21: JOY HARUNA MAKERI | D21: RESEARCH FELLOW 1 TRAINING | E21: 14(9) | F21: 500000 | H21: 500000
A22: 14 | B22: ALI ABDULLAHI | D22: ASST. CHIEF ICT OFFICER | E22: 13(11) | F22: 500000 | H22: 500000
A23: 15 | B23: MARIAM MOHAMMED BELLO | D23: PA- SPECIAL DUTIES | E23: 13 (7) | F23: 500000 | H23: 500000
A24: 16 | B24: PERCY TERFA GBAHABO | D24: HEAD, NILDS LIAISON OFFICE | E24: 13(8) | F24: 500000 | H24: 500000
A25: 17 | B25: ADUGBA RICHARD TERSEER | D25: INFORMATION OFFICER | E25: 10(10) | F25: 300000 | H25: 300000
A26: 18 | B26: CHRISTIAN MADUABUCHI ODO | D26: PRINCIPAL ICT OFFICER | E26: 12(8) | F26: =400000 -> 400000 | H26: =400000 -> 400000
A27: 19 | B27: HASSANA AHMED IBRAHIM | D27: PA- TO DG | E27: 10(9) | F27: 300000 | H27: =500000 -> 500000
A28: 20 | B28: VICTOR ASUKWO | D28: ICT OFFICER | E28: 8 (10) | F28: 300000 | I28: 300000
A29: 21 | B29: SULEIMAN ABUBAKAR SODEEQ | D29: ASST. ADMIN. OFFICER | E29: 8(7) | F29: 300000 | I29: 300000
A30: 22 | B30: YAKUB OLUWATOYIN USMAN | D30: ASST. ADMIN. OFFICER | E30: 10(8) | F30: 300000 | H30: 300000
A31: 23 | B31: ANTHONY EDET | D31: ASST. MGR M&E | E31: 13(9) | F31: 500000 | H31: 500000
A32: 24 | B32: EGUATU U. ONYEJELEM | D32: OFFICER M&E | E32: 10(10) | F32: 300000 | H32: 300000
A33: 25 | B33: ODEH SUZIE | D33: ADMIN. OFFICER, LIASION OFFICE | E33: 10(9) | F33: 300000 | H33: 300000
A34: 26 | B34: IJEOMA NKOLIKWA | D34: ASSISTANT STORES OFFICER | E34: 8(10) | F34: 300000 | I34: 300000
A35: 27 | B35: ABDULRAHMAN A SULAIMAN | D35: ASSISTANT STORES OFFICER | E35: 8 (9) | F35: 300000 | I35: 300000
A36: 28 | B36: TASSNEEM IBRAHIM | D36: ASSIST. INFORMATION | E36: 8(9) | F36: 300000 | I36: 300000
A37: 29 | B37: JIMOH ADEBAYO ZAKA | D37: ASST. OFFICER/COMM | E37: 8(7) | F37: 300000 | I37: 300000
A38: 30 | B38: HABEEBA K MUHAMMAD SALIHU | D38: ASST. OFFICER/COMM | E38: 8(7) | F38: 300000 | I38: 300000
B39: TOTAL | D39: 30 | F39: =SUM(F9:F38) -> 15750000 | G39: =SUM(G9:G38) -> 8250000 | H39: =SUM(H9:H38) -> 5600000 | I39: =SUM(I9:I38) -> 2100000
B41: INTERNAL AUDIT
A42: 1 | B42: OSANAIYE DAVID AKINYEMI | D42: DIRECTOR INTERNAL AUDIT | E42: 17(8) | F42: =1000000 -> 1000000 | G42: =F42 -> 1000000
C43: TOTAL | D43: 1 | F43: =SUM(F42) -> 1000000 | G43: =SUM(G42) -> 1000000
B45: LEG. SUPPORT SEVICES
...

Sheet 13 month
B3: SCHEDULE OF 13TH MONTH SALARY FOR 3 STAFF FOR YEAR, 2021
