Workbook

Sheet APRIL 2025 NEW
A1: NATIONAL INSTITUTE FOR LEGISLATIVE AND DEMOCRATIC STUDIES
A2: STAFF PAYROLL FOR THE MONTH OF APRIL, 2025 (NEW STAFF)
E3: ='[1]FEB 08'!E11/'[1]FEB 08'!M11 -> #REF!
B4: STAFF NAME | C4: DESIGNATION | D4: GRADE LEVEL | E4: BASIC SALARY | F4: ALLCE/ AREARS | G4: ALLOWANCE | H4: ALLOWANCE | I4: DUTY ALLCE | J4: GROSS SALARY | K4: AUCTION | L4: COOP CONTR/SPEC SAVINGS | M4: COOP. LOAN RECOVERY | N4: NHF DED. | O4: PAYE | P4: EMPLOYEE PENSIONS | Q4: TOTAL DEDUCTION | R4: MARCH, 2025 | S4: APRIL, 2025
E5: N | F5: N | G5: N | H5: N | I5: N | J5: N | K5: N | L5: N | M5: N | N5: N | O5: N | P5: N | Q5: N | R5: N | S5: N
A6: S/N | B6: DG'S OFFICE
A7: 1 | B7: HOLINESS PAUL UDO | C7: ADMINISTRATION OFFICER, M&E | D7: 9(7) | E7: =255849 -> 255849 | H7: =60000 -> 60000 | J7: =E7+F7+G7+H7+I7 -> 315849 | L7: 50000 | O7: 36790.688 | P7: 20467.92 | Q7: =O7+N7+M7+L7+K7+P7 -> 107258.61 | R7: 208590.39 | S7: =J7-Q7 -> 208590.39
A8: 2 | B8: CHARITY UDO AKAN | C8: ADMINISTRATION OFFICER, M&E | D8: 9(7) | E8: =255849 -> 255849 | H8: =60000 -> 60000 | J8: =E8+F8+G8+H8+I8 -> 315849 | L8: 50000 | M8: 15000 | O8: 36790.688 | P8: 20467.92 | Q8: =O8+N8+M8+L8+K8+P8 -> 122258.61 | R8: 208590.39 | S8: =J8-Q8 -> 193590.39
A9: 3 | B9: SANI UMAR IBRAHIM | C9: STORE OFFICER | D9: 9(7) | E9: 255849 | H9: =60000 -> 60000 | J9: =E9+F9+G9+H9+I9 -> 315849 | O9: 36790.688 | P9: 20467.92 | Q9: =O9+N9+M9+L9+K9+P9 -> 57258.608 | R9: 258590.39 | S9: =J9-Q9 -> 258590.39
A10: 4 | B10: EDIDIONG EZEKIEL ATAT | C10: ASSIST PROCUREMENT OFFICER | D10: 8(7) | E10: =218287.583333333 -> 218287.58 | H10: =50000 -> 50000 | J10: =SUM(E10:I10) -> 268287.58 | O10: 29305.196 | P10: 17463.007 | Q10: =O10+N10+M10+L10+K10+P10 -> 46768.202 | R10: 221519.38 | S10: =J10-Q10 -> 221519.38
A11: 5 | B11: ALIYU GARBA LERE | C11: ASSIST INFORMATION OFFICER | D11: 8(7) | E11: =218287.583333333 -> 218287.58 | H11: =50000 -> 50000 | J11: =SUM(E11:I11) -> 268287.58 | O11: 29305.196 | P11: 17463.007 | Q11: =O11+N11+M11+L11+K11+P11 -> 46768.202 | R11: 221519.38 | S11: =J11-Q11 -> 221519.38
B12: TOTAL | C12: 5 | E12: =SUM(E7:E11) -> 1204122.2 | F12: =SUM(F7:F11) -> 0 | G12: =SUM(G7:G11) -> 0 | H12: =SUM(H7:H11) -> 280000 | I12: =SUM(I7:I11) -> 0 | J12: =SUM(J7:J11) -> 1484122.2 | K12: =SUM(K7:K11) -> 0 | L12: =SUM(L7:L11) -> 100000 | ... Q12: =SUM(Q7:Q11) -> 380312.23 | R12: 1118809.9 | S12: =SUM(S7:S11) -> 1103809.9
B14: INTERNAL AUDIT
A15: 1 | B15: HASSAN ABDULHADI | C15: AUDITOR 11 | D15: 10(7) | E15: 293029.67 | H15: 60000 | J15: =SUM(E15:I15) -> 353029.67 | L15: =100000 -> 100000 | O15: 43541.87 | P15: 23442.373 | Q15: =O15+N15+M15+L15+K15+P15 -> 166984.24 | R15: 186045.42 | S15: =J15-Q15 -> 186045.42
C16: 1 | E16: =SUM(E15:E15) -> 293029.67 | F16: =SUM(F15:F15) -> 0 | G16: =SUM(G15:G15) -> 0 | H16: =SUM(H15:H15) -> 60000 | I16: =SUM(I15:I15) -> 0 | J16: =SUM(J15:J15) -> 353029.67 | K16: =SUM(K15:K15) -> 0 | L16: =SUM(L15:L15) -> 100000 | ... Q16: =SUM(Q15:Q15) -> 166984.24 | R16: 186045.42 | S16: =SUM(S15:S15) -> 186045.42
B18: LEG. SUPPORT SEVICES
A19: 1 | B19: UMAR MUSA PADAH | C19: PRINC. RESEARCH OFFICER | D19: 12(7) | E19: =353512.5 -> 353512.5 | G19: =110000 -> 110000 | J19: =SUM(E19:I19) -> 463512.5 | O19: 62231.115 | P19: 28281 | Q19: =O19+N19+M19+L19+K19+P19 -> 90512.115 | R19: 373000.39 | S19: =J19-Q19 -> 373000.39
A20: 2 | B20: UMOH USENOBONG EMMANUEL | C20: SENIOR RESEARCH OFFICER | D20: 10(7) | E20: =293029.666666667 -> 293029.67 | G20: =100000 -> 100000 | J20: =SUM(E20:I20) -> 393029.67 | O20: 50775.47 | P20: 23442.373 | Q20: =O20+N20+M20+L20+K20+P20 -> 74217.843 | R20: 318811.82 | S20: =J20-Q20 -> 318811.82
B21: TOTAL | C21: 2 | E21: =SUM(E19:E20) -> 646542.17 | G21: =SUM(G19:G20) -> 210000 | H21: =SUM(H19:H20) -> 0 | I21: =SUM(I19:I20) -> 0 | J21: =SUM(J19:J20) -> 856542.17 | K21: =SUM(K19:K20) -> 0 | L21: =SUM(L19:L20) -> 0 | M21: =SUM(M19:M20) -> 0 | N21: =SUM(N19:N20) -> 0 | ... Q21: =SUM(Q19:Q20) -> 164729.96 | R21: 691812.21 | S21: =SUM(S19:S20) -> 691812.21
B23: DEMOCRACY & GOVERNANCE
A24: 1 | B24: MARTINS SOLOMON UDOM | C24: RESEARCH FELLOW 11 | D24: 13(7) | E24: =390248.916666667 -> 390248.92 | G24: =120000 -> 120000 | I24: 0 | J24: =SUM(E24:I24) -> 510248.92 | L24: 30000 | M24: 15000 | O24: =70640.2353066667*(20/31) -> 45574.345 | P24: 31219.913 | Q24: =O24+N24+M24+L24+K24+P24 -> 121794.26 | R24: 668213.07 | S24: =J24-Q24 -> 388454.66
A25: 2 | B25: ISHAKA DELE | C25: RESEARCH FELLOW 11 | D25: 13(7) | E25: =390248.916666667 -> 390248.92 | G25: =120000 -> 120000 | I25: 0 | J25: =SUM(E25:I25) -> 510248.92 | L25: 100000 | O25: =70640.2353066667*(20/31) -> 45574.345 | P25: 31219.913 | Q25: =O25+N25+M25+L25+K25+P25 -> 176794.26 | R25: 131454.66 | S25: =J25-Q25 -> 333454.66
A26: 3 | B26: OBOT ETIMBUK EMMANUEL | C26: PRINCIPAL INFO. OFFICER | D26: 12(7) | E26: =353512.5 -> 353512.5 | G26: 110000 | J26: =E26+F26+G26+H26+I26 -> 463512.5 | L26: 20000 | M26: 50000 | O26: 62231.115 | P26: 28281 | Q26: =O26+N26+M26+L26+K26+P26 -> 160512.11 | R26: 303000.39 | S26: =J26-Q26 -> 303000.39
B27: TOTAL | C27: 2 | E27: =SUM(E24:E26) -> 1134010.3 | F27: =SUM(F24:F26) -> 0 | G27: =SUM(G24:G26) -> 350000 | H27: =SUM(H24:H26) -> 0 | I27: =SUM(I24:I26) -> 0 | J27: =SUM(J24:J26) -> 1484010.3 | K27: =SUM(K24:K26) -> 0 | L27: =SUM(L24:L26) -> 150000 | ... Q27: =SUM(Q24:Q26) -> 459100.63 | R27: 1102668.1 | S27: =SUM(S24:S26) -> 1024909.7
B29: DEPARTMENT OF STUDIES
A30: 1 | B30: DR. IBANGA ISSAC JONAH | C30: ASSIST. CHIEF PROGRM OFFICER | D30: 13(7) | E30: =390248.916666667 -> 390248.92 | G30: =120000 -> 120000 | I30: 0 | J30: =SUM(E30:I30) -> 510248.92 | L30: 0 | O30: 70640.235 | P30: 31219.913 | Q30: =O30+N30+M30+L30+K30+P30 -> 101860.15 | R30: 408388.77 | S30: =J30-Q30 -> 408388.77
A31: 2 | B31: UDONSI QUEENETH CHIWENDU | C31: ASSIST PROGRAMME OFFICER | D31: 8(7) | E31: =218287.583333333 -> 218287.58 | G31: =100000 -> 100000 | J31: =SUM(E31:I31) -> 318287.58 | O31: 37705.19 | P31: 17463.007 | Q31: =O31+N31+M31+L31+K31+P31 -> 55168.197 | R31: 263119.39 | S31: =J31-Q31 -> 263119.39
B32: TOTAL | C32: 2 | E32: =SUM(E30:E31) -> 608536.5 | F32: =SUM(F30:F31) -> 0 | G32: =SUM(G30:G31) -> 220000 | H32: =SUM(H30:H31) -> 0 | I32: =SUM(I30:I31) -> 0 | J32: =SUM(J30:J31) -> 828536.5 | K32: =SUM(K30:K31) -> 0 | L32: =SUM(L30:L31) -> 0 | M32: =SUM(M30:M31) -> 0 | O32: =SUM(O30:O31) -> 108345.43 | P32: =SUM(P30:P31) -> 48682.92 | Q32: =SUM(Q30:Q31) -> 157028.35 | R32: 671508.15 | S32: =SUM(S30:S31) -> 671508.15
B34: ECON. DEV. & SOC. RESEARCH
A35: 1 | B35: UDOKANG NSISONG BONIFACE | C35: PRINC. RESEARCH OFFICER | D35: 12(7) | E35: =353512.5 -> 353512.5 | G35: =110000 -> 110000 | J35: =SUM(E35:I35) -> 463512.5 | L35: 40000 | O35: 62231.115 | P35: 28281 | Q35: =O35+N35+M35+L35+K35+P35 -> 130512.11 | R35: 333000.39 | S35: =J35-Q35 -> 333000.39
B36: TOTAL | C36: 1 | E36: =SUM(E35) -> 353512.5 | F36: =SUM(F35) -> 0 | G36: =SUM(G35) -> 110000 | H36: =SUM(H35) -> 0 | I36: =SUM(I35) -> 0 | J36: =SUM(J35) -> 463512.5 | K36: =SUM(K35) -> 0 | L36: =SUM(L35) -> 40000 | ... Q36: =SUM(Q35) -> 130512.11 | R36: 333000.39 | S36: =SUM(S35) -> 333000.39
B38: TRAINING & INT''L COOP
A39: 1 | B39: DR. SAMUEL AKPAN MBADAH | C39: ASSIST. CHIEF TRAINING OFFICER | D39: 13(7) | E39: =390248.916666667 -> 390248.92 | H39: =70000 -> 70000 | I39: 0 | J39: =SUM(E39:I39) -> 460248.92 | L39: 150000 | O39: =61040.2353066666 -> 61040.235 | P39: =390248.916666667*0.08 -> 31219.913 | Q39: =O39+N39+M39+L39+K39+P39 -> 242260.15 | R39: 217988.77 | S39: =J39-Q39 -> 217988.77
B40: TOTAL | C40: 1 | E40: =SUM(E39:E39) -> 390248.92 | F40: =SUM(F39:F39) -> 0 | G40: =SUM(G39:G39) -> 0 | H40: =SUM(H39:H39) -> 70000 | I40: =SUM(I39:I39) -> 0 | J40: =SUM(J39:J39) -> 460248.92 | K40: =SUM(K39:K39) -> 0 | L40: =SUM(L39:L39) -> 150000 | ... Q40: =SUM(Q39:Q39) -> 242260.15 | R40: 217988.77 | S40: =SUM(S39:S39) -> 217988.77
B42: LEG, CTRE FOR SEC. ANALYSIS
A43: 1 | B43: UDOH ANIETIE JONAH | C43: RESEARCH OFFICER | D43: 9(7) | E43: =255849 -> 255849 | G43: =100000 -> 100000 | J43: =E43+F43+G43+H43+I43 -> 355849 | L43: 50000 | O43: 44015.51 | P43: 20467.92 | Q43: =O43+N43+M43+L43+K43+P43 -> 114483.43 | R43: 241365.57 | S43: =J43-Q43 -> 241365.57
A44: 2 | B44: ENYONGAMA SUNDAY THOMAS | C44: RESEARCH OFFICER | D44: 9(7) | E44: =255849 -> 255849 | G44: =100000 -> 100000 | J44: =E44+F44+G44+H44+I44 -> 355849 | O44: 44015.51 | P44: 20467.92 | Q44: =O44+N44+M44+L44+K44+P44 -> 64483.43 | R44: 291365.57 | S44: =J44-Q44 -> 291365.57
A45: 3 | B45: UDUAK MONDAY ETIAN | C45: ASSIST RESEARCH OFFICER | D45: 8(7) | E45: =218287.583333333 -> 218287.58 | G45: =100000 -> 100000 | J45: =SUM(E45:I45) -> 318287.58 | O45: 37705.19 | P45: 17463.007 | Q45: =O45+N45+M45+L45+K45+P45 -> 55168.197 | R45: 263119.39 | S45: =J45-Q45 -> 263119.39
B46: TOTAL | C46: 3 | E46: =SUM(E43:E45) -> 729985.58 | F46: =SUM(F43:F45) -> 0 | G46: =SUM(G43:G45) -> 300000 | H46: =SUM(H43:H45) -> 0 | I46: =SUM(I43:I45) -> 0 | J46: =SUM(J43:J45) -> 1029985.6 | K46: =SUM(K43:K45) -> 0 | L46: =SUM(L43:L45) -> 50000 | ... Q46: =SUM(Q43:Q45) -> 234135.06 | R46: 795850.53 | S46: =SUM(S43:S45) -> 795850.53
B48: FINANCE & ACCOUNTS
...

Sheet MEMO
A2: NATIONAL INSTITUTE FOR LEGISLATIVE AND DEMOCRATIC STUDIES
A3: INTERNAL MEMO
A4: FROM : DEPUTY DIRECTOR, FINANCE AND ACCOUNTS
A5: THRU: DIRECTOR, FINANCE AND ACCOUNTS
A6: TO: DG
A7: 29TH JANUARY , 2021
A9: SUBJECT: PAYROLL FOR THE MONTH OF JANUARY, 2021
A10: Find below the details of NILDS Staff Payroll for the month of January, 2021
A13: TO: | C13: DIRECTOR, GENERAL
A14: THRU: | C14: DIRECTOR, FINANCE AND ACCOUNT
A15: FROM: | C15: DEPUTY DIRECTOR, FINANCE AND ACCOUNTS
A16: DATE: | C16: 28TH APRIL, 2025
A18: SUBJECT: PAYROLL FOR THE MONTH OF APRIL 2025
A19: Find below the details of NILDS Staff Payroll for the Month of April 2025: | G19: NGN | H19: NGN
A20: GROSS SALARY FOR APRIL 2025 | H20: ='APRIL 2025 NEW'!J58 -> 8433729.2
A22: DEDUCTIONS
A23: COOP SOCIETY DEDUCTIONS ( CONTR.& SPEC. SAVINGS) | G23: ='APRIL 2025 NEW'!L58 -> 590000
A24: COOP LOAN RECOVERY | G24: ='APRIL 2025 NEW'!M58 -> 80000
A25: NHF DEDUCTIONS | G25: ='APRIL 2025 NEW'!N58 -> 0
A26: PAYE DEDUCTIONS | G26: ='APRIL 2025 NEW'!O58 -> 1004511.8
A27: PENSION DEDUCTIONS | G27: ='APRIL 2025 NEW'!P58 -> 525098.34
A28: TOTAL DEDUCTIONS FOR APRIL 2025 | H28: ='APRIL 2025 NEW'!Q58 -> 2199610.2
A29: NET PAY AS PER APRIL 2025 PAYROLL | H29: =H20-H28 -> 6234119.1
A30: NET PAY AS PER MARCH, 2025 PAYROLL | H30: ='APRIL 2025 NEW'!R58 -> 6326877.5
A31: NET INCREASE/ (DECREASE) IN PAY FOR APRIL, 2025 | H31: =H29-H30 -> -92758.41
A33: ANALYSED AS FOLLOWS:
A34: Effect of Cooperative Adjustment for April, 2025 | H34: -172000
A35: Effect of regularization of Salary of Ishaka Dele | H35: =264758.41 -> 264758.41
H36: =SUM(H34:H35) -> 92758.41
E40: MARCH, 2025 | G40: APRIL, 2025
E41: No. of Staff | F41: N | G41: No. of Staff | H41: N
A42: 1 | B42: Director General's Office | E42: 6 | F42: ='APRIL 2025 NEW'!R12 -> 1118809.9 | G42: ='APRIL 2025 NEW'!C12 -> 5 | H42: ='APRIL 2025 NEW'!S12 -> 1103809.9
A43: 2 | B43: Internal Audit | E43: 1 | F43: ='APRIL 2025 NEW'!R16 -> 186045.42 | G43: ='APRIL 2025 NEW'!C16 -> 1 | H43: ='APRIL 2025 NEW'!S16 -> 186045.42
A44: 3 | B44: Legis. Support Services | E44: 2 | F44: ='APRIL 2025 NEW'!R21 -> 691812.21 | G44: ='APRIL 2025 NEW'!C21 -> 2 | H44: ='APRIL 2025 NEW'!S21 -> 691812.21
A45: 4 | B45: Legal Services | E45: 0 | F45: 0 | G45: 0 | H45: 0
A46: 5 | B46: Democracy and Governance | E46: 1 | F46: ='APRIL 2025 NEW'!R27 -> 1102668.1 | G46: ='APRIL 2025 NEW'!C27 -> 2 | H46: ='APRIL 2025 NEW'!S27 -> 1024909.7
A47: 6 | B47: Studies | E47: 2 | F47: ='APRIL 2025 NEW'!R32 -> 671508.15 | G47: ='APRIL 2025 NEW'!C32 -> 2 | H47: ='APRIL 2025 NEW'!S32 -> 671508.15
A48: 7 | B48: Economic Dev. & Social Research | E48: 1 | F48: ='APRIL 2025 NEW'!R36 -> 333000.39 | G48: ='APRIL 2025 NEW'!C36 -> 1 | H48: ='APRIL 2025 NEW'!S36 -> 333000.39
A49: 8 | B49: Training & Int'l Cooperation | E49: 1 | F49: ='APRIL 2025 NEW'!R40 -> 217988.77 | G49: ='APRIL 2025 NEW'!C40 -> 1 | H49: ='APRIL 2025 NEW'!S40 -> 217988.77
A50: 9 | B50: Library & Documentation | E50: 0 | F50: 0 | G50: 0 | H50: 0
...

Sheet Christmas 2024
A1: NATIONAL INSTITUTE FOR LEGISLATIVE AND DEMOCRATIC STUDIES
A2: NEW STAFF CHRISTMAS WELFARE DECEMBER, 2024
B4: STAFF NAME | C4: DESIGNATION | D4: GRADE LEVEL | E4: AMOUNT
E5: N
A6: S/N | B6: DG'S OFFICE
A7: 1 | B7: HOLINESS PAUL UDO | C7: ADMINISTRATION OFFICER, M&E | D7: 9(7) | E7: 54000
A8: 2 | B8: CHARITY UDO AKAN | C8: ADMINISTRATION OFFICER, M&E | D8: 9(7) | E8: 54000
A9: 3 | B9: SANI UMAR IBRAHIM | C9: STORE OFFICER | D9: 9(7) | E9: 54000
A10: 4 | B10: EDIDIONG EZEKIEL ATAT | C10: ASSIST PROCUREMENT OFFICER | D10: 8(7) | E10: 54000
A11: 5 | B11: ALIYU GARBA LERE | C11: ASSIST INFORMATION OFFICER | D11: 8(7) | E11: 54000
B12: TOTAL | C12: 5 | E12: =SUM(E7:E11) -> 270000
B14: INTERNAL AUDIT
A15: 1 | B15: HASSAN ABDULHADI | C15: AUDITOR 11 | D15: 10(7) | E15: 68000
C16: 1 | E16: =SUM(E15:E15) -> 68000
B18: LEG. SUPPORT SEVICES
A19: 1 | B19: UMAR MUSA PADAH | C19: PRINC. RESEARCH OFFICER | D19: 12(7) | E19: 68000
A20: 2 | B20: UMOH USENOBONG EMMANUEL | C20: SENIOR RESEARCH OFFICER | D20: 10(7) | E20: 68000
B21: TOTAL | C21: 2 | E21: =SUM(E19:E20) -> 136000
B23: DEMOCRACY & GOVERNANCE
A24: 1 | B24: MARTINS SOLOMON UDOM | C24: RESEARCH FELLOW 11 | D24: 13(7) | E24: 90000
A25: 2 | B25: OBOT ETIMBUK EMMANUEL | C25: PRINCIPAL INFO. OFFICER | D25: 12(7) | E25: 68000
A26: 3 | B26: ISHAKA DELE | C26: RESEARCH FELLOW 11 | D26: 13(7) | E26: 90000
B27: TOTAL | C27: 2 | E27: =SUM(E24:E26) -> 248000
B29: DEPARTMENT OF STUDIES
A30: 1 | B30: DR. IBANGA ISSAC JONAH | C30: ASSIST. CHIEF PROGRM OFFICER | D30: 13(7) | E30: 90000
A31: 2 | B31: UDONSI QUEENETH CHIWENDU | C31: ASSIST PROGRAMME OFFICER | D31: 8(7) | E31: 54000
B32: TOTAL | C32: 2 | E32: =SUM(E30:E31) -> 144000
B34: ECON. DEV. & SOC. RESEARCH
A35: 1 | B35: UDOKANG NSISONG BONIFACE | C35: PRINC. RESEARCH OFFICER | D35: 12(7) | E35: 68000
B36: TOTAL | C36: 1 | E36: =SUM(E35) -> 68000
B38: TRAINING & INT''L COOP
A39: 1 | B39: DR. SAMUEL AKPAN MBADAH | C39: ASSIST. CHIEF TRAINING OFFICER | D39: 13(7) | E39: 90000
B40: TOTAL | C40: 1 | E40: =SUM(E39:E39) -> 90000
B42: LEG, CTRE FOR SEC. ANALYSIS
A43: 1 | B43: UDOH ANIETIE JONAH | C43: RESEARCH OFFICER | D43: 9(7) | E43: 54000
A44: 2 | B44: ENYONGAMA SUNDAY THOMAS | C44: RESEARCH OFFICER | D44: 9(7) | E44: 54000
A45: 3 | B45: UDUAK MONDAY ETIAN | C45: ASSIST RESEARCH OFFICER | D45: 8(7) | E45: 54000
B46: TOTAL | C46: 3 | E46: =SUM(E43:E45) -> 162000
B48: FINANCE & ACCOUNTS
A49: 1 | B49: DAUDA HAMZA ILIYASU | C49: ASST. ACCOUNT. OFFICER | D49: 10(7) | E49: 68000
...

Sheet NEW STAFF BONUS
A1: NATIONAL INSTITUTE FOR LEGISLATIVE AND DEMOCRATIC STUDIES
A2: NEW STAFF END OF YEAR BONUS DECEMBER 2024
B4: STAFF NAME | C4: DESIGNATION | D4: GRADE LEVEL | E4: GROSS SALARY | F4: HALF SALARY
E5: N | F5: N
A6: S/N | B6: DG'S OFFICE
A7: 1 | B7: HOLINESS PAUL UDO | C7: ADMINISTRATION OFFICER, M&E | D7: 9(7) | E7: 315849 | F7: =E7/2 -> 157924.5
A8: 2 | B8: CHARITY UDO AKAN | C8: ADMINISTRATION OFFICER, M&E | D8: 9(7) | E8: 315849 | F8: =E8/2 -> 157924.5
A9: 3 | B9: SANI UMAR IBRAHIM | C9: STORE OFFICER | D9: 9(7) | E9: 315849 | F9: =E9/2 -> 157924.5
A10: 4 | B10: EDIDIONG EZEKIEL ATAT | C10: ASSIST PROCUREMENT OFFICER | D10: 8(7) | E10: 268287.58 | F10: =E10/2 -> 134143.79
A11: 5 | B11: ALIYU GARBA LERE | C11: ASSIST INFORMATION OFFICER | D11: 8(7) | E11: 268287.58 | F11: =E11/2 -> 134143.79
B12: TOTAL | C12: 5 | E12: 1484122.2 | F12: =SUM(F7:F11) -> 742061.08
B14: INTERNAL AUDIT
A15: 1 | B15: HASSAN ABDULHADI | C15: AUDITOR 11 | D15: 10(7) | E15: 353029.67 | F15: =E15/2 -> 176514.83
C16: 1 | E16: 353029.67 | F16: =SUM(F15:F15) -> 176514.83
B18: LEG. SUPPORT SEVICES
A19: 1 | B19: UMAR MUSA PADAH | C19: PRINC. RESEARCH OFFICER | D19: 12(7) | E19: 463512.5 | F19: =E19/2 -> 231756.25
A20: 2 | B20: UMOH USENOBONG EMMANUEL | C20: SENIOR RESEARCH OFFICER | D20: 10(7) | E20: 393029.67 | F20: =E20/2 -> 196514.83
B21: TOTAL | C21: 2 | E21: 856542.17 | F21: =SUM(F19:F20) -> 428271.08
B23: DEMOCRACY & GOVERNANCE
A24: 1 | B24: MARTINS SOLOMON UDOM | C24: RESEARCH FELLOW 11 | D24: 13(7) | E24: 510248.92 | F24: =E24/2 -> 255124.46
A25: 2 | B25: OBOT ETIMBUK EMMANUEL | C25: PRINCIPAL INFO. OFFICER | D25: 12(7) | E25: 463512.5 | F25: =E25/2 -> 231756.25
B26: TOTAL | C26: 2 | E26: 973761.42 | F26: =SUM(F24:F25) -> 486880.71
B28: DEPARTMENT OF STUDIES
A29: 1 | B29: DR. IBANGA ISSAC JONAH | C29: ASSIST. CHIEF PROGRM OFFICER | D29: 13(7) | E29: 510248.92 | F29: =E29/2 -> 255124.46
A30: 2 | B30: UDONSI QUEENETH CHIWENDU | C30: ASSIST PROGRAMME OFFICER | D30: 8(7) | E30: 318287.58 | F30: =E30/2 -> 159143.79
B31: TOTAL | C31: 2 | E31: 828536.5 | F31: =SUM(F29:F30) -> 414268.25
B33: ECON. DEV. & SOC. RESEARCH
A34: 1 | B34: UDOKANG NSISONG BONIFACE | C34: PRINC. RESEARCH OFFICER | D34: 12(7) | E34: 463512.5 | F34: =E34/2 -> 231756.25
B35: TOTAL | C35: 1 | E35: 463512.5 | F35: =SUM(F34) -> 231756.25
B37: TRAINING & INT''L COOP
A38: 1 | B38: DR. SAMUEL AKPAN MBADAH | C38: ASSIST. CHIEF TRAINING OFFICER | D38: 13(7) | E38: 460248.92 | F38: =E38/2 -> 230124.46
B39: TOTAL | C39: 1 | E39: 460248.92 | F39: =SUM(F38:F38) -> 230124.46
B41: LEG, CTRE FOR SEC. ANALYSIS
A42: 1 | B42: UDOH ANIETIE JONAH | C42: RESEARCH OFFICER | D42: 9(7) | E42: 355849 | F42: =E42/2 -> 177924.5
A43: 2 | B43: ENYONGAMA SUNDAY THOMAS | C43: RESEARCH OFFICER | D43: 9(7) | E43: 358160.16 | F43: =E43/2 -> 179080.08
A44: 3 | B44: UDUAK MONDAY ETIAN | C44: ASSIST RESEARCH OFFICER | D44: 8(7) | E44: 318287.58 | F44: =E44/2 -> 159143.79
B45: TOTAL | C45: 3 | E45: 1032296.7 | F45: =SUM(F42:F44) -> 516148.37
B47: FINANCE & ACCOUNTS
A48: 1 | B48: DAUDA HAMZA ILIYASU | C48: ASST. ACCOUNT. OFFICER | D48: 10(7) | E48: 353029.67 | F48: =E48/2 -> 176514.83
B49: TOTAL | C49: 1 | E49: 353029.67 | F49: =SUM(F48:F48) -> 176514.83
...

Sheet Sheet5

Sheet Placement
A1: NATIONAL INSTITUTE FOR LEGISLATIVE AND DEMOCRATIC STUDIES | G1: ='[1]FEB 08'!F8/'[1]FEB 08'!Q8 -> 0.3
A2: STAFF PAYROLL FOR THE MONTH OF SEPTEMBER 2024
E3: ='[1]FEB 08'!E11/'[1]FEB 08'!M11 -> #REF! | G3: ='[1]FEB 08'!F11/'[1]FEB 08'!Q11 -> #REF!
B4: STAFF NAME | C4: DESIGNATION | D4: GRADE LEVEL | E4: PRORATED BASIC SALARY | F4: ALLCE/ AREARS | G4: ALLOWANCE | H4: PRORATED ALLOWANCE | I4: DUTY ALLCE | J4: CURRENT GROSS SALARY | K4: PAYE | L4: PENSION | M4: NET SALARY
E5: N | F5: N | G5: N | H5: N | I5: N | J5: N
B7: HASSAN ABDULHADI | C7: AUDITOR 11 | D7: 8(7) | E7: =218287.583333333*(13/31) -> 91539.954 | H7: =50000*(13/31) -> 20967.742 | J7: =E7+H7 -> 112507.7
B8: HASSAN ABDULHADI | C8: AUDITOR 11 | D8: 10(7) | E8: =293029.666666667*(18/31) -> 170146.26 | H8: =60000*(18/31) -> 34838.71 | J8: =E8+H8 -> 204984.97
B9: TOTAL | E9: =SUM(E7:E8) -> 261686.21 | F9: =SUM(F7:F8) -> 0 | G9: =SUM(G7:G8) -> 0 | H9: =SUM(H7:H8) -> 55806.452 | I9: =SUM(I7:I8) -> 0 | J9: =SUM(J7:J8) -> 317492.66 | K9: =37571.65 -> 37571.65 | L9: 17463.007 | M9: =J9-K9-L9 -> 262458.01

Sheet New Staff PAYE
A1: NATIONAL INSTITUTE FOR LEGISLATIVE AND DEMOCRATIC STUDIES
A2: NATIONAL ASSEMBLY ABUJA
A3: TAX COMPUTATION FOR 2022
A4: S/NO | B4: NAME | C4: MONTHLY TOTAL SALARY | D4: NO OF MONTHS | E4: ANNUAL SALARY GROSSED UP | F4: NATIONAL HOUSING SCHEME = 2.5% OF BASIC SALARY | G4: PENSION CONTRIBUTION = 8% OF CONSOLIDATED | H4: NHIS | I4: NET SALARY (EXC OF CRA) | M4: CRA=#200,000+(20% 0F NET SALARY (EXC OF CRA) | N4: TOTAL RELIEF | O4: CHARGEABLE INCOME | P4: FIRST N300,000 @ 7% | Q4: NEXT N300,000 @ 11% | R4: NEXT N500,000 @ 15% | S4: NEXT N500,000@ 19% | T4: NEXT N1,600,000 @ 21% | U4: ABOVE N3,200,000 @ 24% | V4: ANNUAL TAX PAYABLE | X4: MONTHLY TAX PAYABLE | Y4: MINIMUM TAX PAYABLE | Z4: NEW ACTUAL TAX PAYABLE
A5: 1
A6: 3 | B6: OBOT ETIMBUK EMMANUEL | C6: 261891.25 | D6: 12 | E6: =C6*D6 -> 3142695 | G6: 209556.08 | I6: =E6-F6-G6-H6 -> 2933138.9 | J6: 200000 | K6: 0.2 | L6: =I6*K6 -> 586627.78 | M6: =J6+L6 -> 786627.78 | N6: =F6+G6+H6+M6 -> 996183.86 | O6: =E6-N6 -> 2146511.1 | P6: =IF(O6<300000,0.07*O6,21000) -> 21000 | Q6: =IF((O6-300000)<0,0,IF((O6-300000)<300000,0.11*(O6-300000),33000)) -> 33000 | R6: =IF((O6-600000)<0,0,IF((O6-600000)<500000,0.15*(O6-600000),75000)) -> 75000 | S6: =IF((O6-1100000)<0,0,IF((O6-1100000)<500000,0.19*(O6-1100000),95000)) -> 95000 | T6: =IF((O6-1600000)<0,0,IF((O6-1600000)<1600000,0.21*(O6-1600000),336000)) -> 114767.34 | V6: =P6+Q6+R6+S6+T6+U6 -> 338767.34 | W6: 12 | X6: =V6/W6 -> 28230.612 | Z6: =X6 -> 28230.612
A7: 4 | B7: HOLINESS PAUL UDO | C7: 231622.6 | D7: 12 | E7: =C7*D7 -> 2779471.2 | G7: 374638.96 | I7: =E7-F7-G7-H7 -> 2404832.2 | J7: 200000 | K7: 0.2 | L7: =I7*K7 -> 480966.45 | M7: =J7+L7 -> 680966.45 | N7: =F7+G7+H7+M7 -> 1055605.4 | O7: =E7-N7 -> 1723865.8 | P7: =IF(O7<300000,0.07*O7,21000) -> 21000 | Q7: =IF((O7-300000)<0,0,IF((O7-300000)<300000,0.11*(O7-300000),33000)) -> 33000 | R7: =IF((O7-600000)<0,0,IF((O7-600000)<500000,0.15*(O7-600000),75000)) -> 75000 | S7: =IF((O7-1100000)<0,0,IF((O7-1100000)<500000,0.19*(O7-1100000),95000)) -> 95000 | T7: =IF((O7-1600000)<0,0,IF((O7-1600000)<1600000,0.21*(O7-1600000),336000)) -> 26011.816 | V7: =P7+Q7+R7+S7+T7+U7 -> 250011.82 | W7: 12 | X7: =V7/W7 -> 20834.318 | Z7: =X7 -> 20834.318
A8: 5 | B8: CHARITY UDO AKAN | C8: 231622.6 | D8: 12 | E8: =C8*D8 -> 2779471.2 | G8: 245615.04 | I8: =E8-F8-G8-H8 -> 2533856.2 | J8: 200000 | K8: 0.2 | L8: =I8*K8 -> 506771.23 | M8: =J8+L8 -> 706771.23 | N8: =F8+G8+H8+M8 -> 952386.27 | O8: =E8-N8 -> 1827084.9 | P8: =IF(O8<300000,0.07*O8,21000) -> 21000 | Q8: =IF((O8-300000)<0,0,IF((O8-300000)<300000,0.11*(O8-300000),33000)) -> 33000 | R8: =IF((O8-600000)<0,0,IF((O8-600000)<500000,0.15*(O8-600000),75000)) -> 75000 | S8: =IF((O8-1100000)<0,0,IF((O8-1100000)<500000,0.19*(O8-1100000),95000)) -> 95000 | T8: =IF((O8-1600000)<0,0,IF((O8-1600000)<1600000,0.21*(O8-1600000),336000)) -> 47687.835 | V8: =P8+Q8+R8+S8+T8+U8 -> 271687.83 | W8: 12 | X8: =V8/W8 -> 22640.653 | Z8: =X8 -> 22640.653
A9: 6 | B9: SANI UMAR IBRAHIM | C9: 315849 | D9: 12 | E9: =C9*D9 -> 3790188 | G9: 209556.08 | I9: =E9-F9-G9-H9 -> 3580631.9 | J9: 200000 | K9: 0.2 | L9: =I9*K9 -> 716126.38 | M9: =J9+L9 -> 916126.38 | N9: =F9+G9+H9+M9 -> 1125682.5 | O9: =E9-N9 -> 2664505.5 | P9: =IF(O9<300000,0.07*O9,21000) -> 21000 | Q9: =IF((O9-300000)<0,0,IF((O9-300000)<300000,0.11*(O9-300000),33000)) -> 33000 | R9: =IF((O9-600000)<0,0,IF((O9-600000)<500000,0.15*(O9-600000),75000)) -> 75000 | S9: =IF((O9-1100000)<0,0,IF((O9-1100000)<500000,0.19*(O9-1100000),95000)) -> 95000 | T9: =IF((O9-1600000)<0,0,IF((O9-1600000)<1600000,0.21*(O9-1600000),336000)) -> 223546.16 | V9: =P9+Q9+R9+S9+T9+U9 -> 447546.16 | W9: 12 | X9: =V9/W9 -> 37295.514 | Z9: =X9 -> 37295.514
A10: 7 | B10: EDIDIONG EZEKIEL ATAT | C10: 169915.47 | D10: 12 | E10: =C10*D10 -> 2038985.6 | G10: 281308.48 | I10: =E10-F10-G10-H10 -> 1757677.2 | J10: 200000 | K10: 0.2 | L10: =I10*K10 -> 351535.43 | M10: =J10+L10 -> 551535.43 | N10: =F10+G10+H10+M10 -> 832843.91 | O10: =E10-N10 -> 1206141.7 | P10: =IF(O10<300000,0.07*O10,21000) -> 21000 | Q10: =IF((O10-300000)<0,0,IF((O10-300000)<300000,0.11*(O10-300000),33000)) -> 33000 | R10: =IF((O10-600000)<0,0,IF((O10-600000)<500000,0.15*(O10-600000),75000)) -> 75000 | S10: =IF((O10-1100000)<0,0,IF((O10-1100000)<500000,0.19*(O10-1100000),95000)) -> 20166.927 | T10: =IF((O10-1600000)<0,0,IF((O10-1600000)<1600000,0.21*(O10-1600000),336000)) -> 0 | V10: =P10+Q10+R10+S10+T10+U10 -> 149166.93 | W10: 12 | X10: =V10/W10 -> 12430.577 | Z10: =X10 -> 12430.577
A11: 8 | B11: ALIYU GARBA LERE | C11: 196744.23 | D11: 12 | E11: =C11*D11 -> 2360930.7 | G11: 374638.96 | I11: =E11-F11-G11-H11 -> 1986291.8 | J11: 200000 | K11: 0.2 | L11: =I11*K11 -> 397258.35 | M11: =J11+L11 -> 597258.35 | N11: =F11+G11+H11+M11 -> 971897.31 | O11: =E11-N11 -> 1389033.4 | P11: =IF(O11<300000,0.07*O11,21000) -> 21000 | Q11: =IF((O11-300000)<0,0,IF((O11-300000)<300000,0.11*(O11-300000),33000)) -> 33000 | R11: =IF((O11-600000)<0,0,IF((O11-600000)<500000,0.15*(O11-600000),75000)) -> 75000 | S11: =IF((O11-1100000)<0,0,IF((O11-1100000)<500000,0.19*(O11-1100000),95000)) -> 54916.35 | T11: =IF((O11-1600000)<0,0,IF((O11-1600000)<1600000,0.21*(O11-1600000),336000)) -> 0 | V11: =P11+Q11+R11+S11+T11+U11 -> 183916.35 | W11: 12 | X11: =V11/W11 -> 15326.362 | Z11: =X11 -> 15326.362
A13: 10 | B13: HASSAN ABDULHADI | C13: 268287.58 | D13: 12 | E13: =C13*D13 -> 3219451 | G13: 209556.08 | I13: =E13-F13-G13-H13 -> 3009894.9 | J13: 200000 | K13: 0.2 | L13: =I13*K13 -> 601978.98 | M13: =J13+L13 -> 801978.98 | N13: =F13+G13+H13+M13 -> 1011535.1 | O13: =E13-N13 -> 2207915.9 | P13: =IF(O13<300000,0.07*O13,21000) -> 21000 | Q13: =IF((O13-300000)<0,0,IF((O13-300000)<300000,0.11*(O13-300000),33000)) -> 33000 | R13: =IF((O13-600000)<0,0,IF((O13-600000)<500000,0.15*(O13-600000),75000)) -> 75000 | S13: =IF((O13-1100000)<0,0,IF((O13-1100000)<500000,0.19*(O13-1100000),95000)) -> 95000 | T13: =IF((O13-1600000)<0,0,IF((O13-1600000)<1600000,0.21*(O13-1600000),336000)) -> 127662.35 | V13: =P13+Q13+R13+S13+T13+U13 -> 351662.35 | W13: 12 | X13: =V13/W13 -> 29305.196 | Z13: =X13 -> 29305.196
A15: 4 | B15: UMAR MUSA PADAH | C15: 293557.92 | D15: 12 | E15: =C15*D15 -> 3522695 | G15: 374638.96 | I15: =E15-F15-G15-H15 -> 3148056 | J15: 200000 | K15: 0.2 | L15: =I15*K15 -> 629611.21 | M15: =J15+L15 -> 829611.21 | N15: =F15+G15+H15+M15 -> 1204250.2 | O15: =E15-N15 -> 2318444.8 | P15: =IF(O15<300000,0.07*O15,21000) -> 21000 | Q15: =IF((O15-300000)<0,0,IF((O15-300000)<300000,0.11*(O15-300000),33000)) -> 33000 | R15: =IF((O15-600000)<0,0,IF((O15-600000)<500000,0.15*(O15-600000),75000)) -> 75000 | S15: =IF((O15-1100000)<0,0,IF((O15-1100000)<500000,0.19*(O15-1100000),95000)) -> 95000 | T15: =IF((O15-1600000)<0,0,IF((O15-1600000)<1600000,0.21*(O15-1600000),336000)) -> 150873.41 | V15: =P15+Q15+R15+S15+T15+U15 -> 374873.41 | W15: 12 | X15: =V15/W15 -> 31239.451 | Z15: =X15 -> 31239.451
A16: 5 | B16: UMOH USENOBONG EMMANUEL | C16: 248918.79 | D16: 12 | E16: =C16*D16 -> 2987025.5 | G16: 245615.04 | I16: =E16-F16-G16-H16 -> 2741410.4 | J16: 200000 | K16: 0.2 | L16: =I16*K16 -> 548282.09 | M16: =J16+L16 -> 748282.09 | N16: =F16+G16+H16+M16 -> 993897.13 | O16: =E16-N16 -> 1993128.3 | P16: =IF(O16<300000,0.07*O16,21000) -> 21000 | Q16: =IF((O16-300000)<0,0,IF((O16-300000)<300000,0.11*(O16-300000),33000)) -> 33000 | R16: =IF((O16-600000)<0,0,IF((O16-600000)<500000,0.15*(O16-600000),75000)) -> 75000 | S16: =IF((O16-1100000)<0,0,IF((O16-1100000)<500000,0.19*(O16-1100000),95000)) -> 95000 | T16: =IF((O16-1600000)<0,0,IF((O16-1600000)<1600000,0.21*(O16-1600000),336000)) -> 82556.952 | V16: =P16+Q16+R16+S16+T16+U16 -> 306556.95 | W16: 12 | X16: =V16/W16 -> 25546.413 | Z16: =X16 -> 25546.413
A18: 7 | B18: MARTINS SOLOMON UDOM | C18: 374182.54 | D18: 12 | E18: =C18*D18 -> 4490190.5 | G18: 281308.48 | I18: =E18-F18-G18-H18 -> 4208882 | J18: 200000 | K18: 0.2 | L18: =I18*K18 -> 841776.4 | M18: =J18+L18 -> 1041776.4 | N18: =F18+G18+H18+M18 -> 1323084.9 | O18: =E18-N18 -> 3167105.6 | P18: =IF(O18<300000,0.07*O18,21000) -> 21000 | Q18: =IF((O18-300000)<0,0,IF((O18-300000)<300000,0.11*(O18-300000),33000)) -> 33000 | R18: =IF((O18-600000)<0,0,IF((O18-600000)<500000,0.15*(O18-600000),75000)) -> 75000 | S18: =IF((O18-1100000)<0,0,IF((O18-1100000)<500000,0.19*(O18-1100000),95000)) -> 95000 | T18: =IF((O18-1600000)<0,0,IF((O18-1600000)<1600000,0.21*(O18-1600000),336000)) -> 329092.17 | V18: =P18+Q18+R18+S18+T18+U18 -> 553092.17 | W18: 12 | X18: =V18/W18 -> 46091.014 | Z18: =X18 -> 46091.014
A20: 9 | B20: DR. IBANGA ISSAC JONAH | C20: 374182.54 | D20: 12 | E20: =C20*D20 -> 4490190.5 | G20: 209556.08 | I20: =E20-F20-G20-H20 -> 4280634.4 | J20: 200000 | K20: 0.2 | L20: =I20*K20 -> 856126.88 | M20: =J20+L20 -> 1056126.9 | N20: =F20+G20+H20+M20 -> 1265683 | O20: =E20-N20 -> 3224507.5 | P20: =IF(O20<300000,0.07*O20,21000) -> 21000 | Q20: =IF((O20-300000)<0,0,IF((O20-300000)<300000,0.11*(O20-300000),33000)) -> 33000 | R20: =IF((O20-600000)<0,0,IF((O20-600000)<500000,0.15*(O20-600000),75000)) -> 75000 | S20: =IF((O20-1100000)<0,0,IF((O20-1100000)<500000,0.19*(O20-1100000),95000)) -> 95000 | T20: =IF((O20-1600000)<0,0,IF((O20-1600000)<1600000,0.21*(O20-1600000),336000)) -> 336000 | U20: =24%*(O20-3200000) -> 5881.8022 | V20: =P20+Q20+R20+S20+T20+U20 -> 565881.8 | W20: 12 | X20: =V20/W20 -> 47156.817 | Z20: =X20 -> 47156.817
A21: 10 | B21: UDONSI QUEENETH CHIWENDU | C21: 233410.89 | D21: 12 | E21: =C21*D21 -> 2800930.7 | G21: 209556.08 | I21: =E21-F21-G21-H21 -> 2591374.7 | J21: 200000 | K21: 0.2 | L21: =I21*K21 -> 518274.93 | M21: =J21+L21 -> 718274.93 | N21: =F21+G21+H21+M21 -> 927831.01 | O21: =E21-N21 -> 1873099.7 | P21: =IF(O21<300000,0.07*O21,21000) -> 21000 | Q21: =IF((O21-300000)<0,0,IF((O21-300000)<300000,0.11*(O21-300000),33000)) -> 33000 | R21: =IF((O21-600000)<0,0,IF((O21-600000)<500000,0.15*(O21-600000),75000)) -> 75000 | S21: =IF((O21-1100000)<0,0,IF((O21-1100000)<500000,0.19*(O21-1100000),95000)) -> 95000 | T21: =IF((O21-1600000)<0,0,IF((O21-1600000)<1600000,0.21*(O21-1600000),336000)) -> 57350.942 | V21: =P21+Q21+R21+S21+T21+U21 -> 281350.94 | W21: 12 | X21: =V21/W21 -> 23445.912 | Z21: =X21 -> 23445.912
A23: 4 | B23: UDOKANG NSISONG BONIFACE | C23: 216305.83 | D23: 12 | E23: =C23*D23 -> 2595670 | G23: 374638.96 | I23: =E23-F23-G23-H23 -> 2221031 | J23: 200000 | K23: 0.2 | L23: =I23*K23 -> 444206.21 | M23: =J23+L23 -> 644206.21 | N23: =F23+G23+H23+M23 -> 1018845.2 | O23: =E23-N23 -> 1576824.8 | P23: =IF(O23<300000,0.07*O23,21000) -> 21000 | Q23: =IF((O23-300000)<0,0,IF((O23-300000)<300000,0.11*(O23-300000),33000)) -> 33000 | R23: =IF((O23-600000)<0,0,IF((O23-600000)<500000,0.15*(O23-600000),75000)) -> 75000 | S23: =IF((O23-1100000)<0,0,IF((O23-1100000)<500000,0.19*(O23-1100000),95000)) -> 90596.718 | T23: =IF((O23-1600000)<0,0,IF((O23-1600000)<1600000,0.21*(O23-1600000),336000)) -> 0 | V23: =P23+Q23+R23+S23+T23+U23 -> 219596.72 | W23: 12 | X23: =V23/W23 -> 18299.727 | Z23: =X23 -> 18299.727
A25: 6 | B25: DR. SAMUEL AKPAN MBADAH | C25: 337515.87 | D25: 12 | E25: =C25*D25 -> 4050190.5 | G25: 209556.08 | I25: =E25-F25-G25-H25 -> 3840634.4 | J25: 200000 | K25: 0.2 | L25: =I25*K25 -> 768126.88 | M25: =J25+L25 -> 968126.88 | N25: =F25+G25+H25+M25 -> 1177683 | O25: =E25-N25 -> 2872507.5 | P25: =IF(O25<300000,0.07*O25,21000) -> 21000 | Q25: =IF((O25-300000)<0,0,IF((O25-300000)<300000,0.11*(O25-300000),33000)) -> 33000 | R25: =IF((O25-600000)<0,0,IF((O25-600000)<500000,0.15*(O25-600000),75000)) -> 75000 | S25: =IF((O25-1100000)<0,0,IF((O25-1100000)<500000,0.19*(O25-1100000),95000)) -> 95000 | T25: =IF((O25-1600000)<0,0,IF((O25-1600000)<1600000,0.21*(O25-1600000),336000)) -> 267226.58 | V25: =P25+Q25+R25+S25+T25+U25 -> 491226.58 | W25: 12 | X25: =V25/W25 -> 40935.548 | Z25: =X25 -> 40935.548
A27: 8 | B27: UDOH ANIETIE JONAH | C27: 260955.93 | D27: 12 | E27: =C27*D27 -> 3131471.2 | G27: 374638.96 | I27: =E27-F27-G27-H27 -> 2756832.2 | J27: 200000 | K27: 0.2 | L27: =I27*K27 -> 551366.45 | M27: =J27+L27 -> 751366.45 | N27: =F27+G27+H27+M27 -> 1126005.4 | O27: =E27-N27 -> 2005465.8 | P27: =IF(O27<300000,0.07*O27,21000) -> 21000 | Q27: =IF((O27-300000)<0,0,IF((O27-300000)<300000,0.11*(O27-300000),33000)) -> 33000 | R27: =IF((O27-600000)<0,0,IF((O27-600000)<500000,0.15*(O27-600000),75000)) -> 75000 | S27: =IF((O27-1100000)<0,0,IF((O27-1100000)<500000,0.19*(O27-1100000),95000)) -> 95000 | T27: =IF((O27-1600000)<0,0,IF((O27-1600000)<1600000,0.21*(O27-1600000),336000)) -> 85147.816 | V27: =P27+Q27+R27+S27+T27+U27 -> 309147.82 | W27: 12 | X27: =V27/W27 -> 25762.318 | Z27: =X27 -> 25762.318
A28: 9 | B28: ENYONGAMA SUNDAY THOMAS | C28: 260955.93 | D28: 12 | E28: =C28*D28 -> 3131471.2 | G28: 209556.08 | I28: =E28-F28-G28-H28 -> 2921915.1 | J28: 200000 | K28: 0.2 | L28: =I28*K28 -> 584383.02 | M28: =J28+L28 -> 784383.02 | N28: =F28+G28+H28+M28 -> 993939.1 | O28: =E28-N28 -> 2137532.1 | P28: =IF(O28<300000,0.07*O28,21000) -> 21000 | Q28: =IF((O28-300000)<0,0,IF((O28-300000)<300000,0.11*(O28-300000),33000)) -> 33000 | R28: =IF((O28-600000)<0,0,IF((O28-600000)<500000,0.15*(O28-600000),75000)) -> 75000 | S28: =IF((O28-1100000)<0,0,IF((O28-1100000)<500000,0.19*(O28-1100000),95000)) -> 95000 | T28: =IF((O28-1600000)<0,0,IF((O28-1600000)<1600000,0.21*(O28-1600000),336000)) -> 112881.74 | V28: =P28+Q28+R28+S28+T28+U28 -> 336881.74 | W28: 12 | X28: =V28/W28 -> 28073.478 | Z28: =X28 -> 28073.478
A29: 10 | B29: UDUAK MONDAY ETIAN | C29: 212191.72 | D29: 12 | E29: =C29*D29 -> 2546300.7 | G29: 209556.08 | I29: =E29-F29-G29-H29 -> 2336744.6 | J29: 200000 | K29: 0.2 | L29: =I29*K29 -> 467348.92 | M29: =J29+L29 -> 667348.92 | N29: =F29+G29+H29+M29 -> 876905 | O29: =E29-N29 -> 1669395.7 | P29: =IF(O29<300000,0.07*O29,21000) -> 21000 | Q29: =IF((O29-300000)<0,0,IF((O29-300000)<300000,0.11*(O29-300000),33000)) -> 33000 | R29: =IF((O29-600000)<0,0,IF((O29-600000)<500000,0.15*(O29-600000),75000)) -> 75000 | S29: =IF((O29-1100000)<0,0,IF((O29-1100000)<500000,0.19*(O29-1100000),95000)) -> 95000 | T29: =IF((O29-1600000)<0,0,IF((O29-1600000)<1600000,0.21*(O29-1600000),336000)) -> 14573.091 | V29: =P29+Q29+R29+S29+T29+U29 -> 238573.09 | W29: 12 | X29: =V29/W29 -> 19881.091 | Z29: =X29 -> 19881.091
A31: 7 | B31: DAUDA HAMZA ILIYASU | C31: 196744.23 | D31: 12 | E31: =C31*D31 -> 2360930.7 | G31: 281308.48 | I31: =E31-F31-G31-H31 -> 2079622.3 | J31: 200000 | K31: 0.2 | L31: =I31*K31 -> 415924.45 | M31: =J31+L31 -> 615924.45 | N31: =F31+G31+H31+M31 -> 897232.93 | O31: =E31-N31 -> 1463697.8 | P31: =IF(O31<300000,0.07*O31,21000) -> 21000 | Q31: =IF((O31-300000)<0,0,IF((O31-300000)<300000,0.11*(O31-300000),33000)) -> 33000 | R31: =IF((O31-600000)<0,0,IF((O31-600000)<500000,0.15*(O31-600000),75000)) -> 75000 | S31: =IF((O31-1100000)<0,0,IF((O31-1100000)<500000,0.19*(O31-1100000),95000)) -> 69102.583 | T31: =IF((O31-1600000)<0,0,IF((O31-1600000)<1600000,0.21*(O31-1600000),336000)) -> 0 | V31: =P31+Q31+R31+S31+T31+U31 -> 198102.58 | W31: 12 | X31: =V31/W31 -> 16508.549 | Z31: =X31 -> 16508.549
A33: 9 | B33: CHINWEOTUTO PRAISE UKPAI | C33: 353029.67 | D33: 12 | E33: =C33*D33 -> 4236356 | G33: 209556.08 | I33: =E33-F33-G33-H33 -> 4026800 | J33: 200000 | K33: 0.2 | L33: =I33*K33 -> 805359.99 | M33: =J33+L33 -> 1005360 | N33: =F33+G33+H33+M33 -> 1214916.1 | O33: =E33-N33 -> 3021440 | P33: =IF(O33<300000,0.07*O33,21000) -> 21000 | Q33: =IF((O33-300000)<0,0,IF((O33-300000)<300000,0.11*(O33-300000),33000)) -> 33000 | R33: =IF((O33-600000)<0,0,IF((O33-600000)<500000,0.15*(O33-600000),75000)) -> 75000 | S33: =IF((O33-1100000)<0,0,IF((O33-1100000)<500000,0.19*(O33-1100000),95000)) -> 95000 | T33: =IF((O33-1600000)<0,0,IF((O33-1600000)<1600000,0.21*(O33-1600000),336000)) -> 298502.39 | V33: =P33+Q33+R33+S33+T33+U33 -> 522502.39 | W33: 12 | X33: =V33/W33 -> 43541.866 | Z33: =X33 -> 43541.866
A34: 10 | B34: AISHA AMINU SAMBO | C34: 169915.47 | D34: 12 | E34: =C34*D34 -> 2038985.6 | G34: 209556.08 | I34: =E34-F34-G34-H34 -> 1829429.6 | J34: 200000 | K34: 0.2 | L34: =I34*K34 -> 365885.91 | M34: =J34+L34 -> 565885.91 | N34: =F34+G34+H34+M34 -> 775441.99 | O34: =E34-N34 -> 1263543.6 | P34: =IF(O34<300000,0.07*O34,21000) -> 21000 | Q34: =IF((O34-300000)<0,0,IF((O34-300000)<300000,0.11*(O34-300000),33000)) -> 33000 | R34: =IF((O34-600000)<0,0,IF((O34-600000)<500000,0.15*(O34-600000),75000)) -> 75000 | S34: =IF((O34-1100000)<0,0,IF((O34-1100000)<500000,0.19*(O34-1100000),95000)) -> 31073.292 | T34: =IF((O34-1600000)<0,0,IF((O34-1600000)<1600000,0.21*(O34-1600000),336000)) -> 0 | V34: =P34+Q34+R34+S34+T34+U34 -> 160073.29 | W34: 12 | X34: =V34/W34 -> 13339.441 | Z34: =X34 -> 13339.441
A35: 3 | B35: ABDULHAKEEM GARBA LERE | C35: 268287.58 | D35: 12 | E35: =C35*D35 -> 3219451 | G35: 209556.08 | I35: =E35-F35-G35-H35 -> 3009894.9 | J35: 200000 | K35: 0.2 | L35: =I35*K35 -> 601978.98 | M35: =J35+L35 -> 801978.98 | N35: =F35+G35+H35+M35 -> 1011535.1 | O35: =E35-N35 -> 2207915.9 | P35: =IF(O35<300000,0.07*O35,21000) -> 21000 | Q35: =IF((O35-300000)<0,0,IF((O35-300000)<300000,0.11*(O35-300000),33000)) -> 33000 | R35: =IF((O35-600000)<0,0,IF((O35-600000)<500000,0.15*(O35-600000),75000)) -> 75000 | S35: =IF((O35-1100000)<0,0,IF((O35-1100000)<500000,0.19*(O35-1100000),95000)) -> 95000 | T35: =IF((O35-1600000)<0,0,IF((O35-1600000)<1600000,0.21*(O35-1600000),336000)) -> 127662.35 | V35: =P35+Q35+R35+S35+T35+U35 -> 351662.35 | W35: 12 | X35: =V35/W35 -> 29305.196 | Z35: =X35 -> 29305.196
V37: Total | X37: =SUM(X6:X36) -> 575190.05 | Y37: =SUM(Y6:Y36) -> 0 | Z37: =SUM(Z6:Z36) -> 575190.05

Sheet Recovery
B1: STAFF NAME | C1: DESIGNATION | D1: GRADE LEVEL | E1: BASIC SALARY | F1: ALLCE/ AREARS | G1: ALLOWANCE | H1: ALLOWANCE | I1: DUTY ALLCE | J1: GROSS SALARY | K1: AUCTION | L1: COOP CONTR/SPEC SAVINGS | M1: COOP. LOAN RECOVERY | N1: NHF DED. | O1: PAYE | P1: EMPLOYEE PENSIONS | Q1: TOTAL DEDUCTION | R1: SEPTEMBER, 2024 | S1: OCTOBER, 2024
E2: N | F2: N | G2: N | H2: N | I2: N | J2: N | K2: N | L2: N | M2: N | N2: N | O2: N | P2: N | Q2: N | R2: N | S2: N
A5: 1 | B5: UMAR MUSA PADAH | C5: PRINC. RESEARCH OFFICER | D5: 12(7) | E5: =353512.5 -> 353512.5 | G5: =110000 -> 110000 | J5: =SUM(E5:I5) -> 463512.5 | O5: 62231.115 | P5: 28281 | Q5: =O5+N5+M5+L5+K5+P5 -> 90512.115 | R5: 262318.47 | S5: 262318.47

Sheet New Enrolmt
B4: STAFF NAME | C4: DESIGNATION | D4: GRADE LEVEL | E4: BASIC SALARY | F4: ALLOWANCE | G4: DUTY ALLCE | H4: GROSS SALARY | I4: PAYE | J4: EMPLOYEE PENSIONS | K4: TOTAL DEDUCTION | L4: AUGUST, 2024
A5: 1 | B5: JOSEPH GWATANA | C5: SENIOR MOTOR DRIVER MECH. | D5: 5(7) | E5: 83955 | F5: =20000 -> 20000 | G5: =4000+3000 -> 7000 | H5: =SUM(E5:G5) -> 110955 | I5: 5719.04 | K5: 5719.04 | L5: =H5-K5 -> 105235.96
B6: PRORATED FOR 12 DAYS | E6: 83955 | F6: =20000 -> 20000 | G6: =4000+3000 -> 7000 | H6: =SUM(E6:G6)*(12/31) -> 42950.323 | I6: 3127.74 | J6: 0 | K6: 3127.74 | L6: =H6-K6 -> 39822.583
A7: 2 | B7: ABDULMUSHIN TAWFIQ LADAN | C7: ICT OFFICER | D7: 95(7) | E7: 255849 | F7: 60000 | H7: =SUM(E7:G7) -> 315849 | I7: =36790.6881 -> 36790.688 | J7: ='APRIL 2025 NEW'!#REF! -> #REF! | K7: =I7+J7 -> #REF! | L7: =H7-K7 -> #REF!
B8: TOTAL | L8: =SUM(L6:L7) -> #REF!

Sheet 1ST 28 DAYS
A1: SCHEDULE OF 1ST 28 DAY TO THE NEWLY CONVERTED STAFF
A2: S/N | B2: NAME | C2: GRADE LEVEL | D2: AMOUNT (NGN) | E2: PAYE (NGN) | F2: NET AMOUNT (NGN)
A3: 1 | B3: Alabi Adesina Muhydeen | C3: 13 | D3: =25000*28 -> 700000 | E3: 104125.33 | F3: =D3-E3 -> 595874.67
A4: 2 | B4: Ikip Lebo | C4: 13 | D4: =25000*28 -> 700000 | E4: 104125.33 | F4: =D4-E4 -> 595874.67
A5: 3 | B5: Rasheedat Daibu | C5: 10 | D5: =20000*28 -> 560000 | E5: =86186.67 -> 86186.67 | F5: =D5-E5 -> 473813.33
A6: 4 | B6: Yussuf Yussuf Dayyabu | C6: 09 | D6: =20000*28 -> 560000 | E6: =86186.67 -> 86186.67 | F6: =D6-E6 -> 473813.33
A7: 5 | B7: Rahimat Onize Suberu | C7: 08 | D7: =20000*28 -> 560000 | E7: =86186.67 -> 86186.67 | F7: =D7-E7 -> 473813.33
A8: 6 | B8: Ramatu Ibrahim Abdulraheem | C8: 08 | D8: =20000*28 -> 560000 | E8: =86186.67 -> 86186.67 | F8: =D8-E8 -> 473813.33
A9: 7 | B9: Katman Emmanuel | C9: 08 | D9: =20000*28 -> 560000 | E9: =86186.67 -> 86186.67 | F9: =D9-E9 -> 473813.33
A10: 8 | B10: Usman Muhammed Gidado | C10: 08 | D10: =20000*28 -> 560000 | E10: =86186.67 -> 86186.67 | F10: =D10-E10 -> 473813.33
B11: TOTAL | D11: =SUM(D3:D10) -> 4760000 | E11: =SUM(E3:E10) -> 725370.68 | F11: =SUM(F3:F10) -> 4034629.3
A14: S/N | B14: NAME | C14: GRADE LEVEL | D14: AMOUNT (NGN) | E14: PAYE (NGN) | F14: NET AMOUNT (NGN)
B15: Abdulmushin Tawfiq Ladan | C15: 09 | D15: =20000*28 -> 560000 | E15: =86186.67 -> 86186.67 | F15: =D15-E15 -> 473813.33
B16: Joseph Gwatana | C16: 05 | D16: =10000*28 -> 280000 | E16: 31272.88 | F16: =D16-E16 -> 248727.12
B17: TOTAL | D17: =SUM(D15:D16) -> 840000 | E17: =SUM(E15:E16) -> 117459.55 | F17: =SUM(F15:F16) -> 722540.45

Sheet Conversion & Enrol Effect
A1: S/N | B1: STAFF NAME | C1: DESIGNATION | D1: GRADE LEVEL | E1: SALARY | F1: RESEARCH/HARDSHIP | G1: ARREARS | H1: GROSS SALARY | I1: DEDUCTIONS | N1: JULY 2024 NET SALARY
I2: COOP CONTR/SPEC. SAVINGS | J2: COOP LOAN REC. | K2: PAYE TAX | L2: PENSION DEDUCTION | M2: TOTAL DEDUCTION
E4: N | F4: N | G4: N | H4: N | I4: N | J4: N | K4: N | L4: N | M4: N | N4: N
A5: 1 | B5: Rahimat Suberu Onize | C5: Acct Assistant | D5: 8(7) | E5: ='[2]Annual & Monthly'!$H$36 -> 218287.58 | F5: 50000 | H5: =E5+F5+G5 -> 268287.58 | I5: =50000 -> 50000 | K5: 29305.196 | L5: =218287.583333333*0.08 -> 17463.007 | M5: =I5+J5+K5+L5 -> 96768.202 | N5: =H5-M5 -> 171519.38
A6: 2 | B6: Ikip Lebo | C6: Asst Chief Proc Officer | D6: 13(7) | E6: ='[2]Annual & Monthly'!$H$40 -> 390248.92 | F6: =70000 -> 70000 | H6: =E6+F6+G6 -> 460248.92 | I6: 50000 | K6: 61040.235 | L6: =390248.916666667*0.08 -> 31219.913 | M6: =I6+J6+K6+L6 -> 142260.15 | N6: =H6-M6 -> 317988.77
A7: 3 | B7: Yusuf Yusuf Dayyabu | C7: Contract Staff | D7: 9(7) | E7: ='[2]Annual & Monthly'!$H$37 -> 255849 | F7: =60000 -> 60000 | H7: =E7+F7+G7 -> 315849 | I7: 20000 | K7: 36790.688 | L7: =255849*0.08 -> 20467.92 | M7: =I7+J7+K7+L7 -> 77258.608 | N7: =H7-M7 -> 238590.39
A8: 4 | B8: Ramatu Ibrahim Abdulrahim | C8: Info Asst | D8: 8(7) | E8: 218287.58 | F8: =50000 -> 50000 | H8: =E8+F8+G8 -> 268287.58 | I8: 100000 | K8: 29305.196 | L8: =218287.583333333*0.08 -> 17463.007 | M8: =I8+J8+K8+L8 -> 146768.2 | N8: =H8-M8 -> 121519.38
A9: 5 | B9: Rasheedat Daibu | C9: Senior Info Officer | D9: 10(7) | E9: ='[2]Annual & Monthly'!$H$38 -> 293029.67 | F9: =60000 -> 60000 | H9: =E9+F9+G9 -> 353029.67 | I9: 40000 | K9: 42537.332 | L9: =293029.666666667*0.08 -> 23442.373 | M9: =I9+J9+K9+L9 -> 105979.71 | N9: =H9-M9 -> 247049.96
A10: 6 | B10: Dr. Alabi Adesina Muhydeen | C10: Head, Laiason Office | D10: 13(7) | E10: 390248.92 | F10: =120000 -> 120000 | H10: =E10+F10+G10 -> 510248.92 | K10: 70640.235 | L10: =390248.916666667*0.08 -> 31219.913 | M10: =I10+J10+K10+L10 -> 101860.15 | N10: =H10-M10 -> 408388.77
A11: 7 | B11: Katman Emmanuel | C11: Temporary Full time | D11: 8(7) | E11: =218287.583333333 -> 218287.58 | F11: =50000 -> 50000 | H11: =E11+F11+G11 -> 268287.58 | K11: 29305.196 | L11: =218287.583333333*0.08 -> 17463.007 | M11: =I11+J11+K11+L11 -> 46768.202 | N11: =H11-M11 -> 221519.38
A12: 8 | B12: Usman Muhammed Gidado | C12: Temporary Full time | D12: 8(7) | E12: =218287.583333333 -> 218287.58 | F12: =50000 -> 50000 | H12: =E12+F12+G12 -> 268287.58 | K12: 29305.196 | L12: =218287.583333333*0.08 -> 17463.007 | M12: =I12+J12+K12+L12 -> 46768.202 | N12: =H12-M12 -> 221519.38
B13: TOTAL | E13: =SUM(E5:E12) -> 2202526.8 | F13: =SUM(F5:F12) -> 510000 | G13: =SUM(G5:G12) -> 0 | H13: =SUM(H5:H12) -> 2712526.8 | I13: =SUM(I5:I12) -> 260000 | J13: =SUM(J5:J12) -> 0 | K13: =SUM(K5:K12) -> 328229.27 | L13: =SUM(L5:L12) -> 176202.15 | ... N13: =SUM(N5:N12) -> 1948095.4

Sheet Converted Staff PAYE
A1: NATIONAL INSTITUTE FOR LEGISLATIVE AND DEMOCRATIC STUDIES
A2: NATIONAL ASSEMBLY ABUJA
A3: TAX COMPUTATION FOR 2022
A4: S/NO | B4: NAME | C4: MONTHLY TOTAL SALARY | D4: NO OF MONTHS | E4: ANNUAL SALARY GROSSED UP | F4: NATIONAL HOUSING SCHEME = 2.5% OF BASIC SALARY | G4: PENSION CONTRIBUTION = 8% OF CONSOLIDATED | H4: NHIS | I4: NET SALARY (EXC OF CRA) | M4: CRA=#200,000+(20% 0F NET SALARY (EXC OF CRA) | N4: TOTAL RELIEF | O4: CHARGEABLE INCOME | P4: FIRST N300,000 @ 7% | Q4: NEXT N300,000 @ 11% | R4: NEXT N500,000 @ 15% | S4: NEXT N500,000@ 19% | T4: NEXT N1,600,000 @ 21% | U4: ABOVE N3,200,000 @ 24% | V4: ANNUAL TAX PAYABLE | X4: MONTHLY TAX PAYABLE | Y4: MINIMUM TAX PAYABLE | Z4: NEW ACTUAL TAX PAYABLE
A5: 1
A6: 3 | B6: Rahimat Suberu Onize | C6: 268287.58 | D6: 12 | E6: =C6*D6 -> 3219451 | G6: 209556.08 | I6: =E6-F6-G6-H6 -> 3009894.9 | J6: 200000 | K6: 0.2 | L6: =I6*K6 -> 601978.98 | M6: =J6+L6 -> 801978.98 | N6: =F6+G6+H6+M6 -> 1011535.1 | O6: =E6-N6 -> 2207915.9 | P6: =IF(O6<300000,0.07*O6,21000) -> 21000 | Q6: =IF((O6-300000)<0,0,IF((O6-300000)<300000,0.11*(O6-300000),33000)) -> 33000 | R6: =IF((O6-600000)<0,0,IF((O6-600000)<500000,0.15*(O6-600000),75000)) -> 75000 | S6: =IF((O6-1100000)<0,0,IF((O6-1100000)<500000,0.19*(O6-1100000),95000)) -> 95000 | T6: =IF((O6-1600000)<0,0,IF((O6-1600000)<1600000,0.21*(O6-1600000),336000)) -> 127662.35 | V6: =P6+Q6+R6+S6+T6+U6 -> 351662.35 | W6: 12 | X6: =V6/W6 -> 29305.196 | Z6: =X6 -> 29305.196
A7: 4 | B7: Ikip Lebo | C7: 460248.92 | D7: 12 | E7: =C7*D7 -> 5522987 | G7: 374638.96 | I7: =E7-F7-G7-H7 -> 5148348 | J7: 200000 | K7: 0.2 | L7: =I7*K7 -> 1029669.6 | M7: =J7+L7 -> 1229669.6 | N7: =F7+G7+H7+M7 -> 1604308.6 | O7: =E7-N7 -> 3918678.4 | P7: =IF(O7<300000,0.07*O7,21000) -> 21000 | Q7: =IF((O7-300000)<0,0,IF((O7-300000)<300000,0.11*(O7-300000),33000)) -> 33000 | R7: =IF((O7-600000)<0,0,IF((O7-600000)<500000,0.15*(O7-600000),75000)) -> 75000 | S7: =IF((O7-1100000)<0,0,IF((O7-1100000)<500000,0.19*(O7-1100000),95000)) -> 95000 | T7: =IF((O7-1600000)<0,0,IF((O7-1600000)<1600000,0.21*(O7-1600000),336000)) -> 336000 | U7: =24%*(O7-3200000) -> 172482.82 | V7: =P7+Q7+R7+S7+T7+U7 -> 732482.82 | W7: 12 | X7: =V7/W7 -> 61040.235 | Z7: =X7 -> 61040.235
A8: 5 | B8: Yusuf Yusuf Dayyabu | C8: 315849 | D8: 12 | E8: =C8*D8 -> 3790188 | G8: 245615.04 | I8: =E8-F8-G8-H8 -> 3544573 | J8: 200000 | K8: 0.2 | L8: =I8*K8 -> 708914.59 | M8: =J8+L8 -> 908914.59 | N8: =F8+G8+H8+M8 -> 1154529.6 | O8: =E8-N8 -> 2635658.4 | P8: =IF(O8<300000,0.07*O8,21000) -> 21000 | Q8: =IF((O8-300000)<0,0,IF((O8-300000)<300000,0.11*(O8-300000),33000)) -> 33000 | R8: =IF((O8-600000)<0,0,IF((O8-600000)<500000,0.15*(O8-600000),75000)) -> 75000 | S8: =IF((O8-1100000)<0,0,IF((O8-1100000)<500000,0.19*(O8-1100000),95000)) -> 95000 | T8: =IF((O8-1600000)<0,0,IF((O8-1600000)<1600000,0.21*(O8-1600000),336000)) -> 217488.26 | V8: =P8+Q8+R8+S8+T8+U8 -> 441488.26 | W8: 12 | X8: =V8/W8 -> 36790.688 | Z8: =X8 -> 36790.688
A9: 6 | B9: Ramatu Ibrahim Abdulrahim | C9: 268287.58 | D9: 12 | E9: =C9*D9 -> 3219451 | G9: 209556.08 | I9: =E9-F9-G9-H9 -> 3009894.9 | J9: 200000 | K9: 0.2 | L9: =I9*K9 -> 601978.98 | M9: =J9+L9 -> 801978.98 | N9: =F9+G9+H9+M9 -> 1011535.1 | O9: =E9-N9 -> 2207915.9 | P9: =IF(O9<300000,0.07*O9,21000) -> 21000 | Q9: =IF((O9-300000)<0,0,IF((O9-300000)<300000,0.11*(O9-300000),33000)) -> 33000 | R9: =IF((O9-600000)<0,0,IF((O9-600000)<500000,0.15*(O9-600000),75000)) -> 75000 | S9: =IF((O9-1100000)<0,0,IF((O9-1100000)<500000,0.19*(O9-1100000),95000)) -> 95000 | T9: =IF((O9-1600000)<0,0,IF((O9-1600000)<1600000,0.21*(O9-1600000),336000)) -> 127662.35 | V9: =P9+Q9+R9+S9+T9+U9 -> 351662.35 | W9: 12 | X9: =V9/W9 -> 29305.196 | Z9: =X9 -> 29305.196
A10: 7 | B10: Rasheedat Daibu | C10: 353029.67 | D10: 12 | E10: =C10*D10 -> 4236356 | G10: 281308.48 | I10: =E10-F10-G10-H10 -> 3955047.5 | J10: 200000 | K10: 0.2 | L10: =I10*K10 -> 791009.5 | M10: =J10+L10 -> 991009.5 | N10: =F10+G10+H10+M10 -> 1272318 | O10: =E10-N10 -> 2964038 | P10: =IF(O10<300000,0.07*O10,21000) -> 21000 | Q10: =IF((O10-300000)<0,0,IF((O10-300000)<300000,0.11*(O10-300000),33000)) -> 33000 | R10: =IF((O10-600000)<0,0,IF((O10-600000)<500000,0.15*(O10-600000),75000)) -> 75000 | S10: =IF((O10-1100000)<0,0,IF((O10-1100000)<500000,0.19*(O10-1100000),95000)) -> 95000 | T10: =IF((O10-1600000)<0,0,IF((O10-1600000)<1600000,0.21*(O10-1600000),336000)) -> 286447.98 | V10: =P10+Q10+R10+S10+T10+U10 -> 510447.98 | W10: 12 | X10: =V10/W10 -> 42537.332 | Z10: =X10 -> 42537.332
A11: 8 | B11: Dr. Alabi Adesina Muhydeen | C11: 510248.92 | D11: 12 | E11: =C11*D11 -> 6122987 | G11: 374638.96 | I11: =E11-F11-G11-H11 -> 5748348 | J11: 200000 | K11: 0.2 | L11: =I11*K11 -> 1149669.6 | M11: =J11+L11 -> 1349669.6 | N11: =F11+G11+H11+M11 -> 1724308.6 | O11: =E11-N11 -> 4398678.4 | P11: =IF(O11<300000,0.07*O11,21000) -> 21000 | Q11: =IF((O11-300000)<0,0,IF((O11-300000)<300000,0.11*(O11-300000),33000)) -> 33000 | R11: =IF((O11-600000)<0,0,IF((O11-600000)<500000,0.15*(O11-600000),75000)) -> 75000 | S11: =IF((O11-1100000)<0,0,IF((O11-1100000)<500000,0.19*(O11-1100000),95000)) -> 95000 | T11: =IF((O11-1600000)<0,0,IF((O11-1600000)<1600000,0.21*(O11-1600000),336000)) -> 336000 | U11: =24%*(O11-3200000) -> 287682.82 | V11: =P11+Q11+R11+S11+T11+U11 -> 847682.82 | W11: 12 | X11: =V11/W11 -> 70640.235 | Z11: =X11 -> 70640.235
A12: 9 | B12: Katman Emmanuel | C12: 268287.58 | D12: 12 | E12: =C12*D12 -> 3219451 | G12: 209556.08 | I12: =E12-F12-G12-H12 -> 3009894.9 | J12: 200000 | K12: 0.2 | L12: =I12*K12 -> 601978.98 | M12: =J12+L12 -> 801978.98 | N12: =F12+G12+H12+M12 -> 1011535.1 | O12: =E12-N12 -> 2207915.9 | P12: =IF(O12<300000,0.07*O12,21000) -> 21000 | Q12: =IF((O12-300000)<0,0,IF((O12-300000)<300000,0.11*(O12-300000),33000)) -> 33000 | R12: =IF((O12-600000)<0,0,IF((O12-600000)<500000,0.15*(O12-600000),75000)) -> 75000 | S12: =IF((O12-1100000)<0,0,IF((O12-1100000)<500000,0.19*(O12-1100000),95000)) -> 95000 | T12: =IF((O12-1600000)<0,0,IF((O12-1600000)<1600000,0.21*(O12-1600000),336000)) -> 127662.35 | V12: =P12+Q12+R12+S12+T12+U12 -> 351662.35 | W12: 12 | X12: =V12/W12 -> 29305.196 | Z12: =X12 -> 29305.196
A13: 10 | B13: Usman Muhammed Gidado | C13: 268287.58 | D13: 12 | E13: =C13*D13 -> 3219451 | G13: 209556.08 | I13: =E13-F13-G13-H13 -> 3009894.9 | J13: 200000 | K13: 0.2 | L13: =I13*K13 -> 601978.98 | M13: =J13+L13 -> 801978.98 | N13: =F13+G13+H13+M13 -> 1011535.1 | O13: =E13-N13 -> 2207915.9 | P13: =IF(O13<300000,0.07*O13,21000) -> 21000 | Q13: =IF((O13-300000)<0,0,IF((O13-300000)<300000,0.11*(O13-300000),33000)) -> 33000 | R13: =IF((O13-600000)<0,0,IF((O13-600000)<500000,0.15*(O13-600000),75000)) -> 75000 | S13: =IF((O13-1100000)<0,0,IF((O13-1100000)<500000,0.19*(O13-1100000),95000)) -> 95000 | T13: =IF((O13-1600000)<0,0,IF((O13-1600000)<1600000,0.21*(O13-1600000),336000)) -> 127662.35 | V13: =P13+Q13+R13+S13+T13+U13 -> 351662.35 | W13: 12 | X13: =V13/W13 -> 29305.196 | Z13: =X13 -> 29305.196
B14: TOTAL - MONTHLY | Z14: =SUM(Z6:Z13) -> 328229.27
C16: MONTHLY PENSIONS | D16: 12 | E16: ANNUAL PENSIONS
B17: Rahimat Suberu Onize | C17: =218287.583333333*0.08 -> 17463.007 | D17: 12 | E17: =C17*D17 -> 209556.08
B18: Ikip Lebo | C18: =390248.916666667*0.08 -> 31219.913 | D18: 12 | E18: =C18*D18 -> 374638.96
B19: Yusuf Yusuf Dayyabu | C19: =255849*0.08 -> 20467.92 | D19: 12 | E19: =C19*D19 -> 245615.04
B20: Ramatu Ibrahim Abdulrahim | C20: =218287.583333333*0.08 -> 17463.007 | D20: 12 | E20: =C20*D20 -> 209556.08
B21: Rasheedat Daibu | C21: =293029.666666667*0.08 -> 23442.373 | D21: 12 | E21: =C21*D21 -> 281308.48
B22: Dr. Alabi Adesina Muhydeen | C22: =390248.916666667*0.08 -> 31219.913 | D22: 12 | E22: =C22*D22 -> 374638.96
B23: Katman Emmanuel | C23: =218287.583333333*0.08 -> 17463.007 | D23: 12 | E23: =C23*D23 -> 209556.08
B24: Usman Muhammed Gidado | C24: =218287.583333333*0.08 -> 17463.007 | D24: 12 | E24: =C24*D24 -> 209556.08

Sheet Movt to Contract
B3: STAFF NAME | C3: DESIGNATION | D3: GRADE LEVEL | E3: BASIC SALARY | F3: ALLCE/ AREARS | G3: ALLOWANCE | H3: ALLOWANCE | I3: DUTY ALLCE | J3: GROSS SALARY | K3: AUCTION | L3: COOP CONTR/SPEC SAVINGS | M3: COOP. LOAN RECOVERY | N3: NHF DED. | O3: PAYE | P3: EMPLOYEE PENSIONS | Q3: TOTAL DEDUCTION | R3: JUNE, 2024 | S3: JULY, 2024
E4: N | F4: N | G4: N | H4: N | I4: N | J4: N | K4: N | L4: N | M4: N | N4: N | O4: N | P4: N | Q4: N | R4: N | S4: N
A5: 1 | B5: USMAN WALI | C5: SENIOR RESEARCH FELLOW | D5: 15 (8) | E5: 601396.83 | G5: =160000 -> 160000 | I5: 0 | J5: =SUM(E5:I5) -> 761396.83 | N5: 0 | O5: 124854.86 | Q5: =O5+N5+M5+L5+K5+P5 -> 124854.86 | R5: 636541.97 | S5: =J5-Q5 -> 636541.97
A6: 2 | B6: AYOBOLU OLAJIDE OLUFUNSHO | C6: ASST.DIR., INFORMATION | D6: 15 (9) | E6: 620675.58 | G6: 160000 | I6: 0 | J6: =SUM(E6:I6) -> 780675.58 | L6: =50000 -> 50000 | M6: =59583.33 -> 59583.33 | O6: =128556.38 -> 128556.38 | Q6: =O6+N6+M6+L6+K6+P6 -> 238139.71 | R6: 542535.87 | S6: =J6-Q6 -> 542535.87
A7: 3 | B7: ARAOYE GANIYAT TITILOLA | C7: ASST. DIRECTOR, ACCOUNTS | D7: 15(7) | E7: 582118.08 | H7: =80000 -> 80000 | I7: 0 | J7: =SUM(E7:I7) -> 662118.08 | L7: =100000 -> 100000 | M7: =103000 -> 103000 | N7: 0 | O7: 105793.34 | Q7: =O7+N7+M7+L7+K7+P7 -> 308793.34 | R7: 353324.74 | S7: =J7-Q7 -> 353324.74
A8: 4 | B8: MAGAJI BALA | C8: DD ADMIN | D8: 16(9) | E8: 762373.17 | H8: 90000 | J8: =SUM(E8:I8) -> 852373.17 | L8: 50000 | M8: 200000 | O8: 142322.31 | Q8: =O8+N8+M8+L8+K8+P8 -> 392322.31 | R8: 460050.85 | S8: =J8-Q8 -> 460050.85
E9: =SUM(E5:E8) -> 2566563.7 | F9: =SUM(F5:F8) -> 0 | G9: =SUM(G5:G8) -> 320000 | H9: =SUM(H5:H8) -> 170000 | I9: =SUM(I5:I8) -> 0 | J9: =SUM(J5:J8) -> 3056563.7 | K9: =SUM(K5:K8) -> 0 | L9: =SUM(L5:L8) -> 200000 | ... S9: =SUM(S5:S8) -> 1992453.4

Sheet Sheet10

Sheet Sheet8
B3: STAFF NAME | C3: DESIGNATION | D3: GRADE LEVEL | E3: BASIC SALARY | F3: ALLCE/ AREARS | G3: ALLOWANCE | H3: ALLOWANCE | I3: DUTY ALLCE | J3: GROSS SALARY | K3: AUCTION | L3: COOP CONTR/SPEC SAVINGS | M3: COOP. LOAN RECOVERY | N3: NHF DED. | O3: PAYE | P3: EMPLOYEE PENSIONS | Q3: TOTAL DEDUCTION | R3: JUNE, 2024 | S3: JULY, 2024
E4: N | F4: N | G4: N | H4: N | I4: N | J4: N | K4: N | L4: N | M4: N | N4: N | O4: N | P4: N | Q4: N | R4: N | S4: N
A5: 6 | B5: REKIYA IBRAHIM ATTAH | C5: DEPUTY DIRECTOR TRAINING | D5: 16 (9) | E5: 762373.17 | H5: =90000 -> 90000 | I5: =100000+100000 -> 200000 | J5: =E5+F5+G5+H5+I5 -> 1052373.2 | L5: =50000 -> 50000 | M5: =91666.67 -> 91666.67 | O5: ='Additional Leg Duty Allowance'!P3 -> 0 | Q5: =O5+N5+M5+L5+K5+P5 -> 141666.67 | R5: 729984.18 | S5: =J5-Q5 -> 910706.5

Sheet Welfare June
A1: NATIONAL INSTITUTE FOR LEGISLATIVE AND DEMOCRATIC STUDIES
A2: STAFF SALLAH WELFARE JUNE, 2024
B4: STAFF NAME | C4: DESIGNATION | D4: GRADE LEVEL | E4: AMOUNT
E5: N
A6: S/N | B6: DG'S OFFICE
A7: 1 | B7: PROF. ABUBAKAR O. SULAIMAN | C7: DIRECTOR GENERAL | D7: CONSOL | E7: 540000
A8: 2 | B8: RAHEEM USMAN AYIGORO | C8: SA-INFRASTRUCTURE | D8: 16 (9) | E8: 180000
A9: 3 | B9: MARIAM MOHAMMED BELLO | C9: SA- SPECIAL DUTIES | D9: 16 (9) | E9: 180000
A10: 4 | B10: DR IKEME ARTHUR J.O | C10: DEPUTY DIRECTOR, M&E | D10: 16 (9) | E10: 180000
A11: 5 | B11: MOSHOOD M. OLALERE | C11: DEPUTY DIR. GENERAL SERVICE | D11: 16 (9) | E11: 180000
A12: 6 | B12: REKIYA IBRAHIM ATTAH | C12: DEPUTY DIRECTOR TRAINING | D12: 16 (9) | E12: 180000
A13: 7 | B13: ANDRAWUS MUSA | C13: ASST. DIRECTOR, STORES | D13: 15(9) | E13: 126000
A14: 8 | B14: DR FRANCIS NDUM OJIE | C14: AD, TRAINING & IC./SA TO DG | D14: 15(7) | E14: 126000
A15: 9 | B15: ALI ABDULLAHI | C15: CHIEF ICT OFFICER | D15: 14(11) | E15: 90000
A16: 10 | B16: EMILY EKHIDE | C16: RESEARCH FELLOW 1 | D16: 14(10) | E16: 90000
A17: 11 | B17: DORIS DAKDA AARON | C17: RESEARCH FELLOW I | D17: 14(8) | E17: 90000
A18: 12 | B18: ABDULSALAM S. MUSTAPHA | C18: ASST. MANAGER ICT | D18: 13(11) | E18: 90000
... A33: 27 | B33: HARUNA JIBRIL AMEH | C33: ASST. ADMIN. OFFICER | D33: 8(8) | E33: 54000
B34: TOTAL | C34: 27 | E34: =SUM(E7:E33) -> 2990000
B36: INTERNAL AUDIT
A37: 1 | B37: OSANAIYE DAVID AKINYEMI | C37: DIRECTOR INTERNAL AUDIT | D37: 17(9) | E37: 270000
A38: 2 | B38: JAMILA ABDUL | C38: SENIOR INTERNAL AUDITOR | D38: 10(7) | E38: 68000
A39: 3 | B39: IJEOMA EWELUKWA | C39: SENIOR INTERNAL AUDITOR | D39: 10(8) | E39: 68000
C40: 3 | E40: =SUM(E37:E39) -> 406000
B42: LEG. SUPPORT SEVICES
A43: 1 | B43: PROF. EDOBA BRIGHT OMOREGBE | C43: AG. DLSS | D43: 17(9) | E43: 270000
A44: 2 | B44: DR CLINTON JAJA | C44: SENIOR RESEARCH FELLOW | D44: 15(9) | E44: 126000
A45: 3 | B45: BETHEL UZOMA IHUGBA | C45: DEPUTY DIRECTOR, LEGAL RESEARCH | D45: 16(8) | E45: 180000
A46: 4 | B46: OGUCHE SAMUEL | C46: SNR RESEARCH FELLOW | D46: 15(9) | E46: 126000
A47: 5 | B47: IBRAHIM USMAN | C47: SNR RESEARCH FELLOW | D47: 15(9) | E47: 126000
A48: 6 | B48: DR MOHAMMED O. AMALI | C48: SNR RESEARCH FELLOW | D48: 15(7) | E48: 126000
A49: 7 | B49: YAHAYA SHAMSU | C49: RESEARCH FELLOW 1 | D49: 14(10) | E49: 90000
A50: 8 | B50: BILKIS S. LAWAL-GAMBARI | C50: RESEARCH OFFICER | D50: 10(8) | E50: 68000
A51: 9 | B51: ZAINAB AKINDE | C51: RESEARCH OFFICER | D51: 9(8) | E51: 54000
A52: 10 | B52: ABDULLAHI AHMAD USMAN | C52: RESEARCH OFFICER | D52: 9(8) | E52: 54000
A53: 11 | B53: GUNAT NANSAK MARK | C53: RESEARCH OFFICER | D53: 9(8) | E53: 54000
B54: TOTAL | C54: 11 | E54: =SUM(E43:E53) -> 1274000
B56: LEGAL SERVICES
A57: 1 | B57: DR SHUIBU DANWANKA | C57: DIRECTOR LEGAL SERVICES | D57: 17(9) | E57: 270000
A58: 2 | B58: ABDULSALAM BAKO | C58: MANAGER, LEGAL SERVICES | D58: 15 (9) | E58: 126000
...

Sheet Welfare Summary
A2: 1 | B2: Permanent Staff | C2: ='Welfare June'!E194 -> 13858000
A3: 2 | B3: Contract Staff | C3: ='[3]CONTRACT Welfare'!$E$26 -> 1688000
A4: 3 | B4: Casual, Sabbatical & NYSC | C4: ='[3]CAS. SABB. NYSC Welfare'!$D$58 -> 1791000
A5: 4 | B5: Consultants | C5: ='[3]CONSULTANCY Welfare'!$D$31 -> 1746000
A6: 5 | B6: Cleaners & Securities | C6: ='[3]Welfare Others'!$C$92 -> 1225000
C7: =SUM(C2:C6) -> 20308000

Sheet Arrears of Res. Allow
D1: OLD PAYE | E1: ADJUSTED PAYE | F1: DIFFERENCE | G1: FOR 7 MONTHS | H1: TOTAL DIFF IN RES ALLOW | I1: NET DIFFERENCE
A2: AYOBOLU OLAJIDE OLUFUNSHO | B2: ASST.DIR., INFORMATION | C2: 15 (9) | D2: =64596.94 -> 64596.94 | E2: =79956.94 -> 79956.94 | F2: =E2-D2 -> 15360 | G2: =F2*7 -> 107520 | H2: 560000 | I2: =H2-G2 -> 452480

Sheet Additional Leg Duty Allowance
A1: NATIONAL INSTITUTE FOR LEGISLATIVE AND DEMOCRATIC STUDIES
A2: STAFF PAYROLL FOR THE MONTH OF MARCH, 2024
E3: ='[1]FEB 08'!E11/'[1]FEB 08'!M11 -> #REF!
B4: STAFF NAME | C4: DESIGNATION | D4: GRADE LEVEL | E4: BASIC SALARY | F4: ALLCE/ AREARS | G4: ALLOWANCE | H4: ALLOWANCE | I4: DUTY ALLCE | J4: GROSS SALARY | K4: AUCTION | L4: COOP CONTR/SPEC SAVINGS | M4: COOP. LOAN RECOVERY | N4: NHF DED. | O4: PAYE | P4: NEW PAYE | Q4: DIFFERENCE | R4: EMPLOYEE PENSIONS | S4: TOTAL DEDUCTION | T4: FEBRUARY, 2024 | U4: MARCH, 2024
E5: N | G5: N | H5: N | I5: N | J5: N | K5: N | L5: N | M5: N | N5: N | O5: N | P5: N | Q5: N | R5: N | S5: N | T5: N | U5: N
A6: S/N | B6: DG'S OFFICE
A7: 1 | B7: RAHEEM USMAN AYIGORO | C7: SA-INFRASTRUCTURE | D7: 16 (9) | E7: 762373.17 | H7: =90000 -> 90000 | I7: 0 | J7: =E7+F7+G7+H7+I7 -> 852373.17 | L7: =100000 -> 100000 | O7: 130612.26 | P7: ='March New PAYE '!Z7 -> 149812.26 | Q7: =P7-O7 -> 19200 | R7: 60989.853 | S7: =O7+N7+M7+L7+K7+R7 -> 291602.12 | T7: 560771.05 | U7: =J7-S7 -> 560771.05
A8: 2 | B8: MARIAM MOHAMMED BELLO | C8: SA- SPECIAL DUTIES | D8: 16 (9) | E8: 762373.17 | H8: =90000 -> 90000 | I8: =100000+100000 -> 200000 | J8: =E8+F8+G8+H8+I8 -> 1052373.2 | O8: 180722.31 | P8: ='March New PAYE '!Z8 -> 199922.31 | Q8: =P8-O8 -> 19200 | S8: =O8+N8+M8+L8+K8+R8 -> 180722.31 | T8: 871650.85 | U8: =J8-S8 -> 871650.85
A9: 3 | B9: MOSHOOD M. OLALERE | C9: DEPUTY DIR. GENERAL SERVICE | D9: 16 (9) | E9: 762373.17 | H9: =80000+10000 -> 90000 | I9: 150000 | J9: =E9+F9+G9+H9+I9 -> 1002373.2 | L9: =20000+60000 -> 80000 | M9: ='[4]OCTOBER 2023 '!$D$193 -> 230499.8 | N9: 1066.3293 | O9: 159207.53 | P9: ='March New PAYE '!Z10 -> 178407.53 | Q9: =P9-O9 -> 19200 | R9: 60989.853 | S9: =O9+N9+M9+L9+K9+R9 -> 531763.51 | T9: 470609.66 | U9: =J9-S9 -> 470609.66
A10: 4 | B10: REKIYA IBRAHIM ATTAH | C10: DEPUTY DIRECTOR TRAINING | D10: 16 (9) | E10: 762373.17 | H10: =90000 -> 90000 | I10: 100000 | J10: =E10+F10+G10+H10+I10 -> 952373.17 | L10: =50000 -> 50000 | M10: =91666.67 -> 91666.67 | O10: 161522.31 | P10: ='March New PAYE '!Z11 -> 180722.31 | Q10: =P10-O10 -> 19200 | S10: =O10+N10+M10+L10+K10+R10 -> 303188.98 | T10: 649184.18 | U10: =J10-S10 -> 649184.18
A11: 5 | B11: TERFA WILLIAMS ABRAHAM | C11: SNR RESEARCH FELLOW | D11: 15(9) | E11: 620675.58 | G11: =160000 -> 160000 | I11: 100000 | J11: =SUM(E11:I11) -> 880675.58 | O11: 138222.8 | P11: ='March New PAYE '!Z80 -> 157422.8 | Q11: =P11-O11 -> 19200 | R11: 49654.047 | S11: =O11+N11+M11+L11+K11+R11 -> 187876.85 | T11: 692798.73 | U11: =J11-S11 -> 692798.73
