Workbook

Sheet DECEMBER 2023
A1: NATIONAL INSTITUTE FOR LEGISLATIVE AND DEMOCRATIC STUDIES | H1: ='[1]FEB 08'!F8/'[1]FEB 08'!Q8 -> 0.3
A2: STAFF PAYROLL FOR THE MONTH OF DECEMBER 2023
E3: ='[1]FEB 08'!E11/'[1]FEB 08'!M11 -> #REF! | H3: ='[1]FEB 08'!F11/'[1]FEB 08'!Q11 -> #REF!
B4: STAFF NAME | C4: DESIGNATION | D4: GRADE LEVEL | E4: BASIC SALARY | F4: ALLCE/ AREARS | G4: RENT | H4: UTILITY | I4: DOMESTIC | J4: ENTERT. | K4: FURNIT. | L4: FUEL | M4: ALLOWANCE | N4: ALLOWANCE | O4: ALLCE | P4: ALLCE | Q4: DUTY ALLCE | R4: GROSS SALARY | S4: AUCTION | T4: COOP CONTR/SPEC SAVINGS | U4: COOP. LOAN RECOVERY | V4: NHF DED. | W4: PAYE | X4: TOTAL DEDUCTION | Y4: NOVEMBER, 2023 | Z4: DECEMBER, 2023
E5: N | G5: N | H5: N | I5: N | J5: N | K5: N | L5: N | M5: N | N5: N | O5: N | P5: N | Q5: N | R5: N | S5: N | T5: N | U5: N | V5: N | W5: N | X5: N | Y5: N | Z5: N
A6: S/N | B6: DG'S OFFICE
A7: 1 | B7: PROF. ABUBAKAR O. SULAIMAN | C7: DIRECTOR GENERAL | D7: CONSOL | E7: 160488.75 | G7: 320977.5 | H7: 48146.63 | I7: 120366.57 | J7: 72219.94 | K7: 0 | L7: 120366.57 | M7: =250000 -> 250000 | O7: 16048.88 | P7: 25000 | Q7: 25235 | R7: =Q7+P7+O7+N7+M7+L7+K7+J7+I7+H7+G7+F7+E7 -> 1158849.8 | W7: 201165.84 | X7: =W7+V7+U7+T7+S7 -> 201165.84 | Y7: 957684 | Z7: =R7-X7 -> 957684
A8: 2 | B8: RAHEEM USMAN AYIGORO | C8: SA-INFRASTRUCTURE | D8: 16 (9) | E8: =42653.17 -> 42653.17 | G8: =E8*300% -> 127959.51 | H8: =E8*7.5% -> 3198.9877 | I8: 40122.19 | J8: =E8*50% -> 21326.585 | K8: =E8*350% -> 149286.1 | L8: =E8*100% -> 42653.17 | N8: =90000 -> 90000 | O8: =E8*10% -> 4265.317 | P8: 20000 | Q8: 0 | R8: =Q8+P8+O8+N8+M8+L8+K8+J8+I8+H8+G8+F8+E8 -> 541465.02 | T8: =100000 -> 100000 | W8: 82627.951 | X8: =W8+V8+U8+T8+S8 -> 182627.95 | Y8: 358837.07 | Z8: =R8-X8 -> 358837.07
A9: 3 | B9: MARIAM MOHAMMED BELLO | C9: SA- SPECIAL DUTIES | D9: 16(8) | E9: 41157.69 | G9: =E9*300% -> 123473.07 | H9: =E9*7.5% -> 3086.8268 | I9: 40122.19 | J9: =E9*50% -> 20578.845 | K9: =E9*350% -> 144051.92 | L9: =E9*100% -> 41157.69 | N9: =90000 -> 90000 | O9: =E9*10% -> 4115.769 | P9: 20000 | Q9: =100000+100000 -> 200000 | R9: =Q9+P9+O9+N9+M9+L9+K9+J9+I9+H9+G9+F9+E9 -> 727744 | W9: 118393.51 | X9: =W9+V9+U9+T9+S9 -> 118393.51 | Y9: 609350.49 | Z9: =R9-X9 -> 609350.49
A10: 4 | B10: DR IKEME ARTHUR J.O | C10: DEPUTY DIRECTOR, M&E | D10: 16(8) | E10: =41157.69 -> 41157.69 | G10: =E10*300% -> 123473.07 | H10: =E10*7.5% -> 3086.8268 | I10: 40122.19 | J10: =E10*50% -> 20578.845 | K10: =E10*350% -> 144051.92 | L10: =E10*100% -> 41157.69 | M10: 180000 | O10: =E10*10% -> 4115.769 | P10: 20000 | Q10: 0 | R10: =Q10+P10+O10+N10+M10+L10+K10+J10+I10+H10+G10+F10+E10 -> 617744 | T10: =50000 -> 50000 | U10: 0 | V10: 1028.9423 | W10: 97112.68 | X10: =W10+V10+U10+T10+S10 -> 148141.62 | Y10: 469602.37 | Z10: =R10-X10 -> 469602.37
A11: 5 | B11: MOSHOOD M. OLALERE | C11: DEPUTY DIR. GENERAL SERVICE | D11: 16(8) | E11: =41157.69 -> 41157.69 | G11: =E11*300% -> 123473.07 | H11: =E11*7.5% -> 3086.8268 | I11: 40122.19 | J11: =E11*50% -> 20578.845 | K11: =E11*350% -> 144051.92 | L11: =E11*100% -> 41157.69 | N11: =80000+10000 -> 90000 | O11: =E11*10% -> 4115.769 | P11: 20000 | Q11: 150000 | R11: =Q11+P11+O11+N11+M11+L11+K11+J11+I11+H11+G11+F11+E11 -> 677744 | T11: =20000+60000 -> 80000 | U11: ='[2]OCTOBER 2023 '!$D$193 -> 230499.8 | V11: 1028.9423 | W11: =108632.68 -> 108632.68 | X11: =W11+V11+U11+T11+S11 -> 420161.42 | Y11: 257582.57 | Z11: =R11-X11 -> 257582.57
A12: 6 | B12: REKIYA IBRAHIM ATTAH | C12: DEPUTY DIRECTOR TRAINING | D12: 16(8) | E12: 41157.69 | G12: =E12*300% -> 123473.07 | H12: =E12*7.5% -> 3086.8268 | I12: 40122.19 | J12: =E12*50% -> 20578.845 | K12: =E12*350% -> 144051.92 | L12: =E12*100% -> 41157.69 | N12: =90000 -> 90000 | O12: =E12*10% -> 4115.769 | P12: 20000 | Q12: 100000 | R12: =SUM(E12:Q12) -> 627744 | T12: =50000 -> 50000 | U12: =91666.67 -> 91666.67 | W12: =99193.51 -> 99193.51 | X12: =W12+V12+U12+T12+S12 -> 240860.18 | Y12: 386883.82 | Z12: =R12-X12 -> 386883.82
A13: 7 | B13: ANDRAWUS MUSA | C13: ASST. DIRECTOR, STORES | D13: 15(9) | E13: 33507.5 | G13: =E13*300% -> 100522.5 | H13: =E13*7.5% -> 2513.0625 | I13: =40122.19 -> 40122.19 | J13: =E13*50% -> 16753.75 | K13: =E13*350% -> 117276.25 | L13: =E13*100% -> 33507.5 | N13: =80000 -> 80000 | O13: =E13*10% -> 3350.75 | P13: 20000 | Q13: 50000 | R13: =Q13+P13+O13+N13+M13+L13+K13+J13+I13+H13+G13+F13+E13 -> 497553.5 | T13: =50000-40000 -> 10000 | U13: =90000+110000 -> 200000 | V13: 837.6875 | W13: =74036.1 -> 74036.1 | X13: =W13+V13+U13+T13+S13 -> 284873.79 | Y13: 212679.72 | Z13: =R13-X13 -> 212679.72
A14: 8 | B14: DR FRANCIS NDUM OJIE | C14: AD, TRAINING & IC./SA TO DG | D14: 15(7) | E14: 31019.84 | G14: =E14*300% -> 93059.52 | H14: =E14*7.5% -> 2326.488 | I14: =40122.19 -> 40122.19 | J14: =E14*50% -> 15509.92 | K14: =E14*350% -> 108569.44 | L14: =E14*100% -> 31019.84 | M14: 160000 | O14: =E14*10% -> 3101.984 | P14: 20000 | Q14: =100000 -> 100000 | R14: =SUM(E14:Q14) -> 604729.22 | V14: =PROMOTIONS!V29 -> 837.69 | W14: =[3]PROMOTIONS!$X$29 -> 94644.622 | X14: =W14+V14+U14+T14+S14 -> 95482.312 | Y14: 509246.91 | Z14: =R14-X14 -> 509246.91
A15: 9 | B15: ALI ABDULLAHI | C15: CHIEF ICT OFFICER | D15: 14(10) | E15: 27611.23 | G15: =E15*300% -> 82833.69 | H15: =E15*7.5% -> 2070.8422 | I15: 0 | J15: =E15*50% -> 13805.615 | K15: =E15*350% -> 96639.305 | L15: =E15*100% -> 27611.23 | N15: =70000 -> 70000 | O15: =E15*10% -> 2761.123 | P15: 20000 | Q15: =0 -> 0 | R15: =Q15+P15+O15+N15+M15+L15+K15+J15+I15+H15+G15+F15+E15 -> 343333.04 | W15: 44846.62 | X15: =W15+V15+U15+T15+S15 -> 44846.62 | Y15: 298486.42 | Z15: =R15-X15 -> 298486.42
A16: 10 | B16: EMILY EKHIDE | C16: RESEARCH FELLOW 1 | D16: 14(9) | E16: 26732.65 | G16: 80197.95 | H16: 2004.9488 | I16: 0 | J16: 13366.325 | K16: 93564.275 | L16: 26732.65 | M16: 140000 | O16: 2673.265 | P16: 20000 | Q16: 50000 | R16: =SUM(E16:Q16) -> 455272.06 | T16: =50000 -> 50000 | W16: =66078.9 -> 66078.9 | X16: =W16+V16+U16+T16+S16 -> 116078.9 | Y16: 297355.65 | Z16: =R16-X16 -> 339193.16
A17: 11 | B17: ABDULSALAM S. MUSTAPHA | C17: ASST. MANAGER ICT | D17: 13(11) | E17: 26339.3 | G17: =E17*300% -> 79017.9 | H17: =E17*7.5% -> 1975.4475 | I17: 0 | J17: =E17*50% -> 13169.65 | K17: =E17*350% -> 92187.55 | L17: =E17*100% -> 26339.3 | N17: 70000 | O17: =E17*10% -> 2633.93 | P17: 15000 | R17: =SUM(E17:Q17) -> 326663.08 | W17: =42046.06 -> 42046.06 | X17: =42046.06 -> 42046.06 | Y17: 569234.03 | Z17: =R17-X17 -> 284617.02
A18: 12 | B18: PERCY TERFA GBAHABO | C18: HEAD, NILDS LIAISON OFFICE | D18: 13(9) | E18: 24741.26 | G18: =E18*300% -> 74223.78 | H18: =E18*7.5% -> 1855.5945 | I18: 0 | J18: =E18*50% -> 12370.63 | K18: =E18*350% -> 86594.41 | L18: =E18*100% -> 24741.26 | M18: =120000 -> 120000 | O18: =E18*10% -> 2474.126 | P18: 15000 | Q18: 0 | R18: =Q18+P18+O18+N18+M18+L18+K18+J18+I18+H18+G18+F18+E18 -> 362001.06 | T18: =50000 -> 50000 | U18: 0 | W18: 46666.667 | X18: =W18+V18+U18+T18+S18 -> 96666.667 | Y18: 265334.39 | Z18: =R18-X18 -> 265334.39
A19: 13 | B19: HASSANA AHMED IBRAHIM | C19: PA- TO DG | D19: 13 (8) | E19: =23891.12 -> 23891.12 | G19: =E19*300% -> 71673.36 | H19: =E19*7.5% -> 1791.834 | J19: =E19*50% -> 11945.56 | K19: =E19*350% -> 83618.92 | L19: =E19*100% -> 23891.12 | M19: =120000 -> 120000 | O19: =E19*10% -> 2389.112 | P19: 15000 | Q19: =100000 -> 100000 | R19: =Q19+P19+O19+N19+M19+L19+K19+J19+I19+H19+G19+F19+E19 -> 454201.03 | T19: =30000-20000 -> 10000 | U19: =95833.33 -> 95833.33 | V19: 597.278 | W19: =65873.26 -> 65873.26 | X19: =W19+V19+U19+T19+S19 -> 172303.87 | Y19: 281897.16 | Z19: =R19-X19 -> 281897.16
A20: 14 | B20: ADUGBA RICHARD TERSEER | C20: PRINCIPAL INFO. OFFICER | D20: 12(8) | E20: 21520.88 | G20: =E20*300% -> 64562.64 | H20: =E20*7.5% -> 1614.066 | J20: =E20*50% -> 10760.44 | K20: =E20*350% -> 75323.08 | L20: =E20*100% -> 21520.88 | N20: =60000 -> 60000 | O20: =E20*10% -> 2152.088 | P20: 15000 | Q20: 100000 | R20: =Q20+P20+O20+N20+M20+L20+K20+J20+I20+H20+G20+F20+E20 -> 372454.07 | T20: =20000 -> 20000 | U20: =111833.33 -> 111833.33 | W20: =46666.67 -> 46666.67 | X20: =W20+V20+U20+T20+S20 -> 178500 | Y20: 108612.18 | Z20: =R20-X20 -> 193954.07
A21: 15 | B21: LUCKY AGWOM | C21: RESEARCH ASSISTANT | D21: 12(7) | E21: =20749 -> 20749 | G21: =E21*300% -> 62247 | H21: =E21*7.5% -> 1556.175 | J21: =E21*50% -> 10374.5 | K21: =E21*350% -> 72621.5 | L21: =E21*100% -> 20749 | M21: =100000 -> 100000 | O21: =E21*10% -> 2074.9 | P21: 10000 | Q21: 100000 | R21: =SUM(E21:Q21) -> 400372.08 | W21: =55538.11 -> 55538.11 | X21: =W21+V21+U21+T21+S21 -> 55538.11 | Y21: 344833.97 | Z21: =R21-X21 -> 344833.97
A22: 16 | B22: FARUQ ATOFARATI | C22: PA (SPECIAL DUTIES) TO DG | D22: 10(7) | E22: =17286.33 -> 17286.33 | G22: =E22*300% -> 51858.99 | H22: =E22*7.5% -> 1296.4748 | J22: =E22*50% -> 8643.165 | K22: =E22*350% -> 60502.155 | L22: =E22*100% -> 17286.33 | N22: =50000+10000 -> 60000 | O22: =E22*10% -> 1728.633 | P22: 10000 | Q22: 100000 | R22: =SUM(E22:Q22) -> 328602.08 | W22: =42371.82 -> 42371.82 | X22: =W22+V22+U22+T22+S22 -> 42371.82 | Y22: 0 | Z22: =R22-X22 -> 286230.26
A23: 17 | B23: ELIZABETH OGECHUKWU ONYEAKU | C23: ICT OFFICER | D23: 9(8) | E23: 14736.14 | G23: 44208.42 | H23: 1105.2105 | J23: 7368.07 | K23: 51576.49 | L23: 14736.14 | N23: 60000 | O23: 1473.614 | P23: 10000 | R23: =Q23+P23+O23+N23+M23+L23+K23+J23+I23+H23+G23+F23+E23 -> 205204.08 | T23: 10000 | U23: =20000 -> 20000 | W23: 21640.953 | X23: =W23+V23+U23+T23+S23 -> 51640.953 | Y23: 153563.13 | Z23: =R23-X23 -> 153563.13
A24: 18 | B24: VICTOR ASUKWO | C24: ICT OFFICER | D24: 9(8) | E24: =15188.67 -> 15188.67 | G24: =E24*300% -> 45566.01 | H24: =E24*7.5% -> 1139.1502 | J24: =E24*50% -> 7594.335 | K24: =E24*350% -> 53160.345 | L24: =E24*100% -> 15188.67 | N24: =50000+10000 -> 60000 | O24: =E24*10% -> 1518.867 | P24: 10000 | R24: =Q24+P24+O24+N24+M24+L24+K24+J24+I24+H24+G24+F24+E24 -> 209356.05 | W24: 22338.483 | X24: =W24+V24+U24+T24+S24 -> 22338.483 | Y24: 187017.56 | Z24: =R24-X24 -> 187017.56
A25: 19 | B25: ABDULRAHMAN A SULAIMAN | C25: STORE OFFICER | D25: 9(7) | E25: 14736.14 | G25: =E25*300% -> 44208.42 | H25: =E25*7.5% -> 1105.2105 | J25: =E25*50% -> 7368.07 | K25: =E25*350% -> 51576.49 | L25: =E25*100% -> 14736.14 | N25: =60000 -> 60000 | O25: =E25*10% -> 1473.614 | P25: 10000 | R25: =SUM(E25:Q25) -> 205204.08 | T25: =20000 -> 20000 | U25: =17500 -> 17500 | W25: =[3]PROMOTIONS!$X$7 -> 21640.883 | X25: =W25+V25+U25+T25+S25 -> 59140.883 | Y25: 146063.2 | Z25: =R25-X25 -> 146063.2
A26: 20 | B26: DARE SHEU MAGBON | C26: ADMINISTRATION OFFICER | D26: 9(7) | E26: =14736.14 -> 14736.14 | F26: =4766.69 -> 4766.69 | G26: =E26*300% -> 44208.42 | H26: =E26*7.5% -> 1105.2105 | J26: =E26*50% -> 7368.07 | K26: =E26*350% -> 51576.49 | L26: =E26*100% -> 14736.14 | N26: =60000 -> 60000 | O26: =E26*10% -> 1473.614 | P26: 10000 | R26: =SUM(E26:Q26) -> 209970.77 | T26: =30000+20000 -> 50000 | U26: 0 | W26: =21640.88 -> 21640.88 | X26: =W26+V26+U26+T26+S26 -> 71640.88 | Y26: 115688.12 | Z26: =R26-X26 -> 138329.89
A27: 21 | B27: JIMOH ADEBAYO ZAKA | C27: ASST. OFFICER/COMM | D27: 9(8) | E27: 15188.67 | G27: =E27*300% -> 45566.01 | H27: =E27*7.5% -> 1139.1502 | J27: =E27*50% -> 7594.335 | K27: =E27*350% -> 53160.345 | L27: =E27*100% -> 15188.67 | N27: =60000 -> 60000 | O27: =E27*10% -> 1518.867 | P27: 10000 | R27: =Q27+P27+O27+N27+M27+L27+K27+J27+I27+H27+G27+F27+E27 -> 209356.05 | T27: =50000 -> 50000 | U27: 50000 | V27: 0 | W27: 22338.483 | X27: =W27+V27+U27+T27+S27 -> 122338.48 | Y27: 87017.565 | Z27: =R27-X27 -> 87017.565
A28: 22 | B28: MOHAMMED BELLO | C28: PROTOCOL ASSISTANT | D28: 8(8) | E28: =12732 -> 12732 | G28: =E28*300% -> 38196 | H28: =E28*7.5% -> 954.9 | J28: =E28*50% -> 6366 | K28: =E28*350% -> 44562 | L28: =E28*100% -> 12732 | N28: =50000 -> 50000 | O28: =E28*10% -> 1273.2 | P28: 10000 | R28: =SUM(E28:Q28) -> 176816.1 | T28: =0 -> 0 | U28: =26666.67 -> 26666.67 | W28: 17042.714 | X28: =W28+V28+U28+T28+S28 -> 43709.384 | Y28: 133106.72 | Z28: =R28-X28 -> 133106.72
A29: 23 | B29: SULEIMAN ABUBAKAR SODEEQ | C29: ASST. ADMIN. OFFICER | D29: 8(8) | E29: =12732 -> 12732 | G29: =E29*300% -> 38196 | H29: =E29*7.5% -> 954.9 | J29: =E29*50% -> 6366 | K29: =E29*350% -> 44562 | L29: =E29*100% -> 12732 | N29: =50000 -> 50000 | O29: =E29*10% -> 1273.2 | P29: 10000 | R29: =SUM(E29:Q29) -> 176816.1 | T29: =0 -> 0 | W29: 17042.866 | X29: =W29+V29+U29+T29+S29 -> 17042.866 | Y29: 159773.23 | Z29: =R29-X29 -> 159773.23
A30: 24 | B30: HARUNA JIBRIL AMEH | C30: ASST. ADMIN. OFFICER | D30: 8(7) | E30: 12351.94 | G30: 37055.82 | H30: 926.3955 | J30: 6175.97 | K30: 43231.79 | L30: 12351.94 | N30: 50000 | O30: 1235.194 | P30: 10000 | R30: 173329.05 | T30: 20000 | U30: 0 | V30: 0 | W30: 16512.682 | X30: =W30+V30+U30+T30+S30 -> 36512.682 | Y30: 136816.37 | Z30: =R30-X30 -> 136816.37
B31: TOTAL | C31: 24 | E31: =SUM(E7:E30) -> 733573.49 | F31: =SUM(F7:F30) -> 4766.69 | G31: =SUM(G7:G30) -> 2040231.7 | H31: =SUM(H7:H30) -> 91127.986 | I31: =SUM(I7:I30) -> 401221.9 | J31: =SUM(J7:J30) -> 358762.31 | K31: =SUM(K7:K30) -> 2005796.6 | L31: =SUM(L7:L30) -> 693451.31 | ... Z31: =SUM(Z7:Z30) -> 7198101.1
B33: INTERNAL AUDIT
A34: 1 | B34: OSANAIYE DAVID AKINYEMI | C34: DIRECTOR INTERNAL AUDIT | D34: 17(9) | E34: 81740.02 | G34: =E34*300% -> 245220.06 | H34: =E34*7.5% -> 6130.5015 | I34: 80244.38 | J34: =E34*50% -> 40870.01 | K34: =E34*350% -> 286090.07 | L34: =E34*100% -> 81740.02 | N34: =100000 -> 100000 | O34: =E34*10% -> 8174.002 | P34: 20000 | R34: =SUM(E34:Q34) -> 950209.06 | S34: ='DECEMBER 2023'!F196 -> 0 | T34: =100000 -> 100000 | U34: 0 | W34: 161106.81 | X34: =W34+V34+U34+T34+S34 -> 261106.81 | Y34: 689102.26 | Z34: =R34-X34 -> 689102.26
A35: 2 | B35: JAMILA ABDUL | C35: AUDITOR II | D35: 8(7) | E35: 12351.94 | G35: =E35*300% -> 37055.82 | H35: =E35*7.5% -> 926.3955 | J35: =E35*50% -> 6175.97 | K35: =E35*350% -> 43231.79 | L35: =E35*100% -> 12351.94 | N35: =50000 -> 50000 | O35: =E35*10% -> 1235.194 | P35: 10000 | R35: =(Q35+P35+O35+N35+M35+L35+K35+J35+I35+H35+G35+F35+E35) -> 173329.05 | T35: =20000 -> 20000 | V35: 0 | W35: 16512.682 | X35: =W35+V35+U35+T35+S35 -> 36512.682 | Y35: 136816.37 | Z35: =R35-X35 -> 136816.37
A36: 3 | B36: IJEOMA EWELUKWA | C36: AUDIT OFFICER | D36: 10(7) | E36: =17286.33 -> 17286.33 | G36: =E36*300% -> 51858.99 | H36: =E36*7.5% -> 1296.4748 | J36: =E36*50% -> 8643.165 | K36: =E36*350% -> 60502.155 | L36: =E36*100% -> 17286.33 | N36: =50000+10000 -> 60000 | O36: =E36*10% -> 1728.633 | P36: 10000 | R36: =SUM(E36:Q36) -> 228602.08 | T36: =10000 -> 10000 | W36: =25571.73 -> 25571.73 | X36: =W36+V36+U36+T36+S36 -> 35571.73 | Y36: 369165.43 | Z36: =R36-X36 -> 193030.35
C37: 3 | E37: =SUM(E34:E36) -> 111378.29 | F37: =SUM(F34:F36) -> 0 | G37: =SUM(G34:G36) -> 334134.87 | H37: =SUM(H34:H36) -> 8353.3718 | I37: =SUM(I34:I36) -> 80244.38 | J37: =SUM(J34:J36) -> 55689.145 | K37: =SUM(K34:K36) -> 389824.02 | L37: =SUM(L34:L36) -> 111378.29 | ... X37: =SUM(X34:X36) -> 333191.22 | Y37: 1195084.1 | Z37: =SUM(Z34:Z36) -> 1018949
B39: LEG. SUPPORT SEVICES
A40: 1 | B40: PROF. EDOBA BRIGHT OMOREGBE | C40: AG. DLSS | D40: 17(9) | E40: 81740.02 | G40: =E40*300% -> 245220.06 | H40: =E40*7.5% -> 6130.5015 | I40: 80244.38 | J40: =E40*50% -> 40870.01 | K40: =E40*350% -> 286090.07 | L40: =E40*100% -> 81740.02 | M40: =200000 -> 200000 | O40: =E40*10% -> 8174.002 | P40: 20000 | R40: =SUM(E40:Q40) -> 1050209.1 | T40: =200000 -> 200000 | U40: =380000 -> 380000 | W40: 180306.81 | X40: =W40+V40+U40+T40+S40 -> 760306.81 | Y40: 289902.26 | Z40: =R40-X40 -> 289902.26
A41: 2 | B41: DR CLINTON JAJA | C41: SENIOR RESEARCH FELLOW | D41: 15(9) | E41: 33507.5 | G41: =E41*300% -> 100522.5 | H41: =E41*7.5% -> 2513.0625 | I41: 40122.19 | J41: =E41*50% -> 16753.75 | K41: =E41*350% -> 117276.25 | L41: =E41*100% -> 33507.5 | M41: =160000 -> 160000 | O41: =E41*10% -> 3350.75 | P41: 20000 | Q41: 0 | R41: =SUM(E41:Q41) -> 527553.5 | T41: =50000 -> 50000 | U41: =385000 -> 385000 | W41: =79956.9391466667*2 -> 159913.88 | X41: =W41+V41+U41+T41+S41 -> 594913.88 | Y41: 25193.124 | Z41: =R41-X41 -> -67360.376
A42: 3 | B42: BETHEL UZOMA IHUGBA | C42: DEPUTY DIRECTOR, LEGAL RESEARCH | D42: 16(7) | E42: =39662.25 -> 39662.25 | F42: ='PROMOTIONS '!AB11 -> 556088.58 | G42: =E42*300% -> 118986.75 | H42: =E42*7.5% -> 2974.6687 | I42: 40122.19 | J42: =E42*50% -> 19831.125 | K42: =E42*350% -> 138817.88 | L42: =E42*100% -> 39662.25 | M42: =180000 -> 180000 | O42: =E42*10% -> 3966.225 | P42: 20000 | R42: =SUM(E42:Q42) -> 1160111.9 | T42: =80000+23000 -> 103000 | U42: =246905.96 -> 246905.96 | W42: =94639.15 -> 94639.15 | X42: =W42+V42+U42+T42+S42 -> 444545.11 | Y42: 97690.603 | Z42: =R42-X42 -> 715566.8
...

Sheet MEMO 1
A2: NATIONAL INSTITUTE FOR LEGISLATIVE AND DEMOCRATIC STUDIES
A3: INTERNAL MEMO
A4: FROM : DEPUTY DIRECTOR, FINANCE AND ACCOUNTS
A5: THRU: DIRECTOR, FINANCE AND ACCOUNTS
A6: TO: DG
A7: 29TH JANUARY , 2021
A9: SUBJECT: PAYROLL FOR THE MONTH OF JANUARY, 2021
A10: Find below the details of NILDS Staff Payroll for the month of January, 2021
A13: TO: | C13: DIRECTOR, GENERAL
A14: THRU: | C14: DIRECTOR, FINANCE AND ACCOUNT
A15: FROM: | C15: DEPUTY DIRECTOR, FINANCE AND ACCOUNTS
A16: DATE: | C16: 19TH DECEMBER, 2023
A18: SUBJECT: PAYROLL FOR THE MONTH OF DECEMBER, 2023
A19: Find below the details of NILDS Staff Payroll for the Month of December 2023: | G19: NGN | H19: NGN
A20: GROSS SALARY FOR DECEMBER, 2023 | H20: ='DECEMBER 2023'!R194 -> 52931904
A22: DEDUCTIONS
A23: COOP SOCIETY DEDUCTIONS ( CONTR.& SPEC. SAVINGS) | G23: ='DECEMBER 2023'!T194 -> 4768500
A24: COOP LOAN RECOVERY | G24: ='DECEMBER 2023'!U194 -> 7178349.5
A25: PAYE DEDUCTIONS | G25: ='DECEMBER 2023'!W194 -> 7194626.4
A26: NHF DEDUCTIONS | G26: ='DECEMBER 2023'!V194 -> 23490.677
A27: TOTAL DEDUCTIONS FOR DECEMBER, 2023 | H27: =G23+G24+G25+G26 -> 19164967
A28: NET PAY AS PER DECEMBER, 2023 PAYROLL | H28: =H20-H27 -> 33766937
A29: NET PAY AS PER NOVEMBER, 2023 PAYROLL | H29: ='DECEMBER 2023'!Y194 -> 33180438
A30: NET INCREASE/ (DECREASE) IN PAY FOR DECEMBER, 2023 | H30: =H28-H29 -> 586499.64
A31: ANALYSED AS FOLLOWS:
A32: Effect of Cooperative adjustment for December, 2023 | H32: =-370416.67 -> -370416.67
A33: Effect of removal of Arrears to Abdulsalam Mustapha & 7 Others | H33: =1850703.91 -> 1850703.9
A34: Net Effect of Promotions and Arrears to Dr. Bethel Ihugba & 3 Others | H34: =-1358548.88 -> -1358548.9
A35: Effect of Arrears of Duty Allowance to Adejoke Akinsanmi & 1 other | H35: =-41837.51-375628.34 -> -417465.85
A36: Net Effect of Enrolment of Faruq Atofarati | H36: =-4541.9-286230.25 -> -290772.15
H37: =SUM(H32:H36) -> -586499.64
E39: NOVEMBER, 2023 | G39: DECEMBER, 2023
E40: No. of Staff | F40: N | G40: No. of Staff | H40: N
A41: 1 | B41: Director General's Office | E41: 33 | F41: ='DECEMBER 2023'!Y31 -> 7046666.7 | G41: ='DECEMBER 2023'!C31 -> 24 | H41: ='DECEMBER 2023'!Z31 -> 7198101.1
A42: 2 | B42: Internal Audit | E42: 2 | F42: ='DECEMBER 2023'!Y37 -> 1195084.1 | G42: ='DECEMBER 2023'!C37 -> 3 | H42: ='DECEMBER 2023'!Z37 -> 1018949
A43: 3 | B43: Legis. Support Services | E43: 11 | F43: ='DECEMBER 2023'!Y52 -> 2789135.8 | G43: ='DECEMBER 2023'!C52 -> 12 | H43: ='DECEMBER 2023'!Z52 -> 3378453.8
A44: 4 | B44: Legal Services | E44: 2 | F44: ='DECEMBER 2023'!Y57 -> 808634.33 | G44: ='DECEMBER 2023'!C57 -> 2 | H44: ='DECEMBER 2023'!Z57 -> 808634.33
A45: 5 | B45: Democracy and Governance | E45: 13 | F45: ='DECEMBER 2023'!Y71 -> 3523240.8 | G45: ='DECEMBER 2023'!C71 -> 12 | H45: ='DECEMBER 2023'!Z71 -> 2562691.9
A46: 6 | B46: Studies | E46: 4 | F46: ='DECEMBER 2023'!Y81 -> 2073779.4 | G46: ='DECEMBER 2023'!C81 -> 7 | H46: ='DECEMBER 2023'!Z81 -> 2073779.4
A47: 7 | B47: Economic Dev. & Social Research | E47: 12 | F47: ='DECEMBER 2023'!Y95 -> 3225624.5 | G47: ='DECEMBER 2023'!C95 -> 11 | H47: ='DECEMBER 2023'!Z95 -> 3181874.5
...

Sheet PROMOTIONS 
A1: NATIONAL INSTITUTE FOR LEGISLATIVE AND DEMOCRATIC STUDIES | G1: ='[1]FEB 08'!F8/'[1]FEB 08'!Q8 -> 0.3
A2: STAFF PAYROLL FOR THE MONTH OF NOVEMBER 2023
E3: ='[1]FEB 08'!E11/'[1]FEB 08'!M11 -> #REF! | G3: ='[1]FEB 08'!F11/'[1]FEB 08'!Q11 -> #REF!
B4: STAFF NAME | C4: DESIGNATION | D4: CURRENT GRADE LEVEL | E4: BASIC SALARY | F4: RENT | G4: UTILITY | H4: DOMESTIC | I4: ENTERT. | J4: FURNIT. | K4: FUEL | L4: ALLOWANCE | M4: ALLOWANCE | N4: ALLCE | O4: ALLCE | P4: DUTY ALLCE | Q4: CURRENT GROSS SALARY | R4: NEW GRADE LEVEL | S4: NEW GROSS SALARY | T4: INCREMENT IN GROSS SALARY | U4: CURRENT NHF | V4: NEW NHF | W4: CURRENT PAYE | X4: NEW PAYE | Y4: INCREMENT IN PAYE | Z4: NET SALARY INCREMENT | AA4: NO OF MONTHS | AB4: ARREARS
E5: N | F5: N | G5: N | H5: N | I5: N | J5: N | K5: N | L5: N | M5: N | N5: N | O5: N | P5: N | Q5: N | S5: N | U5: N | W5: N
A6: S/N | B6: DG'S OFFICE
A7: 1 | B7: SHEU MAGABON DARE | C7: ADMIN ASSISTANT | D7: 8(10) | E7: 13492.21 | G7: =E7*300% -> 40476.63 | H7: =E7*7.5% -> 1011.9157 | J7: =E7*50% -> 6746.105 | K7: =E7*350% -> 47222.735 | L7: =E7*100% -> 13492.21 | N7: =50000 -> 50000 | O7: =E7*10% -> 1349.221 | P7: 10000 | Q7: =SUM(E7:Q7) -> 183791.03 | R7: 9(7) | S7: =205204.08 -> 205204.08 | T7: =205204.08-183791.03 -> 21413.05 | W7: 18102.9 | X7: =21640.88 -> 21640.88 | Y7: =X7-W7 -> 3537.98 | Z7: =T7-Y7 -> 17875.07 | AA7: =8/30 -> 0.26666667 | AB7: =Z7*AA7 -> 4766.6853
B8: TOTAL | E8: =SUM(E7:E7) -> 13492.21 | F8: =SUM(F7:F7) -> 0 | G8: =SUM(G7:G7) -> 40476.63 | H8: =SUM(H7:H7) -> 1011.9157 | I8: =SUM(I7:I7) -> 0 | J8: =SUM(J7:J7) -> 6746.105 | K8: =SUM(K7:K7) -> 47222.735 | L8: =SUM(L7:L7) -> 13492.21 | ... P8: =SUM(P7:P7) -> 10000 | Q8: =E8+F8+G8+H8+I8+J8+K8+L8+M8+N8+O8+P8 -> 183791.03 | S8: =SUM(S7:S7) -> 205204.08 | T8: =SUM(T7:T7) -> 21413.05 | U8: =SUM(U7:U7) -> 0 | V8: =SUM(V7:V7) -> 0 | W8: =SUM(W7:W7) -> 18102.9 | X8: =SUM(X7:X7) -> 21640.88 | Y8: =SUM(Y7:Y7) -> 3537.98 | Z8: =SUM(Z7:Z7) -> 17875.07 | AB8: =SUM(AB7:AB7) -> 4766.6853
B10: LEG. SUPPORT SEVICES
A11: 2 | B11: BETHEL UZOMA IHUGBA | C11: SNR RESEARCH FELLOW | D11: 15(9) | E11: 33507.5 | G11: =E11*300% -> 100522.5 | H11: =E11*7.5% -> 2513.0625 | I11: 40122.19 | J11: =E11*50% -> 16753.75 | K11: =E11*350% -> 117276.25 | L11: =E11*100% -> 33507.5 | M11: =160000 -> 160000 | O11: =E11*10% -> 3350.75 | P11: 20000 | Q11: =SUM(E11:Q11) -> 527553.5 | R11: 16(7) | S11: ='SALARY STRUCTURE'!H19+180000 -> 604023.33 | T11: =604023.33-527553.5 -> 76469.83 | U11: =837.69 -> 837.69 | V11: =1028.94 -> 1028.94 | W11: =79956.94 -> 79956.94 | X11: =94639.15 -> 94639.15 | Y11: =X11-W11 -> 14682.21 | Z11: =T11-Y11 -> 61787.62 | AA11: 9 | AB11: =Z11*AA11 -> 556088.58
A12: 3 | B12: DR MOHAMMED O. AMALI | C12: RESEARCH FELLOW I | D12: 14(10) | E12: 27611.23 | G12: =E12*300% -> 82833.69 | H12: =E12*7.5% -> 2070.8422 | J12: =E12*50% -> 13805.615 | K12: =E12*350% -> 96639.305 | L12: =E12*100% -> 27611.23 | M12: =140000 -> 140000 | O12: =E12*10% -> 2761.123 | P12: 20000 | Q12: =SUM(E12:Q12) -> 413333.04 | R12: 15(7) | S12: ='SALARY STRUCTURE'!H18+160000 -> 504720.17 | T12: =504720.05-413333.04 -> 91387.01 | U12: 0 | W12: 57889.865 | X12: =75436.17 -> 75436.17 | Y12: =X12-W12 -> 17546.305 | Z12: =T12-Y12 -> 73840.705 | AA12: 0 | AB12: =Z12*AA12 -> 0
B13: TOTAL | E13: =SUM(E11:E12) -> 61118.73 | F13: =SUM(F11:F12) -> 0 | G13: =SUM(G11:G12) -> 183356.19 | H13: =SUM(H11:H12) -> 4583.9047 | I13: =SUM(I11:I12) -> 40122.19 | J13: =SUM(J11:J12) -> 30559.365 | K13: =SUM(K11:K12) -> 213915.55 | L13: =SUM(L11:L12) -> 61118.73 | ... AB13: =SUM(AB11:AB12) -> 556088.58
T14: =S14-Q14 -> 0
Y15: =X15-W15 -> 0 | Z15: =T15-Y15 -> 0 | AB15: =Z15*AA15 -> 0
B16: FINANCE & ACCOUNTS | Y16: =X16-W16 -> 0 | Z16: =T16-Y16 -> 0 | AB16: =Z16*AA16 -> 0
A17: 3 | B17: RAHILA NURUDEEN HABU | C17: ASST. DIRECTOR, ACCOUNTS | D17: 15(9) | E17: 33507.5 | G17: =E17*300% -> 100522.5 | H17: =E17*7.5% -> 2513.0625 | I17: 40122.19 | J17: =E17*50% -> 16753.75 | K17: =E17*350% -> 117276.25 | L17: =E17*100% -> 33507.5 | M17: =80000 -> 80000 | N17: =E17*10% -> 3350.75 | O17: 20000 | P17: 100000 | Q17: =SUM(E17:P17) -> 547553.5 | R17: 16(7) | S17: ='SALARY STRUCTURE'!H19+190000 -> 614023.33 | T17: =S17-Q17 -> 66469.831 | U17: =837.69 -> 837.69 | V17: =1028.94 -> 1028.94 | W17: =83626.1 -> 83626.1 | X17: =96398.31 -> 96398.31 | Y17: =X17-W17 -> 12772.21 | Z17: =T17-Y17 -> 53697.621 | AA17: 11 | AB17: =Z17*AA17 -> 590673.83
B18: OJOGIWA ABISOLA GANIAT | C18: ASST. CHIEF BUDGET OFFICER | D18: 13(10) | E18: 25523.45 | G18: =E18*300% -> 76570.35 | H18: =E18*7.5% -> 1914.2587 | J18: =E18*50% -> 12761.725 | K18: =E18*350% -> 89332.075 | L18: =E18*100% -> 25523.45 | N18: =70000 -> 70000 | O18: =E18*10% -> 2552.345 | P18: 15000 | Q18: =SUM(E18:Q18) -> 319177.65 | R18: 14 (7) | S18: ='DECEMBER 2023'!R127 -> 327211.37 | T18: =327211.37-319177.65 -> 8033.72 | U18: 638.09 | V18: 690.28 | W18: 40684.6 | X18: 42034.24 | Y18: =X18-W18 -> 1349.64 | Z18: =T18-Y18 -> 6684.08 | AA18: 0 | AB18: =Z18*AA18 -> 0
B19: TOTAL | E19: =SUM(E17:E17) -> 33507.5 | F19: =SUM(F17:F17) -> 0 | G19: =SUM(G17:G17) -> 100522.5 | H19: =SUM(H17:H17) -> 2513.0625 | I19: =SUM(I17:I17) -> 40122.19 | J19: =SUM(J17:J17) -> 16753.75 | K19: =SUM(K17:K17) -> 117276.25 | L19: =SUM(L17:L17) -> 33507.5 | M19: =SUM(#REF!) -> #REF! | N19: =SUM(M17:M17) -> 80000 | O19: =SUM(N17:N17) -> 3350.75 | P19: =SUM(O17:O17) -> 20000 | Q19: =SUM(P17:P17) -> 100000 | S19: =SUM(S17:S17) -> 614023.33 | T19: =SUM(T17:T17) -> 66469.831 | U19: =SUM(U17:U17) -> 837.69 | V19: =SUM(V17:V17) -> 1028.94 | W19: =SUM(W17:W17) -> 83626.1 | X19: =SUM(X17:X17) -> 96398.31 | Y19: =SUM(Y17:Y17) -> 12772.21 | Z19: =SUM(Z17:Z17) -> 53697.621 | AB19: =SUM(AB17:AB17) -> 590673.83
B21: FINANCE & ACCOUNTS
A22: 15 | B22: YUNUSA ABDULMUMINI ELEOJO | C22: SENIOR DRIVER | D22: 5(11) | E22: 5428.12 | F22: =E22*300% -> 16284.36 | G22: =E22*7.5% -> 407.109 | I22: =E22*50% -> 2714.06 | J22: =E22*350% -> 18998.42 | K22: =E22*100% -> 5428.12 | M22: =20000 -> 20000 | N22: =E22*10% -> 542.812 | O22: 5000 | P22: =7000 -> 7000 | Q22: =SUM(E22:P22) -> 81803.001 | R22: 7(3) | S22: ='SALARY STRUCTURE'!#REF!+30000 -> #REF! | T22: =S22-Q22 -> #REF! | W22: 4365.3308 | X22: ='[7]October 2023'!$Z$164 -> 8312.59 | Y22: =X22-W22 -> 3947.2592 | Z22: =T22-Y22 -> #REF! | AA22: =(10/31)+2 -> 2.3225806 | AB22: =Z22*AA22 -> #REF!
A23: 16 | B23: JOHN GIMAH | C23: SENIOR DRIVER | D23: 5(11) | E23: 5428.12 | F23: =E23*300% -> 16284.36 | G23: =E23*7.5% -> 407.109 | I23: =E23*50% -> 2714.06 | J23: =E23*350% -> 18998.42 | K23: =E23*100% -> 5428.12 | M23: =20000 -> 20000 | N23: =E23*10% -> 542.812 | O23: 5000 | P23: =7000 -> 7000 | Q23: =SUM(E23:P23) -> 81803.001 | R23: 7(3) | S23: ='SALARY STRUCTURE'!#REF!+30000 -> #REF! | T23: =S23-Q23 -> #REF! | W23: =4365.33075466667 -> 4365.3308 | X23: ='[7]October 2023'!$Z$164 -> 8312.59 | Y23: =X23-W23 -> 3947.2592 | Z23: =T23-Y23 -> #REF! | AA23: =(17/31)+1 -> 1.5483871 | AB23: =Z23*AA23 -> #REF!
A24: 17 | B24: ABUBAKAR MUSA DANLAMI | C24: SENIOR DRIVER | D24: 5(12) | E24: =5598.92 -> 5598.92 | F24: =E24*300% -> 16796.76 | G24: =E24*7.5% -> 419.919 | I24: =E24*50% -> 2799.46 | J24: =E24*350% -> 19596.22 | K24: =E24*100% -> 5598.92 | M24: =20000 -> 20000 | N24: =E24*10% -> 559.892 | O24: 5000 | P24: =7000 -> 7000 | Q24: =SUM(E24:P24) -> 83370.091 | R24: 7(3) | S24: 115104.92 | T24: =S24-Q24 -> 31734.826 | W24: 4504.4109 | X24: ='[7]October 2023'!$Z$164 -> 8312.59 | Y24: =X24-W24 -> 3808.1791 | Z24: =T24-Y24 -> 27926.647 | AA24: 8 | AB24: =Z24*AA24 -> 223413.17
L25: =226713.38+70000 -> 296713.38
B27: GRAND TOTAL | E27: =E19+E13+E8 -> 108118.44 | F27: =F19+F13+F8 -> 0 | G27: =G19+G13+G8 -> 324355.32 | H27: =H19+H13+H8 -> 8108.883 | I27: =I19+I13+I8 -> 80244.38 | J27: =J19+J13+J8 -> 54059.22 | K27: =K19+K13+K8 -> 378414.54 | L27: =L19+L13+L8 -> 108118.44 | ... AB27: =AB19+AB13+AB8 -> 1151529.1

Sheet CHRISTMAS WELFARE
A1: NATIONAL INSTITUTE FOR LEGISLATIVE AND DEMOCRATIC STUDIES
A2: STAFF CHRISTMAS WELFARE DECEMBER 2023
E3: ='[1]FEB 08'!E11/'[1]FEB 08'!M11 -> #REF!
B4: STAFF NAME | C4: DESIGNATION | D4: GRADE LEVEL | E4: AMOUNT
E5: N
A6: S/N | B6: DG'S OFFICE
A7: 1 | B7: PROF. ABUBAKAR O. SULAIMAN | C7: DIRECTOR GENERAL | D7: CONSOL | E7: 540000
A8: 2 | B8: RAHEEM USMAN AYIGORO | C8: SA-INFRASTRUCTURE | D8: 16 (9) | E8: 180000
A9: 3 | B9: MARIAM MOHAMMED BELLO | C9: SA- SPECIAL DUTIES | D9: 16(8) | E9: 180000
A10: 4 | B10: DR IKEME ARTHUR J.O | C10: DEPUTY DIRECTOR, M&E | D10: 16(8) | E10: 180000
A11: 5 | B11: MOSHOOD M. OLALERE | C11: DEPUTY DIR. GENERAL SERVICE | D11: 16(8) | E11: 180000
A12: 6 | B12: REKIYA IBRAHIM ATTAH | C12: DEPUTY DIRECTOR TRAINING | D12: 16(8) | E12: 180000
A13: 7 | B13: ANDRAWUS MUSA | C13: ASST. DIRECTOR, STORES | D13: 15(9) | E13: 126000
A14: 8 | B14: DR FRANCIS NDUM OJIE | C14: AD, TRAINING & IC./SA TO DG | D14: 15(7) | E14: 126000
A15: 9 | B15: ALI ABDULLAHI | C15: CHIEF ICT OFFICER | D15: 14(10) | E15: =90000 -> 90000
A16: 10 | B16: EMILY EKHIDE | C16: RESEARCH FELLOW 1 | D16: 14(9) | E16: =90000 -> 90000
A17: 11 | B17: ABDULSALAM S. MUSTAPHA | C17: ASST. MANAGER ICT | D17: 13(11) | E17: =90000 -> 90000
A18: 12 | B18: PERCY TERFA GBAHABO | C18: HEAD, NILDS LIAISON OFFICE | D18: 13(9) | E18: =90000 -> 90000
A19: 13 | B19: HASSANA AHMED IBRAHIM | C19: PA- TO DG | D19: 13 (8) | E19: =90000 -> 90000
A20: 14 | B20: ADUGBA RICHARD TERSEER | C20: PRINCIPAL INFO. OFFICER | D20: 12(8) | E20: 54000
A21: 15 | B21: LUCKY AGWOM | C21: RESEARCH ASSISTANT | D21: 12(7) | E21: 54000
A22: 16 | B22: FARUQ ATOFARATI | C22: PA (SPECIAL DUTIES) TO DG | D22: 10(7) | E22: 54000
A23: 17 | B23: ELIZABETH OGECHUKWU ONYEAKU | C23: ICT OFFICER | D23: 9(8) | E23: 54000
A24: 18 | B24: VICTOR ASUKWO | C24: ICT OFFICER | D24: 9(8) | E24: 54000
A25: 19 | B25: ABDULRAHMAN A SULAIMAN | C25: STORE OFFICER | D25: 9(7) | E25: 54000
A26: 20 | B26: DARE SHEU MAGBON | C26: ADMINISTRATION OFFICER | D26: 9(7) | E26: 54000
A27: 21 | B27: JIMOH ADEBAYO ZAKA | C27: ASST. OFFICER/COMM | D27: 9(8) | E27: 54000
A28: 22 | B28: MOHAMMED BELLO | C28: PROTOCOL ASSISTANT | D28: 8(8) | E28: 54000
A29: 23 | B29: SULEIMAN ABUBAKAR SODEEQ | C29: ASST. ADMIN. OFFICER | D29: 8(8) | E29: 54000
A30: 24 | B30: HARUNA JIBRIL AMEH | C30: ASST. ADMIN. OFFICER | D30: 8(7) | E30: 54000
B31: TOTAL | C31: 24 | E31: =SUM(E7:E30) -> 2736000
B33: INTERNAL AUDIT
A34: 1 | B34: OSANAIYE DAVID AKINYEMI | C34: DIRECTOR INTERNAL AUDIT | D34: 17(9) | E34: 270000
A35: 2 | B35: JAMILA ABDUL | C35: AUDITOR II | D35: 8(7) | E35: 54000
A36: 3 | B36: IJEOMA EWELUKWA | C36: AUDIT OFFICER | D36: 10(7) | E36: 54000
C37: 3 | E37: =SUM(E34:E36) -> 378000
B39: LEG. SUPPORT SEVICES
A40: 1 | B40: PROF. EDOBA BRIGHT OMOREGBE | C40: AG. DLSS | D40: 17(9) | E40: 270000
A41: 2 | B41: BETHEL UZOMA IHUGBA | C41: DEPUTY DIRECTOR, LEGAL RESEARCH | D41: 16(7) | E41: =180000 -> 180000
A42: 3 | B42: DR CLINTON JAJA | C42: SENIOR RESEARCH FELLOW | D42: 15(9) | E42: 126000
...

Sheet CHRISTMAS WELFARE 1

Sheet HALF 2023 (2)
A1: NATIONAL INSTITUTE FOR LEGISLATIVE AND DEMOCRATIC STUDIES
A2: STAFF PAYROLL FOR THE MONTH OF DECEMBER 2023
B4: STAFF NAME | C4: DESIGNATION | D4: GRADE LEVEL | E4: CONS. SALARY | F4: HALF SALARY
E5: N | F5: N
A6: S/N | B6: DG'S OFFICE
A7: 1 | B7: PROF. ABUBAKAR O. SULAIMAN | C7: DIRECTOR GENERAL | D7: CONSOL | E7: 1158849.8 | F7: =E7/2 -> 579424.92
A8: 2 | B8: RAHEEM USMAN AYIGORO | C8: SA-INFRASTRUCTURE | D8: 16 (9) | E8: 541465.02 | F8: =E8/2 -> 270732.51
A9: 3 | B9: MARIAM MOHAMMED BELLO | C9: SA- SPECIAL DUTIES | D9: 16(8) | E9: 727744 | F9: =E9/2 -> 363872
A10: 4 | B10: DR IKEME ARTHUR J.O | C10: DEPUTY DIRECTOR, M&E | D10: 16(8) | E10: 617744 | F10: =E10/2 -> 308872
A11: 5 | B11: MOSHOOD M. OLALERE | C11: DEPUTY DIR. GENERAL SERVICE | D11: 16(8) | E11: 677744 | F11: =E11/2 -> 338872
A12: 6 | B12: REKIYA IBRAHIM ATTAH | C12: DEPUTY DIRECTOR TRAINING | D12: 16(8) | E12: 627744 | F12: =E12/2 -> 313872
A13: 7 | B13: ANDRAWUS MUSA | C13: ASST. DIRECTOR, STORES | D13: 15(9) | E13: 497553.5 | F13: =E13/2 -> 248776.75
A14: 8 | B14: DR FRANCIS NDUM OJIE | C14: AD, TRAINING & IC./SA TO DG | D14: 15(7) | E14: 604729.22 | F14: =E14/2 -> 302364.61
A15: 9 | B15: ALI ABDULLAHI | C15: CHIEF ICT OFFICER | D15: 14(10) | E15: 343333.04 | F15: =E15/2 -> 171666.52
A16: 10 | B16: EMILY EKHIDE | C16: RESEARCH FELLOW 1 | D16: 14(9) | E16: 455272.06 | F16: =E16/2 -> 227636.03
A17: 11 | B17: ABDULSALAM S. MUSTAPHA | C17: ASST. MANAGER ICT | D17: 13(11) | E17: 326663.08 | F17: =E17/2 -> 163331.54
A18: 12 | B18: PERCY TERFA GBAHABO | C18: HEAD, NILDS LIAISON OFFICE | D18: 13(9) | E18: 362001.06 | F18: =E18/2 -> 181000.53
... A30: 24 | B30: HARUNA JIBRIL AMEH | C30: ASST. ADMIN. OFFICER | D30: 8(7) | E30: 173329.05 | F30: =E30/2 -> 86664.525
B31: TOTAL | C31: 24 | E31: 10062524 | F31: =SUM(F7:F30) -> 5028878.8
B33: INTERNAL AUDIT
A34: 1 | B34: OSANAIYE DAVID AKINYEMI | C34: DIRECTOR INTERNAL AUDIT | D34: 17(9) | E34: 950209.06 | F34: =E34/2 -> 475104.53
A35: 2 | B35: JAMILA ABDUL | C35: AUDITOR II | D35: 8(7) | E35: 173329.05 | F35: =E35/2 -> 86664.525
A36: 3 | B36: IJEOMA EWELUKWA | C36: AUDIT OFFICER | D36: 10(7) | E36: 228602.08 | F36: =E36/2 -> 114301.04
C37: 3 | E37: 1352140.2 | F37: =SUM(F34:F36) -> 676070.1
B39: LEG. SUPPORT SEVICES
A40: 1 | B40: PROF. EDOBA BRIGHT OMOREGBE | C40: AG. DLSS | D40: 17(9) | E40: 1050209.1 | F40: =E40/2 -> 525104.53
A41: 2 | B41: DR CLINTON JAJA | C41: SENIOR RESEARCH FELLOW | D41: 15(9) | E41: 527553.5 | F41: =E41/2 -> 263776.75
A42: 3 | B42: BETHEL UZOMA IHUGBA | C42: DEPUTY DIRECTOR, LEGAL RESEARCH | D42: 16(7) | E42: 604023.33 | F42: =E42/2 -> 302011.66
A43: 4 | B43: OGUCHE SAMUEL | C43: SNR RESEARCH FELLOW | D43: 15(9) | E43: 527553.5 | F43: =E43/2 -> 263776.75
A44: 5 | B44: IBRAHIM USMAN | C44: SNR RESEARCH FELLOW | D44: 15(8) | E44: 516137.05 | F44: =E44/2 -> 258068.53
A45: 6 | B45: DR MOHAMMED O. AMALI | C45: SNR RESEARCH FELLOW | D45: 15(7) | E45: 504720.05 | F45: =E45/2 -> 252360.02
A46: 7 | B46: YAHAYA SHAMSU | C46: RESEARCH FELLOW 1 | D46: 14(10) | E46: 413333.04 | F46: =E46/2 -> 206666.52
A47: 8 | B47: DORIS DAKDA AARON | C47: RESEARCH FELLOW I | D47: 14(8) | E47: 397211.37 | F47: =E47/2 -> 198605.68
A48: 9 | B48: BILKIS S. LAWAL-GAMBARI | C48: RESEARCH OFFICER | D48: 10(7) | E48: 268602.08 | F48: =E48/2 -> 134301.04
A49: 10 | B49: ZAINAB AKINDE | C49: RESEARCH OFFICER | D49: 9(7) | E49: 245204.08 | F49: =E49/2 -> 122602.04
A50: 11 | B50: ABDULLAHI AHMAD USMAN | C50: RESEARCH OFFICER | D50: 9(7) | E50: 245204.08 | F50: =E50/2 -> 122602.04
A51: 12 | B51: GUNAT NANSAK MARK | C51: RESEARCH OFFICER | D51: 9(7) | E51: 245204.08 | F51: =E51/2 -> 122602.04
B52: TOTAL | C52: 12 | E52: 6101043.8 | F52: =SUM(F40:F51) -> 2772477.6
B54: LEGAL SERVICES
A55: 1 | B55: DR SHUIBU DANWANKA | C55: DIRECTOR LEGAL SERVICES | D55: 17(9) | E55: 1050209.1 | F55: =E55/2 -> 525104.53
...

Sheet Sheet3

Sheet NEW ENROLMENT IN NOVEMBER (2)
A1: NATIONAL INSTITUTE FOR LEGISLATIVE AND DEMOCRATIC STUDIES | G1: ='[1]FEB 08'!F8/'[1]FEB 08'!Q8 -> 0.3
A2: STAFF PAYROLL FOR THE MONTH OF NOVEMBER 2023
E3: ='[1]FEB 08'!E11/'[1]FEB 08'!M11 -> #REF! | G3: ='[1]FEB 08'!F11/'[1]FEB 08'!Q11 -> #REF!
B4: STAFF NAME | C4: DESIGNATION | D4: GRADE LEVEL | E4: BASIC SALARY | F4: ALLCE/ AREARS | G4: RENT | H4: UTILITY | I4: DOMESTIC | J4: ENTERT. | K4: FURNIT. | L4: FUEL | M4: ALLOWANCE | N4: ALLOWANCE | O4: ALLCE | P4: ALLCE | Q4: DUTY ALLCE | R4: GROSS SALARY | S4: PAYE | T4: TOTAL DEDUCTION | U4: OCTOBER, 2023 | V4: NOVEMBER, 2023 | W4: NO OF MONTHS | X4: ARREARS
E5: N | F5: N | G5: N | H5: N | I5: N | J5: N | K5: N | L5: N | M5: N | N5: N | O5: N | P5: N | Q5: N | S5: N
A6: S/N | B6: DG'S OFFICE
A7: 3 | B7: ABDULSALAM S. MUSTAPHA | C7: ASST. MANAGER ICT | D7: 13(11) | E7: 26339.3 | G7: =E7*300% -> 79017.9 | H7: =E7*7.5% -> 1975.4475 | I7: 0 | J7: =E7*50% -> 13169.65 | K7: =E7*350% -> 92187.55 | L7: =E7*100% -> 26339.3 | M7: 70000 | O7: =E7*10% -> 2633.93 | P7: 15000 | R7: =SUM(E7:Q7) -> 326663.08 | S7: =42046.06 -> 42046.06 | T7: =42046.06 -> 42046.06 | V7: =R7-T7 -> 284617.02 | W7: 1 | X7: =V7*W7 -> 284617.02
B8: TOTAL | E8: =SUM(E7:E7) -> 26339.3 | F8: =SUM(F7:F7) -> 0 | G8: =SUM(G7:G7) -> 79017.9 | H8: =SUM(H7:H7) -> 1975.4475 | I8: =SUM(I7:I7) -> 0 | J8: =SUM(J7:J7) -> 13169.65 | K8: =SUM(K7:K7) -> 92187.55 | L8: =SUM(L7:L7) -> 26339.3 | ... P8: =SUM(P7:P7) -> 15000 | R8: =SUM(R7) -> 326663.08 | S8: =SUM(S7:S7) -> 42046.06 | T8: =SUM(T7:T7) -> 42046.06 | U8: =SUM(U7:U7) -> 0 | V8: =SUM(V7:V7) -> 284617.02 | X8: =SUM(X7:X7) -> 284617.02
B10: DEM. & GOVERNANCE
A11: 10 | B11: KOLAPO Q. ABAYOMI | C11: RESEARCH OFFICER | D11: 10(7) | E11: 17286.33 | G11: =E11*300% -> 51858.99 | H11: =E11*7.5% -> 1296.4748 | J11: =E11*50% -> 8643.165 | K11: =E11*350% -> 60502.155 | L11: =E11*100% -> 17286.33 | M11: 100000 | O11: =E11*10% -> 1728.633 | P11: 10000 | R11: =SUM(E11:Q11) -> 268602.08 | S11: =32291.82 -> 32291.82 | T11: =32291.82 -> 32291.82 | V11: =R11-T11 -> 236310.26 | W11: =(25/31)+2 -> 2.8064516 | X11: =V11*W11 -> 663193.3
B12: TOTAL | E12: =SUM(E11:E11) -> 17286.33 | F12: =SUM(F11:F11) -> 0 | G12: =SUM(G11:G11) -> 51858.99 | H12: =SUM(H11:H11) -> 1296.4748 | I12: =SUM(I11:I11) -> 0 | J12: =SUM(J11:J11) -> 8643.165 | K12: =SUM(K11:K11) -> 60502.155 | L12: =SUM(L11:L11) -> 17286.33 | ... X12: =SUM(X11:X11) -> 663193.3
B14: GRAND TOTAL | E14: =E8+E12 -> 43625.63 | F14: =F8+F12 -> 0 | G14: =G8+G12 -> 130876.89 | H14: =H8+H12 -> 3271.9222 | I14: =I8+I12 -> 0 | J14: =J8+J12 -> 21812.815 | K14: =K8+K12 -> 152689.71 | L14: =L8+L12 -> 43625.63 | ... V14: =V8+V12 -> 520927.28 | X14: =X8+X12 -> 947810.32

Sheet Regularisation IN NOVEMBER (3)
A1: NATIONAL INSTITUTE FOR LEGISLATIVE AND DEMOCRATIC STUDIES | G1: ='[1]FEB 08'!F8/'[1]FEB 08'!Q8 -> 0.3
A2: STAFF PAYROLL FOR THE MONTH OF NOVEMBER 2023
E3: ='[1]FEB 08'!E11/'[1]FEB 08'!M11 -> #REF! | G3: ='[1]FEB 08'!F11/'[1]FEB 08'!Q11 -> #REF!
B4: STAFF NAME | C4: DESIGNATION | D4: GRADE LEVEL | E4: BASIC SALARY | F4: ALLCE/ AREARS | G4: RENT | H4: UTILITY | I4: DOMESTIC | J4: ENTERT. | K4: FURNIT. | L4: FUEL | M4: ALLOWANCE | N4: ALLOWANCE | O4: ALLCE | P4: ALLCE | Q4: DUTY ALLCE | R4: GROSS SALARY | S4: NEW GRADE LEVEL | T4: NEW GROSS SALARY | U4: INCREMENT IN GROSS SALARY | V4: CURRENT NHF | W4: NEW NHF | X4: CURRENT PAYE | Y4: NEW PAYE | Z4: INCREMENT IN PAYE | AA4: NET SALARY INCREMENT | AB4: NO OF MONTHS | AC4: ARREARS | AD4: ARREARS PAID IN OCTOBER | AE4: SHORTFALL IN ARREARS
E5: N | F5: N | G5: N | H5: N | I5: N | J5: N | K5: N | L5: N | M5: N | N5: N | O5: N | P5: N | Q5: N | S5: N
A6: S/N | B6: ADMIN & HR
A8: 40 | B8: YUNUSA ABDULMUMINI ELEOJO | C8: CHIEF MOTOR DRIVER MECH. | D8: 7(3) | E8: 5428.12 | G8: =E8*300% -> 16284.36 | H8: =E8*7.5% -> 407.109 | J8: =E8*50% -> 2714.06 | K8: =E8*350% -> 18998.42 | L8: =E8*100% -> 5428.12 | N8: =20000 -> 20000 | O8: =E8*10% -> 542.812 | P8: 5000 | Q8: =7000 -> 7000 | R8: =SUM(E8:Q8) -> 81803.001 | S8: 7(3) | T8: =122105 -> 122105 | U8: =T8-R8 -> 40301.999 | X8: 4365.3308 | Y8: =9152.6 -> 9152.6 | Z8: =Y8-X8 -> 4787.2692 | AA8: =U8-Z8 -> 35514.73 | AB8: =(11/31)+3 -> 3.3548387 | AC8: =AA8*AB8 -> 119146.19 | AD8: =66227.57 -> 66227.57 | AE8: =AC8-AD8 -> 52918.62
A9: 41 | B9: JOHN GIMAH | C9: CHIEF MOTOR DRIVER MECH. | D9: 7(3) | E9: 5428.12 | G9: =E9*300% -> 16284.36 | H9: =E9*7.5% -> 407.109 | J9: =E9*50% -> 2714.06 | K9: =E9*350% -> 18998.42 | L9: =E9*100% -> 5428.12 | N9: =20000 -> 20000 | O9: =E9*10% -> 542.812 | P9: 5000 | Q9: =7000 -> 7000 | R9: =SUM(E9:Q9) -> 81803.001 | S9: 7(3) | T9: =122105 -> 122105 | U9: =T9-R9 -> 40301.999 | X9: =4365.33075466667 -> 4365.3308 | Y9: =9152.6 -> 9152.6 | Z9: =Y9-X9 -> 4787.2692 | AA9: =U9-Z9 -> 35514.73 | AB9: =(17/31)+2 -> 2.5483871 | AC9: =AA9*AB9 -> 90505.279 | AD9: 44151.71 | AE9: =AC9-AD9 -> 46353.569
A10: 42 | B10: ABUBAKAR MUSA DANLAMI | C10: CHIEF MOTOR DRIVER MECH. | D10: 7(3) | E10: 5598.92 | G10: =E10*300% -> 16796.76 | H10: =E10*7.5% -> 419.919 | J10: =E10*50% -> 2799.46 | K10: =E10*350% -> 19596.22 | L10: =E10*100% -> 5598.92 | N10: =20000 -> 20000 | O10: =E10*10% -> 559.892 | P10: 5000 | Q10: =7000 -> 7000 | R10: =SUM(E10:Q10) -> 83370.091 | S10: 7(3) | T10: =122105 -> 122105 | U10: =T10-R10 -> 38734.909 | X10: 4504.4109 | Y10: =9152.6 -> 9152.6 | Z10: =Y10-X10 -> 4648.1891 | AA10: =U10-Z10 -> 34086.72 | AB10: 9 | AC10: =AA10*AB10 -> 306780.48 | AD10: 216693.09 | AE10: =AC10-AD10 -> 90087.389
AE11: =SUM(AE8:AE10) -> 189359.58
A13: 40 | B13: YUNUSA ABDULMUMINI ELEOJO | C13: CHIEF MOTOR DRIVER MECH. | D13: 7(3) | E13: =8730.79 -> 8730.79 | G13: =E13*300% -> 26192.37 | H13: =E13*7.5% -> 654.80925 | J13: =E13*50% -> 4365.395 | K13: =E13*350% -> 30557.765 | L13: =E13*100% -> 8730.79 | N13: 30000 | O13: =E13*10% -> 873.079 | P13: 5000 | Q13: =7000 -> 7000 | R13: =SUM(E13:Q13) -> 122105 | T13: =10000+5000+5000 -> 20000 | U13: =15625 -> 15625 | W13: =[3]PROMOTIONS!$X$42 -> 8312.59 | X13: =W13+V13+U13+T13+S13 -> 43937.59 | Y13: 106043.97 | Z13: =R13-X13 -> 78167.408
A14: 41 | B14: JOHN GIMAH | C14: CHIEF MOTOR DRIVER MECH. | D14: 7(3) | E14: =8730.79 -> 8730.79 | G14: =E14*300% -> 26192.37 | H14: =E14*7.5% -> 654.80925 | J14: =E14*50% -> 4365.395 | K14: =E14*350% -> 30557.765 | L14: =E14*100% -> 8730.79 | N14: 30000 | O14: =E14*10% -> 873.079 | P14: 5000 | Q14: =7000 -> 7000 | R14: =SUM(E14:Q14) -> 122105 | T14: 20000 | U14: 18333.33 | W14: =[3]PROMOTIONS!$X$42 -> 8312.59 | X14: =W14+V14+U14+T14+S14 -> 46645.92 | Y14: 80609.452 | Z14: =R14-X14 -> 75459.078
A15: 42 | B15: ABUBAKAR MUSA DANLAMI | C15: CHIEF MOTOR DRIVER MECH. | D15: 7(3) | E15: =8730.79 -> 8730.79 | G15: =E15*300% -> 26192.37 | H15: =E15*7.5% -> 654.80925 | J15: =E15*50% -> 4365.395 | K15: =E15*350% -> 30557.765 | L15: =E15*100% -> 8730.79 | N15: 30000 | O15: =E15*10% -> 873.079 | P15: 5000 | Q15: =7000 -> 7000 | R15: =SUM(E15:Q15) -> 122105 | T15: =3000+5000+5000 -> 13000 | U15: =44000 -> 44000 | W15: =[3]PROMOTIONS!$X$42 -> 8312.59 | X15: =W15+V15+U15+T15+S15 -> 65312.59 | Y15: 239903.58 | Z15: =R15-X15 -> 56792.408
B16: GRAND TOTAL | E16: =E8+E14 -> 14158.91 | F16: =F8+F14 -> 0 | G16: =G8+G14 -> 42476.73 | H16: =H8+H14 -> 1061.9182 | I16: =I8+I14 -> 0 | J16: =J8+J14 -> 7079.455 | K16: =K8+K14 -> 49556.185 | L16: =L8+L14 -> 14158.91 | ... V16: =V8+V14 -> 0 | X16: =X8+X14 -> 51011.251

Sheet Sheet2

Sheet PROMOTIONS
A1: NATIONAL INSTITUTE FOR LEGISLATIVE AND DEMOCRATIC STUDIES | G1: ='[1]FEB 08'!F8/'[1]FEB 08'!Q8 -> 0.3
A2: STAFF PAYROLL FOR THE MONTH OF OCTOBER 2023
E3: ='[1]FEB 08'!E11/'[1]FEB 08'!M11 -> #REF! | G3: ='[1]FEB 08'!F11/'[1]FEB 08'!Q11 -> #REF!
B4: STAFF NAME | C4: DESIGNATION | D4: CURRENT GRADE LEVEL | E4: BASIC SALARY | F4: RENT | G4: UTILITY | H4: DOMESTIC | I4: ENTERT. | J4: FURNIT. | K4: FUEL | L4: ALLOWANCE | M4: ALLOWANCE | N4: ALLCE | O4: ALLCE | P4: DUTY ALLCE | Q4: CURRENT GROSS SALARY | R4: NEW GRADE LEVEL | S4: NEW GROSS SALARY | T4: INCREMENT IN GROSS SALARY | U4: CURRENT NHF | V4: NEW NHF | W4: CURRENT PAYE | X4: NEW PAYE | Y4: INCREMENT IN PAYE | Z4: NET SALARY INCREMENT | AA4: NO OF MONTHS | AB4: ARREARS
E5: N | F5: N | G5: N | H5: N | I5: N | J5: N | K5: N | L5: N | M5: N | N5: N | O5: N | P5: N | Q5: N | S5: N | U5: N | W5: N
A6: S/N | B6: DG'S OFFICE
A7: 1 | B7: ABDULRAHMAN A SULAIMAN | C7: ASSISTANT STORES OFFICER | D7: 8(10) | E7: 13492.21 | F7: =E7*300% -> 40476.63 | G7: =E7*7.5% -> 1011.9157 | I7: =E7*50% -> 6746.105 | J7: =E7*350% -> 47222.735 | K7: =E7*100% -> 13492.21 | M7: =50000 -> 50000 | N7: =E7*10% -> 1349.221 | O7: 10000 | Q7: =SUM(E7:P7) -> 183791.03 | R7: 9(7) | S7: ='SALARY STRUCTURE'!H13+60000 -> 205203.67 | T7: =S7-Q7 -> 21412.64 | W7: 18102.903 | X7: ='[7]October 2023'!$Z$29 -> 21640.883 | Y7: =X7-W7 -> 3537.9799 | Z7: =T7-Y7 -> 17874.66 | AA7: =(19/31)+4 -> 4.6129032 | AB7: =Z7*AA7 -> 82454.077
B8: TOTAL | C8: 1 | E8: =SUM(E7:E7) -> 13492.21 | F8: =SUM(F7:F7) -> 40476.63 | G8: =SUM(G7:G7) -> 1011.9157 | H8: =SUM(H7:H7) -> 0 | I8: =SUM(I7:I7) -> 6746.105 | J8: =SUM(J7:J7) -> 47222.735 | K8: =SUM(K7:K7) -> 13492.21 | L8: =SUM(L7:L7) -> 0 | ... Q8: =SUM(Q7:Q7) -> 183791.03 | S8: =SUM(S7:S7) -> 205203.67 | T8: =SUM(T7:T7) -> 21412.64 | U8: =SUM(U7:U7) -> 0 | V8: =SUM(V7:V7) -> 0 | W8: =SUM(W7:W7) -> 18102.903 | X8: =SUM(X7:X7) -> 21640.883 | Y8: =SUM(Y7:Y7) -> 3537.9799 | Z8: =SUM(Z7:Z7) -> 17874.66 | AB8: =SUM(AB7:AB7) -> 82454.077
B10: LEG. SUPPORT SEVICES
A11: 2 | B11: DORIS DAKDA AARON | C11: RESEARCH FELLOW II | D11: 13(10) | E11: 25523.45 | F11: =E11*300% -> 76570.35 | G11: =E11*7.5% -> 1914.2587 | I11: =E11*50% -> 12761.725 | J11: =E11*350% -> 89332.075 | K11: =E11*100% -> 25523.45 | L11: =120000 -> 120000 | N11: =E11*10% -> 2552.345 | O11: 15000 | Q11: =SUM(E11:P11) -> 369177.65 | R11: 14(8) | S11: ='SALARY STRUCTURE'!I17+140000 -> 397211.25 | T11: =S11-Q11 -> 28033.596 | U11: 638.08625 | V11: =690.28 -> 690.28 | W11: 49548.776 | X11: ='[7]October 2023'!$Z$50 -> 54812.469 | Y11: =X11-W11 -> 5263.6924 | Z11: =T11-Y11 -> 22769.904 | AA11: =(18/31)+1 -> 1.5806452 | AB11: =Z11*AA11 -> 35991.138
B12: TOTAL | C12: 1 | E12: =SUM(E11:E11) -> 25523.45 | F12: =SUM(F11:F11) -> 76570.35 | G12: =SUM(G11:G11) -> 1914.2587 | H12: =SUM(H11:H11) -> 0 | I12: =SUM(I11:I11) -> 12761.725 | J12: =SUM(J11:J11) -> 89332.075 | K12: =SUM(K11:K11) -> 25523.45 | L12: =SUM(L11:L11) -> 120000 | ... Q12: =SUM(Q11:Q11) -> 369177.65 | S12: =SUM(S11:S11) -> 397211.25 | T12: =SUM(T11:T11) -> 28033.596 | U12: =SUM(U11:U11) -> 638.08625 | V12: =SUM(V11:V11) -> 690.28 | W12: =SUM(W11:W11) -> 49548.776 | X12: =SUM(X11:X11) -> 54812.469 | Y12: =SUM(Y11:Y11) -> 5263.6924 | Z12: =SUM(Z11:Z11) -> 22769.904 | AB12: =SUM(AB11:AB11) -> 35991.138
T13: =S13-Q13 -> 0
B14: DEMOCRACY & GOVERNANCE | T14: =S14-Q14 -> 0
A15: 3 | B15: NGARA CHRISTOPHER OCHANJA | C15: RESEARCH FELLOW 1 | D15: 14(11) | E15: =28489.81 -> 28489.81 | F15: =E15*300% -> 85469.43 | G15: =E15*7.5% -> 2136.7357 | I15: =E15*50% -> 14244.905 | J15: =E15*350% -> 99714.335 | K15: =E15*100% -> 28489.81 | L15: 140000 | N15: =E15*10% -> 2848.981 | O15: 20000 | P15: 0 | Q15: =SUM(E15:P15) -> 421394.01 | R15: 15(7) | S15: ='SALARY STRUCTURE'!H18+160000 -> 504720.17 | T15: =S15-Q15 -> 83326.16 | U15: 712.24525 | V15: =837.69 -> 837.69 | W15: 59441.782 | X15: ='[7]October 2023'!$Z$85 -> 75440.405 | Y15: =X15-W15 -> 15998.623 | Z15: =T15-Y15 -> 67327.537 | AA15: =9 -> 9 | AB15: =Z15*AA15 -> 605947.83
A16: 4 | B16: EJALONIBU GANIYU LAYI | C16: RESEARCH FELLOW 11 | D16: 13(10) | E16: 25523.45 | F16: =E16*300% -> 76570.35 | G16: =E16*7.5% -> 1914.2587 | I16: =E16*50% -> 12761.725 | J16: =E16*350% -> 89332.075 | K16: =E16*100% -> 25523.45 | L16: =120000 -> 120000 | N16: =E16*10% -> 2552.345 | O16: 15000 | Q16: =SUM(E16:P16) -> 369177.65 | R16: 14(8) | S16: ='SALARY STRUCTURE'!I17+140000 -> 397211.25 | T16: =S16-Q16 -> 28033.596 | W16: 49548.776 | X16: ='[7]October 2023'!$Z$62 -> 54931.227 | Y16: =X16-W16 -> 5382.4505 | Z16: =T16-Y16 -> 22651.146 | AA16: =(7/31)+2 -> 2.2258065 | AB16: =Z16*AA16 -> 50417.066
B17: TOTAL | C17: 2 | E17: =SUM(E15:E16) -> 54013.26 | F17: =SUM(F15:F16) -> 162039.78 | G17: =SUM(G15:G16) -> 4050.9945 | H17: =SUM(H15:H16) -> 0 | I17: =SUM(I15:I16) -> 27006.63 | J17: =SUM(J15:J16) -> 189046.41 | K17: =SUM(K15:K16) -> 54013.26 | L17: =SUM(L15:L16) -> 260000 | ... Q17: =SUM(Q15:Q16) -> 790571.66 | S17: =SUM(S15:S16) -> 901931.42 | T17: =SUM(T15:T16) -> 111359.76 | U17: =SUM(U15:U16) -> 712.24525 | V17: =SUM(V15:V16) -> 837.69 | W17: =SUM(W15:W16) -> 108990.56 | X17: =SUM(X15:X16) -> 130371.63 | Y17: =SUM(Y15:Y16) -> 21381.073 | Z17: =SUM(Z15:Z16) -> 89978.683 | AB17: =SUM(AB15:AB16) -> 656364.9
Y18: =X18-W18 -> 0 | Z18: =T18-Y18 -> 0 | AB18: =Z18*AA18 -> 0
B19: DEPARTMENT OF STUDIES | Y19: =X19-W19 -> 0 | Z19: =T19-Y19 -> 0 | AB19: =Z19*AA19 -> 0
A20: 5 | B20: ANTHONY EDET | C20: ASST. MGR M&E | D20: 13(10) | E20: 25523.45 | F20: =E20*300% -> 76570.35 | G20: =E20*7.5% -> 1914.2587 | H20: 0 | I20: =E20*50% -> 12761.725 | J20: =E20*350% -> 89332.075 | K20: =E20*100% -> 25523.45 | L20: =120000 -> 120000 | N20: =E20*10% -> 2552.345 | O20: 15000 | P20: 0 | Q20: =SUM(E20:P20) -> 369177.65 | R20: 14(8) | S20: ='SALARY STRUCTURE'!I17+140000 -> 397211.25 | T20: =S20-Q20 -> 28033.596 | U20: 638.08625 | W20: 49548.776 | X20: ='[7]October 2023'!$Z$78 -> 54931.227 | Y20: =X20-W20 -> 5382.4505 | Z20: =T20-Y20 -> 22651.146 | AA20: =9 -> 9 | AB20: =Z20*AA20 -> 203860.31
B21: TOTAL | C21: 1 | E21: =SUM(E20:E20) -> 25523.45 | F21: =SUM(F20:F20) -> 76570.35 | G21: =SUM(G20:G20) -> 1914.2587 | H21: =SUM(H20:H20) -> 0 | I21: =SUM(I20:I20) -> 12761.725 | J21: =SUM(J20:J20) -> 89332.075 | K21: =SUM(K20:K20) -> 25523.45 | L21: =SUM(L20:L20) -> 120000 | ... Q21: =SUM(Q20:Q20) -> 369177.65 | S21: =SUM(S20:S20) -> 397211.25 | U21: =SUM(U20:U20) -> 638.08625 | W21: =SUM(W20:W20) -> 49548.776 | X21: =SUM(X20:X20) -> 54931.227 | Y21: =SUM(Y20:Y20) -> 5382.4505 | Z21: =SUM(Z20:Z20) -> 22651.146 | AB21: =SUM(AB20:AB20) -> 203860.31
Y22: =X22-W22 -> 0 | Z22: =T22-Y22 -> 0 | AB22: =Z22*AA22 -> 0
B23: ECON. DEV. & SOC. RESEARCH | Y23: =X23-W23 -> 0 | Z23: =T23-Y23 -> 0 | AB23: =Z23*AA23 -> 0
A24: 6 | B24: OMOJU OLUWASOLA EMMANUEL | C24: RESEARCH FELLOW I | D24: 14(10) | E24: 27611.23 | F24: =E24*300% -> 82833.69 | G24: =E24*7.5% -> 2070.8422 | I24: =E24*50% -> 13805.615 | J24: =E24*350% -> 96639.305 | K24: =E24*100% -> 27611.23 | L24: 140000 | N24: =E24*10% -> 2761.123 | O24: 20000 | Q24: =SUM(E24:P24) -> 413333.04 | R24: 15(7) | S24: ='SALARY STRUCTURE'!H18+160000 -> 504720.17 | T24: =S24-Q24 -> 91387.131 | W24: 58026.609 | X24: ='[7]October 2023'!$Z$86 -> 75572.939 | Y24: =X24-W24 -> 17546.329 | Z24: =T24-Y24 -> 73840.802 | AA24: 1 | AB24: =Z24*AA24 -> 73840.802
A25: 7 | B25: OKUNGBOWA OSARETIN GODSPOWER | C25: RESEARCH FELLOW 11 | D25: 13(9) | E25: 24741.26 | F25: =E25*300% -> 74223.78 | G25: =E25*7.5% -> 1855.5945 | H25: 0 | I25: =E25*50% -> 12370.63 | J25: =E25*350% -> 86594.41 | K25: =E25*100% -> 24741.26 | L25: =120000 -> 120000 | N25: =E25*10% -> 2474.126 | O25: 15000 | P25: 0 | Q25: =SUM(E25:P25) -> 362001.06 | R25: 14(7) | S25: ='SALARY STRUCTURE'!H17+140000 -> 389153.42 | T25: =S25-Q25 -> 27152.356 | W25: 48170.87 | X25: ='[7]October 2023'!$Z$89 -> 53384.123 | Y25: =X25-W25 -> 5213.2524 | Z25: =T25-Y25 -> 21939.104 | AA25: =(19/31)+2 -> 2.6129032 | AB25: =Z25*AA25 -> 57324.755
B26: TOTAL | C26: 2 | E26: =SUM(E24:E25) -> 52352.49 | F26: =SUM(F24:F25) -> 157057.47 | G26: =SUM(G24:G25) -> 3926.4367 | H26: =SUM(H24:H25) -> 0 | I26: =SUM(I24:I25) -> 26176.245 | J26: =SUM(J24:J25) -> 183233.71 | K26: =SUM(K24:K25) -> 52352.49 | L26: =SUM(L24:L25) -> 260000 | ... Q26: =SUM(Q24:Q25) -> 775334.1 | S26: =SUM(S24:S25) -> 893873.58 | T26: =SUM(T24:T25) -> 118539.49 | U26: =SUM(U24:U25) -> 0 | V26: =SUM(V24:V25) -> 0 | W26: =SUM(W24:W25) -> 106197.48 | X26: =SUM(X24:X25) -> 128957.06 | Y26: =SUM(Y24:Y25) -> 22759.582 | Z26: =SUM(Z24:Z25) -> 95779.906 | AB26: =SUM(AB24:AB25) -> 131165.56
T27: =S27-Q27 -> 0 | Y27: =X27-W27 -> 0 | Z27: =T27-Y27 -> 0 | AB27: =Z27*AA27 -> 0
B28: TRAINING & INT''L COOP | T28: =S28-Q28 -> 0 | Y28: =X28-W28 -> 0 | Z28: =T28-Y28 -> 0 | AB28: =Z28*AA28 -> 0
A29: 8 | B29: DR FRANCIS NDUM OJIE | C29: CHIEF TRAINING OFFICER | D29: 14(10) | E29: 27611.23 | F29: =E29*300% -> 82833.69 | G29: =E29*7.5% -> 2070.8422 | I29: =E29*50% -> 13805.615 | J29: =E29*350% -> 96639.305 | K29: =E29*100% -> 27611.23 | L29: 140000 | N29: =E29*10% -> 2761.123 | O29: 20000 | P29: =100000 -> 100000 | Q29: =SUM(E29:P29) -> 513333.04 | R29: 15(7) | S29: ='SALARY STRUCTURE'!H18+160000+100000 -> 604720.17 | T29: =S29-Q29 -> 91387.131 | U29: 690.28075 | V29: =837.69 -> 837.69 | W29: =77098.29 -> 77098.29 | X29: ='[7]October 2023'!$Z$97 -> 94644.622 | Y29: =X29-W29 -> 17546.332 | Z29: =T29-Y29 -> 73840.8 | AA29: =3 -> 3 | AB29: =Z29*AA29 -> 221522.4
A30: 9 | B30: MOHAMMED R. ADAMU | C30: PRINCIPAL CONF. SECRETARY | D30: 13(10) | E30: 25523.45 | F30: =E30*300% -> 76570.35 | G30: =E30*7.5% -> 1914.2587 | H30: 0 | I30: =E30*50% -> 12761.725 | J30: =E30*350% -> 89332.075 | K30: =E30*100% -> 25523.45 | M30: 70000 | N30: =E30*10% -> 2552.345 | O30: 15000 | P30: 0 | Q30: =SUM(E30:P30) -> 319177.65 | R30: 14(8) | S30: ='SALARY STRUCTURE'!I17+70000 -> 327211.25 | T30: =S30-Q30 -> 8033.5963 | W30: 40698.125 | X30: ='[7]October 2023'!$Z$129 -> 42047.769 | Y30: =X30-W30 -> 1349.6442 | Z30: =T30-Y30 -> 6683.9521 | AA30: 7 | AB30: =Z30*AA30 -> 46787.665
A31: 10 | B31: TASSNEEM IBRAHIM | C31: ASSIST. INFO.OFFICER | D31: 8(10) | E31: 13492.21 | F31: 40476.63 | G31: 1011.9157 | I31: 6746.105 | J31: 47222.735 | K31: 13492.21 | M31: 50000 | N31: 1349.221 | O31: 10000 | Q31: 183791.03 | R31: 10(7) | S31: ='SALARY STRUCTURE'!H14+60000 -> 228601.58 | T31: =S31-Q31 -> 44810.557 | W31: 18102.903 | X31: ='[7]October 2023'!$Z$30 -> 25571.733 | Y31: =X31-W31 -> 7468.8299 | Z31: =T31-Y31 -> 37341.727 | AA31: 1 | AB31: =Z31*AA31 -> 37341.727
B32: TOTAL | C32: 3 | E32: =SUM(E29:E31) -> 66626.89 | F32: =SUM(F29:F31) -> 199880.67 | G32: =SUM(G29:G31) -> 4997.0167 | H32: =SUM(H29:H31) -> 0 | I32: =SUM(I29:I31) -> 33313.445 | J32: =SUM(J29:J31) -> 233194.11 | K32: =SUM(K29:K31) -> 66626.89 | L32: =SUM(L29:L31) -> 140000 | ... Q32: =SUM(Q29:Q31) -> 1016301.7 | S32: =SUM(S29:S31) -> 1160533 | T32: =S32-Q32 -> 144231.28 | U32: =SUM(U29:U31) -> 690.28075 | W32: =SUM(W29:W31) -> 135899.32 | X32: =SUM(X29:X31) -> 162264.12 | Y32: =SUM(Y29:Y31) -> 26364.806 | Z32: =SUM(Z29:Z31) -> 117866.48 | AB32: =SUM(AB29:AB31) -> 305651.79
Y33: =X33-W33 -> 0 | Z33: =T33-Y33 -> 0 | AB33: =Z33*AA33 -> 0
B34: FINANCE & ACCOUNTS | Y34: =X34-W34 -> 0 | Z34: =T34-Y34 -> 0 | AB34: =Z34*AA34 -> 0
A35: 11 | B35: RAHILA SALIHU | C35: ASST. CHIEF ACCOUNTOFFICER | D35: 13(10) | E35: 25523.45 | F35: =E35*300% -> 76570.35 | G35: =E35*7.5% -> 1914.2587 | I35: =E35*50% -> 12761.725 | J35: =E35*350% -> 89332.075 | K35: =E35*100% -> 25523.45 | M35: =70000 -> 70000 | N35: =E35*10% -> 2552.345 | O35: 15000 | Q35: =SUM(E35:P35) -> 319177.65 | R35: 14(8) | S35: ='SALARY STRUCTURE'!I17+70000 -> 327211.25 | T35: =S35-Q35 -> 8033.5963 | U35: 638.08625 | V35: =690.28 -> 690.28 | W35: 40684.599 | X35: ='[7]October 2023'!$Z$118 -> 42034.243 | Y35: =X35-W35 -> 1349.6442 | Z35: =T35-Y35 -> 6683.9521 | AA35: =9 -> 9 | AB35: =Z35*AA35 -> 60155.569
B36: TOTAL | C36: 1 | E36: =SUM(E35:E35) -> 25523.45 | F36: =SUM(F35:F35) -> 76570.35 | G36: =SUM(G35:G35) -> 1914.2587 | H36: =SUM(H35:H35) -> 0 | I36: =SUM(I35:I35) -> 12761.725 | J36: =SUM(J35:J35) -> 89332.075 | K36: =SUM(K35:K35) -> 25523.45 | L36: =SUM(L35:L35) -> 0 | ... Q36: =SUM(Q35:Q35) -> 319177.65 | S36: =SUM(S35:S35) -> 327211.25 | T36: =SUM(T35:T35) -> 8033.5963 | U36: =SUM(U35:U35) -> 638.08625 | V36: =SUM(V35:V35) -> 690.28 | W36: =SUM(W35:W35) -> 40684.599 | X36: =SUM(X35:X35) -> 42034.243 | Y36: =SUM(Y35:Y35) -> 1349.6442 | Z36: =SUM(Z35:Z35) -> 6683.9521 | AB36: =SUM(AB35:AB35) -> 60155.569
L37: =226713.38+70000 -> 296713.38
B38: ADMIN & HUMAN RESOURCE
A39: 12 | B39: ABDULWAHAB DAHIRU | C39: ADMIN OFFICER | D39: 10(10) | E39: 18779.3 | F39: =E39*300% -> 56337.9 | G39: =E39*7.5% -> 1408.4475 | I39: =E39*50% -> 9389.65 | J39: =E39*350% -> 65727.55 | K39: =E39*100% -> 18779.3 | M39: =60000 -> 60000 | N39: =E39*10% -> 1877.93 | O39: 10000 | Q39: =SUM(E39:P39) -> 242300.08 | R39: 12(7) | S39: ='SALARY STRUCTURE'!H15+60000 -> 265371.75 | T39: =S39-Q39 -> 23071.673 | U39: 469.4825 | V39: =570.95 -> 570.95 | W39: 27794.207 | X39: ='[7]October 2023'!$Z$134 -> 31653.201 | Y39: =X39-W39 -> 3858.9944 | Z39: =T39-Y39 -> 19212.678 | AA39: 9 | AB39: =Z39*AA39 -> 172914.1
A40: 13 | B40: ODEH SUZIE | C40: ADMIN. OFFICER | D40: 10(10) | E40: =18779.3 -> 18779.3 | F40: =E40*300% -> 56337.9 | G40: =E40*7.5% -> 1408.4475 | I40: =E40*50% -> 9389.65 | J40: =E40*350% -> 65727.55 | K40: =E40*100% -> 18779.3 | M40: 60000 | N40: =E40*10% -> 1877.93 | O40: 10000 | Q40: =SUM(E40:P40) -> 242300.08 | R40: 12(7) | S40: ='SALARY STRUCTURE'!H15+60000 -> 265371.75 | T40: =S40-Q40 -> 23071.673 | U40: 0 | W40: 27873.08 | X40: ='[7]October 2023'!$Z$24 -> 31749.121 | Y40: =X40-W40 -> 3876.041 | Z40: =T40-Y40 -> 19195.632 | AA40: 1 | AB40: =Z40*AA40 -> 19195.632
A41: 14 | B41: BUKOLA HAUWA SHIRU | C41: ADMIN. ASST. | D41: 8(10) | E41: 13492.21 | F41: =E41*300% -> 40476.63 | G41: =E41*7.5% -> 1011.9157 | I41: =E41*50% -> 6746.105 | J41: =E41*350% -> 47222.735 | K41: =E41*100% -> 13492.21 | M41: =50000 -> 50000 | N41: =E41*10% -> 1349.221 | O41: 10000 | Q41: =SUM(E41:P41) -> 183791.03 | R41: 9(7) | S41: ='SALARY STRUCTURE'!H13+60000 -> 205203.67 | T41: =S41-Q41 -> 21412.64 | W41: 18102.903 | X41: ='[7]October 2023'!$Z$145 -> 21640.883 | Y41: =X41-W41 -> 3537.9799 | Z41: =T41-Y41 -> 17874.66 | AA41: 2 | AB41: =Z41*AA41 -> 35749.32
...

Sheet SALARY STRUCTURE
A1: NATIONAL INSTITUTE FOR LEGISLATIVE STUDIES
A2: TABLE OF MONTHLY CONSOLIDATED SALARY AND ALLOWANCES SCALES
B3: STEP 1 | C3: STEP 2 | D3: STEP 3 | E3: STEP 4 | F3: STEP 5 | G3: STEP 6 | H3: STEP 7 | I3: STEP 8 | J3: STEP 9 | K3: STEP 10 | L3: STEP 11 | M3: STEP 12 | N3: STEP 13 | O3: STEP 14 | P3: STEP 15
A4: CONLESS LEVEL | B4: N | C4: N | D4: N | E4: N | F4: N | G4: N | H4: N | I4: N | J4: N | K4: N | L4: N | M4: N | N4: N | O4: N | P4: N
A5: ,01 | B5: 32012.167 | C5: 32710.5 | D5: 33408.75 | E5: 34107.083 | F5: 34805.5 | G5: 35503.75 | H5: 36202.083 | I5: 36900.333 | J5: 37598.667 | K5: 38297.083 | L5: 38995.333 | M5: 39693.667 | N5: 40391.917 | O5: 41090.167 | P5: 41788.667
A6: ,02 | B6: 32532.167 | C6: 33445.167 | D6: 34358.333 | E6: 35271.25 | F6: 36184.25 | G6: 37097.417 | H6: 38010.333 | I6: 38923.417 | J6: 39836.417 | K6: 40749.417 | L6: 41662.5 | M6: 42575.5 | N6: 43488.667 | O6: 44401.583 | P6: 45314.583
A7: ,03 | B7: 32976.25 | C7: 34098.417 | D7: 35220.667 | E7: 36343 | F7: 37465.167 | G7: 38587.417 | H7: 39709.667 | I7: 40823.583 | J7: 41954.083 | K7: 43076.417 | L7: 44198.667 | M7: 45445.833 | N7: 46443.167 | O7: 47565.333 | P7: 48687.5
A8: ,04 | B8: 34542.5 | C8: 35890.833 | D8: 37238.917 | E8: 38587.167 | F8: 39935.5 | G8: 41283.75 | H8: 42631.917 | I8: 43980 | J8: 45328.333 | K8: 46676.417 | L8: 48024.667 | M8: 49373 | N8: 50721.167 | O8: 52069.417 | P8: 53417.5
A9: ,05 | B9: 39140.333 | C9: 40706.583 | D9: 42272.833 | E9: 43839.083 | F9: 45405.5 | G9: 46971.75 | H9: 48538 | I9: 50104.417 | J9: 51670.667 | K9: 53236.917 | L9: 54803.167 | M9: 56369.583 | N9: 57936 | O9: 59502.083 | P9: 61068.333
A10: ,06 | B10: 47723.333 | C10: 49632.5 | D10: 51541.75 | E10: 53450.917 | F10: 55360.167 | G10: 57269.417 | H10: 59178.667 | I10: 61087.833 | J10: 62997.083 | K10: 64906.25 | L10: 66815.5 | M10: 68724.667 | N10: 70633.917 | O10: 72543.167 | P10: 74452.417
A11: ,07 | B11: 79244.583 | C11: 82174.667 | D11: 85104.917 | E11: 88034.917 | F11: 106590 | G11: 93895 | H11: 96825.167 | I11: 99755.167 | J11: 102685.33 | K11: 105615.33 | L11: 108545.5 | M11: 111468 | N11: 114405.67 | O11: 117335.83 | P11: 120265.83
A12: ,08 | B12: 102403.75 | C12: 105891.25 | D12: 109378.75 | E12: 112866.25 | F12: 116353.67 | G12: 119841.17 | H12: 123328.67 | I12: 126816.17 | J12: 130303.67 | K12: 133791.17 | L12: 137278.67 | M12: 140766.17 | N12: 144253.67 | O12: 147741.17 | P12: 151228.67
A13: ,09 | B13: 120290 | C13: 124442.17 | D13: 128594.58 | E13: 132746.75 | F13: 136899.08 | G13: 141051.25 | H13: 145203.67 | I13: 149355.83 | J13: 153508 | K13: 157660.33 | L13: 161812.5 | M13: 165964.92 | N13: 170117.08 | O13: 174269.42 | P13: 178421.58
A14: ,10 | B14: 141204.92 | C14: 145770.92 | D14: 150337.08 | E14: 154903.33 | F14: 159469.42 | G14: 164035.5 | H14: 168601.58 | I14: 173167.67 | J14: 177733.75 | K14: 182299.92 | L14: 186865.92 | M14: 191432.17 | N14: 195998.33 | O14: 200564.42 | P14: 205130.5
A15: ,12 | B15: 162876.25 | C15: 169958.92 | D15: 177039.92 | E15: 184124.08 | F15: 191206.58 | G15: 198289.25 | H15: 205371.75 | I15: 212454.42 | J15: 219536.92 | K15: 226619.58 | L15: 233702.08
A16: ,13 | B16: 181786.42 | C16: 189274.25 | D16: 198324.58 | E16: 204249.92 | F16: 211737.67 | G16: 219225.5 | H16: 226713.33 | I16: 234201.17 | J16: 242001.42 | K16: 249176.75 | L16: 256664.58
