Workbook

Sheet JULY 2025
A1: NATIONAL INSTITUTE FOR LEGISLATIVE AND DEMOCRATIC STUDIES
A2: STAFF PAYROLL FOR THE MONTH OF JULY, 2025
E3: ='[1]FEB 08'!E11/'[1]FEB 08'!M11 -> #REF!
B4: STAFF NAME | C4: DESIGNATION | D4: GRADE LEVEL | E4: BASIC SALARY | F4: ALLCE/ AREARS | G4: ALLOWANCE | H4: ALLOWANCE | I4: DUTY ALLCE | J4: GROSS SALARY | K4: AUCTION | L4: COOP 1 CONTR/SPEC SAVINGS | M4: COOP. LOAN RECOVERY | N4: COOP 2 CONTR/SPEC SAVINGS | O4: NHF DED. | P4: PAYE | Q4: EMPLOYEE PENSIONS | R4: TOTAL DEDUCTION | S4: JUNE, 2025 | T4: JULY, 2025
E5: N | F5: N | G5: N | H5: N | I5: N | J5: N | K5: N | L5: N | M5: N | O5: N | P5: N | Q5: N | R5: N | S5: N | T5: N
A6: S/N | B6: DG'S OFFICE
A7: 1 | B7: PROF. ABUBAKAR O. SULAIMAN | C7: DIRECTOR GENERAL | D7: CONSOL | E7: 1971137.1 | G7: =250000 -> 250000 | I7: 25235 | J7: =E7+F7+G7+H7+I7 -> 2246372.1 | P7: 409970.11 | Q7: 0 | R7: =P7+O7+M7+N7+L7+K7+Q7 -> 409970.11 | S7: 1836402 | T7: =J7-R7 -> 1836402
A8: 2 | B8: RAHEEM USMAN AYIGORO | C8: SA-INFRASTRUCTURE | D8: 16 (9) | E8: 905306.75 | H8: =90000 -> 90000 | I8: =100000 -> 100000 | J8: =E8+F8+G8+H8+I8 -> 1095306.8 | L8: =250000 -> 250000 | P8: 175060.05 | Q8: 72424.54 | R8: =P8+O8+M8+N8+L8+K8+Q8 -> 497484.59 | S8: 597822.16 | T8: =J8-R8 -> 597822.16
A9: 3 | B9: MARIAM MOHAMMED BELLO | C9: SA- SPECIAL DUTIES | D9: 16 (9) | E9: 905306.75 | H9: =90000 -> 90000 | I9: =200000+100000 -> 300000 | J9: =E9+F9+G9+H9+I9 -> 1295306.8 | P9: 227365.56 | R9: =P9+O9+M9+N9+L9+K9+Q9 -> 227365.56 | S9: 1067941.2 | T9: =J9-R9 -> 1067941.2
A10: 4 | B10: DR IKEME ARTHUR J.O | C10: DEPUTY DIRECTOR, M&E | D10: 16 (9) | E10: 905306.75 | G10: 180000 | I10: 0 | J10: =E10+F10+G10+H10+I10 -> 1085306.8 | L10: =50000 -> 50000 | M10: 206000 | O10: 13866.737 | P10: 170477.64 | Q10: 72424.54 | R10: =P10+O10+M10+N10+L10+K10+Q10 -> 512768.91 | S10: 572537.84 | T10: =J10-R10 -> 572537.84
A11: 5 | B11: ANDRAWUS MUSA | C11: DEP. DIRECTOR, STORES & PROCUREMENT | D11: 16(8) | E11: 879008.92 | F11: =26297.8333333367*2 -> 52595.667 | H11: =90000 -> 90000 | I11: 50000 | J11: =E11+F11+G11+H11+I11 -> 1071604.6 | L11: =50000-40000 -> 10000 | M11: =90000+110000 -> 200000 | O11: 13084.663 | P11: 168804.85 | Q11: 68216.887 | R11: =P11+O11+M11+N11+L11+K11+Q11 -> 460106.4 | S11: 547752.24 | T11: =J11-R11 -> 611498.18
A12: 6 | B12: DR FRANCIS NDUM OJIE | C12: AD, TRAINING & IC./SA TO DG | D12: 15(8) | E12: 722595.5 | G12: 160000 | I12: =100000+100000 -> 200000 | J12: =E12+F12+G12+H12+I12 -> 1082595.5 | O12: 11149.896 | P12: 173285.16 | Q12: 57807.64 | R12: =P12+O12+M12+N12+L12+K12+Q12 -> 242242.69 | S12: 840352.81 | T12: =J12-R12 -> 840352.81
A13: 7 | B13: ALI ABDULLAHI | C13: CHIEF ICT OFFICER | D13: 14(11) | E13: 589657 | H13: =70000 -> 70000 | I13: =0 -> 0 | J13: =E13+F13+G13+H13+I13 -> 659657 | P13: 96263.679 | Q13: 47172.56 | R13: =P13+O13+M13+N13+L13+K13+Q13 -> 143436.24 | S13: 516220.76 | T13: =J13-R13 -> 516220.76
A14: 8 | B14: EMILY EKHIDE | C14: SENIOR RESEARCH FELLOW | D14: 15(8) | E14: 722595.5 | G14: 160000 | I14: =50000 -> 50000 | J14: =E14+F14+G14+H14+I14 -> 932595.5 | L14: =50000 -> 50000 | P14: 146625.94 | Q14: 57807.64 | R14: =P14+O14+M14+N14+L14+K14+Q14 -> 254433.58 | S14: 758961.92 | T14: =J14-R14 -> 678161.92
A15: 9 | B15: DORIS DAKDA AARON | C15: RESEARCH FELLOW I | D15: 14(9) | E15: 558165.25 | G15: =140000 -> 140000 | I15: =150000+100000 -> 250000 | J15: =E15+F15+G15+H15+I15 -> 948165.25 | L15: 70000 | M15: 175000 | P15: 152140.98 | Q15: 44653.22 | R15: =P15+O15+M15+N15+L15+K15+Q15 -> 441794.2 | S15: 506371.05 | T15: =J15-R15 -> 506371.05
A16: 10 | B16: ABDULSALAM S. MUSTAPHA | C16: ASST. DIRECTOR ICT | D16: 15(7) | E16: 700713.92 | H16: 80000 | I16: 50000 | J16: =E16+F16+G16+H16+I16 -> 830713.92 | N16: 12000 | P16: 127400.77 | Q16: 56057.113 | R16: =P16+O16+M16+N16+L16+K16+Q16 -> 195457.89 | S16: 647256.03 | T16: =J16-R16 -> 635256.03
A17: 11 | B17: PERCY TERFA GBAHABO | C17: HEAD, NILDS LIAISON OFFICE | D17: 13(11) | E17: 541351.33 | G17: =120000 -> 120000 | I17: 0 | J17: =E17+F17+G17+H17+I17 -> 661351.33 | P17: 97330.966 | Q17: 43308.107 | R17: =P17+O17+M17+N17+L17+K17+Q17 -> 140639.07 | S17: 520712.26 | T17: =J17-R17 -> 520712.26
A18: 12 | B18: HASSANA AHMED IBRAHIM | C18: PA- TO DG | D18: 13 (10) | E18: 526725.08 | G18: =120000 -> 120000 | I18: =100000+100000 -> 200000 | J18: =E18+F18+G18+H18+I18 -> 846725.08 | L18: =30000-20000 -> 10000 | M18: =127777.78 -> 127777.78 | O18: 8226.1229 | P18: 131567.97 | Q18: 42138.007 | R18: =P18+O18+M18+N18+L18+K18+Q18 -> 319709.88 | S18: 558959.65 | T18: =J18-R18 -> 527015.2
A19: 13 | B19: IKIP LEBO | C19: ASST CHIEF PROC. OFFICER | D19: 13 (8) | E19: 497472.75 | H19: 70000 | J19: =E19+F19+G19+H19+I19 -> 567472.75 | L19: 50000 | O19: 7791.8313 | P19: 78484.222 | Q19: 39797.82 | R19: =P19+O19+M19+N19+L19+K19+Q19 -> 176073.87 | S19: 391398.88 | T19: =J19-R19 -> 391398.88
A20: 14 | B20: ALABI ADESINA MUHYDEEN | C20: HEAD, NILDS LIAISON OFFICE | D20: 13 (8) | E20: 497472.75 | G20: 120000 | J20: =E20+F20+G20+H20+I20 -> 617472.75 | P20: 89580.253 | Q20: 39797.82 | R20: =P20+O20+M20+N20+L20+K20+Q20 -> 129378.07 | S20: 488094.68 | T20: =J20-R20 -> 488094.68
A21: 15 | B21: BASSEY NSONGURUA UDOFIA | C21: PRINC.CONF SEC/PPS | D21: 12(11) | E21: 496497.17 | H21: =60000 -> 60000 | I21: =250000 -> 250000 | J21: =SUM(E21:I21) -> 806497.17 | L21: 20000 | M21: =68750 -> 68750 | O21: 7777.3604 | P21: 124394.67 | Q21: 39719.773 | R21: =P21+O21+M21+N21+L21+K21+Q21 -> 260641.81 | S21: 545855.36 | T21: =J21-R21 -> 545855.36
A22: 16 | B22: ADUGBA RICHARD TERSEER | C22: PRINCIPAL INFO. OFFICER | D22: 12(10) | E22: 482662.67 | H22: =60000 -> 60000 | I22: =100000+50000 -> 150000 | J22: =E22+F22+G22+H22+I22 -> 692662.67 | L22: =10000 -> 10000 | M22: 292813.77 | O22: 7571.9667 | P22: 104244.2 | Q22: 38613.013 | R22: =P22+O22+M22+N22+L22+K22+Q22 -> 453242.95 | S22: 239419.72 | T22: =J22-R22 -> 239419.72
A23: 17 | B23: LUCKY AGWOM | C23: RESEARCH ASSISTANT | D23: 12(8) | E23: 454993.58 | G23: =100000 -> 100000 | I23: =100000+100000 -> 200000 | J23: =E23+F23+G23+H23+I23 -> 754993.58 | L23: =50000+100000 -> 150000 | P23: 116636.73 | Q23: 36399.487 | R23: =P23+O23+M23+N23+L23+K23+Q23 -> 303036.22 | S23: 451957.36 | T23: =J23-R23 -> 451957.36
A24: 18 | B24: IDRIS IBRAHIM | C24: PRINCIPAL RESEARCH OFFICER | D24: 12(8) | E24: 454993.58 | G24: 110000 | I24: 0 | J24: =E24+F24+G24+H24+I24 -> 564993.58 | L24: 0 | N24: 32000 | P24: 80156.733 | Q24: 36399.487 | R24: =P24+O24+M24+N24+L24+K24+Q24 -> 148556.22 | S24: 448437.36 | T24: =J24-R24 -> 416437.36
A25: 19 | B25: FARUQ ATOFARATI | C25: PA (SPECIAL DUTIES) TO DG | D25: 10(7) | E25: 381140.67 | H25: =50000+10000 -> 60000 | I25: =100000+100000 -> 200000 | J25: =E25+F25+G25+H25+I25 -> 641140.67 | L25: 150000 | P25: 95911.354 | Q25: 30491.253 | R25: =P25+O25+M25+N25+L25+K25+Q25 -> 276402.61 | S25: 364738.06 | T25: =J25-R25 -> 364738.06
A26: 20 | B26: RASHEEDAT DAIBU | C26: SENIOR INFO. OFFICER | D26: 10(8) | E26: 381140.67 | H26: 60000 | J26: =E26+F26+G26+H26+I26 -> 441140.67 | L26: 50000 | N26: 12000 | O26: 6021.8646 | P26: 57511.354 | Q26: 30491.253 | R26: =P26+O26+M26+N26+L26+K26+Q26 -> 156024.47 | S26: 297116.19 | T26: =J26-R26 -> 285116.19
A27: 21 | B27: ELIZABETH OGECHUKWU ONYEAKU | C27: ICT OFFICER | D27: 9(10) | E27: 355320.67 | H27: =50000+10000 -> 60000 | J27: =E27+F27+G27+H27+I27 -> 415320.67 | L27: 10000 | M27: 43750 | O27: 5690.3938 | P27: 52950.509 | Q27: 28425.653 | R27: =P27+O27+M27+N27+L27+K27+Q27 -> 140816.56 | S27: 274504.11 | T27: =J27-R27 -> 274504.11
A28: 22 | B28: VICTOR ASUKWO | C28: ICT OFFICER | D28: 9(10) | E28: 355320.67 | H28: =50000+10000 -> 60000 | J28: =E28+F28+G28+H28+I28 -> 415320.67 | O28: 5690.3938 | P28: 52950.509 | Q28: 28425.653 | R28: =P28+O28+M28+N28+L28+K28+Q28 -> 87066.556 | S28: 328254.11 | T28: =J28-R28 -> 328254.11
A29: 23 | B29: NNANDI LIVINUS ATURE | C29: RESEARCH ASSISTANT | D29: 9(10) | E29: 355320.67 | G29: =100000 -> 100000 | J29: =E29+F29+G29+H29+I29 -> 455320.67 | L29: =10000 -> 10000 | M29: 127777.78 | P29: 60630.509 | Q29: 28425.653 | R29: =P29+O29+M29+N29+L29+K29+Q29 -> 226833.94 | S29: 228486.72 | T29: =J29-R29 -> 228486.72
A30: 24 | B30: ABDULRAHMAN A SULAIMAN | C30: STORE OFFICER | D30: 9(9) | E30: 347016.17 | H30: =60000 -> 60000 | J30: =E30+F30+G30+H30+I30 -> 407016.17 | L30: =20000 -> 20000 | M30: =17500 -> 17500 | P30: 51483.602 | Q30: 27761.293 | R30: =P30+O30+M30+N30+L30+K30+Q30 -> 116744.9 | S30: 290271.27 | T30: =J30-R30 -> 290271.27
A31: 25 | B31: DARE SHEU MAGBON | C31: ADMINISTRATION OFFICER | D31: 9(8) | E31: 338711.67 | H31: =60000 -> 60000 | J31: =E31+F31+G31+H31+I31 -> 398711.67 | L31: =30000+20000 -> 50000 | M31: 0 | P31: 50016.695 | Q31: 27096.933 | R31: =P31+O31+M31+N31+L31+K31+Q31 -> 127113.63 | S31: 271598.04 | T31: =J31-R31 -> 271598.04
A32: 26 | B32: ABUBAKAR SULAIMAN SODEEQ | C32: ADMINISTRATION OFFICER | D32: 9(8) | E32: 338711.67 | H32: =60000 -> 60000 | J32: =E32+F32+G32+H32+I32 -> 398711.67 | M32: 0 | P32: 50016.695 | Q32: 27096.933 | R32: =P32+O32+M32+N32+L32+K32+Q32 -> 77113.629 | S32: 321598.04 | T32: =J32-R32 -> 321598.04
A33: 27 | B33: JIMOH ADEBAYO ZAKA | C33: ASST. OFFICER/COMM | D33: 9(10) | E33: 355320.67 | H33: =60000 -> 60000 | J33: =E33+F33+G33+H33+I33 -> 415320.67 | L33: =10000 -> 10000 | M33: 161429.76 | O33: 5690.3938 | P33: 52950.509 | Q33: 28425.653 | R33: =P33+O33+M33+N33+L33+K33+Q33 -> 258496.32 | S33: 156824.35 | T33: =J33-R33 -> 156824.35
A34: 28 | B34: ABDULMUSHIN TAWFIQ LADAN | C34: ICT OFFICER | D34: 9(8) | E34: 338711.67 | H34: =60000 -> 60000 | J34: =E34+F34+G34+H34+I34 -> 398711.67 | M34: 0 | P34: 49761.581 | Q34: 27096.933 | R34: =P34+O34+M34+N34+L34+K34+Q34 -> 76858.515 | S34: 321853.15 | T34: =J34-R34 -> 321853.15
A35: 29 | B35: MOHAMMED BELLO | C35: PROTOCOL ASSISTANT | D35: 9(8) | E35: 338711.67 | H35: =60000 -> 60000 | J35: =E35+F35+G35+H35+I35 -> 398711.67 | L35: =0 -> 0 | P35: 49761.581 | Q35: 27096.933 | R35: =P35+O35+M35+N35+L35+K35+Q35 -> 76858.515 | S35: 321853.15 | T35: =J35-R35 -> 321853.15
A36: 30 | B36: HOLINESS PAUL UDO | C36: ADMINISTRATION OFFICER, M&E | D36: 9(7) | E36: 330407.08 | H36: =60000 -> 60000 | J36: =E36+F36+G36+H36+I36 -> 390407.08 | L36: 50000 | P36: 48549.774 | Q36: 26432.567 | R36: =P36+O36+M36+N36+L36+K36+Q36 -> 124982.34 | S36: 265424.74 | T36: =J36-R36 -> 265424.74
A37: 31 | B37: CHARITY UDO AKAN | C37: ADMINISTRATION OFFICER, M&E | D37: 9(7) | E37: 330408.08 | H37: =60000 -> 60000 | J37: =E37+F37+G37+H37+I37 -> 390408.08 | L37: 50000 | M37: 15000 | P37: 48549.951 | Q37: 26432.647 | R37: =P37+O37+M37+N37+L37+K37+Q37 -> 139982.6 | S37: 250425.49 | T37: =J37-R37 -> 250425.49
A38: 32 | B38: SANI UMAR IBRAHIM | C38: STORE OFFICER | D38: 9(7) | E38: 330409.08 | H38: =60000 -> 60000 | J38: =E38+F38+G38+H38+I38 -> 390409.08 | P38: 48550.127 | Q38: 26432.727 | R38: =P38+O38+M38+N38+L38+K38+Q38 -> 74982.854 | S38: 315426.23 | T38: =J38-R38 -> 315426.23
A39: 33 | B39: FAHAD ABUBUKAR LONGMAN | C39: ICT OFFICER | D39: 9(7) | E39: 330409.08 | H39: =60000 -> 60000 | J39: =E39+F39+G39+H39+I39 -> 390409.08 | P39: 48550.127 | Q39: 26432.727 | R39: =P39+O39+M39+N39+L39+K39+Q39 -> 74982.854 | S39: 315426.23 | T39: =J39-R39 -> 315426.23
A40: 34 | B40: HARUNA JIBRIL AMEH | C40: ASST. ADMIN. OFFICER | D40: 8(9) | E40: 301910.75 | H40: 50000 | J40: =E40+F40+G40+H40+I40 -> 351910.75 | L40: 20000 | M40: 0 | O40: 4909.1104 | P40: 42229.992 | Q40: 24152.86 | R40: =P40+O40+M40+N40+L40+K40+Q40 -> 91291.963 | S40: 260618.79 | T40: =J40-R40 -> 260618.79
...

Sheet MEMO
A2: NATIONAL INSTITUTE FOR LEGISLATIVE AND DEMOCRATIC STUDIES
A3: INTERNAL MEMO
A4: FROM : DEPUTY DIRECTOR, FINANCE AND ACCOUNTS
A5: THRU: DIRECTOR, FINANCE AND ACCOUNTS
A6: TO: DG
A7: 29TH JANUARY , 2021
A9: SUBJECT: PAYROLL FOR THE MONTH OF JANUARY, 2021
A10: Find below the details of NILDS Staff Payroll for the month of January, 2021
A13: TO: | C13: DIRECTOR, GENERAL
A14: THRU: | C14: DIRECTOR, FINANCE AND ACCOUNT
A15: FROM: | C15: DEPUTY DIRECTOR, FINANCE AND ACCOUNTS
A16: DATE: | C16: 26TH JULY 2025
A18: SUBJECT: PAYROLL FOR THE MONTH OF JULY 2025
A19: Find below the details of NILDS Staff Payroll for the Month of July 2025: | G19: NGN | H19: NGN
A20: GROSS SALARY FOR JULY, 2025 | H20: ='JULY 2025'!J225 -> 1.1019571e+08
A22: DEDUCTIONS
A23: COOP SOCIETY 1 DEDUCTIONS ( CONTR.& SPEC. SAVINGS) | G23: ='JULY 2025'!L225 -> 6776500
A24: COOP 1 LOAN RECOVERY | G24: ='JULY 2025'!M225 -> 9195454.7
A25: COOP SOCIETY 2 DEDUCTIONS ( CONTR.& SPEC. SAVINGS) | G25: ='JULY 2025'!N225 -> 2014000
A26: NHF DEDUCTIONS | G26: ='JULY 2025'!O225 -> 518783.93
A27: PAYE DEDUCTIONS | G27: ='JULY 2025'!P225 -> 15958204
A28: PENSION DEDUCTIONS | G28: ='JULY 2025'!Q225 -> 6855777.2
A29: TOTAL DEDUCTIONS FOR JULY 2025 | H29: =G23+G24+G25+G27+G26+G28 -> 41318720
A30: NET PAY AS PER JULY 2025 PAYROLL | H30: =H20-H29 -> 68876986
A31: NET PAY AS PER JUNE, 2025 PAYROLL | H31: ='JULY 2025'!S225 -> 67891076
A32: NET INCREASE/ (DECREASE) IN PAY FOR JULY, 2025 | H32: =H30-H31 -> 985909.59
A33: ANALYSED AS FOLLOWS:
A34: Effect of Cooperative 1 Adjustment for July, 2025 | H34: =1344300.36 -> 1344300.4
A35: Effect of Cooperative 2 First Contribution in July, 2025 | H35: =2014000 -> 2014000
A36: Effect of Removal of Jonathan Gabriel from Payroll due to Termination | H36: =-11708.54 -> -11708.54
A37: Effect of Increase in Shift Duty Allowance of Aliyu Sani & 5 others due to New Minimum Wage | H37: =-65734.42-1012.41 -> -66746.83
A38: Effect of Conversion & Arrears IFO of Mohammed Umar Ali & 1 other | H38: =-684161.64-880615.72 -> -1564777.4
A39: Net Effect of Regularisation of Salary & Arrears IFO Bethel Ihugba as Ag. Director | H39: -2504942.8
A40: Effect of Pulling out of Imprest of GIU unit from Payroll | H40: =80800 -> 80800
A41: Effect of NHF Deduction of Kolapo Abayomi & 1 other | H41: =-1181.62+3910.29 -> 2728.67
A42: Net effect of of Step Regularisation of Andrawus Musa & 1 other | H42: =-84994.6-42497.3 -> -127491.9
A43: Effect of Research Allowance of Christian & 1 other | H43: =-346228 -> -346228
A44: Effect of Arrears on Regularisation of PAYE Tax of Titilayo Marvelous & 1 other | H44: =-40900.56-35950 -> -76850.56
A45: Effect of removal of the arrears of Chinako Osogwa &1 other | H45: =271007.39 -> 271007.39
H46: =SUM(H34:H45) -> -985909.59
...

Sheet Shift duty
B1: STAFF NAME | C1: DESIGNATION | D1: GRADE LEVEL | E1: CONS. SALARY | F1: NEW SHIFT DUTY 11% | G1: OLD SHIFT DUTY ALLCE | H1: INCREASE
E2: N | F2: N | G2: N | H2: N
A4: 1 | B4: ALIYU SANNI ABUBAKAR | C4: RESEARCH FELLOW 11 DATA & DOCU | D4: 13(11) | E4: 541351.33 | F4: =E4*0.11 -> 59548.647 | G4: 41432.939 | H4: =F4-G4 -> 18115.708
A5: 2 | B5: CHINAKO N. ASOGWA | C5: RESEARCH FELLOW 11 DATA & DOCU | D5: 14(7) | E5: 542419.5 | F5: =E5*0.11 -> 59666.145 | G5: 42433.939 | H5: =F5-G5 -> 17232.206
A6: 3 | B6: AMOS ABA | C6: LIBRARY ASSISTANT | D6: 8(13) | E6: 329950.42 | F6: =E6*0.11 -> 36294.546 | G6: 25333.447 | H6: =F6-G6 -> 10961.098
A7: 4 | B7: TITILAYO DANIEL MARVELLOUS | C7: LIBRARY ASSISTANT | D7: 9(7) | E7: 330407.08 | F7: =E7*0.11 -> 36344.779 | G7: 26334.447 | H7: =F7-G7 -> 10010.332
A8: 5 | B8: ENENCHE JEREMIAH AGADA | C8: LIBRARY ASSISTANT | D8: 8(10) | E8: 308920.67 | F8: =E8*0.11 -> 33981.273 | G8: 24566.195 | H8: =F8-G8 -> 9415.0779
B9: TOTAL | H9: =SUM(H4:H8) -> 65734.423

Sheet Changes in July
B1: STAFF NAME | C1: DESIGNATION | D1: GRADE LEVEL | E1: BASIC SALARY | F1: ALLCE/ AREARS | G1: ALLOWANCE | H1: ALLOWANCE | I1: DUTY ALLCE | J1: GROSS SALARY | K1: AUCTION | L1: COOP CONTR/SPEC SAVINGS | M1: COOP. LOAN RECOVERY | N1: NHF DED. | O1: PAYE | P1: EMPLOYEE PENSIONS | Q1: TOTAL DEDUCTION | R1: JULY, 2025
E2: N | F2: N | G2: N | H2: N | I2: N | J2: N | K2: N | L2: N | M2: N | N2: N | O2: N | P2: N | Q2: N | R2: N
A3: 1 | B3: BETHEL UZOMA IHUGBA | C3: Acting Director | D3: 17(7) | E3: 1647612 | G3: =200000 -> 200000 | J3: =SUM(E3:I3) -> 1847612 | O3: 303177.16 | P3: 131808.96 | Q3: =O3+N3+M3+L3+K3+P3 -> 434986.12 | R3: =J3-Q3 -> 1412625.9
A4: 1 | B4: BETHEL UZOMA IHUGBA | C4: DEPUTY DIRECTOR, LEGAL RESEARCH | D4: 16(9) | E4: 905306.75 | G4: =180000 -> 180000 | I4: 100000 | J4: =SUM(E4:I4) -> 1185306.8 | O4: 192340.05 | P4: 72424.54 | Q4: =O4+N4+M4+L4+K4+P4 -> 264764.59 | R4: =J4-Q4 -> 920542.16
B5: Diference in July | J5: =J3-J4 -> 662305.25 | O5: =O3-O4 -> 110837.11 | P5: =P3-P4 -> 59384.42 | Q5: =Q3-Q4 -> 170221.53 | R5: =R3-R4 -> 492083.72
B6: Arrears for 3.65 Months | J6: =J5*3.65 -> 2417414.2 | O6: =O5*3.65 -> 404555.46 | Q6: =O6 -> 404555.46 | R6: =J6-Q6 -> 2012858.7
R7: =SUM(R5:R6) -> 2504942.4
A9: Old | B9: Mohammed Umar Ali | C9: PRINCIPAL ADMIN OFFICER | D9: 12(7) | E9: =353512.5 -> 353512.5 | H9: 60000 | J9: =E9+F9+G9+H9+I9 -> 413512.5 | O9: 52068.58 | P9: 28281 | Q9: =O9+N9+M9+L9+K9+P9 -> 80349.58 | R9: =J9-Q9 -> 333162.92
A10: New | B10: Mohammed Umar Ali | C10: PRINCIPAL ADMIN OFFICER | D10: 12(7) | E10: 441159 | H10: =60000 -> 60000 | J10: =SUM(E10:I10) -> 501159 | O10: 68112.992 | P10: 35292.72 | Q10: =O10+N10+M10+L10+K10+P10 -> 103405.71 | R10: =J10-Q10 -> 397753.29
B11: Difference | E11: =E10-E9 -> 87646.5 | J11: =J10-J9 -> 87646.5 | O11: =O10-O9 -> 16044.412 | Q11: =Q10-Q9 -> 23056.132 | R11: =R10-R9 -> 64590.368
B12: Arrears for 4 Months | E12: =J12 -> 350586 | J12: =J11*4 -> 350586 | O12: =O11*4 -> 64177.65 | Q12: =O12 -> 64177.65 | R12: =J12-Q12 -> 286408.35
R13: =R10+R12 -> 684161.64
A15: New | B15: OLUFEMI E. OYEGOKE | C15: MARKETER | D15: 9(7) | E15: 330407.08 | H15: =60000 -> 60000 | J15: =E15+F15+G15+H15+I15 -> 390407.08 | O15: 48549.774 | P15: 26432.567 | Q15: =O15+N15+M15+L15+K15+P15 -> 74982.341 | R15: =J15-Q15 -> 315424.74
A16: Old | B16: OLUFEMI E. OYEGOKE | C16: MARKETER | D16: 9(7) | E16: =255849 -> 255849 | H16: 60000 | J16: =E16+F16+G16+H16+I16 -> 315849 | O16: 36790.688 | Q16: =O16+N16+M16+L16+K16+P16 -> 36790.688 | R16: =J16-Q16 -> 279058.31
E17: =E15-E16 -> 74558.083 | J17: =J15-J16 -> 74558.083 | O17: =O15-O16 -> 11759.086 | Q17: =Q15-Q16 -> 38191.652 | R17: =R15-R16 -> 36366.431
B18: Arrears for 9 Months | E18: =E17*9 -> 671022.75 | J18: =J17*9 -> 671022.75 | O18: =O17*9 -> 105831.77 | P18: =P17*9 -> 0 | Q18: =O18 -> 105831.77 | R18: =R17*9 -> 327297.88
R19: =R15+R18 -> 642722.62

Sheet Basic & Pensions
A1: NATIONAL INSTITUTE FOR LEGISLATIVE AND DEMOCRATIC STUDIES
A2: STAFF PAYROLL FOR THE MONTH OF JUNE, 2025
E3: ='[1]FEB 08'!E11/'[1]FEB 08'!M11 -> #REF!
B4: STAFF NAME | C4: DESIGNATION | D4: GRADE LEVEL | E4: OLD CUM BASIC SALARY | F4: NEW BASIC SALARY | G4: PECULIAR ALLOW | H4: NEW CUM BASIC SALARY | I4: INCREASE IN CUM BASIC SALARY | J4: OLD EMPLOYEE PENSION 8% | K4: NEW EMPLOYEE PENSION 8% | L4: INCREASE IN DEDUCTION | M4: OLD NHF | N4: NEW NHF | O4: INCREASE IN NHF | P4: ANNUAL NEW EMPLOYEE PENSIONS | Q4: ANNUAL NEW NHF
E5: N | F5: N | G5: N | H5: N | I5: N | J5: N | K5: N | L5: N | M5: N | N5: N | O5: N | P5: N | Q5: N
E6: A | F6: B | G6: C | H6: D | I6: E | J6: F | K6: G | L6: H | M6: I | N6: J | O6: K | P6: L | Q6: M
A7: S/N | B7: DG'S OFFICE | H7: (B+C) | I7: (D-A) | J7: (8% of A) | K7: (8% of D) | L7: (G-F) | N7: (2.5% of B) | O7: (J-I) | P7: (J-I) | Q7: (J-I)
A8: 1 | B8: PROF. ABUBAKAR O. SULAIMAN | C8: DIRECTOR GENERAL | D8: CONSOL | E8: 1659751.2 | F8: 1086777.1 | G8: 884360 | H8: =F8+G8 -> 1971137.1 | I8: =H8-E8 -> 311385.92 | L8: =K8-J8 -> 0 | O8: =N8-M8 -> 0 | P8: =K8*12 -> 0 | Q8: =N8*12 -> 0
A9: 2 | B9: RAHEEM USMAN AYIGORO | C9: SA-INFRASTRUCTURE | D9: 16 (9) | E9: 762373.17 | F9: 554669.5 | G9: 350637.25 | H9: =F9+G9 -> 905306.75 | I9: =H9-E9 -> 142933.58 | J9: 60989.853 | K9: =H9*0.08 -> 72424.54 | L9: =K9-J9 -> 11434.687 | O9: =N9-M9 -> 0 | P9: =K9*12 -> 869094.48 | Q9: =N9*12 -> 0
A10: 3 | B10: MARIAM MOHAMMED BELLO | C10: SA- SPECIAL DUTIES | D10: 16 (9) | E10: 762373.17 | F10: 554669.5 | G10: 350637.25 | H10: =F10+G10 -> 905306.75 | I10: =H10-E10 -> 142933.58 | L10: =K10-J10 -> 0 | O10: =N10-M10 -> 0 | P10: =K10*12 -> 0 | Q10: =N10*12 -> 0
A11: 4 | B11: DR IKEME ARTHUR J.O | C11: DEPUTY DIRECTOR, M&E | D11: 16 (9) | E11: 762373.17 | F11: 554669.5 | G11: 350637.25 | H11: =F11+G11 -> 905306.75 | I11: =H11-E11 -> 142933.58 | J11: 60989.853 | K11: =H11*0.08 -> 72424.54 | L11: =K11-J11 -> 11434.687 | M11: 10293.398 | N11: =0.025*F11 -> 13866.737 | O11: =N11-M11 -> 3573.3396 | P11: =K11*12 -> 869094.48 | Q11: =N11*12 -> 166400.85
A12: 5 | B12: ANDRAWUS MUSA | C12: DEP. DIRECTOR, STORES & PROCUREMENT | D12: 16(8) | E12: 716034 | F12: ='[2] FGN 2024 MGT Monthly'!$I$44 -> 539028 | G12: ='[2]Peculiar Allowance'!$I$44 -> 339980.92 | H12: =F12+G12 -> 879008.92 | I12: =H12-E12 -> 162974.92 | J12: 59136.287 | K12: =H12*0.08 -> 70320.713 | L12: =K12-J12 -> 11184.427 | M12: 10293.398 | N12: =0.025*F12 -> 13475.7 | O12: =N12-M12 -> 3182.3021 | P12: =K12*12 -> 843848.56 | Q12: =N12*12 -> 161708.4
A13: 6 | B13: DR FRANCIS NDUM OJIE | C13: AD, TRAINING & IC./SA TO DG | D13: 15(8) | E13: 601396.83 | F13: 445995.83 | G13: 276599.67 | H13: =F13+G13 -> 722595.5 | I13: =H13-E13 -> 121198.67 | J13: 46569.447 | K13: =H13*0.08 -> 57807.64 | L13: =K13-J13 -> 11238.193 | M13: 7859.6313 | N13: =0.025*F13 -> 11149.896 | O13: =N13-M13 -> 3290.2646 | P13: =K13*12 -> 693691.68 | Q13: =N13*12 -> 133798.75
A14: 7 | B14: ALI ABDULLAHI | C14: CHIEF ICT OFFICER | D14: 14(11) | E14: 484373.75 | F14: 366417.5 | G14: 223239.5 | H14: =F14+G14 -> 589657 | I14: =H14-E14 -> 105283.25 | J14: 38749.9 | K14: =H14*0.08 -> 47172.56 | L14: =K14-J14 -> 8422.66 | O14: =N14-M14 -> 0 | P14: =K14*12 -> 566070.72 | Q14: =N14*12 -> 0
A15: 8 | B15: EMILY EKHIDE | C15: SENIOR RESEARCH FELLOW | D15: 15(8) | E15: 601396.83 | F15: ='[3] FGN 2024 MGT Monthly'!$I$43 -> 445995.83 | G15: 276599.67 | H15: =F15+G15 -> 722595.5 | I15: =H15-E15 -> 121198.67 | J15: 46569.45 | K15: =H15*0.08 -> 57807.64 | L15: =K15-J15 -> 11238.19 | O15: =N15-M15 -> 0 | P15: =K15*12 -> 693691.68 | Q15: =N15*12 -> 0
A16: 9 | B16: DORIS DAKDA AARON | C16: RESEARCH FELLOW I | D16: 14(9) | E16: 456622.25 | F16: 347715.92 | G16: 210449.33 | H16: =F16+G16 -> 558165.25 | I16: =H16-E16 -> 101543 | J16: 35419.72 | K16: =H16*0.08 -> 44653.22 | L16: =K16-J16 -> 9233.5 | O16: =N16-M16 -> 0 | P16: =K16*12 -> 535838.64 | Q16: =N16*12 -> 0
A17: 10 | B17: ABDULSALAM S. MUSTAPHA | C17: ASST. DIRECTOR ICT | D17: 15(7) | E17: 582118.08 | F17: 432981.08 | G17: 267732.83 | H17: =F17+G17 -> 700713.92 | I17: =H17-E17 -> 118595.83 | J17: 46569.45 | K17: =H17*0.08 -> 56057.113 | L17: =K17-J17 -> 9487.6633 | O17: =N17-M17 -> 0 | P17: =K17*12 -> 672685.36 | Q17: =N17*12 -> 0
A18: 11 | B18: PERCY TERFA GBAHABO | C18: HEAD, NILDS LIAISON OFFICE | D18: 13(11) | E18: 441804.92 | F18: 337730.83 | G18: 203620.5 | H18: =F18+G18 -> 541351.33 | I18: =H18-E18 -> 99546.417 | J18: 34313.273 | K18: =H18*0.08 -> 43308.107 | L18: =K18-J18 -> 8994.8333 | O18: =N18-M18 -> 0 | P18: =K18*12 -> 519697.28 | Q18: =N18*12 -> 0
A19: 12 | B19: HASSANA AHMED IBRAHIM | C19: PA- TO DG | D19: 13 (10) | E19: 428915.92 | F19: 329044.92 | G19: 197680.17 | H19: =F19+G19 -> 526725.08 | I19: =H19-E19 -> 97809.167 | J19: 33282.153 | K19: =H19*0.08 -> 42138.007 | L19: =K19-J19 -> 8855.8533 | M19: 5607.1771 | N19: =0.025*F19 -> 8226.1229 | O19: =N19-M19 -> 2618.9458 | P19: =K19*12 -> 505656.08 | Q19: =N19*12 -> 98713.475
A20: 13 | B20: IKIP LEBO | C20: ASST CHIEF PROC. OFFICER | D20: 13 (8) | E20: 403138 | F20: 311673.25 | G20: 185799.5 | H20: =F20+G20 -> 497472.75 | I20: =H20-E20 -> 94334.75 | J20: 31219.913 | K20: =H20*0.08 -> 39797.82 | L20: =K20-J20 -> 8577.9067 | M20: 5967.3062 | N20: =0.025*F20 -> 7791.8313 | O20: =N20-M20 -> 1824.525 | P20: =K20*12 -> 477573.84 | Q20: =N20*12 -> 93501.975
A21: 14 | B21: ALABI ADESINA MUHYDEEN | C21: HEAD, NILDS LIAISON OFFICE | D21: 13 (8) | E21: 403138 | F21: 311673.25 | G21: 185799.5 | H21: =F21+G21 -> 497472.75 | I21: =H21-E21 -> 94334.75 | J21: 31219.913 | K21: =H21*0.08 -> 39797.82 | L21: =K21-J21 -> 8577.9067 | O21: =N21-M21 -> 0 | P21: =K21*12 -> 477573.84 | Q21: =N21*12 -> 0
A22: 15 | B22: BASSEY NSONGURUA UDOFIA | C22: PRINC.CONF SEC/PPS | D22: 12(11) | E22: 402278 | F22: ='[3] FGN 2024 MGT Monthly'!$L$40 -> 311094.42 | G22: 185402.75 | H22: =F22+G22 -> 496497.17 | I22: =H22-E22 -> 94219.167 | J22: 31206.92 | K22: =H22*0.08 -> 39719.773 | L22: =K22-J22 -> 8512.8533 | M22: 5257.5625 | N22: =0.025*F22 -> 7777.3604 | O22: =N22-M22 -> 2519.7979 | P22: =K22*12 -> 476637.28 | Q22: =N22*12 -> 93328.325
A23: 16 | B23: ADUGBA RICHARD TERSEER | C23: PRINCIPAL INFO. OFFICER | D23: 12(10) | E23: 390086.5 | F23: 302878.67 | G23: 179784 | H23: =F23+G23 -> 482662.67 | I23: =H23-E23 -> 92576.167 | J23: 30231.613 | K23: =H23*0.08 -> 38613.013 | L23: =K23-J23 -> 8381.4 | N23: =0.025*F23 -> 7571.9667 | O23: =N23-M23 -> 7571.9667 | P23: =K23*12 -> 463356.16 | Q23: =N23*12 -> 90863.6
A24: 17 | B24: LUCKY AGWOM | C24: RESEARCH ASSISTANT | D24: 12(8) | E24: 365704 | F24: 286447.08 | G24: 168546.5 | H24: =F24+G24 -> 454993.58 | I24: =H24-E24 -> 89289.583 | J24: 28281 | K24: =H24*0.08 -> 36399.487 | L24: =K24-J24 -> 8118.4867 | O24: =N24-M24 -> 0 | P24: =K24*12 -> 436793.84 | Q24: =N24*12 -> 0
A25: 18 | B25: IDRIS IBRAHIM | C25: PRINCIPAL RESEARCH OFFICER | D25: 12(8) | E25: 365704 | F25: 286447.08 | G25: 168546.5 | H25: =F25+G25 -> 454993.58 | I25: =H25-E25 -> 89289.583 | J25: 28281 | K25: =H25*0.08 -> 36399.487 | L25: =K25-J25 -> 8118.4867 | O25: =N25-M25 -> 0 | P25: =K25*12 -> 436793.84 | Q25: =N25*12 -> 0
A26: 19 | B26: FARUQ ATOFARATI | C26: PA (SPECIAL DUTIES) TO DG | D26: 10(7) | E26: 293029.67 | F26: 240874.58 | G26: 140266.08 | H26: =F26+G26 -> 381140.67 | I26: =H26-E26 -> 88111 | J26: 23442.373 | K26: =H26*0.08 -> 30491.253 | L26: =K26-J26 -> 7048.88 | O26: =N26-M26 -> 0 | P26: =K26*12 -> 365895.04 | Q26: =N26*12 -> 0
A27: 20 | B27: RASHEEDAT DAIBU | C27: SENIOR INFO. OFFICER | D27: 10(8) | E27: 300965.58 | F27: 240874.58 | G27: 140266.08 | H27: =F27+G27 -> 381140.67 | I27: =H27-E27 -> 80175.083 | J27: 23442.373 | K27: =H27*0.08 -> 30491.253 | L27: =K27-J27 -> 7048.88 | N27: =0.025*F27 -> 6021.8646 | O27: =N27-M27 -> 6021.8646 | P27: =K27*12 -> 365895.04 | Q27: =N27*12 -> 72262.375
A28: 21 | B28: ELIZABETH OGECHUKWU ONYEAKU | C28: ICT OFFICER | D28: 9(10) | E28: 277798 | F28: 227615.75 | G28: 127704.92 | H28: =F28+G28 -> 355320.67 | I28: =H28-E28 -> 77522.667 | J28: 21638.533 | K28: =H28*0.08 -> 28425.653 | L28: =K28-J28 -> 6787.12 | N28: =0.025*F28 -> 5690.3938 | O28: =N28-M28 -> 5690.3938 | P28: =K28*12 -> 341107.84 | Q28: =N28*12 -> 68284.725
A29: 22 | B29: VICTOR ASUKWO | C29: ICT OFFICER | D29: 9(10) | E29: 277798 | F29: 227615.75 | G29: 127704.92 | H29: =F29+G29 -> 355320.67 | I29: =H29-E29 -> 77522.667 | J29: 21638.533 | K29: =H29*0.08 -> 28425.653 | L29: =K29-J29 -> 6787.12 | N29: =0.025*F29 -> 5690.3938 | O29: =N29-M29 -> 5690.3938 | P29: =K29*12 -> 341107.84 | Q29: =N29*12 -> 68284.725
A30: 23 | B30: NNANDI LIVINUS ATURE | C30: RESEARCH ASSISTANT | D30: 9(10) | E30: 277798 | F30: 227615.75 | G30: 127704.92 | H30: =F30+G30 -> 355320.67 | I30: =H30-E30 -> 77522.667 | J30: 21638.533 | K30: =H30*0.08 -> 28425.653 | L30: =K30-J30 -> 6787.12 | O30: =N30-M30 -> 0 | P30: =K30*12 -> 341107.84 | Q30: =N30*12 -> 0
A31: 24 | B31: ABDULRAHMAN A SULAIMAN | C31: STORE OFFICER | D31: 9(9) | E31: 270481.67 | F31: 222674.58 | G31: 124341.58 | H31: =F31+G31 -> 347016.17 | I31: =H31-E31 -> 76534.5 | J31: 21053.227 | K31: =H31*0.08 -> 27761.293 | L31: =K31-J31 -> 6708.0667 | O31: =N31-M31 -> 0 | P31: =K31*12 -> 333135.52 | Q31: =N31*12 -> 0
A32: 25 | B32: DARE SHEU MAGBON | C32: ADMINISTRATION OFFICER | D32: 9(8) | E32: 263165.33 | F32: 217733.42 | G32: 120978.25 | H32: =F32+G32 -> 338711.67 | I32: =H32-E32 -> 75546.333 | J32: 20467.92 | K32: =H32*0.08 -> 27096.933 | L32: =K32-J32 -> 6629.0133 | O32: =N32-M32 -> 0 | P32: =K32*12 -> 325163.2 | Q32: =N32*12 -> 0
A33: 26 | B33: ABUBAKAR SULAIMAN SODEEQ | C33: ADMINISTRATION OFFICER | D33: 9(8) | E33: 263165.33 | F33: 217733.42 | G33: 120978.25 | H33: =F33+G33 -> 338711.67 | I33: =H33-E33 -> 75546.333 | J33: 20467.92 | K33: =H33*0.08 -> 27096.933 | L33: =K33-J33 -> 6629.0133 | O33: =N33-M33 -> 0 | P33: =K33*12 -> 325163.2 | Q33: =N33*12 -> 0
A34: 27 | B34: JIMOH ADEBAYO ZAKA | C34: ASST. OFFICER/COMM | D34: 9(10) | E34: 277798 | F34: 227615.75 | G34: 127704.92 | H34: =F34+G34 -> 355320.67 | I34: =H34-E34 -> 77522.667 | J34: 21638.533 | K34: =H34*0.08 -> 28425.653 | L34: =K34-J34 -> 6787.12 | M34: 3653.5 | N34: =0.025*F34 -> 5690.3938 | O34: =N34-M34 -> 2036.8937 | P34: =K34*12 -> 341107.84 | Q34: =N34*12 -> 68284.725
A35: 28 | B35: ABDULMUSHIN TAWFIQ LADAN | C35: ICT OFFICER | D35: 9(8) | E35: 263165.33 | F35: 217733.42 | G35: 120978.25 | H35: =F35+G35 -> 338711.67 | I35: =H35-E35 -> 75546.333 | J35: 20467.92 | K35: =H35*0.08 -> 27096.933 | L35: =K35-J35 -> 6629.0133 | O35: =N35-M35 -> 0 | P35: =K35*12 -> 325163.2 | Q35: =N35*12 -> 0
A36: 29 | B36: MOHAMMED BELLO | C36: PROTOCOL ASSISTANT | D36: 9(8) | E36: 263165.33 | F36: 217733.42 | G36: 120978.25 | H36: =F36+G36 -> 338711.67 | I36: =H36-E36 -> 75546.333 | J36: 20467.92 | K36: =H36*0.08 -> 27096.933 | L36: =K36-J36 -> 6629.0133 | O36: =N36-M36 -> 0 | P36: =K36*12 -> 325163.2 | Q36: =N36*12 -> 0
A37: 30 | B37: HARUNA JIBRIL AMEH | C37: ASST. ADMIN. OFFICER | D37: 8(9) | E37: 230631.92 | F37: 196364.42 | G37: 105546.33 | H37: =F37+G37 -> 301910.75 | I37: =H37-E37 -> 71278.833 | J37: 17956.78 | K37: =H37*0.08 -> 24152.86 | L37: =K37-J37 -> 6196.08 | N37: =0.025*F37 -> 4909.1104 | O37: =N37-M37 -> 4909.1104 | P37: =K37*12 -> 289834.32 | Q37: =N37*12 -> 58909.325
A38: 31 | B38: RAMATU IBRAHIM ABDULRAHEEM | C38: INFORMATION OFFICER | D38: 8(8) | E38: 224459.75 | F38: 192179.42 | G38: 102721.42 | H38: =F38+G38 -> 294900.83 | I38: =H38-E38 -> 70441.083 | J38: 17463.007 | K38: =H38*0.08 -> 23592.067 | L38: =K38-J38 -> 6129.06 | N38: =0.025*F38 -> 4804.4854 | O38: =N38-M38 -> 4804.4854 | P38: =K38*12 -> 283104.8 | Q38: =N38*12 -> 57653.825
B39: TOTAL | C39: 31 | E39: =SUM(E8:E38) -> 14073004 | F39: =SUM(F8:F38) -> 10680274 | G39: =SUM(G8:G38) -> 6613927.2 | H39: =SUM(H8:H38) -> 17294201 | I39: =SUM(I8:I38) -> 3221197.1 | J39: =SUM(J8:J38) -> 914813.32 | K39: =SUM(K8:K38) -> 1153420.6 | L39: =SUM(L8:L38) -> 238607.23 | ... Q39: =SUM(Q8:Q38) -> 1231995.1
B41: INTERNAL AUDIT
...

Sheet Changes in PAYE
A1: NATIONAL INSTITUTE FOR LEGISLATIVE AND DEMOCRATIC STUDIES
A2: NATIONAL ASSEMBLY ABUJA
A3: TAX COMPUTATION FOR 2022
A4: S/NO | B4: NAME | C4: MONTHLY TOTAL SALARY | D4: NO OF MONTHS | E4: ANNUAL SALARY GROSSED UP | F4: NATIONAL HOUSING SCHEME = 2.5% OF BASIC SALARY | G4: PENSION CONTRIBUTION = 8% OF CONSOLIDATED | H4: NHIS | I4: NET SALARY (EXC OF CRA) | M4: CRA=#200,000+(20% 0F NET SALARY (EXC OF CRA) | N4: TOTAL RELIEF | O4: CHARGEABLE INCOME | P4: FIRST N300,000 @ 7% | Q4: NEXT N300,000 @ 11% | R4: NEXT N500,000 @ 15% | S4: NEXT N500,000@ 19% | T4: NEXT N1,600,000 @ 21% | U4: ABOVE N3,200,000 @ 24% | V4: ANNUAL TAX PAYABLE | X4: MONTHLY TAX PAYABLE | Y4: MINIMUM TAX PAYABLE | Z4: NEW ACTUAL TAX PAYABLE | AA4: OLD ACTUAL TAX PAYABLE | AB4: INCREASE IN PAYE
A5: 1 | B5: DG'S OFFICE
A6: 3 | B6: PROF. ABUBAKAR O. SULAIMAN | C6: 2246372.1 | D6: 12 | E6: =C6*D6 -> 26956465 | G6: 0 | I6: =E6-F6-G6-H6 -> 26956465 | J6: 200000 | K6: 0.2 | L6: =I6*K6 -> 5391293 | M6: =J6+L6 -> 5591293 | N6: =F6+G6+H6+M6 -> 5591293 | O6: =E6-N6 -> 21365172 | P6: =IF(O6<300000,0.07*O6,21000) -> 21000 | Q6: =IF((O6-300000)<0,0,IF((O6-300000)<300000,0.11*(O6-300000),33000)) -> 33000 | R6: =IF((O6-600000)<0,0,IF((O6-600000)<500000,0.15*(O6-600000),75000)) -> 75000 | S6: =IF((O6-1100000)<0,0,IF((O6-1100000)<500000,0.19*(O6-1100000),95000)) -> 95000 | T6: =IF((O6-1600000)<0,0,IF((O6-1600000)<1600000,0.21*(O6-1600000),336000)) -> 336000 | U6: =24%*(O6-3200000) -> 4359641.3 | V6: =P6+Q6+R6+S6+T6+U6 -> 4919641.3 | W6: 12 | X6: =V6/W6 -> 409970.11 | Z6: =X6 -> 409970.11 | AA6: 350184.01 | AB6: =Z6-AA6 -> 59786.096
A7: 4 | B7: RAHEEM USMAN AYIGORO | C7: 1095306.8 | D7: 12 | E7: =C7*D7 -> 13143681 | G7: 869094.48 | I7: =E7-F7-G7-H7 -> 12274587 | J7: 200000 | K7: 0.2 | L7: =I7*K7 -> 2454917.3 | M7: =J7+L7 -> 2654917.3 | N7: =F7+G7+H7+M7 -> 3524011.8 | O7: =E7-N7 -> 9619669.2 | P7: =IF(O7<300000,0.07*O7,21000) -> 21000 | Q7: =IF((O7-300000)<0,0,IF((O7-300000)<300000,0.11*(O7-300000),33000)) -> 33000 | R7: =IF((O7-600000)<0,0,IF((O7-600000)<500000,0.15*(O7-600000),75000)) -> 75000 | S7: =IF((O7-1100000)<0,0,IF((O7-1100000)<500000,0.19*(O7-1100000),95000)) -> 95000 | T7: =IF((O7-1600000)<0,0,IF((O7-1600000)<1600000,0.21*(O7-1600000),336000)) -> 336000 | U7: =24%*(O7-3200000) -> 1540720.6 | V7: =P7+Q7+R7+S7+T7+U7 -> 2100720.6 | W7: 12 | X7: =V7/W7 -> 175060.05 | Z7: =X7 -> 175060.05 | AA7: 149812.26 | AB7: =Z7-AA7 -> 25247.788
A8: 5 | B8: MARIAM MOHAMMED BELLO | C8: 1295306.8 | D8: 12 | E8: =C8*D8 -> 15543681 | G8: 0 | I8: =E8-F8-G8-H8 -> 15543681 | J8: 200000 | K8: 0.2 | L8: =I8*K8 -> 3108736.2 | M8: =J8+L8 -> 3308736.2 | N8: =F8+G8+H8+M8 -> 3308736.2 | O8: =E8-N8 -> 12234945 | P8: =IF(O8<300000,0.07*O8,21000) -> 21000 | Q8: =IF((O8-300000)<0,0,IF((O8-300000)<300000,0.11*(O8-300000),33000)) -> 33000 | R8: =IF((O8-600000)<0,0,IF((O8-600000)<500000,0.15*(O8-600000),75000)) -> 75000 | S8: =IF((O8-1100000)<0,0,IF((O8-1100000)<500000,0.19*(O8-1100000),95000)) -> 95000 | T8: =IF((O8-1600000)<0,0,IF((O8-1600000)<1600000,0.21*(O8-1600000),336000)) -> 336000 | U8: =24%*(O8-3200000) -> 2168386.8 | V8: =P8+Q8+R8+S8+T8+U8 -> 2728386.8 | W8: 12 | X8: =V8/W8 -> 227365.56 | Z8: =X8 -> 227365.56 | AA8: 199922.31 | AB8: =Z8-AA8 -> 27443.248
A9: 6 | B9: DR IKEME ARTHUR J.O | C9: 1085306.8 | D9: 12 | E9: =C9*D9 -> 13023681 | F9: 166400.85 | G9: 869094.48 | I9: =E9-F9-G9-H9 -> 11988186 | J9: 200000 | K9: 0.2 | L9: =I9*K9 -> 2397637.1 | M9: =J9+L9 -> 2597637.1 | N9: =F9+G9+H9+M9 -> 3633132.5 | O9: =E9-N9 -> 9390548.5 | P9: =IF(O9<300000,0.07*O9,21000) -> 21000 | Q9: =IF((O9-300000)<0,0,IF((O9-300000)<300000,0.11*(O9-300000),33000)) -> 33000 | R9: =IF((O9-600000)<0,0,IF((O9-600000)<500000,0.15*(O9-600000),75000)) -> 75000 | S9: =IF((O9-1100000)<0,0,IF((O9-1100000)<500000,0.19*(O9-1100000),95000)) -> 95000 | T9: =IF((O9-1600000)<0,0,IF((O9-1600000)<1600000,0.21*(O9-1600000),336000)) -> 336000 | U9: =24%*(O9-3200000) -> 1485731.6 | V9: =P9+Q9+R9+S9+T9+U9 -> 2045731.6 | W9: 12 | X9: =V9/W9 -> 170477.64 | Z9: =X9 -> 170477.64 | AA9: 147687.53 | AB9: =Z9-AA9 -> 22790.11
A10: 7 | B10: ANDRAWUS MUSA | C10: 1071604.6 | D10: 12 | E10: =C10*D10 -> 12859255 | F10: 157015.95 | G10: 818602.64 | I10: =E10-F10-G10-H10 -> 11883636 | J10: 200000 | K10: 0.2 | L10: =I10*K10 -> 2376727.3 | M10: =J10+L10 -> 2576727.3 | N10: =F10+G10+H10+M10 -> 3552345.9 | O10: =E10-N10 -> 9306909.1 | P10: =IF(O10<300000,0.07*O10,21000) -> 21000 | Q10: =IF((O10-300000)<0,0,IF((O10-300000)<300000,0.11*(O10-300000),33000)) -> 33000 | R10: =IF((O10-600000)<0,0,IF((O10-600000)<500000,0.15*(O10-600000),75000)) -> 75000 | S10: =IF((O10-1100000)<0,0,IF((O10-1100000)<500000,0.19*(O10-1100000),95000)) -> 95000 | T10: =IF((O10-1600000)<0,0,IF((O10-1600000)<1600000,0.21*(O10-1600000),336000)) -> 336000 | U10: =24%*(O10-3200000) -> 1465658.2 | V10: =P10+Q10+R10+S10+T10+U10 -> 2025658.2 | W10: 12 | X10: =V10/W10 -> 168804.85 | Z10: =X10 -> 168804.85 | AA10: 129694.7 | AB10: =Z10-AA10 -> 39110.154
A11: 8 | B11: DR FRANCIS NDUM OJIE | C11: 1082595.5 | D11: 12 | E11: =C11*D11 -> 12991146 | F11: 133798.75 | G11: 693691.68 | I11: =E11-F11-G11-H11 -> 12163656 | J11: 200000 | K11: 0.2 | L11: =I11*K11 -> 2432731.1 | M11: =J11+L11 -> 2632731.1 | N11: =F11+G11+H11+M11 -> 3460221.5 | O11: =E11-N11 -> 9530924.5 | P11: =IF(O11<300000,0.07*O11,21000) -> 21000 | Q11: =IF((O11-300000)<0,0,IF((O11-300000)<300000,0.11*(O11-300000),33000)) -> 33000 | R11: =IF((O11-600000)<0,0,IF((O11-600000)<500000,0.15*(O11-600000),75000)) -> 75000 | S11: =IF((O11-1100000)<0,0,IF((O11-1100000)<500000,0.19*(O11-1100000),95000)) -> 95000 | T11: =IF((O11-1600000)<0,0,IF((O11-1600000)<1600000,0.21*(O11-1600000),336000)) -> 336000 | U11: =24%*(O11-3200000) -> 1519421.9 | V11: =P11+Q11+R11+S11+T11+U11 -> 2079421.9 | W11: 12 | X11: =V11/W11 -> 173285.16 | Z11: =X11 -> 173285.16 | AA11: 150463.11 | AB11: =Z11-AA11 -> 22822.046
A12: 9 | B12: ALI ABDULLAHI | C12: 659657 | D12: 12 | E12: =C12*D12 -> 7915884 | G12: 566070.72 | I12: =E12-F12-G12-H12 -> 7349813.3 | J12: 200000 | K12: 0.2 | L12: =I12*K12 -> 1469962.7 | M12: =J12+L12 -> 1669962.7 | N12: =F12+G12+H12+M12 -> 2236033.4 | O12: =E12-N12 -> 5679850.6 | P12: =IF(O12<300000,0.07*O12,21000) -> 21000 | Q12: =IF((O12-300000)<0,0,IF((O12-300000)<300000,0.11*(O12-300000),33000)) -> 33000 | R12: =IF((O12-600000)<0,0,IF((O12-600000)<500000,0.15*(O12-600000),75000)) -> 75000 | S12: =IF((O12-1100000)<0,0,IF((O12-1100000)<500000,0.19*(O12-1100000),95000)) -> 95000 | T12: =IF((O12-1600000)<0,0,IF((O12-1600000)<1600000,0.21*(O12-1600000),336000)) -> 336000 | U12: =24%*(O12-3200000) -> 595164.15 | V12: =P12+Q12+R12+S12+T12+U12 -> 1155164.1 | W12: 12 | X12: =V12/W12 -> 96263.679 | Z12: =X12 -> 96263.679 | AA12: 77666.446 | AB12: =Z12-AA12 -> 18597.233
A13: 10 | B13: EMILY EKHIDE | C13: 932595.5 | D13: 12 | E13: =C13*D13 -> 11191146 | G13: 693691.68 | I13: =E13-F13-G13-H13 -> 10497454 | J13: 200000 | K13: 0.2 | L13: =I13*K13 -> 2099490.9 | M13: =J13+L13 -> 2299490.9 | N13: =F13+G13+H13+M13 -> 2993182.5 | O13: =E13-N13 -> 8197963.5 | P13: =IF(O13<300000,0.07*O13,21000) -> 21000 | Q13: =IF((O13-300000)<0,0,IF((O13-300000)<300000,0.11*(O13-300000),33000)) -> 33000 | R13: =IF((O13-600000)<0,0,IF((O13-600000)<500000,0.15*(O13-600000),75000)) -> 75000 | S13: =IF((O13-1100000)<0,0,IF((O13-1100000)<500000,0.19*(O13-1100000),95000)) -> 95000 | T13: =IF((O13-1600000)<0,0,IF((O13-1600000)<1600000,0.21*(O13-1600000),336000)) -> 336000 | U13: =24%*(O13-3200000) -> 1199511.2 | V13: =P13+Q13+R13+S13+T13+U13 -> 1759511.2 | W13: 12 | X13: =V13/W13 -> 146625.94 | Z13: =X13 -> 146625.94 | AA13: 141011.99 | AB13: =Z13-AA13 -> 5613.9468
A14: 11 | B14: DORIS DAKDA AARON | C14: 948165.25 | D14: 12 | E14: =C14*D14 -> 11377983 | G14: 535838.64 | I14: =E14-F14-G14-H14 -> 10842144 | J14: 200000 | K14: 0.2 | L14: =I14*K14 -> 2168428.9 | M14: =J14+L14 -> 2368428.9 | N14: =F14+G14+H14+M14 -> 2904267.5 | O14: =E14-N14 -> 8473715.5 | P14: =IF(O14<300000,0.07*O14,21000) -> 21000 | Q14: =IF((O14-300000)<0,0,IF((O14-300000)<300000,0.11*(O14-300000),33000)) -> 33000 | R14: =IF((O14-600000)<0,0,IF((O14-600000)<500000,0.15*(O14-600000),75000)) -> 75000 | S14: =IF((O14-1100000)<0,0,IF((O14-1100000)<500000,0.19*(O14-1100000),95000)) -> 95000 | T14: =IF((O14-1600000)<0,0,IF((O14-1600000)<1600000,0.21*(O14-1600000),336000)) -> 336000 | U14: =24%*(O14-3200000) -> 1265691.7 | V14: =P14+Q14+R14+S14+T14+U14 -> 1825691.7 | W14: 12 | X14: =V14/W14 -> 152140.98 | Z14: =X14 -> 152140.98 | AA14: 131753.41 | AB14: =Z14-AA14 -> 20387.568
A15: 12 | B15: ABDULSALAM S. MUSTAPHA | C15: 830713.92 | D15: 12 | E15: =C15*D15 -> 9968567 | G15: 672685.36 | I15: =E15-F15-G15-H15 -> 9295881.6 | J15: 200000 | K15: 0.2 | L15: =I15*K15 -> 1859176.3 | M15: =J15+L15 -> 2059176.3 | N15: =F15+G15+H15+M15 -> 2731861.7 | O15: =E15-N15 -> 7236705.3 | P15: =IF(O15<300000,0.07*O15,21000) -> 21000 | Q15: =IF((O15-300000)<0,0,IF((O15-300000)<300000,0.11*(O15-300000),33000)) -> 33000 | R15: =IF((O15-600000)<0,0,IF((O15-600000)<500000,0.15*(O15-600000),75000)) -> 75000 | S15: =IF((O15-1100000)<0,0,IF((O15-1100000)<500000,0.19*(O15-1100000),95000)) -> 95000 | T15: =IF((O15-1600000)<0,0,IF((O15-1600000)<1600000,0.21*(O15-1600000),336000)) -> 336000 | U15: =24%*(O15-3200000) -> 968809.27 | V15: =P15+Q15+R15+S15+T15+U15 -> 1528809.3 | W15: 12 | X15: =V15/W15 -> 127400.77 | Z15: =X15 -> 127400.77 | AA15: 106452 | AB15: =Z15-AA15 -> 20948.773
A16: 13 | B16: PERCY TERFA GBAHABO | C16: 661351.33 | D16: 12 | E16: =C16*D16 -> 7936216 | G16: 519697.28 | I16: =E16-F16-G16-H16 -> 7416518.7 | J16: 200000 | K16: 0.2 | L16: =I16*K16 -> 1483303.7 | M16: =J16+L16 -> 1683303.7 | N16: =F16+G16+H16+M16 -> 2203001 | O16: =E16-N16 -> 5733215 | P16: =IF(O16<300000,0.07*O16,21000) -> 21000 | Q16: =IF((O16-300000)<0,0,IF((O16-300000)<300000,0.11*(O16-300000),33000)) -> 33000 | R16: =IF((O16-600000)<0,0,IF((O16-600000)<500000,0.15*(O16-600000),75000)) -> 75000 | S16: =IF((O16-1100000)<0,0,IF((O16-1100000)<500000,0.19*(O16-1100000),95000)) -> 95000 | T16: =IF((O16-1600000)<0,0,IF((O16-1600000)<1600000,0.21*(O16-1600000),336000)) -> 336000 | U16: =24%*(O16-3200000) -> 607971.59 | V16: =P16+Q16+R16+S16+T16+U16 -> 1167971.6 | W16: 12 | X16: =V16/W16 -> 97330.966 | Z16: =X16 -> 97330.966 | AA16: 77470.374 | AB16: =Z16-AA16 -> 19860.592
A17: 14 | B17: HASSANA AHMED IBRAHIM | C17: 846725.08 | D17: 12 | E17: =C17*D17 -> 10160701 | F17: 98713.475 | G17: 505656.08 | I17: =E17-F17-G17-H17 -> 9556331.4 | J17: 200000 | K17: 0.2 | L17: =I17*K17 -> 1911266.3 | M17: =J17+L17 -> 2111266.3 | N17: =F17+G17+H17+M17 -> 2715635.8 | O17: =E17-N17 -> 7445065.2 | P17: =IF(O17<300000,0.07*O17,21000) -> 21000 | Q17: =IF((O17-300000)<0,0,IF((O17-300000)<300000,0.11*(O17-300000),33000)) -> 33000 | R17: =IF((O17-600000)<0,0,IF((O17-600000)<500000,0.15*(O17-600000),75000)) -> 75000 | S17: =IF((O17-1100000)<0,0,IF((O17-1100000)<500000,0.19*(O17-1100000),95000)) -> 95000 | T17: =IF((O17-1600000)<0,0,IF((O17-1600000)<1600000,0.21*(O17-1600000),336000)) -> 336000 | U17: =24%*(O17-3200000) -> 1018815.6 | V17: =P17+Q17+R17+S17+T17+U17 -> 1578815.6 | W17: 12 | X17: =V17/W17 -> 131567.97 | Z17: =X17 -> 131567.97 | AA17: 113474.9 | AB17: =Z17-AA17 -> 18093.066
A18: 15 | B18: IKIP LEBO | C18: 567472.75 | D18: 12 | E18: =C18*D18 -> 6809673 | F18: 93501.975 | G18: 477573.84 | I18: =E18-F18-G18-H18 -> 6238597.2 | J18: 200000 | K18: 0.2 | L18: =I18*K18 -> 1247719.4 | M18: =J18+L18 -> 1447719.4 | N18: =F18+G18+H18+M18 -> 2018795.3 | O18: =E18-N18 -> 4790877.7 | P18: =IF(O18<300000,0.07*O18,21000) -> 21000 | Q18: =IF((O18-300000)<0,0,IF((O18-300000)<300000,0.11*(O18-300000),33000)) -> 33000 | R18: =IF((O18-600000)<0,0,IF((O18-600000)<500000,0.15*(O18-600000),75000)) -> 75000 | S18: =IF((O18-1100000)<0,0,IF((O18-1100000)<500000,0.19*(O18-1100000),95000)) -> 95000 | T18: =IF((O18-1600000)<0,0,IF((O18-1600000)<1600000,0.21*(O18-1600000),336000)) -> 336000 | U18: =24%*(O18-3200000) -> 381810.66 | V18: =P18+Q18+R18+S18+T18+U18 -> 941810.66 | W18: 12 | X18: =V18/W18 -> 78484.222 | Z18: =X18 -> 78484.222 | AA18: 61040.235 | AB18: =Z18-AA18 -> 17443.986
A19: 16 | B19: ALABI ADESINA MUHYDEEN | C19: 617472.75 | D19: 12 | E19: =C19*D19 -> 7409673 | F19: 0 | G19: 477573.84 | I19: =E19-F19-G19-H19 -> 6932099.2 | J19: 200000 | K19: 0.2 | L19: =I19*K19 -> 1386419.8 | M19: =J19+L19 -> 1586419.8 | N19: =F19+G19+H19+M19 -> 2063993.7 | O19: =E19-N19 -> 5345679.3 | P19: =IF(O19<300000,0.07*O19,21000) -> 21000 | Q19: =IF((O19-300000)<0,0,IF((O19-300000)<300000,0.11*(O19-300000),33000)) -> 33000 | R19: =IF((O19-600000)<0,0,IF((O19-600000)<500000,0.15*(O19-600000),75000)) -> 75000 | S19: =IF((O19-1100000)<0,0,IF((O19-1100000)<500000,0.19*(O19-1100000),95000)) -> 95000 | T19: =IF((O19-1600000)<0,0,IF((O19-1600000)<1600000,0.21*(O19-1600000),336000)) -> 336000 | U19: =24%*(O19-3200000) -> 514963.04 | V19: =P19+Q19+R19+S19+T19+U19 -> 1074963 | W19: 12 | X19: =V19/W19 -> 89580.253 | Z19: =X19 -> 89580.253 | AA19: 70640.235 | AB19: =Z19-AA19 -> 18940.018
A20: 17 | B20: BASSEY NSONGURUA UDOFIA | C20: 806497.17 | D20: 12 | E20: =C20*D20 -> 9677966 | F20: 93328.325 | G20: 476637.28 | I20: =E20-F20-G20-H20 -> 9108000.4 | J20: 200000 | K20: 0.2 | L20: =I20*K20 -> 1821600.1 | M20: =J20+L20 -> 2021600.1 | N20: =F20+G20+H20+M20 -> 2591565.7 | O20: =E20-N20 -> 7086400.3 | P20: =IF(O20<300000,0.07*O20,21000) -> 21000 | Q20: =IF((O20-300000)<0,0,IF((O20-300000)<300000,0.11*(O20-300000),33000)) -> 33000 | R20: =IF((O20-600000)<0,0,IF((O20-600000)<500000,0.15*(O20-600000),75000)) -> 75000 | S20: =IF((O20-1100000)<0,0,IF((O20-1100000)<500000,0.19*(O20-1100000),95000)) -> 95000 | T20: =IF((O20-1600000)<0,0,IF((O20-1600000)<1600000,0.21*(O20-1600000),336000)) -> 336000 | U20: =24%*(O20-3200000) -> 932736.08 | V20: =P20+Q20+R20+S20+T20+U20 -> 1492736.1 | W20: 12 | X20: =V20/W20 -> 124394.67 | Z20: =X20 -> 124394.67 | AA20: 106297.15 | AB20: =Z20-AA20 -> 18097.523
A21: 18 | B21: ADUGBA RICHARD TERSEER | C21: 692662.67 | D21: 12 | E21: =C21*D21 -> 8311952 | G21: 463356.16 | I21: =E21-F21-G21-H21 -> 7848595.8 | J21: 200000 | K21: 0.2 | L21: =I21*K21 -> 1569719.2 | M21: =J21+L21 -> 1769719.2 | N21: =F21+G21+H21+M21 -> 2233075.3 | O21: =E21-N21 -> 6078876.7 | P21: =IF(O21<300000,0.07*O21,21000) -> 21000 | Q21: =IF((O21-300000)<0,0,IF((O21-300000)<300000,0.11*(O21-300000),33000)) -> 33000 | R21: =IF((O21-600000)<0,0,IF((O21-600000)<500000,0.15*(O21-600000),75000)) -> 75000 | S21: =IF((O21-1100000)<0,0,IF((O21-1100000)<500000,0.19*(O21-1100000),95000)) -> 95000 | T21: =IF((O21-1600000)<0,0,IF((O21-1600000)<1600000,0.21*(O21-1600000),336000)) -> 336000 | U21: =24%*(O21-3200000) -> 690930.4 | V21: =P21+Q21+R21+S21+T21+U21 -> 1250930.4 | W21: 12 | X21: =V21/W21 -> 104244.2 | Z21: =X21 -> 104244.2 | AA21: 82601.205 | AB21: =Z21-AA21 -> 21642.995
A22: 19 | B22: LUCKY AGWOM | C22: 754993.58 | D22: 12 | E22: =C22*D22 -> 9059923 | G22: 436793.84 | I22: =E22-F22-G22-H22 -> 8623129.2 | J22: 200000 | K22: 0.2 | L22: =I22*K22 -> 1724625.8 | M22: =J22+L22 -> 1924625.8 | N22: =F22+G22+H22+M22 -> 2361419.7 | O22: =E22-N22 -> 6698503.3 | P22: =IF(O22<300000,0.07*O22,21000) -> 21000 | Q22: =IF((O22-300000)<0,0,IF((O22-300000)<300000,0.11*(O22-300000),33000)) -> 33000 | R22: =IF((O22-600000)<0,0,IF((O22-600000)<500000,0.15*(O22-600000),75000)) -> 75000 | S22: =IF((O22-1100000)<0,0,IF((O22-1100000)<500000,0.19*(O22-1100000),95000)) -> 95000 | T22: =IF((O22-1600000)<0,0,IF((O22-1600000)<1600000,0.21*(O22-1600000),336000)) -> 336000 | U22: =24%*(O22-3200000) -> 839640.8 | V22: =P22+Q22+R22+S22+T22+U22 -> 1399640.8 | W22: 12 | X22: =V22/W22 -> 116636.73 | Z22: =X22 -> 116636.73 | AA22: 98711.115 | AB22: =Z22-AA22 -> 17925.619
A23: 20 | B23: IDRIS IBRAHIM | C23: 564993.58 | D23: 12 | E23: =C23*D23 -> 6779923 | G23: 436793.84 | I23: =E23-F23-G23-H23 -> 6343129.2 | J23: 200000 | K23: 0.2 | L23: =I23*K23 -> 1268625.8 | M23: =J23+L23 -> 1468625.8 | N23: =F23+G23+H23+M23 -> 1905419.7 | O23: =E23-N23 -> 4874503.3 | P23: =IF(O23<300000,0.07*O23,21000) -> 21000 | Q23: =IF((O23-300000)<0,0,IF((O23-300000)<300000,0.11*(O23-300000),33000)) -> 33000 | R23: =IF((O23-600000)<0,0,IF((O23-600000)<500000,0.15*(O23-600000),75000)) -> 75000 | S23: =IF((O23-1100000)<0,0,IF((O23-1100000)<500000,0.19*(O23-1100000),95000)) -> 95000 | T23: =IF((O23-1600000)<0,0,IF((O23-1600000)<1600000,0.21*(O23-1600000),336000)) -> 336000 | U23: =24%*(O23-3200000) -> 401880.8 | V23: =P23+Q23+R23+S23+T23+U23 -> 961880.8 | W23: 12 | X23: =V23/W23 -> 80156.733 | Z23: =X23 -> 80156.733 | AA23: 62231.115 | AB23: =Z23-AA23 -> 17925.619
A24: 21 | B24: FARUQ ATOFARATI | C24: 641140.67 | D24: 12 | E24: =C24*D24 -> 7693688 | G24: 365895.04 | I24: =E24-F24-G24-H24 -> 7327793 | J24: 200000 | K24: 0.2 | L24: =I24*K24 -> 1465558.6 | M24: =J24+L24 -> 1665558.6 | N24: =F24+G24+H24+M24 -> 2031453.6 | O24: =E24-N24 -> 5662234.4 | P24: =IF(O24<300000,0.07*O24,21000) -> 21000 | Q24: =IF((O24-300000)<0,0,IF((O24-300000)<300000,0.11*(O24-300000),33000)) -> 33000 | R24: =IF((O24-600000)<0,0,IF((O24-600000)<500000,0.15*(O24-600000),75000)) -> 75000 | S24: =IF((O24-1100000)<0,0,IF((O24-1100000)<500000,0.19*(O24-1100000),95000)) -> 95000 | T24: =IF((O24-1600000)<0,0,IF((O24-1600000)<1600000,0.21*(O24-1600000),336000)) -> 336000 | U24: =24%*(O24-3200000) -> 590936.25 | V24: =P24+Q24+R24+S24+T24+U24 -> 1150936.2 | W24: 12 | X24: =V24/W24 -> 95911.354 | Z24: =X24 -> 95911.354 | AA24: 80347.427 | AB24: =Z24-AA24 -> 15563.927
A25: 22 | B25: RASHEEDAT DAIBU | C25: 441140.67 | D25: 12 | E25: =C25*D25 -> 5293688 | G25: 365895.04 | I25: =E25-F25-G25-H25 -> 4927793 | J25: 200000 | K25: 0.2 | L25: =I25*K25 -> 985558.59 | M25: =J25+L25 -> 1185558.6 | N25: =F25+G25+H25+M25 -> 1551453.6 | O25: =E25-N25 -> 3742234.4 | P25: =IF(O25<300000,0.07*O25,21000) -> 21000 | Q25: =IF((O25-300000)<0,0,IF((O25-300000)<300000,0.11*(O25-300000),33000)) -> 33000 | R25: =IF((O25-600000)<0,0,IF((O25-600000)<500000,0.15*(O25-600000),75000)) -> 75000 | S25: =IF((O25-1100000)<0,0,IF((O25-1100000)<500000,0.19*(O25-1100000),95000)) -> 95000 | T25: =IF((O25-1600000)<0,0,IF((O25-1600000)<1600000,0.21*(O25-1600000),336000)) -> 336000 | U25: =24%*(O25-3200000) -> 130136.25 | V25: =P25+Q25+R25+S25+T25+U25 -> 690136.25 | W25: 12 | X25: =V25/W25 -> 57511.354 | Z25: =X25 -> 57511.354 | AA25: 42537.332 | AB25: =Z25-AA25 -> 14974.022
A26: 23 | B26: ELIZABETH OGECHUKWU ONYEAKU | C26: 415320.67 | D26: 12 | E26: =C26*D26 -> 4983848 | G26: 341107.84 | I26: =E26-F26-G26-H26 -> 4642740.2 | J26: 200000 | K26: 0.2 | L26: =I26*K26 -> 928548.03 | M26: =J26+L26 -> 1128548 | N26: =F26+G26+H26+M26 -> 1469655.9 | O26: =E26-N26 -> 3514192.1 | P26: =IF(O26<300000,0.07*O26,21000) -> 21000 | Q26: =IF((O26-300000)<0,0,IF((O26-300000)<300000,0.11*(O26-300000),33000)) -> 33000 | R26: =IF((O26-600000)<0,0,IF((O26-600000)<500000,0.15*(O26-600000),75000)) -> 75000 | S26: =IF((O26-1100000)<0,0,IF((O26-1100000)<500000,0.19*(O26-1100000),95000)) -> 95000 | T26: =IF((O26-1600000)<0,0,IF((O26-1600000)<1600000,0.21*(O26-1600000),336000)) -> 336000 | U26: =24%*(O26-3200000) -> 75406.111 | V26: =P26+Q26+R26+S26+T26+U26 -> 635406.11 | W26: 12 | X26: =V26/W26 -> 52950.509 | Z26: =X26 -> 52950.509 | AA26: 39052.313 | AB26: =Z26-AA26 -> 13898.196
A27: 24 | B27: VICTOR ASUKWO | C27: 415320.67 | D27: 12 | E27: =C27*D27 -> 4983848 | G27: 341107.84 | I27: =E27-F27-G27-H27 -> 4642740.2 | J27: 200000 | K27: 0.2 | L27: =I27*K27 -> 928548.03 | M27: =J27+L27 -> 1128548 | N27: =F27+G27+H27+M27 -> 1469655.9 | O27: =E27-N27 -> 3514192.1 | P27: =IF(O27<300000,0.07*O27,21000) -> 21000 | Q27: =IF((O27-300000)<0,0,IF((O27-300000)<300000,0.11*(O27-300000),33000)) -> 33000 | R27: =IF((O27-600000)<0,0,IF((O27-600000)<500000,0.15*(O27-600000),75000)) -> 75000 | S27: =IF((O27-1100000)<0,0,IF((O27-1100000)<500000,0.19*(O27-1100000),95000)) -> 95000 | T27: =IF((O27-1600000)<0,0,IF((O27-1600000)<1600000,0.21*(O27-1600000),336000)) -> 336000 | U27: =24%*(O27-3200000) -> 75406.111 | V27: =P27+Q27+R27+S27+T27+U27 -> 635406.11 | W27: 12 | X27: =V27/W27 -> 52950.509 | Z27: =X27 -> 52950.509 | AA27: 39052.313 | AB27: =Z27-AA27 -> 13898.196
A28: 25 | B28: NNANDI LIVINUS ATURE | C28: 455320.67 | D28: 12 | E28: =C28*D28 -> 5463848 | G28: 341107.84 | I28: =E28-F28-G28-H28 -> 5122740.2 | J28: 200000 | K28: 0.2 | L28: =I28*K28 -> 1024548 | M28: =J28+L28 -> 1224548 | N28: =F28+G28+H28+M28 -> 1565655.9 | O28: =E28-N28 -> 3898192.1 | P28: =IF(O28<300000,0.07*O28,21000) -> 21000 | Q28: =IF((O28-300000)<0,0,IF((O28-300000)<300000,0.11*(O28-300000),33000)) -> 33000 | R28: =IF((O28-600000)<0,0,IF((O28-600000)<500000,0.15*(O28-600000),75000)) -> 75000 | S28: =IF((O28-1100000)<0,0,IF((O28-1100000)<500000,0.19*(O28-1100000),95000)) -> 95000 | T28: =IF((O28-1600000)<0,0,IF((O28-1600000)<1600000,0.21*(O28-1600000),336000)) -> 336000 | U28: =24%*(O28-3200000) -> 167566.11 | V28: =P28+Q28+R28+S28+T28+U28 -> 727566.11 | W28: 12 | X28: =V28/W28 -> 60630.509 | Z28: =X28 -> 60630.509 | AA28: 45772.313 | AB28: =Z28-AA28 -> 14858.196
A29: 26 | B29: ABDULRAHMAN A SULAIMAN | C29: 407016.17 | D29: 12 | E29: =C29*D29 -> 4884194 | G29: 333135.52 | I29: =E29-F29-G29-H29 -> 4551058.5 | J29: 200000 | K29: 0.2 | L29: =I29*K29 -> 910211.7 | M29: =J29+L29 -> 1110211.7 | N29: =F29+G29+H29+M29 -> 1443347.2 | O29: =E29-N29 -> 3440846.8 | P29: =IF(O29<300000,0.07*O29,21000) -> 21000 | Q29: =IF((O29-300000)<0,0,IF((O29-300000)<300000,0.11*(O29-300000),33000)) -> 33000 | R29: =IF((O29-600000)<0,0,IF((O29-600000)<500000,0.15*(O29-600000),75000)) -> 75000 | S29: =IF((O29-1100000)<0,0,IF((O29-1100000)<500000,0.19*(O29-1100000),95000)) -> 95000 | T29: =IF((O29-1600000)<0,0,IF((O29-1600000)<1600000,0.21*(O29-1600000),336000)) -> 336000 | U29: =24%*(O29-3200000) -> 57803.228 | V29: =P29+Q29+R29+S29+T29+U29 -> 617803.23 | W29: 12 | X29: =V29/W29 -> 51483.602 | Z29: =X29 -> 51483.602 | AA29: 37921.501 | AB29: =Z29-AA29 -> 13562.102
A30: 27 | B30: DARE SHEU MAGBON | C30: 398711.67 | D30: 12 | E30: =C30*D30 -> 4784540 | G30: 325163.2 | I30: =E30-F30-G30-H30 -> 4459376.8 | J30: 200000 | K30: 0.2 | L30: =I30*K30 -> 891875.36 | M30: =J30+L30 -> 1091875.4 | N30: =F30+G30+H30+M30 -> 1417038.6 | O30: =E30-N30 -> 3367501.4 | P30: =IF(O30<300000,0.07*O30,21000) -> 21000 | Q30: =IF((O30-300000)<0,0,IF((O30-300000)<300000,0.11*(O30-300000),33000)) -> 33000 | R30: =IF((O30-600000)<0,0,IF((O30-600000)<500000,0.15*(O30-600000),75000)) -> 75000 | S30: =IF((O30-1100000)<0,0,IF((O30-1100000)<500000,0.19*(O30-1100000),95000)) -> 95000 | T30: =IF((O30-1600000)<0,0,IF((O30-1600000)<1600000,0.21*(O30-1600000),336000)) -> 336000 | U30: =24%*(O30-3200000) -> 40200.346 | V30: =P30+Q30+R30+S30+T30+U30 -> 600200.35 | W30: 12 | X30: =V30/W30 -> 50016.695 | Z30: =X30 -> 50016.695 | AA30: 36790.688 | AB30: =Z30-AA30 -> 13226.007
A31: 28 | B31: ABUBAKAR SULAIMAN SODEEQ | C31: 398711.67 | D31: 12 | E31: =C31*D31 -> 4784540 | G31: 325163.2 | I31: =E31-F31-G31-H31 -> 4459376.8 | J31: 200000 | K31: 0.2 | L31: =I31*K31 -> 891875.36 | M31: =J31+L31 -> 1091875.4 | N31: =F31+G31+H31+M31 -> 1417038.6 | O31: =E31-N31 -> 3367501.4 | P31: =IF(O31<300000,0.07*O31,21000) -> 21000 | Q31: =IF((O31-300000)<0,0,IF((O31-300000)<300000,0.11*(O31-300000),33000)) -> 33000 | R31: =IF((O31-600000)<0,0,IF((O31-600000)<500000,0.15*(O31-600000),75000)) -> 75000 | S31: =IF((O31-1100000)<0,0,IF((O31-1100000)<500000,0.19*(O31-1100000),95000)) -> 95000 | T31: =IF((O31-1600000)<0,0,IF((O31-1600000)<1600000,0.21*(O31-1600000),336000)) -> 336000 | U31: =24%*(O31-3200000) -> 40200.346 | V31: =P31+Q31+R31+S31+T31+U31 -> 600200.35 | W31: 12 | X31: =V31/W31 -> 50016.695 | Z31: =X31 -> 50016.695 | AA31: 36790.688 | AB31: =Z31-AA31 -> 13226.007
A32: 29 | B32: JIMOH ADEBAYO ZAKA | C32: 415320.67 | D32: 12 | E32: =C32*D32 -> 4983848 | G32: 341107.84 | I32: =E32-F32-G32-H32 -> 4642740.2 | J32: 200000 | K32: 0.2 | L32: =I32*K32 -> 928548.03 | M32: =J32+L32 -> 1128548 | N32: =F32+G32+H32+M32 -> 1469655.9 | O32: =E32-N32 -> 3514192.1 | P32: =IF(O32<300000,0.07*O32,21000) -> 21000 | Q32: =IF((O32-300000)<0,0,IF((O32-300000)<300000,0.11*(O32-300000),33000)) -> 33000 | R32: =IF((O32-600000)<0,0,IF((O32-600000)<500000,0.15*(O32-600000),75000)) -> 75000 | S32: =IF((O32-1100000)<0,0,IF((O32-1100000)<500000,0.19*(O32-1100000),95000)) -> 95000 | T32: =IF((O32-1600000)<0,0,IF((O32-1600000)<1600000,0.21*(O32-1600000),336000)) -> 336000 | U32: =24%*(O32-3200000) -> 75406.111 | V32: =P32+Q32+R32+S32+T32+U32 -> 635406.11 | W32: 12 | X32: =V32/W32 -> 52950.509 | Z32: =X32 -> 52950.509 | AA32: 39052.313 | AB32: =Z32-AA32 -> 13898.196
... A34: 32 | B34: MOHAMMED BELLO | C34: 398711.67 | D34: 12 | E34: =C34*D34 -> 4784540 | G34: 341107.84 | I34: =E34-F34-G34-H34 -> 4443432.2 | J34: 200000 | K34: 0.2 | L34: =I34*K34 -> 888686.43 | M34: =J34+L34 -> 1088686.4 | N34: =F34+G34+H34+M34 -> 1429794.3 | O34: =E34-N34 -> 3354745.7 | P34: =IF(O34<300000,0.07*O34,21000) -> 21000 | Q34: =IF((O34-300000)<0,0,IF((O34-300000)<300000,0.11*(O34-300000),33000)) -> 33000 | R34: =IF((O34-600000)<0,0,IF((O34-600000)<500000,0.15*(O34-600000),75000)) -> 75000 | S34: =IF((O34-1100000)<0,0,IF((O34-1100000)<500000,0.19*(O34-1100000),95000)) -> 95000 | T34: =IF((O34-1600000)<0,0,IF((O34-1600000)<1600000,0.21*(O34-1600000),336000)) -> 336000 | U34: =24%*(O34-3200000) -> 37138.975 | V34: =P34+Q34+R34+S34+T34+U34 -> 597138.97 | W34: 12 | X34: =V34/W34 -> 49761.581 | Z34: =X34 -> 49761.581 | AA34: 36790.688 | AB34: =Z34-AA34 -> 12970.893
A35: 33 | B35: HARUNA JIBRIL AMEH | C35: 351910.75 | D35: 12 | E35: =C35*D35 -> 4222929 | G35: 289834.32 | I35: =E35-F35-G35-H35 -> 3933094.7 | J35: 200000 | K35: 0.2 | L35: =I35*K35 -> 786618.94 | M35: =J35+L35 -> 986618.94 | N35: =F35+G35+H35+M35 -> 1276453.3 | O35: =E35-N35 -> 2946475.7 | P35: =IF(O35<300000,0.07*O35,21000) -> 21000 | Q35: =IF((O35-300000)<0,0,IF((O35-300000)<300000,0.11*(O35-300000),33000)) -> 33000 | R35: =IF((O35-600000)<0,0,IF((O35-600000)<500000,0.15*(O35-600000),75000)) -> 75000 | S35: =IF((O35-1100000)<0,0,IF((O35-1100000)<500000,0.19*(O35-1100000),95000)) -> 95000 | T35: =IF((O35-1600000)<0,0,IF((O35-1600000)<1600000,0.21*(O35-1600000),336000)) -> 282759.91 | V35: =P35+Q35+R35+S35+T35+U35 -> 506759.91 | W35: 12 | X35: =V35/W35 -> 42229.992 | Z35: =X35 -> 42229.992 | AA35: 30259.166 | AB35: =Z35-AA35 -> 11970.827
A36: 34 | B36: RAMATU IBRAHIM ABDULRAHEEM | C36: 344900.83 | D36: 12 | E36: =C36*D36 -> 4138810 | G36: 283104.8 | I36: =E36-F36-G36-H36 -> 3855705.2 | J36: 200000 | K36: 0.2 | L36: =I36*K36 -> 771141.04 | M36: =J36+L36 -> 971141.04 | N36: =F36+G36+H36+M36 -> 1254245.8 | O36: =E36-N36 -> 2884564.2 | P36: =IF(O36<300000,0.07*O36,21000) -> 21000 | Q36: =IF((O36-300000)<0,0,IF((O36-300000)<300000,0.11*(O36-300000),33000)) -> 33000 | R36: =IF((O36-600000)<0,0,IF((O36-600000)<500000,0.15*(O36-600000),75000)) -> 75000 | S36: =IF((O36-1100000)<0,0,IF((O36-1100000)<500000,0.19*(O36-1100000),95000)) -> 95000 | T36: =IF((O36-1600000)<0,0,IF((O36-1600000)<1600000,0.21*(O36-1600000),336000)) -> 269758.47 | V36: =P36+Q36+R36+S36+T36+U36 -> 493758.47 | W36: 12 | X36: =V36/W36 -> 41146.539 | Z36: =X36 -> 41146.539 | AA36: 29305.196 | AB36: =Z36-AA36 -> 11841.344
B38: INTERNAL AUDIT
B39: OSANAIYE DAVID AKINYEMI | C39: 1847106.4 | D39: 12 | E39: =C39*D39 -> 22165277 | G39: 1677222.2 | I39: =E39-F39-G39-H39 -> 20488055 | J39: 200000 | K39: 0.2 | L39: =I39*K39 -> 4097611 | M39: =J39+L39 -> 4297611 | N39: =F39+G39+H39+M39 -> 5974833.1 | O39: =E39-N39 -> 16190444 | P39: =IF(O39<300000,0.07*O39,21000) -> 21000 | Q39: =IF((O39-300000)<0,0,IF((O39-300000)<300000,0.11*(O39-300000),33000)) -> 33000 | R39: =IF((O39-600000)<0,0,IF((O39-600000)<500000,0.15*(O39-600000),75000)) -> 75000 | S39: =IF((O39-1100000)<0,0,IF((O39-1100000)<500000,0.19*(O39-1100000),95000)) -> 95000 | T39: =IF((O39-1600000)<0,0,IF((O39-1600000)<1600000,0.21*(O39-1600000),336000)) -> 336000 | U39: =24%*(O39-3200000) -> 3117706.5 | V39: =P39+Q39+R39+S39+T39+U39 -> 3677706.5 | W39: 12 | X39: =V39/W39 -> 306475.54 | Z39: =X39 -> 306475.54 | AA39: 251472.25 | AB39: =Z39-AA39 -> 55003.297
B40: JAMILA ABDUL | C40: 441140.67 | D40: 12 | E40: =C40*D40 -> 5293688 | G40: 365895.04 | I40: =E40-F40-G40-H40 -> 4927793 | J40: 200000 | K40: 0.2 | L40: =I40*K40 -> 985558.59 | M40: =J40+L40 -> 1185558.6 | N40: =F40+G40+H40+M40 -> 1551453.6 | O40: =E40-N40 -> 3742234.4 | P40: =IF(O40<300000,0.07*O40,21000) -> 21000 | Q40: =IF((O40-300000)<0,0,IF((O40-300000)<300000,0.11*(O40-300000),33000)) -> 33000 | R40: =IF((O40-600000)<0,0,IF((O40-600000)<500000,0.15*(O40-600000),75000)) -> 75000 | S40: =IF((O40-1100000)<0,0,IF((O40-1100000)<500000,0.19*(O40-1100000),95000)) -> 95000 | T40: =IF((O40-1600000)<0,0,IF((O40-1600000)<1600000,0.21*(O40-1600000),336000)) -> 336000 | U40: =24%*(O40-3200000) -> 130136.25 | V40: =P40+Q40+R40+S40+T40+U40 -> 690136.25 | W40: 12 | X40: =V40/W40 -> 57511.354 | Z40: =X40 -> 57511.354 | AA40: 42537.332 | AB40: =Z40-AA40 -> 14974.022
