Workbook

Sheet JUNE 2023
A1: NATIONAL INSTITUTE FOR LEGISLATIVE AND DEMOCRATIC STUDIES | H1: ='[1]FEB 08'!F8/'[1]FEB 08'!Q8 -> 0.3
A2: STAFF PAYROLL FOR THE MONTH OF MAY 2023
E3: ='[1]FEB 08'!E11/'[1]FEB 08'!M11 -> #REF! | H3: ='[1]FEB 08'!F11/'[1]FEB 08'!Q11 -> #REF!
B4: STAFF NAME | C4: DESIGNATION | D4: GRADE LEVEL | E4: BASIC SALARY | F4: ALLCE/ AREARS | G4: RENT | H4: UTILITY | I4: DOMESTIC | J4: ENTERT. | K4: FURNIT. | L4: FUEL | M4: ALLOWANCE | N4: ALLOWANCE | O4: ALLCE | P4: ALLCE | Q4: DUTY ALLCE | R4: GROSS SALARY | S4: AUCTION | T4: COOP CONTR/SPEC SAVINGS | U4: COOP. LOAN RECOVERY | V4: NHF DED. | W4: PAYE | X4: TOTAL DEDUCTION | Y4: MAY, 2023 | Z4: JUNE, 2023
E5: N | G5: N | H5: N | I5: N | J5: N | K5: N | L5: N | M5: N | N5: N | O5: N | P5: N | Q5: N | R5: N | S5: N | T5: N | U5: N | V5: N | W5: N | X5: N | Y5: N | Z5: N
A6: S/N | B6: DG'S OFFICE
A7: 1 | B7: PROF. ABUBAKAR O. SULAIMAN | C7: DIRECTOR GENERAL | D7: CONSOL | E7: 160488.75 | G7: 320977.5 | H7: 48146.63 | I7: 120366.57 | J7: 72219.94 | K7: 0 | L7: 120366.57 | M7: =250000 -> 250000 | O7: 16048.88 | P7: 25000 | Q7: 25235 | R7: =Q7+P7+O7+N7+M7+L7+K7+J7+I7+H7+G7+F7+E7 -> 1158849.8 | W7: 201165.84 | X7: =W7+V7+U7+T7+S7 -> 201165.84 | Y7: 957684 | Z7: =R7-X7 -> 957684
A8: 2 | B8: DR JAKE DABANG DAN AZUMI | C8: DEPUTY DIR. TECHNICAL | D8: 16(9) | E8: =42653.17 -> 42653.17 | G8: =E8*300% -> 127959.51 | H8: =E8*7.5% -> 3198.9877 | I8: 40122.19 | J8: =E8*50% -> 21326.585 | K8: =E8*350% -> 149286.1 | L8: =E8*100% -> 42653.17 | M8: =180000 -> 180000 | O8: =E8*10% -> 4265.317 | P8: 20000 | Q8: 150000 | R8: =Q8+P8+O8+N8+M8+L8+K8+J8+I8+H8+G8+F8+E8 -> 781465.02 | V8: 1066.3293 | W8: 128510.39 | X8: =W8+V8+U8+T8+S8 -> 129576.72 | Y8: 651888.3 | Z8: =R8-X8 -> 651888.3
A9: 3 | B9: DR ABDULSALAM NASIRU NAEEM | C9: SA ACADEMICS | D9: 16(9) | E9: =42653.17 -> 42653.17 | G9: =E9*300% -> 127959.51 | H9: =E9*7.5% -> 3198.9877 | I9: 40122.19 | J9: =E9*50% -> 21326.585 | K9: =E9*350% -> 149286.1 | L9: =E9*100% -> 42653.17 | M9: =180000 -> 180000 | O9: =E9*10% -> 4265.317 | P9: 20000 | Q9: =100000 -> 100000 | R9: 0 | W9: 0 | X9: =W9+V9+U9+T9+S9 -> 0 | Y9: 612357.07 | Z9: =R9-X9 -> 0
A10: 4 | B10: RAHEEM USMAN AYIGORO | C10: SA-INFRASTRUCTURE | D10: 16 (9) | E10: =42653.17 -> 42653.17 | G10: =E10*300% -> 127959.51 | H10: =E10*7.5% -> 3198.9877 | I10: 40122.19 | J10: =E10*50% -> 21326.585 | K10: =E10*350% -> 149286.1 | L10: =E10*100% -> 42653.17 | N10: =90000 -> 90000 | O10: =E10*10% -> 4265.317 | P10: 20000 | Q10: 0 | R10: =Q10+P10+O10+N10+M10+L10+K10+J10+I10+H10+G10+F10+E10 -> 541465.02 | T10: =100000 -> 100000 | W10: 82627.951 | X10: =W10+V10+U10+T10+S10 -> 182627.95 | Y10: 358837.07 | Z10: =R10-X10 -> 358837.07
A11: 5 | B11: MARIAM MOHAMMED BELLO | C11: SA- SPECIAL DUTIES | D11: 16(8) | E11: 41157.69 | G11: =E11*300% -> 123473.07 | H11: =E11*7.5% -> 3086.8268 | I11: 40122.19 | J11: =E11*50% -> 20578.845 | K11: =E11*350% -> 144051.92 | L11: =E11*100% -> 41157.69 | N11: =90000 -> 90000 | O11: =E11*10% -> 4115.769 | P11: 15000 | Q11: =100000+100000 -> 200000 | R11: =Q11+P11+O11+N11+M11+L11+K11+J11+I11+H11+G11+F11+E11 -> 722744 | W11: 117433.51 | X11: =W11+V11+U11+T11+S11 -> 117433.51 | Y11: 605310.49 | Z11: =R11-X11 -> 605310.49
A12: 6 | B12: AKINSANMI ADEJOKE OLUKEMI | C12: DEPUTY DIR. INFO/PROTOCOL | D12: 16(8) | E12: =41157.69 -> 41157.69 | G12: =E12*300% -> 123473.07 | H12: =E12*7.5% -> 3086.8268 | I12: 40122.19 | J12: =E12*50% -> 20578.845 | K12: =E12*350% -> 144051.92 | L12: =E12*100% -> 41157.69 | N12: =80000+10000 -> 90000 | O12: =E12*10% -> 4115.769 | P12: 20000 | Q12: =100000 -> 100000 | R12: =Q12+P12+O12+N12+M12+L12+K12+J12+I12+H12+G12+F12+E12 -> 627744 | T12: =0 -> 0 | U12: 0 | V12: 1028.9423 | W12: 99032.678 | X12: =W12+V12+U12+T12+S12 -> 100061.62 | Y12: 527682.38 | Z12: =R12-X12 -> 527682.38
A13: 7 | B13: DR IKEME ARTHUR J.O | C13: DEPUTY DIRECTOR, M&E | D13: 16(8) | E13: =41157.69 -> 41157.69 | G13: =E13*300% -> 123473.07 | H13: =E13*7.5% -> 3086.8268 | I13: 40122.19 | J13: =E13*50% -> 20578.845 | K13: =E13*350% -> 144051.92 | L13: =E13*100% -> 41157.69 | N13: =80000+10000 -> 90000 | O13: =E13*10% -> 4115.769 | P13: 20000 | Q13: 0 | R13: =Q13+P13+O13+N13+M13+L13+K13+J13+I13+H13+G13+F13+E13 -> 527744 | T13: =50000 -> 50000 | U13: =160416.67 -> 160416.67 | V13: 1028.9423 | W13: 79832.678 | X13: =W13+V13+U13+T13+S13 -> 291278.29 | Y13: 236465.71 | Z13: =R13-X13 -> 236465.71
A14: 8 | B14: MOSHOOD M. OLALERE | C14: DEPUTY DIR. GENERAL SERVICE | D14: 16(8) | E14: =41157.69 -> 41157.69 | G14: =E14*300% -> 123473.07 | H14: =E14*7.5% -> 3086.8268 | I14: 40122.19 | J14: =E14*50% -> 20578.845 | K14: =E14*350% -> 144051.92 | L14: =E14*100% -> 41157.69 | N14: =80000+10000 -> 90000 | O14: =E14*10% -> 4115.769 | P14: 20000 | Q14: 0 | R14: =Q14+P14+O14+N14+M14+L14+K14+J14+I14+H14+G14+F14+E14 -> 527744 | T14: =20000 -> 20000 | U14: =179017.51 -> 179017.51 | V14: 1028.9423 | W14: 79832.678 | X14: =W14+V14+U14+T14+S14 -> 279879.13 | Y14: 247864.87 | Z14: =R14-X14 -> 247864.87
A15: 9 | B15: ANDRAWUS MUSA | C15: ASST. DIRECTOR, STORES | D15: 15(9) | E15: 33507.5 | G15: =E15*300% -> 100522.5 | H15: =E15*7.5% -> 2513.0625 | I15: =40122.19 -> 40122.19 | J15: =E15*50% -> 16753.75 | K15: =E15*350% -> 117276.25 | L15: =E15*100% -> 33507.5 | N15: =80000 -> 80000 | O15: =E15*10% -> 3350.75 | P15: 20000 | Q15: 0 | R15: =SUM(E15:Q15) -> 447553.5 | T15: =50000-40000 -> 10000 | U15: =90000+110000 -> 200000 | V15: 837.6875 | W15: 64436.103 | X15: =W15+V15+U15+T15+S15 -> 275273.79 | Y15: 172279.71 | Z15: =R15-X15 -> 172279.71
A16: 10 | B16: AYOBOLU OLAJIDE OLUFUNSHO | C16: ASST.DIR., INFORMATION | D16: 15 (8) | E16: 32263.2 | G16: =E16*300% -> 96789.6 | H16: =E16*7.5% -> 2419.74 | I16: 40122.19 | J16: =E16*50% -> 16131.6 | K16: =E16*350% -> 112921.2 | L16: =E16*100% -> 32263.2 | N16: =80000 -> 80000 | O16: =E16*10% -> 3226.32 | P16: 20000 | Q16: 0 | R16: =Q16+P16+O16+N16+M16+L16+K16+J16+I16+H16+G16+F16+E16 -> 436137.05 | T16: =50000 -> 50000 | U16: =59583.33 -> 59583.33 | W16: 62404.98 | X16: =W16+V16+U16+T16+S16 -> 171988.31 | Y16: 264148.74 | Z16: =R16-X16 -> 264148.74
A17: 11 | B17: HUSSEIN EGYE MUSA | C17: CHIEF PROTOCOL OFFICER | D17: 14(10) | E17: 27611.23 | G17: =E17*300% -> 82833.69 | H17: =E17*7.5% -> 2070.8422 | J17: =E17*50% -> 13805.615 | K17: =E17*350% -> 96639.305 | L17: =E17*100% -> 27611.23 | N17: =70000 -> 70000 | O17: =E17*10% -> 2761.123 | P17: 20000 | Q17: 50000 | R17: =Q17+P17+O17+N17+M17+L17+K17+J17+I17+H17+G17+F17+E17 -> 393333.04 | T17: 50000 | U17: =150000 -> 150000 | V17: 0 | W17: 54186.609 | X17: =W17+V17+U17+T17+S17 -> 254186.61 | Y17: 139146.43 | Z17: =R17-X17 -> 139146.43
A18: 12 | B18: DONALD E. MKPANAM | C18: CHIEF ICT OFFICER | D18: 14(10) | E18: 27611.23 | G18: =E18*300% -> 82833.69 | H18: =E18*7.5% -> 2070.8422 | J18: =E18*50% -> 13805.615 | K18: =E18*350% -> 96639.305 | L18: =E18*100% -> 27611.23 | N18: =70000 -> 70000 | O18: =E18*10% -> 2761.123 | P18: 20000 | Q18: 0 | R18: =Q18+P18+O18+N18+M18+L18+K18+J18+I18+H18+G18+F18+E18 -> 343333.04 | V18: 690.28075 | W18: 44734.339 | X18: =W18+V18+U18+T18+S18 -> 45424.62 | Y18: 297908.42 | Z18: =R18-X18 -> 297908.42
A19: 13 | B19: JOY HARUNA MAKERI | C19: RESEARCH FELLOW 1 TRAINING | D19: 14(10) | E19: 27611.23 | G19: =E19*300% -> 82833.69 | H19: =E19*7.5% -> 2070.8422 | J19: =E19*50% -> 13805.615 | K19: =E19*350% -> 96639.305 | L19: =E19*100% -> 27611.23 | M19: =140000 -> 140000 | O19: =E19*10% -> 2761.123 | P19: 20000 | Q19: =50000+100000 -> 150000 | R19: =Q19+P19+O19+N19+M19+L19+K19+J19+I19+H19+G19+F19+E19 -> 563333.04 | W19: 86826.609 | X19: =W19+V19+U19+T19+S19 -> 86826.609 | Y19: 476506.43 | Z19: =R19-X19 -> 476506.43
A20: 14 | B20: ALI ABDULLAHI | C20: CHIEF ICT OFFICER | D20: 14(10) | E20: 27611.23 | G20: =E20*300% -> 82833.69 | H20: =E20*7.5% -> 2070.8422 | I20: 0 | J20: =E20*50% -> 13805.615 | K20: =E20*350% -> 96639.305 | L20: =E20*100% -> 27611.23 | N20: =70000 -> 70000 | O20: =E20*10% -> 2761.123 | P20: 15000 | Q20: =0 -> 0 | R20: =Q20+P20+O20+N20+M20+L20+K20+J20+I20+H20+G20+F20+E20 -> 338333.04 | W20: 44006.617 | X20: =W20+V20+U20+T20+S20 -> 44006.617 | Y20: 294326.42 | Z20: =R20-X20 -> 294326.42
A21: 15 | B21: PERCY TERFA GBAHABO | C21: HEAD, NILDS LIAISON OFFICE | D21: 13(9) | E21: 24741.26 | G21: =E21*300% -> 74223.78 | H21: =E21*7.5% -> 1855.5945 | I21: 0 | J21: =E21*50% -> 12370.63 | K21: =E21*350% -> 86594.41 | L21: =E21*100% -> 24741.26 | M21: =120000 -> 120000 | O21: =E21*10% -> 2474.126 | P21: 15000 | Q21: 0 | R21: =Q21+P21+O21+N21+M21+L21+K21+J21+I21+H21+G21+F21+E21 -> 362001.06 | T21: =50000 -> 50000 | U21: 52500 | W21: 46666.667 | X21: =W21+V21+U21+T21+S21 -> 149166.67 | Y21: 212834.39 | Z21: =R21-X21 -> 212834.39
A22: 16 | B22: HASSANA AHMED IBRAHIM | C22: PA- TO DG | D22: 13 (8) | E22: =23891.12 -> 23891.12 | G22: =E22*300% -> 71673.36 | H22: =E22*7.5% -> 1791.834 | J22: =E22*50% -> 11945.56 | K22: =E22*350% -> 83618.92 | L22: =E22*100% -> 23891.12 | M22: =120000 -> 120000 | O22: =E22*10% -> 2389.112 | P22: 10000 | Q22: =100000 -> 100000 | R22: =Q22+P22+O22+N22+M22+L22+K22+J22+I22+H22+G22+F22+E22 -> 449201.03 | T22: =30000-20000 -> 10000 | U22: =95833.33 -> 95833.33 | V22: 597.278 | W22: 64913.264 | X22: =W22+V22+U22+T22+S22 -> 171343.87 | Y22: 277857.15 | Z22: =R22-X22 -> 277857.15
A23: 17 | B23: CHRISTIAN MADUABUCHI ODO | C23: PRINCIPAL ICT OFFICER | D23: 12(9) | E23: =22837.82 -> 22837.82 | G23: =E23*300% -> 68513.46 | H23: =E23*7.5% -> 1712.8365 | J23: =E23*50% -> 11418.91 | K23: =E23*350% -> 79932.37 | L23: =E23*100% -> 22837.82 | N23: =60000 -> 60000 | O23: =E23*10% -> 2283.782 | P23: 15000 | R23: =Q23+P23+O23+N23+M23+L23+K23+J23+I23+H23+G23+F23+E23 -> 284537 | V23: 570.9455 | W23: 34871.967 | X23: =W23+V23+U23+T23+S23 -> 35442.913 | Y23: 249094.09 | Z23: =R23-X23 -> 249094.09
A24: 18 | B24: ADUGBA RICHARD TERSEER | C24: PRINCIPAL INFO. OFFICER | D24: 12(8) | E24: 21520.88 | G24: =E24*300% -> 64562.64 | H24: =E24*7.5% -> 1614.066 | J24: =E24*50% -> 10760.44 | K24: =E24*350% -> 75323.08 | L24: =E24*100% -> 21520.88 | N24: =60000 -> 60000 | O24: =E24*10% -> 2152.088 | P24: 10000 | R24: =Q24+P24+O24+N24+M24+L24+K24+J24+I24+H24+G24+F24+E24 -> 267454.07 | T24: =20000 -> 20000 | U24: =111833.33 -> 111833.33 | W24: 32008.563 | X24: =W24+V24+U24+T24+S24 -> 163841.89 | Y24: 103612.18 | Z24: =R24-X24 -> 103612.18
A25: 19 | B25: YAKUB OLUWATOYIN USMAN | C25: ASST. ADMIN. OFFICER | D25: 10(9) | E25: 18281.64 | G25: =E25*300% -> 54844.92 | H25: =E25*7.5% -> 1371.123 | J25: =E25*50% -> 9140.82 | K25: =E25*350% -> 63985.74 | L25: =E25*100% -> 18281.64 | N25: =60000 -> 60000 | O25: =E25*10% -> 1828.164 | P25: 10000 | R25: =Q25+P25+O25+N25+M25+L25+K25+J25+I25+H25+G25+F25+E25 -> 237734.05 | T25: 0 | U25: 0 | W25: 27105.987 | X25: =W25+V25+U25+T25+S25 -> 27105.987 | Y25: 210628.06 | Z25: =R25-X25 -> 210628.06
A26: 20 | B26: ELIZABETH OGECHUKWU ONYEAKU | C26: ICT OFFICER | D26: 9(8) | E26: 14736.14 | G26: 44208.42 | H26: 1105.2105 | J26: 7368.07 | K26: 51576.49 | L26: 14736.14 | N26: 60000 | O26: 1473.614 | P26: 10000 | R26: 205204.08 | T26: 10000 | U26: =20000 -> 20000 | W26: 21640.953 | X26: =W26+V26+U26+T26+S26 -> 51640.953 | Y26: 153563.13 | Z26: =R26-X26 -> 153563.13
A27: 21 | B27: VICTOR ASUKWO | C27: ICT OFFICER | D27: 9(8) | E27: =15188.67 -> 15188.67 | G27: =E27*300% -> 45566.01 | H27: =E27*7.5% -> 1139.1502 | J27: =E27*50% -> 7594.335 | K27: =E27*350% -> 53160.345 | L27: =E27*100% -> 15188.67 | N27: =50000+10000 -> 60000 | O27: =E27*10% -> 1518.867 | P27: 10000 | R27: =Q27+P27+O27+N27+M27+L27+K27+J27+I27+H27+G27+F27+E27 -> 209356.05 | W27: 22338.483 | X27: =W27+V27+U27+T27+S27 -> 22338.483 | Y27: 187017.56 | Z27: =R27-X27 -> 187017.56
A28: 22 | B28: IJEOMA NKOLIKWA | C28: STORES OFFICER | D28: 9(8) | E28: =15188.67 -> 15188.67 | G28: =E28*300% -> 45566.01 | H28: =E28*7.5% -> 1139.1502 | J28: =E28*50% -> 7594.335 | K28: =E28*350% -> 53160.345 | L28: =E28*100% -> 15188.67 | N28: =50000+10000 -> 60000 | O28: =E28*10% -> 1518.867 | P28: 10000 | R28: =SUM(E28:Q28) -> 209356.05 | T28: =10000 -> 10000 | W28: 22338.483 | X28: =W28+V28+U28+T28+S28 -> 32338.483 | Y28: 177017.56 | Z28: =R28-X28 -> 177017.56
A29: 23 | B29: ABDULRAHMAN A SULAIMAN | C29: ASSISTANT STORES OFFICER | D29: 8(10) | E29: 13492.21 | G29: =E29*300% -> 40476.63 | H29: =E29*7.5% -> 1011.9157 | J29: =E29*50% -> 6746.105 | K29: =E29*350% -> 47222.735 | L29: =E29*100% -> 13492.21 | N29: =50000 -> 50000 | O29: =E29*10% -> 1349.221 | P29: 10000 | R29: =SUM(E29:Q29) -> 183791.03 | T29: =20000 -> 20000 | U29: =17500 -> 17500 | W29: 18102.903 | X29: =W29+V29+U29+T29+S29 -> 55602.903 | Y29: 128188.12 | Z29: =R29-X29 -> 128188.12
A30: 24 | B30: DARE SHEU MAGBON | C30: ASSIST. PG | D30: 8(10) | E30: 13492.21 | G30: =E30*300% -> 40476.63 | H30: =E30*7.5% -> 1011.9157 | J30: =E30*50% -> 6746.105 | K30: =E30*350% -> 47222.735 | L30: =E30*100% -> 13492.21 | N30: =50000 -> 50000 | O30: =E30*10% -> 1349.221 | P30: 10000 | R30: =SUM(E30:Q30) -> 183791.03 | T30: =30000+20000 -> 50000 | U30: 0 | W30: 18102.903 | X30: =W30+V30+U30+T30+S30 -> 68102.903 | Y30: 115688.12 | Z30: =R30-X30 -> 115688.12
A31: 25 | B31: JIMOH ADEBAYO ZAKA | C31: ASST. OFFICER/COMM | D31: 9(8) | E31: 15188.67 | G31: =E31*300% -> 45566.01 | H31: =E31*7.5% -> 1139.1502 | J31: =E31*50% -> 7594.335 | K31: =E31*350% -> 53160.345 | L31: =E31*100% -> 15188.67 | N31: =60000 -> 60000 | O31: =E31*10% -> 1518.867 | P31: 10000 | R31: =Q31+P31+O31+N31+M31+L31+K31+J31+I31+H31+G31+F31+E31 -> 209356.05 | T31: =50000 -> 50000 | U31: 50000 | V31: 0 | W31: 22338.483 | X31: =W31+V31+U31+T31+S31 -> 122338.48 | Y31: 87017.565 | Z31: =R31-X31 -> 87017.565
A32: 26 | B32: MOHAMMED BELLO | C32: PROTOCOL ASSISTANT | D32: 8(8) | E32: =12732 -> 12732 | G32: =E32*300% -> 38196 | H32: =E32*7.5% -> 954.9 | J32: =E32*50% -> 6366 | K32: =E32*350% -> 44562 | L32: =E32*100% -> 12732 | N32: =50000 -> 50000 | O32: =E32*10% -> 1273.2 | P32: 10000 | R32: =SUM(E32:Q32) -> 176816.1 | T32: =0 -> 0 | U32: =26666.67 -> 26666.67 | W32: 17042.714 | X32: =W32+V32+U32+T32+S32 -> 43709.384 | Y32: 133106.72 | Z32: =R32-X32 -> 133106.72
A33: 27 | B33: SULEIMAN ABUBAKAR SODEEQ | C33: ASST. ADMIN. OFFICER | D33: 8(8) | E33: =12732 -> 12732 | G33: =E33*300% -> 38196 | H33: =E33*7.5% -> 954.9 | J33: =E33*50% -> 6366 | K33: =E33*350% -> 44562 | L33: =E33*100% -> 12732 | N33: =50000 -> 50000 | O33: =E33*10% -> 1273.2 | P33: 10001 | R33: =SUM(E33:Q33) -> 176817.1 | T33: =0 -> 0 | W33: 17042.866 | X33: =W33+V33+U33+T33+S33 -> 17042.866 | Y33: 159774.23 | Z33: =R33-X33 -> 159774.23
A34: 28 | B34: HARUNA JIBRIL A. | C34: ASST. ADMIN. OFFICER | D34: 8(8) | E34: =12732 -> 12732 | G34: =E34*300% -> 38196 | H34: =E34*7.5% -> 954.9 | J34: =E34*50% -> 6366 | K34: =E34*350% -> 44562 | L34: =E34*100% -> 12732 | N34: =50000 -> 50000 | O34: =E34*10% -> 1273.2 | P34: 10002 | R34: =SUM(E34:Q34) -> 176818.1 | T34: 20000 | W34: 17043.018 | X34: =W34+V34+U34+T34+S34 -> 37043.018 | Y34: 139775.08 | Z34: =R34-X34 -> 139775.08
A35: 29 | B35: SHOLAGBERU T. SOFIAT | C35: ASST. ACCOUNT. OFFICER | D35: 8(7) | E35: 12351.94 | G35: 37055.82 | H35: 926.3955 | J35: 6175.97 | K35: 43231.79 | L35: 12351.94 | N35: 50000 | O35: 1235.194 | P35: 10000 | R35: 173329.05 | T35: 10000 | U35: 63888.89 | V35: 0 | W35: 16512.682 | X35: =W35+V35+U35+T35+S35 -> 90401.572 | Y35: 82927.477 | Z35: =R35-X35 -> 82927.477
B36: TOTAL | C36: 29 | E36: =SUM(E7:E35) -> 878401.87 | F36: =SUM(F7:F35) -> 0 | G36: =SUM(G7:G35) -> 2474716.9 | H36: =SUM(H7:H35) -> 101990.11 | I36: =SUM(I7:I35) -> 481466.28 | J36: =SUM(J7:J35) -> 431176.5 | K36: =SUM(K7:K35) -> 2512695.9 | L36: =SUM(L7:L35) -> 838279.69 | ... X36: =SUM(X7:X35) -> 3267190 | Y36: 8260507.5 | Z36: =SUM(Z7:Z35) -> 7648150.4
B38: INTERNAL AUDIT
A39: 1 | B39: OSANAIYE DAVID AKINYEMI | C39: DIRECTOR INTERNAL AUDIT | D39: 17(9) | E39: 81740.02 | G39: =E39*300% -> 245220.06 | H39: =E39*7.5% -> 6130.5015 | I39: 80244.38 | J39: =E39*50% -> 40870.01 | K39: =E39*350% -> 286090.07 | L39: =E39*100% -> 81740.02 | N39: =100000 -> 100000 | O39: =E39*10% -> 8174.002 | P39: 20000 | R39: =SUM(E39:Q39) -> 950209.06 | S39: ='JUNE 2023'!F194 -> 0 | T39: =100000 -> 100000 | U39: ='[2]OCT 2022 '!$D$182 -> 175000 | W39: 161106.81 | X39: =W39+V39+U39+T39+S39 -> 436106.81 | Y39: 514102.26 | Z39: =R39-X39 -> 514102.26
A40: 2 | B40: JAMILA ABDUL | C40: AUDITOR II | D40: 8(7) | E40: 12351.94 | G40: =E40*300% -> 37055.82 | H40: =E40*7.5% -> 926.3955 | J40: =E40*50% -> 6175.97 | K40: =E40*350% -> 43231.79 | L40: =E40*100% -> 12351.94 | N40: =50000 -> 50000 | O40: =E40*10% -> 1235.194 | P40: 10000 | R40: =(Q40+P40+O40+N40+M40+L40+K40+J40+I40+H40+G40+F40+E40) -> 173329.05 | T40: =20000 -> 20000 | V40: 0 | W40: 16512.682 | X40: =W40+V40+U40+T40+S40 -> 36512.682 | Y40: 136816.37 | Z40: =R40-X40 -> 136816.37
C41: 2 | E41: =SUM(E39:E40) -> 94091.96 | G41: =SUM(G39:G40) -> 282275.88 | H41: =SUM(H39:H40) -> 7056.897 | I41: =SUM(I39:I40) -> 80244.38 | J41: =SUM(J39:J40) -> 47045.98 | K41: =SUM(K39:K40) -> 329321.86 | L41: =SUM(L39:L40) -> 94091.96 | N41: =SUM(N39:N40) -> 150000 | O41: =SUM(O39:O40) -> 9409.196 | P41: =SUM(P39:P40) -> 30000 | R41: =SUM(R39:R40) -> 1123538.1 | T41: =SUM(T39:T40) -> 120000 | U41: =SUM(U39:U40) -> 175000 | V41: =SUM(V39:V40) -> 0 | W41: =SUM(W39:W40) -> 177619.49 | X41: =SUM(X39:X40) -> 472619.49 | Y41: 650918.62 | Z41: =SUM(Z39:Z40) -> 650918.62
...

Sheet MEMO 1
A2: NATIONAL INSTITUTE FOR LEGISLATIVE AND DEMOCRATIC STUDIES
A3: INTERNAL MEMO
A4: FROM : DEPUTY DIRECTOR, FINANCE AND ACCOUNTS
A5: THRU: DIRECTOR, FINANCE AND ACCOUNTS
A6: TO: DG
A7: 29TH JANUARY , 2021
A9: SUBJECT: PAYROLL FOR THE MONTH OF JANUARY, 2021
A10: Find below the details of NILDS Staff Payroll for the month of January, 2021
A13: TO: | C13: DIRECTOR, GENERAL
A14: THRU: | C14: DIRECTOR, FINANCE AND ACCOUNT
A15: FROM: | C15: ASST. DIRECTOR, FINANCE AND ACCOUNTS
A16: DATE: | C16: 26TH JUNE, 2023
A18: SUBJECT: PAYROLL FOR THE MONTH OF JUNE, 2023
A19: Find below the details of NILDS Staff Payroll for the Month of June 2023: | G19: NGN | H19: NGN
A20: GROSS SALARY FOR JUNE, 2023 | H20: ='JUNE 2023'!R192 -> 51005732
A22: DEDUCTIONS
A23: COOP SOCIETY DEDUCTIONS ( CONTR.& SPEC. SAVINGS) | G23: ='JUNE 2023'!T192 -> 4802500
A24: COOP LOAN RECOVERY | G24: ='JUNE 2023'!U192 -> 7041474.5
A25: PAYE DEDUCTIONS | G25: ='JUNE 2023'!W192 -> 6946057.7
A26: NHF DEDUCTIONS | G26: ='JUNE 2023'!V192 -> 23887.071
A27: TOTAL DEDUCTIONS FOR JUNE, 2023 | H27: =G23+G24+G25+G26 -> 18813919
A28: NET PAY AS PER JUNE, 2023 PAYROLL | H28: =H20-H27 -> 32191813
A29: NET PAY AS PER MAY, 2023 PAYROLL | H29: ='JUNE 2023'!Y192 -> 32708405
A30: NET INCREASE/ (DECREASE) IN PAY FOR JUNE, 2023 | H30: =H28-H29 -> -516592.08
A31: ANALYSED AS FOLLOWS:
A32: Effect of Cooperative adjustment for June 2023 | H32: -20000
A33: Net Effect of Stoppage of Payment to Nasiru Naeem Abdulsalam | H33: =612357.08 -> 612357.08
A34: Effect of Removal of 1st 28 days Allowance of Maryam Musa Sada | H34: =560000 -> 560000
A35: Net Effect of Stoppage of payment to Murtala Lawal due to transfer of Service | H35: =83161.66 -> 83161.66
A36: Net effect of Conversion to Permanent Staff of Munirat Jimoh | H36: =-560000+2949.39 -> -557050.61
A37: Net effect of Legislative Allowance to Terfa Abraham & one other | H37: -161876.05
H38: =SUM(H32:H37) -> 516592.08
E40: MAY, 2023 | G40: JUNE, 2023
E41: No. of Staff | F41: N | G41: No. of Staff | H41: N
A42: 1 | B42: Director General's Office | E42: 33 | F42: ='JUNE 2023'!Y36 -> 8260507.5 | G42: ='JUNE 2023'!C36 -> 29 | H42: ='JUNE 2023'!Z36 -> 7648150.4
A43: 2 | B43: Internal Audit | E43: 2 | F43: ='JUNE 2023'!Y41 -> 650918.62 | G43: 2 | H43: ='JUNE 2023'!Z41 -> 650918.62
A44: 3 | B44: Legis. Support Services | E44: 11 | F44: ='JUNE 2023'!Y56 -> 2852419.9 | G44: ='JUNE 2023'!C56 -> 12 | H44: ='JUNE 2023'!Z56 -> 2852419.9
A45: 4 | B45: Legal Services | E45: 2 | F45: ='JUNE 2023'!Y61 -> 928634.33 | G45: ='JUNE 2023'!C61 -> 2 | H45: ='JUNE 2023'!Z61 -> 928634.33
A46: 5 | B46: Democracy and Governance | E46: 13 | F46: ='JUNE 2023'!Y77 -> 3316351.5 | G46: ='JUNE 2023'!C77 -> 13 | H46: ='JUNE 2023'!Z77 -> 3316351.5
A47: 6 | B47: Studies | E47: 4 | F47: ='JUNE 2023'!Y85 -> 1848547.3 | G47: ='JUNE 2023'!C85 -> 5 | H47: ='JUNE 2023'!Z85 -> 1848547.3
...

Sheet Sallah Welfare April 2023
A1: NATIONAL INSTITUTE FOR LEGISLATIVE AND DEMOCRATIC STUDIES
A2: STAFF WELFARE APRIL, 2023
B4: STAFF NAME | C4: DESIGNATION | D4: GRADE LEVEL | E4: AMOUNT
E5: N
A6: S/N | B6: DG'S OFFICE
A7: 1 | B7: PROF. ABUBAKAR O. SULAIMAN | C7: DIRECTOR GENERAL | D7: CONSOL | E7: 450000
A8: 2 | B8: DR JAKE DABANG DAN AZUMI | C8: DEPUTY DIR. TTECHNICAL | D8: 16(9) | E8: 150000
A9: 3 | B9: DR ABDULSALAM NASIRU NAEEM | C9: SA ACADEMICS | D9: 16(9) | E9: 150000
A10: 4 | B10: RAHEEM USMAN AYIGORO | C10: SA-INFRASTRUCTURE | D10: 16 (9) | E10: 150000
A11: 5 | B11: MARIAM MOHAMMED BELLO | C11: SA- SPECIAL DUTIES | D11: 16(8) | E11: 150000
A12: 6 | B12: AKINSANMI ADEJOKE OLUKEMI | C12: DEPUTY DIR. INFO/PROTOCOL | D12: 16(8) | E12: 150000
A13: 7 | B13: DR IKEME ARTHUR J.O | C13: DEPUTY DIRECTOR, M&E | D13: 16(8) | E13: 150000
A14: 8 | B14: MOSHOOD M. OLALERE | C14: DEPUTY DIR. GENERAL SERVICE | D14: 16(8) | E14: 150000
A15: 9 | B15: ANDRAWUS MUSA | C15: ASST. DIRECTOR, STORES | D15: 15(9) | E15: 105000
A16: 10 | B16: AYOBOLU OLAJIDE OLUFUNSHO | C16: ASST.DIR., INFORMATION | D16: 15 (8) | E16: 105000
A17: 11 | B17: HUSSEIN EGYE MUSA | C17: CHIEF PROTOCOL OFFICER | D17: 14(10) | E17: 75000
A18: 12 | B18: DONALD E. MKPANAM | C18: CHIEF ICT OFFICER | D18: 14(10) | E18: 75000
... A36: 30 | B36: SHOLAGBERU T. SOFIAT | C36: ASST. ACCOUNT. OFFICER | D36: 8(7) | E36: 45000
B37: TOTAL | C37: 30 | E37: =SUM(E7:E36) -> 2790000
B39: INTERNAL AUDIT
A40: 1 | B40: OSANAIYE DAVID AKINYEMI | C40: DIRECTOR INTERNAL AUDIT | D40: 17(9) | E40: 225000
A41: 2 | B41: JAMILA ABDUL | C41: AUDITOR II | D41: 8(7) | E41: 45000
C42: 2 | E42: =SUM(E40:E41) -> 270000
B44: LEG. SUPPORT SEVICES
A45: 1 | B45: PROF. EDOBA BRIGHT OMOREGBE | C45: AG. DLSS | D45: 17(9) | E45: 225000
A46: 2 | B46: DR CLINTON JAJA | C46: SENIOR RESEARCH FELLOW | D46: 15(9) | E46: 105000
A47: 3 | B47: BETHEL UZOMA IHUGBA | C47: SNR RESEARCH FELLOW | D47: 15(9) | E47: 105000
A48: 4 | B48: OGUCHE SAMUEL | C48: SNR RESEARCH FELLOW | D48: 15(9) | E48: 105000
A49: 5 | B49: IBRAHIM USMAN | C49: SNR RESEARCH FELLOW | D49: 15(8) | E49: 105000
A50: 6 | B50: DR MOHAMMED O. AMALI | C50: RESEARCH FELLOW I | D50: 14(10) | E50: 75000
A51: 7 | B51: YAHAYA SHAMSU | C51: RESEARCH FELLOW 1 | D51: 14(10) | E51: 75000
A52: 8 | B52: OFORDEME ADAOBI JULIA | C52: RESEARCH FELLOW 1 | D52: 14(9) | E52: 75000
A53: 9 | B53: DORIS DAKDA AARON | C53: RESEARCH FELLOW II | D53: 13(10) | E53: 75000
A54: 10 | B54: ZAINAB AKINDE | C54: RESEARCH OFFICER | D54: 9(7) | E54: 45000
A55: 11 | B55: ABDULLAHI AHMAD USMAN | C55: RESEARCH OFFICER | D55: 9(7) | E55: 45000
A56: 12 | B56: GUNAT NANSAK MARK | C56: RESEARCH OFFICER | D56: 9(7) | E56: 45000
B57: TOTAL | C57: 12 | E57: =SUM(E45:E56) -> 1080000
B59: LEGAL SERVICES
A60: 1 | B60: DR SHUIBU DANWANKA | C60: DIRECTOR LEGAL SERVICES | D60: 17(9) | E60: 225000
A61: 2 | B61: ABDULSALAM BAKO | C61: MANAGER, LEGAL SERVICES | D61: 15 (8) | E61: 105000
...

Sheet Sallah Welfare June 2023
A1: NATIONAL INSTITUTE FOR LEGISLATIVE AND DEMOCRATIC STUDIES
A2: STAFF WELFARE APRIL, 2023
B4: STAFF NAME | C4: DESIGNATION | D4: GRADE LEVEL | E4: AMOUNT
E5: N
A6: S/N | B6: DG'S OFFICE
A7: 1 | B7: PROF. ABUBAKAR O. SULAIMAN | C7: DIRECTOR GENERAL | D7: CONSOL | E7: 450000
A8: 2 | B8: DR JAKE DABANG DAN AZUMI | C8: DEPUTY DIR. TTECHNICAL | D8: 16(9) | E8: 150000
A9: 3 | B9: DR ABDULSALAM NASIRU NAEEM | C9: SA ACADEMICS | D9: 16(9) | E9: 150000
A10: 4 | B10: RAHEEM USMAN AYIGORO | C10: SA-INFRASTRUCTURE | D10: 16 (9) | E10: 150000
A11: 5 | B11: MARIAM MOHAMMED BELLO | C11: SA- SPECIAL DUTIES | D11: 16(8) | E11: 150000
A12: 6 | B12: AKINSANMI ADEJOKE OLUKEMI | C12: DEPUTY DIR. INFO/PROTOCOL | D12: 16(8) | E12: 150000
A13: 7 | B13: DR IKEME ARTHUR J.O | C13: DEPUTY DIRECTOR, M&E | D13: 16(8) | E13: 150000
A14: 8 | B14: MOSHOOD M. OLALERE | C14: DEPUTY DIR. GENERAL SERVICE | D14: 16(8) | E14: 150000
A15: 9 | B15: ANDRAWUS MUSA | C15: ASST. DIRECTOR, STORES | D15: 15(9) | E15: 105000
A16: 10 | B16: AYOBOLU OLAJIDE OLUFUNSHO | C16: ASST.DIR., INFORMATION | D16: 15 (8) | E16: 105000
A17: 11 | B17: HUSSEIN EGYE MUSA | C17: CHIEF PROTOCOL OFFICER | D17: 14(10) | E17: 75000
A18: 12 | B18: DONALD E. MKPANAM | C18: CHIEF ICT OFFICER | D18: 14(10) | E18: 75000
... A35: 29 | B35: SHOLAGBERU T. SOFIAT | C35: ASST. ACCOUNT. OFFICER | D35: 8(7) | E35: 45000
B36: TOTAL | C36: 29 | E36: =SUM(E7:E35) -> 2745000
B38: INTERNAL AUDIT
A39: 1 | B39: OSANAIYE DAVID AKINYEMI | C39: DIRECTOR INTERNAL AUDIT | D39: 17(9) | E39: 225000
A40: 2 | B40: JAMILA ABDUL | C40: AUDITOR II | D40: 8(7) | E40: 45000
C41: 2 | E41: =SUM(E39:E40) -> 270000
B43: LEG. SUPPORT SEVICES
A44: 1 | B44: PROF. EDOBA BRIGHT OMOREGBE | C44: AG. DLSS | D44: 17(9) | E44: 225000
A45: 2 | B45: DR CLINTON JAJA | C45: SENIOR RESEARCH FELLOW | D45: 15(9) | E45: 105000
A46: 3 | B46: BETHEL UZOMA IHUGBA | C46: SNR RESEARCH FELLOW | D46: 15(9) | E46: 105000
A47: 4 | B47: OGUCHE SAMUEL | C47: SNR RESEARCH FELLOW | D47: 15(9) | E47: 105000
A48: 5 | B48: IBRAHIM USMAN | C48: SNR RESEARCH FELLOW | D48: 15(8) | E48: 105000
A49: 6 | B49: DR MOHAMMED O. AMALI | C49: RESEARCH FELLOW I | D49: 14(10) | E49: 75000
A50: 7 | B50: YAHAYA SHAMSU | C50: RESEARCH FELLOW 1 | D50: 14(10) | E50: 75000
A51: 8 | B51: OFORDEME ADAOBI JULIA | C51: RESEARCH FELLOW 1 | D51: 14(9) | E51: 75000
A52: 9 | B52: DORIS DAKDA AARON | C52: RESEARCH FELLOW II | D52: 13(10) | E52: 75000
A53: 10 | B53: ZAINAB AKINDE | C53: RESEARCH OFFICER | D53: 9(7) | E53: 45000
A54: 11 | B54: ABDULLAHI AHMAD USMAN | C54: RESEARCH OFFICER | D54: 9(7) | E54: 45000
A55: 12 | B55: GUNAT NANSAK MARK | C55: RESEARCH OFFICER | D55: 9(7) | E55: 45000
B56: TOTAL | C56: 12 | E56: =SUM(E44:E55) -> 1080000
B58: LEGAL SERVICES
A59: 1 | B59: DR SHUIBU DANWANKA | C59: DIRECTOR LEGAL SERVICES | D59: 17(9) | E59: 225000
A60: 2 | B60: ABDULSALAM BAKO | C60: MANAGER, LEGAL SERVICES | D60: 15 (8) | E60: 105000
...

Sheet Sallah Welfare June 2023 Latest
A1: NATIONAL INSTITUTE FOR LEGISLATIVE AND DEMOCRATIC STUDIES
A2: STAFF WELFARE APRIL, 2023
B4: STAFF NAME | C4: DESIGNATION | D4: GRADE LEVEL | E4: AMOUNT
E5: N
A6: S/N | B6: DG'S OFFICE
A7: 1 | B7: PROF. ABUBAKAR O. SULAIMAN | C7: DIRECTOR GENERAL | D7: CONSOL | E7: 540000
A8: 2 | B8: DR JAKE DABANG DAN AZUMI | C8: DEPUTY DIR. TTECHNICAL | D8: 16(9) | E8: 180000
A9: 3 | B9: RAHEEM USMAN AYIGORO | C9: SA-INFRASTRUCTURE | D9: 16 (9) | E9: 180000
A10: 4 | B10: MARIAM MOHAMMED BELLO | C10: SA- SPECIAL DUTIES | D10: 16(8) | E10: 180000
A11: 5 | B11: AKINSANMI ADEJOKE OLUKEMI | C11: DEPUTY DIR. INFO/PROTOCOL | D11: 16(8) | E11: 180000
A12: 6 | B12: DR IKEME ARTHUR J.O | C12: DEPUTY DIRECTOR, M&E | D12: 16(8) | E12: 180000
A13: 7 | B13: MOSHOOD M. OLALERE | C13: DEPUTY DIR. GENERAL SERVICE | D13: 16(8) | E13: 180000
A14: 8 | B14: ANDRAWUS MUSA | C14: ASST. DIRECTOR, STORES | D14: 15(9) | E14: 126000
A15: 9 | B15: AYOBOLU OLAJIDE OLUFUNSHO | C15: ASST.DIR., INFORMATION | D15: 15 (8) | E15: 126000
A16: 10 | B16: HUSSEIN EGYE MUSA | C16: CHIEF PROTOCOL OFFICER | D16: 14(10) | E16: 90000
A17: 11 | B17: DONALD E. MKPANAM | C17: CHIEF ICT OFFICER | D17: 14(10) | E17: 90000
A18: 12 | B18: JOY HARUNA MAKERI | C18: RESEARCH FELLOW 1 TRAINING | D18: 14(10) | E18: 90000
... A34: 28 | B34: SHOLAGBERU T. SOFIAT | C34: ASST. ACCOUNT. OFFICER | D34: 8(7) | E34: 54000
B35: TOTAL | C35: 28 | E35: =SUM(E7:E34) -> 3114000
B37: INTERNAL AUDIT
A38: 1 | B38: OSANAIYE DAVID AKINYEMI | C38: DIRECTOR INTERNAL AUDIT | D38: 17(9) | E38: 270000
A39: 2 | B39: JAMILA ABDUL | C39: AUDITOR II | D39: 8(7) | E39: 54000
C40: 2 | E40: 324000
B42: LEG. SUPPORT SEVICES
A43: 1 | B43: PROF. EDOBA BRIGHT OMOREGBE | C43: AG. DLSS | D43: 17(9) | E43: 270000
A44: 2 | B44: DR CLINTON JAJA | C44: SENIOR RESEARCH FELLOW | D44: 15(9) | E44: 126000
A45: 3 | B45: BETHEL UZOMA IHUGBA | C45: SNR RESEARCH FELLOW | D45: 15(9) | E45: 126000
A46: 4 | B46: OGUCHE SAMUEL | C46: SNR RESEARCH FELLOW | D46: 15(9) | E46: 126000
A47: 5 | B47: IBRAHIM USMAN | C47: SNR RESEARCH FELLOW | D47: 15(8) | E47: 126000
A48: 6 | B48: DR MOHAMMED O. AMALI | C48: RESEARCH FELLOW I | D48: 14(10) | E48: 90000
A49: 7 | B49: YAHAYA SHAMSU | C49: RESEARCH FELLOW 1 | D49: 14(10) | E49: 90000
A50: 8 | B50: OFORDEME ADAOBI JULIA | C50: RESEARCH FELLOW 1 | D50: 14(9) | E50: 90000
A51: 9 | B51: DORIS DAKDA AARON | C51: RESEARCH FELLOW II | D51: 13(10) | E51: 90000
A52: 10 | B52: ZAINAB AKINDE | C52: RESEARCH OFFICER | D52: 9(7) | E52: 54000
A53: 11 | B53: ABDULLAHI AHMAD USMAN | C53: RESEARCH OFFICER | D53: 9(7) | E53: 54000
A54: 12 | B54: GUNAT NANSAK MARK | C54: RESEARCH OFFICER | D54: 9(7) | E54: 54000
B55: TOTAL | C55: 12 | E55: 1296000
B57: LEGAL SERVICES
A58: 1 | B58: DR SHUIBU DANWANKA | C58: DIRECTOR LEGAL SERVICES | D58: 17(9) | E58: 270000
A59: 2 | B59: ABDULSALAM BAKO | C59: MANAGER, LEGAL SERVICES | D59: 15 (8) | E59: 126000
...

Sheet Sheet1

Sheet January 2023 PAYE
A1: NATIONAL INSTITUTE FOR LEGISLATIVE AND DEMOCRATIC STUDIES
A2: STAFF PAYROLL FOR THE MONTH OF JANUARY 2023
B4: STAFF NAME | C4: DESIGNATION | D4: GRADE LEVEL | E4: OLD PAYE | F4: NEW PAYE | G4: DIFFRENCE
A5: S/N | B5: DG'S OFFICE | E5: N | F5: N | G5: N
A6: 1 | B6: PROF. ABUBAKAR O. SULAIMAN | C6: DIRECTOR GENERAL | D6: CONSOL | E6: =201165.84 -> 201165.84 | F6: 201165.84 | G6: 0
A7: 2 | B7: DR JAKE DABANG DAN AZUMI | C7: DEPUTY DIR. TTECHNICAL | D7: 16(9) | E7: =#REF! -> #REF! | F7: 128510.39 | G7: =F7-E7 -> #REF!
A8: 3 | B8: DR ABDULSALAM NASIRU NAEEM | C8: SA ACADEMICS | D8: 16(9) | E8: =116473.51 -> 116473.51 | F8: 119107.95 | G8: =F8-E8 -> 2634.4414
A9: 4 | B9: RAHEEM USMAN AYIGORO | C9: SA-INFRASTRUCTURE | D9: 16 (9) | E9: =79993.51 -> 79993.51 | F9: 82627.951 | G9: =F9-E9 -> 2634.4414
A10: 5 | B10: MARIAM MOHAMMED BELLO | C10: SA- SPECIAL DUTIES | D10: 16(8) | E10: =107095.69 -> 107095.69 | F10: 109730.05 | G10: =F10-E10 -> 2634.3634
A11: 6 | B11: AKINSANMI ADEJOKE OLUKEMI | C11: DEPUTY DIR. INFO/PROTOCOL | D11: 16(8) | E11: =#REF! -> #REF! | F11: 99032.678 | G11: =F11-E11 -> #REF!
A12: 7 | B12: DR IKEME ARTHUR J.O | C12: DEPUTY DIRECTOR, M&E | D12: 16(8) | E12: =#REF! -> #REF! | F12: 79832.678 | G12: =F12-E12 -> #REF!
A13: 8 | B13: MOSHOOD M. OLALERE | C13: DEPUTY DIR. GENERAL SERVICE | D13: 16(8) | E13: =#REF! -> #REF! | F13: 79832.678 | G13: =F13-E13 -> #REF!
A14: 9 | B14: ANDRAWUS MUSA | C14: ASST. DIRECTOR, STORES | D14: 15(9) | E14: =64436.1 -> 64436.1 | F14: 64436.103 | G14: =F14-E14 -> 0.0031466667
A15: 10 | B15: AYOBOLU OLAJIDE OLUFUNSHO | C15: ASST.DIR., INFORMATION | D15: 15 (8) | E15: =60212.92 -> 60212.92 | F15: 62404.98 | G15: =F15-E15 -> 2192.0603
A16: 11 | B16: HUSSEIN EGYE MUSA | C16: CHIEF PROTOCOL OFFICER | D16: 14(10) | E16: =52638.9 -> 52638.9 | F16: 54186.609 | G16: =F16-E16 -> 1547.7094
A17: 12 | B17: DONALD E. MKPANAM | C17: CHIEF ICT OFFICER | D17: 14(10) | E17: =43380 -> 43380 | F17: 44734.339 | G17: =F17-E17 -> 1354.3394
A18: 13 | B18: JOY HARUNA MAKERI | C18: RESEARCH FELLOW 1 TRAINING | D18: 14(10) | E18: =85278.9 -> 85278.9 | F18: 86826.609 | G18: =F18-E18 -> 1547.7094
A19: 14 | B19: ALI ABDULLAHI | C19: CHIEF ICT OFFICER | D19: 14(10) | E19: =#REF! -> #REF! | F19: 44006.617 | G19: =F19-E19 -> #REF!
A20: 15 | B20: PERCY TERFA GBAHABO | C20: HEAD, NILDS LIAISON OFFICE | D20: 13(9) | E20: =46673.26 -> 46673.26 | F20: 46666.667 | G20: =F20-E20 -> -6.5933333
A21: 16 | B21: HASSANA AHMED IBRAHIM | C21: PA- TO DG | D21: 13 (8) | E21: =63364.81 -> 63364.81 | F21: 64913.264 | G21: =F21-E21 -> 1548.4537
A22: 17 | B22: CHRISTIAN MADUABUCHI ODO | C22: PRINCIPAL ICT OFFICER | D22: 12(9) | E22: =31848.56 -> 31848.56 | F22: 34871.967 | G22: =F22-E22 -> 3023.4074
A23: 18 | B23: ADUGBA RICHARD TERSEER | C23: PRINCIPAL INFO. OFFICER | D23: 12(8) | E23: =#REF! -> #REF! | F23: 32008.563 | G23: =F23-E23 -> #REF!
A24: 19 | B24: EGUATU U. ONYEJELEM | C24: PRINCIPAL M&E OFFICER | D24: 12(8) | E24: =#REF! -> #REF! | F24: 32098.951 | G24: =F24-E24 -> #REF!
A25: 20 | B25: ODEH SUZIE | C25: ADMIN. OFFICER, LIASION OFFICE | D25: 10(10) | E25: =27105.99 -> 27105.99 | F25: 27873.08 | G25: =F25-E25 -> 767.08969
A26: 21 | B26: YAKUB OLUWATOYIN USMAN | C26: ASST. ADMIN. OFFICER | D26: 10(9) | E26: =26339.08 -> 26339.08 | F26: 27105.987 | G26: =F26-E26 -> 766.90656
A27: 22 | B27: ELIZABETH OGECHUKWU ONYEAKU | C27: ICT OFFICER | D27: 9(8) | E27: 21640.95 | F27: 21640.953 | G27: =F27-E27 -> 0.0028626667
A28: 23 | B28: VICTOR ASUKWO | C28: ICT OFFICER | D28: 9(8) | E28: =21640.95 -> 21640.95 | F28: 22338.483 | G28: =F28-E28 -> 697.5326
A29: 24 | B29: IJEOMA NKOLIKWA | C29: STORES OFFICER | D29: 9(8) | E29: 21640.95 | F29: 22338.483 | G29: =F29-E29 -> 697.5326
A30: 25 | B30: ABDULRAHMAN A SULAIMAN | C30: ASSISTANT STORES OFFICER | D30: 8 (10) | E30: =17572.89 -> 17572.89 | F30: 18102.903 | G30: =F30-E30 -> 530.01273
A31: 26 | B31: TASSNEEM IBRAHIM | C31: ASSIST. INFORMATION | D31: 8(10) | E31: =17572.89 -> 17572.89 | F31: 18102.903 | G31: =F31-E31 -> 530.01273
A32: 27 | B32: DARE SHEU MAGBON | C32: ASSIST. PG | D32: 8(10) | E32: =17572.89 -> 17572.89 | F32: 18102.903 | G32: =F32-E32 -> 530.01273
A33: 28 | B33: JIMOH ADEBAYO ZAKA | C33: ASST. OFFICER/COMM | D33: 9(8) | E33: 21640.95 | F33: 22338.483 | G33: =F33-E33 -> 697.5326
A34: 29 | B34: MOHAMMED BELLO | C34: RESEARCH ASSITANT PG | D34: 8(8) | E34: =16512.68 -> 16512.68 | F34: 17042.714 | G34: =F34-E34 -> 530.03387
A35: 30 | B35: SULEIMAN ABUBAKAR SODEEQ | C35: ASST. ADMIN. OFFICER | D35: 8(8) | E35: =16512.68 -> 16512.68 | F35: 17042.866 | G35: =F35-E35 -> 530.18587
A36: 31 | B36: HARUNA JIBRIL A. | C36: ASST. ADMIN. OFFICER | D36: 8(8) | E36: =16512.68 -> 16512.68 | F36: 17043.018 | G36: =F36-E36 -> 530.33787
B37: TOTAL | C37: 31 | E37: =SUM(E6:E36) -> #REF! | F37: =SUM(F6:F36) -> 1716067.7 | G37: =SUM(G6:G36) -> #REF!
B39: INTERNAL AUDIT
A40: 1 | B40: OSANAIYE DAVID AKINYEMI | C40: DIRECTOR INTERNAL AUDIT | D40: 17(9) | E40: =156349.82 -> 156349.82 | F40: 161106.81 | G40: =F40-E40 -> 4756.9869
A41: 2 | B41: JAMILA ABDUL | C41: AUDITOR II | D41: 8(7) | E41: =16512.68 -> 16512.68 | F41: 16512.682 | G41: =F41-E41 -> 0.0021906667
C42: 2 | E42: =SUM(E40:E41) -> 172862.5 | F42: =SUM(F40:F41) -> 177619.49 | G42: =SUM(G40:G41) -> 4756.989
...

Sheet January 2023 NHF)
A1: NATIONAL INSTITUTE FOR LEGISLATIVE AND DEMOCRATIC STUDIES
A2: STAFF PAYROLL FOR THE MONTH OF JANUARY 2023
E3: ='[1]FEB 08'!E11/'[1]FEB 08'!M11 -> #REF!
B4: STAFF NAME | C4: DESIGNATION | D4: GRADE LEVEL | E4: BASIC SALARY | F4: NEW NHF DED. | G4: OLD NHF DED. | H4: DIFFERENCE
A5: S/N | B5: DG'S OFFICE | E5: N | F5: N | G5: N | H5: N
A6: 1 | B6: PROF. ABUBAKAR O. SULAIMAN | C6: DIRECTOR GENERAL | D6: CONSOL | E6: 160488.75
A7: 2 | B7: DR JAKE DABANG DAN AZUMI | C7: DEPUTY DIR. TTECHNICAL | D7: 16(9) | E7: =42653.17 -> 42653.17 | F7: =0.025*E7 -> 1066.3293 | G7: ='[5]April 2022'!$H$26 -> 1028.9423 | H7: =F7-G7 -> 37.387
A8: 3 | B8: DR ABDULSALAM NASIRU NAEEM | C8: SA ACADEMICS | D8: 16(9) | E8: =42653.17 -> 42653.17 | H8: =F8-G8 -> 0
A9: 4 | B9: RAHEEM USMAN AYIGORO | C9: SA-INFRASTRUCTURE | D9: 16 (9) | E9: =42653.17 -> 42653.17 | H9: =F9-G9 -> 0
A10: 5 | B10: MARIAM MOHAMMED BELLO | C10: SA- SPECIAL DUTIES | D10: 16(8) | E10: 41157.69 | H10: =F10-G10 -> 0
A11: 6 | B11: AKINSANMI ADEJOKE OLUKEMI | C11: DEPUTY DIR. INFO/PROTOCOL | D11: 16(8) | E11: =41157.69 -> 41157.69 | F11: =0.025*E11 -> 1028.9423 | G11: =G7 -> 1028.9423 | H11: =F11-G11 -> 0
A12: 7 | B12: DR IKEME ARTHUR J.O | C12: DEPUTY DIRECTOR, M&E | D12: 16(8) | E12: =41157.69 -> 41157.69 | F12: =0.025*E12 -> 1028.9423 | G12: =1028.94 -> 1028.94 | H12: =F12-G12 -> 0.00225
A13: 8 | B13: MOSHOOD M. OLALERE | C13: DEPUTY DIR. GENERAL SERVICE | D13: 16(8) | E13: =41157.69 -> 41157.69 | F13: =0.025*E13 -> 1028.9423 | G13: =1028.94 -> 1028.94 | H13: =F13-G13 -> 0.00225
A14: 9 | B14: ANDRAWUS MUSA | C14: ASST. DIRECTOR, STORES | D14: 15(9) | E14: 33507.5 | F14: =0.025*E14 -> 837.6875 | G14: ='[5]April 2022'!$H$28 -> 837.6875 | H14: =F14-G14 -> 0
A15: 10 | B15: AYOBOLU OLAJIDE OLUFUNSHO | C15: ASST.DIR., INFORMATION | D15: 15 (8) | E15: 32263.2 | H15: =F15-G15 -> 0
A16: 11 | B16: HUSSEIN EGYE MUSA | C16: CHIEF PROTOCOL OFFICER | D16: 14(10) | E16: 27611.23 | F16: 0 | G16: 0 | H16: =F16-G16 -> 0
A17: 12 | B17: DONALD E. MKPANAM | C17: CHIEF ICT OFFICER | D17: 14(10) | E17: 27611.23 | F17: =0.025*E17 -> 690.28075 | G17: ='[5]April 2022'!$H$27 -> 668.31625 | H17: =F17-G17 -> 21.9645
A18: 13 | B18: JOY HARUNA MAKERI | C18: RESEARCH FELLOW 1 TRAINING | D18: 14(10) | E18: 27611.23 | H18: =F18-G18 -> 0
A19: 14 | B19: ALI ABDULLAHI | C19: CHIEF ICT OFFICER | D19: 14(10) | E19: 27611.23 | H19: =F19-G19 -> 0
A20: 15 | B20: PERCY TERFA GBAHABO | C20: HEAD, NILDS LIAISON OFFICE | D20: 13(9) | E20: 24741.26 | H20: =F20-G20 -> 0
A21: 16 | B21: HASSANA AHMED IBRAHIM | C21: PA- TO DG | D21: 13 (8) | E21: =23891.12 -> 23891.12 | F21: =0.025*E21 -> 597.278 | G21: ='[5]April 2022'!$H$52 -> 576.87475 | H21: =F21-G21 -> 20.40325
A22: 17 | B22: CHRISTIAN MADUABUCHI ODO | C22: PRINCIPAL ICT OFFICER | D22: 12(9) | E22: =22837.82 -> 22837.82 | F22: =0.025*E22 -> 570.9455 | G22: ='[5]April 2022'!$H$45 -> 538.022 | H22: =F22-G22 -> 32.9235
A23: 18 | B23: ADUGBA RICHARD TERSEER | C23: PRINCIPAL INFO. OFFICER | D23: 12(8) | E23: 21520.88 | H23: =F23-G23 -> 0
A24: 19 | B24: EGUATU U. ONYEJELEM | C24: PRINCIPAL M&E OFFICER | D24: 12(8) | E24: 21520.88 | H24: =F24-G24 -> 0
A25: 20 | B25: ODEH SUZIE | C25: ADMIN. OFFICER, LIASION OFFICE | D25: 10(10) | E25: =18779.3 -> 18779.3 | F25: =0 -> 0 | G25: =0 -> 0 | H25: =F25-G25 -> 0
A26: 21 | B26: YAKUB OLUWATOYIN USMAN | C26: ASST. ADMIN. OFFICER | D26: 10(9) | E26: 18281.64 | H26: =F26-G26 -> 0
A27: 22 | B27: ELIZABETH OGECHUKWU ONYEAKU | C27: ICT OFFICER | D27: 9(8) | E27: 14736.14 | H27: =F27-G27 -> 0
A28: 23 | B28: VICTOR ASUKWO | C28: ICT OFFICER | D28: 9(8) | E28: =15188.67 -> 15188.67 | H28: =F28-G28 -> 0
A29: 24 | B29: IJEOMA NKOLIKWA | C29: STORES OFFICER | D29: 9(8) | E29: =15188.67 -> 15188.67 | H29: =F29-G29 -> 0
A30: 25 | B30: ABDULRAHMAN A SULAIMAN | C30: ASSISTANT STORES OFFICER | D30: 8 (10) | E30: 13492.21 | H30: =F30-G30 -> 0
A31: 26 | B31: TASSNEEM IBRAHIM | C31: ASSIST. INFORMATION | D31: 8(10) | E31: 13492.21 | H31: =F31-G31 -> 0
A32: 27 | B32: DARE SHEU MAGBON | C32: ASSIST. PG | D32: 8(10) | E32: 13492.21 | H32: =F32-G32 -> 0
A33: 28 | B33: JIMOH ADEBAYO ZAKA | C33: ASST. OFFICER/COMM | D33: 9(8) | E33: 15188.67 | F33: =0 -> 0 | G33: =0 -> 0 | H33: =F33-G33 -> 0
A34: 29 | B34: MOHAMMED BELLO | C34: RESEARCH ASSITANT PG | D34: 8(8) | E34: =12732 -> 12732 | H34: =F34-G34 -> 0
A35: 30 | B35: SULEIMAN ABUBAKAR SODEEQ | C35: ASST. ADMIN. OFFICER | D35: 8(8) | E35: =12732 -> 12732 | H35: =F35-G35 -> 0
A36: 31 | B36: HARUNA JIBRIL A. | C36: ASST. ADMIN. OFFICER | D36: 8(8) | E36: =12732 -> 12732 | H36: =F36-G36 -> 0
B37: TOTAL | C37: 31 | E37: =SUM(E6:E36) -> 919842.32 | F37: =SUM(F6:F36) -> 6849.3477 | G37: =SUM(G6:G36) -> 6736.665 | H37: =F37-G37 -> 112.68275
H38: =F38-G38 -> 0
B39: INTERNAL AUDIT | H39: =F39-G39 -> 0
A40: 1 | B40: OSANAIYE DAVID AKINYEMI | C40: DIRECTOR INTERNAL AUDIT | D40: 17(9) | E40: 81740.02 | H40: =F40-G40 -> 0
...

Sheet PAYE Computation
A1: NATIONAL INSTITUTE FOR LEGISLATIVE AND DEMOCRATIC STUDIES
A2: NATIONAL ASSEMBLY ABUJA
A3: TAX COMPUTATION FOR 2023
A4: S/NO | B4: NAME | C4: MONTHLY TOTAL SALARY | D4: NO OF MONTHS | E4: ANNUAL SALARY GROSSED UP | F4: NATIONAL HOUSING SCHEME = 2.5% OF BASIC SALARY | G4: PENSION CONTRIBUTION = 8% OF CONSOLIDATED | H4: NHIS | I4: NET SALARY (EXC OF CRA) | M4: CRA=#200,000+(20% 0F NET SALARY (EXC OF CRA) | N4: TOTAL RELIEF | O4: CHARGEABLE INCOME | P4: FIRST N300,000 @ 7% | Q4: NEXT N300,000 @ 11% | R4: NEXT N500,000 @ 15% | S4: NEXT N500,000@ 19% | T4: NEXT N1,600,000 @ 21% | U4: ABOVE N3,200,000 @ 24% | V4: ANNUAL TAX PAYABLE | X4: MONTHLY TAX PAYABLE | Y4: MINIMUM TAX PAYABLE | Z4: NEW ACTUAL TAX PAYABLE | AA4: OLD Tax | AB4: Difference
A5: 1 | B5: PROF. ABUBAKAR O. SULAIMAN | C5: 1158849.8 | D5: 12 | E5: 13906198 | I5: 13906198 | J5: 200000 | K5: 0.2 | L5: 2781239.6 | M5: 2981239.6 | N5: 2981239.6 | O5: 10924958 | P5: 21000 | Q5: 33000 | R5: 75000 | S5: 95000 | T5: 336000 | U5: 1853990 | V5: 2413990 | W5: 12 | X5: 201165.84 | Z5: 201165.84 | AA5: 201165.84 | AB5: -0.0040533334
A6: 3 | B6: DR JAKE DABANG DAN AZUMI | C6: 781465.02 | D6: 12 | E6: 9377580.3 | F6: 12347.31 | I6: 9365233 | J6: 200000 | K6: 0.2 | L6: 1873046.6 | M6: 2073046.6 | N6: 2085393.9 | O6: 7292186.4 | P6: 21000 | Q6: 33000 | R6: 75000 | S6: 95000 | T6: 336000 | U6: 982124.73 | V6: 1542124.7 | W6: 12 | X6: 128510.39 | Z6: 128510.39 | AA6: 128508.39 | AB6: 2.006208
A7: 4 | B7: DR ABDULSALAM NASIRU NAEEM | C7: 731465.02 | D7: 12 | E7: 8777580.3 | I7: 8777580.3 | J7: 200000 | K7: 0.2 | L7: 1755516.1 | M7: 1955516.1 | N7: 1955516.1 | O7: 6822064.2 | P7: 21000 | Q7: 33000 | R7: 75000 | S7: 95000 | T7: 336000 | U7: 869295.42 | V7: 1429295.4 | W7: 12 | X7: 119107.95 | Z7: 119107.95 | AA7: 116473.51 | AB7: 2634.4414
A8: 5 | B8: RAHEEM USMAN AYIGORO | C8: 541465.02 | D8: 12 | E8: 6497580.3 | I8: 6497580.3 | J8: 200000 | K8: 0.2 | L8: 1299516.1 | M8: 1499516.1 | N8: 1499516.1 | O8: 4998064.2 | P8: 21000 | Q8: 33000 | R8: 75000 | S8: 95000 | T8: 336000 | U8: 431535.42 | V8: 991535.42 | W8: 12 | X8: 82627.951 | Z8: 82627.951 | AA8: 79993.51 | AB8: 2634.4414
A9: 6 | B9: MARIAM MOHAMMED BELLO | C9: 682621.81 | D9: 12 | E9: 8191461.7 | I9: 8191461.7 | J9: 200000 | K9: 0.2 | L9: 1638292.3 | M9: 1838292.3 | N9: 1838292.3 | O9: 6353169.3 | P9: 21000 | Q9: 33000 | R9: 75000 | S9: 95000 | T9: 336000 | U9: 756760.64 | V9: 1316760.6 | W9: 12 | X9: 109730.05 | Z9: 109730.05 | AA9: 107095.69 | AB9: 2634.3634
A10: 7 | B10: AKINSANMI ADEJOKE OLUKEMI | C10: 627744 | D10: 12 | E10: 7532927.9 | F10: 10052.25 | I10: 7522875.7 | J10: 200000 | K10: 0.2 | L10: 1504575.1 | M10: 1704575.1 | N10: 1714627.4 | O10: 5818300.6 | P10: 21000 | Q10: 33000 | R10: 75000 | S10: 95000 | T10: 336000 | U10: 628392.13 | V10: 1188392.1 | W10: 12 | X10: 99032.678 | Z10: 99032.678 | AA10: 96398.374 | AB10: 2634.304
A11: 8 | B11: DR IKEME ARTHUR J.O | C11: 527744 | D11: 12 | E11: 6332927.9 | F11: 10052.25 | I11: 6322875.7 | J11: 200000 | K11: 0.2 | L11: 1264575.1 | M11: 1464575.1 | N11: 1474627.4 | O11: 4858300.6 | P11: 21000 | Q11: 33000 | R11: 75000 | S11: 95000 | T11: 336000 | U11: 397992.13 | V11: 957992.13 | W11: 12 | X11: 79832.678 | Z11: 79832.678 | AA11: 77198.374 | AB11: 2634.304
A12: 9 | B12: MOSHOOD M. OLALERE | C12: 527744 | D12: 12 | E12: 6332927.9 | F12: 10052.25 | I12: 6322875.7 | J12: 200000 | K12: 0.2 | L12: 1264575.1 | M12: 1464575.1 | N12: 1474627.4 | O12: 4858300.6 | P12: 21000 | Q12: 33000 | R12: 75000 | S12: 95000 | T12: 336000 | U12: 397992.13 | V12: 957992.13 | W12: 12 | X12: 79832.678 | Z12: 79832.678 | AA12: 77198.374 | AB12: 2634.304
A13: 10 | B13: ANDRAWUS MUSA | C13: 447553.5 | D13: 12 | E13: 5370642 | F13: 10052.25 | I13: 5360589.8 | J13: 200000 | K13: 0.2 | L13: 1072118 | M13: 1272118 | N13: 1282170.2 | O13: 4088471.8 | P13: 21000 | Q13: 33000 | R13: 75000 | S13: 95000 | T13: 336000 | U13: 213233.24 | V13: 773233.24 | W13: 12 | X13: 64436.103 | Z13: 64436.103 | AA13: 64436.1 | AB13: 0.0031466667
A14: 11 | B14: AYOBOLU OLAJIDE OLUFUNSHO | C14: 436137.05 | D14: 12 | E14: 5233644.6 | I14: 5233644.6 | J14: 200000 | K14: 0.2 | L14: 1046728.9 | M14: 1246728.9 | N14: 1246728.9 | O14: 3986915.7 | P14: 21000 | Q14: 33000 | R14: 75000 | S14: 95000 | T14: 336000 | U14: 188859.76 | V14: 748859.76 | W14: 12 | X14: 62404.98 | Z14: 62404.98 | AA14: 60212.92 | AB14: 2192.0603
A15: 12 | B15: HUSSEIN EGYE MUSA | C15: 393333.04 | D15: 12 | E15: 4719996.4 | I15: 4719996.4 | J15: 200000 | K15: 0.2 | L15: 943999.28 | M15: 1143999.3 | N15: 1143999.3 | O15: 3575997.1 | P15: 21000 | Q15: 33000 | R15: 75000 | S15: 95000 | T15: 336000 | U15: 90239.313 | V15: 650239.31 | W15: 12 | X15: 54186.609 | Z15: 54186.609 | AA15: 52638.9 | AB15: 1547.7094
A16: 13 | B16: DONALD E. MKPANAM | C16: 343333.04 | D16: 12 | E16: 4119996.4 | F16: 8019.8 | I16: 4111976.6 | J16: 200000 | K16: 0.2 | L16: 822395.32 | M16: 1022395.3 | N16: 1030415.1 | O16: 3089581.3 | P16: 21000 | Q16: 33000 | R16: 75000 | S16: 95000 | T16: 312812.07 | V16: 536812.07 | W16: 12 | X16: 44734.339 | Z16: 44734.339 | AA16: 43380 | AB16: 1354.3394
A17: 14 | B17: JOY HARUNA MAKERI | C17: 563333.04 | D17: 12 | E17: 6759996.4 | I17: 6759996.4 | J17: 200000 | K17: 0.2 | L17: 1351999.3 | M17: 1551999.3 | N17: 1551999.3 | O17: 5207997.1 | P17: 21000 | Q17: 33000 | R17: 75000 | S17: 95000 | T17: 336000 | U17: 481919.31 | V17: 1041919.3 | W17: 12 | X17: 86826.609 | Z17: 86826.609 | AA17: 85278.9 | AB17: 1547.7094
A18: 15 | B18: ALI ABDULLAHI | C18: 338333.04 | D18: 12 | E18: 4059996.4 | I18: 4059996.4 | J18: 200000 | K18: 0.2 | L18: 811999.28 | M18: 1011999.3 | N18: 1011999.3 | O18: 3047997.1 | P18: 21000 | Q18: 33000 | R18: 75000 | S18: 95000 | T18: 304079.4 | V18: 528079.4 | W18: 12 | X18: 44006.617 | Z18: 44006.617 | AA18: 43492.04 | AB18: 514.5769
A19: 16 | B19: PERCY TERFA GBAHABO | C19: 362001.06 | D19: 12 | E19: 4344012.7 | F19: 7422.38 | I19: 4336590.3 | J19: 200000 | K19: 0.2 | L19: 867318.07 | M19: 1067318.1 | N19: 1074740.4 | O19: 3269272.3 | P19: 21000 | Q19: 33000 | R19: 75000 | S19: 95000 | T19: 336000 | V19: 560000 | W19: 12 | X19: 46666.667 | Z19: 46666.667 | AA19: 46673.26 | AB19: -6.5933333
A20: 17 | B20: HASSANA AHMED IBRAHIM | C20: 449201.03 | D20: 12 | E20: 5390412.3 | I20: 5390412.3 | J20: 200000 | K20: 0.2 | L20: 1078082.5 | M20: 1278082.5 | N20: 1278082.5 | O20: 4112329.8 | P20: 21000 | Q20: 33000 | R20: 75000 | S20: 95000 | T20: 336000 | U20: 218959.16 | V20: 778959.16 | W20: 12 | X20: 64913.264 | Z20: 64913.264 | AA20: 63364.81 | AB20: 1548.4537
A21: 18 | B21: CHRISTIAN MADUABUCHI ODO | C21: 284537 | D21: 12 | E21: 3414444 | F21: 6922.5 | I21: 3407521.5 | J21: 200000 | K21: 0.2 | L21: 681504.3 | M21: 881504.3 | N21: 888426.8 | O21: 2526017.2 | P21: 21000 | Q21: 33000 | R21: 75000 | S21: 95000 | T21: 194463.61 | U21: 0 | V21: 418463.61 | W21: 12 | X21: 34871.967 | Z21: 34871.967 | AA21: 31848.56 | AB21: 3023.4074
A22: 19 | B22: ADUGBA RICHARD TERSEER | C22: 267454.07 | D22: 12 | E22: 3209448.9 | F22: 6456.26 | I22: 3202992.6 | J22: 200000 | K22: 0.2 | L22: 640598.53 | M22: 840598.53 | N22: 847054.79 | O22: 2362394.1 | P22: 21000 | Q22: 33000 | R22: 75000 | S22: 95000 | T22: 160102.76 | V22: 384102.76 | W22: 12 | X22: 32008.563 | Z22: 32008.563 | AA22: 31749.189 | AB22: 259.37433
A23: 20 | B23: EGUATU U. ONYEJELEM | C23: 267454.07 | D23: 12 | E23: 3209448.9 | I23: 3209448.9 | J23: 200000 | K23: 0.2 | L23: 641889.78 | M23: 841889.78 | N23: 841889.78 | O23: 2367559.1 | P23: 21000 | Q23: 33000 | R23: 75000 | S23: 95000 | T23: 161187.41 | V23: 385187.41 | W23: 12 | X23: 32098.951 | Z23: 32098.951 | AA23: 31749.189 | AB23: 349.76197
A24: 21 | B24: ODEH SUZIE | C24: 242300.08 | D24: 12 | E24: 2907600.9 | I24: 2907600.9 | J24: 200000 | K24: 0.2 | L24: 581520.19 | M24: 781520.19 | N24: 781520.19 | O24: 2126080.7 | P24: 21000 | Q24: 33000 | R24: 75000 | S24: 95000 | T24: 110476.96 | V24: 334476.96 | W24: 12 | X24: 27873.08 | Z24: 27873.08 | AA24: 27105.99 | AB24: 767.08969
A25: 22 | B25: YAKUB OLUWATOYIN USMAN | C25: 237734.05 | D25: 12 | E25: 2852808.6 | I25: 2852808.6 | J25: 200000 | K25: 0.2 | L25: 570561.71 | M25: 770561.71 | N25: 770561.71 | O25: 2082246.9 | P25: 21000 | Q25: 33000 | R25: 75000 | S25: 95000 | T25: 101271.84 | V25: 325271.84 | W25: 12 | X25: 27105.987 | Z25: 27105.987 | AA25: 26339.08 | AB25: 766.90656
A26: 23 | B26: ELIZABETH OGECHUKWU ONYEAKU | C26: 205204.08 | D26: 12 | E26: 2462449 | I26: 2462449 | J26: 200000 | K26: 0.2 | L26: 492489.8 | M26: 692489.8 | N26: 692489.8 | O26: 1769959.2 | P26: 21000 | Q26: 33000 | R26: 75000 | S26: 95000 | T26: 35691.434 | V26: 259691.43 | W26: 12 | X26: 21640.953 | Z26: 21640.953 | AA26: 21640.95 | AB26: 0.0028626667
A27: 24 | B27: VICTOR ASUKWO | C27: 209356.05 | D27: 12 | E27: 2512272.6 | I27: 2512272.6 | J27: 200000 | K27: 0.2 | L27: 502454.51 | M27: 702454.51 | N27: 702454.51 | O27: 1809818.1 | P27: 21000 | Q27: 33000 | R27: 75000 | S27: 95000 | T27: 44061.791 | V27: 268061.79 | W27: 12 | X27: 22338.483 | Z27: 22338.483 | AA27: 21640.95 | AB27: 697.5326
A28: 25 | B28: IJEOMA NKOLIKWA | C28: 209356.05 | D28: 12 | E28: 2512272.6 | I28: 2512272.6 | J28: 200000 | K28: 0.2 | L28: 502454.51 | M28: 702454.51 | N28: 702454.51 | O28: 1809818.1 | P28: 21000 | Q28: 33000 | R28: 75000 | S28: 95000 | T28: 44061.791 | V28: 268061.79 | W28: 12 | X28: 22338.483 | Z28: 22338.483 | AA28: 21640.95 | AB28: 697.5326
A29: 26 | B29: ABDULRAHMAN A SULAIMAN | C29: 183791.03 | D29: 12 | E29: 2205492.3 | I29: 2205492.3 | J29: 200000 | K29: 0.2 | L29: 441098.46 | M29: 641098.46 | N29: 641098.46 | O29: 1564393.9 | P29: 21000 | Q29: 33000 | R29: 75000 | S29: 88234.833 | T29: 0 | V29: 217234.83 | W29: 12 | X29: 18102.903 | Z29: 18102.903 | AA29: 17572.89 | AB29: 530.01273
A30: 27 | B30: TASSNEEM IBRAHIM | C30: 183791.03 | D30: 12 | E30: 2205492.3 | I30: 2205492.3 | J30: 200000 | K30: 0.2 | L30: 441098.46 | M30: 641098.46 | N30: 641098.46 | O30: 1564393.9 | P30: 21000 | Q30: 33000 | R30: 75000 | S30: 88234.833 | T30: 0 | V30: 217234.83 | W30: 12 | X30: 18102.903 | Z30: 18102.903 | AA30: 17572.89 | AB30: 530.01273
A31: 28 | B31: DARE SHEU MAGBON | C31: 183791.03 | D31: 12 | E31: 2205492.3 | I31: 2205492.3 | J31: 200000 | K31: 0.2 | L31: 441098.46 | M31: 641098.46 | N31: 641098.46 | O31: 1564393.9 | P31: 21000 | Q31: 33000 | R31: 75000 | S31: 88234.833 | T31: 0 | V31: 217234.83 | W31: 12 | X31: 18102.903 | Z31: 18102.903 | AA31: 17572.89 | AB31: 530.01273
A32: 29 | B32: JIMOH ADEBAYO ZAKA | C32: 209356.05 | D32: 12 | E32: 2512272.6 | I32: 2512272.6 | J32: 200000 | K32: 0.2 | L32: 502454.51 | M32: 702454.51 | N32: 702454.51 | O32: 1809818.1 | P32: 21000 | Q32: 33000 | R32: 75000 | S32: 95000 | T32: 44061.791 | V32: 268061.79 | W32: 12 | X32: 22338.483 | Z32: 22338.483 | AA32: 21640.95 | AB32: 697.5326
A33: 30 | B33: MOHAMMED BELLO | C33: 176816.1 | D33: 12 | E33: 2121793.2 | I33: 2121793.2 | J33: 200000 | K33: 0.2 | L33: 424358.64 | M33: 624358.64 | N33: 624358.64 | O33: 1497434.6 | P33: 21000 | Q33: 33000 | R33: 75000 | S33: 75512.566 | T33: 0 | V33: 204512.57 | W33: 12 | X33: 17042.714 | Z33: 17042.714 | AA33: 16512.68 | AB33: 530.03387
A34: 31 | B34: SULEIMAN ABUBAKAR SODEEQ | C34: 176817.1 | D34: 12 | E34: 2121805.2 | I34: 2121805.2 | J34: 200000 | K34: 0.2 | L34: 424361.04 | M34: 624361.04 | N34: 624361.04 | O34: 1497444.2 | P34: 21000 | Q34: 33000 | R34: 75000 | S34: 75514.39 | T34: 0 | V34: 204514.39 | W34: 12 | X34: 17042.866 | Z34: 17042.866 | AA34: 16512.68 | AB34: 530.18587
A35: 32 | B35: HARUNA JIBRIL A. | C35: 176818.1 | D35: 12 | E35: 2121817.2 | I35: 2121817.2 | J35: 200000 | K35: 0.2 | L35: 424363.44 | M35: 624363.44 | N35: 624363.44 | O35: 1497453.8 | P35: 21000 | Q35: 33000 | R35: 75000 | S35: 75516.214 | T35: 0 | V35: 204516.21 | W35: 12 | X35: 17043.018 | Z35: 17043.018 | AA35: 16512.68 | AB35: 530.33787
C36: 12126899 | G36: 0 | Z36: 1716067.7 | AA36: 1681121.5 | AB36: 34946.156
A38: 33 | B38: OSANAIYE DAVID AKINYEMI | C38: 950209.06 | D38: 12 | E38: 11402509 | I38: 11402509 | J38: 200000 | K38: 0.2 | L38: 2280501.8 | M38: 2480501.8 | N38: 2480501.8 | O38: 8922007 | P38: 21000 | Q38: 33000 | R38: 75000 | S38: 95000 | T38: 336000 | U38: 1373281.7 | V38: 1933281.7 | W38: 12 | X38: 161106.81 | Z38: 161106.81 | AA38: 156349.82 | AB38: 4756.9869
A39: 34 | B39: JAMILA ABDUL | C39: 173329.05 | D39: 12 | E39: 2079948.6 | I39: 2079948.6 | J39: 200000 | K39: 0.2 | L39: 415989.72 | M39: 615989.72 | N39: 615989.72 | O39: 1463958.9 | P39: 21000 | Q39: 33000 | R39: 75000 | S39: 69152.186 | T39: 0 | V39: 198152.19 | W39: 12 | X39: 16512.682 | Z39: 16512.682 | AA39: 16512.68 | AB39: 0.0021906667
A42: 35 | B42: PROF. EDOBA BRIGHT OMOREGBE | C42: 1050209.1 | D42: 12 | E42: 12602509 | I42: 12602509 | J42: 200000 | K42: 0.2 | L42: 2520501.8 | M42: 2720501.8 | N42: 2720501.8 | O42: 9882007 | P42: 21000 | Q42: 33000 | R42: 75000 | S42: 95000 | T42: 336000 | U42: 1603681.7 | V42: 2163681.7 | W42: 12 | X42: 180306.81 | Z42: 180306.81 | AA42: 180306.81 | AB42: -0.0031413333
A43: 36 | B43: DR CLINTON JAJA | C43: 527553.5 | D43: 12 | E43: 6330642 | I43: 6330642 | J43: 200000 | K43: 0.2 | L43: 1266128.4 | M43: 1466128.4 | N43: 1466128.4 | O43: 4864513.6 | P43: 21000 | Q43: 33000 | R43: 75000 | S43: 95000 | T43: 336000 | U43: 399483.27 | V43: 959483.27 | W43: 12 | X43: 79956.939 | Z43: 79956.939 | AA43: 79956.94 | AB43: -0.00085333335
...

Sheet Tax adj August, 2022
B3: STAFF PAYROLL FOR THE MONTH OF AUGUST 2022
B5: STAFF NAME
C6: DESIGNATION | D6: SALARY
D7: LEVEL | E7: JULY 2022 PAYE | F7: AUGUST 2022 PAYE | G7: DIFFERENCE
A8: S/N | B8: DG'S OFFICE | E8: N | F8: N | G8: N
A9: 1 | B9: PROF. ABUBAKAR O. SULAIMAN | C9: DIRECTOR GENERAL | D9: CONSOL | E9: 113176.97 | F9: =201165.84 -> 201165.84 | G9: =F9-E9 -> 87988.87
A10: 2 | B10: DR ADEYEMI AKEEB FAJINGBESI | C10: DIR. SPECIAL DUTIES, DG OFFICE | D10: 17(9) | E10: 52776.63 | F10: =0 -> 0 | G10: =F10-E10 -> -52776.63
A11: 3 | B11: DR JAKE DABANG DAN AZUMI | C11: DEPUTY DIRECTOR TRAINING | D11: 16(8) | E11: 21618.09 | F11: =125875.96 -> 125875.96 | G11: =F11-E11 -> 104257.87
A12: 4 | B12: DR ABDULSALAM NASIRU NAEEM | C12: SA ACADEMICS | D12: 16(8) | E12: 21618.09 | F12: =116473.51 -> 116473.51 | G12: =F12-E12 -> 94855.42
A13: 5 | B13: RAHEEM USMAN AYIGORO | C13: SA-INFRASTRUCTURE | D13: 16 (8) | E13: 21618.09 | F13: =79993.51 -> 79993.51 | G13: =F13-E13 -> 58375.42
A14: 6 | B14: MARIAM MOHAMMED BELLO | C14: SA- SPECIAL DUTIES | D14: 15 (7) | E14: 21618.09 | F14: =107095.69 -> 107095.69 | G14: =F14-E14 -> 85477.6
A15: 7 | B15: AKINSANMI ADEJOKE OLUKEMI | C15: HEAD INFORMATION/PROTOCOL | D15: 15(9) | E15: 15548.33 | F15: =83636.1 -> 83636.1 | G15: =F15-E15 -> 68087.77
A16: 8 | B16: DR IKEME ARTHUR J.O | C16: SNR RESEARCH FELLOW | D16: 15(9) | E16: 15548.33 | F16: =64436.1 -> 64436.1 | G16: =F16-E16 -> 48887.77
A17: 9 | B17: MOSHOOD M. OLALERE | C17: MANAGER ADMIN DG's OFFICE | D17: 15(9) | E17: 15548.33 | F17: =64436.1 -> 64436.1 | G17: =F17-E17 -> 48887.77
A18: 10 | B18: ANDRAWUS MUSA | C18: ASST. DIRECTOR, STORE | D18: 15(9) | E18: 15548.33 | F18: =64436.1 -> 64436.1 | G18: =F18-E18 -> 48887.77
A19: 11 | B19: AYOBOLU OLAJIDE OLUFUNSHO | C19: ASST.DIR., INFORMATION | D19: 15 (7) | E19: 15548.33 | F19: =60212.92 -> 60212.92 | G19: =F19-E19 -> 44664.59
A20: 12 | B20: HUSSEIN EGYE MUSA | C20: CHIEF PROTOCOL OFFICER | D20: 14(9) | E20: 7709.76 | F20: =52638.9 -> 52638.9 | G20: =F20-E20 -> 44929.14
A21: 13 | B21: DONALD E. MKPANAM | C21: CHIEF ICT OFFICER | D21: 14(9) | E21: 7709.76 | F21: =43380 -> 43380 | G21: =F21-E21 -> 35670.24
A22: 14 | B22: JOY HARUNA MAKERI | C22: RESEARCH FELLOW 1 TRAINING | D22: 14(9) | E22: 7709.76 | F22: =85278.9 -> 85278.9 | G22: =F22-E22 -> 77569.14
A23: 15 | B23: ALI ABDULLAHI | C23: ASST. CHIEF ICT OFFICER | D23: 13(11) | E23: 7709.76 | F23: =42046.06 -> 42046.06 | G23: =F23-E23 -> 34336.3
A24: 16 | B24: ANTHONY EDET | C24: ASST. MGR M&E | D24: 13(9) | E24: 7709.76 | F24: =39478.93 -> 39478.93 | G24: =F24-E24 -> 31769.17
A25: 17 | B25: PERCY TERFA GBAHABO | C25: HEAD, NILDS LIAISON OFFICE | D25: 13(8) | E25: 7709.76 | F25: =46673.26 -> 46673.26 | G25: =F25-E25 -> 38963.5
A26: 18 | B26: HASSANA AHMED IBRAHIM | C26: PA- TO DG | D26: 13 (7) | E26: 7709.76 | F26: =63364.81 -> 63364.81 | G26: =F26-E26 -> 55655.05
A27: 19 | B27: CHRISTIAN MADUABUCHI ODO | C27: PRINCIPAL ICT OFFICER | D27: 12(8) | E27: 3369.51 | F27: =31848.56 -> 31848.56 | G27: =F27-E27 -> 28479.05
A28: 20 | B28: ADUGBA RICHARD TERSEER | C28: INFORMATION OFFICER | D28: 10(10) | E28: 3369.51 | F28: =27873.08 -> 27873.08 | G28: =F28-E28 -> 24503.57
A29: 21 | B29: EGUATU U. ONYEJELEM | C29: OFFICER M&E | D29: 10(10) | E29: 3369.51 | F29: =27873.08 -> 27873.08 | G29: =F29-E29 -> 24503.57
A30: 22 | B30: ODEH SUZIE | C30: ADMIN. OFFICER, LIASION OFFICE | D30: 10(9) | E30: 3369.51 | F30: =27105.99 -> 27105.99 | G30: =F30-E30 -> 23736.48
A31: 23 | B31: YAKUB OLUWATOYIN USMAN | C31: ASST. ADMIN. OFFICER | D31: 10(8) | E31: 1484.37 | F31: =26339.08 -> 26339.08 | G31: =F31-E31 -> 24854.71
A32: 24 | B32: ELIZABETH OGECHUKWU ONYEAKU | C32: ICT OFFICER | D32: 9(7) | E32: 3369.51 | F32: =21640.95 -> 21640.95 | G32: =F32-E32 -> 18271.44
A33: 25 | B33: VICTOR ASUKWO | C33: ICT OFFICER | D33: 8 (10) | E33: 1484.37 | F33: =18102.9 -> 18102.9 | G33: =F33-E33 -> 16618.53
A34: 26 | B34: IJEOMA NKOLIKWA | C34: ASSISTANT STORES OFFICER | D34: 8(10) | E34: 1484.37 | F34: =18102.9 -> 18102.9 | G34: =F34-E34 -> 16618.53
A35: 27 | B35: ABDULRAHMAN A SULAIMAN | C35: ASSISTANT STORES OFFICER | D35: 8 (9) | E35: 1484.37 | F35: =17572.89 -> 17572.89 | G35: =F35-E35 -> 16088.52
A36: 28 | B36: TASSNEEM IBRAHIM | C36: ASSIST. INFORMATION | D36: 8(9) | E36: 1484.37 | F36: =17572.89 -> 17572.89 | G36: =F36-E36 -> 16088.52
A37: 29 | B37: DARE SHEU MAGBON | C37: ASSIST. PG | D37: 8(9) | E37: 1484.37 | F37: =17572.89 -> 17572.89 | G37: =F37-E37 -> 16088.52
A38: 30 | B38: JIMOH ADEBAYO ZAKA | C38: ASST. OFFICER/COMM | D38: 8(7) | E38: 1484.37 | F38: =16512.68 -> 16512.68 | G38: =F38-E38 -> 15028.31
A39: 31 | B39: HABEEBA K MUHAMMAD SALIHU | C39: ASST. OFFICER/COMM | D39: 8(7) | E39: 1484.37 | F39: =16512.68 -> 16512.68 | G39: =F39-E39 -> 15028.31
A40: 32 | B40: MOHAMMED BELLO | C40: RESEARCH ASSITANT PG | D40: 8(7) | E40: 1484.37 | F40: =16512.68 -> 16512.68 | G40: =F40-E40 -> 15028.31
A41: 33 | B41: SULEIMAN ABUBAKAR SODEEQ | C41: ASST. ADMIN. OFFICER | D41: 8(7) | E41: 1484.37 | F41: =16512.68 -> 16512.68 | G41: =F41-E41 -> 15028.31
A42: 34 | B42: HARUNA JIBRIL A. | C42: ASST. ADMIN. OFFICER | D42: 8(7) | E42: 0 | F42: =16512.68 -> 16512.68 | G42: =F42-E42 -> 16512.68
B43: TOTAL | C43: 33 | E43: =SUM(E9:E42) -> 415827.18 | F43: =SUM(F9:F41) -> 1658278.6 | G43: =F43-E43 -> 1242451.4
...

Sheet Annual Increement
B3: STAFF PAYROLL FOR THE MONTH OF DECEMBER, 2021
F4: ='[1]FEB 08'!E8/'[1]FEB 08'!M8 -> 0.22 | I4: ='[1]FEB 08'!F8/'[1]FEB 08'!Q8 -> 0.3
B5: STAFF NAME
D6: DESIGNATION | E6: SALARY | F6: BASIC | M6: MOTOR/ | N6: RESEARCH | O6: HARDSHIP | P6: LEAVE | Q6: OUT FIT | R6: LEGISLATIVE | S6: NEW GROSS | T6: OLD GROSS | U6: DIFFERENCE
E7: LEVEL | F7: SALARY | G7: SALARY/ALLOWCE AREARS | H7: RENT | I7: UTILITY | J7: DOMESTIC | K7: ENTERT. | L7: FURNIT. | M7: FUEL | N7: ALLOWANCE | O7: ALLOWANCE | P7: ALLCE | Q7: ALLCE | R7: DUTY ALLCE | S7: SALARY | T7: SALARY | W7: OLD PAYE | X7: NEW PAYE | Y7: DIFFERENCE
A8: S/N | B8: DG OFFICE | F8: N | I8: N | S8: N | T8: N | U8: N | W8: N | X8: N | Y8: N
A9: 1 | B9: PROF. ABUBAKAR O. SULAIMAN | D9: DIRECTOR GENERAL | E9: CONSOL | F9: 160488.75 | H9: 320977.5 | I9: 48146.63 | J9: 120366.57 | K9: 72219.94 | L9: 0 | M9: 120366.57 | N9: =250000 -> 250000 | P9: 16048.88 | Q9: 25000 | R9: 25235 | S9: =R9+Q9+P9+O9+N9+M9+L9+K9+J9+I9+H9+G9+F9 -> 1158849.8 | T9: 1158849.8 | U9: =S9-T9 -> 0 | W9: 113176.97 | X9: 113176.97 | Y9: =X9-W9 -> 0
A10: 2 | B10: DR ADEYEMI AKEEB FAJINGBESI | D10: DIR. SPECIAL DUTIES, DG OFFICE | E10: 17(9) | F10: 81740.02 | H10: =F10*300% -> 245220.06 | I10: =F10*7.5% -> 6130.5015 | J10: 80244.38 | K10: =F10*50% -> 40870.01 | L10: =F10*350% -> 286090.07 | M10: =F10*100% -> 81740.02 | N10: =200000 -> 200000 | P10: =F10*10% -> 8174.002 | Q10: 20000 | R10: 0 | S10: =R10+Q10+P10+O10+N10+M10+L10+K10+J10+I10+H10+G10+F10 -> 1050209.1 | T10: 1050209.1 | U10: =S10-T10 -> 0 | W10: 52776.63 | X10: 52776.63 | Y10: =X10-W10 -> 0
