Workbook

Sheet MAY 2024
A1: NATIONAL INSTITUTE FOR LEGISLATIVE AND DEMOCRATIC STUDIES
A2: STAFF PAYROLL FOR THE MONTH OF MAY, 2024
E3: ='[1]FEB 08'!E11/'[1]FEB 08'!M11 -> #REF!
B4: STAFF NAME | C4: DESIGNATION | D4: GRADE LEVEL | E4: BASIC SALARY | F4: ALLCE/ AREARS | G4: ALLOWANCE | H4: ALLOWANCE | I4: DUTY ALLCE | J4: GROSS SALARY | K4: AUCTION | L4: COOP CONTR/SPEC SAVINGS | M4: COOP. LOAN RECOVERY | N4: NHF DED. | O4: PAYE | P4: EMPLOYEE PENSIONS | Q4: TOTAL DEDUCTION | R4: APRIL, 2024 | S4: MAY, 2024
E5: N | G5: N | H5: N | I5: N | J5: N | K5: N | L5: N | M5: N | N5: N | O5: N | P5: N | Q5: N | R5: N | S5: N
A6: S/N | B6: DG'S OFFICE
A7: 1 | B7: PROF. ABUBAKAR O. SULAIMAN | C7: DIRECTOR GENERAL | D7: CONSOL | E7: 1659751.2 | G7: =250000 -> 250000 | I7: 25235 | J7: =E7+F7+G7+H7+I7 -> 1934986.2 | O7: 350184.01 | Q7: =O7+N7+M7+L7+K7+P7 -> 350184.01 | R7: 1584802.2 | S7: =J7-Q7 -> 1584802.2
A8: 2 | B8: RAHEEM USMAN AYIGORO | C8: SA-INFRASTRUCTURE | D8: 16 (9) | E8: 762373.17 | H8: =90000 -> 90000 | I8: =100000 -> 100000 | J8: =E8+F8+G8+H8+I8 -> 952373.17 | L8: =250000 -> 250000 | O8: ='Additional Leg Duty Allowance'!P7 -> 149812.26 | P8: 60989.853 | Q8: =O8+N8+M8+L8+K8+P8 -> 460802.12 | R8: 641571.05 | S8: =J8-Q8 -> 491571.05
A9: 3 | B9: MARIAM MOHAMMED BELLO | C9: SA- SPECIAL DUTIES | D9: 16 (9) | E9: 762373.17 | H9: =90000 -> 90000 | I9: =200000+100000 -> 300000 | J9: =E9+F9+G9+H9+I9 -> 1152373.2 | O9: ='Additional Leg Duty Allowance'!P8 -> 199922.31 | Q9: =O9+N9+M9+L9+K9+P9 -> 199922.31 | R9: 952450.85 | S9: =J9-Q9 -> 952450.85
A10: 4 | B10: DR IKEME ARTHUR J.O | C10: DEPUTY DIRECTOR, M&E | D10: 16 (9) | E10: 762373.17 | G10: 180000 | I10: 0 | J10: =E10+F10+G10+H10+I10 -> 942373.17 | L10: =50000 -> 50000 | M10: 103000 | N10: 10293.398 | O10: 147687.53 | P10: 60989.853 | Q10: =O10+N10+M10+L10+K10+P10 -> 371970.78 | R10: 570402.39 | S10: =J10-Q10 -> 570402.39
A11: 5 | B11: MOSHOOD M. OLALERE | C11: DEPUTY DIR. GENERAL SERVICE | D11: 16 (9) | E11: 762373.17 | H11: =80000+10000 -> 90000 | I11: =150000+100000 -> 250000 | J11: =E11+F11+G11+H11+I11 -> 1102373.2 | L11: =20000+60000 -> 80000 | M11: ='[2]OCTOBER 2023 '!$D$193 -> 230499.8 | N11: 10293.398 | O11: ='Additional Leg Duty Allowance'!P9 -> 178407.53 | P11: 60989.853 | Q11: =O11+N11+M11+L11+K11+P11 -> 560190.58 | R11: 542182.59 | S11: =J11-Q11 -> 542182.59
A12: 6 | B12: REKIYA IBRAHIM ATTAH | C12: DEPUTY DIRECTOR TRAINING | D12: 16 (9) | E12: 762373.17 | H12: =90000 -> 90000 | I12: =100000+100000 -> 200000 | J12: =E12+F12+G12+H12+I12 -> 1052373.2 | L12: =50000 -> 50000 | M12: =91666.67 -> 91666.67 | O12: ='Additional Leg Duty Allowance'!P10 -> 180722.31 | Q12: =O12+N12+M12+L12+K12+P12 -> 322388.98 | R12: 729984.18 | S12: =J12-Q12 -> 729984.18
A13: 7 | B13: ANDRAWUS MUSA | C13: ASST. DIRECTOR, STORES | D13: 15(9) | E13: 620675.58 | H13: =80000 -> 80000 | I13: 50000 | J13: =E13+F13+G13+H13+I13 -> 750675.58 | L13: =50000-40000 -> 10000 | M13: =90000+110000 -> 200000 | N13: 8380.2271 | O13: 113101.97 | P13: 49654.047 | Q13: =O13+N13+M13+L13+K13+P13 -> 381136.24 | R13: 369539.34 | S13: =J13-Q13 -> 369539.34
A14: 8 | B14: DR FRANCIS NDUM OJIE | C14: AD, TRAINING & IC./SA TO DG | D14: 15(7) | E14: 582118.08 | G14: 160000 | I14: =100000+100000 -> 200000 | J14: =E14+F14+G14+H14+I14 -> 942118.08 | N14: 7859.6313 | O14: ='Additional Leg Duty Allowance'!P12 -> 150463.11 | P14: 46569.447 | Q14: =O14+N14+M14+L14+K14+P14 -> 204892.19 | R14: 737225.9 | S14: =J14-Q14 -> 737225.9
A15: 9 | B15: ALI ABDULLAHI | C15: CHIEF ICT OFFICER | D15: 14(11) | E15: 484373.75 | H15: =70000 -> 70000 | I15: =0 -> 0 | J15: =E15+F15+G15+H15+I15 -> 554373.75 | O15: 77666.446 | P15: 38749.9 | Q15: =O15+N15+M15+L15+K15+P15 -> 116416.35 | R15: 437957.4 | S15: =J15-Q15 -> 437957.4
A16: 10 | B16: EMILY EKHIDE | C16: RESEARCH FELLOW 1 | D16: 14(10) | E16: 470498 | G16: 140000 | I16: =50000+100000 -> 150000 | J16: =E16+F16+G16+H16+I16 -> 760498 | L16: =50000 -> 50000 | O16: 98255.433 | P16: 37639.84 | Q16: =O16+N16+M16+L16+K16+P16 -> 185895.27 | R16: 574602.73 | S16: =J16-Q16 -> 574602.73
A17: 11 | B17: DORIS DAKDA AARON | C17: RESEARCH FELLOW I | D17: 14(8) | E17: 442746.5 | G17: =140000 -> 140000 | I17: =150000+100000 -> 250000 | J17: =E17+F17+G17+H17+I17 -> 832746.5 | L17: 70000 | O17: ='Additional Leg Duty Allowance'!P13 -> 131753.41 | P17: 35419.72 | Q17: =O17+N17+M17+L17+K17+P17 -> 237173.13 | R17: 595573.37 | S17: =J17-Q17 -> 595573.37
A18: 12 | B18: ABDULSALAM S. MUSTAPHA | C18: ASST. MANAGER ICT | D18: 13(11) | E18: 441804.92 | H18: 70000 | J18: =E18+F18+G18+H18+I18 -> 511804.92 | O18: 70147.087 | P18: 35344.393 | Q18: =O18+N18+M18+L18+K18+P18 -> 105491.48 | R18: 406313.44 | S18: =J18-Q18 -> 406313.44
A19: 13 | B19: PERCY TERFA GBAHABO | C19: HEAD, NILDS LIAISON OFFICE | D19: 13(10) | E19: 428915.92 | G19: =120000 -> 120000 | I19: 0 | J19: =E19+F19+G19+H19+I19 -> 548915.92 | L19: =50000 -> 50000 | M19: 105000 | O19: 77470.374 | P19: 34313.273 | Q19: =O19+N19+M19+L19+K19+P19 -> 266783.65 | R19: 282132.27 | S19: =J19-Q19 -> 282132.27
A20: 14 | B20: HASSANA AHMED IBRAHIM | C20: PA- TO DG | D20: 13 (9) | E20: 416026.92 | G20: =120000 -> 120000 | I20: =100000+100000 -> 200000 | J20: =E20+F20+G20+H20+I20 -> 736026.92 | L20: =30000-20000 -> 10000 | M20: =95833.33 -> 95833.33 | N20: 5607.1771 | O20: ='Additional Leg Duty Allowance'!P14 -> 113474.9 | P20: 33282.153 | Q20: =O20+N20+M20+L20+K20+P20 -> 258197.56 | R20: 477829.35 | S20: =J20-Q20 -> 477829.35
A21: 15 | B21: ADUGBA RICHARD TERSEER | C21: PRINCIPAL INFO. OFFICER | D21: 12(9) | E21: 377895.17 | H21: =60000 -> 60000 | I21: 100000 | J21: =E21+F21+G21+H21+I21 -> 537895.17 | L21: =20000+30000 -> 50000 | M21: =111833.33 -> 111833.33 | O21: 76138.069 | P21: 30231.613 | Q21: =O21+N21+M21+L21+K21+P21 -> 268203.01 | R21: 269692.15 | S21: =J21-Q21 -> 269692.15
A22: 16 | B22: LUCKY AGWOM | C22: RESEARCH ASSISTANT | D22: 12(7) | E22: 353512.5 | G22: =100000 -> 100000 | I22: =100000+100000 -> 200000 | J22: =E22+F22+G22+H22+I22 -> 653512.5 | L22: =50000+100000 -> 150000 | O22: ='Additional Leg Duty Allowance'!P15 -> 98711.115 | P22: 28281 | Q22: =O22+N22+M22+L22+K22+P22 -> 276992.11 | R22: 376520.39 | S22: =J22-Q22 -> 376520.39
A23: 17 | B23: IDRIS IBRAHIM | C23: PRINCIPAL RESEARCH OFFICER | D23: 12(7) | E23: 353512.5 | G23: 110000 | I23: 0 | J23: =E23+F23+G23+H23+I23 -> 463512.5 | L23: 0 | O23: 62231.115 | P23: 28281 | Q23: =O23+N23+M23+L23+K23+P23 -> 90512.115 | R23: 373000.39 | S23: =J23-Q23 -> 373000.39
A24: 18 | B24: FARUQ ATOFARATI | C24: PA (SPECIAL DUTIES) TO DG | D24: 10(7) | E24: 293029.67 | H24: =50000+10000 -> 60000 | I24: =100000+100000 -> 200000 | J24: =E24+F24+G24+H24+I24 -> 553029.67 | L24: 130000 | O24: ='Additional Leg Duty Allowance'!P16 -> 80347.427 | P24: 23442.373 | Q24: =O24+N24+M24+L24+K24+P24 -> 233789.8 | R24: 319239.87 | S24: =J24-Q24 -> 319239.87
A25: 19 | B25: ELIZABETH OGECHUKWU ONYEAKU | C25: ICT OFFICER | D25: 9(9) | E25: 270481.67 | H25: =50000+10000 -> 60000 | J25: =E25+F25+G25+H25+I25 -> 330481.67 | L25: 10000 | M25: =20000 -> 20000 | O25: 39052.313 | P25: 21638.533 | Q25: =O25+N25+M25+L25+K25+P25 -> 90690.846 | R25: 239790.82 | S25: =J25-Q25 -> 239790.82
A26: 20 | B26: VICTOR ASUKWO | C26: ICT OFFICER | D26: 9(9) | E26: 270481.67 | H26: =50000+10000 -> 60000 | J26: =E26+F26+G26+H26+I26 -> 330481.67 | O26: 39052.313 | P26: 21638.533 | Q26: =O26+N26+M26+L26+K26+P26 -> 60690.846 | R26: 269790.82 | S26: =J26-Q26 -> 269790.82
A27: 21 | B27: NNANDI LIVINUS ATURE | C27: RESEARCH ASSISTANT | D27: 9(9) | E27: 270481.67 | G27: =100000 -> 100000 | J27: =E27+F27+G27+H27+I27 -> 370481.67 | L27: =10000 -> 10000 | M27: =95833.33 -> 95833.33 | O27: 45772.313 | P27: 21638.533 | Q27: =O27+N27+M27+L27+K27+P27 -> 173244.18 | R27: 197237.49 | S27: =J27-Q27 -> 197237.49
A28: 22 | B28: ABDULRAHMAN A SULAIMAN | C28: STORE OFFICER | D28: 9(8) | E28: 263165.33 | H28: =60000 -> 60000 | J28: =E28+F28+G28+H28+I28 -> 323165.33 | L28: =20000 -> 20000 | M28: =17500 -> 17500 | O28: 37921.501 | P28: 21053.227 | Q28: =O28+N28+M28+L28+K28+P28 -> 96474.727 | R28: 226690.61 | S28: =J28-Q28 -> 226690.61
A29: 23 | B29: DARE SHEU MAGBON | C29: ADMINISTRATION OFFICER | D29: 9(7) | E29: 255849 | H29: =60000 -> 60000 | J29: =E29+F29+G29+H29+I29 -> 315849 | L29: =30000+20000 -> 50000 | M29: 0 | O29: 36790.688 | P29: 20467.92 | Q29: =O29+N29+M29+L29+K29+P29 -> 107258.61 | R29: 208590.39 | S29: =J29-Q29 -> 208590.39
A30: 24 | B30: ABUBAKAR SULAIMAN SODEEQ | C30: ADMINISTRATION OFFICER | D30: 9(7) | E30: 255849 | H30: =60000 -> 60000 | J30: =E30+F30+G30+H30+I30 -> 315849 | M30: 0 | O30: 36790.688 | P30: 20467.92 | Q30: =O30+N30+M30+L30+K30+P30 -> 57258.608 | R30: 258590.39 | S30: =J30-Q30 -> 258590.39
A31: 25 | B31: JIMOH ADEBAYO ZAKA | C31: ASST. OFFICER/COMM | D31: 9(9) | E31: 270481.67 | H31: =60000 -> 60000 | J31: =E31+F31+G31+H31+I31 -> 330481.67 | L31: =50000+50000 -> 100000 | M31: 50000 | O31: 39052.313 | P31: 21638.533 | Q31: =O31+N31+M31+L31+K31+P31 -> 210690.85 | R31: 119790.82 | S31: =J31-Q31 -> 119790.82
A32: 26 | B32: MOHAMMED BELLO | C32: PROTOCOL ASSISTANT | D32: 8(9) | E32: 230631.92 | H32: =50000 -> 50000 | J32: =E32+F32+G32+H32+I32 -> 280631.92 | L32: =0 -> 0 | M32: =26666.67 -> 26666.67 | O32: 31213.136 | P32: 18450.553 | Q32: =O32+N32+M32+L32+K32+P32 -> 76330.359 | R32: 204301.56 | S32: =J32-Q32 -> 204301.56
A33: 27 | B33: HARUNA JIBRIL AMEH | C33: ASST. ADMIN. OFFICER | D33: 8(8) | E33: 224459.75 | H33: 50000 | J33: =E33+F33+G33+H33+I33 -> 274459.75 | L33: 20000 | M33: 0 | O33: 30259.166 | P33: 17956.78 | Q33: =O33+N33+M33+L33+K33+P33 -> 68215.946 | R33: 206243.8 | S33: =J33-Q33 -> 206243.8
B34: TOTAL | C34: 27 | E34: 13048608 | F34: =SUM(F7:F33) -> 0 | G34: =SUM(G7:G33) -> 1420000 | H34: =SUM(H7:H33) -> 1160000 | I34: =SUM(I7:I33) -> 2225235 | J34: =SUM(J7:J33) -> 17853843 | K34: =SUM(K7:K33) -> 0 | L34: =SUM(L7:L33) -> 1160000 | M34: =SUM(M7:M33) -> 1147833.1 | ... Q34: =SUM(Q7:Q33) -> 5831796.7 | R34: 12172047 | S34: =SUM(S7:S33) -> 12022047
B36: INTERNAL AUDIT
A37: 1 | B37: OSANAIYE DAVID AKINYEMI | C37: DIRECTOR INTERNAL AUDIT | D37: 17(9) | E37: 1435720 | H37: =100000 -> 100000 | J37: =SUM(E37:I37) -> 1535720 | K37: ='MAY 2024'!F196 -> 0 | L37: =200000+200000 -> 400000 | M37: 0 | O37: 251472.25 | P37: 114857.6 | Q37: =O37+N37+M37+L37+K37+P37 -> 766329.85 | R37: 769390.15 | S37: =J37-Q37 -> 769390.15
A38: 2 | B38: JAMILA ABDUL | C38: SENIOR INTERNAL AUDITOR | D38: 10(7) | E38: 293029.67 | H38: =60000 -> 60000 | J38: =SUM(E38:I38) -> 353029.67 | L38: =20000 -> 20000 | O38: 42537.332 | P38: 23442.373 | Q38: =O38+N38+M38+L38+K38+P38 -> 85979.705 | R38: 267049.96 | S38: =J38-Q38 -> 267049.96
A39: 3 | B39: IJEOMA EWELUKWA | C39: SENIOR INTERNAL AUDITOR | D39: 10(8) | E39: 300965.58 | H39: =50000+10000 -> 60000 | J39: =SUM(E39:I39) -> 360965.58 | L39: =10000 -> 10000 | O39: 43763.907 | P39: 24077.247 | Q39: =O39+N39+M39+L39+K39+P39 -> 77841.154 | R39: 283124.43 | S39: =J39-Q39 -> 283124.43
C40: 3 | E40: 2029715.2 | F40: =SUM(F37:F39) -> 0 | G40: =SUM(G37:G39) -> 0 | H40: =SUM(H37:H39) -> 220000 | I40: =SUM(I37:I39) -> 0 | J40: =SUM(J37:J39) -> 2249715.2 | K40: =SUM(K37:K39) -> 0 | L40: =SUM(L37:L39) -> 430000 | M40: =SUM(M37:M39) -> 0 | N40: 0 | O40: 337773.49 | P40: =SUM(P37:P39) -> 162377.22 | Q40: =SUM(Q37:Q39) -> 930150.71 | R40: 1319564.5 | S40: =SUM(S37:S39) -> 1319564.5
B42: LEG. SUPPORT SEVICES
...

Sheet MEMO
A2: NATIONAL INSTITUTE FOR LEGISLATIVE AND DEMOCRATIC STUDIES
A3: INTERNAL MEMO
A4: FROM : DEPUTY DIRECTOR, FINANCE AND ACCOUNTS
A5: THRU: DIRECTOR, FINANCE AND ACCOUNTS
A6: TO: DG
A7: 29TH JANUARY , 2021
A9: SUBJECT: PAYROLL FOR THE MONTH OF JANUARY, 2021
A10: Find below the details of NILDS Staff Payroll for the month of January, 2021
A13: TO: | C13: DIRECTOR, GENERAL
A14: THRU: | C14: DIRECTOR, FINANCE AND ACCOUNT
A15: FROM: | C15: DEPUTY DIRECTOR, FINANCE AND ACCOUNTS
A16: DATE: | C16: 29TH MAY 2024
A18: SUBJECT: PAYROLL FOR THE MONTH OF MAY 2024
A19: Find below the details of NILDS Staff Payroll for the Month of May, 2024: | G19: NGN | H19: NGN
A20: GROSS SALARY FOR MAY, 2024 | H20: ='MAY 2024'!J194 -> 80911797
A22: DEDUCTIONS
A23: COOP SOCIETY DEDUCTIONS ( CONTR.& SPEC. SAVINGS) | G23: ='MAY 2024'!L194 -> 6373500
A24: COOP LOAN RECOVERY | G24: ='MAY 2024'!M194 -> 7974625
A25: NHF DEDUCTIONS | G25: ='MAY 2024'!N194 -> 226658.47
A26: PAYE DEDUCTIONS | G26: ='MAY 2024'!O194 -> 11600740
A27: PENSION DEDUCTIONS | G27: ='MAY 2024'!P194 -> 4618348.5
A28: TOTAL DEDUCTIONS FOR MAY 2024 | H28: =G23+G24+G26+G25+G27 -> 30793872
A29: NET PAY AS PER MAY 2024 PAYROLL | H29: =H20-H28 -> 50117925
A30: NET PAY AS PER APRIL, 2024 PAYROLL | H30: ='MAY 2024'!R194 -> 51163557
A31: NET INCREASE/ (DECREASE) IN PAY FOR MAY, 2024 | H31: =H29-H30 -> -1045631.5
A32: ANALYSED AS FOLLOWS:
A33: Effect of Cooperative Adjustment for May, 2024 | H33: =593151.54 -> 593151.54
A34: Effect of Removal of Arrears of Ayobolu Olufunsho | H34: =452480 -> 452480
H35: =SUM(H33:H34) -> 1045631.5
E37: APRIL, 2024 | G37: MAY, 2024
E38: No. of Staff | F38: N | G38: No. of Staff | H38: N
A39: 1 | B39: Director General's Office | E39: 33 | F39: ='MAY 2024'!R34 -> 12172047 | G39: ='MAY 2024'!C34 -> 27 | H39: ='MAY 2024'!S34 -> 12022047
A40: 2 | B40: Internal Audit | E40: 2 | F40: ='MAY 2024'!R40 -> 1319564.5 | G40: ='MAY 2024'!C40 -> 3 | H40: ='MAY 2024'!S40 -> 1319564.5
A41: 3 | B41: Legis. Support Services | E41: 11 | F41: ='MAY 2024'!R54 -> 4657183.5 | G41: ='MAY 2024'!C54 -> 11 | H41: ='MAY 2024'!S54 -> 4410412.5
A42: 4 | B42: Legal Services | E42: 2 | F42: ='MAY 2024'!R59 -> 1482548.9 | G42: ='MAY 2024'!C59 -> 2 | H42: ='MAY 2024'!S59 -> 1482548.9
A43: 5 | B43: Democracy and Governance | E43: 13 | F43: ='MAY 2024'!R72 -> 3282337.7 | G43: ='MAY 2024'!C72 -> 12 | H43: ='MAY 2024'!S72 -> 3282337.7
A44: 6 | B44: Studies | E44: 4 | F44: ='MAY 2024'!R82 -> 3760018.2 | G44: ='MAY 2024'!C82 -> 7 | H44: ='MAY 2024'!S82 -> 3193417.3
A45: 7 | B45: Economic Dev. & Social Research | E45: 12 | F45: ='MAY 2024'!R95 -> 4131549.2 | G45: ='MAY 2024'!C95 -> 11 | H45: ='MAY 2024'!S95 -> 4131549.2
A46: 8 | B46: Training & Int'l Cooperation | E46: 4 | F46: ='MAY 2024'!R102 -> 1779231.7 | G46: ='MAY 2024'!C102 -> 4 | H46: ='MAY 2024'!S102 -> 1791538
A47: 9 | B47: Library & Documentation | E47: 8 | F47: ='MAY 2024'!R112 -> 3185436 | G47: ='MAY 2024'!C112 -> 7 | H47: ='MAY 2024'!S112 -> 3139602.7
...

Sheet Arrears of Res. Allow
D1: OLD PAYE | E1: ADJUSTED PAYE | F1: DIFFERENCE | G1: FOR 7 MONTHS | H1: TOTAL DIFF IN RES ALLOW | I1: NET DIFFERENCE
A2: AYOBOLU OLAJIDE OLUFUNSHO | B2: ASST.DIR., INFORMATION | C2: 15 (9) | D2: =64596.94 -> 64596.94 | E2: =79956.94 -> 79956.94 | F2: =E2-D2 -> 15360 | G2: =F2*7 -> 107520 | H2: 560000 | I2: =H2-G2 -> 452480

Sheet Additional Leg Duty Allowance
A1: NATIONAL INSTITUTE FOR LEGISLATIVE AND DEMOCRATIC STUDIES
A2: STAFF PAYROLL FOR THE MONTH OF MARCH, 2024
E3: ='[1]FEB 08'!E11/'[1]FEB 08'!M11 -> #REF!
B4: STAFF NAME | C4: DESIGNATION | D4: GRADE LEVEL | E4: BASIC SALARY | F4: ALLCE/ AREARS | G4: ALLOWANCE | H4: ALLOWANCE | I4: DUTY ALLCE | J4: GROSS SALARY | K4: AUCTION | L4: COOP CONTR/SPEC SAVINGS | M4: COOP. LOAN RECOVERY | N4: NHF DED. | O4: PAYE | P4: NEW PAYE | Q4: DIFFERENCE | R4: EMPLOYEE PENSIONS | S4: TOTAL DEDUCTION | T4: FEBRUARY, 2024 | U4: MARCH, 2024
E5: N | G5: N | H5: N | I5: N | J5: N | K5: N | L5: N | M5: N | N5: N | O5: N | P5: N | Q5: N | R5: N | S5: N | T5: N | U5: N
A6: S/N | B6: DG'S OFFICE
A7: 1 | B7: RAHEEM USMAN AYIGORO | C7: SA-INFRASTRUCTURE | D7: 16 (9) | E7: 762373.17 | H7: =90000 -> 90000 | I7: 0 | J7: =E7+F7+G7+H7+I7 -> 852373.17 | L7: =100000 -> 100000 | O7: 130612.26 | P7: ='March New PAYE '!Z7 -> 149812.26 | Q7: =P7-O7 -> 19200 | R7: 60989.853 | S7: =O7+N7+M7+L7+K7+R7 -> 291602.12 | T7: 560771.05 | U7: =J7-S7 -> 560771.05
A8: 2 | B8: MARIAM MOHAMMED BELLO | C8: SA- SPECIAL DUTIES | D8: 16 (9) | E8: 762373.17 | H8: =90000 -> 90000 | I8: =100000+100000 -> 200000 | J8: =E8+F8+G8+H8+I8 -> 1052373.2 | O8: 180722.31 | P8: ='March New PAYE '!Z8 -> 199922.31 | Q8: =P8-O8 -> 19200 | S8: =O8+N8+M8+L8+K8+R8 -> 180722.31 | T8: 871650.85 | U8: =J8-S8 -> 871650.85
A9: 3 | B9: MOSHOOD M. OLALERE | C9: DEPUTY DIR. GENERAL SERVICE | D9: 16 (9) | E9: 762373.17 | H9: =80000+10000 -> 90000 | I9: 150000 | J9: =E9+F9+G9+H9+I9 -> 1002373.2 | L9: =20000+60000 -> 80000 | M9: ='[2]OCTOBER 2023 '!$D$193 -> 230499.8 | N9: 1066.3293 | O9: 159207.53 | P9: ='March New PAYE '!Z10 -> 178407.53 | Q9: =P9-O9 -> 19200 | R9: 60989.853 | S9: =O9+N9+M9+L9+K9+R9 -> 531763.51 | T9: 470609.66 | U9: =J9-S9 -> 470609.66
A10: 4 | B10: REKIYA IBRAHIM ATTAH | C10: DEPUTY DIRECTOR TRAINING | D10: 16 (9) | E10: 762373.17 | H10: =90000 -> 90000 | I10: 100000 | J10: =E10+F10+G10+H10+I10 -> 952373.17 | L10: =50000 -> 50000 | M10: =91666.67 -> 91666.67 | O10: 161522.31 | P10: ='March New PAYE '!Z11 -> 180722.31 | Q10: =P10-O10 -> 19200 | S10: =O10+N10+M10+L10+K10+R10 -> 303188.98 | T10: 649184.18 | U10: =J10-S10 -> 649184.18
A11: 5 | B11: TERFA WILLIAMS ABRAHAM | C11: SNR RESEARCH FELLOW | D11: 15(9) | E11: 620675.58 | G11: =160000 -> 160000 | I11: 100000 | J11: =SUM(E11:I11) -> 880675.58 | O11: 138222.8 | P11: ='March New PAYE '!Z80 -> 157422.8 | Q11: =P11-O11 -> 19200 | R11: 49654.047 | S11: =O11+N11+M11+L11+K11+R11 -> 187876.85 | T11: 692798.73 | U11: =J11-S11 -> 692798.73
A12: 6 | B12: DR FRANCIS NDUM OJIE | C12: AD, TRAINING & IC./SA TO DG | D12: 15(7) | E12: 582118.08 | G12: 160000 | I12: =100000 -> 100000 | J12: =E12+F12+G12+H12+I12 -> 842118.08 | N12: 775.496 | O12: 131263.11 | P12: ='March New PAYE '!Z13 -> 150463.11 | Q12: =P12-O12 -> 19200 | R12: 46569.447 | S12: =O12+N12+M12+L12+K12+R12 -> 178608.05 | T12: 663510.03 | U12: =J12-S12 -> 663510.03
A13: 7 | B13: DORIS DAKDA AARON | C13: RESEARCH FELLOW I | D13: 14(8) | E13: 442746.5 | G13: =140000 -> 140000 | I13: 150000 | J13: =E13+F13+G13+H13+I13 -> 732746.5 | L13: 70000 | O13: 112553.41 | P13: ='March New PAYE '!Z16 -> 131753.41 | Q13: =P13-O13 -> 19200 | R13: 35419.72 | S13: =O13+N13+M13+L13+K13+R13 -> 217973.13 | T13: 514773.37 | U13: =J13-S13 -> 514773.37
A14: 8 | B14: HASSANA AHMED IBRAHIM | C14: PA- TO DG | D14: 13 (9) | E14: 416026.92 | G14: =120000 -> 120000 | I14: =100000 -> 100000 | J14: =E14+F14+G14+H14+I14 -> 636026.92 | L14: =30000-20000 -> 10000 | M14: =95833.33 -> 95833.33 | N14: 618.5315 | O14: 94274.903 | P14: ='March New PAYE '!Z19 -> 113474.9 | Q14: =P14-O14 -> 19200 | R14: 33282.153 | S14: =O14+N14+M14+L14+K14+R14 -> 234008.92 | T14: 402018 | U14: =J14-S14 -> 402018
A15: 9 | B15: LUCKY AGWOM | C15: RESEARCH ASSISTANT | D15: 12(7) | E15: 353512.5 | G15: =100000 -> 100000 | I15: 100000 | J15: =E15+F15+G15+H15+I15 -> 553512.5 | L15: 50000 | O15: 79511.115 | P15: ='March New PAYE '!Z21 -> 98711.115 | Q15: =P15-O15 -> 19200 | R15: 28281 | S15: =O15+N15+M15+L15+K15+R15 -> 157792.11 | T15: 395720.39 | U15: =J15-S15 -> 395720.39
A16: 10 | B16: FARUQ ATOFARATI | C16: PA (SPECIAL DUTIES) TO DG | D16: 10(7) | E16: 293029.67 | H16: =50000+10000 -> 60000 | I16: 100000 | J16: =E16+F16+G16+H16+I16 -> 453029.67 | O16: 61147.427 | P16: ='March New PAYE '!Z23 -> 80347.427 | Q16: =P16-O16 -> 19200 | R16: 23442.373 | S16: =O16+N16+M16+L16+K16+R16 -> 84589.8 | T16: 368439.87 | U16: =J16-S16 -> 368439.87
B17: TOTAL | C17: 10 | E17: 14898686 | G17: =SUM(#REF!) -> #REF! | H17: =SUM(#REF!) -> #REF! | I17: =SUM(#REF!) -> #REF! | J17: =SUM(#REF!) -> #REF! | K17: =SUM(#REF!) -> #REF! | L17: =SUM(#REF!) -> #REF! | M17: =SUM(#REF!) -> #REF! | N17: 6347.233 | O17: =SUM(O7:O16) -> 1249037.2 | P17: =SUM(P7:P16) -> 1441037.2 | Q17: =SUM(Q7:Q16) -> 192000 | R17: 1130905.1 | S17: =SUM(#REF!) -> #REF! | T17: 11108681 | U17: =SUM(#REF!) -> #REF!
J19: PREPARED BY: Rahila N. Habu SIGNATURE……………….. DATE: 29TH JANUARY, 2024

Sheet March New PAYE 
A1: NATIONAL INSTITUTE FOR LEGISLATIVE AND DEMOCRATIC STUDIES
A2: NATIONAL ASSEMBLY ABUJA
A3: TAX COMPUTATION FOR 2022
A4: S/NO | B4: NAME | C4: MONTHLY TOTAL SALARY | D4: NO OF MONTHS | E4: ANNUAL SALARY GROSSED UP | F4: NATIONAL HOUSING SCHEME = 2.5% OF BASIC SALARY | G4: PENSION CONTRIBUTION = 8% OF CONSOLIDATED | H4: NHIS | I4: NET SALARY (EXC OF CRA) | M4: CRA=#200,000+(20% 0F NET SALARY (EXC OF CRA) | N4: TOTAL RELIEF | O4: CHARGEABLE INCOME | P4: FIRST N300,000 @ 7% | Q4: NEXT N300,000 @ 11% | R4: NEXT N500,000 @ 15% | S4: NEXT N500,000@ 19% | T4: NEXT N1,600,000 @ 21% | U4: ABOVE N3,200,000 @ 24% | V4: ANNUAL TAX PAYABLE | X4: MONTHLY TAX PAYABLE | Y4: MINIMUM TAX PAYABLE | Z4: NEW ACTUAL TAX PAYABLE | AB4: Difference
A5: 1 | B5: DG'S OFFICE
A6: 3 | B6: PROF. ABUBAKAR O. SULAIMAN | C6: 1934986.2 | D6: 12 | E6: =C6*D6 -> 23219834 | I6: =E6-F6-G6-H6 -> 23219834 | J6: 200000 | K6: 0.2 | L6: =I6*K6 -> 4643966.8 | M6: =J6+L6 -> 4843966.8 | N6: =F6+G6+H6+M6 -> 4843966.8 | O6: =E6-N6 -> 18375867 | P6: =IF(O6<300000,0.07*O6,21000) -> 21000 | Q6: =IF((O6-300000)<0,0,IF((O6-300000)<300000,0.11*(O6-300000),33000)) -> 33000 | R6: =IF((O6-600000)<0,0,IF((O6-600000)<500000,0.15*(O6-600000),75000)) -> 75000 | S6: =IF((O6-1100000)<0,0,IF((O6-1100000)<500000,0.19*(O6-1100000),95000)) -> 95000 | T6: =IF((O6-1600000)<0,0,IF((O6-1600000)<1600000,0.21*(O6-1600000),336000)) -> 336000 | U6: =24%*(O6-3200000) -> 3642208.1 | V6: =P6+Q6+R6+S6+T6+U6 -> 4202208.1 | W6: 12 | X6: =V6/W6 -> 350184.01 | Z6: =X6 -> 350184.01 | AA6: 201165.84 | AB6: =Z6-AA6 -> 149018.17
A7: 4 | B7: RAHEEM USMAN AYIGORO | C7: =852373.166666667+100000 -> 952373.17 | D7: 12 | E7: =C7*D7 -> 11428478 | G7: 731878.24 | I7: =E7-F7-G7-H7 -> 10696600 | J7: 200000 | K7: 0.2 | L7: =I7*K7 -> 2139320 | M7: =J7+L7 -> 2339320 | N7: =F7+G7+H7+M7 -> 3071198.2 | O7: =E7-N7 -> 8357279.8 | P7: =IF(O7<300000,0.07*O7,21000) -> 21000 | Q7: =IF((O7-300000)<0,0,IF((O7-300000)<300000,0.11*(O7-300000),33000)) -> 33000 | R7: =IF((O7-600000)<0,0,IF((O7-600000)<500000,0.15*(O7-600000),75000)) -> 75000 | S7: =IF((O7-1100000)<0,0,IF((O7-1100000)<500000,0.19*(O7-1100000),95000)) -> 95000 | T7: =IF((O7-1600000)<0,0,IF((O7-1600000)<1600000,0.21*(O7-1600000),336000)) -> 336000 | U7: =24%*(O7-3200000) -> 1237747.2 | V7: =P7+Q7+R7+S7+T7+U7 -> 1797747.2 | W7: 12 | X7: =V7/W7 -> 149812.26 | Z7: =X7 -> 149812.26 | AA7: 82627.951 | AB7: =Z7-AA7 -> 67184.311
A8: 5 | B8: MARIAM MOHAMMED BELLO | C8: =1052373.16666667+100000 -> 1152373.2 | D8: 12 | E8: =C8*D8 -> 13828478 | G8: 0 | I8: =E8-F8-G8-H8 -> 13828478 | J8: 200000 | K8: 0.2 | L8: =I8*K8 -> 2765695.6 | M8: =J8+L8 -> 2965695.6 | N8: =F8+G8+H8+M8 -> 2965695.6 | O8: =E8-N8 -> 10862782 | P8: =IF(O8<300000,0.07*O8,21000) -> 21000 | Q8: =IF((O8-300000)<0,0,IF((O8-300000)<300000,0.11*(O8-300000),33000)) -> 33000 | R8: =IF((O8-600000)<0,0,IF((O8-600000)<500000,0.15*(O8-600000),75000)) -> 75000 | S8: =IF((O8-1100000)<0,0,IF((O8-1100000)<500000,0.19*(O8-1100000),95000)) -> 95000 | T8: =IF((O8-1600000)<0,0,IF((O8-1600000)<1600000,0.21*(O8-1600000),336000)) -> 336000 | U8: =24%*(O8-3200000) -> 1839067.8 | V8: =P8+Q8+R8+S8+T8+U8 -> 2399067.8 | W8: 12 | X8: =V8/W8 -> 199922.31 | Z8: =X8 -> 199922.31 | AA8: 121027.95 | AB8: =Z8-AA8 -> 78894.363
A9: 6 | B9: DR IKEME ARTHUR J.O | C9: 942373.17 | D9: 12 | E9: =C9*D9 -> 11308478 | F9: ='[5]JANUARY 2024'!$V$10*12 -> 12795.951 | G9: 731878.24 | I9: =E9-F9-G9-H9 -> 10563804 | J9: 200000 | K9: 0.2 | L9: =I9*K9 -> 2112760.8 | M9: =J9+L9 -> 2312760.8 | N9: =F9+G9+H9+M9 -> 3057435 | O9: =E9-N9 -> 8251043 | P9: =IF(O9<300000,0.07*O9,21000) -> 21000 | Q9: =IF((O9-300000)<0,0,IF((O9-300000)<300000,0.11*(O9-300000),33000)) -> 33000 | R9: =IF((O9-600000)<0,0,IF((O9-600000)<500000,0.15*(O9-600000),75000)) -> 75000 | S9: =IF((O9-1100000)<0,0,IF((O9-1100000)<500000,0.19*(O9-1100000),95000)) -> 95000 | T9: =IF((O9-1600000)<0,0,IF((O9-1600000)<1600000,0.21*(O9-1600000),336000)) -> 336000 | U9: =24%*(O9-3200000) -> 1212250.3 | V9: =P9+Q9+R9+S9+T9+U9 -> 1772250.3 | W9: 12 | X9: =V9/W9 -> 147687.53 | Z9: =X9 -> 147687.53 | AA9: 99703.216 | AB9: =Z9-AA9 -> 47984.311
A10: 7 | B10: MOSHOOD M. OLALERE | C10: =1002373.16666667+100000 -> 1102373.2 | D10: 12 | E10: =C10*D10 -> 13228478 | F10: ='[5]JANUARY 2024'!$V$10*12 -> 12795.951 | G10: 731878.24 | I10: =E10-F10-G10-H10 -> 12483804 | J10: 200000 | K10: 0.2 | L10: =I10*K10 -> 2496760.8 | M10: =J10+L10 -> 2696760.8 | N10: =F10+G10+H10+M10 -> 3441435 | O10: =E10-N10 -> 9787043 | P10: =IF(O10<300000,0.07*O10,21000) -> 21000 | Q10: =IF((O10-300000)<0,0,IF((O10-300000)<300000,0.11*(O10-300000),33000)) -> 33000 | R10: =IF((O10-600000)<0,0,IF((O10-600000)<500000,0.15*(O10-600000),75000)) -> 75000 | S10: =IF((O10-1100000)<0,0,IF((O10-1100000)<500000,0.19*(O10-1100000),95000)) -> 95000 | T10: =IF((O10-1600000)<0,0,IF((O10-1600000)<1600000,0.21*(O10-1600000),336000)) -> 336000 | U10: =24%*(O10-3200000) -> 1580890.3 | V10: =P10+Q10+R10+S10+T10+U10 -> 2140890.3 | W10: 12 | X10: =V10/W10 -> 178407.53 | Z10: =X10 -> 178407.53 | AA10: 111223.22 | AB10: =Z10-AA10 -> 67184.311
A11: 8 | B11: REKIYA IBRAHIM ATTAH | C11: =952373.166666667+100000 -> 1052373.2 | D11: 12 | E11: =C11*D11 -> 12628478 | G11: 0 | I11: =E11-F11-G11-H11 -> 12628478 | J11: 200000 | K11: 0.2 | L11: =I11*K11 -> 2525695.6 | M11: =J11+L11 -> 2725695.6 | N11: =F11+G11+H11+M11 -> 2725695.6 | O11: =E11-N11 -> 9902782.4 | P11: =IF(O11<300000,0.07*O11,21000) -> 21000 | Q11: =IF((O11-300000)<0,0,IF((O11-300000)<300000,0.11*(O11-300000),33000)) -> 33000 | R11: =IF((O11-600000)<0,0,IF((O11-600000)<500000,0.15*(O11-600000),75000)) -> 75000 | S11: =IF((O11-1100000)<0,0,IF((O11-1100000)<500000,0.19*(O11-1100000),95000)) -> 95000 | T11: =IF((O11-1600000)<0,0,IF((O11-1600000)<1600000,0.21*(O11-1600000),336000)) -> 336000 | U11: =24%*(O11-3200000) -> 1608667.8 | V11: =P11+Q11+R11+S11+T11+U11 -> 2168667.8 | W11: 12 | X11: =V11/W11 -> 180722.31 | Z11: =X11 -> 180722.31 | AA11: 101827.95 | AB11: =Z11-AA11 -> 78894.363
A12: 9 | B12: ANDRAWUS MUSA | C12: 750675.58 | D12: 12 | E12: =C12*D12 -> 9008107 | F12: ='[5]JANUARY 2024'!$V$13*12 -> 10052.25 | G12: 595848.56 | I12: =E12-F12-G12-H12 -> 8402206.2 | J12: 200000 | K12: 0.2 | L12: =I12*K12 -> 1680441.2 | M12: =J12+L12 -> 1880441.2 | N12: =F12+G12+H12+M12 -> 2486342 | O12: =E12-N12 -> 6521765 | P12: =IF(O12<300000,0.07*O12,21000) -> 21000 | Q12: =IF((O12-300000)<0,0,IF((O12-300000)<300000,0.11*(O12-300000),33000)) -> 33000 | R12: =IF((O12-600000)<0,0,IF((O12-600000)<500000,0.15*(O12-600000),75000)) -> 75000 | S12: =IF((O12-1100000)<0,0,IF((O12-1100000)<500000,0.19*(O12-1100000),95000)) -> 95000 | T12: =IF((O12-1600000)<0,0,IF((O12-1600000)<1600000,0.21*(O12-1600000),336000)) -> 336000 | U12: =24%*(O12-3200000) -> 797223.59 | V12: =P12+Q12+R12+S12+T12+U12 -> 1357223.6 | W12: 12 | X12: =V12/W12 -> 113101.97 | Z12: =X12 -> 113101.97 | AA12: 74036.103 | AB12: =Z12-AA12 -> 39065.863
A13: 10 | B13: DR FRANCIS NDUM OJIE | C13: =842118.083333333+100000 -> 942118.08 | D13: 12 | E13: =C13*D13 -> 11305417 | F13: ='[5]JANUARY 2024'!$V$14*12 -> 9305.952 | G13: 558833.36 | I13: =E13-F13-G13-H13 -> 10737278 | J13: 200000 | K13: 0.2 | L13: =I13*K13 -> 2147455.5 | M13: =J13+L13 -> 2347455.5 | N13: =F13+G13+H13+M13 -> 2915594.8 | O13: =E13-N13 -> 8389822.2 | P13: =IF(O13<300000,0.07*O13,21000) -> 21000 | Q13: =IF((O13-300000)<0,0,IF((O13-300000)<300000,0.11*(O13-300000),33000)) -> 33000 | R13: =IF((O13-600000)<0,0,IF((O13-600000)<500000,0.15*(O13-600000),75000)) -> 75000 | S13: =IF((O13-1100000)<0,0,IF((O13-1100000)<500000,0.19*(O13-1100000),95000)) -> 95000 | T13: =IF((O13-1600000)<0,0,IF((O13-1600000)<1600000,0.21*(O13-1600000),336000)) -> 336000 | U13: =24%*(O13-3200000) -> 1245557.3 | V13: =P13+Q13+R13+S13+T13+U13 -> 1805557.3 | W13: 12 | X13: =V13/W13 -> 150463.11 | Z13: =X13 -> 150463.11 | AA13: 94625.782 | AB13: =Z13-AA13 -> 55837.328
A14: 11 | B14: ALI ABDULLAHI | C14: 554373.75 | D14: 12 | E14: =C14*D14 -> 6652485 | G14: 464998.8 | I14: =E14-F14-G14-H14 -> 6187486.2 | J14: 200000 | K14: 0.2 | L14: =I14*K14 -> 1237497.2 | M14: =J14+L14 -> 1437497.2 | N14: =F14+G14+H14+M14 -> 1902496 | O14: =E14-N14 -> 4749989 | P14: =IF(O14<300000,0.07*O14,21000) -> 21000 | Q14: =IF((O14-300000)<0,0,IF((O14-300000)<300000,0.11*(O14-300000),33000)) -> 33000 | R14: =IF((O14-600000)<0,0,IF((O14-600000)<500000,0.15*(O14-600000),75000)) -> 75000 | S14: =IF((O14-1100000)<0,0,IF((O14-1100000)<500000,0.19*(O14-1100000),95000)) -> 95000 | T14: =IF((O14-1600000)<0,0,IF((O14-1600000)<1600000,0.21*(O14-1600000),336000)) -> 336000 | U14: =24%*(O14-3200000) -> 371997.35 | V14: =P14+Q14+R14+S14+T14+U14 -> 931997.35 | W14: 12 | X14: =V14/W14 -> 77666.446 | Z14: =X14 -> 77666.446 | AA14: 44846.617 | AB14: =Z14-AA14 -> 32819.829
A15: 12 | B15: EMILY EKHIDE | C15: =660498 -> 660498 | D15: 12 | E15: =C15*D15 -> 7925976 | G15: 451678.08 | I15: =E15-F15-G15-H15 -> 7474297.9 | J15: 200000 | K15: 0.2 | L15: =I15*K15 -> 1494859.6 | M15: =J15+L15 -> 1694859.6 | N15: =F15+G15+H15+M15 -> 2146537.7 | O15: =E15-N15 -> 5779438.3 | P15: =IF(O15<300000,0.07*O15,21000) -> 21000 | Q15: =IF((O15-300000)<0,0,IF((O15-300000)<300000,0.11*(O15-300000),33000)) -> 33000 | R15: =IF((O15-600000)<0,0,IF((O15-600000)<500000,0.15*(O15-600000),75000)) -> 75000 | S15: =IF((O15-1100000)<0,0,IF((O15-1100000)<500000,0.19*(O15-1100000),95000)) -> 95000 | T15: =IF((O15-1600000)<0,0,IF((O15-1600000)<1600000,0.21*(O15-1600000),336000)) -> 336000 | U15: =24%*(O15-3200000) -> 619065.2 | V15: =P15+Q15+R15+S15+T15+U15 -> 1179065.2 | W15: 12 | X15: =V15/W15 -> 98255.433 | Z15: =X15 -> 98255.433 | AA15: 46666.667 | AB15: =Z15-AA15 -> 51588.767
A16: 13 | B16: DORIS DAKDA AARON | C16: =732746.5+100000 -> 832746.5 | D16: 12 | E16: =C16*D16 -> 9992958 | G16: 425036.64 | I16: =E16-F16-G16-H16 -> 9567921.4 | J16: 200000 | K16: 0.2 | L16: =I16*K16 -> 1913584.3 | M16: =J16+L16 -> 2113584.3 | N16: =F16+G16+H16+M16 -> 2538620.9 | O16: =E16-N16 -> 7454337.1 | P16: =IF(O16<300000,0.07*O16,21000) -> 21000 | Q16: =IF((O16-300000)<0,0,IF((O16-300000)<300000,0.11*(O16-300000),33000)) -> 33000 | R16: =IF((O16-600000)<0,0,IF((O16-600000)<500000,0.15*(O16-600000),75000)) -> 75000 | S16: =IF((O16-1100000)<0,0,IF((O16-1100000)<500000,0.19*(O16-1100000),95000)) -> 95000 | T16: =IF((O16-1600000)<0,0,IF((O16-1600000)<1600000,0.21*(O16-1600000),336000)) -> 336000 | U16: =24%*(O16-3200000) -> 1021040.9 | V16: =P16+Q16+R16+S16+T16+U16 -> 1581040.9 | W16: 12 | X16: =V16/W16 -> 131753.41 | Z16: =X16 -> 131753.41 | AA16: 46666.667 | AB16: =Z16-AA16 -> 85086.742
A17: 14 | B17: ABDULSALAM S. MUSTAPHA | C17: 511804.92 | D17: 12 | E17: =C17*D17 -> 6141659 | G17: 424132.72 | I17: =E17-F17-G17-H17 -> 5717526.3 | J17: 200000 | K17: 0.2 | L17: =I17*K17 -> 1143505.3 | M17: =J17+L17 -> 1343505.3 | N17: =F17+G17+H17+M17 -> 1767638 | O17: =E17-N17 -> 4374021 | P17: =IF(O17<300000,0.07*O17,21000) -> 21000 | Q17: =IF((O17-300000)<0,0,IF((O17-300000)<300000,0.11*(O17-300000),33000)) -> 33000 | R17: =IF((O17-600000)<0,0,IF((O17-600000)<500000,0.15*(O17-600000),75000)) -> 75000 | S17: =IF((O17-1100000)<0,0,IF((O17-1100000)<500000,0.19*(O17-1100000),95000)) -> 95000 | T17: =IF((O17-1600000)<0,0,IF((O17-1600000)<1600000,0.21*(O17-1600000),336000)) -> 336000 | U17: =24%*(O17-3200000) -> 281765.05 | V17: =P17+Q17+R17+S17+T17+U17 -> 841765.05 | W17: 12 | X17: =V17/W17 -> 70147.087 | Z17: =X17 -> 70147.087 | AA17: 42046.064 | AB17: =Z17-AA17 -> 28101.023
A18: 15 | B18: PERCY TERFA GBAHABO | C18: 548915.92 | D18: 12 | E18: =C18*D18 -> 6586991 | G18: 411759.28 | I18: =E18-F18-G18-H18 -> 6175231.7 | J18: 200000 | K18: 0.2 | L18: =I18*K18 -> 1235046.3 | M18: =J18+L18 -> 1435046.3 | N18: =F18+G18+H18+M18 -> 1846805.6 | O18: =E18-N18 -> 4740185.4 | P18: =IF(O18<300000,0.07*O18,21000) -> 21000 | Q18: =IF((O18-300000)<0,0,IF((O18-300000)<300000,0.11*(O18-300000),33000)) -> 33000 | R18: =IF((O18-600000)<0,0,IF((O18-600000)<500000,0.15*(O18-600000),75000)) -> 75000 | S18: =IF((O18-1100000)<0,0,IF((O18-1100000)<500000,0.19*(O18-1100000),95000)) -> 95000 | T18: =IF((O18-1600000)<0,0,IF((O18-1600000)<1600000,0.21*(O18-1600000),336000)) -> 336000 | U18: =24%*(O18-3200000) -> 369644.49 | V18: =P18+Q18+R18+S18+T18+U18 -> 929644.49 | W18: 12 | X18: =V18/W18 -> 77470.374 | Z18: =X18 -> 77470.374 | AA18: 46666.667 | AB18: =Z18-AA18 -> 30803.708
A19: 16 | B19: HASSANA AHMED IBRAHIM | C19: =636026.916666667+100000 -> 736026.92 | D19: 12 | E19: =C19*D19 -> 8832323 | F19: =618.53*12 -> 7422.36 | G19: 399385.84 | I19: =E19-F19-G19-H19 -> 8425514.8 | J19: 200000 | K19: 0.2 | L19: =I19*K19 -> 1685103 | M19: =J19+L19 -> 1885103 | N19: =F19+G19+H19+M19 -> 2291911.2 | O19: =E19-N19 -> 6540411.8 | P19: =IF(O19<300000,0.07*O19,21000) -> 21000 | Q19: =IF((O19-300000)<0,0,IF((O19-300000)<300000,0.11*(O19-300000),33000)) -> 33000 | R19: =IF((O19-600000)<0,0,IF((O19-600000)<500000,0.15*(O19-600000),75000)) -> 75000 | S19: =IF((O19-1100000)<0,0,IF((O19-1100000)<500000,0.19*(O19-1100000),95000)) -> 95000 | T19: =IF((O19-1600000)<0,0,IF((O19-1600000)<1600000,0.21*(O19-1600000),336000)) -> 336000 | U19: =24%*(O19-3200000) -> 801698.84 | V19: =P19+Q19+R19+S19+T19+U19 -> 1361698.8 | W19: 12 | X19: =V19/W19 -> 113474.9 | Z19: =X19 -> 113474.9 | AA19: 46666.667 | AB19: =Z19-AA19 -> 66808.237
A20: 17 | B20: ADUGBA RICHARD TERSEER | C20: 537895.17 | D20: 12 | E20: =C20*D20 -> 6454742 | G20: 362779.36 | I20: =E20-F20-G20-H20 -> 6091962.6 | J20: 200000 | K20: 0.2 | L20: =I20*K20 -> 1218392.5 | M20: =J20+L20 -> 1418392.5 | N20: =F20+G20+H20+M20 -> 1781171.9 | O20: =E20-N20 -> 4673570.1 | P20: =IF(O20<300000,0.07*O20,21000) -> 21000 | Q20: =IF((O20-300000)<0,0,IF((O20-300000)<300000,0.11*(O20-300000),33000)) -> 33000 | R20: =IF((O20-600000)<0,0,IF((O20-600000)<500000,0.15*(O20-600000),75000)) -> 75000 | S20: =IF((O20-1100000)<0,0,IF((O20-1100000)<500000,0.19*(O20-1100000),95000)) -> 95000 | T20: =IF((O20-1600000)<0,0,IF((O20-1600000)<1600000,0.21*(O20-1600000),336000)) -> 336000 | U20: =24%*(O20-3200000) -> 353656.83 | V20: =P20+Q20+R20+S20+T20+U20 -> 913656.83 | W20: 12 | X20: =V20/W20 -> 76138.069 | Z20: =X20 -> 76138.069 | AA20: 52497.77 | AB20: =Z20-AA20 -> 23640.299
A21: 18 | B21: LUCKY AGWOM | C21: =553512.5+100000 -> 653512.5 | D21: 12 | E21: =C21*D21 -> 7842150 | G21: 339372 | I21: =E21-F21-G21-H21 -> 7502778 | J21: 200000 | K21: 0.2 | L21: =I21*K21 -> 1500555.6 | M21: =J21+L21 -> 1700555.6 | N21: =F21+G21+H21+M21 -> 2039927.6 | O21: =E21-N21 -> 5802222.4 | P21: =IF(O21<300000,0.07*O21,21000) -> 21000 | Q21: =IF((O21-300000)<0,0,IF((O21-300000)<300000,0.11*(O21-300000),33000)) -> 33000 | R21: =IF((O21-600000)<0,0,IF((O21-600000)<500000,0.15*(O21-600000),75000)) -> 75000 | S21: =IF((O21-1100000)<0,0,IF((O21-1100000)<500000,0.19*(O21-1100000),95000)) -> 95000 | T21: =IF((O21-1600000)<0,0,IF((O21-1600000)<1600000,0.21*(O21-1600000),336000)) -> 336000 | U21: =24%*(O21-3200000) -> 624533.38 | V21: =P21+Q21+R21+S21+T21+U21 -> 1184533.4 | W21: 12 | X21: =V21/W21 -> 98711.115 | Z21: =X21 -> 98711.115 | AA21: 46666.667 | AB21: =Z21-AA21 -> 52044.448
A22: 19 | B22: IDRIS IBRAHIM | C22: 463512.5 | D22: 12 | E22: =C22*D22 -> 5562150 | G22: 339372 | I22: =E22-F22-G22-H22 -> 5222778 | J22: 200000 | K22: 0.2 | L22: =I22*K22 -> 1044555.6 | M22: =J22+L22 -> 1244555.6 | N22: =F22+G22+H22+M22 -> 1583927.6 | O22: =E22-N22 -> 3978222.4 | P22: =IF(O22<300000,0.07*O22,21000) -> 21000 | Q22: =IF((O22-300000)<0,0,IF((O22-300000)<300000,0.11*(O22-300000),33000)) -> 33000 | R22: =IF((O22-600000)<0,0,IF((O22-600000)<500000,0.15*(O22-600000),75000)) -> 75000 | S22: =IF((O22-1100000)<0,0,IF((O22-1100000)<500000,0.19*(O22-1100000),95000)) -> 95000 | T22: =IF((O22-1600000)<0,0,IF((O22-1600000)<1600000,0.21*(O22-1600000),336000)) -> 336000 | U22: =24%*(O22-3200000) -> 186773.38 | V22: =P22+Q22+R22+S22+T22+U22 -> 746773.38 | W22: 12 | X22: =V22/W22 -> 62231.115 | Z22: =X22 -> 62231.115 | AA22: 46666.667 | AB22: =Z22-AA22 -> 15564.448
A23: 20 | B23: FARUQ ATOFARATI | C23: =453029.666666667+100000 -> 553029.67 | D23: 12 | E23: =C23*D23 -> 6636356 | G23: 281308.48 | I23: =E23-F23-G23-H23 -> 6355047.5 | J23: 200000 | K23: 0.2 | L23: =I23*K23 -> 1271009.5 | M23: =J23+L23 -> 1471009.5 | N23: =F23+G23+H23+M23 -> 1752318 | O23: =E23-N23 -> 4884038 | P23: =IF(O23<300000,0.07*O23,21000) -> 21000 | Q23: =IF((O23-300000)<0,0,IF((O23-300000)<300000,0.11*(O23-300000),33000)) -> 33000 | R23: =IF((O23-600000)<0,0,IF((O23-600000)<500000,0.15*(O23-600000),75000)) -> 75000 | S23: =IF((O23-1100000)<0,0,IF((O23-1100000)<500000,0.19*(O23-1100000),95000)) -> 95000 | T23: =IF((O23-1600000)<0,0,IF((O23-1600000)<1600000,0.21*(O23-1600000),336000)) -> 336000 | U23: =24%*(O23-3200000) -> 404169.12 | V23: =P23+Q23+R23+S23+T23+U23 -> 964169.12 | W23: 12 | X23: =V23/W23 -> 80347.427 | Z23: =X23 -> 80347.427 | AA23: 42371.816 | AB23: =Z23-AA23 -> 37975.611
A24: 21 | B24: ELIZABETH OGECHUKWU ONYEAKU | C24: 330481.67 | D24: 12 | E24: =C24*D24 -> 3965780 | G24: 259662.4 | I24: =E24-F24-G24-H24 -> 3706117.6 | J24: 200000 | K24: 0.2 | L24: =I24*K24 -> 741223.52 | M24: =J24+L24 -> 941223.52 | N24: =F24+G24+H24+M24 -> 1200885.9 | O24: =E24-N24 -> 2764894.1 | P24: =IF(O24<300000,0.07*O24,21000) -> 21000 | Q24: =IF((O24-300000)<0,0,IF((O24-300000)<300000,0.11*(O24-300000),33000)) -> 33000 | R24: =IF((O24-600000)<0,0,IF((O24-600000)<500000,0.15*(O24-600000),75000)) -> 75000 | S24: =IF((O24-1100000)<0,0,IF((O24-1100000)<500000,0.19*(O24-1100000),95000)) -> 95000 | T24: =IF((O24-1600000)<0,0,IF((O24-1600000)<1600000,0.21*(O24-1600000),336000)) -> 244627.76 | V24: =P24+Q24+R24+S24+T24+U24 -> 468627.76 | W24: 12 | X24: =V24/W24 -> 39052.313 | Z24: =X24 -> 39052.313 | AA24: 23036.012 | AB24: =Z24-AA24 -> 16016.301
A25: 22 | B25: VICTOR ASUKWO | C25: 330481.67 | D25: 12 | E25: =C25*D25 -> 3965780 | G25: 259662.4 | I25: =E25-F25-G25-H25 -> 3706117.6 | J25: 200000 | K25: 0.2 | L25: =I25*K25 -> 741223.52 | M25: =J25+L25 -> 941223.52 | N25: =F25+G25+H25+M25 -> 1200885.9 | O25: =E25-N25 -> 2764894.1 | P25: =IF(O25<300000,0.07*O25,21000) -> 21000 | Q25: =IF((O25-300000)<0,0,IF((O25-300000)<300000,0.11*(O25-300000),33000)) -> 33000 | R25: =IF((O25-600000)<0,0,IF((O25-600000)<500000,0.15*(O25-600000),75000)) -> 75000 | S25: =IF((O25-1100000)<0,0,IF((O25-1100000)<500000,0.19*(O25-1100000),95000)) -> 95000 | T25: =IF((O25-1600000)<0,0,IF((O25-1600000)<1600000,0.21*(O25-1600000),336000)) -> 244627.76 | V25: =P25+Q25+R25+S25+T25+U25 -> 468627.76 | W25: 12 | X25: =V25/W25 -> 39052.313 | Z25: =X25 -> 39052.313 | AA25: 23036.012 | AB25: =Z25-AA25 -> 16016.301
A26: 23 | B26: NNANDI LIVINUS ATURE | C26: 370481.67 | D26: 12 | E26: =C26*D26 -> 4445780 | G26: 259662.4 | I26: =E26-F26-G26-H26 -> 4186117.6 | J26: 200000 | K26: 0.2 | L26: =I26*K26 -> 837223.52 | M26: =J26+L26 -> 1037223.5 | N26: =F26+G26+H26+M26 -> 1296885.9 | O26: =E26-N26 -> 3148894.1 | P26: =IF(O26<300000,0.07*O26,21000) -> 21000 | Q26: =IF((O26-300000)<0,0,IF((O26-300000)<300000,0.11*(O26-300000),33000)) -> 33000 | R26: =IF((O26-600000)<0,0,IF((O26-600000)<500000,0.15*(O26-600000),75000)) -> 75000 | S26: =IF((O26-1100000)<0,0,IF((O26-1100000)<500000,0.19*(O26-1100000),95000)) -> 95000 | T26: =IF((O26-1600000)<0,0,IF((O26-1600000)<1600000,0.21*(O26-1600000),336000)) -> 325267.76 | V26: =P26+Q26+R26+S26+T26+U26 -> 549267.76 | W26: 12 | X26: =V26/W26 -> 45772.313 | Z26: =X26 -> 45772.313 | AA26: 29756.012 | AB26: =Z26-AA26 -> 16016.301
A27: 24 | B27: ABDULRAHMAN A SULAIMAN | C27: 323165.33 | D27: 12 | E27: =C27*D27 -> 3877984 | G27: 252638.72 | I27: =E27-F27-G27-H27 -> 3625345.3 | J27: 200000 | K27: 0.2 | L27: =I27*K27 -> 725069.06 | M27: =J27+L27 -> 925069.06 | N27: =F27+G27+H27+M27 -> 1177707.8 | O27: =E27-N27 -> 2700276.2 | P27: =IF(O27<300000,0.07*O27,21000) -> 21000 | Q27: =IF((O27-300000)<0,0,IF((O27-300000)<300000,0.11*(O27-300000),33000)) -> 33000 | R27: =IF((O27-600000)<0,0,IF((O27-600000)<500000,0.15*(O27-600000),75000)) -> 75000 | S27: =IF((O27-1100000)<0,0,IF((O27-1100000)<500000,0.19*(O27-1100000),95000)) -> 95000 | T27: =IF((O27-1600000)<0,0,IF((O27-1600000)<1600000,0.21*(O27-1600000),336000)) -> 231058.01 | V27: =P27+Q27+R27+S27+T27+U27 -> 455058.01 | W27: 12 | X27: =V27/W27 -> 37921.501 | Z27: =X27 -> 37921.501 | AA27: 22338.483 | AB27: =Z27-AA27 -> 15583.018
A28: 25 | B28: DARE SHEU MAGBON | C28: 315849 | D28: 12 | E28: =C28*D28 -> 3790188 | G28: 245615.04 | I28: =E28-F28-G28-H28 -> 3544573 | J28: 200000 | K28: 0.2 | L28: =I28*K28 -> 708914.59 | M28: =J28+L28 -> 908914.59 | N28: =F28+G28+H28+M28 -> 1154529.6 | O28: =E28-N28 -> 2635658.4 | P28: =IF(O28<300000,0.07*O28,21000) -> 21000 | Q28: =IF((O28-300000)<0,0,IF((O28-300000)<300000,0.11*(O28-300000),33000)) -> 33000 | R28: =IF((O28-600000)<0,0,IF((O28-600000)<500000,0.15*(O28-600000),75000)) -> 75000 | S28: =IF((O28-1100000)<0,0,IF((O28-1100000)<500000,0.19*(O28-1100000),95000)) -> 95000 | T28: =IF((O28-1600000)<0,0,IF((O28-1600000)<1600000,0.21*(O28-1600000),336000)) -> 217488.26 | V28: =P28+Q28+R28+S28+T28+U28 -> 441488.26 | W28: 12 | X28: =V28/W28 -> 36790.688 | Z28: =X28 -> 36790.688 | AA28: 21640.953 | AB28: =Z28-AA28 -> 15149.735
A29: 26 | B29: ABUBAKAR SULAIMAN SODEEQ | C29: 315849 | D29: 12 | E29: =C29*D29 -> 3790188 | G29: 245615.04 | I29: =E29-F29-G29-H29 -> 3544573 | J29: 200000 | K29: 0.2 | L29: =I29*K29 -> 708914.59 | M29: =J29+L29 -> 908914.59 | N29: =F29+G29+H29+M29 -> 1154529.6 | O29: =E29-N29 -> 2635658.4 | P29: =IF(O29<300000,0.07*O29,21000) -> 21000 | Q29: =IF((O29-300000)<0,0,IF((O29-300000)<300000,0.11*(O29-300000),33000)) -> 33000 | R29: =IF((O29-600000)<0,0,IF((O29-600000)<500000,0.15*(O29-600000),75000)) -> 75000 | S29: =IF((O29-1100000)<0,0,IF((O29-1100000)<500000,0.19*(O29-1100000),95000)) -> 95000 | T29: =IF((O29-1600000)<0,0,IF((O29-1600000)<1600000,0.21*(O29-1600000),336000)) -> 217488.26 | V29: =P29+Q29+R29+S29+T29+U29 -> 441488.26 | W29: 12 | X29: =V29/W29 -> 36790.688 | Z29: =X29 -> 36790.688 | AA29: 21640.953 | AB29: =Z29-AA29 -> 15149.735
A30: 27 | B30: JIMOH ADEBAYO ZAKA | C30: 330481.67 | D30: 12 | E30: =C30*D30 -> 3965780 | G30: 259662.4 | I30: =E30-F30-G30-H30 -> 3706117.6 | J30: 200000 | K30: 0.2 | L30: =I30*K30 -> 741223.52 | M30: =J30+L30 -> 941223.52 | N30: =F30+G30+H30+M30 -> 1200885.9 | O30: =E30-N30 -> 2764894.1 | P30: =IF(O30<300000,0.07*O30,21000) -> 21000 | Q30: =IF((O30-300000)<0,0,IF((O30-300000)<300000,0.11*(O30-300000),33000)) -> 33000 | R30: =IF((O30-600000)<0,0,IF((O30-600000)<500000,0.15*(O30-600000),75000)) -> 75000 | S30: =IF((O30-1100000)<0,0,IF((O30-1100000)<500000,0.19*(O30-1100000),95000)) -> 95000 | T30: =IF((O30-1600000)<0,0,IF((O30-1600000)<1600000,0.21*(O30-1600000),336000)) -> 244627.76 | V30: =P30+Q30+R30+S30+T30+U30 -> 468627.76 | W30: 12 | X30: =V30/W30 -> 39052.313 | Z30: =X30 -> 39052.313 | AA30: 22338.483 | AB30: =Z30-AA30 -> 16713.83
A31: 28 | B31: MOHAMMED BELLO | C31: 280631.92 | D31: 12 | E31: =C31*D31 -> 3367583 | G31: 221406.64 | I31: =E31-F31-G31-H31 -> 3146176.4 | J31: 200000 | K31: 0.2 | L31: =I31*K31 -> 629235.27 | M31: =J31+L31 -> 829235.27 | N31: =F31+G31+H31+M31 -> 1050641.9 | O31: =E31-N31 -> 2316941.1 | P31: =IF(O31<300000,0.07*O31,21000) -> 21000 | Q31: =IF((O31-300000)<0,0,IF((O31-300000)<300000,0.11*(O31-300000),33000)) -> 33000 | R31: =IF((O31-600000)<0,0,IF((O31-600000)<500000,0.15*(O31-600000),75000)) -> 75000 | S31: =IF((O31-1100000)<0,0,IF((O31-1100000)<500000,0.19*(O31-1100000),95000)) -> 95000 | T31: =IF((O31-1600000)<0,0,IF((O31-1600000)<1600000,0.21*(O31-1600000),336000)) -> 150557.63 | V31: =P31+Q31+R31+S31+T31+U31 -> 374557.63 | W31: 12 | X31: =V31/W31 -> 31213.136 | Z31: =X31 -> 31213.136 | AA31: 17572.885 | AB31: =Z31-AA31 -> 13640.251
A32: 29 | B32: HARUNA JIBRIL AMEH | C32: 274459.75 | D32: 12 | E32: =C32*D32 -> 3293517 | G32: =17956.78*12 -> 215481.36 | I32: =E32-F32-G32-H32 -> 3078035.6 | J32: 200000 | K32: 0.2 | L32: =I32*K32 -> 615607.13 | M32: =J32+L32 -> 815607.13 | N32: =F32+G32+H32+M32 -> 1031088.5 | O32: =E32-N32 -> 2262428.5 | P32: =IF(O32<300000,0.07*O32,21000) -> 21000 | Q32: =IF((O32-300000)<0,0,IF((O32-300000)<300000,0.11*(O32-300000),33000)) -> 33000 | R32: =IF((O32-600000)<0,0,IF((O32-600000)<500000,0.15*(O32-600000),75000)) -> 75000 | S32: =IF((O32-1100000)<0,0,IF((O32-1100000)<500000,0.19*(O32-1100000),95000)) -> 95000 | T32: =IF((O32-1600000)<0,0,IF((O32-1600000)<1600000,0.21*(O32-1600000),336000)) -> 139109.99 | V32: =P32+Q32+R32+S32+T32+U32 -> 363109.99 | W32: 12 | X32: =V32/W32 -> 30259.166 | Z32: =X32 -> 30259.166 | AA32: 16512.682 | AB32: =Z32-AA32 -> 13746.483
A33: 31
A34: 32 | B34: INTERNAL AUDIT
B35: OSANAIYE DAVID AKINYEMI | C35: 1535720 | D35: 12 | E35: =C35*D35 -> 18428640 | G35: 1378291.2 | I35: =E35-F35-G35-H35 -> 17050349 | J35: 200000 | K35: 0.2 | L35: =I35*K35 -> 3410069.8 | M35: =J35+L35 -> 3610069.8 | N35: =F35+G35+H35+M35 -> 4988361 | O35: =E35-N35 -> 13440279 | P35: =IF(O35<300000,0.07*O35,21000) -> 21000 | Q35: =IF((O35-300000)<0,0,IF((O35-300000)<300000,0.11*(O35-300000),33000)) -> 33000 | R35: =IF((O35-600000)<0,0,IF((O35-600000)<500000,0.15*(O35-600000),75000)) -> 75000 | S35: =IF((O35-1100000)<0,0,IF((O35-1100000)<500000,0.19*(O35-1100000),95000)) -> 95000 | T35: =IF((O35-1600000)<0,0,IF((O35-1600000)<1600000,0.21*(O35-1600000),336000)) -> 336000 | U35: =24%*(O35-3200000) -> 2457667 | V35: =P35+Q35+R35+S35+T35+U35 -> 3017667 | W35: 12 | X35: =V35/W35 -> 251472.25 | Z35: =X35 -> 251472.25 | AA35: 161106.81 | AB35: =Z35-AA35 -> 90365.441
B36: JAMILA ABDUL | C36: 353029.67 | D36: 12 | E36: =C36*D36 -> 4236356 | G36: 281308.48 | I36: =E36-F36-G36-H36 -> 3955047.5 | J36: 200000 | K36: 0.2 | L36: =I36*K36 -> 791009.5 | M36: =J36+L36 -> 991009.5 | N36: =F36+G36+H36+M36 -> 1272318 | O36: =E36-N36 -> 2964038 | P36: =IF(O36<300000,0.07*O36,21000) -> 21000 | Q36: =IF((O36-300000)<0,0,IF((O36-300000)<300000,0.11*(O36-300000),33000)) -> 33000 | R36: =IF((O36-600000)<0,0,IF((O36-600000)<500000,0.15*(O36-600000),75000)) -> 75000 | S36: =IF((O36-1100000)<0,0,IF((O36-1100000)<500000,0.19*(O36-1100000),95000)) -> 95000 | T36: =IF((O36-1600000)<0,0,IF((O36-1600000)<1600000,0.21*(O36-1600000),336000)) -> 286447.98 | V36: =P36+Q36+R36+S36+T36+U36 -> 510447.98 | W36: 12 | X36: =V36/W36 -> 42537.332 | Z36: =X36 -> 42537.332 | AA36: 17042.714 | AB36: =Z36-AA36 -> 25494.618
A37: 33 | B37: IJEOMA EWELUKWA | C37: 360965.58 | D37: 12 | E37: =C37*D37 -> 4331587 | G37: 288926.96 | I37: =E37-F37-G37-H37 -> 4042660 | J37: 200000 | K37: 0.2 | L37: =I37*K37 -> 808532.01 | M37: =J37+L37 -> 1008532 | N37: =F37+G37+H37+M37 -> 1297459 | O37: =E37-N37 -> 3034128 | P37: =IF(O37<300000,0.07*O37,21000) -> 21000 | Q37: =IF((O37-300000)<0,0,IF((O37-300000)<300000,0.11*(O37-300000),33000)) -> 33000 | R37: =IF((O37-600000)<0,0,IF((O37-600000)<500000,0.15*(O37-600000),75000)) -> 75000 | S37: =IF((O37-1100000)<0,0,IF((O37-1100000)<500000,0.19*(O37-1100000),95000)) -> 95000 | T37: =IF((O37-1600000)<0,0,IF((O37-1600000)<1600000,0.21*(O37-1600000),336000)) -> 301166.89 | V37: =P37+Q37+R37+S37+T37+U37 -> 525166.89 | W37: 12 | X37: =V37/W37 -> 43763.907 | Z37: =X37 -> 43763.907 | AA37: 26339.078 | AB37: =Z37-AA37 -> 17424.829
G38: 0
B39: LEG. SUPPORT SEVICES | G39: 0
A40: 35 | B40: PROF. EDOBA BRIGHT OMOREGBE | C40: 1635720 | D40: 12 | E40: =C40*D40 -> 19628640 | G40: 1378291.2 | I40: =E40-F40-G40-H40 -> 18250349 | J40: 200000 | K40: 0.2 | L40: =I40*K40 -> 3650069.8 | M40: =J40+L40 -> 3850069.8 | N40: =F40+G40+H40+M40 -> 5228361 | O40: =E40-N40 -> 14400279 | P40: =IF(O40<300000,0.07*O40,21000) -> 21000 | Q40: =IF((O40-300000)<0,0,IF((O40-300000)<300000,0.11*(O40-300000),33000)) -> 33000 | R40: =IF((O40-600000)<0,0,IF((O40-600000)<500000,0.15*(O40-600000),75000)) -> 75000 | S40: =IF((O40-1100000)<0,0,IF((O40-1100000)<500000,0.19*(O40-1100000),95000)) -> 95000 | T40: =IF((O40-1600000)<0,0,IF((O40-1600000)<1600000,0.21*(O40-1600000),336000)) -> 336000 | U40: =0.24*(O40-3200000) -> 2688067 | V40: =P40+Q40+R40+S40+T40+U40 -> 3248067 | W40: 12 | X40: =V40/W40 -> 270672.25 | Z40: =X40 -> 270672.25 | AA40: 180306.81 | AB40: =Z40-AA40 -> 90365.441
...

Sheet Upgrade in March
A1: NATIONAL INSTITUTE FOR LEGISLATIVE AND DEMOCRATIC STUDIES
A2: UPGRADE FROM GL 16(9) TO GL 17(7)
E3: ='[1]FEB 08'!E11/'[1]FEB 08'!M11 -> #REF!
B4: STAFF NAME | C4: DESIGNATION | D4: GRADE LEVEL | E4: BASIC SALARY | F4: ALLCE/ AREARS | G4: ALLOWANCE | H4: ALLOWANCE | I4: DUTY ALLCE | J4: GROSS SALARY | K4: AUCTION | L4: COOP CONTR/SPEC SAVINGS | M4: COOP. LOAN RECOVERY | N4: NHF DED. | O4: PAYE | P4: EMPLOYEE PENSIONS | Q4: TOTAL DEDUCTION | R4: FEBRUARY, 2024 | S4: MARCH, 2024
E5: N | G5: N | H5: N | I5: N | J5: N | K5: N | L5: N | M5: N | N5: N | O5: N | P5: N | Q5: N | R5: N | S5: N
B6: TRAINING & INT''L COOP
A7: 1 | B7: AKINSANMI ADEJOKE OLUKEMI | C7: Ag. DIR. TRAINING & IC | D7: 16(9) | E7: 762373.17 | H7: =80000+10000 -> 90000 | J7: =E7+F7+G7+H7+I7 -> 852373.17 | L7: =0 -> 0 | M7: 0 | N7: 1066.3293 | O7: 130407.53 | P7: 60989.853 | Q7: =O7+N7+M7+L7+K7+P7 -> 192463.71 | R7: 659909.46 | S7: =J7-Q7 -> 659909.46
A8: 1 | B8: AKINSANMI ADEJOKE OLUKEMI | C8: Ag. DIR. TRAINING & IC | D8: 17(7) | E8: ='[3]Annual & Monthly'!$H$44 -> 1352042.7 | H8: =100000 -> 100000 | I8: 0 | J8: =SUM(E8:I8) -> 1452042.7 | N8: 1066.3293 | O8: ='March New PAYE '!Z93 -> 236486.75 | P8: 114857.6 | Q8: =O8+N8+M8+L8+K8+P8 -> 352410.68 | R8: 659909.46 | S8: =J8-Q8 -> 1099632 | T8: =R8-S8 -> -439722.53
B9: DIFFERENCE | C9: =#REF!+#REF!+#REF!+#REF!+#REF!+#REF!+#REF!+#REF!+#REF!+#REF!+#REF! -> #REF! | E9: =E8-E7 -> 589669.5 | F9: =F8-F7 -> 0 | G9: =G8-G7 -> 0 | H9: =H8-H7 -> 10000 | I9: =I8-I7 -> 0 | J9: =J8-J7 -> 599669.5 | K9: =K8-K7 -> 0 | L9: =L8-L7 -> 0 | ... S9: =S8-S7 -> 439722.53

Sheet New NHF Deduction
A1: NATIONAL INSTITUTE FOR LEGISLATIVE AND DEMOCRATIC STUDIES
A2: COMPUTATION OF 2.5% EMPLOYEE NATIONAL HOUSING FUND (NHF)
B5: STAFF NAME | C5: DESIGNATION | D5: GRADE LEVEL | E5: ANNUAL SALARY | F5: MONTHLY SALARY | G5: EMPLOYEE NHF @ 2.25% | H5: OLD EMPLOYEE NHF | I5: DIFFERENCE
E6: N | F6: N | G6: N | H6: N | I6: N
A7: S/N | B7: DG'S OFFICE
A8: 1 | B8: PROF. ABUBAKAR O. SULAIMAN | C8: DIRECTOR GENERAL | D8: CONSOL | F8: =E8/12 -> 0 | G8: =E8*0.025 -> 0 | I8: =G8-H8 -> 0
A9: 2 | B9: RAHEEM USMAN AYIGORO | C9: SA-INFRASTRUCTURE | D9: 16 (9) | F9: =E9/12 -> 0 | G9: =E9*0.025 -> 0 | I9: =G9-H9 -> 0
A10: 3 | B10: MARIAM MOHAMMED BELLO | C10: SA- SPECIAL DUTIES | D10: 16 (9) | F10: =E10/12 -> 0 | G10: =E10*0.025 -> 0 | I10: =G10-H10 -> 0
A11: 4 | B11: DR IKEME ARTHUR J.O | C11: DEPUTY DIRECTOR, M&E | D11: 16 (9) | E11: ='[6]NASS New Structure'!$J$20 -> 4940831 | F11: =E11/12 -> 411735.92 | G11: =F11*0.025 -> 10293.398 | H11: 1066.3293 | I11: =G11-H11 -> 9227.0687
A12: 5 | B12: MOSHOOD M. OLALERE | C12: PPS TO DG | D12: 16 (9) | E12: ='[6]NASS New Structure'!$J$20 -> 4940831 | F12: =E12/12 -> 411735.92 | G12: =F12*0.025 -> 10293.398 | H12: 1066.3293 | I12: =G12-H12 -> 9227.0687
A13: 6 | B13: REKIYA IBRAHIM ATTAH | C13: DEPUTY DIRECTOR TRAINING | D13: 16 (9) | F13: =E13/12 -> 0 | G13: =F13*0.025 -> 0 | I13: =G13-H13 -> 0
A14: 7 | B14: ANDRAWUS MUSA | C14: ASST. DIRECTOR, STORES | D14: 15(9) | E14: ='[6]NASS New Structure'!$J$19 -> 4022509 | F14: =E14/12 -> 335209.08 | G14: =F14*0.025 -> 8380.2271 | H14: 837.6875 | I14: =G14-H14 -> 7542.5396
A15: 8 | B15: DR FRANCIS NDUM OJIE | C15: AD, TRAINING & IC./SA TO DG | D15: 15(7) | E15: ='[6]NASS New Structure'!$H$19 -> 3772623 | F15: =E15/12 -> 314385.25 | G15: =F15*0.025 -> 7859.6313 | H15: 775.496 | I15: =G15-H15 -> 7084.1353
A16: 9 | B16: ALI ABDULLAHI | C16: CHIEF ICT OFFICER | D16: 14(11) | F16: =E16/12 -> 0 | G16: =E16*0.025 -> 0 | I16: =G16-H16 -> 0
A17: 10 | B17: EMILY EKHIDE | C17: RESEARCH FELLOW 1 | D17: 14(10) | F17: =E17/12 -> 0 | G17: =E17*0.025 -> 0 | I17: =G17-H17 -> 0
A18: 11 | B18: DORIS DAKDA AARON | C18: RESEARCH FELLOW I | D18: 14(8) | F18: =E18/12 -> 0 | G18: =E18*0.025 -> 0 | I18: =G18-H18 -> 0
A19: 12 | B19: ABDULSALAM S. MUSTAPHA | C19: ASST. MANAGER ICT | D19: 13(11) | F19: =E19/12 -> 0 | G19: =E19*0.025 -> 0 | I19: =G19-H19 -> 0
A20: 13 | B20: PERCY TERFA GBAHABO | C20: HEAD, NILDS LIAISON OFFICE | D20: 13(10) | F20: =E20/12 -> 0 | G20: =E20*0.025 -> 0 | I20: =G20-H20 -> 0
A21: 14 | B21: HASSANA AHMED IBRAHIM | C21: PA- TRAINING | D21: 13 (9) | E21: ='[6]NASS New Structure'!$J$17 -> 2691445 | F21: =E21/12 -> 224287.08 | G21: =F21*0.025 -> 5607.1771 | H21: 618.5315 | I21: =G21-H21 -> 4988.6456
A22: 15 | B22: ADUGBA RICHARD TERSEER | C22: PRINCIPAL INFO. OFFICER | D22: 12(9) | F22: =E22/12 -> 0 | G22: =E22*0.025 -> 0 | I22: =G22-H22 -> 0
A23: 16 | B23: LUCKY AGWOM | C23: PA-TECHNICAL | D23: 12(7) | F23: =E23/12 -> 0 | G23: =E23*0.025 -> 0 | I23: =G23-H23 -> 0
A24: 17 | B24: IDRIS IBRAHIM | C24: PRINCIPAL RESEARCH OFFICER | D24: 12(7) | F24: =E24/12 -> 0 | G24: =E24*0.025 -> 0 | I24: =G24-H24 -> 0
A25: 18 | B25: FARUQ ATOFARATI | C25: PA (SPECIAL DUTIES) TO DG | D25: 10(7) | F25: =E25/12 -> 0 | G25: =E25*0.025 -> 0 | I25: =G25-H25 -> 0
A26: 19 | B26: ELIZABETH OGECHUKWU ONYEAKU | C26: ICT OFFICER | D26: 9(9) | F26: =E26/12 -> 0 | G26: =E26*0.025 -> 0 | I26: =G26-H26 -> 0
A27: 20 | B27: VICTOR ASUKWO | C27: ICT OFFICER | D27: 9(9) | F27: =E27/12 -> 0 | G27: =E27*0.025 -> 0 | I27: =G27-H27 -> 0
A28: 21 | B28: NNANDI LIVINUS ATURE | C28: RESEARCH ASSISTANT | D28: 9(9) | F28: =E28/12 -> 0 | G28: =E28*0.025 -> 0 | I28: =G28-H28 -> 0
A29: 22 | B29: ABDULRAHMAN A SULAIMAN | C29: STORE OFFICER | D29: 9(8) | F29: =E29/12 -> 0 | G29: =E29*0.025 -> 0 | I29: =G29-H29 -> 0
A30: 23 | B30: DARE SHEU MAGBON | C30: ADMINISTRATION OFFICER | D30: 9(7) | F30: =E30/12 -> 0 | G30: =E30*0.025 -> 0 | I30: =G30-H30 -> 0
A31: 24 | B31: ABUBAKAR SULAIMAN SODEEQ | C31: ADMINISTRATION OFFICER | D31: 9(7) | F31: =E31/12 -> 0 | G31: =E31*0.025 -> 0 | I31: =G31-H31 -> 0
A32: 25 | B32: JIMOH ADEBAYO ZAKA | C32: ASST. OFFICER/COMM | D32: 9(9) | F32: =E32/12 -> 0 | G32: =E32*0.025 -> 0 | I32: =G32-H32 -> 0
A33: 26 | B33: MOHAMMED BELLO | C33: PROTOCOL ASSISTANT | D33: 8(9) | F33: =E33/12 -> 0 | G33: =E33*0.025 -> 0 | I33: =G33-H33 -> 0
A34: 27 | B34: HARUNA JIBRIL AMEH | C34: ASST. ADMIN. OFFICER | D34: 8(8) | F34: =E34/12 -> 0 | G34: =E34*0.025 -> 0 | I34: =G34-H34 -> 0
B35: TOTAL | C35: 27 | E35: =SUM(E8:E34) -> 20368239 | F35: =SUM(F8:F34) -> 1697353.2 | G35: =SUM(G8:G34) -> 42433.831 | H35: =SUM(H8:H34) -> 4364.3735 | I35: =SUM(I8:I34) -> 38069.458
B37: INTERNAL AUDIT
A38: 1 | B38: OSANAIYE DAVID AKINYEMI | C38: DIRECTOR INTERNAL AUDIT | D38: 17(9) | G38: =E38*0.025 -> 0 | H38: =F38*0.025 -> 0 | I38: =G38*0.025 -> 0
A39: 2 | B39: JAMILA ABDUL | C39: SENIOR INTERNAL AUDITOR | D39: 10(7) | G39: =E39*0.025 -> 0 | H39: =F39*0.025 -> 0 | I39: =G39*0.025 -> 0
A40: 3 | B40: IJEOMA EWELUKWA | C40: AUDIT OFFICER | D40: 10(8) | G40: =E40*0.025 -> 0 | H40: =F40*0.025 -> 0 | I40: =G40*0.025 -> 0
C41: 3 | E41: =SUM(E38:E40) -> 0 | G41: =SUM(G38:G40) -> 0 | H41: =SUM(H38:H40) -> 0 | I41: =SUM(I38:I40) -> 0
B43: LEG. SUPPORT SEVICES
A44: 1 | B44: PROF. EDOBA BRIGHT OMOREGBE | C44: AG. DLSS | D44: 17(9) | G44: =E44*0.025 -> 0 | I44: =G44*0.025 -> 0
...

Sheet Regularisation
D1: Gross | E1: PAYE
A2: HARUNA JIBRIL AMEH | B2: ASST. ADMIN. OFFICER | C2: 8(7) | D2: ='[5]JANUARY 2024'!$R$33 -> 173329.05 | E2: ='[5]JANUARY 2024'!$W$33 -> 16512.682
A3: HARUNA JIBRIL AMEH | B3: ASST. ADMIN. OFFICER | C3: 8(8) | D3: ='[5]JANUARY 2024'!$R$38 -> 176816.1 | E3: ='[5]JANUARY 2024'!$W$38 -> 17042.714
A4: Difference | D4: =D3-D2 -> 3487.0505 | E4: =E3-E2 -> 530.03168 | F4: =D4-E4 -> 2957.0188

Sheet Sallah Welfare, April 2024
A1: NATIONAL INSTITUTE FOR LEGISLATIVE AND DEMOCRATIC STUDIES
A2: STAFF SALLAH WELFARE APRIL 2024
E3: ='[1]FEB 08'!E11/'[1]FEB 08'!M11 -> #REF!
B4: STAFF NAME | C4: DESIGNATION | D4: GRADE LEVEL | E4: AMOUNT
E5: N
A6: S/N | B6: DG'S OFFICE
A7: 1 | B7: PROF. ABUBAKAR O. SULAIMAN | C7: DIRECTOR GENERAL | D7: CONSOL | E7: 540000
A8: 2 | B8: RAHEEM USMAN AYIGORO | C8: SA-INFRASTRUCTURE | D8: 16 (9) | E8: 180000
A9: 3 | B9: MARIAM MOHAMMED BELLO | C9: SA- SPECIAL DUTIES | D9: 16 (9) | E9: 180000
A10: 4 | B10: DR IKEME ARTHUR J.O | C10: DEPUTY DIRECTOR, M&E | D10: 16 (9) | E10: 180000
A11: 5 | B11: MOSHOOD M. OLALERE | C11: DEPUTY DIR. GENERAL SERVICE | D11: 16 (9) | E11: 180000
A12: 6 | B12: REKIYA IBRAHIM ATTAH | C12: DEPUTY DIRECTOR TRAINING | D12: 16 (9) | E12: 180000
A13: 7 | B13: ANDRAWUS MUSA | C13: ASST. DIRECTOR, STORES | D13: 15(9) | E13: 126000
A14: 8 | B14: DR FRANCIS NDUM OJIE | C14: AD, TRAINING & IC./SA TO DG | D14: 15(7) | E14: 126000
A15: 9 | B15: ALI ABDULLAHI | C15: CHIEF ICT OFFICER | D15: 14(11) | E15: 90000
A16: 10 | B16: EMILY EKHIDE | C16: RESEARCH FELLOW 1 | D16: 14(10) | E16: 90000
A17: 11 | B17: DORIS DAKDA AARON | C17: RESEARCH FELLOW I | D17: 14(8) | E17: 90000
A18: 12 | B18: ABDULSALAM S. MUSTAPHA | C18: ASST. MANAGER ICT | D18: 13(11) | E18: 90000
... A33: 27 | B33: HARUNA JIBRIL AMEH | C33: ASST. ADMIN. OFFICER | D33: 8(8) | E33: 54000
B34: TOTAL | C34: 27 | E34: =SUM(E7:E33) -> 2990000
B36: INTERNAL AUDIT
A37: 1 | B37: OSANAIYE DAVID AKINYEMI | C37: DIRECTOR INTERNAL AUDIT | D37: 17(9) | E37: 270000
A38: 2 | B38: JAMILA ABDUL | C38: AUDITOR II | D38: 10(7) | E38: 68000
A39: 3 | B39: IJEOMA EWELUKWA | C39: AUDIT OFFICER | D39: 10(8) | E39: 68000
C40: 3 | E40: =SUM(E37:E39) -> 406000
B42: LEG. SUPPORT SEVICES
A43: 1 | B43: PROF. EDOBA BRIGHT OMOREGBE | C43: AG. DLSS | D43: 17(9) | E43: 270000
A44: 2 | B44: DR CLINTON JAJA | C44: SENIOR RESEARCH FELLOW | D44: 15(9) | E44: 126000
A45: 3 | B45: BETHEL UZOMA IHUGBA | C45: DEPUTY DIRECTOR, LEGAL RESEARCH | D45: 16(8) | E45: 180000
A46: 4 | B46: OGUCHE SAMUEL | C46: SNR RESEARCH FELLOW | D46: 15(9) | E46: 126000
A47: 5 | B47: IBRAHIM USMAN | C47: SNR RESEARCH FELLOW | D47: 15(9) | E47: 126000
A48: 6 | B48: DR MOHAMMED O. AMALI | C48: SNR RESEARCH FELLOW | D48: 15(7) | E48: 126000
A49: 7 | B49: YAHAYA SHAMSU | C49: RESEARCH FELLOW 1 | D49: 14(10) | E49: 90000
A50: 8 | B50: BILKIS S. LAWAL-GAMBARI | C50: RESEARCH OFFICER | D50: 10(8) | E50: 68000
A51: 9 | B51: ZAINAB AKINDE | C51: RESEARCH OFFICER | D51: 9(8) | E51: 54000
A52: 10 | B52: ABDULLAHI AHMAD USMAN | C52: RESEARCH OFFICER | D52: 9(8) | E52: 54000
A53: 11 | B53: GUNAT NANSAK MARK | C53: RESEARCH OFFICER | D53: 9(8) | E53: 54000
B54: TOTAL | C54: 11 | E54: =SUM(E43:E53) -> 1274000
B56: LEGAL SERVICES
A57: 1 | B57: DR SHUIBU DANWANKA | C57: DIRECTOR LEGAL SERVICES | D57: 17(9) | E57: 270000
...

Sheet Sheet4

Sheet January Arrears
A1: NATIONAL INSTITUTE FOR LEGISLATIVE AND DEMOCRATIC STUDIES
A2: COMPUTATION OF JANUARY 2024 ARREARS
E3: ='[1]FEB 08'!E11/'[1]FEB 08'!M11 -> #REF!
B4: STAFF NAME | C4: DESIGNATION | D4: GRADE LEVEL | E4: SALARY | F4: AREARS | G4: RESEARCH ALLOW. | H4: HARDSHIP ALLOW. | I4: DUTY ALLCE | J4: NEW GROSS SALARY | K4: OLD GROSS SALARY | L4: VARIATION IN GROSS SALARY | M4: NEW PAYE TAX | N4: OLD PAYE TAX | O4: VARIATION IN PAYE TAX | Q4: JANUARY 2024 ARREARS
L5: A | O5: B | Q5: (A-B)
A6: S/N | B6: DG'S OFFICE | E6: N | F6: N | G6: N | H6: N | I6: N | J6: N | K6: N | L6: N | M6: N | N6: N | O6: N | Q6: N
A7: 1 | B7: PROF. ABUBAKAR O. SULAIMAN | C7: DIRECTOR GENERAL | D7: CONSOL | E7: 1659751.2 | G7: =250000 -> 250000 | I7: 25235 | J7: =E7+F7+G7+H7+I7 -> 1934986.2 | K7: 1158849.8 | L7: =J7-K7 -> 776136.33 | M7: 350184.01 | N7: 201165.84 | O7: =M7-N7 -> 149018.17 | Q7: =L7-O7 -> 627118.15
A8: 2 | B8: RAHEEM USMAN AYIGORO | C8: SA-INFRASTRUCTURE | D8: 16 (9) | E8: 762373.17 | H8: =90000 -> 90000 | I8: 0 | J8: =E8+F8+G8+H8+I8 -> 852373.17 | K8: 541465.02 | L8: =J8-K8 -> 310908.14 | M8: 130612.26 | N8: 82627.951 | O8: =M8-N8 -> 47984.311 | Q8: =L8-O8 -> 262923.83
A9: 3 | B9: MARIAM MOHAMMED BELLO | C9: SA- SPECIAL DUTIES | D9: 16 (9) | E9: 762373.17 | H9: =90000 -> 90000 | I9: =100000+100000 -> 200000 | J9: =E9+F9+G9+H9+I9 -> 1052373.2 | K9: 741465.02 | L9: =J9-K9 -> 310908.14 | M9: 180722.31 | N9: 121027.95 | O9: =M9-N9 -> 59694.363 | Q9: =L9-O9 -> 251213.78
A10: 4 | B10: DR IKEME ARTHUR J.O | C10: DEPUTY DIRECTOR, M&E | D10: 16 (9) | E10: 762373.17 | G10: 180000 | I10: 0 | J10: =E10+F10+G10+H10+I10 -> 942373.17 | K10: 631465.02 | L10: =J10-K10 -> 310908.14 | M10: 147687.53 | N10: 99703.216 | O10: =M10-N10 -> 47984.311 | Q10: =L10-O10 -> 262923.83
